File: Main text Fig 3bcd SQUID/Michaela_Gd_Hyst300K.dat
[Header]
; MPMS3 Data File (default extension .dat)
; Copyright (c) 2007, Quantum Design, Inc. All rights reserved.
TITLE,
FILEOPENTIME,3832333600.41406,06/08/2021,5:06 pm
BYAPP,MPMS3 w/ AC,1.0,1.1
INFO,MPMS3 Measurement Release 1.1.16 Build 424, MultiVu Release 2.3.4.19,APPNAME
INFO,Linear Motor Servo Controller,MOTOR_MODULE_NAME
INFO,3101-100 E1,MOTOR_HW_VERSION
INFO,MMC211,MOTOR_SERIAL_NUMBER
INFO,01.04.28,MOTOR_SOFTWARE_VERSION
INFO,Quantum Design Squid Module,SQUID_MODULE_NAME
INFO,3101-501 B0,SQUID_HW_VERSION
INFO,SQM059,SQUID_SERIAL_NUMBER
INFO,01.03.04,SQUID_SOFTWARE_VERSION
INFO,SQUID AC,AC_MODULE_NAME
INFO,3101-401 F1,AC_HW_VERSION
INFO,SAC057,AC_SERIAL_NUMBER
INFO,SQUID AC 00.95.07,AC_SOFTWARE_VERSION
INFO,TCIXXX,COIL_SERIAL_NUMBER
INFO,0,MOMENT_UNITS
INFO,Michaela_Gd,SAMPLE_MATERIAL
INFO,Michaela_Gd,SAMPLE_COMMENT
INFO,0.9,SAMPLE_MASS
INFO,,SAMPLE_VOLUME
INFO,,SAMPLE_MOLECULAR_WEIGHT
INFO,,SAMPLE_SIZE
INFO,,SAMPLE_SHAPE
INFO,Straw,SAMPLE_HOLDER
INFO,Standard,SAMPLE_HOLDER_DETAIL
INFO,54.44,SAMPLE_OFFSET
DATATYPE,COMMENT,1
DATATYPE,TIME,2
STARTUPAXIS,X,2
STARTUPAXIS,Y1,5
FIELDGROUP, VSM,2,3,4,5,6,8,9,10,11,14,15
FIELDGROUP, DC, 2,3,4,14,56,57,58,59,60,61,62,63,64,65,66,67,68,69
FIELDGROUP, AC, 2,3,4,11,16,17,18,19,20,21,22,23,24,25,26,27,28,29,30
STARTUPGROUP, All
[Data]
Comment,Time Stamp (sec),Temperature (K),Magnetic Field (Oe),Moment (emu),M. Std. Err. (emu),Transport Action,Averaging Time (sec),Frequency (Hz),Peak Amplitude (mm),Center Position (mm),Lockin Signal' (V),Lockin Signal (V),Range,M. Quad. Signal (emu),AC Moment (emu),AC M. Std Err. (emu),AC Phase (deg),AC Phase Std. Err. (deg),AC Susceptibility (emu/Oe),AC Suscept. Std Err. (emu/Oe),AC X' (emu/Oe),AC X' Std Err. (emu/Oe),AC X'' (emu/Oe),AC X'' Std Err. (emu/Oe),AC Drive (Oe),AC Frequency (Hz),AC Averaging Time (sec),AC Cycles,AC Range,AC Measure Type,AC Signal' (V),AC Signal'' (V),AC Trim Coil Ratio,AC Trim Coil Phase,Min. Temperature (K),Max. Temperature (K),Min. Field (Oe),Max. Field (Oe),Mass (grams),Motor Lag (deg),Pressure (Torr),Measure Count,Measurement Number,SQUID Status (code),Motor Status (code),Measure Status (code),Motor Current (amps),Motor Temp. (C),Temp. Status (code),Field Status (code),Chamber Status (code),Chamber Temp (K),Redirection State,Average Temp (K),Rotation Angle (deg),Rotator state,DC Moment Fixed Ctr (emu),DC Moment Err Fixed Ctr (emu),DC Moment Free Ctr (emu),DC Moment Err Free Ctr (emu),DC Fixed Fit,DC Free Fit,DC Calculated Center (mm),DC Calculated Center Err (mm),DC Scan Length (mm),DC Scan Time (s),DC Number of Points,DC Squid Drift,DC Min V (V),DC Max V (V),DC Scans per Measure,Map 01,Map 02,Map 03,Map 04,Map 05,Map 06,Map 07,Map 08,Map 09,Map 10,Map 11,Map 12,Map 13,Map 14,Map 15,Map 16
,3832333806.54065,299.684265136719,0.099701814353466,1.00723416469031E-6,1.09487090495175E-8,1,2,13.4005146026611,4.99502417996082,32.600000500679,0.00133933235413975,0.000205401985813872,1,1.33514068680145E-8,,,,,,,,,,,,,,,,,,,,,299.684265136719,299.684265136719,0.099701814353466,0.099701814353466,47.2220869893319,5.26350412895955,12.4085035324097,27,1,0,0,1,0.275421142578125,38.1231689453125,1,1,1,299.684265136719,0,299.684265136719,,,,,,,,,,,,,,,,,,,,,,,,,,,,,,,,,
,3832333828.5281,299.746276855469,1578.52905273438,3.9959501736373E-5,3.90383956184924E-8,1,2,13.4005146026611,4.99509053192908,32.600000500679,0.053111129485168,0.00832422524698034,1,6.61244300765978E-7,,,,,,,,,,,,,,,,,,,,,299.746246337891,299.746307373047,1578.52905273438,1578.52905273438,47.2732836573415,5.26317997769881,12.6502895355225,26,1,68,0,0,0.284042358398438,38.1231689453125,1,1,1,299.746246337891,0,299.746276855469,,,,,,,,,,,,,,,,,,,,,,,,,,,,,,,,,
,3832333859.28704,299.823333740234,3683.84497070313,8.27909810229887E-5,3.26324833637921E-8,1,2,13.4005146026611,4.99510031624007,32.600000500679,0.110179750595503,0.0162456286365781,1,6.18519063440932E-7,,,,,,,,,,,,,,,,,,,,,299.823333740234,299.823333740234,3683.84497070313,3683.84497070313,47.2662490006685,5.26344427268911,12.923526763916,27,1,0,0,1,0.283279418945313,38.6119270324707,1,1,1,299.823333740234,0,299.823333740234,,,,,,,,,,,,,,,,,,,,,,,,,,,,,,,,,
,3832333888.52133,299.915908813477,5788.98681640625,0.000122794981177573,4.09123199788538E-8,1,2,13.4005146026611,4.99513690414901,32.600000500679,0.163367668991666,0.0244659386279292,1,1.19533832214278E-6,,,,,,,,,,,,,,,,,,,,,299.913848876953,299.91796875,5788.98681640625,5788.98681640625,47.1892585915242,5.26275301783907,13.1081457138062,27,1,0,0,1,0.28411865234375,38.6119270324707,1,1,1,299.91796875,0,299.915908813477,,,,,,,,,,,,,,,,,,,,,,,,,,,,,,,,,
,3832333909.75661,299.990509033203,7894.4267578125,0.000162241900177328,5.14101468564294E-8,1,2,13.4005146026611,4.99509120351631,32.600000500679,0.215851784827867,0.032280351564573,1,1.54579920048972E-6,,,,,,,,,,,,,,,,,,,,,299.983734130859,299.997283935547,7894.4267578125,7894.4267578125,47.2330297886012,5.26260768642149,13.210636138916,27,1,0,0,1,0.275115966796875,38.1231689453125,1,1,1,299.997283935547,0,299.990509033203,,,,,,,,,,,,,,,,,,,,,,,,,,,,,,,,,
,3832333931.38732,299.991073608398,9999.53125,0.000201227515756205,1.4575358741122E-7,1,2,13.4005146026611,4.9950617756886,32.600000500679,0.267763923362893,0.0397035225497747,1,1.66709102476076E-6,,,,,,,,,,,,,,,,,,,,,299.985534667969,299.996612548828,9999.53125,9999.53125,47.2259951319281,5.26287874061481,13.2959060668945,27,1,0,0,1,0.2923583984375,38.1231689453125,1,1,1,299.985534667969,0,299.991073608398,,,,,,,,,,,,,,,,,,,,,,,,,,,,,,,,,
,3832333965.10408,299.917938232422,13333.07421875,0.000250638828917898,3.89924541277205E-6,1,2,13.4005146026611,4.99505878119577,32.600000500679,0.335293269018229,0.0367198352993495,1,-7.48133732121474E-6,,,,,,,,,,,,,,,,,,,,,299.916351318359,299.919525146484,13333.07421875,13333.07421875,47.1998105765338,5.26411570623532,13.4145393371582,27,1,0,0,1,0.283966064453125,38.6119270324707,1,1,1,299.919525146484,0,299.917938232422,,,,,,,,,,,,,,,,,,,,,,,,,,,,,,,,,
,3832333990.33956,299.931243896484,17777.53125,0.000331747006750703,1.31931140083655E-5,1,2,13.4005146026611,4.99505438466894,32.600000500679,0.444618557261659,0.0427166187222741,1,-1.43205519128614E-5,,,,,,,,,,,,,,,,,,,,,299.931091308594,299.931396484375,17777.53125,17777.53125,47.1482230942646,5.26392604744824,13.4778709411621,27,1,0,0,1,0.284271240234375,38.6119270324707,1,1,1,299.931396484375,0,299.931243896484,,,,,,,,,,,,,,,,,,,,,,,,,,,,,,,,,
,3832334034.50715,300.030639648438,21999.62890625,0.0004238302730713,5.11466277500132E-6,1,2,13.4005146026611,4.9950089799575,32.600000500679,0.564961204516939,0.0764820607816968,1,-1.8493211579741E-6,,,,,,,,,,,,,,,,,,,,,300.030639648438,300.030639648438,21999.62890625,21999.62890625,47.2095809330242,5.26274433758896,13.5661144256592,27,1,0,0,1,0.285110473632813,38.6119270324707,1,1,1,300.030639648438,0,300.030639648438,,,,,,,,,,,,,,,,,,,,,,,,,,,,,,,,,
,3832334084.38689,300.036407470703,34999.76171875,0.00135066432265292,3.89264225224653E-5,1,2,13.4005146026611,4.99486376339547,32.600000500679,1.76282328230148,0.512108740387308,10,0.00019557818059038,,,,,,,,,,,,,,,,,,,,,300.036407470703,300.036407470703,34999.76171875,34999.76171875,47.2216961750723,5.26356379177083,13.6435327529907,27,1,0,0,1,0.284042358398438,38.6119270324707,1,1,1,300.036407470703,0,300.036407470703,,,,,,,,,,,,,,,,,,,,,,,,,,,,,,,,,
,3832334144.52235,300.084655761719,58333.015625,0.00112581163334785,3.73399161250717E-6,1,2,13.4005146026611,4.9949512783571,32.600000500679,1.4981096449982,0.221473766497066,10,8.83927751080882E-6,,,,,,,,,,,,,,,,,,,,,300.084136962891,300.085174560547,58333.015625,58333.015625,47.0630255856684,5.26325125354775,13.7099742889404,27,1,0,0,1,0.284271240234375,38.6119270324707,1,1,1,300.084136962891,0,300.084655761719,,,,,,,,,,,,,,,,,,,,,,,,,,,,,,,,,
,3832334197.51949,300.017974853516,58333.1171875,0.00110815959959431,1.73345843513464E-7,1,2,13.4005146026611,4.99499723780943,32.600000500679,1.47474890275314,0.217216448611999,10,8.10954836262218E-6,,,,,,,,,,,,,,,,,,,,,300.017395019531,300.0185546875,58333.1171875,58333.1171875,47.0001044898704,5.2619379772875,13.7571630477905,27,1,0,0,1,0.283966064453125,38.6119270324707,1,1,1,300.017395019531,0,300.017974853516,,,,,,,,,,,,,,,,,,,,,,,,,,,,,,,,,
,3832334250.27751,300.008224487305,34999.7734375,0.000673198919445795,6.36406859950104E-7,1,2,13.4005146026611,4.99498508907385,32.600000500679,0.89587008284813,0.132144319978931,10,5.06712164400029E-6,,,,,,,,,,,,,,,,,,,,,300.007904052734,300.008544921875,34999.7734375,34999.7734375,47.1544761224185,5.26281043283032,13.7678966522217,27,1,0,0,1,0.284271240234375,38.6119270324707,1,1,1,300.007904052734,0,300.008224487305,,,,,,,,,,,,,,,,,,,,,,,,,,,,,,,,,
,3832334290.33057,300.007431030273,21999.767578125,0.000429161705650253,4.76768799451325E-7,1,2,13.4005146026611,4.99492517778719,32.600000500679,0.571174670333379,0.0837370141617667,10,2.85261341385519E-6,,,,,,,,,,,,,,,,,,,,,300.00732421875,300.007537841797,21999.767578125,21999.767578125,47.2373287454569,5.26298256265689,13.8001022338867,27,1,0,0,1,0.283279418945313,38.6119270324707,1,1,1,300.007537841797,0,300.007431030273,,,,,,,,,,,,,,,,,,,,,,,,,,,,,,,,,
,3832334331.03196,300.002883911133,17777.53125,0.000348865855461721,8.69511451023147E-8,1,2,13.4005146026611,4.99494648896741,32.600000500679,0.464227036791201,0.0686708429386396,1,2.76971541917631E-6,,,,,,,,,,,,,,,,,,,,,300.002014160156,300.003753662109,17777.53125,17777.53125,47.1576026364954,5.26265484888171,13.8144521713257,27,1,0,0,1,0.284347534179687,38.6119270324707,1,1,1,300.002014160156,0,300.002883911133,,,,,,,,,,,,,,,,,,,,,,,,,,,,,,,,,
,3832334357.19553,300.001449584961,13332.8369140625,0.000265116300563988,4.54302339285157E-8,1,2,13.4005146026611,4.9949383926052,32.600000500679,0.352790496130541,0.0521305656117849,1,2.06361604140677E-6,,,,,,,,,,,,,,,,,,,,,300.001220703125,300.001678466797,13332.8369140625,13332.8369140625,47.1662005502069,5.26307776970397,13.8068494796753,26,1,68,0,0,0.284652709960938,38.6119270324707,1,1,1,300.001220703125,0,300.001449584961,,,,,,,,,,,,,,,,,,,,,,,,,,,,,,,,,
,3832334392.8438,300.001525878906,9999.59375,0.000202216665827764,6.11298611985681E-8,1,2,13.4005146026611,4.99491578264493,32.600000500679,0.26907905965013,0.0398277572876249,1,1.62323898793977E-6,,,,,,,,,,,,,,,,,,,,,300.001525878906,300.001525878906,9999.59375,9999.59375,47.2529613158415,5.26282633064983,13.8034143447876,27,1,0,0,1,0.275955200195313,38.6119270324707,1,1,1,300.001373291016,0,300.001525878906,,,,,,,,,,,,,,,,,,,,,,,,,,,,,,,,,
,3832334415.24183,300.000061035156,7894.41455078125,0.000162409104949681,5.01536798945225E-8,1,2,13.4005146026611,4.99493407319793,32.600000500679,0.21615312690603,0.0316814351109784,1,1.0738778796111E-6,,,,,,,,,,,,,,,,,,,,,299.999847412109,300.000274658203,7894.41455078125,7894.41455078125,47.2428001450915,5.26271877586842,13.8091268539429,27,1,0,0,1,0.276336669921875,38.6119270324707,1,1,1,299.999847412109,0,300.000061035156,,,,,,,,,,,,,,,,,,,,,,,,,,,,,,,,,
,3832334437.55115,300.011184692383,5789.173828125,0.000122713034603568,3.07952861525105E-8,1,2,13.4005146026611,4.99493962969419,32.600000500679,0.163329686001047,0.0238770489559622,1,7.65730615721328E-7,,,,,,,,,,,,,,,,,,,,,300.010986328125,300.011383056641,5789.173828125,5789.173828125,47.2412368880531,5.26233733203814,13.8008146286011,27,1,0,0,1,0.2850341796875,38.6119270324707,1,1,1,300.010986328125,0,300.011184692383,,,,,,,,,,,,,,,,,,,,,,,,,,,,,,,,,
,3832334467.1772,300.008255004883,3683.73291015625,8.2604084559542E-5,3.02418982460649E-8,1,2,13.4005146026611,4.99491392656827,32.600000500679,0.109959157902702,0.0159667357731483,1,4.35917860486287E-7,,,,,,,,,,,,,,,,,,,,,300.008056640625,300.008453369141,3683.73291015625,3683.73291015625,47.2170064039569,5.26259518813564,13.8037014007568,27,1,0,0,1,0.284271240234375,38.6119270324707,1,1,1,300.008056640625,0,300.008255004883,,,,,,,,,,,,,,,,,,,,,,,,,,,,,,,,,
,3832334490.04286,300.002395629883,1578.6162109375,4.02245327713558E-5,3.01326123018878E-8,1,2,13.4005146026611,4.9949023683143,32.600000500679,0.0535581259037392,0.00768171433044756,1,1.42193912271289E-7,,,,,,,,,,,,,,,,,,,,,300.001922607422,300.002868652344,1578.6162109375,1578.6162109375,47.1431425088896,5.26270627207187,13.8116245269775,27,1,0,0,1,0.286331176757813,38.6119270324707,1,1,1,300.001922607422,0,300.002395629883,,,,,,,,,,,,,,,,,,,,,,,,,,,,,,,,,
,3832334511.08865,300.000381469727,-526.001831054687,-1.54922905260855E-5,3.20612934791485E-8,1,2,13.4005146026611,4.99484519280735,32.600000500679,-0.0205891608034895,-0.00323157229843877,1,-2.59734130258864E-7,,,,,,,,,,,,,,,,,,,,,299.999847412109,300.000915527344,-526.001831054687,-526.001831054687,47.2486623589858,5.26298056536725,13.7908773422241,27,1,0,0,1,0.27496337890625,38.6119270324707,1,1,1,299.999847412109,0,300.000381469727,,,,,,,,,,,,,,,,,,,,,,,,,,,,,,,,,
,3832334533.77355,300.003280639648,-2631.3427734375,-6.09596618101775E-5,1.80106895225924E-7,1,2,13.4005146026611,4.99484223959554,32.600000500679,-0.0811108184830691,-0.0120301125928432,1,-5.07347576320366E-7,,,,,,,,,,,,,,,,,,,,,300.002777099609,300.003784179687,-2631.3427734375,-2631.3427734375,47.1747984639185,5.26332836867361,13.8103141784668,27,1,0,0,1,0.2850341796875,38.6119270324707,1,1,1,300.002777099609,0,300.003280639648,,,,,,,,,,,,,,,,,,,,,,,,,,,,,,,,,
,3832334564.6524,299.998428344727,-4736.62158203125,-0.000101904183450996,3.00250259626906E-8,1,2,13.4005146026611,4.9948939226362,32.600000500679,-0.135560731553894,-0.0203349975447458,1,-1.0165553392141E-6,,,,,,,,,,,,,,,,,,,,,299.998046875,299.998809814453,-4736.62158203125,-4736.62158203125,47.1861320774473,5.26350308286992,13.8134098052979,27,1,0,0,1,0.284194946289062,38.6119270324707,1,1,1,299.998046875,0,299.998428344727,,,,,,,,,,,,,,,,,,,,,,,,,,,,,,,,,
,3832334586.00937,299.998504638672,-6841.712890625,-0.000141956655195272,2.5019346298744E-8,1,2,13.4005146026611,4.994870663753,32.600000500679,-0.188850480629706,-0.0282550936081178,1,-1.36190297447025E-6,,,,,,,,,,,,,,,,,,,,,299.998229980469,299.998779296875,-6841.712890625,-6841.712890625,47.1372802949954,5.26311122962801,13.8038854598999,27,1,0,0,1,0.28167724609375,39.1006851196289,1,1,1,299.998229980469,0,299.998504638672,,,,,,,,,,,,,,,,,,,,,,,,,,,,,,,,,
,3832334607.34747,300.014892578125,-8947.029296875,-0.000181988033099001,3.92454072018706E-8,1,2,13.4005146026611,4.99482179091494,32.600000500679,-0.242105957341994,-0.0361980273317463,1,-1.72761060942793E-6,,,,,,,,,,,,,,,,,,,,,300.014739990234,300.015045166016,-8947.029296875,-8947.029296875,47.1974656909762,5.26364419507105,13.811505317688,27,1,0,0,1,0.276031494140625,38.6119270324707,1,1,1,300.015045166016,0,300.014892578125,,,,,,,,,,,,,,,,,,,,,,,,,,,,,,,,,
,3832334642.25424,300.015228271484,-11999.76171875,-0.000240306841039441,4.29304833985274E-8,1,2,13.4005146026611,4.99483205024198,32.600000500679,-0.31974488845495,-0.0474104062575788,1,-1.99029308726781E-6,,,,,,,,,,,,,,,,,,,,,300.015228271484,300.015228271484,-11999.76171875,-11999.76171875,47.1693270642838,5.26372913672607,13.8057909011841,27,1,0,0,1,0.285568237304687,38.6119270324707,1,1,1,300.015228271484,0,300.015228271484,,,,,,,,,,,,,,,,,,,,,,,,,,,,,,,,,
,3832334664.95287,299.97184753418,-14999.7265625,-0.000296998915259492,6.84153080032584E-8,1,2,13.4005146026611,4.99479779355409,32.600000500679,-0.39511707534522,-0.0590011436522689,1,-2.76494991465394E-6,,,,,,,,,,,,,,,,,,,,,299.951568603516,299.992126464844,-14999.7265625,-14999.7265625,47.1341537809185,5.26351815452237,13.8155126571655,27,1,0,0,1,0.285720825195313,38.6119270324707,1,1,1,299.951568603516,0,299.97184753418,,,,,,,,,,,,,,,,,,,,,,,,,,,,,,,,,
,3832334701.18518,299.708892822266,-19999.51171875,-0.000392033682819279,5.1665251129718E-8,1,2,13.4005146026611,4.99479029380322,32.600000500679,-0.521605407070216,-0.0774624205187584,1,-3.33592858310258E-6,,,,,,,,,,,,,,,,,,,,,299.708892822266,299.708892822266,-19999.51171875,-19999.51171875,47.1638556646492,5.26401530174232,13.7895069122314,27,1,0,0,1,0.2734375,38.6119270324707,1,1,1,299.708892822266,0,299.708892822266,,,,,,,,,,,,,,,,,,,,,,,,,,,,,,,,,
,3832334737.12812,299.799468994141,-25555.283203125,-0.000496214402362083,7.2610009770574E-8,1,2,13.4005146026611,4.99477525518369,32.600000500679,-0.660168538368517,-0.098389172043823,1,-4.47914075427619E-6,,,,,,,,,,,,,,,,,,,,,299.796691894531,299.80224609375,-25555.283203125,-25555.283203125,47.18339637763,5.26387189778855,13.7937202453613,27,1,0,0,1,0.284347534179687,38.6119270324707,1,1,1,299.80224609375,0,299.799468994141,,,,,,,,,,,,,,,,,,,,,,,,,,,,,,,,,
,3832334782.37667,299.911636352539,-43333.1015625,-0.000830167522859255,2.29755327790909E-7,1,2,13.4005146026611,4.99472503070136,32.600000500679,-1.10426544073449,-0.165907580008352,1,-8.47298474154934E-6,,,,,,,,,,,,,,,,,,,,,299.909973144531,299.913299560547,-43333.1015625,-43333.1015625,47.1415792518511,5.26304402469456,13.7847414016724,26,1,68,0,0,0.28106689453125,38.6119270324707,1,1,1,299.913299560547,0,299.911636352539,,,,,,,,,,,,,,,,,,,,,,,,,,,,,,,,,
,3832334850.37718,299.998718261719,-61110.7578125,-0.00116258273384653,2.32467465020066E-7,1,2,13.4005146026611,4.9947193524652,32.600000500679,-1.54695072940157,-0.228632599038356,10,-9.08266800985252E-6,,,,,,,,,,,,,,,,,,,,,299.998718261719,299.998718261719,-61110.7578125,-61110.7578125,46.9758740057742,5.26346990282531,13.7909622192383,27,1,0,0,1,0.284271240234375,38.6119270324707,1,1,1,299.998718261719,0,299.998718261719,,,,,,,,,,,,,,,,,,,,,,,,,,,,,,,,,
,3832334895.12092,300.009552001953,-61110.8203125,-0.00116263042706692,1.38627192014357E-7,1,2,13.4005146026611,4.99473673545623,32.600000500679,-1.54711004560866,-0.228010268364899,10,-8.60799296073033E-6,,,,,,,,,,,,,,,,,,,,,300.009216308594,300.009887695313,-61110.8203125,-61110.8203125,46.9918973904184,5.2630704511677,13.7959861755371,27,1,0,0,1,0.2764892578125,38.6119270324707,1,1,1,300.009216308594,0,300.009552001953,,,,,,,,,,,,,,,,,,,,,,,,,,,,,,,,,
,3832334940.682,300.004653930664,-43333.015625,-0.000831080442899082,2.26429163055662E-7,1,2,13.4005146026611,4.9946043131849,32.600000500679,-1.10591466320176,-0.162712489285776,10,-5.95079745849561E-6,,,,,,,,,,,,,,,,,,,,,300.004180908203,300.005126953125,-43333.015625,-43333.015625,47.1470506514858,5.26393274327689,13.8062181472778,27,1,0,0,1,0.284500122070313,38.6119270324707,1,1,1,300.004180908203,0,300.004653930664,,,,,,,,,,,,,,,,,,,,,,,,,,,,,,,,,
,3832334986.32971,300.000259399414,-25555.357421875,-0.000497010487575926,1.9376330847537E-7,1,2,13.4005146026611,4.99465031259689,32.600000500679,-0.661465991920426,-0.0966770312802844,10,-3.08501480727132E-6,,,,,,,,,,,,,,,,,,,,,299.999176025391,300.001342773438,-25555.357421875,-25555.357421875,47.16307403613,5.26465179798146,13.7841262817383,27,1,0,0,1,0.28411865234375,38.6119270324707,1,1,1,300.001342773438,0,300.000259399414,,,,,,,,,,,,,,,,,,,,,,,,,,,,,,,,,
,3832335028.9414,300.013092041016,-19999.537109375,-0.000391291825242745,5.41020331863043E-8,1,2,13.4005146026611,4.99459351644323,32.600000500679,-0.520582576264196,-0.0773666114150928,1,-3.37086751707501E-6,,,,,,,,,,,,,,,,,,,,,300.013092041016,300.013092041016,-19999.537109375,-19999.537109375,47.2056727904281,5.26550972777388,13.7753686904907,27,1,0,0,1,0.285263061523438,39.1006851196289,1,1,1,300.013092041016,0,300.013092041016,,,,,,,,,,,,,,,,,,,,,,,,,,,,,,,,,
,3832335056.23055,300.005157470703,-14999.615234375,-0.000297124088301777,1.07509132251594E-7,1,2,13.4005146026611,4.99459082502834,32.600000500679,-0.395326101318472,-0.058558223402871,1,-2.41744558175061E-6,,,,,,,,,,,,,,,,,,,,,300.004455566406,300.005859375,-14999.615234375,-14999.615234375,47.2072360474665,5.26434010876896,13.777569770813,27,1,0,0,1,0.284652709960938,38.6119270324707,1,1,1,300.004455566406,0,300.005157470703,,,,,,,,,,,,,,,,,,,,,,,,,,,,,,,,,
,3832335082.77434,299.996932983398,-9999.5810546875,-0.000202476519351683,5.18034493991153E-8,1,2,13.4005146026611,4.99465004787294,32.600000500679,-0.269427493751923,-0.039716568526226,1,-1.50561269462272E-6,,,,,,,,,,,,,,,,,,,,,299.996429443359,299.997436523438,-9999.5810546875,-9999.5810546875,47.1572118222358,5.26497651866572,13.7748689651489,27,1,0,0,1,0.285263061523438,38.6119270324707,1,1,1,299.996429443359,0,299.996932983398,,,,,,,,,,,,,,,,,,,,,,,,,,,,,,,,,
,3832335112.49802,299.994720458984,-8947.0048828125,-0.000182636223999592,6.97964231458953E-8,1,2,13.4005146026611,4.99459360563581,32.600000500679,-0.243040804053778,-0.0356971806394992,1,-1.26267611686078E-6,,,,,,,,,,,,,,,,,,,,,299.994445800781,299.994995117188,-8947.0048828125,-8947.0048828125,47.1310272668415,5.26546122424188,13.7682266235352,27,1,0,0,1,0.284957885742187,38.6119270324707,1,1,1,299.994445800781,0,299.994720458984,,,,,,,,,,,,,,,,,,,,,,,,,,,,,,,,,
,3832335134.05623,299.995880126953,-6841.77587890625,-0.000142789060151163,9.84282736675666E-8,1,2,13.4005146026611,4.99460685415706,32.600000500679,-0.190027807224607,-0.0278201732881045,1,-9.20539931201511E-7,,,,,,,,,,,,,,,,,,,,,299.995452880859,299.996307373047,-6841.77587890625,-6841.77587890625,47.2150523326588,5.2649645002598,13.766414642334,27,1,0,0,1,0.293197631835937,38.6119270324707,1,1,1,299.996307373047,0,299.995880126953,,,,,,,,,,,,,,,,,,,,,,,,,,,,,,,,,
,3832335165.64967,299.994384765625,-4736.33447265625,-0.000102721375760496,2.1278246442485E-8,1,2,13.4005146026611,4.99457767513448,32.600000500679,-0.136681412074541,-0.0201712991203823,1,-7.80723242479924E-7,,,,,,,,,,,,,,,,,,,,,299.994384765625,299.994384765625,-4736.33447265625,-4736.33447265625,47.1966840624569,5.26520683632782,13.7705392837524,27,1,0,0,1,0.28533935546875,38.6119270324707,1,1,1,299.994384765625,0,299.994384765625,,,,,,,,,,,,,,,,,,,,,,,,,,,,,,,,,
,3832335188.2764,299.994064331055,-2631.33032226562,-6.21037657890236E-5,8.48692452971619E-8,1,2,13.4005146026611,4.99450739366749,32.600000500679,-0.0826733375951414,-0.011912887952553,1,-2.60199494526015E-7,,,,,,,,,,,,,,,,,,,,,299.994018554687,299.994110107422,-2631.33032226562,-2631.33032226562,47.1900402200434,5.26593587404254,13.7735376358032,25,1,68,0,0,0.276107788085938,39.1006851196289,1,1,1,299.994018554687,0,299.994064331055,,,,,,,,,,,,,,,,,,,,,,,,,,,,,,,,,
,3832335211.43984,299.992080688477,-526.625,-1.67201050111874E-5,2.54666629722726E-8,1,2,13.4005146026611,4.99451751417885,32.600000500679,-0.0222771034998395,-0.00307125840064684,1,3.20790201860669E-8,,,,,,,,,,,,,,,,,,,,,299.991577148438,299.992584228516,-526.625,-526.625,47.1658097359473,5.2651094138103,13.7503089904785,27,1,0,0,1,0.284881591796875,39.1006851196289,1,1,1,299.992584228516,0,299.992080688477,,,,,,,,,,,,,,,,,,,,,,,,,,,,,,,,,
,3832335234.69158,300.00553894043,1578.79064941406,3.93060847002735E-5,3.63999330353748E-8,1,2,13.4005146026611,4.99456338870689,32.600000500679,0.0522710323427526,0.00792997154914129,1,4.57526421171656E-7,,,,,,,,,,,,,,,,,,,,,300.005157470703,300.005920410156,1578.79064941406,1578.79064941406,47.2678122577069,5.26533592495988,13.769082069397,27,1,0,0,1,0.27374267578125,38.6119270324707,1,1,1,300.005157470703,0,300.00553894043,,,,,,,,,,,,,,,,,,,,,,,,,,,,,,,,,
,3832335256.52302,300.002838134766,3683.95703125,8.16800415347419E-5,2.54180311842917E-8,1,2,13.4005146026611,4.99454661269136,32.600000500679,0.108646706394434,0.016297544345813,1,8.1468006690472E-7,,,,,,,,,,,,,,,,,,,,,300.002227783203,300.003448486328,3683.95703125,3683.95703125,47.1865228917069,5.26461858908618,13.7608032226563,27,1,0,0,1,0.27557373046875,39.1006851196289,1,1,1,300.002227783203,0,300.002838134766,,,,,,,,,,,,,,,,,,,,,,,,,,,,,,,,,
,3832335287.7994,299.998016357422,5789.173828125,0.000122129859705491,2.16272980648334E-8,1,2,13.4005146026611,4.99451769063255,32.600000500679,0.162478239843192,0.0241644571581549,1,1.06511789532764E-6,,,,,,,,,,,,,,,,,,,,,299.998016357422,299.998016357422,5789.173828125,5789.173828125,47.1685454357646,5.26536981701564,13.762228012085,27,1,0,0,1,0.285720825195313,38.6119270324707,1,1,1,299.998016357422,0,299.998016357422,,,,,,,,,,,,,,,,,,,,,,,,,,,,,,,,,
,3832335319.4389,300.001403808594,7894.6015625,0.000162178943609733,2.58340996035386E-8,1,2,13.4005146026611,4.99440448366951,32.600000500679,0.215763970900374,0.0320001234456504,1,1.3487776323641E-6,,,,,,,,,,,,,,,,,,,,,300.001403808594,300.001403808594,7894.6015625,7894.6015625,47.2091901187646,5.2661202205959,13.7655944824219,27,1,0,0,1,0.294113159179687,38.6119270324707,1,1,1,300.001403808594,0,300.001403808594,,,,,,,,,,,,,,,,,,,,,,,,,,,,,,,,,
,3832335340.02942,300.015335083008,9999.71875,0.000202104412515114,3.47377030197616E-7,1,2,13.4005146026611,4.99436817333276,32.600000500679,0.268741993491796,0.040853202678283,1,2.41331253544414E-6,,,,,,,,,,,,,,,,,,,,,300.014526367188,300.016143798828,9999.71875,9999.71875,47.2408460737935,5.26541527597101,13.7452869415283,27,1,0,0,1,0.277023315429687,39.1006851196289,1,1,1,300.016143798828,0,300.015335083008,,,,,,,,,,,,,,,,,,,,,,,,,,,,,,,,,
,3832335373.1981,300.032562255859,13332.9375,0.000264856633307116,1.16558640523511E-7,1,2,13.4005146026611,4.99437582892679,32.600000500679,0.352277799874569,0.0528780621520274,1,2.66716845563251E-6,,,,,,,,,,,,,,,,,,,,,300.032379150391,300.032745361328,13332.9375,13332.9375,47.1798790492935,5.26577215566525,13.7588930130005,26,1,68,0,0,0.285720825195313,39.1006851196289,1,1,1,300.032745361328,0,300.032562255859,,,,,,,,,,,,,,,,,,,,,,,,,,,,,,,,,
,3832335398.68879,300.02799987793,17777.28125,0.000349705934782546,4.86030637747815E-7,1,2,13.4005146026611,4.99434263551954,32.600000500679,0.465093962612139,0.0700683892815397,1,3.71005425303088E-6,,,,,,,,,,,,,,,,,,,,,300.027893066406,300.028106689453,17777.28125,17777.28125,47.1486139085242,5.26569360461995,13.7486095428467,27,1,0,0,1,0.285873413085938,39.1006851196289,1,1,1,300.027893066406,0,300.02799987793,,,,,,,,,,,,,,,,,,,,,,,,,,,,,,,,,
,3832335443.84373,300.028869628906,21999.830078125,0.000428768875928294,6.00389784434661E-8,1,2,13.4005146026611,4.99437469164222,32.600000500679,0.57037231402153,0.0850307930943582,1,3.88837690306313E-6,,,,,,,,,,,,,,,,,,,,,300.028869628906,300.028869628906,21999.830078125,21999.830078125,47.2154431469185,5.26580940916688,13.7483005523682,27,1,0,0,1,0.286026000976562,39.1006851196289,1,1,1,300.028869628906,0,300.028869628906,,,,,,,,,,,,,,,,,,,,,,,,,,,,,,,,,
,3832335481.23753,300.015365600586,34999.76171875,0.000673865353219866,8.43442202768319E-8,1,2,13.4005146026611,4.99432450800832,32.600000500679,0.896345713386093,0.134030392587294,1,6.40796249810968E-6,,,,,,,,,,,,,,,,,,,,,300.01513671875,300.015594482422,34999.76171875,34999.76171875,47.1364986664761,5.26617903586452,13.7486343383789,27,1,0,0,1,0.27679443359375,39.1006851196289,1,1,1,300.01513671875,0,300.015365600586,,,,,,,,,,,,,,,,,,,,,,,,,,,,,,,,,
,3832335543.65711,300.004425048828,58332.8671875,0.00111184310676391,1.40049405450952E-7,1,2,13.4005146026611,4.99429070794177,32.600000500679,1.47893110211715,0.220994014750255,1,1.04623085191042E-5,,,,,,,,,,,,,,,,,,,,,300.004425048828,300.004425048828,58332.8671875,58332.8671875,47.04113998713,5.26620378953066,13.7415351867676,27,1,0,0,1,0.286483764648438,39.1006851196289,1,1,1,300.004425048828,0,300.004425048828,,,,,,,,,,,,,,,,,,,,,,,,,,,,,,,,,
,3832335609.19774,299.784393310547,58332.8671875,0.0011129885171133,1.42436433295325E-7,1,2,13.4005146026611,4.99427373398795,32.600000500679,1.4808617749853,0.218259842827761,10,8.25010427201274E-6,,,,,,,,,,,,,,,,,,,,,299.783660888672,299.785125732422,58332.8671875,58332.8671875,47.0489562723223,5.2660579601843,13.7312545776367,27,1,0,0,1,0.285797119140625,39.1006851196289,1,1,1,299.785125732422,0,299.784393310547,,,,,,,,,,,,,,,,,,,,,,,,,,,,,,,,,
,3832335663.81269,299.935989379883,34999.67578125,0.000674626605288196,2.68826484138858E-7,1,2,13.4005146026611,4.99426092476163,32.600000500679,0.897663013704518,0.131888201847961,10,4.69490992242012E-6,,,,,,,,,,,,,,,,,,,,,299.933837890625,299.938140869141,34999.67578125,34999.67578125,47.12242935313,5.26678807884736,13.7433805465698,27,1,0,0,1,0.2862548828125,39.1006851196289,1,1,1,299.938842773438,0,299.935989379883,,,,,,,,,,,,,,,,,,,,,,,,,,,,,,,,,
,3832335706.58391,299.993438720703,21999.529296875,0.000428540313991394,1.2241229370665E-7,1,2,13.4005146026611,4.99417876071856,32.600000500679,0.570041362907331,0.0849541965180265,1,3.86625570710779E-6,,,,,,,,,,,,,,,,,,,,,299.99267578125,299.994201660156,21999.529296875,21999.529296875,47.1978565052358,5.26699171419712,13.7287292480469,27,1,0,0,1,0.29296875,39.1006851196289,1,1,1,299.994201660156,0,299.993438720703,,,,,,,,,,,,,,,,,,,,,,,,,,,,,,,,,