File: Main text Fig 3bcd SQUID/Michaela_Y_ZFC1T.dat
[Header]
; MPMS3 Data File (default extension .dat)
; Copyright (c) 2007, Quantum Design, Inc. All rights reserved.
TITLE,
FILEOPENTIME,3833436712.90471,06/21/2021,11:32 am
BYAPP,MPMS3 w/ AC,1.0,1.1
INFO,MPMS3 Measurement Release 1.1.16 Build 424, MultiVu Release 2.3.4.19,APPNAME
INFO,Linear Motor Servo Controller,MOTOR_MODULE_NAME
INFO,3101-100 E1,MOTOR_HW_VERSION
INFO,MMC211,MOTOR_SERIAL_NUMBER
INFO,01.04.28,MOTOR_SOFTWARE_VERSION
INFO,Quantum Design Squid Module,SQUID_MODULE_NAME
INFO,3101-501 B0,SQUID_HW_VERSION
INFO,SQM059,SQUID_SERIAL_NUMBER
INFO,01.03.04,SQUID_SOFTWARE_VERSION
INFO,SQUID AC,AC_MODULE_NAME
INFO,3101-401 F1,AC_HW_VERSION
INFO,SAC057,AC_SERIAL_NUMBER
INFO,SQUID AC 00.95.07,AC_SOFTWARE_VERSION
INFO,TCIXXX,COIL_SERIAL_NUMBER
INFO,0,MOMENT_UNITS
INFO,Michaela_Y,SAMPLE_MATERIAL
INFO,Michaela_Y,SAMPLE_COMMENT
INFO,1.14,SAMPLE_MASS
INFO,,SAMPLE_VOLUME
INFO,,SAMPLE_MOLECULAR_WEIGHT
INFO,,SAMPLE_SIZE
INFO,,SAMPLE_SHAPE
INFO,Straw,SAMPLE_HOLDER
INFO,Standard,SAMPLE_HOLDER_DETAIL
INFO,56.41,SAMPLE_OFFSET
DATATYPE,COMMENT,1
DATATYPE,TIME,2
STARTUPAXIS,X,2
STARTUPAXIS,Y1,5
FIELDGROUP, VSM,2,3,4,5,6,8,9,10,11,14,15
FIELDGROUP, DC, 2,3,4,14,56,57,58,59,60,61,62,63,64,65,66,67,68,69
FIELDGROUP, AC, 2,3,4,11,16,17,18,19,20,21,22,23,24,25,26,27,28,29,30
STARTUPGROUP, All
[Data]
Comment,Time Stamp (sec),Temperature (K),Magnetic Field (Oe),Moment (emu),M. Std. Err. (emu),Transport Action,Averaging Time (sec),Frequency (Hz),Peak Amplitude (mm),Center Position (mm),Lockin Signal' (V),Lockin Signal (V),Range,M. Quad. Signal (emu),AC Moment (emu),AC M. Std Err. (emu),AC Phase (deg),AC Phase Std. Err. (deg),AC Susceptibility (emu/Oe),AC Suscept. Std Err. (emu/Oe),AC X' (emu/Oe),AC X' Std Err. (emu/Oe),AC X'' (emu/Oe),AC X'' Std Err. (emu/Oe),AC Drive (Oe),AC Frequency (Hz),AC Averaging Time (sec),AC Cycles,AC Range,AC Measure Type,AC Signal' (V),AC Signal'' (V),AC Trim Coil Ratio,AC Trim Coil Phase,Min. Temperature (K),Max. Temperature (K),Min. Field (Oe),Max. Field (Oe),Mass (grams),Motor Lag (deg),Pressure (Torr),Measure Count,Measurement Number,SQUID Status (code),Motor Status (code),Measure Status (code),Motor Current (amps),Motor Temp. (C),Temp. Status (code),Field Status (code),Chamber Status (code),Chamber Temp (K),Redirection State,Average Temp (K),Rotation Angle (deg),Rotator state,DC Moment Fixed Ctr (emu),DC Moment Err Fixed Ctr (emu),DC Moment Free Ctr (emu),DC Moment Err Free Ctr (emu),DC Fixed Fit,DC Free Fit,DC Calculated Center (mm),DC Calculated Center Err (mm),DC Scan Length (mm),DC Scan Time (s),DC Number of Points,DC Squid Drift,DC Min V (V),DC Max V (V),DC Scans per Measure,Map 01,Map 02,Map 03,Map 04,Map 05,Map 06,Map 07,Map 08,Map 09,Map 10,Map 11,Map 12,Map 13,Map 14,Map 15,Map 16
,3833436733.05343,7.99914884567261,9999.6064453125,-6.7438818352214E-5,7.59649468542897E-8,1,2,13.4005146026611,4.99539513376799,29.8699997365475,-0.0897408097914627,-0.0133433521937966,1,-5.85732198645483E-7,,,,,,,,,,,,,,,,,,,,,7.99914884567261,7.99914884567261,9999.6064453125,9999.6064453125,46.7288793936972,5.253996310869,3.92914462089539,27,1,0,0,1,0.275344848632813,35.6793746948242,1,1,1,7.99914884567261,0,7.99914884567261,,,,,,,,,,,,,,,,,,,,,,,,,,,,,,,,,
,3833436788.96244,10.4241414070129,9999.6064453125,-9.6676961550359E-5,5.37307515241251E-8,1,2,13.4005146026611,4.99530825561433,29.8599991947412,-0.128643235765044,-0.0191400400200831,1,-8.48777342110829E-7,,,,,,,,,,,,,,,,,,,,,10.3849678039551,10.4633150100708,9999.6064453125,9999.6064453125,46.802352474505,5.25343298150433,4.15699052810669,27,1,0,0,1,0.282821655273438,36.1681327819824,6,1,1,10.4633150100708,0,10.4241414070129,,,,,,,,,,,,,,,,,,,,,,,,,,,,,,,,,
,3833436853.42256,13.4760999679565,9999.6064453125,-0.000104665970574396,8.0784531226397E-8,1,2,13.4005146026611,4.99540494472247,29.8599991947412,-0.139272587311416,-0.0207574284367597,1,-9.45322327037955E-7,,,,,,,,,,,,,,,,,,,,,13.4234561920166,13.5287437438965,9999.6064453125,9999.6064453125,46.778903618928,5.25301005909082,4.40343332290649,27,1,0,0,1,0.29083251953125,36.6568908691406,6,1,1,13.5287437438965,0,13.4760999679565,,,,,,,,,,,,,,,,,,,,,,,,,,,,,,,,,
,3833436911.85892,16.3510341644287,9999.6064453125,-0.000109497602871286,6.12194345986833E-8,1,2,13.4005146026611,4.99542074243199,29.8599991947412,-0.14570736514193,-0.0216800473736966,1,-9.62174587033673E-7,,,,,,,,,,,,,,,,,,,,,16.3049640655518,16.3971042633057,9999.6064453125,9999.6064453125,46.8445604145434,5.25306926145608,4.59991931915283,27,1,0,0,1,0.290603637695313,36.6568908691406,2,1,1,16.3971042633057,0,16.3510341644287,,,,,,,,,,,,,,,,,,,,,,,,,,,,,,,,,
,3833436968.34359,19.0655632019043,9999.6064453125,-0.000112838325446698,4.96216940484048E-8,1,2,13.4005146026611,4.99534502648125,29.8599991947412,-0.150145624246976,-0.0223702807398691,1,-1.01348366978237E-6,,,,,,,,,,,,,,,,,,,,,19.0145206451416,19.116605758667,9999.6064453125,9999.6064453125,46.7824209472646,5.25246462872795,4.72874689102173,27,1,0,0,1,0.28289794921875,37.1456527709961,2,1,1,19.116605758667,0,19.0655632019043,,,,,,,,,,,,,,,,,,,,,,,,,,,,,,,,,
,3833437024.9247,21.7728748321533,9999.6064453125,-0.000115355899228686,4.8873841654402E-8,1,2,13.4005146026611,4.99538426250848,29.8599991947412,-0.153501071535404,-0.0228421284105366,1,-1.01544813325373E-6,,,,,,,,,,,,,,,,,,,,,21.7176284790039,21.8281211853027,9999.6064453125,9999.6064453125,46.809387131178,5.25275965865022,4.84399461746216,27,1,0,0,1,0.283279418945313,36.6568908691406,2,1,1,21.8281211853027,0,21.7728748321533,,,,,,,,,,,,,,,,,,,,,,,,,,,,,,,,,
,3833437081.16552,24.5061492919922,9999.6064453125,-0.00011758140230853,4.96521213601599E-8,1,2,13.4005146026611,4.99530946236421,29.8599991947412,-0.156464772294191,-0.0232430588894323,1,-1.00556030045908E-6,,,,,,,,,,,,,,,,,,,,,24.4589862823486,24.5533123016357,9999.6064453125,9999.6064453125,46.7011315812646,5.25286668326657,4.92888307571411,27,1,0,0,1,0.291061401367188,36.6568908691406,2,1,1,24.5533123016357,0,24.5061492919922,,,,,,,,,,,,,,,,,,,,,,,,,,,,,,,,,
,3833437145.66759,27.6101398468018,9999.6064453125,-0.000119477612880555,4.05928810699346E-8,1,2,13.4005146026611,4.99526976941107,29.8599991947412,-0.15898973110148,-0.0235932153485278,1,-1.00344536373823E-6,,,,,,,,,,,,,,,,,,,,,27.5692481994629,27.6510314941406,9999.6064453125,9999.6064453125,46.8191574876684,5.25370940038586,9.32135581970215,27,1,0,0,1,0.282821655273438,36.6568908691406,2,1,1,27.6510314941406,0,27.6101398468018,,,,,,,,,,,,,,,,,,,,,,,,,,,,,,,,,
,3833437200.25614,30.2480001449585,9999.6064453125,-0.000120627858658407,7.43881093042E-8,1,2,13.4005146026611,4.99522993523561,29.8599991947412,-0.160517404497423,-0.0238287738653765,1,-1.01962105045019E-6,,,,,,,,,,,,,,,,,,,,,30.193883895874,30.302116394043,9999.6064453125,9999.6064453125,46.7441211498223,5.25399685721425,9.41810035705566,27,1,0,0,1,0.291290283203125,36.6568908691406,2,1,1,30.302116394043,0,30.2480001449585,,,,,,,,,,,,,,,,,,,,,,,,,,,,,,,,,
,3833437256.54791,32.9916839599609,9999.6064453125,-0.000121484534051207,5.6299126104984E-8,1,2,13.4005146026611,4.9952405050776,29.8699997365475,-0.161657259766047,-0.0240021932050498,1,-1.02995656530018E-6,,,,,,,,,,,,,,,,,,,,,32.9533843994141,33.0299835205078,9999.6064453125,9999.6064453125,46.8519858854761,5.25477764937562,9.47299575805664,27,1,0,0,1,0.274505615234375,36.6568908691406,2,1,1,33.0299835205078,0,32.9916839599609,,,,,,,,,,,,,,,,,,,,,,,,,,,,,,,,,
,3833437311.11711,35.6295757293701,9999.6064453125,-0.000122547378886065,7.65179124989898E-8,1,2,13.4005146026611,4.99514481497875,29.8699997365475,-0.163067782951209,-0.024208015758028,1,-1.03631574097981E-6,,,,,,,,,,,,,,,,,,,,,35.5708312988281,35.6883201599121,9999.6064453125,9999.6064453125,46.7112927520146,5.25466816319648,9.50879669189453,27,1,0,0,1,0.283432006835938,36.6568908691406,2,1,1,35.6883201599121,0,35.6295757293701,,,,,,,,,,,,,,,,,,,,,,,,,,,,,,,,,
,3833437367.41167,38.3822956085205,9999.6064453125,-0.000123435139467559,5.58330648258711E-8,1,2,13.4005146026611,4.99509594691708,29.8699997365475,-0.164249859060541,-0.0243617601798483,1,-1.02783674033194E-6,,,,,,,,,,,,,,,,,,,,,38.3475532531738,38.4170379638672,9999.6064453125,9999.6064453125,46.7617077915049,5.25550103804574,9.5734395980835,27,1,0,0,1,0.291595458984375,36.6568908691406,2,1,1,38.4170379638672,0,38.3822956085205,,,,,,,,,,,,,,,,,,,,,,,,,,,,,,,,,
,3833437431.87907,41.5331554412842,9999.6064453125,-0.00011699283002673,5.30114954845321E-8,1,2,13.4005146026611,4.9950057108934,29.8699997365475,-0.155672056163368,-0.0231000375277801,1,-9.81949493029451E-7,,,,,,,,,,,,,,,,,,,,,41.4995498657227,41.5667610168457,9999.6064453125,9999.6064453125,46.8586297278896,5.25601197649056,9.65178394317627,27,1,0,0,1,0.281906127929687,36.6568908691406,2,1,1,41.5667610168457,0,41.5331554412842,,,,,,,,,,,,,,,,,,,,,,,,,,,,,,,,,
,3833437488.36401,44.2945861816406,9999.6064453125,-9.27341349222831E-5,8.48464928301632E-8,1,2,13.4005146026611,4.99499711085206,29.8699997365475,-0.123399532003981,-0.0182624082463513,1,-7.42498446422329E-7,,,,,,,,,,,,,,,,,,,,,44.2638092041016,44.3253631591797,9999.6064453125,9999.6064453125,46.8226748160049,5.25643231889458,9.72537994384766,27,1,0,0,1,0.282745361328125,36.6568908691406,2,1,1,44.3253631591797,0,44.2945861816406,,,,,,,,,,,,,,,,,,,,,,,,,,,,,,,,,
,3833437544.52782,47.0276546478271,9999.6064453125,-3.74137602923477E-5,8.17338540480049E-8,1,2,13.4005146026611,4.99499082224167,29.8800002783537,-0.0497844502808292,-0.00737682987052962,1,-3.06198021471375E-7,,,,,,,,,,,,,,,,,,,,,46.9797592163086,47.0755500793457,9999.6064453125,9999.6064453125,46.7062121666396,5.25612586975766,9.83206939697266,27,1,0,0,1,0.284271240234375,36.6568908691406,2,1,1,47.0755500793457,0,47.0276546478271,,,,,,,,,,,,,,,,,,,,,,,,,,,,,,,,,
,3833437600.92763,49.7957363128662,9999.6064453125,-0.000121623409288642,6.12399916445167E-8,1,2,13.4005146026611,4.9948803126502,29.8800002783537,-0.161828675409399,-0.0240086437618208,1,-1.01716077891879E-6,,,,,,,,,,,,,,,,,,,,,49.7436943054199,49.8477783203125,9999.6064453125,9999.6064453125,46.7351324218511,5.25643748281987,9.98444652557373,27,1,0,0,1,0.283584594726562,36.6568908691406,2,1,1,49.8477783203125,0,49.7957363128662,,,,,,,,,,,,,,,,,,,,,,,,,,,,,,,,,
,3833437657.37751,52.5467700958252,9999.6064453125,-0.000129956927289531,5.15083638966198E-8,1,2,13.4005146026611,4.99492210653536,29.8800002783537,-0.172920283384941,-0.0256448170166089,1,-1.07997218479372E-6,,,,,,,,,,,,,,,,,,,,,52.5067939758301,52.5867462158203,9999.6064453125,9999.6064453125,46.7269253223992,5.25711087503262,10.2284488677979,27,1,0,0,1,0.284347534179687,36.6568908691406,2,1,1,52.5867462158203,0,52.5467700958252,,,,,,,,,,,,,,,,,,,,,,,,,,,,,,,,,
,3833437714.05939,55.3502140045166,9999.6064453125,-0.000131196903171308,3.32763706429144E-8,1,2,13.4005146026611,4.99493550892098,29.8900008201599,-0.174570044185727,-0.0258952428402904,1,-1.0945121177234E-6,,,,,,,,,,,,,,,,,,,,,55.3135261535645,55.3869018554687,9999.6064453125,9999.6064453125,46.8308819154569,5.25722958649186,10.5395431518555,26,1,64,0,0,0.283584594726562,36.6568908691406,2,1,1,55.3869018554687,0,55.3502140045166,,,,,,,,,,,,,,,,,,,,,,,,,,,,,,,,,
,3833437770.28289,58.0943984985352,9999.6064453125,-0.000132698605986532,6.34937243088229E-8,1,2,13.4005146026611,4.99484173496743,29.8900008201599,-0.1765644546759,-0.0261853063000044,1,-1.10278787278576E-6,,,,,,,,,,,,,,,,,,,,,58.0290412902832,58.1597557067871,9999.6064453125,9999.6064453125,46.8566756565915,5.25819472703321,10.7930326461792,27,1,0,0,1,0.283737182617187,36.6568908691406,2,1,1,58.1597557067871,0,58.0943984985352,,,,,,,,,,,,,,,,,,,,,,,,,,,,,,,,,
,3833437824.58459,60.7783756256104,9999.6064453125,-0.000132980556503156,3.63801316777876E-8,1,2,13.4005146026611,4.99490764091481,29.8900008201599,-0.176943174720697,-0.0262387886170416,1,-1.1031574522917E-6,,,,,,,,,,,,,,,,,,,,,60.7309074401855,60.8258438110352,9999.6064453125,9999.6064453125,46.712856009053,5.25888899969017,11.2858924865723,27,1,0,0,1,0.28533935546875,36.6568908691406,2,1,1,60.8258438110352,0,60.7783756256104,,,,,,,,,,,,,,,,,,,,,,,,,,,,,,,,,
,3833437883.19915,63.6528015136719,9999.6064453125,-0.000133180726661391,4.82460371874747E-8,1,2,13.4005146026611,4.9947540792777,29.8900008201599,-0.177207546985979,-0.0262379123433854,1,-1.07534106117151E-6,,,,,,,,,,,,,,,,,,,,,63.6029472351074,63.7026557922363,9999.6064453125,9999.6064453125,46.8187666734088,5.26022046393926,12.6541891098022,27,1,0,0,1,0.284347534179687,36.6568908691406,2,1,1,63.7026557922363,0,63.6528015136719,,,,,,,,,,,,,,,,,,,,,,,,,,,,,,,,,
,3833437939.69235,66.4382171630859,9999.6064453125,-0.000133458657325214,4.77479330115681E-8,1,2,13.4005146026611,4.9947775375045,29.899999499321,-0.177579138659575,-0.0262882570638882,1,-1.07414731887932E-6,,,,,,,,,,,,,,,,,,,,,66.4070205688477,66.4694137573242,9999.6064453125,9999.6064453125,46.8898948686588,5.25902636863208,14.1187162399292,27,1,0,0,1,0.292816162109375,36.6568908691406,2,1,1,66.4781951904297,0,66.4382171630859,,,,,,,,,,,,,,,,,,,,,,,,,,,,,,,,,
,3833437995.83835,69.1966705322266,9999.6064453125,-0.000133553108982199,4.85943870310032E-8,1,2,13.4005146026611,4.99475818705733,29.899999499321,-0.177704576256457,-0.0263016871826298,1,-1.07112769073598E-6,,,,,,,,,,,,,,,,,,,,,69.1542587280273,69.2390823364258,9999.6064453125,9999.6064453125,46.8910673114377,5.25834541214422,14.5501108169556,27,1,0,0,1,0.27557373046875,36.6568908691406,2,1,1,69.2390823364258,0,69.1966705322266,,,,,,,,,,,,,,,,,,,,,,,,,,,,,,,,,
,3833438052.25011,71.9669609069824,9999.6064453125,-0.000133504005762119,5.76219082907078E-8,1,2,13.4005146026611,4.99476992508042,29.9100000411272,-0.177639699957183,-0.0262929016938637,1,-1.07133455112237E-6,,,,,,,,,,,,,,,,,,,,,71.9169769287109,72.0169448852539,9999.6064453125,9999.6064453125,46.8445604145434,5.25950989401451,14.8730773925781,27,1,0,0,1,0.29327392578125,37.1456527709961,2,1,1,72.0169448852539,0,71.9669609069824,,,,,,,,,,,,,,,,,,,,,,,,,,,,,,,,,
,3833438106.6508,74.6473350524902,9999.6064453125,-0.000133874022433688,4.88490988448282E-8,1,2,13.4005146026611,4.99469964159377,29.9100000411272,-0.17813010391752,-0.0263545699667202,1,-1.06627396891543E-6,,,,,,,,,,,,,,,,,,,,,74.5889587402344,74.7057113647461,9999.6064453125,9999.6064453125,46.8527675139953,5.25952334522547,15.1815843582153,27,1,0,0,1,0.2850341796875,37.1456527709961,2,1,1,74.7057113647461,0,74.6473350524902,,,,,,,,,,,,,,,,,,,,,,,,,,,,,,,,,
,3833438163.03815,77.4201812744141,9999.6064453125,-0.000134267438469041,5.99256095961172E-8,1,2,13.4005146026611,4.99465338489123,29.9100000411272,-0.178648670945525,-0.026450549117393,1,-1.08357077508533E-6,,,,,,,,,,,,,,,,,,,,,77.3705749511719,77.4697875976563,9999.6064453125,9999.6064453125,47.0047942609857,5.25936825986762,15.2548522949219,27,1,0,0,1,0.283355712890625,37.1456527709961,2,1,1,77.4697875976563,0,77.4201812744141,,,,,,,,,,,,,,,,,,,,,,,,,,,,,,,,,
,3833438216.70019,80.0723915100098,9999.6064453125,-0.000134345429370408,3.62026726391114E-8,1,2,13.4005146026611,4.99471540939316,29.9200005829334,-0.178751007682073,-0.0264983648755002,1,-1.10822400004002E-6,,,,,,,,,,,,,,,,,,,,,79.9878082275391,80.1569747924805,9999.6064453125,9999.6064453125,47.0071391465434,5.25886263372435,15.2571849822998,27,1,0,0,1,0.282211303710938,37.1456527709961,2,1,1,80.1569747924805,0,80.0723915100098,,,,,,,,,,,,,,,,,,,,,,,,,,,,,,,,,
,3833438270.03033,82.693359375,9999.6064453125,-0.000134640842524537,4.0976256937702E-8,1,2,13.4005146026611,4.99466438594818,29.9200005829334,-0.179143151226659,-0.026544862942283,1,-1.10210434624074E-6,,,,,,,,,,,,,,,,,,,,,82.6611557006836,82.7255630493164,9999.6064453125,9999.6064453125,46.9610230639088,5.25912799228278,15.2902402877808,27,1,0,0,1,0.28350830078125,37.1456527709961,2,1,1,82.7255630493164,0,82.693359375,,,,,,,,,,,,,,,,,,,,,,,,,,,,,,,,,
,3833438328.26582,85.5834732055664,9999.6064453125,-0.000134656634504854,4.33469610761677E-8,1,2,13.4005146026611,4.99462420214002,29.9299992620945,-0.179167958551606,-0.0265064144105108,1,-1.07125143740823E-6,,,,,,,,,,,,,,,,,,,,,85.5403442382813,85.6266021728516,9999.6064453125,9999.6064453125,46.9403099081492,5.25972969568441,15.3226432800293,27,1,0,0,1,0.275421142578125,37.6344108581543,2,1,1,85.6266021728516,0,85.5834732055664,,,,,,,,,,,,,,,,,,,,,,,,,,,,,,,,,
,3833438386.8849,88.5180397033691,9999.6064453125,-0.000134761375001283,2.70041873700884E-8,1,2,13.4005146026611,4.9945541170214,29.9299992620945,-0.179300719152261,-0.0265490897739491,1,-1.0890272864682E-6,,,,,,,,,,,,,,,,,,,,,88.455322265625,88.5807571411133,9999.6064453125,9999.6064453125,46.8812969549473,5.25964852585235,15.3639125823975,27,1,0,0,1,0.29266357421875,37.1456527709961,2,1,1,88.5807571411133,0,88.5180397033691,,,,,,,,,,,,,,,,,,,,,,,,,,,,,,,,,
,3833438443.38952,91.3222007751465,9999.6064453125,-0.000134798529091312,3.6609412359093E-8,1,2,13.4005146026611,4.99455866315156,29.9399998039007,-0.179361694340089,-0.0264754978002573,1,-1.02855875189899E-6,,,,,,,,,,,,,,,,,,,,,91.2666854858398,91.3777160644531,9999.6064453125,9999.6064453125,46.9485170076011,5.25961831873558,15.3797960281372,27,1,0,0,1,0.284271240234375,37.6344108581543,2,1,1,91.3777160644531,0,91.3222007751465,,,,,,,,,,,,,,,,,,,,,,,,,,,,,,,,,
,3833438499.71539,94.1478805541992,9999.6064453125,-0.000134966722559289,3.29707029545948E-8,1,2,13.4005146026611,4.99453117548522,29.9399998039007,-0.179578547605809,-0.0265483078833749,1,-1.05985365664244E-6,,,,,,,,,,,,,,,,,,,,,94.1115493774414,94.184211730957,9999.6064453125,9999.6064453125,47.0505195293607,5.25971360940508,15.3717908859253,27,1,0,0,1,0.282669067382813,37.6344108581543,2,1,1,94.184211730957,0,94.1478805541992,,,,,,,,,,,,,,,,,,,,,,,,,,,,,,,,,
,3833438557.98565,97.0072479248047,9999.6064453125,-0.000135033616861319,4.80372967821977E-8,1,2,13.4005146026611,4.99456159231934,29.9500003457069,-0.179657386568271,-0.0266451191940982,1,-1.12301454611994E-6,,,,,,,,,,,,,,,,,,,,,96.9529342651367,97.0615615844727,9999.6064453125,9999.6064453125,46.9340568799953,5.26057997469059,15.3893661499023,27,1,0,0,1,0.27557373046875,37.6344108581543,2,1,1,97.0615615844727,0,97.0072479248047,,,,,,,,,,,,,,,,,,,,,,,,,,,,,,,,,
,3833438616.45628,99.9208488464355,9999.6064453125,-0.000135218658167913,4.4782922111738E-8,1,2,13.4005146026611,4.99452713815578,29.9500003457069,-0.17991602500016,-0.0265801954452261,1,-1.04858926097251E-6,,,,,,,,,,,,,,,,,,,,,99.8646545410156,99.9770431518555,9999.6064453125,9999.6064453125,46.9758740057742,5.26016523131968,15.41721534729,27,1,0,0,1,0.284500122070313,37.6344108581543,2,1,1,99.9770431518555,0,99.9208488464355,,,,,,,,,,,,,,,,,,,,,,,,,,,,,,,,,
,3833438673.05029,102.745269775391,9999.6064453125,-0.000135280346286209,4.5277377943081E-8,1,2,13.4005146026611,4.99450479238069,29.9600008875132,-0.179987824322848,-0.0266577916696384,1,-1.09834199326534E-6,,,,,,,,,,,,,,,,,,,,,102.686630249023,102.803909301758,9999.6064453125,9999.6064453125,46.9930698331973,5.26084150477759,15.4029502868652,27,1,0,0,1,0.276336669921875,37.6344108581543,2,1,1,102.803909301758,0,102.745269775391,,,,,,,,,,,,,,,,,,,,,,,,,,,,,,,,,
,3833438729.32062,105.555637359619,9999.6064453125,-0.000135435062380429,4.1767175899894E-8,1,2,13.4005146026611,4.99450673320171,29.9600008875132,-0.180194632124673,-0.0266821059173025,1,-1.0949527039731E-6,,,,,,,,,,,,,,,,,,,,,105.514053344727,105.597221374512,9999.6064453125,9999.6064453125,46.954770035755,5.26036737430968,15.415355682373,27,1,0,0,1,0.276412963867187,37.1456527709961,2,1,1,105.597221374512,0,105.555637359619,,,,,,,,,,,,,,,,,,,,,,,,,,,,,,,,,
,3833438783.86055,108.28494644165,9999.6064453125,-0.00013532445429607,3.39991948917102E-8,1,2,13.4005146026611,4.99447868565509,29.9699995666742,-0.180063617868872,-0.0265347105143167,1,-9.99913586903153E-7,,,,,,,,,,,,,,,,,,,,,108.219482421875,108.350410461426,9999.6064453125,9999.6064453125,46.9688393491011,5.26092985134488,15.4789514541626,27,1,0,0,1,0.2764892578125,37.1456527709961,2,1,1,108.350410461426,0,108.28494644165,,,,,,,,,,,,,,,,,,,,,,,,,,,,,,,,,
,3833438840.19699,111.074077606201,9999.6064453125,-0.000135435487986714,3.6393159152649E-8,1,2,13.4005146026611,4.9944377967965,29.9800001084805,-0.180205594058014,-0.0265829669107866,1,-1.02084149923886E-6,,,,,,,,,,,,,,,,,,,,,111.032844543457,111.115310668945,9999.6064453125,9999.6064453125,46.9016192964473,5.26054868007951,15.4808578491211,27,1,0,0,1,0.2850341796875,37.1456527709961,2,1,1,111.115310668945,0,111.074077606201,,,,,,,,,,,,,,,,,,,,,,,,,,,,,,,,,
,3833438897.74699,113.956764221191,9999.6064453125,-0.000135602316806001,4.11233414280182E-8,1,2,13.4005146026611,4.99441610347083,29.9800001084805,-0.180426980474885,-0.0266120944770154,1,-1.01950216626912E-6,,,,,,,,,,,,,,,,,,,,,113.871658325195,114.041870117187,9999.6064453125,9999.6064453125,46.9918973904184,5.26070961543018,15.4509916305542,27,1,0,0,1,0.285415649414062,37.1456527709961,2,1,1,114.041870117187,0,113.956764221191,,,,,,,,,,,,,,,,,,,,,,,,,,,,,,,,,
,3833438952.85704,116.712688446045,9999.6064453125,-0.000135575676715948,4.09791503811126E-8,1,2,13.4005146026611,4.99442635085575,29.9900006502867,-0.180388926260022,-0.0266292198124708,1,-1.03602807831833E-6,,,,,,,,,,,,,,,,,,,,,116.669830322266,116.755546569824,9999.6064453125,9999.6064453125,46.9633679494665,5.2607334682754,15.4667482376099,27,1,0,0,1,0.285797119140625,37.1456527709961,2,1,1,116.755546569824,0,116.712688446045,,,,,,,,,,,,,,,,,,,,,,,,,,,,,,,,,
,3833439009.27127,119.510040283203,9999.6064453125,-0.000135610045605253,3.41235280466946E-8,1,2,13.4005146026611,4.994401813296,29.9999993294477,-0.180428533109991,-0.0266708922150995,1,-1.06264377744237E-6,,,,,,,,,,,,,,,,,,,,,119.4580078125,119.562072753906,9999.6064453125,9999.6064453125,46.9106080244184,5.26107697538653,15.5100259780884,27,1,0,0,1,0.294036865234375,37.1456527709961,2,1,1,119.562072753906,0,119.510040283203,,,,,,,,,,,,,,,,,,,,,,,,,,,,,,,,,
,3833439065.70186,122.325878143311,9999.6064453125,-0.00013562935642129,2.69100468169662E-8,1,2,13.4005146026611,4.99437436003734,30.009999871254,-0.180454473451518,-0.026663000964233,1,-1.0541698895539E-6,,,,,,,,,,,,,,,,,,,,,122.266578674316,122.385177612305,9999.6064453125,9999.6064453125,46.9086539531203,5.26105722186034,15.5253353118896,27,1,0,0,1,0.284576416015625,37.1456527709961,2,1,1,122.385177612305,0,122.325878143311,,,,,,,,,,,,,,,,,,,,,,,,,,,,,,,,,
,3833439122.08958,125.132633209229,9999.6064453125,-0.000135796941033207,2.78132937759211E-8,1,2,13.4005146026611,4.99436618270904,30.009999871254,-0.180676153569282,-0.0267022188159476,1,-1.06022694475085E-6,,,,,,,,,,,,,,,,,,,,,125.085121154785,125.180145263672,9999.6064453125,9999.6064453125,46.9098263958992,5.26117195254739,15.5301780700684,27,1,0,0,1,0.284500122070313,37.1456527709961,2,1,1,125.180145263672,0,125.132633209229,,,,,,,,,,,,,,,,,,,,,,,,,,,,,,,,,
,3833439178.60677,127.925842285156,9999.6064453125,-0.00013578536716089,3.71567746297276E-8,1,2,13.4005146026611,4.99433123471032,30.0200004130602,-0.180654758283411,-0.0267301864538549,1,-1.08303525835911E-6,,,,,,,,,,,,,,,,,,,,,127.872489929199,127.979194641113,9999.6064453125,9999.6064453125,46.9164702383127,5.26105368031394,15.5944547653198,27,1,0,0,1,0.275955200195313,37.1456527709961,2,1,1,127.979194641113,0,127.925842285156,,,,,,,,,,,,,,,,,,,,,,,,,,,,,,,,,
,3833439235.17421,130.755493164062,9999.6064453125,-0.00013586968822054,3.29832966418104E-8,1,2,13.4005146026611,4.99431630812971,30.0299990922213,-0.180773126257792,-0.026697157809422,1,-1.04652981077318E-6,,,,,,,,,,,,,,,,,,,,,130.688247680664,130.822738647461,9999.6064453125,9999.6064453125,46.944608865005,5.26086447178144,15.6030759811401,27,1,0,0,1,0.284423828125,37.1456527709961,2,1,1,130.822738647461,0,130.755493164062,,,,,,,,,,,,,,,,,,,,,,,,,,,,,,,,,
,3833439293.68348,133.646453857422,9999.6064453125,-0.000135831827137687,2.97774776172609E-8,1,2,13.4005146026611,4.99431931142332,30.0399996340275,-0.180721572027541,-0.0266992479966958,1,-1.0533763978913E-6,,,,,,,,,,,,,,,,,,,,,133.60530090332,133.687606811523,9999.6064453125,9999.6064453125,46.9367925798127,5.26100001036163,15.6515083312988,27,1,0,0,1,0.276412963867187,37.1456527709961,2,1,1,133.687606811523,0,133.646453857422,,,,,,,,,,,,,,,,,,,,,,,,,,,,,,,,,
,3833439351.77567,136.602394104004,9999.6064453125,-0.00013601156324489,3.72689938785105E-8,1,2,13.4005146026611,4.99431658401251,30.0399996340275,-0.180956096946624,-0.0267665624778891,1,-1.07879968183545E-6,,,,,,,,,,,,,,,,,,,,,136.557952880859,136.646835327148,9999.6064453125,9999.6064453125,46.944608865005,5.2611374825626,15.6710681915283,27,1,0,0,1,0.285110473632813,36.6568908691406,2,1,1,136.646835327148,0,136.602394104004,,,,,,,,,,,,,,,,,,,,,,,,,,,,,,,,,
,3833439408.23245,139.36279296875,9999.6064453125,-0.000136093479358046,3.62211497056957E-8,1,2,13.4005146026611,4.99428845435094,30.0500001758337,-0.181069612383014,-0.0267400826187891,1,-1.04762003170279E-6,,,,,,,,,,,,,,,,,,,,,139.307983398438,139.417602539062,9999.6064453125,9999.6064453125,46.98017296263,5.26139140409213,15.7190275192261,27,1,0,0,1,0.284347534179687,37.1456527709961,2,1,1,139.417602539062,0,139.36279296875,,,,,,,,,,,,,,,,,,,,,,,,,,,,,,,,,
,3833439464.79441,142.186729431152,9999.6064453125,-0.000136125731540422,4.18295205179162E-8,1,2,13.4005146026611,4.99429102677282,30.0600007176399,-0.181109657450334,-0.0267678486980878,1,-1.06394305659603E-6,,,,,,,,,,,,,,,,,,,,,142.131958007812,142.241500854492,9999.6064453125,9999.6064453125,46.9977596043127,5.26177151786352,15.7863330841064,27,1,0,0,1,0.285263061523438,37.1456527709961,2,1,1,142.241500854492,0,142.186729431152,,,,,,,,,,,,,,,,,,,,,,,,,,,,,,,,,
,3833439521.41879,145.009399414062,9999.6064453125,-0.000136142021306419,3.5192185661364E-8,1,2,13.4005146026611,4.99427661233839,30.069999396801,-0.181129689746079,-0.0267775569985506,1,-1.06903387281541E-6,,,,,,,,,,,,,,,,,,,,,144.943054199219,145.075744628906,9999.6064453125,9999.6064453125,46.951643521678,5.26128820656943,15.842022895813,27,1,0,0,1,0.27618408203125,37.1456527709961,2,1,1,145.075744628906,0,145.009399414062,,,,,,,,,,,,,,,,,,,,,,,,,,,,,,,,,
,3833439581.48673,148.003364562988,9999.6064453125,-0.000136318515706608,4.33702050093656E-8,1,2,13.4005146026611,4.99422404169107,30.0799999386072,-0.181364705864618,-0.0267917504274563,1,-1.05530266658903E-6,,,,,,,,,,,,,,,,,,,,,147.948669433594,148.058059692383,9999.6064453125,9999.6064453125,47.0266798595242,5.26124142600421,15.8341054916382,27,1,0,0,1,0.285415649414062,37.6344108581543,2,1,1,148.058059692383,0,148.003364562988,,,,,,,,,,,,,,,,,,,,,,,,,,,,,,,,,
,3833439637.89744,150.799690246582,9999.6064453125,-0.0001363099255758,3.67598980547753E-8,1,2,13.4005146026611,4.9942015787652,30.0900004804134,-0.181353766834286,-0.026778402360222,1,-1.04660574549807E-6,,,,,,,,,,,,,,,,,,,,,150.75537109375,150.844009399414,9999.6064453125,9999.6064453125,46.9704026061396,5.26184336269529,15.8117294311523,27,1,0,0,1,0.293960571289063,37.1456527709961,2,1,1,150.85319519043,0,150.799690246582,,,,,,,,,,,,,,,,,,,,,,,,,,,,,,,,,
,3833439694.42688,153.665992736816,9999.6064453125,-0.00013636146823013,3.31212561550132E-8,1,2,13.4005146026611,4.99421422750532,30.0999991595745,-0.18141962147568,-0.0268125792035556,1,-1.06498968328636E-6,,,,,,,,,,,,,,,,,,,,,153.614379882813,153.71760559082,9999.6064453125,9999.6064453125,46.9375742083319,5.26162948102306,15.8745212554932,27,1,0,0,1,0.294876098632812,37.1456527709961,2,1,1,153.71760559082,0,153.665992736816,,,,,,,,,,,,,,,,,,,,,,,,,,,,,,,,,
,3833439750.95939,156.427383422852,9999.6064453125,-0.000136496974629681,3.05604335443239E-8,1,2,13.4005146026611,4.99423689294429,30.0999991595745,-0.181598822823835,-0.0268551948601248,1,-1.07791404890355E-6,,,,,,,,,,,,,,,,,,,,,156.371627807617,156.483139038086,9999.6064453125,9999.6064453125,47.0810030416108,5.26176862612975,15.8825569152832,27,1,0,0,1,0.292282104492188,37.1456527709961,2,1,1,156.483139038086,0,156.427383422852,,,,,,,,,,,,,,,,,,,,,,,,,,,,,,,,,
,3833439809.47152,159.337577819824,9999.6064453125,-0.000136576690849378,3.16320246708659E-8,1,2,13.4005146026611,4.99418250960466,30.1099997013807,-0.181708626454002,-0.026824290086563,1,-1.0438648322538E-6,,,,,,,,,,,,,,,,,,,,,159.314102172852,159.361053466797,9999.6064453125,9999.6064453125,46.9907249476396,5.26143637808534,15.9279527664185,27,1,0,0,1,0.28564453125,37.6344108581543,2,1,1,159.361053466797,0,159.337577819824,,,,,,,,,,,,,,,,,,,,,,,,,,,,,,,,,
,3833439864.81344,162.106224060059,9999.6064453125,-0.000136565514677441,2.4579997338569E-8,1,2,13.4005146026611,4.99419963354221,30.120000243187,-0.181686789171767,-0.0268781597389833,1,-1.08577919541391E-6,,,,,,,,,,,,,,,,,,,,,162.023468017578,162.188980102539,9999.6064453125,9999.6064453125,46.9907249476396,5.26231684177672,15.9077272415161,27,1,0,0,1,0.29388427734375,37.6344108581543,2,1,1,162.188980102539,0,162.106224060059,,,,,,,,,,,,,,,,,,,,,,,,,,,,,,,,,
,3833439922.00251,164.954193115234,9999.6064453125,-0.000136625154903207,3.08156289590947E-8,1,2,13.4005146026611,4.9941470179043,30.1300007849932,-0.181762439597513,-0.026897172067041,1,-1.09200648676644E-6,,,,,,,,,,,,,,,,,,,,,164.904754638672,165.003631591797,9999.6064453125,9999.6064453125,46.9149069812742,5.26238376990505,15.9092721939087,27,1,0,0,1,0.27618408203125,37.1456527709961,2,1,1,165.003631591797,0,164.954193115234,,,,,,,,,,,,,,,,,,,,,,,,,,,,,,,,,
,3833439980.52072,167.897850036621,9999.6064453125,-0.000136798713050722,4.01970184024245E-8,1,2,13.4005146026611,4.99417007670888,30.1399994641542,-0.181999633561031,-0.0268947092271949,1,-1.06576238060721E-6,,,,,,,,,,,,,,,,,,,,,167.838973999023,167.956726074219,9999.6064453125,9999.6064453125,46.9688393491011,5.26167715755307,15.8949975967407,27,1,0,0,1,0.295257568359375,37.1456527709961,2,1,1,167.956726074219,0,167.897850036621,,,,,,,,,,,,,,,,,,,,,,,,,,,,,,,,,
,3833440037.12591,170.737503051758,9999.6064453125,-0.000136783855377853,3.49676047253424E-8,1,2,13.4005146026611,4.99416392778057,30.1600005477667,-0.181979753851341,-0.0268903539881209,1,-1.06460384476623E-6,,,,,,,,,,,,,,,,,,,,,170.676605224609,170.798400878906,9999.6064453125,9999.6064453125,46.9367925798127,5.26228315285866,15.9168787002563,27,1,0,0,1,0.277175903320313,37.1456527709961,2,1,1,170.798400878906,0,170.737503051758,,,,,,,,,,,,,,,,,,,,,,,,,,,,,,,,,
,3833440095.24279,173.605880737305,9999.6064453125,-0.000137094297739819,6.28826744701448E-8,1,2,13.4005146026611,4.99412430819363,30.1699992269278,-0.182388513869477,-0.0269673674818817,1,-1.07924100991213E-6,,,,,,,,,,,,,,,,,,,,,173.553787231445,173.657974243164,9999.6064453125,9999.6064453125,47.0165186887742,5.26241806773817,15.9495754241943,27,1,0,0,1,0.293807983398438,37.1456527709961,2,1,1,173.657974243164,0,173.605880737305,,,,,,,,,,,,,,,,,,,,,,,,,,,,,,,,,
,3833440151.72654,176.422523498535,9999.6064453125,-0.000136916677718954,3.31858201222883E-8,1,2,13.4005146026611,4.99413653397258,30.179999768734,-0.182147737704002,-0.0269688769845415,1,-1.10514161784029E-6,,,,,,,,,,,,,,,,,,,,,176.369552612305,176.475494384766,9999.6064453125,9999.6064453125,46.9661036492838,5.26155499592833,15.9613418579102,27,1,0,0,1,0.29449462890625,37.1456527709961,2,1,1,176.475494384766,0,176.422523498535,,,,,,,,,,,,,,,,,,,,,,,,,,,,,,,,,
,3833440208.08564,179.252891540527,9999.6064453125,-0.000137066662151628,4.03671963529855E-8,1,2,13.4005146026611,4.9941363468155,30.1900003105402,-0.182354940921555,-0.0269434907105413,1,-1.06511077556511E-6,,,,,,,,,,,,,,,,,,,,,179.211578369141,179.294204711914,9999.6064453125,9999.6064453125,46.956724107053,5.26165099032342,15.9858236312866,27,1,0,0,1,0.293807983398438,37.1456527709961,2,1,1,179.294204711914,0,179.252891540527,,,,,,,,,,,,,,,,,,,,,,,,,,,,,,,,,
,3833440266.69342,182.168647766113,9999.6064453125,-0.000137177428379113,4.75309724201868E-8,1,2,13.4005146026611,4.99412778120075,30.2000008523464,-0.182501760069318,-0.0269660346005787,1,-1.06659747862782E-6,,,,,,,,,,,,,,,,,,,,,182.103378295898,182.233917236328,9999.6064453125,9999.6064453125,46.8828602119857,5.26213490428572,16.0017414093018,27,1,0,0,1,0.295181274414063,37.1456527709961,2,1,1,182.233917236328,0,182.168647766113,,,,,,,,,,,,,,,,,,,,,,,,,,,,,,,,,
,3833440322.99199,184.972946166992,9999.6064453125,-0.000137185615881108,5.24833069095744E-8,1,2,13.4005146026611,4.99408630131298,30.2099995315075,-0.182508880742899,-0.0269794609963876,1,-1.0757641790747E-6,,,,,,,,,,,,,,,,,,,,,184.931793212891,185.014099121094,9999.6064453125,9999.6064453125,47.0173003172934,5.26233633653733,16.0135822296143,27,1,0,0,1,0.294570922851562,37.1456527709961,2,1,1,185.014099121094,0,184.972946166992,,,,,,,,,,,,,,,,,,,,,,,,,,,,,,,,,
,3833440379.55275,187.816635131836,9999.6064453125,-0.000137314736909141,5.33386523944015E-8,1,2,13.4005146026611,4.99404734629225,30.2200000733137,-0.182676253784846,-0.0270221211191849,1,-1.08995806610845E-6,,,,,,,,,,,,,,,,,,,,,187.777587890625,187.855682373047,9999.6064453125,9999.6064453125,46.9235048949857,5.26171892877494,16.0484085083008,27,1,0,0,1,0.285415649414062,37.1456527709961,2,1,1,187.855682373047,0,187.816635131836,,,,,,,,,,,,,,,,,,,,,,,,,,,,,,,,,
,3833440437.7487,190.699783325195,9999.6064453125,-0.000137259278043296,5.87574646351622E-8,1,2,13.4005146026611,4.99408167693961,30.2300006151199,-0.182606277777441,-0.0269965590068595,1,-1.07832821628243E-6,,,,,,,,,,,,,,,,,,,,,190.654907226562,190.744659423828,9999.6064453125,9999.6064453125,47.0286339308223,5.26199889186156,16.0502643585205,27,1,0,0,1,0.27435302734375,37.1456527709961,2,1,1,190.744659423828,0,190.699783325195,,,,,,,,,,,,,,,,,,,,,,,,,,,,,,,,,
,3833440494.3307,193.515434265137,9999.6064453125,-0.000137420183460326,6.23193998292667E-8,1,2,13.4005146026611,4.99406617471157,30.239999294281,-0.182808118613094,-0.0271099539695173,1,-1.14105843861779E-6,,,,,,,,,,,,,,,,,,,,,193.464080810547,193.566787719727,9999.6064453125,9999.6064453125,46.9332752514761,5.26269238260531,16.0773639678955,25,1,64,0,0,0.275955200195313,37.1456527709961,2,1,1,193.566787719727,0,193.515434265137,,,,,,,,,,,,,,,,,,,,,,,,,,,,,,,,,
,3833440550.58396,196.331344604492,9999.6064453125,-0.000137448921047111,4.72669334395623E-8,1,2,13.4005146026611,4.99405227191084,30.2499998360872,-0.182851714953308,-0.0270721465600669,1,-1.10873030854071E-6,,,,,,,,,,,,,,,,,,,,,196.286590576172,196.376098632813,9999.6064453125,9999.6064453125,47.0493470865819,5.2625711026375,16.079870223999,27,1,0,0,1,0.286026000976562,37.1456527709961,2,1,1,196.376098632813,0,196.331344604492,,,,,,,,,,,,,,,,,,,,,,,,,,,,,,,,,
,3833440607.14113,199.155853271484,9999.6064453125,-0.000137607263486486,3.97524383390267E-8,1,2,13.4005146026611,4.99407675986113,30.2600003778934,-0.183067746170045,-0.027073803024377,1,-1.08769778481906E-6,,,,,,,,,,,,,,,,,,,,,199.075057983398,199.23664855957,9999.6064453125,9999.6064453125,46.9715750489184,5.2624600716166,16.087516784668,27,1,0,0,1,0.285797119140625,37.1456527709961,2,1,1,199.23664855957,0,199.155853271484,,,,,,,,,,,,,,,,,,,,,,,,,,,,,,,,,
,3833440661.41354,201.86784362793,9999.6064453125,-0.000137433176890517,3.0024916475135E-8,1,2,13.4005146026611,4.99403443306174,30.2700009196997,-0.182836644375703,-0.0270205012845072,1,-1.07225320662043E-6,,,,,,,,,,,,,,,,,,,,,201.815444946289,201.92024230957,9999.6064453125,9999.6064453125,47.0102656606204,5.26237706763648,16.1187934875488,27,1,0,0,1,0.294876098632812,37.6344108581543,2,1,1,201.92024230957,0,201.86784362793,,,,,,,,,,,,,,,,,,,,,,,,,,,,,,,,,
,3833440719.99983,204.773567199707,9999.6064453125,-0.00013740842367161,3.32548985231695E-8,1,2,13.4005146026611,4.99400753464,30.290000140667,-0.182798274793376,-0.0270446848212623,1,-1.09402235076558E-6,,,,,,,,,,,,,,,,,,,,,204.740417480469,204.806716918945,9999.6064453125,9999.6064453125,47.0231625311877,5.26242643686136,16.1429767608643,27,1,0,0,1,0.276336669921875,37.1456527709961,2,1,1,204.806716918945,0,204.773567199707,,,,,,,,,,,,,,,,,,,,,,,,,,,,,,,,,
,3833440777.58843,207.644866943359,9999.6064453125,-0.000137531699054944,3.4154890327493E-8,1,2,13.4005146026611,4.99398342622001,30.3000006824732,-0.182964695044042,-0.0270427809292877,1,-1.07549052337979E-6,,,,,,,,,,,,,,,,,,,,,207.563491821289,207.72624206543,9999.6064453125,9999.6064453125,46.9539884072357,5.26234615547308,16.1893939971924,27,1,0,0,1,0.276336669921875,37.6344108581543,2,1,1,207.72624206543,0,207.644866943359,,,,,,,,,,,,,,,,,,,,,,,,,,,,,,,,,
,3833440832.6584,210.37744140625,9999.6064453125,-0.000137579665860661,3.8502474915366E-8,1,2,13.4005146026611,4.99400144788141,30.3099993616343,-0.183026365735602,-0.0270741360037206,1,-1.09222656115538E-6,,,,,,,,,,,,,,,,,,,,,210.326721191406,210.428161621094,9999.6064453125,9999.6064453125,47.0059667037646,5.26274189919765,16.2219791412354,27,1,0,0,1,0.285873413085938,37.6344108581543,2,1,1,210.428161621094,0,210.37744140625,,,,,,,,,,,,,,,,,,,,,,,,,,,,,,,,,
,3833440889.06653,213.208717346191,9999.6064453125,-0.000137522766106708,2.80230880785614E-8,1,2,13.4005146026611,4.99404779165686,30.3300004452467,-0.182956727554952,-0.027036597367351,1,-1.07173806644328E-6,,,,,,,,,,,,,,,,,,,,,213.159484863281,213.257949829102,9999.6064453125,9999.6064453125,47.0387951015723,5.26153578893683,16.249475479126,27,1,0,0,1,0.278091430664062,37.6344108581543,2,1,1,213.257949829102,0,213.208717346191,,,,,,,,,,,,,,,,,,,,,,,,,,,,,,,,,
,3833440947.57912,216.139785766602,9999.6064453125,-0.000137642363407611,3.00584490414231E-8,1,2,13.4005146026611,4.99394974805107,30.3399991244078,-0.183108088872227,-0.0270795683764819,1,-1.08782742555625E-6,,,,,,,,,,,,,,,,,,,,,216.093109130859,216.186462402344,9999.6064453125,9999.6064453125,47.0028401896877,5.26292289586585,16.2474746704102,27,1,0,0,1,0.294570922851562,37.6344108581543,2,1,1,216.186462402344,0,216.139785766602,,,,,,,,,,,,,,,,,,,,,,,,,,,,,,,,,
,3833441004.19062,218.919845581055,9999.6064453125,-0.000137612976345767,2.64832752833253E-8,1,2,13.4005146026611,4.99392540011983,30.349999666214,-0.183063969376131,-0.0271008012181725,1,-1.10801539679145E-6,,,,,,,,,,,,,,,,,,,,,218.864135742187,218.975555419922,9999.6064453125,9999.6064453125,46.9840811052261,5.26269350202907,16.2380924224854,27,1,0,0,1,0.295028686523438,37.6344108581543,2,1,1,218.975555419922,0,218.919845581055,,,,,,,,,,,,,,,,,,,,,,,,,,,,,,,,,
,3833441060.52716,221.764923095703,9999.6064453125,-0.000137720916443009,2.92570559125217E-8,1,2,13.4005146026611,4.99391679472126,30.3600002080202,-0.183209192666834,-0.0271072245893682,1,-1.09779422633719E-6,,,,,,,,,,,,,,,,,,,,,221.727035522461,221.802810668945,9999.6064453125,9999.6064453125,47.0579450002934,5.26281453574433,16.2285785675049,27,1,0,0,1,0.27435302734375,37.6344108581543,2,1,1,221.802810668945,0,221.764923095703,,,,,,,,,,,,,,,,,,,,,,,,,,,,,,,,,
,3833441117.11626,224.58667755127,9999.6064453125,-0.00013772497083026,3.26341559562209E-8,1,2,13.4005146026611,4.99385268405354,30.3799994289875,-0.183230228289807,-0.0269726263756815,1,-9.96516979427866E-7,,,,,,,,,,,,,,,,,,,,,224.554489135742,224.618865966797,9999.6064453125,9999.6064453125,47.0040126324665,5.2628215121823,16.2527236938477,27,1,0,0,1,0.2947998046875,37.6344108581543,2,1,1,224.618865966797,0,224.58667755127,,,,,,,,,,,,,,,,,,,,,,,,,,,,,,,,,
,3833441171.35569,227.294975280762,9999.6064453125,-0.000137803528773177,2.76441777953294E-8,1,2,13.4005146026611,4.99387649131447,30.3899999707937,-0.183321169087964,-0.0270938273924409,1,-1.07640854740955E-6,,,,,,,,,,,,,,,,,,,,,227.260269165039,227.329681396484,9999.6064453125,9999.6064453125,47.0489562723223,5.26262569426886,16.2604866027832,27,1,0,0,1,0.28564453125,37.6344108581543,2,1,1,227.329681396484,0,227.294975280762,,,,,,,,,,,,,,,,,,,,,,,,,,,,,,,,,
,3833441230.15408,230.228706359863,9999.6064453125,-0.000137788142511705,3.63964764960111E-8,1,2,13.4005146026611,4.99394202933343,30.409999191761,-0.183299390390758,-0.0271242321731284,1,-1.10102414827499E-6,,,,,,,,,,,,,,,,,,,,,230.214202880859,230.243209838867,9999.6064453125,9999.6064453125,47.0434848726877,5.26106654992392,16.2661743164062,25,1,64,0,0,0.277633666992187,37.6344108581543,2,1,1,230.243209838867,0,230.228706359863,,,,,,,,,,,,,,,,,,,,,,,,,,,,,,,,,
,3833441285.982,233.011871337891,9999.6064453125,-0.00013786993112376,2.96543000760471E-8,1,2,13.4005146026611,4.99386900535253,30.4199997335672,-0.183401536439929,-0.0271611217154362,1,-1.11769620797552E-6,,,,,,,,,,,,,,,,,,,,,232.958404541016,233.065338134766,9999.6064453125,9999.6064453125,47.012610546178,5.26258793633807,16.2576522827148,27,1,0,0,1,0.29541015625,37.6344108581543,2,1,1,233.065338134766,0,233.011871337891,,,,,,,,,,,,,,,,,,,,,,,,,,,,,,,,,
,3833441342.42678,235.807250976562,9999.6064453125,-0.000137967093150484,3.4933821435032E-8,1,2,13.4005146026611,4.99387320614327,30.4300002753735,-0.183544160459984,-0.0270861555472815,1,-1.04779635673945E-6,,,,,,,,,,,,,,,,,,,,,235.757064819336,235.857437133789,9999.6064453125,9999.6064453125,46.9895525048607,5.26245507446618,16.2769317626953,27,1,0,0,1,0.295028686523438,37.6344108581543,2,1,1,235.857437133789,0,235.807250976562,,,,,,,,,,,,,,,,,,,,,,,,,,,,,,,,,
,3833441401.00531,238.732231140137,9999.6064453125,-0.000138074288398125,2.86069447374265E-8,1,2,13.4005146026611,4.9938799777326,30.4400008171797,-0.183694836062956,-0.0270519845528882,1,-1.00711190183582E-6,,,,,,,,,,,,,,,,,,,,,238.685440063477,238.779022216797,9999.6064453125,9999.6064453125,47.03097881638,5.26294066230978,16.2937812805176,27,1,0,0,1,0.285873413085938,37.6344108581543,2,1,1,238.779022216797,0,238.732231140137,,,,,,,,,,,,,,,,,,,,,,,,,,,,,,,,,
,3833441457.51766,241.570762634277,9999.6064453125,-0.000138050316234033,2.81133966081262E-8,1,2,13.4005146026611,4.99384097098731,30.460000038147,-0.183656970954924,-0.0270756554440646,1,-1.02845539618662E-6,,,,,,,,,,,,,,,,,,,,,241.539154052734,241.60237121582,9999.6064453125,9999.6064453125,47.0520827863992,5.26237651139088,16.3096027374268,27,1,0,0,1,0.286026000976562,37.1456527709961,2,1,1,241.60237121582,0,241.570762634277,,,,,,,,,,,,,,,,,,,,,,,,,,,,,,,,,
,3833441513.65202,244.373069763184,9999.6064453125,-0.000138094955275841,2.87787851470488E-8,1,2,13.4005146026611,4.99385884573735,30.4799992591143,-0.183701149820626,-0.0271997486432863,1,-1.11529429412261E-6,,,,,,,,,,,,,,,,,,,,,244.312072753906,244.434066772461,9999.6064453125,9999.6064453125,47.0610715143704,5.26239608057158,16.3325233459473,27,1,0,0,1,0.286788940429687,37.1456527709961,2,1,1,244.434066772461,0,244.373069763184,,,,,,,,,,,,,,,,,,,,,,,,,,,,,,,,,
,3833441570.06054,247.176628112793,9999.6064453125,-0.000138146311398916,2.222079063566E-8,1,2,13.4005146026611,4.9938448621716,30.4899998009205,-0.18377374861019,-0.0271740911604098,1,-1.08892597672753E-6,,,,,,,,,,,,,,,,,,,,,247.12890625,247.224349975586,9999.6064453125,9999.6064453125,46.9817362196684,5.26256297403552,16.3533172607422,27,1,0,0,1,0.283737182617187,37.1456527709961,2,1,1,247.224349975586,0,247.176628112793,,,,,,,,,,,,,,,,,,,,,,,,,,,,,,,,,
,3833441626.49049,249.980918884277,9999.6064453125,-0.000138227507782549,3.21957677456208E-8,1,2,13.4005146026611,4.99382098177123,30.5000003427267,-0.183886110668905,-0.027150172617197,1,-1.05974631185876E-6,,,,,,,,,,,,,,,,,,,,,249.919021606445,250.042816162109,9999.6064453125,9999.6064453125,47.0059667037646,5.26239179756073,16.3712749481201,27,1,0,0,1,0.29541015625,37.1456527709961,2,1,1,250.042816162109,0,249.980918884277,,,,,,,,,,,,,,,,,,,,,,,,,,,,,,,,,
,3833441682.93693,252.786956787109,9999.6064453125,-0.000138275553523236,4.16238745352967E-8,1,2,13.4005146026611,4.99382929948669,30.519999563694,-0.183949541682061,-0.0271661422304491,1,-1.06497343962743E-6,,,,,,,,,,,,,,,,,,,,,252.738098144531,252.835815429687,9999.6064453125,9999.6064453125,47.02081764563,5.26217526369085,16.3627147674561,27,1,0,0,1,0.27435302734375,37.1456527709961,2,1,1,252.835815429687,0,252.786956787109,,,,,,,,,,,,,,,,,,,,,,,,,,,,,,,,,
,3833441739.47025,255.602142333984,9999.6064453125,-0.00013835968378478,4.36329053263421E-8,1,2,13.4005146026611,4.99382422006569,30.5300001055002,-0.184060658154806,-0.027186541183777,1,-1.06855610719622E-6,,,,,,,,,,,,,,,,,,,,,255.547485351562,255.656799316406,9999.6064453125,9999.6064453125,46.9426547937069,5.26166178573322,16.3852424621582,27,1,0,0,1,0.28564453125,37.1456527709961,2,1,1,255.656799316406,0,255.602142333984,,,,,,,,,,,,,,,,,,,,,,,,,,,,,,,,,
,3833441793.75513,258.336456298828,9999.6064453125,-0.000138383507666758,4.5869910232008E-8,1,2,13.4005146026611,4.99379302126743,30.5499993264675,-0.184088289201593,-0.027208770866135,1,-1.08209206040758E-6,,,,,,,,,,,,,,,,,,,,,258.282653808594,258.390258789062,9999.6064453125,9999.6064453125,47.0016677469088,5.26218956278585,16.4143829345703,27,1,0,0,1,0.286102294921875,37.1456527709961,2,1,1,258.390258789062,0,258.336456298828,,,,,,,,,,,,,,,,,,,,,,,,,,,,,,,,,
,3833441852.3062,261.217651367187,9999.6064453125,-0.000138391600185784,3.39860637750448E-8,1,2,13.4005146026611,4.99383622612049,30.57000041008,-0.184099089006126,-0.027226045362305,1,-1.09368965944018E-6,,,,,,,,,,,,,,,,,,,,,261.175415039062,261.259887695313,9999.6064453125,9999.6064453125,47.0595082573319,5.26178542112583,16.4727115631104,27,1,0,0,1,0.28594970703125,37.1456527709961,2,1,1,261.259887695313,0,261.217651367187,,,,,,,,,,,,,,,,,,,,,,,,,,,,,,,,,
,3833441909.99176,264.12336730957,9999.6064453125,-0.000138463853077091,3.13441447932089E-8,1,2,13.4005146026611,4.99379804681803,30.579999089241,-0.184197198981599,-0.0272119166759743,1,-1.07319204648014E-6,,,,,,,,,,,,,,,,,,,,,264.044281005859,264.202453613281,9999.6064453125,9999.6064453125,46.9950239044954,5.26209978052942,16.5376873016357,27,1,0,0,1,0.286178588867187,37.1456527709961,2,1,1,264.202453613281,0,264.12336730957,,,,,,,,,,,,,,,,,,,,,,,,,,,,,,,,,
,3833441969.0962,267.039703369141,9999.6064453125,-0.000138517687733586,4.86717074487635E-8,1,2,13.4005146026611,4.99383187413911,30.6000001728535,-0.184272731003204,-0.0272069715987329,1,-1.06176192334736E-6,,,,,,,,,,,,,,,,,,,,,266.992309570313,267.087097167969,9999.6064453125,9999.6064453125,46.9840811052261,5.26183980940287,16.6337471008301,27,1,0,0,1,0.285568237304687,37.1456527709961,2,1,1,267.087097167969,0,267.039703369141,,,,,,,,,,,,,,,,,,,,,,,,,,,,,,,,,
,3833442025.6802,269.894912719727,9999.6064453125,-0.000138669862441884,3.69436533231989E-8,1,2,13.4005146026611,4.99382772294916,30.6100007146597,-0.184475782677242,-0.0272309592962162,1,-1.05852009289078E-6,,,,,,,,,,,,,,,,,,,,,269.836456298828,269.953369140625,9999.6064453125,9999.6064453125,47.0669337282646,5.2617998998875,16.7613315582275,27,1,0,0,1,0.277175903320313,37.1456527709961,2,1,1,269.953369140625,0,269.894912719727,,,,,,,,,,,,,,,,,,,,,,,,,,,,,,,,,
,3833442081.933,272.674728393555,9999.6064453125,-0.000138694708850681,3.47854276301405E-8,1,2,13.4005146026611,4.99377231337445,30.629999935627,-0.18450704611004,-0.027228167764497,1,-1.0532607031661E-6,,,,,,,,,,,,,,,,,,,,,272.630645751953,272.718811035156,9999.6064453125,9999.6064453125,47.0419216156492,5.26295040502935,16.842493057251,27,1,0,0,1,0.283432006835938,37.1456527709961,2,1,1,272.718811035156,0,272.674728393555,,,,,,,,,,,,,,,,,,,,,,,,,,,,,,,,,
,3833442136.47998,275.365417480469,9999.6064453125,-0.000138762666631857,3.24919684692168E-8,1,2,13.4005146026611,4.99374641906848,30.6499991565943,-0.18459297969128,-0.0272639149456041,1,-1.07074695097348E-6,,,,,,,,,,,,,,,,,,,,,275.302703857422,275.428131103516,9999.6064453125,9999.6064453125,46.956724107053,5.26258803066864,16.7731246948242,27,1,0,0,1,0.275955200195313,37.1456527709961,2,1,1,275.428131103516,0,275.365417480469,,,,,,,,,,,,,,,,,,,,,,,,,,,,,,,,,
,3833442192.82122,278.194961547852,9999.6064453125,-0.000138898821641292,4.0335673142662E-8,1,2,13.4005146026611,4.99376560156794,30.6599996984005,-0.184772459844905,-0.0273095225574277,1,-1.08584886407012E-6,,,,,,,,,,,,,,,,,,,,,278.1513671875,278.238555908203,9999.6064453125,9999.6064453125,46.9590689926107,5.26265120063535,16.7709407806396,27,1,0,0,1,0.286407470703125,37.1456527709961,2,1,1,278.238555908203,0,278.194961547852,,,,,,,,,,,,,,,,,,,,,,,,,,,,,,,,,
,3833442247.43567,280.94905090332,9999.6064453125,-0.000138973245565695,3.05148533003805E-8,1,2,13.4005146026611,4.99375665047707,30.6800007820129,-0.184878604612904,-0.0272697681414492,1,-1.04564118994133E-6,,,,,,,,,,,,,,,,,,,,,280.881561279297,281.016540527344,9999.6064453125,9999.6064453125,47.0438756869473,5.26243093654146,16.7839279174805,27,1,0,0,1,0.286483764648438,37.1456527709961,2,1,1,281.016540527344,0,280.94905090332,,,,,,,,,,,,,,,,,,,,,,,,,,,,,,,,,
,3833442305.46492,283.859222412109,9999.6064453125,-0.000139169272791121,3.41040052820773E-8,1,2,13.4005146026611,4.99376516456807,30.689999461174,-0.185133514176,-0.0273533648485476,1,-1.08095788017286E-6,,,,,,,,,,,,,,,,,,,,,283.814331054687,283.904113769531,9999.6064453125,9999.6064453125,47.0270706737838,5.26241781847766,16.8073310852051,27,1,0,0,1,0.286331176757813,37.1456527709961,2,1,1,283.904113769531,0,283.859222412109,,,,,,,,,,,,,,,,,,,,,,,,,,,,,,,,,
,3833442363.88947,286.645797729492,9999.6064453125,-0.000139232554967357,3.98607801827039E-8,1,2,13.4005146026611,4.99375393703289,30.7100005447865,-0.18522271942103,-0.0273257171433739,1,-1.05141199913469E-6,,,,,,,,,,,,,,,,,,,,,286.594268798828,286.697326660156,9999.6064453125,9999.6064453125,46.9774372628127,5.26257012748974,16.8407974243164,27,1,0,0,1,0.28411865234375,37.1456527709961,2,1,1,286.697326660156,0,286.645797729492,,,,,,,,,,,,,,,,,,,,,,,,,,,,,,,,,
,3833442422.54381,289.516494750977,9999.6064453125,-0.000139352484349461,3.73536080137285E-8,1,2,13.4005146026611,4.99373346673165,30.7299997657537,-0.185381406262731,-0.0273477809314862,1,-1.05132651833603E-6,,,,,,,,,,,,,,,,,,,,,289.471740722656,289.561248779297,9999.6064453125,9999.6064453125,47.0419216156492,5.26252548728602,16.8995418548584,25,1,64,0,0,0.286102294921875,37.1456527709961,2,1,1,289.561248779297,0,289.516494750977,,,,,,,,,,,,,,,,,,,,,,,,,,,,,,,,,
,3833442480.09172,292.52116394043,9999.6064453125,-0.000139519926238518,4.33430715949014E-8,1,2,13.4005146026611,4.99372897398583,30.7500008493662,-0.185604676890286,-0.0273752398083391,1,-1.04855909907616E-6,,,,,,,,,,,,,,,,,,,,,292.433746337891,292.608581542969,9999.6064453125,9999.6064453125,47.0559909289954,5.26286057237797,16.965991973877,27,1,0,0,1,0.285568237304687,37.1456527709961,2,1,1,292.608581542969,0,292.52116394043,,,,,,,,,,,,,,,,,,,,,,,,,,,,,,,,,
,3833442537.19366,295.45881652832,9999.6064453125,-0.000139672148785693,2.87335827163517E-8,1,2,13.4005146026611,4.99373950347958,30.7599995285273,-0.185801499299719,-0.0274496538096079,1,-1.08309411321036E-6,,,,,,,,,,,,,,,,,,,,,295.406982421875,295.510650634766,9999.6064453125,9999.6064453125,47.0051850752454,5.2633370512628,17.0663166046143,27,1,0,0,1,0.275726318359375,37.6344108581543,2,1,1,295.510650634766,0,295.45881652832,,,,,,,,,,,,,,,,,,,,,,,,,,,,,,,,,
,3833442593.58542,298.319625854492,9999.6064453125,-0.00013978930234137,2.74176457736478E-8,1,2,13.4005146026611,4.9937273358388,30.7800006121397,-0.185956997389729,-0.0274706324009677,1,-1.08253545860251E-6,,,,,,,,,,,,,,,,,,,,,298.275299072266,298.363952636719,9999.6064453125,9999.6064453125,47.0649796569665,5.26319332789775,17.1980266571045,27,1,0,0,1,0.28656005859375,37.6344108581543,2,1,1,298.363952636719,0,298.319625854492,,,,,,,,,,,,,,,,,,,,,,,,,,,,,,,,,
,3833442647.99958,299.743682861328,9999.6064453125,-0.000139873289190467,3.16989231880589E-8,1,2,13.4005146026611,4.99372247568607,30.7899992913008,-0.186067288859185,-0.0274955774950385,1,-1.08955145628556E-6,,,,,,,,,,,,,,,,,,,,,299.737030029297,299.750335693359,9999.6064453125,9999.6064453125,47.1048427114473,5.26300548156353,17.3340110778809,27,1,0,0,1,0.276565551757813,37.1456527709961,5,1,1,299.750335693359,0,299.743682861328,,,,,,,,,,,,,,,,,,,,,,,,,,,,,,,,,
,3833442688.5384,299.899703979492,9999.6064453125,-0.000139978869800136,3.75464067679405E-8,1,2,13.4005146026611,4.99375623297048,30.7899992913008,-0.186214371158458,-0.0274814822464094,1,-1.06401351004802E-6,,,,,,,,,,,,,,,,,,,,,299.897247314453,299.902160644531,9999.6064453125,9999.6064453125,47.1642464789088,5.26303504676185,17.4237213134766,27,1,0,0,1,0.275115966796875,37.6344108581543,1,1,1,299.902160644531,0,299.899703979492,,,,,,,,,,,,,,,,,,,,,,,,,,,,,,,,,