File: Main text Fig 3bcd SQUID/Michaela_Y_FC1T.dat
[Header]
; MPMS3 Data File (default extension .dat)
; Copyright (c) 2007, Quantum Design, Inc. All rights reserved.
TITLE,
FILEOPENTIME,3833442697.39187,06/21/2021,1:12 pm
BYAPP,MPMS3 w/ AC,1.0,1.1
INFO,MPMS3 Measurement Release 1.1.16 Build 424, MultiVu Release 2.3.4.19,APPNAME
INFO,Linear Motor Servo Controller,MOTOR_MODULE_NAME
INFO,3101-100 E1,MOTOR_HW_VERSION
INFO,MMC211,MOTOR_SERIAL_NUMBER
INFO,01.04.28,MOTOR_SOFTWARE_VERSION
INFO,Quantum Design Squid Module,SQUID_MODULE_NAME
INFO,3101-501 B0,SQUID_HW_VERSION
INFO,SQM059,SQUID_SERIAL_NUMBER
INFO,01.03.04,SQUID_SOFTWARE_VERSION
INFO,SQUID AC,AC_MODULE_NAME
INFO,3101-401 F1,AC_HW_VERSION
INFO,SAC057,AC_SERIAL_NUMBER
INFO,SQUID AC 00.95.07,AC_SOFTWARE_VERSION
INFO,TCIXXX,COIL_SERIAL_NUMBER
INFO,0,MOMENT_UNITS
INFO,Michaela_Y,SAMPLE_MATERIAL
INFO,Michaela_Y,SAMPLE_COMMENT
INFO,1.14,SAMPLE_MASS
INFO,,SAMPLE_VOLUME
INFO,,SAMPLE_MOLECULAR_WEIGHT
INFO,,SAMPLE_SIZE
INFO,,SAMPLE_SHAPE
INFO,Straw,SAMPLE_HOLDER
INFO,Standard,SAMPLE_HOLDER_DETAIL
INFO,56.41,SAMPLE_OFFSET
DATATYPE,COMMENT,1
DATATYPE,TIME,2
STARTUPAXIS,X,2
STARTUPAXIS,Y1,5
FIELDGROUP, VSM,2,3,4,5,6,8,9,10,11,14,15
FIELDGROUP, DC, 2,3,4,14,56,57,58,59,60,61,62,63,64,65,66,67,68,69
FIELDGROUP, AC, 2,3,4,11,16,17,18,19,20,21,22,23,24,25,26,27,28,29,30
STARTUPGROUP, All
[Data]
Comment,Time Stamp (sec),Temperature (K),Magnetic Field (Oe),Moment (emu),M. Std. Err. (emu),Transport Action,Averaging Time (sec),Frequency (Hz),Peak Amplitude (mm),Center Position (mm),Lockin Signal' (V),Lockin Signal (V),Range,M. Quad. Signal (emu),AC Moment (emu),AC M. Std Err. (emu),AC Phase (deg),AC Phase Std. Err. (deg),AC Susceptibility (emu/Oe),AC Suscept. Std Err. (emu/Oe),AC X' (emu/Oe),AC X' Std Err. (emu/Oe),AC X'' (emu/Oe),AC X'' Std Err. (emu/Oe),AC Drive (Oe),AC Frequency (Hz),AC Averaging Time (sec),AC Cycles,AC Range,AC Measure Type,AC Signal' (V),AC Signal'' (V),AC Trim Coil Ratio,AC Trim Coil Phase,Min. Temperature (K),Max. Temperature (K),Min. Field (Oe),Max. Field (Oe),Mass (grams),Motor Lag (deg),Pressure (Torr),Measure Count,Measurement Number,SQUID Status (code),Motor Status (code),Measure Status (code),Motor Current (amps),Motor Temp. (C),Temp. Status (code),Field Status (code),Chamber Status (code),Chamber Temp (K),Redirection State,Average Temp (K),Rotation Angle (deg),Rotator state,DC Moment Fixed Ctr (emu),DC Moment Err Fixed Ctr (emu),DC Moment Free Ctr (emu),DC Moment Err Free Ctr (emu),DC Fixed Fit,DC Free Fit,DC Calculated Center (mm),DC Calculated Center Err (mm),DC Scan Length (mm),DC Scan Time (s),DC Number of Points,DC Squid Drift,DC Min V (V),DC Max V (V),DC Scans per Measure,Map 01,Map 02,Map 03,Map 04,Map 05,Map 06,Map 07,Map 08,Map 09,Map 10,Map 11,Map 12,Map 13,Map 14,Map 15,Map 16
,3833442705.37833,299.928955078125,9999.6064453125,-0.000139992470873004,3.42826600945055E-8,1,2,13.4005146026611,4.99374856720583,30.7899992913008,-0.186236228740613,-0.0274543731061025,1,-1.04179864008141E-6,,,,,,,,,,,,,,,,,,,,,299.928955078125,299.928955078125,9999.6064453125,9999.6064453125,47.0899917695819,5.26321346751705,17.4517822265625,27,1,0,0,1,0.295867919921875,37.6344108581543,1,1,1,299.928955078125,0,299.928955078125,,,,,,,,,,,,,,,,,,,,,,,,,,,,,,,,,
,3833442763.25522,297.851837158203,9999.6064453125,-0.000139901062520689,2.62347216526706E-8,1,2,13.4005146026611,4.99372382257121,30.7899992913008,-0.186109427009201,-0.0274644024261262,1,-1.06225065504917E-6,,,,,,,,,,,,,,,,,,,,,297.773162841797,297.930511474609,9999.6064453125,9999.6064453125,47.0673245425242,5.26311359829593,17.3878498077393,27,1,0,0,1,0.285720825195313,37.6344108581543,2,1,1,297.773162841797,0,297.851837158203,,,,,,,,,,,,,,,,,,,,,,,,,,,,,,,,,
,3833442821.2581,294.845275878906,9999.6064453125,-0.000139794300824905,3.13556317104368E-8,1,2,13.4005146026611,4.99373365451305,30.7700000703335,-0.185970914661651,-0.0274219879144069,1,-1.04527297757648E-6,,,,,,,,,,,,,,,,,,,,,294.778930664063,294.91162109375,9999.6064453125,9999.6064453125,47.0489562723223,5.26308569406785,17.3097286224365,27,1,0,0,1,0.2838134765625,37.6344108581543,2,1,1,294.778930664063,0,294.845275878906,,,,,,,,,,,,,,,,,,,,,,,,,,,,,,,,,
,3833442877.69049,291.983840942383,9999.6064453125,-0.000139768119080587,3.10517618627229E-8,1,2,13.4005146026611,4.99369639828916,30.7500008493662,-0.185937045929904,-0.0273961031258441,1,-1.02970679775294E-6,,,,,,,,,,,,,,,,,,,,,291.928527832031,292.039154052734,9999.6064453125,9999.6064453125,47.0892101410627,5.26321675560934,17.2470035552979,27,1,0,0,1,0.275726318359375,37.6344108581543,2,1,1,291.928527832031,0,291.983840942383,,,,,,,,,,,,,,,,,,,,,,,,,,,,,,,,,
,3833442934.09554,289.202545166016,9999.6064453125,-0.000139647349199991,3.05248401709857E-8,1,2,13.4005146026611,4.99362689986101,30.74000030756,-0.185757256581253,-0.0274833624256127,1,-1.11251148790985E-6,,,,,,,,,,,,,,,,,,,,,289.143402099609,289.261688232422,9999.6064453125,9999.6064453125,47.0528644149184,5.26297017042571,17.1917057037354,27,1,0,0,1,0.286636352539062,37.6344108581543,2,1,1,289.143402099609,0,289.202545166016,,,,,,,,,,,,,,,,,,,,,,,,,,,,,,,,,
,3833442990.51361,286.332244873047,9999.6064453125,-0.000139492462208677,2.88966049857712E-8,1,2,13.4005146026611,4.99366090971147,30.7299997657537,-0.185571380532362,-0.0273213875609431,1,-1.01234385686187E-6,,,,,,,,,,,,,,,,,,,,,286.271057128906,286.393432617187,9999.6064453125,9999.6064453125,47.0485654580627,5.26291190487348,17.1454696655273,27,1,0,0,1,0.295257568359375,37.6344108581543,2,1,1,286.271057128906,0,286.332244873047,,,,,,,,,,,,,,,,,,,,,,,,,,,,,,,,,
,3833443047.08525,283.519241333008,9999.6064453125,-0.000139483709678951,2.09641468489623E-8,1,2,13.4005146026611,4.99368034522686,30.7000000029802,-0.185558864196869,-0.0273331365709346,1,-1.02228086766482E-6,,,,,,,,,,,,,,,,,,,,,283.471527099609,283.566955566406,9999.6064453125,9999.6064453125,46.9891616906011,5.26187321534661,17.0976943969727,27,1,0,0,1,0.286026000976562,37.6344108581543,2,1,1,283.471527099609,0,283.519241333008,,,,,,,,,,,,,,,,,,,,,,,,,,,,,,,,,
,3833443101.32493,280.819046020508,9999.6064453125,-0.000139336734509193,2.62204417986373E-8,1,2,13.4005146026611,4.99364065632732,30.7000000029802,-0.18536019556035,-0.0273120849367683,1,-1.02724633593197E-6,,,,,,,,,,,,,,,,,,,,,280.777496337891,280.860595703125,9999.6064453125,9999.6064453125,46.98017296263,5.26235744245913,17.0493316650391,27,1,0,0,1,0.29571533203125,37.6344108581543,2,1,1,280.777496337891,0,280.819046020508,,,,,,,,,,,,,,,,,,,,,,,,,,,,,,,,,
,3833443159.9526,277.861099243164,9999.6064453125,-0.000139266740136278,3.77682399160728E-8,1,2,13.4005146026611,4.99368412147385,30.6800007820129,-0.185265257946856,-0.0273275367295712,1,-1.04839159983661E-6,,,,,,,,,,,,,,,,,,,,,277.830657958984,277.891540527344,9999.6064453125,9999.6064453125,47.0079207750627,5.26204538336734,16.9992980957031,27,1,0,0,1,0.277481079101562,37.1456527709961,2,1,1,277.830657958984,0,277.861099243164,,,,,,,,,,,,,,,,,,,,,,,,,,,,,,,,,
,3833443216.49017,275.074722290039,9999.6064453125,-0.000139090376620464,2.6586597753698E-8,1,2,13.4005146026611,4.99368328615597,30.6800007820129,-0.18502072746596,-0.0273635372615155,1,-1.10008942735004E-6,,,,,,,,,,,,,,,,,,,,,275.041625976562,275.107818603516,9999.6064453125,9999.6064453125,46.9410915366684,5.26223959387123,16.9763717651367,27,1,0,0,1,0.295944213867188,37.1456527709961,2,1,1,275.041625976562,0,275.074722290039,,,,,,,,,,,,,,,,,,,,,,,,,,,,,,,,,
,3833443274.57744,272.121536254883,9999.6064453125,-0.000139029170138456,2.55213446359773E-8,1,2,13.4005146026611,4.99363932908133,30.6599996984005,-0.184938648166685,-0.0273399427004907,1,-1.09117730813001E-6,,,,,,,,,,,,,,,,,,,,,272.061889648438,272.181182861328,9999.6064453125,9999.6064453125,47.0509103436204,5.26249036414521,16.9472103118896,27,1,0,0,1,0.27557373046875,37.1456527709961,2,1,1,272.061889648438,0,272.121536254883,,,,,,,,,,,,,,,,,,,,,,,,,,,,,,,,,
,3833443331.03465,269.30632019043,9999.6064453125,-0.000138986823912,2.46089097703302E-8,1,2,13.4005146026611,4.99361168990805,30.6400004774332,-0.184881706655216,-0.0273257569588893,1,-1.08660130067587E-6,,,,,,,,,,,,,,,,,,,,,269.261383056641,269.351257324219,9999.6064453125,9999.6064453125,46.9266314090626,5.26244746103028,16.9129486083984,27,1,0,0,1,0.286026000976562,37.1456527709961,2,1,1,269.2294921875,0,269.30632019043,,,,,,,,,,,,,,,,,,,,,,,,,,,,,,,,,
,3833443387.56548,266.466445922852,9999.6064453125,-0.000138882180125681,3.48005858332827E-8,1,2,13.4005146026611,4.99379210133306,30.629999935627,-0.184752129242326,-0.0273031321434475,1,-1.08322803709698E-6,,,,,,,,,,,,,,,,,,,,,266.419921875,266.512969970703,9999.6064453125,9999.6064453125,46.9309303659184,5.26076241413207,16.8831768035889,27,1,0,0,1,0.283737182617187,37.1456527709961,2,1,1,266.419921875,0,266.466445922852,,,,,,,,,,,,,,,,,,,,,,,,,,,,,,,,,
,3833443439.8199,263.877059936523,9999.6064453125,-0.000138849250105374,3.49818425168416E-8,1,2,13.4005146026611,4.99369721195046,30.6199993938208,-0.184700480601661,-0.0273176447279418,1,-1.09926395276509E-6,,,,,,,,,,,,,,,,,,,,,263.825317382813,263.928802490234,9999.6064453125,9999.6064453125,47.0231625311877,5.26224445090031,16.8693294525146,27,1,0,0,1,0.273208618164062,36.6568908691406,2,1,1,263.825317382813,0,263.877059936523,,,,,,,,,,,,,,,,,,,,,,,,,,,,,,,,,
,3833443494.19502,261.177017211914,9999.6064453125,-0.000138698220552413,3.15442260156684E-8,1,2,13.4005146026611,4.99364816609796,30.6100007146597,-0.184501181899832,-0.0272583326079015,1,-1.07611787583523E-6,,,,,,,,,,,,,,,,,,,,,261.123931884766,261.230102539062,9999.6064453125,9999.6064453125,47.0622439571492,5.26233851774032,16.8515567779541,27,1,0,0,1,0.277023315429687,37.1456527709961,2,1,1,261.123931884766,0,261.177017211914,,,,,,,,,,,,,,,,,,,,,,,,,,,,,,,,,
,3833443550.69324,258.294952392578,9999.6064453125,-0.000138685098464159,4.70735623382247E-8,1,2,13.4005146026611,4.99366590561391,30.5899996310473,-0.184474697174436,-0.0273268855105698,1,-1.12933128431995E-6,,,,,,,,,,,,,,,,,,,,,258.245727539062,258.344177246094,9999.6064453125,9999.6064453125,47.0368410302742,5.26180434295089,16.85422706604,25,1,64,0,0,0.29449462890625,37.1456527709961,2,1,1,258.245727539062,0,258.294952392578,,,,,,,,,,,,,,,,,,,,,,,,,,,,,,,,,
,3833443607.02378,255.536071777344,9999.6064453125,-0.000138498349347274,3.61267018323054E-8,1,2,13.4005146026611,4.99363008034972,30.5899996310473,-0.18423228691566,-0.0272339727213741,1,-1.08587308973953E-6,,,,,,,,,,,,,,,,,,,,,255.490188598633,255.581954956055,9999.6064453125,9999.6064453125,46.8789520693896,5.26181541404563,16.869161605835,27,1,0,0,1,0.295639038085937,37.1456527709961,2,1,1,255.490188598633,0,255.536071777344,,,,,,,,,,,,,,,,,,,,,,,,,,,,,,,,,
,3833443663.56293,252.665641784668,9999.6064453125,-0.000138536275005113,4.1623763874502E-8,1,2,13.4005146026611,4.99365920706753,30.57000041008,-0.184285484684706,-0.0272325234693075,1,-1.07931853386462E-6,,,,,,,,,,,,,,,,,,,,,252.617202758789,252.714080810547,9999.6064453125,9999.6064453125,46.9317119944377,5.26210330277675,16.8835678100586,27,1,0,0,1,0.277252197265625,36.6568908691406,2,1,1,252.617202758789,0,252.665641784668,,,,,,,,,,,,,,,,,,,,,,,,,,,,,,,,,
,3833443717.85349,249.999931335449,9999.6064453125,-0.000138364232149776,3.35266039575631E-8,1,2,13.4005146026611,4.99360505335373,30.57000041008,-0.184055843656377,-0.0271843479341861,1,-1.06750076539999E-6,,,,,,,,,,,,,,,,,,,,,249.940338134766,250.059524536133,9999.6064453125,9999.6064453125,46.9797821483704,5.26203828097299,16.8705520629883,27,1,0,0,1,0.276870727539062,37.1456527709961,2,1,1,249.940338134766,0,249.999931335449,,,,,,,,,,,,,,,,,,,,,,,,,,,,,,,,,
,3833443774.42095,247.151733398438,9999.6064453125,-0.00013838343463268,3.98616049076168E-8,1,2,13.4005146026611,4.99366095714765,30.5499993264675,-0.184082845075722,-0.027198306443584,1,-1.07498456440758E-6,,,,,,,,,,,,,,,,,,,,,247.087509155273,247.215957641602,9999.6064453125,9999.6064453125,46.9094355816396,5.2623809730747,16.8933162689209,27,1,0,0,1,0.295867919921875,36.6568908691406,2,1,1,247.087509155273,0,247.151733398438,,,,,,,,,,,,,,,,,,,,,,,,,,,,,,,,,
,3833443831.032,244.348731994629,9999.6064453125,-0.000138184545344356,4.35909010783185E-8,1,2,13.4005146026611,4.993609309938,30.5499993264675,-0.183814825450575,-0.0271648728201089,1,-1.07797640815434E-6,,,,,,,,,,,,,,,,,,,,,244.28987121582,244.407592773438,9999.6064453125,9999.6064453125,46.9664944635434,5.26221063069586,16.8631935119629,27,1,0,0,1,0.295867919921875,36.6568908691406,2,1,1,244.28987121582,0,244.348731994629,,,,,,,,,,,,,,,,,,,,,,,,,,,,,,,,,
,3833443889.09696,241.439208984375,9999.6064453125,-0.000138311093824646,4.12638957266121E-8,1,2,13.4005146026611,4.99358411249405,30.5300001055002,-0.183986478862091,-0.0271567415416063,1,-1.05431707781669E-6,,,,,,,,,,,,,,,,,,,,,241.402877807617,241.475540161133,9999.6064453125,9999.6064453125,46.9532067787165,5.26211397954996,16.8603706359863,27,1,0,0,1,0.283737182617187,37.1456527709961,2,1,1,241.402877807617,0,241.439208984375,,,,,,,,,,,,,,,,,,,,,,,,,,,,,,,,,
,3833443947.60706,238.543380737305,9999.6064453125,-0.000138152213798864,3.02742776788992E-8,1,2,13.4005146026611,4.99361572716953,30.519999563694,-0.183777091010432,-0.0271231639330117,1,-1.05114034449056E-6,,,,,,,,,,,,,,,,,,,,,238.486373901367,238.600387573242,9999.6064453125,9999.6064453125,46.9485170076011,5.26211525374434,16.8760528564453,27,1,0,0,1,0.283584594726562,37.1456527709961,2,1,1,238.486373901367,0,238.543380737305,,,,,,,,,,,,,,,,,,,,,,,,,,,,,,,,,
,3833444004.04216,235.688949584961,9999.6064453125,-0.000138121087928459,6.76238159025963E-8,1,2,13.4005146026611,4.99362914336176,30.5100008845329,-0.183732829155549,-0.0271424208022035,1,-1.06987810571441E-6,,,,,,,,,,,,,,,,,,,,,235.635528564453,235.742370605469,9999.6064453125,9999.6064453125,46.9805637768896,5.26217593587508,16.9000301361084,27,1,0,0,1,0.284347534179687,37.1456527709961,2,1,1,235.635528564453,0,235.688949584961,,,,,,,,,,,,,,,,,,,,,,,,,,,,,,,,,
,3833444058.32989,233.018325805664,9999.6064453125,-0.000138085387750451,3.30989334091991E-8,1,2,13.4005146026611,4.99362645213596,30.4899998009205,-0.183679878778124,-0.0271734715321354,1,-1.09820192796249E-6,,,,,,,,,,,,,,,,,,,,,232.973571777344,233.063079833984,9999.6064453125,9999.6064453125,46.9825178481877,5.26255651178738,16.9185485839844,27,1,0,0,1,0.295791625976562,37.1456527709961,2,1,1,232.973571777344,0,233.018325805664,,,,,,,,,,,,,,,,,,,,,,,,,,,,,,,,,
,3833444116.90264,230.08757019043,9999.6064453125,-0.000137899521230064,3.5810522780998E-8,1,2,13.4005146026611,4.9936050099787,30.5000003427267,-0.183436906538136,-0.027098509498934,1,-1.06801813693714E-6,,,,,,,,,,,,,,,,,,,,,230.050598144531,230.124542236328,9999.6064453125,9999.6064453125,47.0282431165627,5.26268905874065,16.9104328155518,27,1,0,0,1,0.284042358398438,37.1456527709961,2,1,1,230.050598144531,0,230.08757019043,,,,,,,,,,,,,,,,,,,,,,,,,,,,,,,,,
,3833444171.53459,227.341613769531,9999.6064453125,-0.000137904777565476,3.44404225333753E-8,1,2,13.4005146026611,4.99361668583423,30.4700005799532,-0.183445013928781,-0.0270958558151021,1,-1.0652252424818E-6,,,,,,,,,,,,,,,,,,,,,227.273147583008,227.410079956055,9999.6064453125,9999.6064453125,46.9672760920627,5.26318906238723,16.9239959716797,26,1,64,0,0,0.29571533203125,37.1456527709961,2,1,1,227.273147583008,0,227.341613769531,,,,,,,,,,,,,,,,,,,,,,,,,,,,,,,,,
,3833444227.7201,224.534820556641,9999.6064453125,-0.000137935101583368,3.40529547613961E-8,1,2,13.4005146026611,4.99361253120792,30.4499994963407,-0.183485609191596,-0.027098446495503,1,-1.06295392395155E-6,,,,,,,,,,,,,,,,,,,,,224.498504638672,224.571136474609,9999.6064453125,9999.6064453125,46.9793913341107,5.26291015358834,16.926513671875,27,1,0,0,1,0.277175903320313,37.1456527709961,2,1,1,224.498504638672,0,224.534820556641,,,,,,,,,,,,,,,,,,,,,,,,,,,,,,,,,
,3833444282.3206,221.794952392578,9999.6064453125,-0.000137777346979227,3.98941903283065E-8,1,2,13.4005146026611,4.99370548325025,30.4499994963407,-0.183280999200049,-0.0270640981146252,1,-1.05869958370025E-6,,,,,,,,,,,,,,,,,,,,,221.730178833008,221.859725952148,9999.6064453125,9999.6064453125,46.9731383059569,5.26202212342791,16.9207019805908,27,1,0,0,1,0.277099609375,37.1456527709961,2,1,1,221.730178833008,0,221.794952392578,,,,,,,,,,,,,,,,,,,,,,,,,,,,,,,,,
,3833444340.45938,218.913223266602,9999.6064453125,-0.000137994683594812,3.61244157174571E-8,1,2,13.4005146026611,4.99364831138554,30.4300002753735,-0.183568569934751,-0.0270968240371335,1,-1.05320493275449E-6,,,,,,,,,,,,,,,,,,,,,218.877456665039,218.948989868164,9999.6064453125,9999.6064453125,47.0239441597069,5.26259522084986,16.9270496368408,27,1,0,0,1,0.274505615234375,37.1456527709961,2,1,1,218.877456665039,0,218.913223266602,,,,,,,,,,,,,,,,,,,,,,,,,,,,,,,,,
,3833444398.87491,215.981559753418,9999.6064453125,-0.000137733816322846,4.04987285652829E-8,1,2,13.4005146026611,4.99367967184859,30.4300002753735,-0.183224017013513,-0.0270394575023024,1,-1.04642679027131E-6,,,,,,,,,,,,,,,,,,,,,215.925979614258,216.037139892578,9999.6064453125,9999.6064453125,47.0040126324665,5.26256482544971,16.9249954223633,27,1,0,0,1,0.2764892578125,37.1456527709961,2,1,1,215.925979614258,0,215.981559753418,,,,,,,,,,,,,,,,,,,,,,,,,,,,,,,,,
,3833444455.65143,213.163414001465,9999.6064453125,-0.00013786470690036,4.15640371740971E-8,1,2,13.4005146026611,4.99363132147989,30.409999191761,-0.183392641464907,-0.0270867020748932,1,-1.06387241791369E-6,,,,,,,,,,,,,,,,,,,,,213.127792358398,213.199035644531,9999.6064453125,9999.6064453125,47.0270706737838,5.26262622529177,16.915943145752,26,1,64,0,0,0.27587890625,37.1456527709961,2,1,1,213.127792358398,0,213.163414001465,,,,,,,,,,,,,,,,,,,,,,,,,,,,,,,,,
,3833444511.90475,210.332778930664,9999.6064453125,-0.000137875821582304,3.95407726792448E-8,1,2,13.4005146026611,4.99364047788641,30.3899999707937,-0.183414684004853,-0.0270403448078858,1,-1.02745603483141E-6,,,,,,,,,,,,,,,,,,,,,210.282043457031,210.383514404297,9999.6064453125,9999.6064453125,46.9961963472742,5.26227556041785,16.8862533569336,27,1,0,0,1,0.29541015625,37.6344108581543,2,1,1,210.282043457031,0,210.332778930664,,,,,,,,,,,,,,,,,,,,,,,,,,,,,,,,,
,3833444568.18768,207.565414428711,9999.6064453125,-0.000137875496819689,4.66412731960761E-8,1,2,13.4005146026611,4.99361051736512,30.3899999707937,-0.18341081060665,-0.0270538878162838,1,-1.03783834574908E-6,,,,,,,,,,,,,,,,,,,,,207.526290893555,207.604537963867,9999.6064453125,9999.6064453125,47.0071391465434,5.26271895118588,16.8618450164795,27,1,0,0,1,0.295181274414063,37.6344108581543,2,1,1,207.526290893555,0,207.565414428711,,,,,,,,,,,,,,,,,,,,,,,,,,,,,,,,,
,3833444625.80409,204.641754150391,9999.6064453125,-0.000137817582573577,4.22393346896404E-8,1,2,13.4005146026611,4.99359785132596,30.3700007498264,-0.183333922915025,-0.0270367748853057,1,-1.03315580335384E-6,,,,,,,,,,,,,,,,,,,,,204.558059692383,204.725448608398,9999.6064453125,9999.6064453125,47.0333237019377,5.26322888666455,16.8633556365967,27,1,0,0,1,0.276718139648438,37.6344108581543,2,1,1,204.558059692383,0,204.641754150391,,,,,,,,,,,,,,,,,,,,,,,,,,,,,,,,,
,3833444682.95841,201.812271118164,9999.6064453125,-0.000137715761448315,5.05688291120542E-8,1,2,13.4005146026611,4.99359673644532,30.3700007498264,-0.183205887144275,-0.0269633709429562,1,-9.92276706002485E-7,,,,,,,,,,,,,,,,,,,,,201.761199951172,201.863342285156,9999.6064453125,9999.6064453125,47.0305880021204,5.26273214220995,16.8615627288818,27,1,0,0,1,0.295867919921875,37.6344108581543,2,1,1,201.761199951172,0,201.812271118164,,,,,,,,,,,,,,,,,,,,,,,,,,,,,,,,,
,3833444739.36527,198.999114990234,9999.6064453125,-0.000137809391579166,6.0515113468419E-8,1,2,13.4005146026611,4.99358883906689,30.349999666214,-0.183313298657039,-0.0271014337282791,1,-1.08290644309277E-6,,,,,,,,,,,,,,,,,,,,,198.958953857422,199.039276123047,9999.6064453125,9999.6064453125,47.0247257882261,5.26294137511323,16.8585968017578,27,1,0,0,1,0.29541015625,37.6344108581543,2,1,1,198.958953857422,0,198.999114990234,,,,,,,,,,,,,,,,,,,,,,,,,,,,,,,,,
,3833444793.75718,196.242698669434,9999.6064453125,-0.000137580729251699,5.38958207120018E-8,1,2,13.4005146026611,4.99358684134738,30.349999666214,-0.183014619474476,-0.0270164959080995,1,-1.05110599760451E-6,,,,,,,,,,,,,,,,,,,,,196.188522338867,196.296875,9999.6064453125,9999.6064453125,46.9711842346588,5.2629311242855,16.8314685821533,27,1,0,0,1,0.2777099609375,37.6344108581543,2,1,1,196.188522338867,0,196.242698669434,,,,,,,,,,,,,,,,,,,,,,,,,,,,,,,,,
,3833444852.41365,193.313522338867,9999.6064453125,-0.000137451807414235,3.59415098560369E-8,1,2,13.4005146026611,4.99358859365875,30.3300004452467,-0.182839474985474,-0.0270179134500261,1,-1.0701868103225E-6,,,,,,,,,,,,,,,,,,,,,193.259735107422,193.367309570313,9999.6064453125,9999.6064453125,47.0102656606204,5.26314938886567,16.818000793457,27,1,0,0,1,0.295181274414063,37.6344108581543,2,1,1,193.259735107422,0,193.313522338867,,,,,,,,,,,,,,,,,,,,,,,,,,,,,,,,,
,3833444912.60489,190.335594177246,9999.6064453125,-0.000137423923801465,4.73476565321425E-8,1,2,13.4005146026611,4.99360767609793,30.3199999034405,-0.182801961466764,-0.0270224413034002,1,-1.0773794592912E-6,,,,,,,,,,,,,,,,,,,,,190.281555175781,190.389633178711,9999.6064453125,9999.6064453125,46.916079424053,5.26308080103688,16.8011455535889,27,1,0,0,1,0.29571533203125,37.6344108581543,2,1,1,190.281555175781,0,190.335594177246,,,,,,,,,,,,,,,,,,,,,,,,,,,,,,,,,
,3833444969.02228,187.498588562012,9999.6064453125,-0.000137371969678552,5.33566123194735E-8,1,2,13.4005146026611,4.99355741614264,30.3099993616343,-0.182721915168936,-0.0270720485803279,1,-1.12217621572045E-6,,,,,,,,,,,,,,,,,,,,,187.442825317383,187.554351806641,9999.6064453125,9999.6064453125,47.0395767300915,5.26356042351929,16.7744426727295,27,1,0,0,1,0.284957885742187,37.6344108581543,2,1,1,187.442825317383,0,187.498588562012,,,,,,,,,,,,,,,,,,,,,,,,,,,,,,,,,
,3833445027.69754,184.564247131348,9999.6064453125,-0.000137385315983522,5.43902939473532E-8,1,2,13.4005146026611,4.9935602924412,30.3000006824732,-0.182747951037721,-0.0270164874918529,1,-1.07857048815575E-6,,,,,,,,,,,,,,,,,,,,,184.515731811523,184.612762451172,9999.6064453125,9999.6064453125,46.94968945038,5.26356081712133,16.7568683624268,27,1,0,0,1,0.295257568359375,37.6344108581543,2,1,1,184.515731811523,0,184.564247131348,,,,,,,,,,,,,,,,,,,,,,,,,,,,,,,,,
,3833445084.10559,181.771766662598,9999.6064453125,-0.000137505535966308,5.14589880296574E-8,1,2,13.4005146026611,4.99358772842491,30.2799995988607,-0.182900338536726,-0.0271040154628774,1,-1.12733699751705E-6,,,,,,,,,,,,,,,,,,,,,181.736068725586,181.807464599609,9999.6064453125,9999.6064453125,46.9766556342934,5.26369767649734,16.751802444458,25,1,64,0,0,0.2862548828125,37.6344108581543,2,1,1,181.736068725586,0,181.771766662598,,,,,,,,,,,,,,,,,,,,,,,,,,,,,,,,,
,3833445141.71571,178.862075805664,9999.6064453125,-0.000137108612144294,4.82984760331175E-8,1,2,13.4005146026611,4.9935365711474,30.2799995988607,-0.182385797428426,-0.0269111134481894,1,-1.03826063232031E-6,,,,,,,,,,,,,,,,,,,,,178.771621704102,178.952529907227,9999.6064453125,9999.6064453125,47.0813938558704,5.26400586949687,16.7330379486084,27,1,0,0,1,0.277328491210938,37.6344108581543,2,1,1,178.771621704102,0,178.862075805664,,,,,,,,,,,,,,,,,,,,,,,,,,,,,,,,,
,3833445197.11053,176.083541870117,9999.6064453125,-0.000137237401091109,7.19001870394783E-8,1,2,13.4005146026611,4.99343961136562,30.2600003778934,-0.182543488649952,-0.0269984018273533,1,-1.08634216447361E-6,,,,,,,,,,,,,,,,,,,,,176.059005737305,176.10807800293,9999.6064453125,9999.6064453125,46.9848627337454,5.26463309690295,16.7259521484375,25,1,64,0,0,0.285797119140625,37.6344108581543,2,1,1,176.059005737305,0,176.083541870117,,,,,,,,,,,,,,,,,,,,,,,,,,,,,,,,,
,3833445253.11301,173.303329467773,9999.6064453125,-0.000137176469513153,4.93040279576405E-8,1,2,13.4005146026611,4.99355038483118,30.2600003778934,-0.182472876035017,-0.0269522757019726,1,-1.05960696302809E-6,,,,,,,,,,,,,,,,,,,,,173.250411987305,173.356246948242,9999.6064453125,9999.6064453125,46.9739199344761,5.2638178501634,16.7043838500977,27,1,0,0,1,0.2960205078125,37.6344108581543,2,1,1,173.250411987305,0,173.303329467773,,,,,,,,,,,,,,,,,,,,,,,,,,,,,,,,,
,3833445311.67935,170.389640808105,9999.6064453125,-0.00013710449263792,5.08363999083156E-8,1,2,13.4005146026611,4.99358983646083,30.239999294281,-0.182386777577502,-0.0268835604051641,1,-1.0178504878333E-6,,,,,,,,,,,,,,,,,,,,,170.339202880859,170.440078735352,9999.6064453125,9999.6064453125,46.94968945038,5.26360238787108,16.6914691925049,27,1,0,0,1,0.286178588867187,37.1456527709961,2,1,1,170.339202880859,0,170.389640808105,,,,,,,,,,,,,,,,,,,,,,,,,,,,,,,,,
,3833445365.95224,167.666297912598,9999.6064453125,-0.000136923972904873,4.89765260391965E-8,1,2,13.4005146026611,4.99356908900191,30.239999294281,-0.182137104113483,-0.026908770753736,1,-1.06213765137309E-6,,,,,,,,,,,,,,,,,,,,,167.624557495117,167.708038330078,9999.6064453125,9999.6064453125,47.0825662986492,5.26364251906417,16.6585578918457,27,1,0,0,1,0.275955200195313,37.1456527709961,2,1,1,167.624557495117,0,167.666297912598,,,,,,,,,,,,,,,,,,,,,,,,,,,,,,,,,
,3833445424.54251,164.731903076172,9999.6064453125,-0.000136975991676757,6.17560400812286E-8,1,2,13.4005146026611,4.99345633369778,30.2200000733137,-0.182201569559441,-0.0269116738598595,1,-1.05766964985925E-6,,,,,,,,,,,,,,,,,,,,,164.697021484375,164.766784667969,9999.6064453125,9999.6064453125,46.9289762946203,5.26373389503586,16.6333999633789,27,1,0,0,1,0.276336669921875,37.1456527709961,2,1,1,164.697021484375,0,164.731903076172,,,,,,,,,,,,,,,,,,,,,,,,,,,,,,,,,
,3833445482.1132,161.891540527344,9999.6064453125,-0.000136867395746298,6.62993117840743E-8,1,2,13.4005146026611,4.99349373973776,30.2099995315075,-0.182060081248595,-0.0268827880515237,1,-1.05095410020715E-6,,,,,,,,,,,,,,,,,,,,,161.799179077148,161.983901977539,9999.6064453125,9999.6064453125,46.9856443622646,5.2630250621316,16.6155815124512,27,1,0,0,1,0.275650024414062,37.1456527709961,2,1,1,161.799179077148,0,161.891540527344,,,,,,,,,,,,,,,,,,,,,,,,,,,,,,,,,
,3833445537.21963,159.123672485352,9999.6064453125,-0.000136872028870165,6.10657776490576E-8,1,2,13.4005146026611,4.99350243390573,30.2000008523464,-0.182060756600474,-0.0269261157271684,1,-1.08279554673633E-6,,,,,,,,,,,,,,,,,,,,,159.074356079102,159.172988891602,9999.6064453125,9999.6064453125,47.03097881638,5.26339224107706,16.6042461395264,27,1,0,0,1,0.283660888671875,37.1456527709961,2,1,1,159.074356079102,0,159.123672485352,,,,,,,,,,,,,,,,,,,,,,,,,,,,,,,,,
,3833445595.6784,156.167106628418,9999.6064453125,-0.00013667201789333,4.76461029546143E-8,1,2,13.4005146026611,4.99357799164497,30.1900003105402,-0.181807410062626,-0.0268234617721162,1,-1.03325463492623E-6,,,,,,,,,,,,,,,,,,,,,156.130523681641,156.203689575195,9999.6064453125,9999.6064453125,47.0200360171107,5.26314102115348,16.5718631744385,27,1,0,0,1,0.295639038085937,37.1456527709961,2,1,1,156.130523681641,0,156.167106628418,,,,,,,,,,,,,,,,,,,,,,,,,,,,,,,,,
,3833445652.10622,153.371482849121,9999.6064453125,-0.000136574262799083,6.48804263126496E-8,1,2,13.4005146026611,4.99351928601725,30.179999768734,-0.181668382666763,-0.0268472038543278,1,-1.06507669971031E-6,,,,,,,,,,,,,,,,,,,,,153.307830810547,153.435134887695,9999.6064453125,9999.6064453125,46.9391374653703,5.26364228059922,16.5291786193848,27,1,0,0,1,0.274658203125,36.6568908691406,2,1,1,153.307830810547,0,153.371482849121,,,,,,,,,,,,,,,,,,,,,,,,,,,,,,,,,
,3833445708.69287,150.562629699707,9999.6064453125,-0.000136753015479195,6.634324073423E-8,1,2,13.4005146026611,4.99356785647139,30.1600005477667,-0.181911676187032,-0.0268605587478388,1,-1.04984333304872E-6,,,,,,,,,,,,,,,,,,,,,150.508514404297,150.616744995117,9999.6064453125,9999.6064453125,46.9575057355723,5.26295221990127,16.5539493560791,27,1,0,0,1,0.286865234375,37.1456527709961,2,1,1,150.508514404297,0,150.562629699707,,,,,,,,,,,,,,,,,,,,,,,,,,,,,,,,,
,3833445767.21286,147.612289428711,9999.6064453125,-0.000136524589978039,6.65082253604729E-8,1,2,13.4005146026611,4.99356179223788,30.1600005477667,-0.181604049869187,-0.0268404493487837,1,-1.06671460310989E-6,,,,,,,,,,,,,,,,,,,,,147.591522216797,147.633056640625,9999.6064453125,9999.6064453125,46.944608865005,5.26291261406409,16.5445671081543,27,1,0,0,1,0.273361206054687,36.6568908691406,2,1,1,147.591522216797,0,147.612289428711,,,,,,,,,,,,,,,,,,,,,,,,,,,,,,,,,
,3833445822.56006,144.882698059082,9999.6064453125,-0.000136076703391363,4.37966487787816E-8,1,2,13.4005146026611,4.99355288050223,30.1600005477667,-0.181003994476702,-0.0267797737896173,1,-1.08382378051165E-6,,,,,,,,,,,,,,,,,,,,,144.799057006836,144.966339111328,9999.6064453125,9999.6064453125,47.0063575180242,5.26317443063726,16.5190620422363,27,1,0,0,1,0.277023315429687,36.6568908691406,2,1,1,144.799057006836,0,144.882698059082,,,,,,,,,,,,,,,,,,,,,,,,,,,,,,,,,
,3833445879.7355,142.017601013184,9999.6064453125,-0.000136077307588826,4.4025895226425E-8,1,2,13.4005146026611,4.99349593702022,30.1399994641542,-0.181002829064501,-0.0267733302795761,1,-1.07921468698455E-6,,,,,,,,,,,,,,,,,,,,,141.965576171875,142.069625854492,9999.6064453125,9999.6064453125,46.8476869286203,5.26306017053462,16.5145397186279,27,1,0,0,1,0.275421142578125,37.1456527709961,2,1,1,141.965576171875,0,142.017601013184,,,,,,,,,,,,,,,,,,,,,,,,,,,,,,,,,
,3833445938.34937,139.082397460938,9999.6064453125,-0.000136008502032028,4.51627100646221E-8,1,2,13.4005146026611,4.9934884653639,30.1399994641542,-0.180909807907837,-0.0267678106133857,1,-1.08473134595222E-6,,,,,,,,,,,,,,,,,,,,,139.031524658203,139.133270263672,9999.6064453125,9999.6064453125,46.9172518668319,5.26326277705369,16.5035381317139,27,1,0,0,1,0.286331176757813,36.6568908691406,2,1,1,139.031524658203,0,139.082397460938,,,,,,,,,,,,,,,,,,,,,,,,,,,,,,,,,
,3833445994.61012,136.269981384277,9999.6064453125,-0.000135998392309647,9.24712667353441E-8,1,2,13.4005146026611,4.99352038008797,30.120000243187,-0.180899209886134,-0.0267570071785567,1,-1.0778559461321E-6,,,,,,,,,,,,,,,,,,,,,136.222686767578,136.317276000977,9999.6064453125,9999.6064453125,46.9790005198511,5.26306283760613,16.4870185852051,27,1,0,0,1,0.284500122070313,36.6568908691406,2,1,1,136.222686767578,0,136.269981384277,,,,,,,,,,,,,,,,,,,,,,,,,,,,,,,,,
,3833446052.99564,133.373558044434,9999.6064453125,-0.000135970151967631,7.25392402883904E-8,1,2,13.4005146026611,4.99348964815226,30.120000243187,-0.180857511540632,-0.0267698857523698,1,-1.09164534893472E-6,,,,,,,,,,,,,,,,,,,,,133.3173828125,133.429733276367,9999.6064453125,9999.6064453125,46.9899433191204,5.26352938092318,16.4587249755859,27,1,0,0,1,0.2850341796875,36.6568908691406,2,1,1,133.3173828125,0,133.373558044434,,,,,,,,,,,,,,,,,,,,,,,,,,,,,,,,,
,3833446109.39945,130.561569213867,9999.6064453125,-0.000136039265113359,7.54581046918162E-8,1,2,13.4005146026611,4.99350471595927,30.0999991595745,-0.180957774640073,-0.0267293506946899,1,-1.05145846144201E-6,,,,,,,,,,,,,,,,,,,,,130.506790161133,130.616348266602,9999.6064453125,9999.6064453125,47.0337145161973,5.26343790512359,16.4356079101562,27,1,0,0,1,0.275955200195313,36.6568908691406,2,1,1,130.506790161133,0,130.561569213867,,,,,,,,,,,,,,,,,,,,,,,,,,,,,,,,,
,3833446168.0142,127.567707061768,9999.6064453125,-0.000135858266635531,6.91114335092091E-8,1,2,13.4005146026611,4.99346017260119,30.0999991595745,-0.180712157248263,-0.0267123898289667,1,-1.0642742151736E-6,,,,,,,,,,,,,,,,,,,,,127.507926940918,127.627487182617,9999.6064453125,9999.6064453125,46.8941938255146,5.26331740780965,16.4223365783691,27,1,0,0,1,0.2862548828125,36.6568908691406,2,1,1,127.507926940918,0,127.567707061768,,,,,,,,,,,,,,,,,,,,,,,,,,,,,,,,,
,3833446224.62764,124.769027709961,9999.6064453125,-0.000135820849250079,1.05329620673444E-7,1,2,13.4005146026611,4.99347137997879,30.0799999386072,-0.180664121434916,-0.0266966798645927,1,-1.05764660756737E-6,,,,,,,,,,,,,,,,,,,,,124.702674865723,124.835380554199,9999.6064453125,9999.6064453125,46.8730898554953,5.26310295319716,16.4104290008545,27,1,0,0,1,0.295867919921875,36.6568908691406,2,1,1,124.702674865723,0,124.769027709961,,,,,,,,,,,,,,,,,,,,,,,,,,,,,,,,,
,3833446278.84609,122.113460540771,9999.6064453125,-0.000135558892801864,6.36055028236849E-8,1,2,13.4005146026611,4.99349409535261,30.0799999386072,-0.180315904824031,-0.0266517591933253,1,-1.06041507233596E-6,,,,,,,,,,,,,,,,,,,,,122.055824279785,122.171096801758,9999.6064453125,9999.6064453125,46.9657128350242,5.26289041603735,16.4120254516602,27,1,0,0,1,0.284271240234375,36.6568908691406,2,1,1,122.055824279785,0,122.113460540771,,,,,,,,,,,,,,,,,,,,,,,,,,,,,,,,,
,3833446337.40951,119.166816711426,9999.6064453125,-0.000135318310836272,8.07292363376031E-8,1,2,13.4005146026611,4.99348496785678,30.0799999386072,-0.179990605921822,-0.0266389652579842,1,-1.08449598407467E-6,,,,,,,,,,,,,,,,,,,,,119.129013061523,119.204620361328,9999.6064453125,9999.6064453125,47.0587266288127,5.26294642248903,16.3902435302734,27,1,0,0,1,0.275802612304687,36.6568908691406,2,1,1,119.129013061523,0,119.166816711426,,,,,,,,,,,,,,,,,,,,,,,,,,,,,,,,,
,3833446393.50103,116.316200256348,9999.6064453125,-0.000135372603267297,1.12082257420458E-7,1,2,13.4005146026611,4.99348975630264,30.0600007176399,-0.180068458797985,-0.0266110646760443,1,-1.05592610035963E-6,,,,,,,,,,,,,,,,,,,,,116.255516052246,116.376884460449,9999.6064453125,9999.6064453125,46.9836902909665,5.2628867604289,16.3741092681885,27,1,0,0,1,0.285797119140625,36.6568908691406,2,1,1,116.255516052246,0,116.316200256348,,,,,,,,,,,,,,,,,,,,,,,,,,,,,,,,,
,3833446448.19948,113.626510620117,9999.6064453125,-0.000135315327014684,7.84355506851444E-8,1,2,13.4005146026611,4.99344122581286,30.0500001758337,-0.179986296749102,-0.0266250414444136,1,-1.07469687868491E-6,,,,,,,,,,,,,,,,,,,,,113.604721069336,113.648300170898,9999.6064453125,9999.6064453125,46.9586781783511,5.26274677699362,16.3924961090088,27,1,0,0,1,0.277786254882813,36.6568908691406,2,1,1,113.604721069336,0,113.626510620117,,,,,,,,,,,,,,,,,,,,,,,,,,,,,,,,,
,3833446502.57011,110.891796112061,9999.6064453125,-0.000135146652732813,6.60534126892749E-8,1,2,13.4005146026611,4.993453637275,30.0500001758337,-0.179763175434341,-0.0265874778815566,1,-1.07000394109621E-6,,,,,,,,,,,,,,,,,,,,,110.865058898926,110.918533325195,9999.6064453125,9999.6064453125,46.8879407973607,5.26315948134422,16.3769378662109,27,1,0,0,1,0.295486450195313,36.6568908691406,2,1,1,110.865058898926,0,110.891796112061,,,,,,,,,,,,,,,,,,,,,,,,,,,,,,,,,
,3833446559.03386,108.051818847656,9999.6064453125,-0.000134953882378088,3.95736518081218E-8,1,2,13.4005146026611,4.99346418618337,30.0399996340275,-0.179503242771621,-0.0265785379920217,1,-1.09018604465826E-6,,,,,,,,,,,,,,,,,,,,,108.035842895508,108.067794799805,9999.6064453125,9999.6064453125,46.9653220207646,5.26268404890443,16.3457298278809,27,1,0,0,1,0.274810791015625,36.6568908691406,2,1,1,108.035842895508,0,108.051818847656,,,,,,,,,,,,,,,,,,,,,,,,,,,,,,,,,
,3833446617.19398,105.184234619141,9999.6064453125,-0.000135252694156631,5.1925849976985E-8,1,2,13.4005146026611,4.9934071702971,30.0200004130602,-0.17990120225244,-0.026613211266523,1,-1.0747569215146E-6,,,,,,,,,,,,,,,,,,,,,105.123359680176,105.245109558105,9999.6064453125,9999.6064453125,46.8453420430626,5.26285900729354,16.3333206176758,27,1,0,0,1,0.295562744140625,36.6568908691406,2,1,1,105.123359680176,0,105.184234619141,,,,,,,,,,,,,,,,,,,,,,,,,,,,,,,,,
,3833446673.55137,102.340656280518,9999.6064453125,-0.000134826109464122,4.45639093424778E-8,1,2,13.4005146026611,4.9934844865549,30.0200004130602,-0.179337688033801,-0.0265292186431596,1,-1.07090317290392E-6,,,,,,,,,,,,,,,,,,,,,102.292129516602,102.389183044434,9999.6064453125,9999.6064453125,46.8715265984569,5.26246891472322,16.3248558044434,27,1,0,0,1,0.277023315429687,36.6568908691406,2,1,1,102.292129516602,0,102.340656280518,,,,,,,,,,,,,,,,,,,,,,,,,,,,,,,,,
,3833446730.18725,99.5080986022949,9999.6064453125,-0.000134616594886062,3.17571898473001E-8,1,2,13.4005146026611,4.99347304334474,30.0200004130602,-0.179063582880116,-0.0264511422393368,1,-1.04162756681906E-6,,,,,,,,,,,,,,,,,,,,,99.4426879882813,99.5735092163086,9999.6064453125,9999.6064453125,46.8812969549473,5.26301191012709,16.2913627624512,27,1,0,0,1,0.295639038085937,37.1456527709961,2,1,1,99.4426879882813,0,99.5080986022949,,,,,,,,,,,,,,,,,,,,,,,,,,,,,,,,,
,3833446786.43412,96.7267112731934,9999.6064453125,-0.000134684905454481,3.66043839190165E-8,1,2,13.4005146026611,4.99344584723931,29.9999993294477,-0.179151257299996,-0.0264776242514374,1,-1.05211178476195E-6,,,,,,,,,,,,,,,,,,,,,96.6867218017578,96.7667007446289,9999.6064453125,9999.6064453125,46.9614138781684,5.26284525759354,16.2593441009521,27,1,0,0,1,0.27435302734375,37.1456527709961,2,1,1,96.6867218017578,0,96.7267112731934,,,,,,,,,,,,,,,,,,,,,,,,,,,,,,,,,
,3833446843.02787,93.862174987793,9999.6064453125,-0.0001344209257701,2.96373672586034E-8,1,2,13.4005146026611,4.99344700630753,29.9999993294477,-0.178795668758827,-0.0264580108319121,1,-1.07428640585776E-6,,,,,,,,,,,,,,,,,,,,,93.8296585083008,93.8946914672852,9999.6064453125,9999.6064453125,46.9774372628127,5.26298963640606,16.1987800598145,27,1,0,0,1,0.275497436523438,37.1456527709961,2,1,1,93.8296585083008,0,93.862174987793,,,,,,,,,,,,,,,,,,,,,,,,,,,,,,,,,
,3833446899.54377,91.0648612976074,9999.6064453125,-0.000134223015889869,3.03082327953656E-8,1,2,13.4005146026611,4.99344422129371,29.9999993294477,-0.178536037545104,-0.0263922256957977,1,-1.05257079206475E-6,,,,,,,,,,,,,,,,,,,,,91.0449295043945,91.0847930908203,9999.6064453125,9999.6064453125,46.9688393491011,5.26288131664554,16.1889533996582,27,1,0,0,1,0.284652709960938,37.6344108581543,2,1,1,91.0449295043945,0,91.0648612976074,,,,,,,,,,,,,,,,,,,,,,,,,,,,,,,,,
,3833446954.91327,88.2924766540527,9999.6064453125,-0.000134251672507224,3.79661122829244E-8,1,2,13.4005146026611,4.99343159485453,29.9800001084805,-0.178566596450476,-0.02644740244009,1,-1.09006906441987E-6,,,,,,,,,,,,,,,,,,,,,88.2008285522461,88.3841247558594,9999.6064453125,9999.6064453125,46.9535975929761,5.26250146179317,16.1657161712646,27,1,0,0,1,0.27740478515625,37.1456527709961,2,1,1,88.2008285522461,0,88.2924766540527,,,,,,,,,,,,,,,,,,,,,,,,,,,,,,,,,
,3833447010.37551,85.5289306640625,9999.6064453125,-0.000134040217442512,2.89152513092866E-8,1,2,13.4005146026611,4.99344027256187,29.9800001084805,-0.178293293816821,-0.0263519777385826,1,-1.04792627639808E-6,,,,,,,,,,,,,,,,,,,,,85.5042419433594,85.5536193847656,9999.6064453125,9999.6064453125,46.8691817128992,5.26227010734469,16.123628616333,27,1,0,0,1,0.286102294921875,37.1456527709961,2,1,1,85.5042419433594,0,85.5289306640625,,,,,,,,,,,,,,,,,,,,,,,,,,,,,,,,,
,3833447068.48528,82.6084747314453,9999.6064453125,-0.00013377073922396,4.40084641381672E-8,1,2,13.4005146026611,4.99338889753871,29.9800001084805,-0.177928568160061,-0.02632560109912,1,-1.06607571137002E-6,,,,,,,,,,,,,,,,,,,,,82.5716857910156,82.645263671875,9999.6064453125,9999.6064453125,47.0415308013896,5.26267055790038,16.1093978881836,27,1,0,0,1,0.274887084960938,37.1456527709961,2,1,1,82.5716857910156,0,82.6084747314453,,,,,,,,,,,,,,,,,,,,,,,,,,,,,,,,,
,3833447120.86504,79.9908256530762,9999.6064453125,-0.000133779578552396,3.52862507456839E-8,1,2,13.4005146026611,4.99344485658111,29.9600008875132,-0.177942671129567,-0.0263305097664068,1,-1.06822248493834E-6,,,,,,,,,,,,,,,,,,,,,79.938102722168,80.0435485839844,9999.6064453125,9999.6064453125,46.9653220207646,5.26284115356334,16.0649871826172,27,1,0,0,1,0.286636352539062,37.1456527709961,2,1,1,79.938102722168,0,79.9908256530762,,,,,,,,,,,,,,,,,,,,,,,,,,,,,,,,,
,3833447177.24706,77.1530570983887,9999.6064453125,-0.000133518545320726,3.23850727174922E-8,1,2,13.4005146026611,4.99346934803348,29.9600008875132,-0.177590900527766,-0.0263204982131107,1,-1.09706935400056E-6,,,,,,,,,,,,,,,,,,,,,77.0961456298828,77.2099685668945,9999.6064453125,9999.6064453125,46.8672276416011,5.26279019961137,16.0260200500488,27,1,0,0,1,0.286941528320313,37.1456527709961,2,1,1,77.0961456298828,0,77.1530570983887,,,,,,,,,,,,,,,,,,,,,,,,,,,,,,,,,
,3833447233.67823,74.2846832275391,9999.6064453125,-0.000133221288748805,3.10042564286578E-8,1,2,13.4005146026611,4.99343835336692,29.9600008875132,-0.177198592179113,-0.0262289569300716,1,-1.07005519312984E-6,,,,,,,,,,,,,,,,,,,,,74.2277908325195,74.3415756225586,9999.6064453125,9999.6064453125,46.946562936303,5.2626275604356,16.0084571838379,27,1,0,0,1,0.28656005859375,37.1456527709961,2,1,1,74.2277908325195,0,74.2846832275391,,,,,,,,,,,,,,,,,,,,,,,,,,,,,,,,,
,3833447292.32318,71.3627433776855,9999.6064453125,-0.000133231108624036,5.3640608810059E-8,1,2,13.4005146026611,4.99339582912209,29.9399998039007,-0.177210397325763,-0.0262247804266758,1,-1.06577552101301E-6,,,,,,,,,,,,,,,,,,,,,71.3131256103516,71.4123611450195,9999.6064453125,9999.6064453125,47.00049530413,5.26287786239036,15.9741287231445,27,1,0,0,1,0.284347534179687,37.1456527709961,2,1,1,71.3131256103516,0,71.3627433776855,,,,,,,,,,,,,,,,,,,,,,,,,,,,,,,,,
,3833447350.87512,68.3965225219727,9999.6064453125,-0.000132910884499765,3.88252632467544E-8,1,2,13.4005146026611,4.99338758936308,29.9399998039007,-0.176777221776068,-0.0262106549441898,1,-1.09998630980784E-6,,,,,,,,,,,,,,,,,,,,,68.3773727416992,68.4156723022461,9999.6064453125,9999.6064453125,46.9477353790819,5.2623882845117,15.9173898696899,27,1,0,0,1,0.295867919921875,37.1456527709961,2,1,1,68.3773727416992,0,68.3965225219727,,,,,,,,,,,,,,,,,,,,,,,,,,,,,,,,,
,3833447406.23445,65.6243171691895,9999.6064453125,-0.000132519981878033,4.64248714286116E-8,1,2,13.4005146026611,4.99345756900595,29.9399998039007,-0.176263677892302,-0.0261126926647348,1,-1.08069819719015E-6,,,,,,,,,,,,,,,,,,,,,65.5419845581055,65.7066497802734,9999.6064453125,9999.6064453125,46.890676497178,5.26251590627138,15.8597507476807,27,1,0,0,1,0.286178588867187,36.6568908691406,2,1,1,65.5419845581055,0,65.6243171691895,,,,,,,,,,,,,,,,,,,,,,,,,,,,,,,,,
,3833447461.3711,62.8751831054687,9999.6064453125,-0.000131874355463646,3.93003509970343E-8,1,2,13.4005146026611,4.99335137012654,29.9399998039007,-0.175402240944193,-0.0259674329106761,1,-1.06245324742648E-6,,,,,,,,,,,,,,,,,,,,,62.8350219726563,62.9153442382813,9999.6064453125,9999.6064453125,46.9266314090626,5.26312574938792,15.7927904129028,27,1,0,0,1,0.295944213867188,37.1456527709961,2,1,1,62.8350219726563,0,62.8751831054687,,,,,,,,,,,,,,,,,,,,,,,,,,,,,,,,,
,3833447527.83144,59.522647857666,9999.6064453125,-0.0001310788623879,3.83561688331436E-8,1,2,13.4005146026611,4.99338806679733,29.9200005829334,-0.174343418845064,-0.025829043081441,1,-1.06955537803715E-6,,,,,,,,,,,,,,,,,,,,,59.4692344665527,59.5760612487793,9999.6064453125,9999.6064453125,46.9281946661011,5.26298462522576,15.5681276321411,27,1,0,0,1,0.284881591796875,37.1456527709961,2,1,1,59.4692344665527,0,59.522647857666,,,,,,,,,,,,,,,,,,,,,,,,,,,,,,,,,
,3833447584.24252,56.6510047912598,9999.6064453125,-0.000130374247661892,3.6080351993217E-8,1,2,13.4005146026611,4.9933244037451,29.9200005829334,-0.173405171731005,-0.0256756917907347,1,-1.05324813716711E-6,,,,,,,,,,,,,,,,,,,,,56.5937461853027,56.7082633972168,9999.6064453125,9999.6064453125,46.9180334953511,5.26239118784257,15.303505897522,27,1,0,0,1,0.2862548828125,36.6568908691406,2,1,1,56.5937461853027,0,56.6510047912598,,,,,,,,,,,,,,,,,,,,,,,,,,,,,,,,,
,3833447642.80477,53.7500438690186,9999.6064453125,-0.000129350457011985,3.58020183414625E-8,1,2,13.4005146026611,4.99337630988542,29.9200005829334,-0.172047821859949,-0.0254608461881472,1,-1.03477528440557E-6,,,,,,,,,,,,,,,,,,,,,53.7174644470215,53.7826232910156,9999.6064453125,9999.6064453125,46.8945846397742,5.26253413507421,15.014139175415,27,1,0,0,1,0.286178588867187,37.1456527709961,2,1,1,53.7174644470215,0,53.7500438690186,,,,,,,,,,,,,,,,,,,,,,,,,,,,,,,,,
,3833447697.44058,50.954517364502,9999.6064453125,-0.00012714887270636,4.05478751125911E-8,1,2,13.4005146026611,4.99328710717583,29.899999499321,-0.169117828731267,-0.0250093378365981,1,-1.00398718471332E-6,,,,,,,,,,,,,,,,,,,,,50.8938865661621,51.0151481628418,9999.6064453125,9999.6064453125,47.0141738032165,5.26257690060222,14.7756605148315,27,1,0,0,1,0.284652709960938,37.1456527709961,2,1,1,50.8938865661621,0,50.954517364502,,,,,,,,,,,,,,,,,,,,,,,,,,,,,,,,,
,3833447755.50209,48.0554580688477,9999.6064453125,-0.000117816858222996,3.43775774901883E-8,1,2,13.4005146026611,4.99334155855033,29.899999499321,-0.156711529136,-0.0231479666756397,1,-9.10644945844459E-7,,,,,,,,,,,,,,,,,,,,,48.0031852722168,48.1077308654785,9999.6064453125,9999.6064453125,46.9235048949857,5.26202277726981,14.4845304489136,27,1,0,0,1,0.28472900390625,37.1456527709961,2,1,1,48.0031852722168,0,48.0554580688477,,,,,,,,,,,,,,,,,,,,,,,,,,,,,,,,,
,3833447811.9214,45.2132930755615,9999.6064453125,-0.000114370102175146,7.38357618827762E-8,1,2,13.4005146026611,4.99334201877844,29.899999499321,-0.152120670132026,-0.0225154758023469,1,-9.17576864232789E-7,,,,,,,,,,,,,,,,,,,,,45.1582984924316,45.2682876586914,9999.6064453125,9999.6064453125,46.9629771352069,5.2617221488443,14.1038455963135,27,1,0,0,1,0.277099609375,36.6568908691406,2,1,1,45.1582984924316,0,45.2132930755615,,,,,,,,,,,,,,,,,,,,,,,,,,,,,,,,,
,3833447868.36267,42.3810272216797,9999.6064453125,-0.000112297216044786,3.36810254396482E-8,1,2,13.4005146026611,4.99338300944718,29.899999499321,-0.149365668490563,-0.0221047155130765,1,-8.98745874652532E-7,,,,,,,,,,,,,,,,,,,,,42.3274459838867,42.4346084594727,9999.6064453125,9999.6064453125,46.9020101107069,5.262115993418,13.7198371887207,27,1,0,0,1,0.286788940429687,37.1456527709961,2,1,1,42.3274459838867,0,42.3810272216797,,,,,,,,,,,,,,,,,,,,,,,,,,,,,,,,,
,3833447932.82692,39.153190612793,9999.6064453125,-0.000110650600488785,4.15986833821535E-8,1,2,13.4005146026611,4.99339184766336,29.8900008201599,-0.147173014187153,-0.0218011046644104,1,-9.00931236456747E-7,,,,,,,,,,,,,,,,,,,,,39.1129150390625,39.1934661865234,9999.6064453125,9999.6064453125,46.8902856829184,5.26160630704871,13.3258943557739,27,1,0,0,1,0.275497436523438,36.6568908691406,2,1,1,39.1129150390625,0,39.153190612793,,,,,,,,,,,,,,,,,,,,,,,,,,,,,,,,,
,3833447991.44023,36.1987590789795,9999.6064453125,-0.000108732573764728,3.9490635847864E-8,1,2,13.4005146026611,4.99342446797722,29.8900008201599,-0.14462867583915,-0.0213842272599428,1,-8.55900875641544E-7,,,,,,,,,,,,,,,,,,,,,36.1505165100098,36.2470016479492,9999.6064453125,9999.6064453125,46.9223324522069,5.26149422806478,12.9583740234375,27,1,0,0,1,0.276412963867187,37.1456527709961,2,1,1,36.1505165100098,0,36.1987590789795,,,,,,,,,,,,,,,,,,,,,,,,,,,,,,,,,
,3833448057.12017,32.8987426757812,9999.6064453125,-0.000106559572612439,4.79029084354167E-8,1,2,13.4005146026611,4.99345038059374,29.8800002783537,-0.141733245908442,-0.0210003528314683,1,-8.71340387581983E-7,,,,,,,,,,,,,,,,,,,,,32.8987426757812,32.8987426757812,9999.6064453125,9999.6064453125,46.893803011255,5.26138168321471,12.5460958480835,27,1,0,0,1,0.273284912109375,36.6568908691406,2,1,1,32.8987426757812,0,32.8987426757812,,,,,,,,,,,,,,,,,,,,,,,,,,,,,,,,,
,3833448124.21463,29.556432723999,9999.6064453125,-0.000103567828374765,4.12640754034422E-8,1,2,13.4005146026611,4.99349219082524,29.8800002783537,-0.137753120688025,-0.0204283841552882,1,-8.5994258201952E-7,,,,,,,,,,,,,,,,,,,,,29.5028514862061,29.610013961792,9999.6064453125,9999.6064453125,46.8773888123511,5.26163901217566,12.114559173584,27,1,0,0,1,0.286407470703125,36.6568908691406,2,1,1,29.5028514862061,0,29.556432723999,,,,,,,,,,,,,,,,,,,,,,,,,,,,,,,,,
,3833448180.62953,26.6939210891724,9999.6064453125,-0.000100181239420418,4.5713361552108E-8,1,2,13.4005146026611,4.99357650661266,29.8800002783537,-0.133261792554355,-0.0196892506189031,1,-7.78056760117983E-7,,,,,,,,,,,,,,,,,,,,,26.6444244384766,26.7434177398682,9999.6064453125,9999.6064453125,46.9821270339281,5.26229989620692,11.7215566635132,27,1,0,0,1,0.27557373046875,36.6568908691406,2,1,1,26.6444244384766,0,26.6939210891724,,,,,,,,,,,,,,,,,,,,,,,,,,,,,,,,,
,3833448253.17458,23.0988655090332,9999.6064453125,-9.47468947849844E-5,5.29944384050412E-8,1,2,13.4005146026611,4.99361259000743,29.8800002783537,-0.126027131580806,-0.0186722048935326,1,-7.74010620116284E-7,,,,,,,,,,,,,,,,,,,,,23.0561008453369,23.1416301727295,9999.6064453125,9999.6064453125,46.9184243096107,5.262619236844,11.1146020889282,27,1,0,0,1,0.273666381835938,36.6568908691406,2,1,1,23.0561008453369,0,23.0988655090332,,,,,,,,,,,,,,,,,,,,,,,,,,,,,,,,,
,3833448307.84789,20.3859958648682,9999.6064453125,-8.94851206851064E-5,4.86426602403499E-8,1,2,13.4005146026611,4.99361166540887,29.8699997365475,-0.119029433691583,-0.0176262548433049,1,-7.24279735861554E-7,,,,,,,,,,,,,,,,,,,,,20.3485813140869,20.4234104156494,9999.6064453125,9999.6064453125,46.8672276416011,5.26202682972219,10.544337272644,27,1,0,0,1,0.286483764648438,36.6568908691406,2,1,1,20.3485813140869,0,20.3859958648682,,,,,,,,,,,,,,,,,,,,,,,,,,,,,,,,,
,3833448366.00677,17.4654216766357,9999.6064453125,-8.32324159664438E-5,3.84768052529979E-8,1,2,13.4005146026611,4.99364718560349,29.8500005155802,-0.110706845586108,-0.0164418249123934,1,-7.0898863374771E-7,,,,,,,,,,,,,,,,,,,,,17.4133205413818,17.5175228118896,9999.6064453125,9999.6064453125,46.9535975929761,5.26227602652983,9.92821216583252,27,1,0,0,1,0.277175903320313,36.6568908691406,2,1,1,17.4133205413818,0,17.4654216766357,,,,,,,,,,,,,,,,,,,,,,,,,,,,,,,,,
,3833448422.38716,14.7192192077637,9999.6064453125,-7.45143702611137E-5,5.4687517169432E-8,1,2,13.4005146026611,4.99359040080377,29.8500005155802,-0.0991158402987517,-0.0146740107012909,1,-6.00624666412719E-7,,,,,,,,,,,,,,,,,,,,,14.6773309707642,14.7611074447632,9999.6064453125,9999.6064453125,46.9172518668319,5.26259907626745,4.62600660324097,27,1,0,0,1,0.286102294921875,36.6568908691406,2,1,1,14.6773309707642,0,14.7192192077637,,,,,,,,,,,,,,,,,,,,,,,,,,,,,,,,,
,3833448478.91822,11.960871219635,9999.6064453125,-6.26194730273228E-5,4.65160400646568E-8,1,2,13.4005146026611,4.99367389049855,29.8500005155802,-0.0832936813328343,-0.0123460202119864,1,-5.15388087571608E-7,,,,,,,,,,,,,,,,,,,,,11.9169301986694,12.0048122406006,9999.6064453125,9999.6064453125,46.9274130375819,5.26285869579395,4.19321203231812,26,1,32,0,0,0.286483764648438,37.1456527709961,2,1,1,11.9169301986694,0,11.960871219635,,,,,,,,,,,,,,,,,,,,,,,,,,,,,,,,,
,3833448545.42266,9.0096697807312,9999.6064453125,-4.36113487714228E-5,6.05106190511434E-8,1,2,13.4005146026611,4.99371321284918,29.8500005155802,-0.0580125854073034,-0.00858379999397521,1,-3.47917296293318E-7,,,,,,,,,,,,,,,,,,,,,8.9668025970459,9.0525369644165,9999.6064453125,9999.6064453125,46.9207691951684,5.26274639943642,3.82895350456238,27,1,0,0,1,0.273361206054687,37.1456527709961,6,1,1,8.9668025970459,0,9.0096697807312,,,,,,,,,,,,,,,,,,,,,,,,,,,,,,,,,
,3833448599.9341,8.00048780441284,9999.6064453125,-3.5170300573362E-5,4.48747053131989E-8,1,2,13.4005146026611,4.99369579077057,29.8500005155802,-0.0467855299113815,-0.00691091984134236,1,-2.71987934617701E-7,,,,,,,,,,,,,,,,,,,,,8.00004100799561,8.00093460083008,9999.6064453125,9999.6064453125,46.9606322496492,5.26290251065205,3.71298551559448,27,1,0,0,1,0.277481079101562,37.1456527709961,5,1,1,8.00004100799561,0,8.00048780441284,,,,,,,,,,,,,,,,,,,,,,,,,,,,,,,,,
,3833448627.95567,8.0000114440918,9999.6064453125,-3.51375014987649E-5,3.95079024597885E-8,1,2,13.4005146026611,4.99367460397965,29.8500005155802,-0.0467424197412552,-0.00689876509566005,1,-2.67476809816819E-7,,,,,,,,,,,,,,,,,,,,,8.00000858306885,8.00001430511475,9999.6064453125,9999.6064453125,46.9180334953511,5.26294756643493,3.70139408111572,27,1,0,0,1,0.275650024414062,37.1456527709961,1,1,1,7.99998712539673,0,8.0000114440918,,,,,,,,,,,,,,,,,,,,,,,,,,,,,,,,,