File: SI Fig S11-13 SQUID all/Michaela_Tb_FC1T.dat
[Header]
; MPMS3 Data File (default extension .dat)
; Copyright (c) 2007, Quantum Design, Inc. All rights reserved.
TITLE,
FILEOPENTIME,3834070700.73838,06/28/2021,7:39 pm
BYAPP,MPMS3 w/ AC,1.0,1.1
INFO,MPMS3 Measurement Release 1.1.16 Build 424, MultiVu Release 2.3.4.19,APPNAME
INFO,Linear Motor Servo Controller,MOTOR_MODULE_NAME
INFO,3101-100 E1,MOTOR_HW_VERSION
INFO,MMC211,MOTOR_SERIAL_NUMBER
INFO,01.04.28,MOTOR_SOFTWARE_VERSION
INFO,Quantum Design Squid Module,SQUID_MODULE_NAME
INFO,3101-501 B0,SQUID_HW_VERSION
INFO,SQM059,SQUID_SERIAL_NUMBER
INFO,01.03.04,SQUID_SOFTWARE_VERSION
INFO,SQUID AC,AC_MODULE_NAME
INFO,3101-401 F1,AC_HW_VERSION
INFO,SAC057,AC_SERIAL_NUMBER
INFO,SQUID AC 00.95.07,AC_SOFTWARE_VERSION
INFO,TCIXXX,COIL_SERIAL_NUMBER
INFO,0,MOMENT_UNITS
INFO,Michaela_Tb,SAMPLE_MATERIAL
INFO,Michaela_Tb,SAMPLE_COMMENT
INFO,1.8,SAMPLE_MASS
INFO,,SAMPLE_VOLUME
INFO,,SAMPLE_MOLECULAR_WEIGHT
INFO,,SAMPLE_SIZE
INFO,,SAMPLE_SHAPE
INFO,Straw,SAMPLE_HOLDER
INFO,Standard,SAMPLE_HOLDER_DETAIL
INFO,55,SAMPLE_OFFSET
DATATYPE,COMMENT,1
DATATYPE,TIME,2
STARTUPAXIS,X,2
STARTUPAXIS,Y1,5
FIELDGROUP, VSM,2,3,4,5,6,8,9,10,11,14,15
FIELDGROUP, DC, 2,3,4,14,56,57,58,59,60,61,62,63,64,65,66,67,68,69
FIELDGROUP, AC, 2,3,4,11,16,17,18,19,20,21,22,23,24,25,26,27,28,29,30
STARTUPGROUP, All
[Data]
Comment,Time Stamp (sec),Temperature (K),Magnetic Field (Oe),Moment (emu),M. Std. Err. (emu),Transport Action,Averaging Time (sec),Frequency (Hz),Peak Amplitude (mm),Center Position (mm),Lockin Signal' (V),Lockin Signal (V),Range,M. Quad. Signal (emu),AC Moment (emu),AC M. Std Err. (emu),AC Phase (deg),AC Phase Std. Err. (deg),AC Susceptibility (emu/Oe),AC Suscept. Std Err. (emu/Oe),AC X' (emu/Oe),AC X' Std Err. (emu/Oe),AC X'' (emu/Oe),AC X'' Std Err. (emu/Oe),AC Drive (Oe),AC Frequency (Hz),AC Averaging Time (sec),AC Cycles,AC Range,AC Measure Type,AC Signal' (V),AC Signal'' (V),AC Trim Coil Ratio,AC Trim Coil Phase,Min. Temperature (K),Max. Temperature (K),Min. Field (Oe),Max. Field (Oe),Mass (grams),Motor Lag (deg),Pressure (Torr),Measure Count,Measurement Number,SQUID Status (code),Motor Status (code),Measure Status (code),Motor Current (amps),Motor Temp. (C),Temp. Status (code),Field Status (code),Chamber Status (code),Chamber Temp (K),Redirection State,Average Temp (K),Rotation Angle (deg),Rotator state,DC Moment Fixed Ctr (emu),DC Moment Err Fixed Ctr (emu),DC Moment Free Ctr (emu),DC Moment Err Free Ctr (emu),DC Fixed Fit,DC Free Fit,DC Calculated Center (mm),DC Calculated Center Err (mm),DC Scan Length (mm),DC Scan Time (s),DC Number of Points,DC Squid Drift,DC Min V (V),DC Max V (V),DC Scans per Measure,Map 01,Map 02,Map 03,Map 04,Map 05,Map 06,Map 07,Map 08,Map 09,Map 10,Map 11,Map 12,Map 13,Map 14,Map 15,Map 16
,3834070706.7133,299.944946289063,9999.755859375,0.000657508557826869,6.02545340702219E-8,1,2,13.4005146026611,4.99243145092349,32.1700014173985,0.874257905127777,0.129826041939324,1,5.5890510470937E-6,,,,,,,,,,,,,,,,,,,,,299.944946289063,299.944946289063,9999.755859375,9999.755859375,47.2560878299185,5.28728711549205,12.9387550354004,27,1,0,0,1,0.276870727539062,39.5894432067871,1,1,1,299.944946289063,0,299.944946289063,,,,,,,,,,,,,,,,,,,,,,,,,,,,,,,,,
,3834070735.19791,299.143127441406,9999.755859375,0.000660291166757866,8.54541069899083E-8,1,2,13.4005146026611,4.99234871845127,32.1599990129471,0.877913263923825,0.130548488588684,1,5.74489819213995E-6,,,,,,,,,,,,,,,,,,,,,299.105224609375,299.181030273438,9999.755859375,9999.755859375,47.32565276813,5.28777618681979,12.9576234817505,25,1,64,0,0,0.277175903320313,40.0782012939453,2,1,1,299.105224609375,0,299.143127441406,,,,,,,,,,,,,,,,,,,,,,,,,,,,,,,,,
,3834070766.42232,296.734039306641,9999.755859375,0.000667687707032584,6.82511409876766E-8,1,2,13.4005146026611,4.99252744870948,32.1400016546249,0.887783933700594,0.132068963570593,1,5.84801378408195E-6,,,,,,,,,,,,,,,,,,,,,296.593566894531,296.87451171875,9999.755859375,9999.755859375,47.3393312672166,5.28689903996699,12.9808187484741,27,1,0,0,1,0.275344848632813,39.5894432067871,2,1,1,296.593566894531,0,296.734039306641,,,,,,,,,,,,,,,,,,,,,,,,,,,,,,,,,
,3834070797.47288,293.809921264648,9999.755859375,0.000675400610185972,8.00597763826942E-8,1,2,13.4005146026611,4.99260502380724,32.1400016546249,0.898080488752146,0.133439709710676,1,5.79710121576045E-6,,,,,,,,,,,,,,,,,,,,,293.720275878906,293.899566650391,9999.755859375,9999.755859375,47.2623408580723,5.2861266143418,13.0204086303711,25,1,64,0,0,0.275039672851562,39.5894432067871,2,1,1,293.720275878906,0,293.809921264648,,,,,,,,,,,,,,,,,,,,,,,,,,,,,,,,,
,3834070827.97492,291.103759765625,9999.755859375,0.00068261896673923,6.92536526355023E-8,1,2,13.4005146026611,4.99242789342823,32.1099981665611,0.907603766378046,0.135079879426331,1,6.02475945007642E-6,,,,,,,,,,,,,,,,,,,,,290.982513427734,291.225006103516,9999.755859375,9999.755859375,47.3405037099954,5.28654895820276,13.0748023986816,27,1,0,0,1,0.277557373046875,39.5894432067871,2,1,1,290.982513427734,0,291.103759765625,,,,,,,,,,,,,,,,,,,,,,,,,,,,,,,,,
,3834070858.4382,288.564529418945,9999.755859375,0.000689893478670319,5.67218535366226E-8,1,2,13.4005146026611,4.99266959804885,32.090000808239,0.917347084228827,0.136454530399283,1,6.03343885244066E-6,,,,,,,,,,,,,,,,,,,,,288.551483154297,288.577575683594,9999.755859375,9999.755859375,47.3616076800146,5.28611747052798,13.1357975006104,26,1,64,0,0,0.275497436523438,39.5894432067871,2,1,1,288.551483154297,0,288.564529418945,,,,,,,,,,,,,,,,,,,,,,,,,,,,,,,,,
,3834070888.10583,286.175842285156,9999.755859375,0.000696920575681948,3.29911062432388E-8,1,2,13.4005146026611,4.99246214135969,32.090000808239,0.926663417212753,0.13765624535409,1,5.95943422153143E-6,,,,,,,,,,,,,,,,,,,,,286.097381591797,286.254302978516,9999.755859375,9999.755859375,47.3600444229762,5.2861045282013,13.2113046646118,27,1,0,0,1,0.274200439453125,39.5894432067871,2,1,1,286.097381591797,0,286.175842285156,,,,,,,,,,,,,,,,,,,,,,,,,,,,,,,,,
,3834070920.40818,283.601226806641,9999.755859375,0.000704000872291764,6.87335138930045E-8,1,2,13.4005146026611,4.99247313253944,32.0699997246265,0.936087296282922,0.139007192843912,1,5.98393926583101E-6,,,,,,,,,,,,,,,,,,,,,283.534851074219,283.667602539062,9999.755859375,9999.755859375,47.2830540138319,5.2866362511821,13.2864990234375,27,1,0,0,1,0.276947021484375,39.5894432067871,2,1,1,283.534851074219,0,283.601226806641,,,,,,,,,,,,,,,,,,,,,,,,,,,,,,,,,
,3834070948.69859,281.458084106445,9999.755859375,0.000710659714366699,6.79655088871975E-8,1,2,13.4005146026611,4.99225639566166,32.0699997246265,0.944843090399501,0.140614287181027,1,6.26638008627978E-6,,,,,,,,,,,,,,,,,,,,,281.389190673828,281.526977539062,9999.755859375,9999.755859375,47.208799304505,5.28707595738757,13.2638883590698,27,1,0,0,1,0.27740478515625,39.5894432067871,2,1,1,281.389190673828,0,281.458084106445,,,,,,,,,,,,,,,,,,,,,,,,,,,,,,,,,
,3834070980.86612,278.801330566406,9999.755859375,0.000718129201522144,6.1957159243782E-8,1,2,13.4005146026611,4.99227560087529,32.0499986410141,0.954788281824381,0.142026799650416,1,6.28252643538745E-6,,,,,,,,,,,,,,,,,,,,,278.718841552734,278.883819580078,9999.755859375,9999.755859375,47.279927499755,5.28678522628835,13.2048673629761,26,1,64,0,0,0.27679443359375,39.5894432067871,2,1,1,278.718841552734,0,278.801330566406,,,,,,,,,,,,,,,,,,,,,,,,,,,,,,,,,
,3834071011.13435,276.341430664062,9999.755859375,0.000725410002828302,7.98187106367659E-8,1,2,13.4005146026611,4.99230621307433,32.030001282692,0.964509008805719,0.143235967798395,1,6.17195265404766E-6,,,,,,,,,,,,,,,,,,,,,276.262542724609,276.420318603516,9999.755859375,9999.755859375,47.3682515224281,5.28660260789559,13.1650257110596,27,1,0,0,1,0.276947021484375,39.5894432067871,2,1,1,276.262542724609,0,276.341430664062,,,,,,,,,,,,,,,,,,,,,,,,,,,,,,,,,
,3834071041.43357,273.807525634766,9999.755859375,0.000733102600718483,4.1825705343678E-8,1,2,13.4005146026611,4.99249095884209,32.030001282692,0.974782570782655,0.144790796049274,1,6.25884415271441E-6,,,,,,,,,,,,,,,,,,,,,273.758575439453,273.856475830078,9999.755859375,9999.755859375,47.3092385692262,5.28593687900154,13.1530275344849,27,1,0,0,1,0.276870727539062,39.5894432067871,2,1,1,273.758575439453,0,273.807525634766,,,,,,,,,,,,,,,,,,,,,,,,,,,,,,,,,
,3834071070.71336,271.287414550781,9999.755859375,0.000740603367320392,1.02417899941911E-7,1,2,13.4005146026611,4.99250383569635,32.0100001990795,0.984756150776704,0.146297240980324,1,6.34128195642583E-6,,,,,,,,,,,,,,,,,,,,,271.155822753906,271.419006347656,9999.755859375,9999.755859375,47.2928243703223,5.28569272949284,13.1074533462524,27,1,0,0,1,0.2752685546875,39.5894432067871,2,1,1,271.155822753906,0,271.287414550781,,,,,,,,,,,,,,,,,,,,,,,,,,,,,,,,,
,3834071101.93755,268.802215576172,9999.755859375,0.000748208124979082,7.9144004848881E-8,1,2,13.4005146026611,4.99232604772551,31.9899991154671,0.994805077827533,0.147894667924342,1,6.48332860000421E-6,,,,,,,,,,,,,,,,,,,,,268.753509521484,268.850921630859,9999.755859375,9999.755859375,47.2295124602646,5.28650872321753,13.1013307571411,26,1,64,0,0,0.276336669921875,40.0782012939453,2,1,1,268.753509521484,0,268.802215576172,,,,,,,,,,,,,,,,,,,,,,,,,,,,,,,,,
,3834071132.23361,266.237731933594,9999.755859375,0.000756178245257309,1.10779238435169E-7,1,2,13.4005146026611,4.99261893345449,31.9899991154671,1.00545923888929,0.149650975525502,1,6.67924038722864E-6,,,,,,,,,,,,,,,,,,,,,266.126373291016,266.349090576172,9999.755859375,9999.755859375,47.30533042663,5.28506012510402,13.0906934738159,27,1,0,0,1,0.27496337890625,40.0782012939453,2,1,1,266.126373291016,0,266.237731933594,,,,,,,,,,,,,,,,,,,,,,,,,,,,,,,,,
,3834071164.12802,263.656860351562,9999.755859375,0.000764478450569685,8.22939808231245E-8,1,2,13.4005146026611,4.99263732232684,31.9700017571449,1.01650053465164,0.151296373952861,1,6.75404840598276E-6,,,,,,,,,,,,,,,,,,,,,263.586883544922,263.726837158203,9999.755859375,9999.755859375,47.3541822090819,5.28520272318575,13.0810537338257,27,1,0,0,1,0.276412963867187,40.0782012939453,2,1,1,263.586883544922,0,263.656860351562,,,,,,,,,,,,,,,,,,,,,,,,,,,,,,,,,
,3834071194.3526,261.093231201172,9999.755859375,0.000772836339289717,9.51396476954544E-8,1,2,13.4005146026611,4.99252572117509,31.9700017571449,1.02757244299984,0.153015931401145,1,6.88058311552571E-6,,,,,,,,,,,,,,,,,,,,,260.991790771484,261.194671630859,9999.755859375,9999.755859375,47.3518373235242,5.28579383315713,13.0666904449463,27,1,0,0,1,0.276107788085938,40.0782012939453,2,1,1,260.991790771484,0,261.093231201172,,,,,,,,,,,,,,,,,,,,,,,,,,,,,,,,,
,3834071226.887,258.392135620117,9999.755859375,0.000781551610784908,9.47893060308154E-8,1,2,13.4005146026611,4.99237005187355,31.9500006735325,1.03916356722604,0.154394454778247,1,6.70245035706195E-6,,,,,,,,,,,,,,,,,,,,,258.357788085938,258.426483154297,9999.755859375,9999.755859375,47.2279492032262,5.2866210307904,13.0568141937256,27,1,0,0,1,0.278244018554687,39.5894432067871,2,1,1,258.357788085938,0,258.392135620117,,,,,,,,,,,,,,,,,,,,,,,,,,,,,,,,,
,3834071254.762,256.110061645508,9999.755859375,0.000789397046494422,5.65659256454417E-8,1,2,13.4005146026611,4.99121616529496,31.9399982690811,1.04925053553201,0.155980525801052,1,6.83406469682071E-6,,,,,,,,,,,,,,,,,,,,,256.014953613281,256.205169677734,9999.755859375,9999.755859375,47.4006891059762,5.29080279739277,13.0516195297241,27,1,0,0,1,0.279159545898438,39.5894432067871,2,1,1,256.014953613281,0,256.110061645508,,,,,,,,,,,,,,,,,,,,,,,,,,,,,,,,,
,3834071284.96655,253.529960632324,9999.755859375,0.000797869565587032,6.95140829722805E-8,1,2,13.4005146026611,4.99232897200383,31.92999958992,1.06079868178835,0.157970553813919,1,7.10853172115017E-6,,,,,,,,,,,,,,,,,,,,,253.429550170898,253.63037109375,9999.755859375,9999.755859375,47.3436302240723,5.28609926300771,13.0393857955933,27,1,0,0,1,0.277099609375,40.0782012939453,2,1,1,253.429550170898,0,253.529960632324,,,,,,,,,,,,,,,,,,,,,,,,,,,,,,,,,
,3834071315.42816,250.986099243164,9999.755859375,0.000806482099386132,9.84157998035773E-8,1,2,13.4005146026611,4.99240993582419,31.9099985063076,1.07229851203109,0.159498360044668,1,7.04934285492757E-6,,,,,,,,,,,,,,,,,,,,,250.884719848633,251.087478637695,9999.755859375,9999.755859375,47.3416761527742,5.28574708799329,13.0169973373413,27,1,0,0,1,0.277023315429687,39.5894432067871,2,1,1,250.884719848633,0,250.986099243164,,,,,,,,,,,,,,,,,,,,,,,,,,,,,,,,,
,3834071343.75719,248.621841430664,9999.755859375,0.000814980831617272,8.91705852198671E-8,1,2,13.4005146026611,4.99249862608224,31.9099985063076,1.08360590079942,0.161318295568252,1,7.225196822684E-6,,,,,,,,,,,,,,,,,,,,,248.509063720703,248.734619140625,9999.755859375,9999.755859375,47.2459266591685,5.28552171042686,13.0201168060303,27,1,0,0,1,0.274887084960938,39.5894432067871,2,1,1,248.509063720703,0,248.621841430664,,,,,,,,,,,,,,,,,,,,,,,,,,,,,,,,,
,3834071375.64026,245.967041015625,9999.755859375,0.000824641204665184,5.88692746082885E-8,1,2,13.4005146026611,4.99259886898828,31.8900011479855,1.09648408307472,0.163209993580543,1,7.29207743120887E-6,,,,,,,,,,,,,,,,,,,,,245.90007019043,246.03401184082,9999.755859375,9999.755859375,47.2826631995723,5.28560076120019,13.0014810562134,27,1,0,0,1,0.276641845703125,40.0782012939453,2,1,1,245.90007019043,0,245.967041015625,,,,,,,,,,,,,,,,,,,,,,,,,,,,,,,,,
,3834071403.87924,243.660827636719,9999.755859375,0.000833317968162552,8.10085297942322E-8,1,2,13.4005146026611,4.99257510301733,31.8900011479855,1.10803830972166,0.164751703690631,1,7.2377369036877E-6,,,,,,,,,,,,,,,,,,,,,243.589309692383,243.732345581055,9999.755859375,9999.755859375,47.3236986968319,5.28526637244443,12.9782676696777,27,1,0,0,1,0.276718139648438,39.5894432067871,2,1,1,243.589309692383,0,243.660827636719,,,,,,,,,,,,,,,,,,,,,,,,,,,,,,,,,
,3834071436.16925,240.919281005859,9999.755859375,0.000843316264562519,1.05987279714549E-7,1,2,13.4005146026611,4.99253712423687,31.870000064373,1.12127350635657,0.167066786128533,1,7.5800465886849E-6,,,,,,,,,,,,,,,,,,,,,240.856521606445,240.982040405273,9999.755859375,9999.755859375,47.3412853385146,5.28554506785657,12.961428642273,27,1,0,0,1,0.27587890625,39.5894432067871,2,1,1,240.856521606445,0,240.919281005859,,,,,,,,,,,,,,,,,,,,,,,,,,,,,,,,,
,3834071464.49722,238.606842041016,9999.755859375,0.000852392165335708,5.83148050359102E-8,1,2,13.4005146026611,4.99258219430533,31.870000064373,1.13337953791081,0.168690286301418,1,7.52898020299432E-6,,,,,,,,,,,,,,,,,,,,,238.551712036133,238.661972045898,9999.755859375,9999.755859375,47.3877922354089,5.28483911510264,12.9419059753418,27,1,0,0,1,0.276947021484375,39.5894432067871,2,1,1,238.551712036133,0,238.606842041016,,,,,,,,,,,,,,,,,,,,,,,,,,,,,,,,,
,3834071496.56335,235.929229736328,9999.755859375,0.000862848574536653,8.25169964194861E-8,1,2,13.4005146026611,4.9926692656129,31.8600013852119,1.14731073682828,0.170760424134045,1,7.61886820984636E-6,,,,,,,,,,,,,,,,,,,,,235.832321166992,236.026138305664,9999.755859375,9999.755859375,47.3010314697742,5.28465051429166,12.9323167800903,27,1,0,0,1,0.2734375,39.5894432067871,2,1,1,235.832321166992,0,235.929229736328,,,,,,,,,,,,,,,,,,,,,,,,,,,,,,,,,
,3834071524.75211,233.554298400879,9999.755859375,0.000872317434805433,1.08310420585389E-7,1,2,13.4005146026611,4.99268961710356,31.8499989807606,1.15990902410673,0.172626199792033,1,7.69563778663849E-6,,,,,,,,,,,,,,,,,,,,,233.454498291016,233.654098510742,9999.755859375,9999.755859375,47.3193997399762,5.28503660975675,12.9325551986694,27,1,0,0,1,0.27587890625,39.5894432067871,2,1,1,233.454498291016,0,233.554298400879,,,,,,,,,,,,,,,,,,,,,,,,,,,,,,,,,
,3834071555.23864,231.088073730469,9999.755859375,0.000882392723952975,9.34409419769252E-8,1,2,13.4005146026611,4.9928604166643,31.8300016224384,1.17332610087781,0.174877879730705,1,7.97203816699497E-6,,,,,,,,,,,,,,,,,,,,,230.994506835938,231.181640625,9999.755859375,9999.755859375,47.3287792822069,5.28454172381996,12.9253931045532,27,1,0,0,1,0.276031494140625,39.5894432067871,2,1,1,230.994506835938,0,231.088073730469,,,,,,,,,,,,,,,,,,,,,,,,,,,,,,,,,
,3834071585.5199,228.503730773926,9999.755859375,0.000892933847629543,5.8201457035984E-8,1,2,13.4005146026611,4.99288338883211,31.8300016224384,1.18739030054318,0.17668144837767,1,7.85197282642294E-6,,,,,,,,,,,,,,,,,,,,,228.434417724609,228.573043823242,9999.755859375,9999.755859375,47.3678607081685,5.28465884446448,12.9117097854614,27,1,0,0,1,0.273590087890625,39.5894432067871,2,1,1,228.434417724609,0,228.503730773926,,,,,,,,,,,,,,,,,,,,,,,,,,,,,,,,,
,3834071615.47081,226.015830993652,9999.755859375,0.000903643730855571,5.63931503193621E-8,1,2,13.4005146026611,4.99285465843048,31.810000538826,1.20161016376249,0.178886895372142,1,8.01204531860367E-6,,,,,,,,,,,,,,,,,,,,,225.921981811523,226.109680175781,9999.755859375,9999.755859375,47.3623893085339,5.28436202502409,12.9138879776001,25,1,64,0,0,0.276031494140625,39.5894432067871,2,1,1,225.921981811523,0,226.015830993652,,,,,,,,,,,,,,,,,,,,,,,,,,,,,,,,,
,3834071647.86339,223.334197998047,9999.755859375,0.00091519729710741,7.59880037884481E-8,1,2,13.4005146026611,4.99289996572633,31.810000538826,1.21699586603162,0.1811237924132,1,8.07503651130546E-6,,,,,,,,,,,,,,,,,,,,,223.273651123047,223.394744873047,9999.755859375,9999.755859375,47.3061120551492,5.28386366740243,12.90478515625,25,1,64,0,0,0.276718139648438,39.5894432067871,2,1,1,223.273651123047,0,223.334197998047,,,,,,,,,,,,,,,,,,,,,,,,,,,,,,,,,
,3834071676.05377,221.029472351074,9999.755859375,0.000925604446381362,7.36415691574506E-8,1,2,13.4005146026611,4.99290161262067,31.7899994552135,1.23083378723509,0.18319554566509,1,8.17589312022074E-6,,,,,,,,,,,,,,,,,,,,,220.962783813477,221.096160888672,9999.755859375,9999.755859375,47.3580903516781,5.28353323377486,12.9233016967773,27,1,0,0,1,0.2752685546875,39.5894432067871,2,1,1,220.962783813477,0,221.029472351074,,,,,,,,,,,,,,,,,,,,,,,,,,,,,,,,,
,3834071708.09916,218.304260253906,9999.755859375,0.000937888939642271,7.55765138999517E-8,1,2,13.4005146026611,4.99306426444557,31.7899994552135,1.24720870052476,0.185751148839505,1,8.3715026521676E-6,,,,,,,,,,,,,,,,,,,,,218.21369934082,218.394821166992,9999.755859375,9999.755859375,47.2975141414377,5.28321569734409,12.9042520523071,27,1,0,0,1,0.278472900390625,39.5894432067871,2,1,1,218.21369934082,0,218.304260253906,,,,,,,,,,,,,,,,,,,,,,,,,,,,,,,,,
,3834071736.29747,215.952903747559,9999.755859375,0.000948805102440767,1.05498445208264E-7,1,2,13.4005146026611,4.99299098392685,31.7699983716011,1.26170700444322,0.187856997604449,1,8.4296251801207E-6,,,,,,,,,,,,,,,,,,,,,215.860092163086,216.045715332031,9999.755859375,9999.755859375,47.3522281377839,5.28398653630213,12.9113540649414,27,1,0,0,1,0.274200439453125,40.0782012939453,2,1,1,215.860092163086,0,215.952903747559,,,,,,,,,,,,,,,,,,,,,,,,,,,,,,,,,
,3834071766.77685,213.474586486816,9999.755859375,0.000960753531721129,7.57642318212658E-8,1,2,13.4005146026611,4.99295850197085,31.7699983716011,1.27757626929303,0.190279589232402,1,8.57977782297594E-6,,,,,,,,,,,,,,,,,,,,,213.384643554687,213.564529418945,9999.755859375,9999.755859375,47.3354231246204,5.28375895658848,12.90940284729,27,1,0,0,1,0.27862548828125,39.5894432067871,2,1,1,213.384643554687,0,213.474586486816,,,,,,,,,,,,,,,,,,,,,,,,,,,,,,,,,
,3834071797.18491,210.81990814209,9999.755859375,0.0009728114443385,1.44021495799451E-7,1,2,13.4005146026611,4.99280659340592,31.750001013279,1.29356116194379,0.192626492546128,1,8.6625490626019E-6,,,,,,,,,,,,,,,,,,,,,210.786880493164,210.852935791016,9999.755859375,9999.755859375,47.2810999425338,5.2849934913702,12.9161643981934,26,1,64,0,0,0.27679443359375,39.5894432067871,2,1,1,210.786880493164,0,210.81990814209,,,,,,,,,,,,,,,,,,,,,,,,,,,,,,,,,
,3834071826.97647,208.253257751465,9999.755859375,0.000985942481975577,8.72636064503807E-8,1,2,13.4005146026611,4.99282083479667,31.750001013279,1.31102726479719,0.19522410403347,1,8.7770505739172E-6,,,,,,,,,,,,,,,,,,,,,208.164077758789,208.342437744141,9999.755859375,9999.755859375,47.2740652858608,5.28485919287558,12.896427154541,27,1,0,0,1,0.278472900390625,39.5894432067871,2,1,1,208.164077758789,0,208.253257751465,,,,,,,,,,,,,,,,,,,,,,,,,,,,,,,,,
,3834071857.26821,205.603271484375,9999.755859375,0.00099927856710883,8.58051202884492E-8,1,2,13.4005146026611,4.99301851519254,31.7299999296665,1.32884221746559,0.197806803029279,1,8.84418624469731E-6,,,,,,,,,,,,,,,,,,,,,205.531677246094,205.674865722656,9999.755859375,9999.755859375,47.3319057962839,5.28478811527072,12.8758840560913,27,1,0,0,1,0.275421142578125,39.5894432067871,2,1,1,205.531677246094,0,205.603271484375,,,,,,,,,,,,,,,,,,,,,,,,,,,,,,,,,
,3834071885.54874,203.307220458984,9999.755859375,0.00101156280295762,6.52012073255964E-8,1,2,13.4005146026611,4.99313460530732,31.7399986088276,1.34520606854716,0.200349279033377,1,9.0313446201226E-6,,,,,,,,,,,,,,,,,,,,,203.217361450195,203.397079467773,9999.755859375,9999.755859375,47.3471475524089,5.28303081471357,12.8725090026855,27,1,0,0,1,0.273208618164062,39.5894432067871,2,1,1,203.217361450195,0,203.307220458984,,,,,,,,,,,,,,,,,,,,,,,,,,,,,,,,,
,3834071934.96675,199.128967285156,9999.755859375,0.00103408720001052,7.05085572331308E-8,1,2,13.4005146026611,4.99313702470482,31.7099988460541,1.37507730105099,0.205406254487868,1,9.67981979916301E-6,,,,,,,,,,,,,,,,,,,,,198.981460571289,199.276473999023,9999.755859375,9999.755859375,47.2318573458223,5.28232076615715,12.8581714630127,27,1,0,0,1,0.27679443359375,39.5894432067871,2,1,1,198.981460571289,0,199.128967285156,,,,,,,,,,,,,,,,,,,,,,,,,,,,,,,,,
,3834071976.09605,195.699897766113,9999.755859375,0.00105275450923072,1.01853263904251E-7,1,2,13.4005146026611,4.99313510166882,31.7200012505054,1.39996159261064,0.208669431612365,1,9.52057356251269E-6,,,,,,,,,,,,,,,,,,,,,195.610504150391,195.789291381836,9999.755859375,9999.755859375,47.2353746741588,5.2846372360988,12.8459386825562,27,1,0,0,1,0.273208618164062,39.5894432067871,2,1,1,195.610504150391,0,195.699897766113,,,,,,,,,,,,,,,,,,,,,,,,,,,,,,,,,
,3834072024.68737,191.638824462891,9999.755859375,0.00107582421156147,1.38429579730728E-7,1,2,13.4005146026611,4.99307315641871,31.6900014877319,1.43057267478555,0.213545171047667,1,9.95951660462709E-6,,,,,,,,,,,,,,,,,,,,,191.530242919922,191.747406005859,9999.755859375,9999.755859375,47.2396736310146,5.28420018462792,12.8286533355713,27,1,0,0,1,0.27557373046875,40.0782012939453,2,1,1,191.530242919922,0,191.638824462891,,,,,,,,,,,,,,,,,,,,,,,,,,,,,,,,,
,3834072054.94807,189.211822509766,9999.755859375,0.00109110226395963,1.2672457450574E-7,1,2,13.4005146026611,4.99306409136921,31.6700004041195,1.45092744946405,0.216273576655379,1,9.87288626821015E-6,,,,,,,,,,,,,,,,,,,,,189.162185668945,189.261459350586,9999.755859375,9999.755859375,47.3061120551492,5.28337249097916,12.8064651489258,27,1,0,0,1,0.276565551757813,39.5894432067871,2,1,1,189.162185668945,0,189.211822509766,,,,,,,,,,,,,,,,,,,,,,,,,,,,,,,,,
,3834072084.86345,186.644104003906,9999.755859375,0.00110642268169037,1.54851589582296E-7,1,2,13.4005146026611,4.99303811695948,31.6700004041195,1.47127240480555,0.219432936559596,1,1.01047771880728E-5,,,,,,,,,,,,,,,,,,,,,186.545318603516,186.742889404297,9999.755859375,9999.755859375,47.2404552595338,5.2831799058453,12.7828769683838,27,1,0,0,1,0.274505615234375,39.5894432067871,2,1,1,186.545318603516,0,186.644104003906,,,,,,,,,,,,,,,,,,,,,,,,,,,,,,,,,
,3834072115.1227,184.209854125977,9999.755859375,0.00112195924033065,8.6532985627817E-8,1,2,13.4005146026611,4.99311073066028,31.6700004041195,1.49193627592519,0.222702453803723,1,1.03846903309366E-5,,,,,,,,,,,,,,,,,,,,,184.132843017578,184.286865234375,9999.755859375,9999.755859375,47.4092870196877,5.28280165876204,12.7914218902588,27,1,0,0,1,0.275726318359375,39.5894432067871,2,1,1,184.132843017578,0,184.209854125977,,,,,,,,,,,,,,,,,,,,,,,,,,,,,,,,,
,3834072147.65004,181.537300109863,9999.755859375,0.00113931188939516,9.67787682436386E-8,1,2,13.4005146026611,4.99300913692821,31.649999320507,1.51500348090148,0.225893163001804,1,1.03595009161139E-5,,,,,,,,,,,,,,,,,,,,,181.497177124023,181.577423095703,9999.755859375,9999.755859375,47.2287308317454,5.2832680128646,12.7730026245117,27,1,0,0,1,0.276336669921875,39.5894432067871,2,1,1,181.497177124023,0,181.537300109863,,,,,,,,,,,,,,,,,,,,,,,,,,,,,,,,,
,3834072175.53004,179.216812133789,9999.755859375,0.00115462812305396,9.10703753636076E-8,1,2,13.4005146026611,4.99304877975516,31.649999320507,1.53536330895733,0.22910182220556,1,1.06259926768256E-5,,,,,,,,,,,,,,,,,,,,,179.112945556641,179.320678710938,9999.755859375,9999.755859375,47.2412368880531,5.28307689186079,12.7556190490723,27,1,0,0,1,0.2862548828125,39.5894432067871,2,1,1,179.112945556641,0,179.216812133789,,,,,,,,,,,,,,,,,,,,,,,,,,,,,,,,,
,3834072207.86825,176.409950256348,9999.755859375,0.00117298547897968,1.17437997450553E-7,1,2,13.4005146026611,4.99318905196967,31.6299982368946,1.55983938040555,0.232714730203366,1,1.07660002776126E-5,,,,,,,,,,,,,,,,,,,,,176.308624267578,176.511276245117,9999.755859375,9999.755859375,47.2584327154761,5.2831317103547,12.745888710022,27,1,0,0,1,0.276718139648438,39.5894432067871,2,1,1,176.308624267578,0,176.409950256348,,,,,,,,,,,,,,,,,,,,,,,,,,,,,,,,,
,3834072238.21651,173.87720489502,9999.755859375,0.00119017714158165,6.49692493944914E-8,1,2,13.4005146026611,4.99346698613647,31.6299982368946,1.58279443974762,0.23633785095783,1,1.10697540247739E-5,,,,,,,,,,,,,,,,,,,,,173.827285766602,173.927124023438,9999.755859375,9999.755859375,47.3018130982935,5.28125333298713,12.7482643127441,27,1,0,0,1,0.285263061523438,39.5894432067871,2,1,1,173.827285766602,0,173.87720489502,,,,,,,,,,,,,,,,,,,,,,,,,,,,,,,,,
,3834072288.41833,169.707260131836,9999.755859375,0.00122081593190175,8.80926105573446E-8,1,2,13.4005146026611,4.99338619216361,31.6199995577335,1.62350701529519,0.24239785372505,1,1.13406948326463E-5,,,,,,,,,,,,,,,,,,,,,169.627258300781,169.787261962891,9999.755859375,9999.755859375,47.2725020288223,5.28287480235458,12.713059425354,25,1,64,0,0,0.274887084960938,39.5894432067871,2,1,1,169.627258300781,0,169.707260131836,,,,,,,,,,,,,,,,,,,,,,,,,,,,,,,,,
,3834072326.66836,166.550445556641,9999.755859375,0.00124466208176567,8.23702545520408E-8,1,2,13.4005146026611,4.99349667173406,31.6100008785725,1.65525917027316,0.247211069446329,1,1.16155123708695E-5,,,,,,,,,,,,,,,,,,,,,166.482528686523,166.618362426758,9999.755859375,9999.755859375,47.2764101714185,5.28059889837394,12.71555519104,27,1,0,0,1,0.285186767578125,39.5894432067871,2,1,1,166.482528686523,0,166.550445556641,,,,,,,,,,,,,,,,,,,,,,,,,,,,,,,,,
,3834072359.20541,163.890640258789,9999.755859375,0.00126565531052244,1.02690730287368E-7,1,2,13.4005146026611,4.99354243131823,31.58999979496,1.68319746921395,0.251394170761273,1,1.18191858752262E-5,,,,,,,,,,,,,,,,,,,,,163.854339599609,163.926940917969,9999.755859375,9999.755859375,47.2506164302838,5.2802158909909,12.7030200958252,27,1,0,0,1,0.277938842773438,39.5894432067871,2,1,1,163.854339599609,0,163.890640258789,,,,,,,,,,,,,,,,,,,,,,,,,,,,,,,,,
,3834072409.23854,159.700202941895,9999.755859375,0.00129942034216624,1.08326606060958E-7,1,2,13.4005146026611,4.9935445709454,31.580001115799,1.728044474981,0.258517167078853,1,1.24470248647729E-5,,,,,,,,,,,,,,,,,,,,,159.627014160156,159.773391723633,9999.755859375,9999.755859375,47.2330297886012,5.27994645059313,12.6767749786377,27,1,0,0,1,0.29632568359375,39.5894432067871,2,1,1,159.627014160156,0,159.700202941895,,,,,,,,,,,,,,,,,,,,,,,,,,,,,,,,,
,3834072447.85473,156.452743530273,9999.755859375,0.00132661934175972,1.43279995903241E-7,1,2,13.4005146026611,4.99374857509188,31.5600000321865,1.76430459428936,0.264010649892396,1,1.27582635018012E-5,,,,,,,,,,,,,,,,,,,,,156.380859375,156.524627685547,9999.755859375,9999.755859375,47.2705479575242,5.27875799476705,12.6571865081787,27,1,0,0,1,0.277557373046875,39.5894432067871,2,1,1,156.380859375,0,156.452743530273,,,,,,,,,,,,,,,,,,,,,,,,,,,,,,,,,
,3834072488.1209,153.123229980469,9999.755859375,0.00135590779284295,1.72145067815093E-7,1,2,13.4005146026611,4.99399248062766,31.5600000321865,1.80341710543192,0.269568562618674,1,1.28230537636695E-5,,,,,,,,,,,,,,,,,,,,,153.089553833008,153.15690612793,9999.755859375,9999.755859375,47.3737229220627,5.27770762389315,12.6297750473022,27,1,0,0,1,0.28472900390625,39.5894432067871,2,1,1,153.075897216797,0,153.123229980469,,,,,,,,,,,,,,,,,,,,,,,,,,,,,,,,,
,3834072520.12135,150.450828552246,9999.755859375,0.00138073434116768,9.95875466121933E-8,1,2,13.4005146026611,4.99404558976655,31.5399989485741,1.83641749045405,0.274842874234044,1,1.33090290793557E-5,,,,,,,,,,,,,,,,,,,,,150.385192871094,150.516464233398,9999.755859375,9999.755859375,47.3338598675819,5.27811832539949,12.6038646697998,27,1,0,0,1,0.285186767578125,39.5894432067871,2,1,1,150.385192871094,0,150.450828552246,,,,,,,,,,,,,,,,,,,,,,,,,,,,,,,,,
,3834072574.13116,145.907577514648,9999.755859375,0.00142277365612663,1.43894594760256E-7,1,2,13.4005146026611,4.99413106212416,31.5399989485741,1.89285724387681,0.279771504104482,10,1.11267542286964E-5,,,,,,,,,,,,,,,,,,,,,145.907577514648,145.907577514648,9999.755859375,9999.755859375,47.2842264566108,5.27832577865549,12.5448989868164,27,1,0,0,1,0.28533935546875,39.5894432067871,2,1,1,145.907577514648,0,145.907577514648,,,,,,,,,,,,,,,,,,,,,,,,,,,,,,,,,
,3834072620.7866,142.068428039551,9999.755859375,0.00146360451427626,8.9603167266763E-8,1,2,13.4005146026611,4.99433291670953,31.5200015902519,1.94684691299905,0.290959668174041,1,1.38060490754128E-5,,,,,,,,,,,,,,,,,,,,,141.998733520508,142.138122558594,9999.755859375,9999.755859375,47.2779734284569,5.27805965085543,12.5032567977905,27,1,0,0,1,0.294723510742188,39.5894432067871,2,1,1,141.998733520508,0,142.068428039551,,,,,,,,,,,,,,,,,,,,,,,,,,,,,,,,,
,3834072649.04054,139.760810852051,9999.755859375,0.00148817858794604,8.65978139021023E-8,1,2,13.4005146026611,4.99440225401053,31.5200015902519,1.97957011464441,0.295866368669293,1,1.40497389648467E-5,,,,,,,,,,,,,,,,,,,,,139.692825317383,139.828796386719,9999.755859375,9999.755859375,47.2463174734281,5.27792848510684,12.4929714202881,27,1,0,0,1,0.28472900390625,39.5894432067871,2,1,1,139.692825317383,0,139.760810852051,,,,,,,,,,,,,,,,,,,,,,,,,,,,,,,,,
,3834072697.39737,135.67308807373,9999.755859375,0.00153294726175954,1.7429486458946E-7,1,2,13.4005146026611,4.99450522878804,31.5000005066395,2.03916004684618,0.3049099682612,1,1.45733594068279E-5,,,,,,,,,,,,,,,,,,,,,135.607360839844,135.738815307617,9999.755859375,9999.755859375,47.2932151845819,5.27751447142105,12.4697408676147,27,1,0,0,1,0.284652709960938,39.5894432067871,2,1,1,135.550842285156,0,135.67308807373,,,,,,,,,,,,,,,,,,,,,,,,,,,,,,,,,
,3834072755.77354,130.843536376953,9999.755859375,0.00159037395653362,1.30000676736931E-7,1,2,13.4005146026611,4.99449897712634,31.479999423027,2.11549905169917,0.316672392802772,1,1.53749668488493E-5,,,,,,,,,,,,,,,,,,,,,130.776550292969,130.910522460938,9999.755859375,9999.755859375,47.2619500438127,5.27774907459603,12.4178800582886,27,1,0,0,1,0.28533935546875,39.5894432067871,2,1,1,130.776550292969,0,130.843536376953,,,,,,,,,,,,,,,,,,,,,,,,,,,,,,,,,
,3834072796.07046,127.435852050781,9999.755859375,0.00163186588084824,1.45741473561601E-7,1,2,13.4005146026611,4.99453581829104,31.479999423027,2.17074387995617,0.324717461426116,1,1.5610916960681E-5,,,,,,,,,,,,,,,,,,,,,127.374450683594,127.497253417969,9999.755859375,9999.755859375,47.3170548544185,5.27738832565862,12.3996067047119,27,1,0,0,1,0.284881591796875,39.5894432067871,2,1,1,127.374450683594,0,127.435852050781,,,,,,,,,,,,,,,,,,,,,,,,,,,,,,,,,
,3834072842.47453,123.68041229248,9999.755859375,0.00168309973308694,1.88128171053474E-7,1,2,13.4005146026611,4.99461208701968,31.4599983394146,2.23890945435553,0.335159988614733,1,1.62817615598859E-5,,,,,,,,,,,,,,,,,,,,,123.607490539551,123.75333404541,9999.755859375,9999.755859375,47.2580419012165,5.27740433017814,12.3638010025024,27,1,0,0,1,0.282135009765625,39.5894432067871,2,1,1,123.607490539551,0,123.68041229248,,,,,,,,,,,,,,,,,,,,,,,,,,,,,,,,,
,3834072886.83634,119.895168304443,9999.755859375,0.00173498242437213,2.31488808975192E-7,1,2,13.4005146026611,4.99464520771212,31.4599983394146,2.30859558517946,0.340851165835491,10,1.32976643586821E-5,,,,,,,,,,,,,,,,,,,,,119.812660217285,119.977676391602,9999.755859375,9999.755859375,47.2877437849473,5.27670042683491,12.3556528091431,26,1,64,0,0,0.285110473632813,39.5894432067871,2,1,1,119.812660217285,0,119.895168304443,,,,,,,,,,,,,,,,,,,,,,,,,,,,,,,,,
,3834072919.12111,117.253818511963,9999.755859375,0.00177475367361661,2.58427378865855E-7,1,2,13.4005146026611,4.99474354063967,31.4400009810925,2.36162729959289,0.348332390763976,10,1.33460785387997E-5,,,,,,,,,,,,,,,,,,,,,117.192924499512,117.314712524414,9999.755859375,9999.755859375,47.2474899162069,5.27618563318079,12.3280820846558,27,1,0,0,1,0.294036865234375,39.5894432067871,2,1,1,117.192924499512,0,117.253818511963,,,,,,,,,,,,,,,,,,,,,,,,,,,,,,,,,
,3834072947.40284,114.891208648682,9999.755859375,0.00181014054123779,1.66846470642582E-7,1,2,13.4005146026611,4.99476846131734,31.4400009810925,2.40871107209317,0.355432207195388,10,1.3726276370003E-5,,,,,,,,,,,,,,,,,,,,,114.839981079102,114.942436218262,9999.755859375,9999.755859375,47.2779734284569,5.27618807278024,12.3099012374878,27,1,0,0,1,0.284500122070313,39.5894432067871,2,1,1,114.839981079102,0,114.891208648682,,,,,,,,,,,,,,,,,,,,,,,,,,,,,,,,,
,3834072979.42651,112.233581542969,9999.755859375,0.00185338348932817,2.86409248251657E-7,1,2,13.4005146026611,4.99458071346481,31.41999989748,2.46612781481971,0.36389465827053,10,1.40468092944881E-5,,,,,,,,,,,,,,,,,,,,,112.164794921875,112.302368164062,9999.755859375,9999.755859375,47.2947784416204,5.27832509702719,12.2879457473755,27,1,0,0,1,0.276031494140625,39.5894432067871,2,1,1,112.164794921875,0,112.233581542969,,,,,,,,,,,,,,,,,,,,,,,,,,,,,,,,,
,3834073007.6592,109.847610473633,9999.755859375,0.00189194795595074,2.25382644228785E-7,1,2,13.4005146026611,4.99466528357088,31.41999989748,2.51747163826361,0.371680876469282,10,1.44936079667559E-5,,,,,,,,,,,,,,,,,,,,,109.75804901123,109.937171936035,9999.755859375,9999.755859375,47.2756285428992,5.2762795221488,12.2654209136963,27,1,0,0,1,0.284881591796875,39.5894432067871,2,1,1,109.75804901123,0,109.847610473633,,,,,,,,,,,,,,,,,,,,,,,,,,,,,,,,,
,3834073038.16784,107.296356201172,9999.755859375,0.00193512120214382,1.76191979600903E-7,1,2,13.4005146026611,4.99463738379828,31.41999989748,2.57493519344413,0.379902805326266,10,1.46316160872297E-5,,,,,,,,,,,,,,,,,,,,,107.187538146973,107.405174255371,9999.755859375,9999.755859375,47.2435817736108,5.27638289490177,12.2368087768555,27,1,0,0,1,0.275955200195313,39.5894432067871,2,1,1,107.187538146973,0,107.296356201172,,,,,,,,,,,,,,,,,,,,,,,,,,,,,,,,,
,3834073068.37509,104.802570343018,9999.755859375,0.00198135767664168,1.54262357016247E-7,1,2,13.4005146026611,4.99463736011564,31.3999988138676,2.63647000767745,0.388900735092598,10,1.49217504622245E-5,,,,,,,,,,,,,,,,,,,,,104.75813293457,104.847007751465,9999.755859375,9999.755859375,47.2943876273608,5.27917489340034,12.2372426986694,27,1,0,0,1,0.276107788085938,39.5894432067871,2,1,1,104.75813293457,0,104.802570343018,,,,,,,,,,,,,,,,,,,,,,,,,,,,,,,,,
,3834073098.31127,102.319900512695,9999.755859375,0.00202846099397965,2.04905321338085E-7,1,2,13.4005146026611,4.99459453316162,31.3999988138676,2.69908097819226,0.39839032548091,10,1.54632960790101E-5,,,,,,,,,,,,,,,,,,,,,102.231384277344,102.408416748047,9999.755859375,9999.755859375,47.2975141414377,5.27659206181052,12.1958265304565,27,1,0,0,1,0.276565551757813,39.5894432067871,2,1,1,102.231384277344,0,102.319900512695,,,,,,,,,,,,,,,,,,,,,,,,,,,,,,,,,
,3834073128.59704,99.8047866821289,9999.755859375,0.00207758522345164,3.3351453558857E-7,1,2,13.4005146026611,4.99454712485368,31.3999988138676,2.76441780700911,0.407977137523247,10,1.57958153534547E-5,,,,,,,,,,,,,,,,,,,,,99.7266616821289,99.8829116821289,9999.755859375,9999.755859375,47.2361563026781,5.27671095683243,12.1892013549805,27,1,0,0,1,0.285797119140625,39.5894432067871,2,1,1,99.7266616821289,0,99.8047866821289,,,,,,,,,,,,,,,,,,,,,,,,,,,,,,,,,
,3834073158.93128,97.2246932983398,9999.755859375,0.00212913975452165,1.90833104713377E-7,1,2,13.4005146026611,4.9944970670767,31.3999988138676,2.8329890539296,0.418008589795922,10,1.6122757426056E-5,,,,,,,,,,,,,,,,,,,,,97.1563720703125,97.2930145263672,9999.755859375,9999.755859375,47.2896978562454,5.27596538300255,12.1585750579834,27,1,0,0,1,0.285491943359375,39.5894432067871,2,1,1,97.1563720703125,0,97.2246932983398,,,,,,,,,,,,,,,,,,,,,,,,,,,,,,,,,
,3834073191.01534,94.6063194274902,9999.755859375,0.00218877012722683,2.27834107265988E-7,1,2,13.4005146026611,4.99451178972557,31.3800014555454,2.91229560931853,0.430061691099538,10,1.6832778573751E-5,,,,,,,,,,,,,,,,,,,,,94.515510559082,94.6971282958984,9999.755859375,9999.755859375,47.2740652858608,5.27612866640054,12.1410665512085,27,1,0,0,1,0.285568237304687,39.5894432067871,2,1,1,94.515510559082,0,94.6063194274902,,,,,,,,,,,,,,,,,,,,,,,,,,,,,,,,,
,3834073221.38436,92.0394096374512,9999.755859375,0.00224630829778758,2.62792838254004E-7,1,2,13.4005146026611,4.99447880327532,31.3800014555454,2.98886260609436,0.441106334391004,10,1.70824951961688E-5,,,,,,,,,,,,,,,,,,,,,91.9557113647461,92.1231079101562,9999.755859375,9999.755859375,47.1775341637358,5.27631399555097,12.1068992614746,27,1,0,0,1,0.286178588867187,39.5894432067871,2,1,1,91.9557113647461,0,92.0394096374512,,,,,,,,,,,,,,,,,,,,,,,,,,,,,,,,,
,3834073252.68872,89.4212799072266,9999.755859375,0.00231095379002197,1.94385622521927E-7,1,2,13.4005146026611,4.99448132945664,31.3800014555454,3.07488981010065,0.453729915715007,10,1.7520700693257E-5,,,,,,,,,,,,,,,,,,,,,89.2853393554687,89.5572204589844,9999.755859375,9999.755859375,47.2725020288223,5.27644934259583,12.0923624038696,27,1,0,0,1,0.284576416015625,39.5894432067871,2,1,1,89.2853393554687,0,89.4212799072266,,,,,,,,,,,,,,,,,,,,,,,,,,,,,,,,,
,3834073283.65149,86.8095893859863,9999.755859375,0.00237682565791486,2.32129115771383E-7,1,2,13.4005146026611,4.99445172229515,31.360000371933,3.16245304121081,0.46707651432576,10,1.83333219145655E-5,,,,,,,,,,,,,,,,,,,,,86.7286758422852,86.8905029296875,9999.755859375,9999.755859375,47.2771917999377,5.27657856314266,12.0755529403687,27,1,0,0,1,0.294952392578125,39.5894432067871,2,1,1,86.7286758422852,0,86.8095893859863,,,,,,,,,,,,,,,,,,,,,,,,,,,,,,,,,
,3834073314.11711,84.3268051147461,9999.755859375,0.00244448393986637,2.79674767115595E-7,1,2,13.4005146026611,4.9944494228847,31.360000371933,3.25237152017542,0.481096248812975,10,1.93989925691927E-5,,,,,,,,,,,,,,,,,,,,,84.2194442749023,84.4341659545898,9999.755859375,9999.755859375,47.2670306291877,5.27653087111863,12.0381727218628,27,1,0,0,1,0.27587890625,39.5894432067871,2,1,1,84.2194442749023,0,84.3268051147461,,,,,,,,,,,,,,,,,,,,,,,,,,,,,,,,,
,3834073342.44048,81.9655418395996,9999.755859375,0.00251131511388145,2.5136358096592E-7,1,2,13.4005146026611,4.99443915037098,31.360000371933,3.34131383470209,0.49401005987491,10,1.97508445270046E-5,,,,,,,,,,,,,,,,,,,,,81.8721694946289,82.0589141845703,9999.755859375,9999.755859375,47.2076268617262,5.27602811124696,12.014627456665,27,1,0,0,1,0.27618408203125,39.5894432067871,2,1,1,81.8721694946289,0,81.9655418395996,,,,,,,,,,,,,,,,,,,,,,,,,,,,,,,,,
,3834073374.32021,79.3126792907715,9999.755859375,0.00259397286616128,2.58714517949946E-7,1,2,13.4005146026611,4.99435968666107,31.3399992883205,3.45125018650152,0.510007517118202,10,2.02122303034996E-5,,,,,,,,,,,,,,,,,,,,,79.2438049316406,79.3815536499023,9999.755859375,9999.755859375,47.2725020288223,5.2762695488396,11.9811010360718,27,1,0,0,1,0.276260375976562,39.5894432067871,2,1,1,79.2438049316406,0,79.3126792907715,,,,,,,,,,,,,,,,,,,,,,,,,,,,,,,,,
,3834073402.5543,76.9358367919922,9999.755859375,0.00266921762545584,3.98733255632497E-7,1,2,13.4005146026611,4.99443488444808,31.3399992883205,3.55145867459221,0.524648112012106,10,2.06751923209399E-5,,,,,,,,,,,,,,,,,,,,,76.8412628173828,77.0304107666016,9999.755859375,9999.755859375,47.32565276813,5.27633099704649,11.9506921768188,27,1,0,0,1,0.275726318359375,39.5894432067871,2,1,1,76.8412628173828,0,76.9358367919922,,,,,,,,,,,,,,,,,,,,,,,,,,,,,,,,,
,3834073434.88124,74.2159423828125,9999.755859375,0.00276065984320712,3.9938396879522E-7,1,2,13.4005146026611,4.99442990615452,31.3399992883205,3.67308473240368,0.54287119464006,10,2.15714750363208E-5,,,,,,,,,,,,,,,,,,,,,74.1537857055664,74.2780990600586,9999.755859375,9999.755859375,47.1873045202262,5.27606949211177,11.9055843353271,27,1,0,0,1,0.282745361328125,39.5894432067871,2,1,1,74.1537857055664,0,74.2159423828125,,,,,,,,,,,,,,,,,,,,,,,,,,,,,,,,,
,3834073463.12774,71.8532180786133,9999.755859375,0.00284792411283748,4.14645599321763E-7,1,2,13.4005146026611,4.9943898920045,31.3199982047081,3.78894610327885,0.561476998657734,10,2.33433505641621E-5,,,,,,,,,,,,,,,,,,,,,71.7644348144531,71.9420013427734,9999.755859375,9999.755859375,47.2005922050531,5.27663102499517,11.8798875808716,27,1,0,0,1,0.28472900390625,39.5894432067871,2,1,1,71.7644348144531,0,71.8532180786133,,,,,,,,,,,,,,,,,,,,,,,,,,,,,,,,,
,3834073493.21729,69.2634048461914,9999.755859375,0.00294581645913807,4.48000086452401E-7,1,2,13.4005146026611,4.99436687070946,31.3199982047081,3.9192775671364,0.579929871295833,10,2.35126484718236E-5,,,,,,,,,,,,,,,,,,,,,69.1972808837891,69.3295288085938,9999.755859375,9999.755859375,47.3135375260819,5.27686451635827,11.8380508422852,27,1,0,0,1,0.27679443359375,39.5894432067871,2,1,1,69.1972808837891,0,69.2634048461914,,,,,,,,,,,,,,,,,,,,,,,,,,,,,,,,,
,3834073521.40151,66.9185256958008,9999.755859375,0.00304385254137604,4.09946790083923E-7,1,2,13.4005146026611,4.99437226142585,31.3199982047081,4.04974260302609,0.599041822568105,10,2.41533472508609E-5,,,,,,,,,,,,,,,,,,,,,66.8226547241211,67.0143966674805,9999.755859375,9999.755859375,47.3248711396108,5.27658240835345,11.7789926528931,27,1,0,0,1,0.295486450195313,39.5894432067871,2,1,1,66.8226547241211,0,66.9185256958008,,,,,,,,,,,,,,,,,,,,,,,,,,,,,,,,,
,3834073551.65108,64.4158554077148,9999.755859375,0.00315615707755412,3.61140017095465E-7,1,2,13.4005146026611,4.99431472251174,31.3199982047081,4.19905468488967,0.621413041598852,10,2.52540146979201E-5,,,,,,,,,,,,,,,,,,,,,64.3357543945313,64.4959564208984,9999.755859375,9999.755859375,47.2768009856781,5.27698947186613,11.7338724136353,27,1,0,0,1,0.284957885742187,39.5894432067871,2,1,1,64.3357543945313,0,64.4158554077148,,,,,,,,,,,,,,,,,,,,,,,,,,,,,,,,,
,3834073592.12501,60.9041881561279,9999.755859375,0.00332317781154156,3.60264023636017E-7,1,2,13.4005146026611,4.99432439891822,31.300000846386,4.42130249032796,0.654111834263607,10,2.64496496808767E-5,,,,,,,,,,,,,,,,,,,,,60.8486213684082,60.9597549438477,9999.755859375,9999.755859375,47.3518373235242,5.27682333665434,11.6573047637939,27,1,0,0,1,0.276260375976562,39.5894432067871,2,1,1,60.8486213684082,0,60.9041881561279,,,,,,,,,,,,,,,,,,,,,,,,,,,,,,,,,
,3834073624.1944,58.214298248291,9999.755859375,0.00346914861876299,4.31802362073973E-7,1,2,13.4005146026611,4.99429971121131,31.300000846386,4.61544683692527,0.683056560775811,10,2.77747093177929E-5,,,,,,,,,,,,,,,,,,,,,58.1184158325195,58.3101806640625,9999.755859375,9999.755859375,47.3995166631973,5.27684983828074,11.5883083343506,27,1,0,0,1,0.274581909179687,39.5894432067871,2,1,1,58.1184158325195,0,58.214298248291,,,,,,,,,,,,,,,,,,,,,,,,,,,,,,,,,
,3834073654.57546,55.6522083282471,9999.755859375,0.00361881482100553,6.14728160961274E-7,1,2,13.4005146026611,4.99442964229287,31.300000846386,4.81471672441324,0.712704731855121,10,2.90888197715003E-5,,,,,,,,,,,,,,,,,,,,,55.5691299438477,55.7352867126465,9999.755859375,9999.755859375,47.2756285428992,5.27657208563459,11.5071506500244,27,1,0,0,1,0.275192260742187,39.1006851196289,2,1,1,55.5691299438477,0,55.6522083282471,,,,,,,,,,,,,,,,,,,,,,,,,,,,,,,,,
,3834073695.00304,52.2641468048096,9999.755859375,0.00383870739057616,8.18565206456635E-7,1,2,13.4005146026611,4.99438538772129,31.300000846386,5.10720498630986,0.756071727856796,10,3.09086171608017E-5,,,,,,,,,,,,,,,,,,,,,52.2258491516113,52.3024444580078,9999.755859375,9999.755859375,47.2576510869569,5.27642841493281,11.3928804397583,27,1,0,0,1,0.27618408203125,39.1006851196289,2,1,1,52.2258491516113,0,52.2641468048096,,,,,,,,,,,,,,,,,,,,,,,,,,,,,,,,,
,3834073734.98266,48.8707790374756,9999.755859375,0.0040924835790293,8.23149053798625E-7,1,2,13.4005146026611,4.9943685178149,31.2799997627735,5.44472946427656,0.806671398237572,10,3.34172007369112E-5,,,,,,,,,,,,,,,,,,,,,48.7752723693848,48.9662857055664,9999.755859375,9999.755859375,47.3502740664858,5.2768311829811,11.2712125778198,27,1,0,0,1,0.274887084960938,39.5894432067871,2,1,1,48.7752723693848,0,48.8707790374756,,,,,,,,,,,,,,,,,,,,,,,,,,,,,,,,,
,3834073765.44496,46.3084468841553,9999.755859375,0.00430223344270057,7.39494004199028E-7,1,2,13.4005146026611,4.99439315334383,31.2799997627735,5.72375263770945,0.848530976590119,10,3.55127750828395E-5,,,,,,,,,,,,,,,,,,,,,46.2199745178223,46.3969192504883,9999.755859375,9999.755859375,47.2779734284569,5.2763223334135,11.1756191253662,27,1,0,0,1,0.275726318359375,39.5894432067871,2,1,1,46.2199745178223,0,46.3084468841553,,,,,,,,,,,,,,,,,,,,,,,,,,,,,,,,,
,3834073793.75458,43.9036731719971,9999.755859375,0.00451660038134865,8.18869535189706E-7,1,2,13.4005146026611,4.99439360490838,31.2799997627735,6.00843917130678,0.894465681456314,10,4.00263072066435E-5,,,,,,,,,,,,,,,,,,,,,43.7883529663086,44.0189933776855,9999.755859375,9999.755859375,47.2115350043223,5.27667584653676,11.0715446472168,27,1,0,0,1,0.285568237304687,39.5894432067871,2,1,1,43.7883529663086,0,43.9036731719971,,,,,,,,,,,,,,,,,,,,,,,,,,,,,,,,,
,3834073825.64118,41.2596778869629,9999.755859375,0.0047952791587073,1.04940964298996E-6,1,2,13.4005146026611,4.99437328643225,31.2799997627735,6.37950531652486,0.94696803879292,10,4.04825377875503E-5,,,,,,,,,,,,,,,,,,,,,41.1616439819336,41.3577117919922,9999.755859375,9999.755859375,47.3092385692262,5.27623385307015,10.9517402648926,27,1,0,0,1,0.294952392578125,39.5894432067871,2,1,1,41.1616439819336,0,41.2596778869629,,,,,,,,,,,,,,,,,,,,,,,,,,,,,,,,,
,3834073873.98786,37.1632671356201,9999.755859375,0.00528975424180497,1.16060136784918E-6,1,2,13.4005146026611,4.99431729573147,31.2599986791611,7.03718588737929,1.04493790939362,10,4.4910262480545E-5,,,,,,,,,,,,,,,,,,,,,37.0649337768555,37.2616004943848,9999.755859375,9999.755859375,47.2420185165723,5.27635737907207,10.7650156021118,27,1,0,0,1,0.295333862304687,39.5894432067871,2,1,1,37.0649337768555,0,37.1632671356201,,,,,,,,,,,,,,,,,,,,,,,,,,,,,,,,,
,3834073935.72756,31.96852684021,9999.755859375,0.00606993444142552,1.5001033552768E-6,1,2,13.4005146026611,4.99428968025693,31.2599986791611,8.07582397876372,1.19337954920837,100,4.72799604002431E-5,,,,,,,,,,,,,,,,,,,,,31.96852684021,31.96852684021,9999.755859375,9999.755859375,47.3147099688608,5.27732880334828,10.4804210662842,27,1,0,0,1,0.284423828125,39.5894432067871,2,1,1,31.96852684021,0,31.96852684021,,,,,,,,,,,,,,,,,,,,,,,,,,,,,,,,,
,3834073980.76882,28.1520652770996,9999.755859375,0.00684274393283178,4.89426403161985E-6,1,2,13.4005146026611,4.99422271202705,31.2599986791611,9.10286874253952,1.35232004720577,10,5.85754888773681E-5,,,,,,,,,,,,,,,,,,,,,28.0582809448242,28.245849609375,9999.755859375,9999.755859375,47.2986865842165,5.27739736506649,10.2470998764038,27,1,0,0,1,0.276565551757813,39.5894432067871,2,1,1,28.0582809448242,0,28.1520652770996,,,,,,,,,,,,,,,,,,,,,,,,,,,,,,,,,
,3834074029.17292,24.142915725708,9999.755859375,0.00788184556863565,6.60087401613244E-5,1,2,13.4005146026611,4.99421225571178,31.2599986791611,10.472264343174,1.64983272324252,10,0.000136666502243706,,,,,,,,,,,,,,,,,,,,,24.0392665863037,24.2465648651123,9999.755859375,9999.755859375,47.320572182755,5.27734767079102,9.95815086364746,27,1,0,0,1,0.276947021484375,39.5894432067871,2,1,1,24.0392665863037,0,24.142915725708,,,,,,,,,,,,,,,,,,,,,,,,,,,,,,,,,
,3834074075.47577,20.24733543396,9999.755859375,0.00931921670345585,3.94798846080183E-6,1,2,13.4005146026611,4.99417282072708,31.2399994581938,12.3952385082976,1.85530588520857,10,8.99782682540106E-5,,,,,,,,,,,,,,,,,,,,,20.1584415435791,20.3362293243408,9999.755859375,9999.755859375,47.259605158255,5.27744577162902,9.567551612854,27,1,0,0,1,0.275115966796875,39.5894432067871,2,1,1,20.1584415435791,0,20.24733543396,,,,,,,,,,,,,,,,,,,,,,,,,,,,,,,,,
,3834074137.25743,15.138927936554,9999.755859375,0.0122326486396359,6.57199259717115E-6,1,2,13.4005146026611,4.9941340131101,31.2399994581938,16.2735495064072,2.41093014190895,100,9.98122000312587E-5,,,,,,,,,,,,,,,,,,,,,15.0002393722534,15.2776165008545,9999.755859375,9999.755859375,47.2385011882358,5.27738388729527,8.69753742218018,27,1,0,0,1,0.277633666992187,39.1006851196289,2,1,1,15.0002393722534,0,15.138927936554,,,,,,,,,,,,,,,,,,,,,,,,,,,,,,,,,
,3834074181.77006,11.5299043655396,9999.755859375,0.0154354063037452,9.80088384009338E-6,1,2,13.4005146026611,4.99405313422001,31.2399994581938,20.5353209618463,3.0315165317833,1000,0.000118003397203205,,,,,,,,,,,,,,,,,,,,,11.5299043655396,11.5299043655396,9999.755859375,9999.755859375,47.2685938862262,5.27703317199202,7.77699995040894,27,1,0,0,1,0.284500122070313,39.1006851196289,2,1,1,11.5299043655396,0,11.5299043655396,,,,,,,,,,,,,,,,,,,,,,,,,,,,,,,,,
,3834074216.69292,9.14634227752686,9999.755859375,0.019046430277715,1.57424457157475E-5,1,2,13.4005146026611,4.99407104404316,31.2200002372265,25.3375722339077,3.75499254410809,100,0.000156310557143481,,,,,,,,,,,,,,,,,,,,,9.04181957244873,9.25086498260498,9999.755859375,9999.755859375,47.3600444229762,5.2764026516654,7.07671308517456,27,1,0,0,1,0.276718139648438,39.1006851196289,6,1,1,9.04181957244873,0,9.14634227752686,,,,,,,,,,,,,,,,,,,,,,,,,,,,,,,,,
,3834074266.13594,7.99988961219788,9999.755859375,0.0210893328449215,2.27337577672728E-6,1,2,13.4005146026611,4.99409320016396,31.2200002372265,28.054576835528,4.16385820322126,100,0.000177643902008429,,,,,,,,,,,,,,,,,,,,,7.99969053268433,8.00008869171143,9999.755859375,9999.755859375,47.3236986968319,5.27671602112108,6.87971496582031,27,1,0,0,1,0.286865234375,39.1006851196289,5,1,1,7.99969053268433,0,7.99988961219788,,,,,,,,,,,,,,,,,,,,,,,,,,,,,,,,,
,3834074294.45004,7.99995970726013,9999.755859375,0.0210891625045694,2.22444919827624E-6,1,2,13.4005146026611,4.99408372802604,31.2200002372265,28.0543052475737,4.16361412725153,100,0.000177492580940306,,,,,,,,,,,,,,,,,,,,,7.99981260299683,8.00010681152344,9999.755859375,9999.755859375,47.2994682127358,5.27702650581782,6.86676836013794,27,1,0,0,1,0.276870727539062,39.1006851196289,1,1,1,7.99981260299683,0,7.99995970726013,,,,,,,,,,,,,,,,,,,,,,,,,,,,,,,,,