File: SI Fig S11-13 SQUID all/Michaela_La_FC1T_00001.dat
[Header]
; MPMS3 Data File (default extension .dat)
; Copyright (c) 2007, Quantum Design, Inc. All rights reserved.
TITLE,
FILEOPENTIME,3834159186.83534,06/29/2021,8:14 pm
BYAPP,MPMS3 w/ AC,1.0,1.1
INFO,MPMS3 Measurement Release 1.1.16 Build 424, MultiVu Release 2.3.4.19,APPNAME
INFO,Linear Motor Servo Controller,MOTOR_MODULE_NAME
INFO,3101-100 E1,MOTOR_HW_VERSION
INFO,MMC211,MOTOR_SERIAL_NUMBER
INFO,01.04.28,MOTOR_SOFTWARE_VERSION
INFO,Quantum Design Squid Module,SQUID_MODULE_NAME
INFO,3101-501 B0,SQUID_HW_VERSION
INFO,SQM059,SQUID_SERIAL_NUMBER
INFO,01.03.04,SQUID_SOFTWARE_VERSION
INFO,SQUID AC,AC_MODULE_NAME
INFO,3101-401 F1,AC_HW_VERSION
INFO,SAC057,AC_SERIAL_NUMBER
INFO,SQUID AC 00.95.07,AC_SOFTWARE_VERSION
INFO,TCIXXX,COIL_SERIAL_NUMBER
INFO,0,MOMENT_UNITS
INFO,La_02,SAMPLE_MATERIAL
INFO,La_02,SAMPLE_COMMENT
INFO,0.07,SAMPLE_MASS
INFO,,SAMPLE_VOLUME
INFO,,SAMPLE_MOLECULAR_WEIGHT
INFO,,SAMPLE_SIZE
INFO,,SAMPLE_SHAPE
INFO,Straw,SAMPLE_HOLDER
INFO,Standard,SAMPLE_HOLDER_DETAIL
INFO,58.69,SAMPLE_OFFSET
DATATYPE,COMMENT,1
DATATYPE,TIME,2
STARTUPAXIS,X,2
STARTUPAXIS,Y1,5
FIELDGROUP, VSM,2,3,4,5,6,8,9,10,11,14,15
FIELDGROUP, DC, 2,3,4,14,56,57,58,59,60,61,62,63,64,65,66,67,68,69
FIELDGROUP, AC, 2,3,4,11,16,17,18,19,20,21,22,23,24,25,26,27,28,29,30
STARTUPGROUP, All
[Data]
Comment,Time Stamp (sec),Temperature (K),Magnetic Field (Oe),Moment (emu),M. Std. Err. (emu),Transport Action,Averaging Time (sec),Frequency (Hz),Peak Amplitude (mm),Center Position (mm),Lockin Signal' (V),Lockin Signal (V),Range,M. Quad. Signal (emu),AC Moment (emu),AC M. Std Err. (emu),AC Phase (deg),AC Phase Std. Err. (deg),AC Susceptibility (emu/Oe),AC Suscept. Std Err. (emu/Oe),AC X' (emu/Oe),AC X' Std Err. (emu/Oe),AC X'' (emu/Oe),AC X'' Std Err. (emu/Oe),AC Drive (Oe),AC Frequency (Hz),AC Averaging Time (sec),AC Cycles,AC Range,AC Measure Type,AC Signal' (V),AC Signal'' (V),AC Trim Coil Ratio,AC Trim Coil Phase,Min. Temperature (K),Max. Temperature (K),Min. Field (Oe),Max. Field (Oe),Mass (grams),Motor Lag (deg),Pressure (Torr),Measure Count,Measurement Number,SQUID Status (code),Motor Status (code),Measure Status (code),Motor Current (amps),Motor Temp. (C),Temp. Status (code),Field Status (code),Chamber Status (code),Chamber Temp (K),Redirection State,Average Temp (K),Rotation Angle (deg),Rotator state,DC Moment Fixed Ctr (emu),DC Moment Err Fixed Ctr (emu),DC Moment Free Ctr (emu),DC Moment Err Free Ctr (emu),DC Fixed Fit,DC Free Fit,DC Calculated Center (mm),DC Calculated Center Err (mm),DC Scan Length (mm),DC Scan Time (s),DC Number of Points,DC Squid Drift,DC Min V (V),DC Max V (V),DC Scans per Measure,Map 01,Map 02,Map 03,Map 04,Map 05,Map 06,Map 07,Map 08,Map 09,Map 10,Map 11,Map 12,Map 13,Map 14,Map 15,Map 16
,3834159193.19047,299.948867797852,9999.53125,-0.000120303226082457,5.23670323511919E-8,1,2,13.4005146026611,4.98384045521443,28.3899996429682,-0.159588586054926,-0.0236660080539944,1,-9.98522230792646E-7,,,,,,,,,,,,,,,,,,,,,299.948028564453,299.94970703125,9999.53125,9999.53125,46.8875499831011,5.26349975757894,8.96844005584717,27,1,0,0,1,0.27252197265625,38.1231689453125,1,1,1,299.94970703125,0,299.948867797852,,,,,,,,,,,,,,,,,,,,,,,,,,,,,,,,,
,3834159225.05141,299.112716674805,9999.53125,-0.000120471020993576,4.73630152889803E-8,1,2,13.4005146026611,4.98383667020825,28.4000001847744,-0.15979959349086,-0.0237806302648687,1,-1.06138530881734E-6,,,,,,,,,,,,,,,,,,,,,299.090698242188,299.134735107422,9999.53125,9999.53125,46.8527675139953,5.26368474597239,9.02806949615479,26,1,64,0,0,0.272979736328125,38.1231689453125,2,1,1,299.090698242188,0,299.112716674805,,,,,,,,,,,,,,,,,,,,,,,,,,,,,,,,,
,3834159259.09378,296.429870605469,9999.53125,-0.000120456986148039,5.07779561781483E-8,1,2,13.4005146026611,4.98389253146098,28.3700004220009,-0.159809907767897,-0.0235888908486467,1,-9.18702470456014E-7,,,,,,,,,,,,,,,,,,,,,296.368377685547,296.491363525391,9999.53125,9999.53125,46.8726990412357,5.26312634542963,9.09212589263916,26,1,64,0,0,0.272064208984375,38.1231689453125,2,1,1,296.368377685547,0,296.429870605469,,,,,,,,,,,,,,,,,,,,,,,,,,,,,,,,,
,3834159289.10493,293.735229492188,9999.53125,-0.000120395182763435,5.3847951973895E-8,1,2,13.4005146026611,4.98383850758098,28.3700004220009,-0.159705531110268,-0.0237195207805865,1,-1.02596713987535E-6,,,,,,,,,,,,,,,,,,,,,293.648864746094,293.821594238281,9999.53125,9999.53125,46.9176426810915,5.26355549487308,9.06263542175293,27,1,0,0,1,0.270919799804687,38.1231689453125,2,1,1,293.648864746094,0,293.735229492188,,,,,,,,,,,,,,,,,,,,,,,,,,,,,,,,,
,3834159323.52704,290.64973449707,9999.53125,-0.000120366011587569,5.87610274257256E-8,1,2,13.4005146026611,4.98369736578529,28.3499993383884,-0.159662041394857,-0.023702755272002,1,-1.01811583396721E-6,,,,,,,,,,,,,,,,,,,,,290.586730957031,290.712738037109,9999.53125,9999.53125,46.8930213827357,5.26500456558361,8.98611640930176,27,1,0,0,1,0.273818969726562,38.1231689453125,2,1,1,290.586730957031,0,290.64973449707,,,,,,,,,,,,,,,,,,,,,,,,,,,,,,,,,
,3834159353.5905,288.095062255859,9999.53125,-0.000120282341370662,5.18467063378732E-8,1,2,13.4005146026611,4.98382304344561,28.3300001174211,-0.15957149596439,-0.0235803995848566,1,-9.37067855959408E-7,,,,,,,,,,,,,,,,,,,,,288.005676269531,288.184448242187,9999.53125,9999.53125,46.9297579231396,5.26341841840533,8.94260025024414,27,1,0,0,1,0.272750854492187,38.1231689453125,2,1,1,288.005676269531,0,288.095062255859,,,,,,,,,,,,,,,,,,,,,,,,,,,,,,,,,
,3834159387.97644,285.302932739258,9999.53125,-0.000120174006699397,5.95941279784792E-8,1,2,13.4005146026611,4.98383166861355,28.3100008964539,-0.159416099215811,-0.0236454284320997,1,-1.00113737954951E-6,,,,,,,,,,,,,,,,,,,,,285.244506835938,285.361358642578,9999.53125,9999.53125,46.8797336979088,5.26407643214126,8.91015243530273,27,1,0,0,1,0.274581909179687,38.1231689453125,2,1,1,285.244506835938,0,285.302932739258,,,,,,,,,,,,,,,,,,,,,,,,,,,,,,,,,
,3834159418.05227,282.905410766602,9999.53125,-0.000120422023437071,5.26729378886277E-8,1,2,13.4005146026611,4.98387478406472,28.3100008964539,-0.159754567902448,-0.0236403904654998,1,-9.62454531761643E-7,,,,,,,,,,,,,,,,,,,,,282.828002929687,282.982818603516,9999.53125,9999.53125,46.8386982006492,5.26431771479831,8.88677406311035,27,1,0,0,1,0.276641845703125,38.1231689453125,2,1,1,282.828002929687,0,282.905410766602,,,,,,,,,,,,,,,,,,,,,,,,,,,,,,,,,
,3834159452.41661,280.232925415039,9999.53125,-0.00012040550418412,5.1756956044979E-8,1,2,13.4005146026611,4.98383841547652,28.2899998128414,-0.15971591163407,-0.0237452044964822,1,-1.04386322171654E-6,,,,,,,,,,,,,,,,,,,,,280.170166015625,280.295684814453,9999.53125,9999.53125,46.8445604145434,5.2637830212472,8.8657808303833,27,1,0,0,1,0.271377563476562,38.1231689453125,2,1,1,280.170166015625,0,280.232925415039,,,,,,,,,,,,,,,,,,,,,,,,,,,,,,,,,
,3834159484.58043,277.59992980957,9999.53125,-0.000120413560999978,2.71521548596507E-8,1,2,13.4005146026611,4.98382061837033,28.2700005918741,-0.159735510655647,-0.0236773418473973,1,-9.91726275067914E-7,,,,,,,,,,,,,,,,,,,,,277.513854980469,277.686004638672,9999.53125,9999.53125,46.7980535176492,5.26437061766534,8.86159610748291,27,1,0,0,1,0.274581909179687,38.1231689453125,2,1,1,277.513854980469,0,277.59992980957,,,,,,,,,,,,,,,,,,,,,,,,,,,,,,,,,
,3834159516.87055,274.864837646484,9999.53125,-0.000120531841985246,4.93685423010025E-8,1,2,13.4005146026611,4.98380446978809,28.2700005918741,-0.159894150682623,-0.0236830114263469,1,-9.79536303663621E-7,,,,,,,,,,,,,,,,,,,,,274.794830322266,274.934844970703,9999.53125,9999.53125,46.8644919417838,5.26444690364323,8.85126972198486,27,1,0,0,1,0.270767211914062,38.1231689453125,2,1,1,274.794830322266,0,274.864837646484,,,,,,,,,,,,,,,,,,,,,,,,,,,,,,,,,
,3834159549.01787,272.238235473633,9999.53125,-0.000120586417970296,5.12449225990348E-8,1,2,13.4005146026611,4.98379410535335,28.2499995082617,-0.159954753797415,-0.0237747655859881,1,-1.04104426305092E-6,,,,,,,,,,,,,,,,,,,,,272.177581787109,272.298889160156,9999.53125,9999.53125,46.8715265984569,5.26393042154952,8.8464412689209,27,1,0,0,1,0.2734375,38.1231689453125,2,1,1,272.177581787109,0,272.238235473633,,,,,,,,,,,,,,,,,,,,,,,,,,,,,,,,,
,3834159581.35481,269.529083251953,9999.53125,-0.000120647709025594,4.74749742127077E-8,1,2,13.4005146026611,4.98380204451593,28.2400008291006,-0.160053069204448,-0.0236677174927332,1,-9.51831662315937E-7,,,,,,,,,,,,,,,,,,,,,269.468109130859,269.590057373047,9999.53125,9999.53125,46.7988351461684,5.26432354283501,8.82637786865234,27,1,0,0,1,0.275039672851562,38.1231689453125,2,1,1,269.468109130859,0,269.529083251953,,,,,,,,,,,,,,,,,,,,,,,,,,,,,,,,,
,3834159613.49331,266.864120483398,9999.53125,-0.000120568523492441,5.07234392517926E-8,1,2,13.4005146026611,4.9837867910688,28.2199997454882,-0.159929722205476,-0.0237781478539497,1,-1.0461291017017E-6,,,,,,,,,,,,,,,,,,,,,266.772918701172,266.955322265625,9999.53125,9999.53125,46.8422155289857,5.26457126072028,8.81636905670166,27,1,0,0,1,0.272750854492187,38.1231689453125,2,1,1,266.772918701172,0,266.864120483398,,,,,,,,,,,,,,,,,,,,,,,,,,,,,,,,,
,3834159645.81717,264.218139648438,9999.53125,-0.000120769099884912,4.77752523017134E-8,1,2,13.4005146026611,4.98368672171284,28.2199997454882,-0.160195571991885,-0.0237869605794541,1,-1.02521345151121E-6,,,,,,,,,,,,,,,,,,,,,264.139068603516,264.297210693359,9999.53125,9999.53125,46.8816877692069,5.26493119881188,8.81215000152588,27,1,0,0,1,0.273590087890625,38.1231689453125,2,1,1,264.139068603516,0,264.218139648438,,,,,,,,,,,,,,,,,,,,,,,,,,,,,,,,,
,3834159677.9638,261.577728271484,9999.53125,-0.000120655805998543,3.53530916259965E-8,1,2,13.4005146026611,4.98384842350588,28.2000005245209,-0.160061149583323,-0.0237032611033055,1,-9.77234746636601E-7,,,,,,,,,,,,,,,,,,,,,261.513702392578,261.641754150391,9999.53125,9999.53125,46.9340568799953,5.26437453910318,8.80639553070068,27,1,0,0,1,0.273666381835938,38.1231689453125,2,1,1,261.513702392578,0,261.577728271484,,,,,,,,,,,,,,,,,,,,,,,,,,,,,,,,,
,3834159712.63512,258.735275268555,9999.53125,-0.000120722847143958,5.11994594026885E-8,1,2,13.4005146026611,4.9838203775463,28.1899999827147,-0.160149600798439,-0.0237108721684062,1,-9.73729622664625E-7,,,,,,,,,,,,,,,,,,,,,258.692535400391,258.778015136719,9999.53125,9999.53125,46.7824209472646,5.26380281436414,8.80320644378662,25,1,64,0,0,0.272979736328125,38.1231689453125,2,1,1,258.692535400391,0,258.735275268555,,,,,,,,,,,,,,,,,,,,,,,,,,,,,,,,,
,3834159744.46766,256.057228088379,9999.53125,-0.000120731807352089,5.05979180964561E-8,1,2,13.4005146026611,4.98383157838334,28.1700007617474,-0.160150782021091,-0.0237928020342463,1,-1.03411167957033E-6,,,,,,,,,,,,,,,,,,,,,255.980239868164,256.134216308594,9999.53125,9999.53125,46.7667883768799,5.26406517345345,8.77814674377441,27,1,0,0,1,0.275650024414062,38.1231689453125,2,1,1,255.980239868164,0,256.057228088379,,,,,,,,,,,,,,,,,,,,,,,,,,,,,,,,,
,3834159774.73564,253.434494018555,9999.53125,-0.000120810993508595,5.1625132182432E-8,1,2,13.4005146026611,4.98378466990687,28.1700007617474,-0.160267909607508,-0.0237068483984946,1,-9.58550616547476E-7,,,,,,,,,,,,,,,,,,,,,253.373916625977,253.495071411133,9999.53125,9999.53125,46.814467716553,5.26400785356253,8.77293300628662,27,1,0,0,1,0.270919799804687,38.1231689453125,2,1,1,253.373916625977,0,253.434494018555,,,,,,,,,,,,,,,,,,,,,,,,,,,,,,,,,
,3834159808.96384,250.611885070801,9999.53125,-0.000120714107879364,5.41639440857418E-8,1,2,13.4005146026611,4.98376713629359,28.1499996781349,-0.160128374929227,-0.0237609079453032,1,-1.01288894581932E-6,,,,,,,,,,,,,,,,,,,,,250.519302368164,250.704467773438,9999.53125,9999.53125,46.8648827560434,5.26450881582705,8.75975894927978,27,1,0,0,1,0.275650024414062,38.1231689453125,2,1,1,250.519302368164,0,250.611885070801,,,,,,,,,,,,,,,,,,,,,,,,,,,,,,,,,
,3834159845.19443,247.591583251953,9999.53125,-0.000120873617222085,4.82885305203891E-8,1,2,13.4005146026611,4.98371866676832,28.1399991363287,-0.160333680262585,-0.0238216338521204,1,-1.03655050961182E-6,,,,,,,,,,,,,,,,,,,,,247.504867553711,247.678298950195,9999.53125,9999.53125,46.7468568496396,5.26461521302873,8.75318145751953,27,1,0,0,1,0.274505615234375,38.1231689453125,2,1,1,247.504867553711,0,247.591583251953,,,,,,,,,,,,,,,,,,,,,,,,,,,,,,,,,
,3834159878.79778,244.769630432129,9999.53125,-0.000120802187045053,4.84404340292332E-8,1,2,13.4005146026611,4.98377927414197,28.1199999153614,-0.160252721741033,-0.0237284512202375,1,-9.76074780595448E-7,,,,,,,,,,,,,,,,,,,,,244.646636962891,244.892623901367,9999.53125,9999.53125,46.8089963169184,5.26464907028302,8.75211143493652,27,1,0,0,1,0.27435302734375,38.1231689453125,2,1,1,244.646636962891,0,244.769630432129,,,,,,,,,,,,,,,,,,,,,,,,,,,,,,,,,
,3834159911.88657,242.045181274414,9999.53125,-0.000120830602274948,3.46003815604357E-8,1,2,13.4005146026611,4.98378212643928,28.1199999153614,-0.160278707316853,-0.0238186958907994,1,-1.04003928035214E-6,,,,,,,,,,,,,,,,,,,,,241.941696166992,242.148666381836,9999.53125,9999.53125,46.8367441293511,5.2643477381709,8.73991203308105,27,1,0,0,1,0.271987915039062,38.1231689453125,2,1,1,241.941696166992,0,242.045181274414,,,,,,,,,,,,,,,,,,,,,,,,,,,,,,,,,
,3834159945.98932,239.189308166504,9999.53125,-0.000120929654080668,5.2329613976771E-8,1,2,13.4005146026611,4.98375739465043,28.1000006943941,-0.160415012416079,-0.0237950910340501,1,-1.00853794243725E-6,,,,,,,,,,,,,,,,,,,,,239.094680786133,239.283935546875,9999.53125,9999.53125,46.8000075889473,5.26454803751258,8.7382287979126,27,1,0,0,1,0.2728271484375,38.1231689453125,2,1,1,239.094680786133,0,239.189308166504,,,,,,,,,,,,,,,,,,,,,,,,,,,,,,,,,
,3834159980.19205,236.409248352051,9999.53125,-0.000120919872176956,5.01747586062526E-8,1,2,13.4005146026611,4.9837448589791,28.1000006943941,-0.160402714214548,-0.0237842775797725,1,-1.00182521640174E-6,,,,,,,,,,,,,,,,,,,,,236.323608398438,236.494888305664,9999.53125,9999.53125,46.8605837991877,5.26477636365038,8.7437047958374,27,1,0,0,1,0.275115966796875,38.1231689453125,2,1,1,236.323608398438,0,236.409248352051,,,,,,,,,,,,,,,,,,,,,,,,,,,,,,,,,
,3834160014.54146,233.454612731934,9999.53125,-0.000120842685329992,5.28718321999415E-8,1,2,13.4005146026611,4.98378501853674,28.0799996107817,-0.160295023520658,-0.0238199475425534,1,-1.03927798003111E-6,,,,,,,,,,,,,,,,,,,,,233.390670776367,233.5185546875,9999.53125,9999.53125,46.8766071838319,5.26464883424887,8.72107887268066,27,1,0,0,1,0.274658203125,38.1231689453125,2,1,1,233.390670776367,0,233.454612731934,,,,,,,,,,,,,,,,,,,,,,,,,,,,,,,,,
,3834160046.72873,230.799369812012,9999.53125,-0.000120934648167429,4.83905982532386E-8,1,2,13.4005146026611,4.98374116386382,28.0900001525879,-0.16041488160455,-0.0238391547377356,1,-1.04109879737603E-6,,,,,,,,,,,,,,,,,,,,,230.693695068359,230.905044555664,9999.53125,9999.53125,46.8285370298992,5.26443482680967,8.73153591156006,27,1,0,0,1,0.272369384765625,38.1231689453125,2,1,1,230.693695068359,0,230.799369812012,,,,,,,,,,,,,,,,,,,,,,,,,,,,,,,,,
,3834160079.00552,228.096008300781,9999.53125,-0.000120926343475315,5.33360699113212E-8,1,2,13.4005146026611,4.98371538864424,28.0600003898144,-0.160410092679814,-0.0237846711617817,1,-1.00136208958376E-6,,,,,,,,,,,,,,,,,,,,,228.007369995117,228.184646606445,9999.53125,9999.53125,46.8562848423319,5.26522185268046,8.71970272064209,27,1,0,0,1,0.272979736328125,38.1231689453125,2,1,1,228.007369995117,0,228.096008300781,,,,,,,,,,,,,,,,,,,,,,,,,,,,,,,,,
,3834160111.16111,225.437484741211,9999.53125,-0.000120906327117019,2.93489504647083E-8,1,2,13.4005146026611,4.98373029180441,28.0499998480082,-0.16037403813328,-0.0238535017990324,1,-1.05591550908124E-6,,,,,,,,,,,,,,,,,,,,,225.385208129883,225.489761352539,9999.53125,9999.53125,46.8074330598799,5.2649304583686,8.7240104675293,27,1,0,0,1,0.273818969726562,38.1231689453125,2,1,1,225.385208129883,0,225.437484741211,,,,,,,,,,,,,,,,,,,,,,,,,,,,,,,,,
,3834160143.48778,222.708557128906,9999.53125,-0.000120913913148432,3.35802122688068E-8,1,2,13.4005146026611,4.98375692178894,28.0399993062019,-0.160395548155544,-0.0237817117537908,1,-1.00066692277478E-6,,,,,,,,,,,,,,,,,,,,,222.647033691406,222.770080566406,9999.53125,9999.53125,46.8527675139953,5.26466827616451,8.71085739135742,27,1,0,0,1,0.275039672851562,37.6344108581543,2,1,1,222.647033691406,0,222.708557128906,,,,,,,,,,,,,,,,,,,,,,,,,,,,,,,,,
,3834160175.62429,220.014472961426,9999.53125,-0.000120899712376949,4.95237474164213E-8,1,2,13.4005146026611,4.9837422219008,28.0200000852346,-0.160373945071839,-0.023793957301553,1,-1.01194562726506E-6,,,,,,,,,,,,,,,,,,,,,219.931777954102,220.09716796875,9999.53125,9999.53125,46.8086055026588,5.26504478331192,8.70527458190918,27,1,0,0,1,0.273361206054687,38.1231689453125,2,1,1,219.931777954102,0,220.014472961426,,,,,,,,,,,,,,,,,,,,,,,,,,,,,,,,,
,3834160207.94576,217.387496948242,9999.53125,-0.000120957638628453,5.42126938427007E-8,1,2,13.4005146026611,4.98374589846245,28.0200000852346,-0.160460808349036,-0.0237348531130644,1,-9.59323969614649E-7,,,,,,,,,,,,,,,,,,,,,217.326110839844,217.448883056641,9999.53125,9999.53125,46.7667883768799,5.26508527393501,8.72007179260254,27,1,0,0,1,0.273208618164062,38.1231689453125,2,1,1,217.326110839844,0,217.387496948242,,,,,,,,,,,,,,,,,,,,,,,,,,,,,,,,,
,3834160240.12398,214.739044189453,9999.53125,-0.000120898204365564,5.14561055513623E-8,1,2,13.4005146026611,4.98372528578362,28.0000008642674,-0.160361525570592,-0.0238627174723674,1,-1.064015247739E-6,,,,,,,,,,,,,,,,,,,,,214.64030456543,214.837783813477,9999.53125,9999.53125,46.7824209472646,5.26502281310468,8.70987129211426,27,1,0,0,1,0.271377563476562,38.1231689453125,2,1,1,214.64030456543,0,214.739044189453,,,,,,,,,,,,,,,,,,,,,,,,,,,,,,,,,
,3834160272.40621,211.963935852051,9999.53125,-0.000121042074062989,4.18924772833282E-8,1,2,13.4005146026611,4.98370400000818,28.0000008642674,-0.160557601327945,-0.0238467355386184,1,-1.03197027451654E-6,,,,,,,,,,,,,,,,,,,,,211.897247314453,212.030624389648,9999.53125,9999.53125,46.8613654277069,5.26517508128957,8.70848751068115,27,1,0,0,1,0.271759033203125,38.1231689453125,2,1,1,211.897247314453,0,211.963935852051,,,,,,,,,,,,,,,,,,,,,,,,,,,,,,,,,
,3834160304.57434,209.356384277344,9999.53125,-0.000120934663557884,3.12976630124477E-8,1,2,13.4005146026611,4.98366069416142,27.9799997806549,-0.160413344832032,-0.0238243433757082,1,-1.03034152859918E-6,,,,,,,,,,,,,,,,,,,,,209.269668579102,209.443099975586,9999.53125,9999.53125,46.7402130072261,5.26514904968568,8.68938636779785,27,1,0,0,1,0.273971557617187,38.1231689453125,2,1,1,209.269668579102,0,209.356384277344,,,,,,,,,,,,,,,,,,,,,,,,,,,,,,,,,
,3834160336.95704,206.679183959961,9999.53125,-0.000120915490630587,3.82962570860866E-8,1,2,13.4005146026611,4.98372976431763,27.9799997806549,-0.160391542217939,-0.0238168815284648,1,-1.02706246881251E-6,,,,,,,,,,,,,,,,,,,,,206.603149414062,206.755218505859,9999.53125,9999.53125,46.8218931874857,5.26504387413484,8.69100093841553,26,1,64,0,0,0.273590087890625,38.1231689453125,2,1,1,206.603149414062,0,206.679183959961,,,,,,,,,,,,,,,,,,,,,,,,,,,,,,,,,
,3834160369.03841,203.997840881348,9999.53125,-0.000120928602363152,5.27309222572251E-8,1,2,13.4005146026611,4.9837310651761,27.9600005596876,-0.160416540504011,-0.0237654866627842,1,-9.86523363628763E-7,,,,,,,,,,,,,,,,,,,,,203.899658203125,204.09602355957,9999.53125,9999.53125,46.850031814178,5.26466848548201,8.6716423034668,27,1,0,0,1,0.275802612304687,38.1231689453125,2,1,1,203.899658203125,0,203.997840881348,,,,,,,,,,,,,,,,,,,,,,,,,,,,,,,,,
,3834160401.37657,201.173141479492,9999.53125,-0.000120935834864836,4.09296870497763E-8,1,2,13.4005146026611,4.98368783748291,27.9600005596876,-0.160416127994766,-0.0238245346600579,1,-1.03018769559033E-6,,,,,,,,,,,,,,,,,,,,,201.098419189453,201.247863769531,9999.53125,9999.53125,46.8699633414184,5.26507040095732,8.67146682739258,27,1,0,0,1,0.270614624023438,37.6344108581543,2,1,1,201.098419189453,0,201.173141479492,,,,,,,,,,,,,,,,,,,,,,,,,,,,,,,,,
,3834160433.52753,198.364364624023,9999.53125,-0.000120909048761552,5.51495779719615E-8,1,2,13.4005146026611,4.98366939313557,27.9399994760752,-0.160386187549378,-0.0237733301355612,1,-9.95467386972326E-7,,,,,,,,,,,,,,,,,,,,,198.310577392578,198.418151855469,9999.53125,9999.53125,46.8066514313607,5.26509923195924,8.66599655151367,27,1,0,0,1,0.274887084960938,38.1231689453125,2,1,1,198.310577392578,0,198.364364624023,,,,,,,,,,,,,,,,,,,,,,,,,,,,,,,,,
,3834160465.81595,195.670166015625,9999.53125,-0.000120945927234836,3.33706261323602E-8,1,2,13.4005146026611,4.98366373325588,27.9399994760752,-0.160422257802659,-0.023870652383069,1,-1.06362207392967E-6,,,,,,,,,,,,,,,,,,,,,195.601776123047,195.738555908203,9999.53125,9999.53125,46.8746531125338,5.26540870757414,8.6637544631958,27,1,0,0,1,0.273895263671875,38.1231689453125,2,1,1,195.56184387207,0,195.670166015625,,,,,,,,,,,,,,,,,,,,,,,,,,,,,,,,,
,3834160498.57798,192.943809509277,9999.53125,-0.000120859319154839,5.14471843726943E-8,1,2,13.4005146026611,4.98354437974114,27.9200002551079,-0.160312227537203,-0.0237804299847739,1,-1.00838329358065E-6,,,,,,,,,,,,,,,,,,,,,192.912673950195,192.974945068359,9999.53125,9999.53125,46.8433879717646,5.26503555057794,8.65755081176758,25,1,64,0,0,0.272750854492187,38.1231689453125,2,1,1,192.912673950195,0,192.943809509277,,,,,,,,,,,,,,,,,,,,,,,,,,,,,,,,,
,3834160528.26734,190.381942749023,9999.53125,-0.000120897277375345,5.29504159258037E-8,1,2,13.4005146026611,4.98363348081745,27.9200002551079,-0.160365009791975,-0.0237992237371415,1,-1.01678824338908E-6,,,,,,,,,,,,,,,,,,,,,190.286529541016,190.477355957031,9999.53125,9999.53125,46.7355232361107,5.26480076682821,8.64279556274414,27,1,0,0,1,0.2740478515625,38.1231689453125,2,1,1,190.286529541016,0,190.381942749023,,,,,,,,,,,,,,,,,,,,,,,,,,,,,,,,,
,3834160562.49892,187.603942871094,9999.53125,-0.000120975291378544,5.00170871246485E-8,1,2,13.4005146026611,4.98367078878013,27.9099997133017,-0.160480307101769,-0.0237421157887469,1,-9.6269413882227E-7,,,,,,,,,,,,,,,,,,,,,187.514007568359,187.693878173828,9999.53125,9999.53125,46.7710873337357,5.26563176600409,8.63778686523437,27,1,0,0,1,0.273590087890625,38.1231689453125,2,1,1,187.514007568359,0,187.603942871094,,,,,,,,,,,,,,,,,,,,,,,,,,,,,,,,,
,3834160592.7481,185.093139648438,9999.53125,-0.000120981401503828,5.38612055035246E-8,1,2,13.4005146026611,4.98372257254425,27.8999991714954,-0.160470674648526,-0.0238868821727248,1,-1.07059151749492E-6,,,,,,,,,,,,,,,,,,,,,185.019882202148,185.166397094727,9999.53125,9999.53125,46.7706965194761,5.2657596033274,8.63065814971924,27,1,0,0,1,0.272064208984375,38.1231689453125,2,1,1,185.019882202148,0,185.093139648438,,,,,,,,,,,,,,,,,,,,,,,,,,,,,,,,,
,3834160627.54255,182.18155670166,9999.53125,-0.000120897684106626,5.3126269999701E-8,1,2,13.4005146026611,4.9834727061977,27.8799999505281,-0.160366437100403,-0.0237411199320689,1,-9.73770665312101E-7,,,,,,,,,,,,,,,,,,,,,182.141555786133,182.221557617187,9999.53125,9999.53125,46.8136860880338,5.26690662776631,8.639328956604,25,1,64,0,0,0.27130126953125,38.1231689453125,2,1,1,182.141555786133,0,182.18155670166,,,,,,,,,,,,,,,,,,,,,,,,,,,,,,,,,
,3834160657.22426,179.700828552246,9999.53125,-0.000120919082498543,4.87180402298068E-8,1,2,13.4005146026611,4.98359739850004,27.8900004923344,-0.160386431701539,-0.0238455325938037,1,-1.04878847657349E-6,,,,,,,,,,,,,,,,,,,,,179.602767944336,179.798889160156,9999.53125,9999.53125,46.8476869286203,5.26525774447649,8.62127780914307,27,1,0,0,1,0.272140502929687,38.1231689453125,2,1,1,179.602767944336,0,179.700828552246,,,,,,,,,,,,,,,,,,,,,,,,,,,,,,,,,
,3834160691.41476,176.816619873047,9999.53125,-0.000120945539547563,5.59745260675785E-8,1,2,13.4005146026611,4.98356237422406,27.8799999505281,-0.160418750268109,-0.0238592925801168,1,-1.05562389320557E-6,,,,,,,,,,,,,,,,,,,,,176.735946655273,176.89729309082,9999.53125,9999.53125,46.8301002869377,5.26518956216585,8.60499668121338,27,1,0,0,1,0.274429321289062,38.1231689453125,2,1,1,176.735946655273,0,176.816619873047,,,,,,,,,,,,,,,,,,,,,,,,,,,,,,,,,
,3834160723.74275,174.171340942383,9999.53125,-0.00012094499566618,5.58980335004327E-8,1,2,13.4005146026611,4.98348922354579,27.8699994087219,-0.160425353851496,-0.0237832039858751,1,-9.98764775895127E-7,,,,,,,,,,,,,,,,,,,,,174.108154296875,174.234527587891,9999.53125,9999.53125,46.789064789678,5.26586097057561,8.60168743133545,27,1,0,0,1,0.271987915039062,38.1231689453125,2,1,1,174.108154296875,0,174.171340942383,,,,,,,,,,,,,,,,,,,,,,,,,,,,,,,,,
,3834160755.98667,171.522285461426,9999.53125,-0.000120986036710304,6.19944417144125E-8,1,2,13.4005146026611,4.98354360433162,27.8600007295609,-0.160479472408548,-0.023811105794978,1,-1.01376875680395E-6,,,,,,,,,,,,,,,,,,,,,171.425262451172,171.61930847168,9999.53125,9999.53125,46.8164217878511,5.26452058301419,8.57831764221191,25,1,64,0,0,0.2728271484375,38.1231689453125,2,1,1,171.425262451172,0,171.522285461426,,,,,,,,,,,,,,,,,,,,,,,,,,,,,,,,,
,3834160790.49003,168.634262084961,9999.53125,-0.000120873095876109,5.12873424254557E-8,1,2,13.4005146026611,4.98360876508642,27.8399996459484,-0.160335438524447,-0.0237685850039496,1,-9.9722014686362E-7,,,,,,,,,,,,,,,,,,,,,168.587539672852,168.68098449707,9999.53125,9999.53125,46.8148585308126,5.26560045285186,8.57404804229736,27,1,0,0,1,0.271377563476562,38.1231689453125,2,1,1,168.57389831543,0,168.634262084961,,,,,,,,,,,,,,,,,,,,,,,,,,,,,,,,,
,3834160820.36961,166.111740112305,9999.53125,-0.000120858035557598,5.085596152447E-8,1,2,13.4005146026611,4.98353213282006,27.8399996459484,-0.160310627640538,-0.0237754956510105,1,-1.00490749974218E-6,,,,,,,,,,,,,,,,,,,,,166.016189575195,166.207290649414,9999.53125,9999.53125,46.8148585308126,5.26583752406841,8.55677700042725,27,1,0,0,1,0.271682739257813,38.1231689453125,2,1,1,166.016189575195,0,166.111740112305,,,,,,,,,,,,,,,,,,,,,,,,,,,,,,,,,
,3834160854.97477,163.266578674316,9999.53125,-0.000120764420055509,3.66938902734818E-8,1,2,13.4005146026611,4.98359539227215,27.8200004249811,-0.160193743355409,-0.0237253082498699,1,-9.79893493415937E-7,,,,,,,,,,,,,,,,,,,,,163.209381103516,163.323776245117,9999.53125,9999.53125,46.6581420127069,5.26584378340183,8.54717636108398,27,1,0,0,1,0.2734375,38.1231689453125,2,1,1,163.209381103516,0,163.266578674316,,,,,,,,,,,,,,,,,,,,,,,,,,,,,,,,,
,3834160884.91333,160.813667297363,9999.53125,-0.000120798850014627,2.64815576282198E-8,1,2,13.4005146026611,4.98360680010204,27.8200004249811,-0.160234462251798,-0.0237711664246041,1,-1.00955484419832E-6,,,,,,,,,,,,,,,,,,,,,160.723052978516,160.904281616211,9999.53125,9999.53125,46.8422155289857,5.26589294259112,8.54916286468506,25,1,64,0,0,0.27099609375,38.1231689453125,2,1,1,160.723052978516,0,160.813667297363,,,,,,,,,,,,,,,,,,,,,,,,,,,,,,,,,
,3834160917.13943,158.09122467041,9999.53125,-0.000120760813702473,3.99525586606958E-8,1,2,13.4005146026611,4.98366844635251,27.8200004249811,-0.160190694198346,-0.0237357195992082,1,-9.87878013954985E-7,,,,,,,,,,,,,,,,,,,,,158.050155639648,158.132293701172,9999.53125,9999.53125,46.7957086320915,5.26587716892895,8.53484439849854,27,1,0,0,1,0.27191162109375,38.1231689453125,2,1,1,158.050155639648,0,158.09122467041,,,,,,,,,,,,,,,,,,,,,,,,,,,,,,,,,
,3834160949.29727,155.360534667969,9999.53125,-0.000120775491366219,5.74550168434944E-8,1,2,13.4005146026611,4.98365310704978,27.7999993413687,-0.160184901756676,-0.0239143409171474,1,-1.12040266665619E-6,,,,,,,,,,,,,,,,,,,,,155.299835205078,155.421234130859,9999.53125,9999.53125,46.9074815103415,5.26557652339294,8.53496646881103,27,1,0,0,1,0.272598266601562,38.1231689453125,2,1,1,155.299835205078,0,155.360534667969,,,,,,,,,,,,,,,,,,,,,,,,,,,,,,,,,
,3834160981.60737,152.672737121582,9999.53125,-0.000120680159350347,5.15639217710717E-8,1,2,13.4005146026611,4.9836975066443,27.7999993413687,-0.160074110445465,-0.0237978405072368,1,-1.04578853274702E-6,,,,,,,,,,,,,,,,,,,,,152.611434936523,152.734039306641,9999.53125,9999.53125,46.7620986057646,5.2652610988048,8.51866436004639,27,1,0,0,1,0.273208618164062,38.1231689453125,2,1,1,152.611434936523,0,152.672737121582,,,,,,,,,,,,,,,,,,,,,,,,,,,,,,,,,
,3834161013.78444,149.979064941406,9999.53125,-0.000120723526945919,4.83102706919458E-8,1,2,13.4005146026611,4.98372326353663,27.7900006622076,-0.160130074118285,-0.0238258453546857,1,-1.06068487404946E-6,,,,,,,,,,,,,,,,,,,,,149.900939941406,150.057189941406,9999.53125,9999.53125,46.8238472587838,5.2654873945366,8.51992893218994,27,1,0,0,1,0.272750854492187,38.1231689453125,2,1,1,149.900939941406,0,149.979064941406,,,,,,,,,,,,,,,,,,,,,,,,,,,,,,,,,
,3834161056.29363,146.499603271484,9999.53125,-0.000120636534700678,5.09808322722934E-8,1,2,13.4005146026611,4.98363356282994,27.7699995785952,-0.160021843886757,-0.023728625814162,1,-1.00008498030876E-6,,,,,,,,,,,,,,,,,,,,,146.444290161133,146.554916381836,9999.53125,9999.53125,46.7945361893126,5.26528893332246,8.50895404815674,27,1,0,0,1,0.2728271484375,38.1231689453125,2,1,1,146.444290161133,0,146.499603271484,,,,,,,,,,,,,,,,,,,,,,,,,,,,,,,,,
,3834161090.44658,143.66414642334,9999.53125,-0.000120643455389369,5.66076740896769E-8,1,2,13.4005146026611,4.98353336639617,27.7699995785952,-0.16002835877233,-0.0237168132374115,1,-9.90715216250944E-7,,,,,,,,,,,,,,,,,,,,,143.561309814453,143.766983032227,9999.53125,9999.53125,46.8207207447069,5.26569273138626,8.50266456604004,27,1,0,0,1,0.273513793945313,38.1231689453125,2,1,1,143.561309814453,0,143.66414642334,,,,,,,,,,,,,,,,,,,,,,,,,,,,,,,,,
,3834161122.95115,140.981063842773,9999.53125,-0.000120583577776878,3.4550277611504E-8,1,2,13.4005146026611,4.98355339219691,27.7600008994341,-0.159947058316227,-0.0237248943930206,1,-1.00507417057668E-6,,,,,,,,,,,,,,,,,,,,,140.932968139648,141.029159545898,9999.53125,9999.53125,46.8367441293511,5.26604037515819,8.49689674377441,25,1,64,0,0,0.273666381835938,38.1231689453125,2,1,1,140.932968139648,0,140.981063842773,,,,,,,,,,,,,,,,,,,,,,,,,,,,,,,,,
,3834161156.98048,138.068748474121,9999.53125,-0.000120533911887493,3.57069378952475E-8,1,2,13.4005146026611,4.98355226091282,27.7500003576279,-0.159882443071968,-0.0237057213768849,1,-9.97586471862837E-7,,,,,,,,,,,,,,,,,,,,,138.018508911133,138.118988037109,9999.53125,9999.53125,46.7417762642646,5.26595899261883,8.48745536804199,27,1,0,0,1,0.273895263671875,38.1231689453125,2,1,1,138.018508911133,0,138.068748474121,,,,,,,,,,,,,,,,,,,,,,,,,,,,,,,,,
,3834161187.04058,135.603096008301,9999.53125,-0.000120600490002903,4.55230004810172E-8,1,2,13.4005146026611,4.98358143800855,27.7399998158216,-0.159963361163518,-0.0237810849199787,1,-1.0448836532228E-6,,,,,,,,,,,,,,,,,,,,,135.538650512695,135.667541503906,9999.53125,9999.53125,46.7718689622549,5.2657756447634,8.48112773895264,27,1,0,0,1,0.272903442382813,38.1231689453125,2,1,1,135.538650512695,0,135.603096008301,,,,,,,,,,,,,,,,,,,,,,,,,,,,,,,,,
,3834161221.41346,132.70580291748,9999.53125,-0.000120452631359838,5.18490038289632E-8,1,2,13.4005146026611,4.98358256216268,27.7200005948544,-0.159775620078027,-0.0236923762377189,1,-9.98753243147116E-7,,,,,,,,,,,,,,,,,,,,,132.644195556641,132.76741027832,9999.53125,9999.53125,46.7253620653607,5.26591587322576,8.47778415679932,27,1,0,0,1,0.2734375,38.1231689453125,2,1,1,132.644195556641,0,132.70580291748,,,,,,,,,,,,,,,,,,,,,,,,,,,,,,,,,
,3834161251.52115,130.227951049805,9999.53125,-0.000120491046821902,5.74641311235033E-8,1,2,13.4005146026611,4.9835607497659,27.7200005948544,-0.159817064491587,-0.0237609542968882,1,-1.04512951779872E-6,,,,,,,,,,,,,,,,,,,,,130.163757324219,130.292144775391,9999.53125,9999.53125,46.8812969549473,5.26576350159248,8.4761266708374,27,1,0,0,1,0.271835327148438,38.1231689453125,2,1,1,130.163757324219,0,130.227951049805,,,,,,,,,,,,,,,,,,,,,,,,,,,,,,,,,
,3834161285.86915,127.33109664917,9999.53125,-0.000120467267489773,5.23422912157744E-8,1,2,13.4005146026611,4.9835053765149,27.6999995112419,-0.159788894720687,-0.0237143689076633,1,-1.01364712807004E-6,,,,,,,,,,,,,,,,,,,,,127.265716552734,127.396476745605,9999.53125,9999.53125,46.8000075889473,5.2663228304562,8.46327114105225,27,1,0,0,1,0.270919799804687,38.1231689453125,2,1,1,127.265716552734,0,127.33109664917,,,,,,,,,,,,,,,,,,,,,,,,,,,,,,,,,
,3834161328.09493,123.894226074219,9999.53125,-0.000120360231336766,5.10711865421584E-8,1,2,13.4005146026611,4.98355332381524,27.6999995112419,-0.159649755551933,-0.0236884154524779,1,-1.00883388351832E-6,,,,,,,,,,,,,,,,,,,,,123.821647644043,123.966804504395,9999.53125,9999.53125,46.7445119640819,5.26603184539996,8.44499778747559,27,1,0,0,1,0.275039672851562,38.1231689453125,2,1,1,123.821647644043,0,123.894226074219,,,,,,,,,,,,,,,,,,,,,,,,,,,,,,,,,
,3834161358.61677,121.333866119385,9999.53125,-0.000120350229855815,4.43832256111771E-8,1,2,13.4005146026611,4.98354381307064,27.6999995112419,-0.159622681638654,-0.0237821462350904,1,-1.08086020046578E-6,,,,,,,,,,,,,,,,,,,,,121.213005065918,121.454727172852,9999.53125,9999.53125,46.8070422456203,5.26586093261389,8.4374418258667,27,1,0,0,1,0.273971557617187,38.1231689453125,2,1,1,121.213005065918,0,121.333866119385,,,,,,,,,,,,,,,,,,,,,,,,,,,,,,,,,
,3834161390.58219,118.680595397949,9999.53125,-0.000120283123647557,5.73366954320835E-8,1,2,13.4005146026611,4.98356115402544,27.6800002902746,-0.159546766274608,-0.023680837183882,1,-1.01387018602264E-6,,,,,,,,,,,,,,,,,,,,,118.591087341309,118.77010345459,9999.53125,9999.53125,46.8242380730434,5.2659333968751,8.44123458862305,27,1,0,0,1,0.273208618164062,38.1231689453125,2,1,1,118.591087341309,0,118.680595397949,,,,,,,,,,,,,,,,,,,,,,,,,,,,,,,,,
,3834161423.05806,115.91185760498,9999.53125,-0.000120261481835104,4.32962309965779E-8,1,2,13.4005146026611,4.98355754975182,27.6800002902746,-0.159514349834319,-0.0237019554434392,1,-1.03281629710025E-6,,,,,,,,,,,,,,,,,,,,,115.80451965332,116.019195556641,9999.53125,9999.53125,46.7554547633511,5.26626031528124,8.4138765335083,27,1,0,0,1,0.273513793945313,38.1231689453125,2,1,1,115.80451965332,0,115.91185760498,,,,,,,,,,,,,,,,,,,,,,,,,,,,,,,,,
,3834161455.02213,113.284774780273,9999.53125,-0.000120238950328655,5.13420647538095E-8,1,2,13.4005146026611,4.98351329374874,27.6599992066622,-0.159488665764499,-0.0236532742762675,1,-9.99526012014634E-7,,,,,,,,,,,,,,,,,,,,,113.19507598877,113.374473571777,9999.53125,9999.53125,46.6890163392165,5.2663546990194,8.41590976715088,27,1,0,0,1,0.273590087890625,38.1231689453125,2,1,1,113.19507598877,0,113.284774780273,,,,,,,,,,,,,,,,,,,,,,,,,,,,,,,,,
,3834161487.55593,110.643726348877,9999.53125,-0.000120090228432193,5.25647175180047E-8,1,2,13.4005146026611,4.98350150361427,27.6599992066622,-0.159289941412507,-0.0236306483394846,1,-1.00334041143331E-6,,,,,,,,,,,,,,,,,,,,,110.527481079102,110.759971618652,9999.53125,9999.53125,46.8895040543992,5.26643704433909,8.40859603881836,27,1,0,0,1,0.272293090820313,38.1231689453125,2,1,1,110.527481079102,0,110.643726348877,,,,,,,,,,,,,,,,,,,,,,,,,,,,,,,,,
,3834161523.73306,107.605339050293,9999.53125,-0.000120069050733319,5.14777930655523E-8,1,2,13.4005146026611,4.98351906201287,27.6500005275011,-0.159260184414853,-0.0236440219773832,1,-1.01628615545469E-6,,,,,,,,,,,,,,,,,,,,,107.526062011719,107.684616088867,9999.53125,9999.53125,46.8152493450723,5.2658795898296,8.39495849609375,27,1,0,0,1,0.2703857421875,38.1231689453125,2,1,1,107.526062011719,0,107.605339050293,,,,,,,,,,,,,,,,,,,,,,,,,,,,,,,,,
,3834161555.04041,105.032203674316,9999.53125,-0.00012013712689022,5.3545829011651E-8,1,2,13.4005146026611,4.98352274646838,27.6599992066622,-0.159346491059486,-0.0236871436395203,1,-1.03922123471221E-6,,,,,,,,,,,,,,,,,,,,,104.885864257813,105.17854309082,9999.53125,9999.53125,46.8019616602453,5.26633917614196,8.38723945617676,27,1,0,0,1,0.273056030273438,38.1231689453125,2,1,1,104.885864257813,0,105.032203674316,,,,,,,,,,,,,,,,,,,,,,,,,,,,,,,,,
,3834161596.11497,101.590324401855,9999.53125,-0.000120027611012699,4.04540174908055E-8,1,2,13.4005146026611,4.98351226821716,27.6399999856949,-0.159210390209913,-0.023596699638676,1,-9.86478654607374E-7,,,,,,,,,,,,,,,,,,,,,101.51732635498,101.66332244873,9999.53125,9999.53125,46.7855474613415,5.2665254231081,8.37812423706055,27,1,0,0,1,0.271530151367187,38.1231689453125,2,1,1,101.51732635498,0,101.590324401855,,,,,,,,,,,,,,,,,,,,,,,,,,,,,,,,,
,3834161630.36062,98.7109489440918,9999.53125,-0.000120001888526058,4.89155112939095E-8,1,2,13.4005146026611,4.98349936952946,27.6299994438887,-0.159177891004773,-0.0235759263680279,1,-9.74495453598341E-7,,,,,,,,,,,,,,,,,,,,,98.6215896606445,98.8003082275391,9999.53125,9999.53125,46.8109503882165,5.26712645957322,8.37680244445801,27,1,0,0,1,0.27191162109375,38.1231689453125,2,1,1,98.6215896606445,0,98.7109489440918,,,,,,,,,,,,,,,,,,,,,,,,,,,,,,,,,
,3834161664.91676,95.8213310241699,9999.53125,-0.000119904541092828,5.74942616107696E-8,1,2,13.4005146026611,4.9834449522122,27.6100002229214,-0.159038725059581,-0.023611194534858,1,-1.01493116898982E-6,,,,,,,,,,,,,,,,,,,,,95.7869186401367,95.8557434082031,9999.53125,9999.53125,46.7675700053992,5.26672992937783,8.3550271987915,27,1,0,0,1,0.273284912109375,38.1231689453125,2,1,1,95.7869186401367,0,95.8213310241699,,,,,,,,,,,,,,,,,,,,,,,,,,,,,,,,,
,3834161696.84582,93.1002044677734,9999.53125,-0.000119791587265904,4.63225790820292E-8,1,2,13.4005146026611,4.98346535853574,27.6100002229214,-0.158885996886284,-0.0236162740694428,1,-1.03444971811924E-6,,,,,,,,,,,,,,,,,,,,,93.0090713500977,93.1913375854492,9999.53125,9999.53125,46.855112399553,5.26724440282926,8.36574745178223,27,1,0,0,1,0.274505615234375,38.1231689453125,2,1,1,93.0090713500977,0,93.1002044677734,,,,,,,,,,,,,,,,,,,,,,,,,,,,,,,,,
,3834161731.05059,90.3780326843262,9999.53125,-0.000119802920964452,2.33986258692113E-8,1,2,13.4005146026611,4.98344841357908,27.6100002229214,-0.158902426696698,-0.0236031011724824,1,-1.02302829526586E-6,,,,,,,,,,,,,,,,,,,,,90.284782409668,90.4712829589844,9999.53125,9999.53125,46.7632710485434,5.26692274000773,8.33932590484619,27,1,0,0,1,0.274276733398438,38.1231689453125,2,1,1,90.284782409668,0,90.3780326843262,,,,,,,,,,,,,,,,,,,,,,,,,,,,,,,,,
,3834161761.31714,87.8064270019531,9999.53125,-0.000119649735492951,4.87856644584246E-8,1,2,13.4005146026611,4.98343227607873,27.5999996811152,-0.158695550407362,-0.0235942086166581,1,-1.03782946590895E-6,,,,,,,,,,,,,,,,,,,,,87.7348403930664,87.8780136108398,9999.53125,9999.53125,46.8070422456203,5.26765728776725,8.33700180053711,27,1,0,0,1,0.273895263671875,38.1231689453125,2,1,1,87.7348403930664,0,87.8064270019531,,,,,,,,,,,,,,,,,,,,,,,,,,,,,,,,,
,3834161795.51429,84.9776725769043,9999.53125,-0.000119652949799058,5.54946679949567E-8,1,2,13.4005146026611,4.98343134284873,27.5899991393089,-0.158691918331071,-0.0236510117313894,1,-1.08015981982801E-6,,,,,,,,,,,,,,,,,,,,,84.8962249755859,85.0591201782227,9999.53125,9999.53125,46.809387131178,5.26766034160084,8.31113433837891,27,1,0,0,1,0.271987915039062,38.1231689453125,2,1,1,84.8962249755859,0,84.9776725769043,,,,,,,,,,,,,,,,,,,,,,,,,,,,,,,,,
,3834161825.76327,82.4137840270996,9999.53125,-0.000119606356619506,5.32772660512832E-8,1,2,13.4005146026611,4.9834321589103,27.5899991393089,-0.158645350460723,-0.0235331579455415,1,-9.97921546278445E-7,,,,,,,,,,,,,,,,,,,,,82.3420028686523,82.4855651855469,9999.53125,9999.53125,46.8160309735915,5.26740381174156,8.30548858642578,27,1,0,0,1,0.270919799804687,38.1231689453125,2,1,1,82.3420028686523,0,82.4137840270996,,,,,,,,,,,,,,,,,,,,,,,,,,,,,,,,,
,3834161859.98395,79.5549087524414,9999.53125,-0.000119505173978508,5.22695284766111E-8,1,2,13.4005146026611,4.98346220215237,27.5999996811152,-0.158513181479528,-0.0235082398113171,1,-9.93158169532389E-7,,,,,,,,,,,,,,,,,,,,,79.4738998413086,79.6359176635742,9999.53125,9999.53125,46.91920593813,5.26768681474,8.28127002716065,27,1,0,0,1,0.2740478515625,38.1231689453125,2,1,1,79.4738998413086,0,79.5549087524414,,,,,,,,,,,,,,,,,,,,,,,,,,,,,,,,,
,3834161892.58491,76.8437423706055,9999.53125,-0.000119431814841016,3.37597257825128E-8,1,2,13.4005146026611,4.98343832862601,27.5699999183416,-0.158414925682117,-0.0234930091386758,1,-9.92062425533007E-7,,,,,,,,,,,,,,,,,,,,,76.7496719360352,76.9378128051758,9999.53125,9999.53125,46.8922397542165,5.26751632977654,8.27885437011719,27,1,0,0,1,0.27313232421875,38.1231689453125,2,1,1,76.7496719360352,0,76.8437423706055,,,,,,,,,,,,,,,,,,,,,,,,,,,,,,,,,
,3834161926.47836,73.9702606201172,9999.53125,-0.000119279387714748,5.02937032291078E-8,1,2,13.4005146026611,4.9834291826162,27.5699999183416,-0.158203487704287,-0.023526328745995,1,-1.03851073940851E-6,,,,,,,,,,,,,,,,,,,,,73.9061050415039,74.0344161987305,9999.53125,9999.53125,46.783984204303,5.2674506669941,8.25728130340576,27,1,0,0,1,0.27191162109375,38.1231689453125,2,1,1,73.9061050415039,0,73.9702606201172,,,,,,,,,,,,,,,,,,,,,,,,,,,,,,,,,
,3834161957.03324,71.4133415222168,9999.53125,-0.000119293380753046,5.39143372159358E-8,1,2,13.4005146026611,4.98344705836939,27.5699999183416,-0.158223301484194,-0.0235258038238164,1,-1.03607170242006E-6,,,,,,,,,,,,,,,,,,,,,71.3200531005859,71.5066299438477,9999.53125,9999.53125,46.7519374350146,5.26711205314651,8.22956943511963,27,1,0,0,1,0.270614624023438,38.1231689453125,2,1,1,71.3200531005859,0,71.4133415222168,,,,,,,,,,,,,,,,,,,,,,,,,,,,,,,,,
,3834161990.96228,68.4986534118652,9999.53125,-0.000116985478997195,4.85105629435044E-8,1,2,13.4005146026611,4.98346291875615,27.5500006973743,-0.155175375140491,-0.0229817015754766,1,-9.48960004981097E-7,,,,,,,,,,,,,,,,,,,,,68.4408721923828,68.5564346313477,9999.53125,9999.53125,46.7875015326396,5.26723873053309,8.21236801147461,27,1,0,0,1,0.2734375,38.1231689453125,2,1,1,68.4408721923828,0,68.4986534118652,,,,,,,,,,,,,,,,,,,,,,,,,,,,,,,,,
,3834162024.50793,65.6754112243652,9999.53125,-0.000116875191525185,3.43188184328669E-8,1,2,13.4005146026611,4.98345925518357,27.5500006973743,-0.15501816887994,-0.0230369607869793,1,-1.00601032107002E-6,,,,,,,,,,,,,,,,,,,,,65.5377731323242,65.8130493164062,9999.53125,9999.53125,46.794145375053,5.26743874840472,8.18543338775635,27,1,0,0,1,0.27130126953125,38.1231689453125,2,1,1,65.5377731323242,0,65.6754112243652,,,,,,,,,,,,,,,,,,,,,,,,,,,,,,,,,
,3834162057.63879,62.8748779296875,9999.53125,-0.000116779071700219,5.35536348281952E-8,1,2,13.4005146026611,4.98346955708959,27.5500006973743,-0.154897036876528,-0.0229757569993403,1,-9.73312111615939E-7,,,,,,,,,,,,,,,,,,,,,62.7722549438477,62.9775009155273,9999.53125,9999.53125,46.733178350553,5.26663331300891,8.14298057556152,27,1,0,0,1,0.273284912109375,38.1231689453125,2,1,1,62.7722549438477,0,62.8748779296875,,,,,,,,,,,,,,,,,,,,,,,,,,,,,,,,,
,3834162091.70304,60.0122871398926,9999.53125,-0.000116570853062886,5.65412045964296E-8,1,2,13.4005146026611,4.98352917976466,27.5500006973743,-0.154624576179755,-0.0229267004505866,1,-9.6520078910712E-7,,,,,,,,,,,,,,,,,,,,,59.9198455810547,60.1047286987305,9999.53125,9999.53125,46.7894556039376,5.26654431842261,8.12041282653809,27,1,0,0,1,0.272216796875,38.1231689453125,2,1,1,59.9198455810547,0,60.0122871398926,,,,,,,,,,,,,,,,,,,,,,,,,,,,,,,,,
,3834162122.14442,57.4404220581055,9999.53125,-0.000116375067258089,5.9551058761217E-8,1,2,13.4005146026611,4.98355285985286,27.5400001555681,-0.154347955098309,-0.0230165714188908,1,-1.06013779518627E-6,,,,,,,,,,,,,,,,,,,,,57.3400344848633,57.5408096313477,9999.53125,9999.53125,46.7554547633511,5.26728791848276,8.09452056884766,27,1,0,0,1,0.274505615234375,37.6344108581543,2,1,1,57.3400344848633,0,57.4404220581055,,,,,,,,,,,,,,,,,,,,,,,,,,,,,,,,,
,3834162153.42823,54.8443984985352,9999.53125,-0.00011623790821445,4.62828929708974E-8,1,2,13.4005146026611,4.98358023526141,27.5299996137619,-0.154176780859627,-0.0229211217834084,1,-1.00731016244923E-6,,,,,,,,,,,,,,,,,,,,,54.7085494995117,54.9802474975586,9999.53125,9999.53125,46.88872242588,5.26682019127822,8.05668544769287,27,1,0,0,1,0.275650024414062,38.1231689453125,2,1,1,54.7085494995117,0,54.8443984985352,,,,,,,,,,,,,,,,,,,,,,,,,,,,,,,,,
,3834162186.71993,52.0423698425293,9999.53125,-0.000115915535569937,5.43898336604698E-8,1,2,13.4005146026611,4.98354392313382,27.5299996137619,-0.153756651636022,-0.022792955843215,1,-9.5604592368001E-7,,,,,,,,,,,,,,,,,,,,,51.9499931335449,52.1347465515137,9999.53125,9999.53125,46.8074330598799,5.26677058892012,8.00861167907715,27,1,0,0,1,0.271835327148438,38.1231689453125,2,1,1,51.9499931335449,0,52.0423698425293,,,,,,,,,,,,,,,,,,,,,,,,,,,,,,,,,
,3834162218.62633,49.3779468536377,9999.53125,-0.000115732849294997,4.96066395260789E-8,1,2,13.4005146026611,4.98361622222446,27.5100003927946,-0.153506806208481,-0.0228331331098504,1,-1.01150139058393E-6,,,,,,,,,,,,,,,,,,,,,49.279483795166,49.4764099121094,9999.53125,9999.53125,46.7261436938799,5.26670979397942,7.96318674087524,27,1,0,0,1,0.274810791015625,37.6344108581543,2,1,1,49.279483795166,0,49.3779468536377,,,,,,,,,,,,,,,,,,,,,,,,,,,,,,,,,
,3834162251.19016,46.5953636169434,9999.53125,-0.000115512507206584,4.77681753416987E-8,1,2,13.4005146026611,4.98364662778357,27.5100003927946,-0.153211675357601,-0.0228195642858855,1,-1.03194872639636E-6,,,,,,,,,,,,,,,,,,,,,46.5082397460937,46.682487487793,9999.53125,9999.53125,46.8273645871203,5.26656023842849,7.92380905151367,27,1,0,0,1,0.27191162109375,38.1231689453125,2,1,1,46.5082397460937,0,46.5953636169434,,,,,,,,,,,,,,,,,,,,,,,,,,,,,,,,,
,3834162293.18199,43.0844058990479,9999.53125,-0.000115054371716441,5.51174885334456E-8,1,2,13.4005146026611,4.98363987513943,27.5100003927946,-0.152603888112836,-0.0227279362036004,1,-1.02704200101651E-6,,,,,,,,,,,,,,,,,,,,,42.9955024719238,43.1733093261719,9999.53125,9999.53125,46.7683516339184,5.26691251005594,7.85544490814209,27,1,0,0,1,0.273666381835938,38.1231689453125,2,1,1,42.9955024719238,0,43.0844058990479,,,,,,,,,,,,,,,,,,,,,,,,,,,,,,,,,
,3834162333.73648,39.6155529022217,9999.53125,-0.000114727313363477,2.92431581722075E-8,1,2,13.4005146026611,4.98363211774288,27.5100003927946,-0.152160904187783,-0.0227266516443027,1,-1.07184114728273E-6,,,,,,,,,,,,,,,,,,,,,39.4970741271973,39.7340316772461,9999.53125,9999.53125,46.8555032138127,5.26696030121539,7.80350351333618,27,1,0,0,1,0.273208618164062,38.1231689453125,2,1,1,39.4970741271973,0,39.6155529022217,,,,,,,,,,,,,,,,,,,,,,,,,,,,,,,,,
,3834162367.80124,36.8127632141113,9999.53125,-0.000114419266180974,3.02922189916103E-8,1,2,13.4005146026611,4.98361324158973,27.4899993091822,-0.151748160381915,-0.0226898083469053,1,-1.08725857651371E-6,,,,,,,,,,,,,,,,,,,,,36.7578964233398,36.8676300048828,9999.53125,9999.53125,46.7843750185626,5.26681583426964,7.7435154914856,25,1,32,0,0,0.27435302734375,38.1231689453125,2,1,1,36.7578964233398,0,36.8127632141113,,,,,,,,,,,,,,,,,,,,,,,,,,,,,,,,,
,3834162410.36416,33.2236862182617,9999.53125,-0.000113949576554502,5.41746030755664E-8,1,2,13.4005146026611,4.98358341248702,27.4899993091822,-0.151139263408202,-0.0224872800285944,1,-1.00056548985556E-6,,,,,,,,,,,,,,,,,,,,,33.1837043762207,33.2636680603027,9999.53125,9999.53125,46.7136376375722,5.26685811444939,7.64042377471924,27,1,0,0,1,0.275115966796875,38.1231689453125,2,1,1,33.1837043762207,0,33.2236862182617,,,,,,,,,,,,,,,,,,,,,,,,,,,,,,,,,
,3834162460.39147,29.0094738006592,9999.53125,-0.000113398465660931,5.23395746344888E-8,1,2,13.4005146026611,4.98357304255708,27.4999998509884,-0.150408028451268,-0.0223772320875692,1,-9.94803465862242E-7,,,,,,,,,,,,,,,,,,,,,28.9310340881348,29.0879135131836,9999.53125,9999.53125,46.8445604145434,5.26658007104408,7.50378847122192,27,1,0,0,1,0.272445678710938,38.1231689453125,2,1,1,28.9310340881348,0,29.0094738006592,,,,,,,,,,,,,,,,,,,,,,,,,,,,,,,,,
,3834162491.00952,26.4495782852173,9999.53125,-0.000112886433578531,5.46354044490386E-8,1,2,13.4005146026611,4.98359611665342,27.4899993091822,-0.149713364876499,-0.0223941425985574,1,-1.07902337141568E-6,,,,,,,,,,,,,,,,,,,,,26.3459892272949,26.5531673431396,9999.53125,9999.53125,46.723017179803,5.26677032761044,7.39189195632935,27,1,0,0,1,0.27557373046875,38.1231689453125,2,1,1,26.3459892272949,0,26.4495782852173,,,,,,,,,,,,,,,,,,,,,,,,,,,,,,,,,
,3834162524.88732,23.5805473327637,9999.53125,-0.000112259257341985,5.02387085307674E-8,1,2,13.4005146026611,4.98358611447973,27.4899993091822,-0.1488735778884,-0.0223239970694288,1,-1.11394229605008E-6,,,,,,,,,,,,,,,,,,,,,23.4897060394287,23.6713886260986,9999.53125,9999.53125,46.8613654277069,5.26659787378163,7.25801515579224,27,1,0,0,1,0.271835327148438,38.1231689453125,2,1,1,23.4897060394287,0,23.5805473327637,,,,,,,,,,,,,,,,,,,,,,,,,,,,,,,,,
,3834162567.20297,20.0827054977417,9999.53125,-0.00011129581764198,5.51889816131807E-8,1,2,13.4005146026611,4.98359952522652,27.4700000882149,-0.147592113505144,-0.0221634965892745,1,-1.12773176065902E-6,,,,,,,,,,,,,,,,,,,,,20.0074806213379,20.1579303741455,9999.53125,9999.53125,46.8078238741396,5.26677738184673,4.88236045837402,27,1,0,0,1,0.271377563476562,38.1231689453125,2,1,1,20.0074806213379,0,20.0827054977417,,,,,,,,,,,,,,,,,,,,,,,,,,,,,,,,,
,3834162615.55358,16.1007661819458,9999.53125,-0.000109693481117736,5.36811462578872E-8,1,2,13.4005146026611,4.98360028729479,27.4700000882149,-0.145481178884588,-0.0217447656179135,1,-1.0364617343521E-6,,,,,,,,,,,,,,,,,,,,,16.0343952178955,16.1671371459961,9999.53125,9999.53125,46.7812485044857,5.26681270322872,4.53995418548584,27,1,0,0,1,0.2734375,38.1231689453125,2,1,1,16.0343952178955,0,16.1007661819458,,,,,,,,,,,,,,,,,,,,,,,,,,,,,,,,,
,3834162659.89849,12.4787974357605,9999.53125,-0.000107444978508897,7.07715752113687E-8,1,2,13.4005146026611,4.98360341372995,27.4700000882149,-0.142493160513609,-0.0213424022950576,1,-1.04785440482181E-6,,,,,,,,,,,,,,,,,,,,,12.3861570358276,12.5714378356934,9999.53125,9999.53125,46.8172034163703,5.26690401338184,4.14721059799194,27,1,0,0,1,0.275192260742187,38.1231689453125,2,1,1,12.3861570358276,0,12.4787974357605,,,,,,,,,,,,,,,,,,,,,,,,,,,,,,,,,
,3834162701.62846,9.60748863220215,9999.53125,-0.000104331849307361,5.64031748630882E-8,1,2,13.4005146026611,4.98366987545152,27.4800006300211,-0.138382524050031,-0.020613888793373,1,-9.34277013582007E-7,,,,,,,,,,,,,,,,,,,,,9.60748863220215,9.60748863220215,9999.53125,9999.53125,46.7398221929665,5.2664137970428,3.80699801445007,27,1,0,0,1,0.275115966796875,38.1231689453125,6,1,1,9.60748863220215,0,9.60748863220215,,,,,,,,,,,,,,,,,,,,,,,,,,,,,,,,,
,3834162734.41818,7.99595189094543,9999.53125,-0.000101648209011905,5.30682124213334E-8,1,2,13.4005146026611,4.98364944189859,27.4700000882149,-0.134811862148042,-0.0201579662986993,1,-9.66286701374553E-7,,,,,,,,,,,,,,,,,,,,,7.99542856216431,7.99647521972656,9999.53125,9999.53125,46.8105595739569,5.26601532652042,3.6837694644928,27,1,0,0,1,0.272064208984375,38.1231689453125,5,1,1,7.99647521972656,0,7.99595189094543,,,,,,,,,,,,,,,,,,,,,,,,,,,,,,,,,
,3834162766.89067,7.99991869926453,9999.53125,-0.000101604549659407,4.72066103496822E-8,1,2,13.4005146026611,4.9836652681322,27.4700000882149,-0.134765703496996,-0.0200695967497828,1,-9.05783244445468E-7,,,,,,,,,,,,,,,,,,,,,7.99985551834106,7.99998188018799,9999.53125,9999.53125,46.7527190635338,5.26607803913218,3.69336581230164,27,1,0,0,1,0.2734375,38.1231689453125,5,1,1,7.99985551834106,0,7.99991869926453,,,,,,,,,,,,,,,,,,,,,,,,,,,,,,,,,
,3834162782.77955,8.00007510185242,9999.53125,-0.000101662063965216,5.84184750708085E-8,1,2,13.4005146026611,4.98368344494906,27.4700000882149,-0.134847406464652,-0.0200471397724148,1,-8.80755942827794E-7,,,,,,,,,,,,,,,,,,,,,7.99983835220337,8.00031185150146,9999.53125,9999.53125,46.7835933900434,5.26559771127122,3.68000602722168,27,1,0,0,1,0.272445678710938,38.1231689453125,1,1,1,7.99982976913452,0,8.00007510185242,,,,,,,,,,,,,,,,,,,,,,,,,,,,,,,,,