File: SI Fig S11-13 SQUID all/Michaela_Tb_ZFC1T.dat
[Header]
; MPMS3 Data File (default extension .dat)
; Copyright (c) 2007, Quantum Design, Inc. All rights reserved.
TITLE,
FILEOPENTIME,3834067040.46979,06/28/2021,6:38 pm
BYAPP,MPMS3 w/ AC,1.0,1.1
INFO,MPMS3 Measurement Release 1.1.16 Build 424, MultiVu Release 2.3.4.19,APPNAME
INFO,Linear Motor Servo Controller,MOTOR_MODULE_NAME
INFO,3101-100 E1,MOTOR_HW_VERSION
INFO,MMC211,MOTOR_SERIAL_NUMBER
INFO,01.04.28,MOTOR_SOFTWARE_VERSION
INFO,Quantum Design Squid Module,SQUID_MODULE_NAME
INFO,3101-501 B0,SQUID_HW_VERSION
INFO,SQM059,SQUID_SERIAL_NUMBER
INFO,01.03.04,SQUID_SOFTWARE_VERSION
INFO,SQUID AC,AC_MODULE_NAME
INFO,3101-401 F1,AC_HW_VERSION
INFO,SAC057,AC_SERIAL_NUMBER
INFO,SQUID AC 00.95.07,AC_SOFTWARE_VERSION
INFO,TCIXXX,COIL_SERIAL_NUMBER
INFO,0,MOMENT_UNITS
INFO,Michaela_Tb,SAMPLE_MATERIAL
INFO,Michaela_Tb,SAMPLE_COMMENT
INFO,1.8,SAMPLE_MASS
INFO,,SAMPLE_VOLUME
INFO,,SAMPLE_MOLECULAR_WEIGHT
INFO,,SAMPLE_SIZE
INFO,,SAMPLE_SHAPE
INFO,Straw,SAMPLE_HOLDER
INFO,Standard,SAMPLE_HOLDER_DETAIL
INFO,55,SAMPLE_OFFSET
DATATYPE,COMMENT,1
DATATYPE,TIME,2
STARTUPAXIS,X,2
STARTUPAXIS,Y1,5
FIELDGROUP, VSM,2,3,4,5,6,8,9,10,11,14,15
FIELDGROUP, DC, 2,3,4,14,56,57,58,59,60,61,62,63,64,65,66,67,68,69
FIELDGROUP, AC, 2,3,4,11,16,17,18,19,20,21,22,23,24,25,26,27,28,29,30
STARTUPGROUP, All
[Data]
Comment,Time Stamp (sec),Temperature (K),Magnetic Field (Oe),Moment (emu),M. Std. Err. (emu),Transport Action,Averaging Time (sec),Frequency (Hz),Peak Amplitude (mm),Center Position (mm),Lockin Signal' (V),Lockin Signal (V),Range,M. Quad. Signal (emu),AC Moment (emu),AC M. Std Err. (emu),AC Phase (deg),AC Phase Std. Err. (deg),AC Susceptibility (emu/Oe),AC Suscept. Std Err. (emu/Oe),AC X' (emu/Oe),AC X' Std Err. (emu/Oe),AC X'' (emu/Oe),AC X'' Std Err. (emu/Oe),AC Drive (Oe),AC Frequency (Hz),AC Averaging Time (sec),AC Cycles,AC Range,AC Measure Type,AC Signal' (V),AC Signal'' (V),AC Trim Coil Ratio,AC Trim Coil Phase,Min. Temperature (K),Max. Temperature (K),Min. Field (Oe),Max. Field (Oe),Mass (grams),Motor Lag (deg),Pressure (Torr),Measure Count,Measurement Number,SQUID Status (code),Motor Status (code),Measure Status (code),Motor Current (amps),Motor Temp. (C),Temp. Status (code),Field Status (code),Chamber Status (code),Chamber Temp (K),Redirection State,Average Temp (K),Rotation Angle (deg),Rotator state,DC Moment Fixed Ctr (emu),DC Moment Err Fixed Ctr (emu),DC Moment Free Ctr (emu),DC Moment Err Free Ctr (emu),DC Fixed Fit,DC Free Fit,DC Calculated Center (mm),DC Calculated Center Err (mm),DC Scan Length (mm),DC Scan Time (s),DC Number of Points,DC Squid Drift,DC Min V (V),DC Max V (V),DC Scans per Measure,Map 01,Map 02,Map 03,Map 04,Map 05,Map 06,Map 07,Map 08,Map 09,Map 10,Map 11,Map 12,Map 13,Map 14,Map 15,Map 16
,3834067072.90612,8.00249862670898,9999.755859375,0.0211484981970914,8.41518568543061E-6,1,2,13.4005146026611,4.99574328959143,31.2200002372265,28.1434174167044,4.19602405109314,100,0.000192097271193295,,,,,,,,,,,,,,,,,,,,,8.00249862670898,8.00249862670898,9999.755859375,9999.755859375,47.1372802949954,5.27212467397586,7.13924312591553,27,1,0,0,1,0.291671752929687,38.6119270324707,1,1,1,8.00249862670898,0,8.00249862670898,,,,,,,,,,,,,,,,,,,,,,,,,,,,,,,,,
,3834067114.36136,10.9776248931885,9999.755859375,0.0160608807008707,1.05064599772836E-5,1,2,13.4005146026611,4.99595957160923,31.2200002372265,21.3769349496365,3.16812407810758,100,0.000131876638016184,,,,,,,,,,,,,,,,,,,,,10.9018497467041,11.0534000396729,9999.755859375,9999.755859375,47.2369379311973,5.27144958138423,7.78744792938232,27,1,0,0,1,0.291671752929687,39.1006851196289,6,1,1,11.0534000396729,0,10.9776248931885,,,,,,,,,,,,,,,,,,,,,,,,,,,,,,,,,
,3834067147.92283,13.6042375564575,9999.755859375,0.0132229485458741,7.74947194384584E-6,1,2,13.4005146026611,4.99593222306582,31.2200002372265,17.6000951772863,2.6042776490993,100,0.000105554110268838,,,,,,,,,,,,,,,,,,,,,13.4707231521606,13.7377519607544,9999.755859375,9999.755859375,47.35613628038,5.27168103103382,8.23951435089111,27,1,0,0,1,0.29205322265625,39.1006851196289,6,1,1,13.7377519607544,0,13.6042375564575,,,,,,,,,,,,,,,,,,,,,,,,,,,,,,,,,
,3834067181.10344,16.2795515060425,9999.755859375,0.0112905048224153,5.52578787164531E-6,1,2,13.4005146026611,4.99592258397566,31.2200002372265,15.0278958328601,2.22385880327954,100,9.02665144838358E-5,,,,,,,,,,,,,,,,,,,,,16.1745662689209,16.3845367431641,9999.755859375,9999.755859375,47.31549159738,5.27292312059539,8.59920978546143,27,1,0,0,1,0.29083251953125,39.1006851196289,2,1,1,16.3845367431641,0,16.2795515060425,,,,,,,,,,,,,,,,,,,,,,,,,,,,,,,,,
,3834067225.26471,19.7658205032349,9999.755859375,0.00943054317385839,3.87412880472844E-6,1,2,13.4005146026611,4.99585065953981,31.2300007790327,12.5497524933954,1.87355085102205,10,8.74640299438815E-5,,,,,,,,,,,,,,,,,,,,,19.684606552124,19.8470344543457,9999.755859375,9999.755859375,47.2982957699569,5.27261378427127,8.95680904388428,27,1,0,0,1,0.291595458984375,39.1006851196289,2,1,1,19.8470344543457,0,19.7658205032349,,,,,,,,,,,,,,,,,,,,,,,,,,,,,,,,,
,3834067257.74025,22.3600063323975,9999.755859375,0.00842474001695859,3.12444191896437E-6,1,2,13.4005146026611,4.99581895637056,31.2300007790327,11.211279187216,1.67297987683157,10,7.75839557703937E-5,,,,,,,,,,,,,,,,,,,,,22.3066539764404,22.4133586883545,9999.755859375,9999.755859375,47.2170064039569,5.27313715334221,9.17735290527344,27,1,0,0,1,0.292434692382812,39.5894432067871,2,1,1,22.4133586883545,0,22.3600063323975,,,,,,,,,,,,,,,,,,,,,,,,,,,,,,,,,
,3834067289.71189,24.8287134170532,9999.755859375,0.00761861514401995,2.59256039770198E-6,1,2,13.4005146026611,4.99582180044266,31.2300007790327,10.1387685106518,1.51120273513871,10,6.88855879349254E-5,,,,,,,,,,,,,,,,,,,,,24.7443027496338,24.9131240844727,9999.755859375,9999.755859375,47.3369863816589,5.27343105225406,9.33557987213135,27,1,0,0,1,0.291595458984375,39.5894432067871,2,1,1,24.9131240844727,0,24.8287134170532,,,,,,,,,,,,,,,,,,,,,,,,,,,,,,,,,
,3834067331.19511,28.1635608673096,9999.755859375,0.00678633822792512,1.95837629315962E-6,1,2,13.4005146026611,4.99585418947542,31.2300007790327,9.03161070352249,1.34364615336893,10,5.94984912700732E-5,,,,,,,,,,,,,,,,,,,,,28.0372714996338,28.2898502349854,9999.755859375,9999.755859375,47.2928243703223,5.27340946686326,9.53341102600098,27,1,0,0,1,0.291671752929687,39.5894432067871,2,1,1,28.2898502349854,0,28.1635608673096,,,,,,,,,,,,,,,,,,,,,,,,,,,,,,,,,
,3834067362.18528,30.6082983016968,9999.755859375,0.0062607305175488,1.81845574382369E-6,1,2,13.4005146026611,4.99583469546705,31.2300007790327,8.33210692044939,1.23923873570834,10,5.46394360552987E-5,,,,,,,,,,,,,,,,,,,,,30.5375671386719,30.6790294647217,9999.755859375,9999.755859375,47.3569179088992,5.27336728808411,9.67151832580566,27,1,0,0,1,0.290908813476562,39.5894432067871,2,1,1,30.6790294647217,0,30.6082983016968,,,,,,,,,,,,,,,,,,,,,,,,,,,,,,,,,
,3834067395.67777,33.3060569763184,9999.755859375,0.00577740444447603,1.36187325131943E-6,1,2,13.4005146026611,4.99586324294917,31.2300007790327,7.6888951916759,1.14383884396963,10,5.06163619033222E-5,,,,,,,,,,,,,,,,,,,,,33.1678314208984,33.4442825317383,9999.755859375,9999.755859375,47.2541337586204,5.27346338368037,9.79790306091309,27,1,0,0,1,0.292587280273438,39.5894432067871,2,1,1,33.4442825317383,0,33.3060569763184,,,,,,,,,,,,,,,,,,,,,,,,,,,,,,,,,
,3834067426.67047,35.7492599487305,9999.755859375,0.00541051569916357,1.31842376250706E-6,1,2,13.4005146026611,4.9958589221906,31.2300007790327,7.20077154451595,1.07004706015698,10,4.65374053092521E-5,,,,,,,,,,,,,,,,,,,,,35.6712875366211,35.8272323608398,9999.755859375,9999.755859375,47.36629745113,5.27334301615106,9.88749408721924,27,1,0,0,1,0.290298461914063,39.5894432067871,2,1,1,35.8272323608398,0,35.7492599487305,,,,,,,,,,,,,,,,,,,,,,,,,,,,,,,,,
,3834067460.14955,38.4396343231201,9999.755859375,0.00504544011617443,1.01174786299706E-6,1,2,13.4005146026611,4.9958621737467,31.2399994581938,6.71492593423275,0.997690100547373,10,4.32800465488464E-5,,,,,,,,,,,,,,,,,,,,,38.3044090270996,38.5748596191406,9999.755859375,9999.755859375,47.30533042663,5.27339003130053,10.0147771835327,27,1,0,0,1,0.292282104492188,39.5894432067871,2,1,1,38.5748596191406,0,38.4396343231201,,,,,,,,,,,,,,,,,,,,,,,,,,,,,,,,,
,3834067493.34047,41.1498756408691,9999.755859375,0.00474806909717556,9.31239007668945E-7,1,2,13.4005146026611,4.99581289286522,31.2399994581938,6.31932320396622,0.937081489068625,10,3.93831863756094E-5,,,,,,,,,,,,,,,,,,,,,41.0715293884277,41.2282218933105,9999.755859375,9999.755859375,47.2682030719665,5.27387125850444,10.0930013656616,27,1,0,0,1,0.292129516601562,39.5894432067871,2,1,1,41.2282218933105,0,41.1498756408691,,,,,,,,,,,,,,,,,,,,,,,,,,,,,,,,,
,3834067524.72126,43.6152248382568,9999.755859375,0.00448994319991714,9.11333614254625E-7,1,2,13.4005146026611,4.99579905738286,31.2399994581938,5.97589392520661,0.885136115220448,10,3.64930463271405E-5,,,,,,,,,,,,,,,,,,,,,43.4706153869629,43.7598342895508,9999.755859375,9999.755859375,47.2639041151108,5.27387766748265,10.1854219436646,27,1,0,0,1,0.283584594726562,39.5894432067871,2,1,1,43.7598342895508,0,43.6152248382568,,,,,,,,,,,,,,,,,,,,,,,,,,,,,,,,,
,3834067557.85404,46.2959594726562,9999.755859375,0.00426341403064276,3.74875636821624E-6,1,2,13.4005146026611,4.99581331563666,31.2399994581938,5.67505856272441,0.835892904986524,10,3.12078207008652E-5,,,,,,,,,,,,,,,,,,,,,46.1902542114258,46.4016647338867,9999.755859375,9999.755859375,47.2463174734281,5.27386428921185,10.2505187988281,27,1,0,0,1,0.292510986328125,39.5894432067871,2,1,1,46.4016647338867,0,46.2959594726562,,,,,,,,,,,,,,,,,,,,,,,,,,,,,,,,,
,3834067589.84537,48.9137172698975,9999.755859375,0.00403638567381369,6.69960768019904E-7,1,2,13.4005146026611,4.99590345819986,31.2399994581938,5.37236032833059,0.795921423507666,10,3.29385274578337E-5,,,,,,,,,,,,,,,,,,,,,48.8382034301758,48.9892311096191,9999.755859375,9999.755859375,47.3084569407069,5.27423567161186,10.385425567627,27,1,0,0,1,0.291976928710937,39.5894432067871,2,1,1,48.9892311096191,0,48.9137172698975,,,,,,,,,,,,,,,,,,,,,,,,,,,,,,,,,
,3834067622.38367,51.507022857666,9999.755859375,0.00387581952958583,4.74918812391714E-6,1,2,13.4005146026611,4.99589647490306,31.25,5.15976221320186,0.756229990495514,10,2.5603130227895E-5,,,,,,,,,,,,,,,,,,,,,51.4086685180664,51.6053771972656,9999.755859375,9999.755859375,47.3076753121877,5.2744984378737,10.476749420166,27,1,0,0,1,0.290985107421875,39.5894432067871,2,1,1,51.6053771972656,0,51.507022857666,,,,,,,,,,,,,,,,,,,,,,,,,,,,,,,,,
,3834067654.33318,54.0797863006592,9999.755859375,0.00370514121751889,6.5554255983876E-6,1,2,13.4005146026611,4.99591853844697,31.25,4.93254583046472,0.723127769774776,10,2.46222046409516E-5,,,,,,,,,,,,,,,,,,,,,53.9995231628418,54.1600494384766,9999.755859375,9999.755859375,47.3115834547839,5.2745028805973,10.5684328079224,27,1,0,0,1,0.290451049804687,39.5894432067871,2,1,1,54.1600494384766,0,54.0797863006592,,,,,,,,,,,,,,,,,,,,,,,,,,,,,,,,,
,3834067686.84262,56.7246170043945,9999.755859375,0.00351201481460768,1.75890353601391E-6,1,2,13.4005146026611,4.9958550368191,31.25,4.67425131803422,0.693359425598105,10,2.92944560647594E-5,,,,,,,,,,,,,,,,,,,,,56.6223373413086,56.8268966674805,9999.755859375,9999.755859375,47.3369863816589,5.2743476905889,10.6470422744751,27,1,0,0,1,0.283203125,39.5894432067871,2,1,1,56.8268966674805,0,56.7246170043945,,,,,,,,,,,,,,,,,,,,,,,,,,,,,,,,,
,3834067718.79092,59.3054485321045,9999.755859375,0.00341230243012951,5.44547484227979E-6,1,2,13.4005146026611,4.99585772781468,31.2599986791611,4.54349145125299,0.659748324289599,10,1.8011684277734E-5,,,,,,,,,,,,,,,,,,,,,59.2211990356445,59.3896980285645,9999.755859375,9999.755859375,47.3756769933608,5.27337311305095,10.7109451293945,27,1,0,0,1,0.28228759765625,39.5894432067871,2,1,1,59.3896980285645,0,59.3054485321045,,,,,,,,,,,,,,,,,,,,,,,,,,,,,,,,,
,3834067751.32838,61.9210510253906,9999.755859375,0.0032878374819185,4.87471962888564E-6,1,2,13.4005146026611,4.99582452526671,31.2599986791611,4.37940746665486,0.623653123106524,10,8.33024406810973E-6,,,,,,,,,,,,,,,,,,,,,61.815185546875,62.0269165039063,9999.755859375,9999.755859375,47.2584327154761,5.27513788706596,10.8270473480225,27,1,0,0,1,0.291824340820313,40.0782012939453,2,1,1,62.0269165039063,0,61.9210510253906,,,,,,,,,,,,,,,,,,,,,,,,,,,,,,,,,
,3834067785.29793,64.6822929382324,9999.755859375,0.00314189652427862,7.61073930789251E-6,1,2,13.4005146026611,4.9958760741634,31.2599986791611,4.18206692633562,0.617477397841808,10,2.40946311379893E-5,,,,,,,,,,,,,,,,,,,,,64.6083831787109,64.7562026977539,9999.755859375,9999.755859375,47.2377195597165,5.27452209689128,10.9682970046997,27,1,0,0,1,0.283203125,40.0782012939453,2,1,1,64.7562026977539,0,64.6822929382324,,,,,,,,,,,,,,,,,,,,,,,,,,,,,,,,,
,3834067818.80215,67.4132652282715,9999.755859375,0.00302725863271255,7.13509954073845E-6,1,2,13.4005146026611,4.99582681363224,31.2599986791611,4.02997885423463,0.590957529862319,10,2.02270476613866E-5,,,,,,,,,,,,,,,,,,,,,67.2790298461914,67.5475006103516,9999.755859375,9999.755859375,47.198638133755,5.27458935579176,11.1519937515259,27,1,0,0,1,0.2825927734375,40.0782012939453,2,1,1,67.5475006103516,0,67.4132652282715,,,,,,,,,,,,,,,,,,,,,,,,,,,,,,,,,
,3834067849.74434,69.9281196594238,9999.755859375,0.00293692566608394,6.54933647223689E-6,1,2,13.4005146026611,4.99582703624345,31.2700010836124,3.91406122378832,0.54231165467332,10,-3.65036676993172E-6,,,,,,,,,,,,,,,,,,,,,69.8447570800781,70.0114822387695,9999.755859375,9999.755859375,47.2388920024954,5.27437905224264,11.4050121307373,27,1,0,0,1,0.291748046875,40.0782012939453,2,1,1,70.0114822387695,0,69.9281196594238,,,,,,,,,,,,,,,,,,,,,,,,,,,,,,,,,
,3834067883.26644,72.632999420166,9999.755859375,0.00278848235626538,2.65354729192506E-6,1,2,13.4005146026611,4.99581159080644,31.2799997627735,3.71110400806869,0.551445890563977,10,2.39620724989307E-5,,,,,,,,,,,,,,,,,,,,,72.4894332885742,72.7765655517578,9999.755859375,9999.755859375,47.2861805279088,5.27412595462786,11.6080436706543,27,1,0,0,1,0.292129516601562,39.5894432067871,2,1,1,72.7765655517578,0,72.632999420166,,,,,,,,,,,,,,,,,,,,,,,,,,,,,,,,,
,3834067914.31338,75.1482048034668,9999.755859375,0.0027335323179709,8.12780290282382E-6,1,2,13.4005146026611,4.99581615914725,31.2799997627735,3.63964824889058,0.528628996279508,10,1.4521022664733E-5,,,,,,,,,,,,,,,,,,,,,75.0761489868164,75.2202606201172,9999.755859375,9999.755859375,47.2502256160242,5.27421757100627,11.7075805664062,26,1,64,0,0,0.291824340820313,39.5894432067871,2,1,1,75.2202606201172,0,75.1482048034668,,,,,,,,,,,,,,,,,,,,,,,,,,,,,,,,,
,3834067946.73263,77.8070983886719,9999.755859375,0.00265687589916128,5.98031898639984E-6,1,2,13.4005146026611,4.99581008053774,31.2799997627735,3.54046372246527,0.493149016819451,10,-1.38732597995034E-6,,,,,,,,,,,,,,,,,,,,,77.7501220703125,77.8640747070312,9999.755859375,9999.755859375,47.2439725878704,5.27417629492461,11.7890243530273,27,1,0,0,1,0.291824340820313,39.5894432067871,2,1,1,77.8640747070312,0,77.8070983886719,,,,,,,,,,,,,,,,,,,,,,,,,,,,,,,,,
,3834067978.74258,80.4442367553711,9999.755859375,0.00257275231127739,5.53292433465057E-6,1,2,13.4005146026611,4.99579476392857,31.2899984419346,3.4290489648589,0.4725268944714,10,-5.10015448345944E-6,,,,,,,,,,,,,,,,,,,,,80.3667602539063,80.5217132568359,9999.755859375,9999.755859375,47.2580419012165,5.27393919227277,11.8181819915771,27,1,0,0,1,0.291519165039063,39.5894432067871,2,1,1,80.5217132568359,0,80.4442367553711,,,,,,,,,,,,,,,,,,,,,,,,,,,,,,,,,
,3834068012.2098,83.1884994506836,9999.755859375,0.0024853513012802,5.8984946495862E-6,1,2,13.4005146026611,4.99581979510719,31.2899984419346,3.31416425440518,0.445152308163839,10,-1.34262286875082E-5,,,,,,,,,,,,,,,,,,,,,83.0506362915039,83.3263626098633,9999.755859375,9999.755859375,47.2842264566108,5.2737173844611,11.8190498352051,27,1,0,0,1,0.291748046875,39.5894432067871,2,1,1,83.3263626098633,0,83.1884994506836,,,,,,,,,,,,,,,,,,,,,,,,,,,,,,,,,
,3834068045.34838,85.8666839599609,9999.755859375,0.00239721151026421,4.75852359012426E-6,1,2,13.4005146026611,4.99581105942389,31.300000846386,3.19197629086714,0.462604925690522,10,1.19963771788721E-5,,,,,,,,,,,,,,,,,,,,,85.7745895385742,85.9587783813477,9999.755859375,9999.755859375,47.2045003476492,5.27423841639441,11.8833675384521,27,1,0,0,1,0.282440185546875,40.0782012939453,2,1,1,85.9587783813477,0,85.8666839599609,,,,,,,,,,,,,,,,,,,,,,,,,,,,,,,,,
,3834068079.50046,88.7126312255859,9999.755859375,0.0023126107390556,6.26323069612034E-6,1,2,13.4005146026611,4.99577239827982,31.300000846386,3.07724653446701,0.460921789001324,10,2.25658981950136E-5,,,,,,,,,,,,,,,,,,,,,88.6381530761719,88.787109375,9999.755859375,9999.755859375,47.2963416986588,5.27431367338234,11.9109811782837,26,1,64,0,0,0.291976928710937,40.0782012939453,2,1,1,88.787109375,0,88.7126312255859,,,,,,,,,,,,,,,,,,,,,,,,,,,,,,,,,
,3834068112.1589,91.42333984375,9999.755859375,0.00222406833193085,1.48194508547954E-6,1,2,13.4005146026611,4.99586480567098,31.309999525547,2.96025679179119,0.437899479718367,10,1.76596153635772E-5,,,,,,,,,,,,,,,,,,,,,91.3899154663086,91.4567642211914,9999.755859375,9999.755859375,47.2424093308319,5.27306253568997,11.940299987793,25,1,64,0,0,0.292434692382812,39.5894432067871,2,1,1,91.4567642211914,0,91.42333984375,,,,,,,,,,,,,,,,,,,,,,,,,,,,,,,,,
,3834068146.03667,94.2354278564453,9999.755859375,0.00215676604628358,3.14936051657284E-7,1,2,13.4005146026611,4.99578748006121,31.309999525547,2.87074919862467,0.423686129017125,10,1.64099111650531E-5,,,,,,,,,,,,,,,,,,,,,94.144401550293,94.3264541625977,9999.755859375,9999.755859375,47.1540853081588,5.27410514199661,12.0017032623291,27,1,0,0,1,0.29205322265625,39.5894432067871,2,1,1,94.3264541625977,0,94.2354278564453,,,,,,,,,,,,,,,,,,,,,,,,,,,,,,,,,
,3834068178.1524,96.8539733886719,9999.755859375,0.0020990031970555,2.9780230090132E-7,1,2,13.4005146026611,4.99578087564514,31.3199982047081,2.793861384906,0.412323105469748,10,1.59591248959679E-5,,,,,,,,,,,,,,,,,,,,,96.7806091308594,96.9273376464844,9999.755859375,9999.755859375,47.3123650833031,5.27435549918546,12.028694152832,27,1,0,0,1,0.282669067382813,39.5894432067871,2,1,1,96.9273376464844,0,96.8539733886719,,,,,,,,,,,,,,,,,,,,,,,,,,,,,,,,,
,3834068212.51735,99.7094192504883,9999.755859375,0.00204162295945626,2.27708718748424E-7,1,2,13.4005146026611,4.99576380223964,31.3199982047081,2.7175142520164,0.400755697605979,10,1.53022844483261E-5,,,,,,,,,,,,,,,,,,,,,99.6402206420898,99.7786178588867,9999.755859375,9999.755859375,47.3252619538704,5.27431659589296,12.0784969329834,27,1,0,0,1,0.291595458984375,39.5894432067871,2,1,1,99.7786178588867,0,99.7094192504883,,,,,,,,,,,,,,,,,,,,,,,,,,,,,,,,,
,3834068244.65782,102.409973144531,9999.755859375,0.00198942099807856,2.2932127811487E-7,1,2,13.4005146026611,4.99578270628167,31.3300006091595,2.64799481145502,0.390864430204437,10,1.51763762396578E-5,,,,,,,,,,,,,,,,,,,,,102.351013183594,102.468933105469,9999.755859375,9999.755859375,47.2939968131012,5.27398799868345,12.1080026626587,27,1,0,0,1,0.29083251953125,39.5894432067871,2,1,1,102.468933105469,0,102.409973144531,,,,,,,,,,,,,,,,,,,,,,,,,,,,,,,,,
,3834068276.96656,105.078094482422,9999.755859375,0.00194049424461897,1.80852710589354E-7,1,2,13.4005146026611,4.99572859162547,31.3300006091595,2.58286647364972,0.381007562602068,10,1.4624140874566E-5,,,,,,,,,,,,,,,,,,,,,105.00789642334,105.148292541504,9999.755859375,9999.755859375,47.2388920024954,5.27416611504357,12.1412534713745,27,1,0,0,1,0.291900634765625,39.5894432067871,2,1,1,105.148292541504,0,105.078094482422,,,,,,,,,,,,,,,,,,,,,,,,,,,,,,,,,
,3834068309.11085,107.712585449219,9999.755859375,0.00189313523112008,1.62096565913092E-7,1,2,13.4005146026611,4.99573582818895,31.3399992883205,2.5198496162391,0.371604680405721,10,1.41885133625878E-5,,,,,,,,,,,,,,,,,,,,,107.62956237793,107.795608520508,9999.755859375,9999.755859375,47.2482715447262,5.27441074540234,12.1797752380371,27,1,0,0,1,0.291976928710937,40.0782012939453,2,1,1,107.795608520508,0,107.712585449219,,,,,,,,,,,,,,,,,,,,,,,,,,,,,,,,,
,3834068341.44005,110.396602630615,9999.755859375,0.00184851623129012,2.74226150158078E-7,1,2,13.4005146026611,4.99573910337657,31.3399992883205,2.46047002473196,0.362788573475101,10,1.38104710952928E-5,,,,,,,,,,,,,,,,,,,,,110.323593139648,110.469612121582,9999.755859375,9999.755859375,47.20371871913,5.27416322408608,12.2166576385498,27,1,0,0,1,0.2911376953125,39.5894432067871,2,1,1,110.519668579102,0,110.396602630615,,,,,,,,,,,,,,,,,,,,,,,,,,,,,,,,,
,3834068373.6603,113.08194732666,9999.755859375,0.0018056045884096,9.06515626299627E-8,1,2,13.4005146026611,4.9957026080391,31.3500016927719,2.40331841314677,0.35443447585172,10,1.35433537748297E-5,,,,,,,,,,,,,,,,,,,,,112.981155395508,113.182739257813,9999.755859375,9999.755859375,47.1767525352165,5.27385311435197,12.2162094116211,25,1,64,0,0,0.291976928710937,39.5894432067871,2,1,1,113.182739257813,0,113.08194732666,,,,,,,,,,,,,,,,,,,,,,,,,,,,,,,,,
,3834068406.22786,115.758522033691,9999.755859375,0.00176497827856969,2.09441082565733E-7,1,2,13.4005146026611,4.99571302939431,31.360000371933,2.3492903220336,0.34617360000197,10,1.3023194274733E-5,,,,,,,,,,,,,,,,,,,,,115.65111541748,115.865928649902,9999.755859375,9999.755859375,47.3217446255339,5.2738389923038,12.2400856018066,27,1,0,0,1,0.29083251953125,39.5894432067871,2,1,1,115.865928649902,0,115.758522033691,,,,,,,,,,,,,,,,,,,,,,,,,,,,,,,,,
,3834068440.07405,118.537124633789,9999.755859375,0.00173592862847484,1.84320182610574E-6,1,2,13.4005146026611,4.99568557766255,31.360000371933,2.31063131824357,0.340293254110184,10,1.26736514854139E-5,,,,,,,,,,,,,,,,,,,,,118.457733154297,118.616516113281,9999.755859375,9999.755859375,47.2201329180338,5.2742360267855,12.2614088058472,27,1,0,0,1,0.292739868164063,39.5894432067871,2,1,1,118.616516113281,0,118.537124633789,,,,,,,,,,,,,,,,,,,,,,,,,,,,,,,,,
,3834068470.66182,121.105804443359,9999.755859375,0.00169529917132539,1.74709226169018E-6,1,2,13.4005146026611,4.99568241735608,31.3699990510941,2.25638341681788,0.333512449636776,10,1.32656736745747E-5,,,,,,,,,,,,,,,,,,,,,121.016189575195,121.195419311523,9999.755859375,9999.755859375,47.2084084902454,5.2736053757043,12.2669105529785,27,1,0,0,1,0.283279418945313,39.5894432067871,2,1,1,121.195419311523,0,121.105804443359,,,,,,,,,,,,,,,,,,,,,,,,,,,,,,,,,
,3834068504.59228,123.909042358398,9999.755859375,0.00165022100013804,1.86723129029528E-7,1,2,13.4005146026611,4.99565105152099,31.3800014555454,2.19649105129874,0.323754834035272,10,1.22474565610923E-5,,,,,,,,,,,,,,,,,,,,,123.83275604248,123.985328674316,9999.755859375,9999.755859375,47.2459266591685,5.27250445136913,12.2818422317505,27,1,0,0,1,0.2911376953125,39.5894432067871,2,1,1,123.985328674316,0,123.909042358398,,,,,,,,,,,,,,,,,,,,,,,,,,,,,,,,,
,3834068538.12774,126.694725036621,9999.755859375,0.00161781336689198,1.59238805480478E-6,1,2,13.4005146026611,4.99566423357984,31.3800014555454,2.15333405220488,0.317607526844334,10,1.21642144326308E-5,,,,,,,,,,,,,,,,,,,,,126.557456970215,126.831993103027,9999.755859375,9999.755859375,47.3342506818415,5.27402349244324,12.2921695709229,27,1,0,0,1,0.283203125,39.5894432067871,2,1,1,126.831993103027,0,126.694725036621,,,,,,,,,,,,,,,,,,,,,,,,,,,,,,,,,
,3834068571.70252,129.4921875,9999.755859375,0.00158754729558718,1.38535318451733E-6,1,2,13.4005146026611,4.99562712651648,31.3999988138676,2.11311695831732,0.311026006266057,10,1.14589042948876E-5,,,,,,,,,,,,,,,,,,,,,129.40983581543,129.57453918457,9999.755859375,9999.755859375,47.3537913948223,5.27405385362841,12.3251571655273,26,1,64,0,0,0.290908813476562,39.5894432067871,2,1,1,129.57453918457,0,129.4921875,,,,,,,,,,,,,,,,,,,,,,,,,,,,,,,,,
,3834068605.32078,132.266021728516,9999.755859375,0.00155392980058365,2.19657178365696E-6,1,2,13.4005146026611,4.99567096964688,31.3999988138676,2.06810968576299,0.306484005783884,10,1.27477145941039E-5,,,,,,,,,,,,,,,,,,,,,132.184448242188,132.347595214844,9999.755859375,9999.755859375,47.3276068394281,5.27414645591535,12.3324012756348,27,1,0,0,1,0.291061401367188,39.5894432067871,2,1,1,132.347595214844,0,132.266021728516,,,,,,,,,,,,,,,,,,,,,,,,,,,,,,,,,
,3834068638.83414,135.065872192383,9999.755859375,0.00151829442459358,1.75055896635444E-6,1,2,13.4005146026611,4.99564132083316,31.4100012183189,2.02067125422686,0.299419096614067,10,1.24298204205755E-5,,,,,,,,,,,,,,,,,,,,,134.909652709961,135.222091674805,9999.755859375,9999.755859375,47.3244803253512,5.27391353565961,12.3528518676758,27,1,0,0,1,0.2825927734375,39.5894432067871,2,1,1,135.222091674805,0,135.065872192383,,,,,,,,,,,,,,,,,,,,,,,,,,,,,,,,,
,3834068671.92877,137.779441833496,9999.755859375,0.0014910724715433,2.28303695897293E-6,1,2,13.4005146026611,4.99565162288396,31.41999989748,1.98425764560947,0.295410405012737,10,1.32268067197297E-5,,,,,,,,,,,,,,,,,,,,,137.674240112305,137.884643554688,9999.755859375,9999.755859375,47.2639041151108,5.27453903304802,12.3700819015503,27,1,0,0,1,0.291671752929687,39.5894432067871,2,1,1,137.884643554688,0,137.779441833496,,,,,,,,,,,,,,,,,,,,,,,,,,,,,,,,,
,3834068706.03901,140.627838134766,9999.755859375,0.00146207849134415,1.72614852830138E-6,1,2,13.4005146026611,4.9956420504117,31.4299985766411,1.94591993688549,0.287867449917805,10,1.16202307656606E-5,,,,,,,,,,,,,,,,,,,,,140.539077758789,140.716598510742,9999.755859375,9999.755859375,47.2592143439954,5.27394468648756,12.3672428131104,27,1,0,0,1,0.291366577148438,39.5894432067871,2,1,1,140.716598510742,0,140.627838134766,,,,,,,,,,,,,,,,,,,,,,,,,,,,,,,,,
,3834068736.44449,143.168525695801,9999.755859375,0.00143049314839859,1.06600309207829E-7,1,2,13.4005146026611,4.99563893304372,31.4299985766411,1.9040346411735,0.280546124673875,10,1.05419195261118E-5,,,,,,,,,,,,,,,,,,,,,143.058456420898,143.278594970703,9999.755859375,9999.755859375,47.2166155896973,5.27391434729714,12.4115381240845,27,1,0,0,1,0.291290283203125,39.5894432067871,2,1,1,143.278594970703,0,143.168525695801,,,,,,,,,,,,,,,,,,,,,,,,,,,,,,,,,
,3834068770.5001,145.981903076172,9999.755859375,0.00140264311387171,1.53819857226678E-7,1,2,13.4005146026611,4.99562744792771,31.4400009810925,1.8669470539363,0.275171840936677,10,1.04030934597406E-5,,,,,,,,,,,,,,,,,,,,,145.901306152344,146.0625,9999.755859375,9999.755859375,47.208799304505,5.27403429069288,12.4226341247559,27,1,0,0,1,0.291976928710937,39.5894432067871,2,1,1,146.0625,0,145.981903076172,,,,,,,,,,,,,,,,,,,,,,,,,,,,,,,,,
,3834068800.95033,148.493324279785,9999.755859375,0.00137880351747136,1.69954768434084E-7,1,2,13.4005146026611,4.99563692058871,31.4499996602535,1.83525818527003,0.270228459332154,10,1.00257336288888E-5,,,,,,,,,,,,,,,,,,,,,148.399337768555,148.587310791016,9999.755859375,9999.755859375,47.2123166328415,5.27414028400243,12.4406967163086,27,1,0,0,1,0.291976928710937,39.5894432067871,2,1,1,148.587310791016,0,148.493324279785,,,,,,,,,,,,,,,,,,,,,,,,,,,,,,,,,
,3834068835.03864,151.303871154785,9999.755859375,0.00135281410266287,1.05475677824586E-7,1,2,13.4005146026611,4.99563356769419,31.4599983394146,1.80068258281112,0.264996601898952,10,9.73317686227275E-6,,,,,,,,,,,,,,,,,,,,,151.232086181641,151.37565612793,9999.755859375,9999.755859375,47.2299032745242,5.27425916963577,12.4730863571167,27,1,0,0,1,0.292510986328125,40.0782012939453,2,1,1,151.37565612793,0,151.303871154785,,,,,,,,,,,,,,,,,,,,,,,,,,,,,,,,,
,3834068867.43124,154.015785217285,9999.755859375,0.00132912320618691,1.5195025276644E-7,1,2,13.4005146026611,4.99562316839176,31.470000743866,1.76913156366978,0.260440035539623,10,9.6264294926199E-6,,,,,,,,,,,,,,,,,,,,,153.95768737793,154.073883056641,9999.755859375,9999.755859375,47.2846172708704,5.2744545118148,12.4930028915405,27,1,0,0,1,0.29296875,40.0782012939453,2,1,1,154.073883056641,0,154.015785217285,,,,,,,,,,,,,,,,,,,,,,,,,,,,,,,,,
,3834068901.61028,156.877647399902,9999.755859375,0.0013049142485487,8.81846319798366E-8,1,2,13.4005146026611,4.9955906130294,31.470000743866,1.73688719883346,0.255733297402211,10,9.48055683116671E-6,,,,,,,,,,,,,,,,,,,,,156.789169311523,156.966125488281,9999.755859375,9999.755859375,47.2498348017646,5.27421745985399,12.5253944396973,27,1,0,0,1,0.291900634765625,39.5894432067871,2,1,1,156.966125488281,0,156.877647399902,,,,,,,,,,,,,,,,,,,,,,,,,,,,,,,,,
,3834068931.92987,159.409225463867,9999.755859375,0.00128409391008873,8.88140971712764E-8,1,2,13.4005146026611,4.99553769291626,31.479999423027,1.7091592036717,0.251582003140247,10,9.27875480904715E-6,,,,,,,,,,,,,,,,,,,,,159.346343994141,159.472106933594,9999.755859375,9999.755859375,47.2682030719665,5.27454398566125,12.5263671875,27,1,0,0,1,0.291900634765625,39.5894432067871,2,1,1,159.472106933594,0,159.409225463867,,,,,,,,,,,,,,,,,,,,,,,,,,,,,,,,,
,3834068966.08377,162.224365234375,9999.755859375,0.0012609681361841,1.48547840966558E-7,1,2,13.4005146026611,4.99546139598603,31.4900018274784,1.67833491354214,0.247104847260918,10,9.15582469365629E-6,,,,,,,,,,,,,,,,,,,,,162.119522094727,162.329208374023,9999.755859375,9999.755859375,47.2510072445435,5.27517881683195,12.5620908737183,27,1,0,0,1,0.292282104492188,39.5894432067871,2,1,1,162.329208374023,0,162.224365234375,,,,,,,,,,,,,,,,,,,,,,,,,,,,,,,,,
,3834069002.24579,165.200408935547,9999.755859375,0.00123682632900597,9.34418649189968E-8,1,2,13.4005146026611,4.99538352434068,31.5000005066395,1.64569511448533,0.245745646432513,1,1.1515152874964E-5,,,,,,,,,,,,,,,,,,,,,165.108947753906,165.291870117187,9999.755859375,9999.755859375,47.2478807304665,5.27538005783572,12.5795335769653,27,1,0,0,1,0.293807983398438,39.5894432067871,2,1,1,165.291870117187,0,165.200408935547,,,,,,,,,,,,,,,,,,,,,,,,,,,,,,,,,
,3834069034.7696,167.948333740234,9999.755859375,0.00121647341323925,6.44714773329463E-8,1,2,13.4005146026611,4.99534910001655,31.5200015902519,1.61859207362429,0.241746638608088,1,1.13610933190403E-5,,,,,,,,,,,,,,,,,,,,,167.884460449219,168.01220703125,9999.755859375,9999.755859375,47.2990773984762,5.27491086159943,12.6183776855469,27,1,0,0,1,0.291595458984375,39.5894432067871,2,1,1,168.01220703125,0,167.948333740234,,,,,,,,,,,,,,,,,,,,,,,,,,,,,,,,,
,3834069064.66854,170.371871948242,9999.755859375,0.00119826354899445,1.40713302131996E-7,1,2,13.4005146026611,4.99514784738067,31.5200015902519,1.59430448352585,0.237902059746755,1,1.10314138019855E-5,,,,,,,,,,,,,,,,,,,,,170.290191650391,170.453552246094,9999.755859375,9999.755859375,47.3475383666685,5.27608452886864,12.6261625289917,27,1,0,0,1,0.293655395507812,39.5894432067871,2,1,1,170.453552246094,0,170.371871948242,,,,,,,,,,,,,,,,,,,,,,,,,,,,,,,,,
,3834069115.63718,174.671585083008,9999.755859375,0.00116859782614449,1.34335223859844E-7,1,2,13.4005146026611,4.99499504198849,31.5399989485741,1.55473555620324,0.232239707253431,1,1.09363411461888E-5,,,,,,,,,,,,,,,,,,,,,174.58122253418,174.761947631836,9999.755859375,9999.755859375,47.2736744716012,5.27643555284136,12.650182723999,27,1,0,0,1,0.2838134765625,39.5894432067871,2,1,1,174.761947631836,0,174.671585083008,,,,,,,,,,,,,,,,,,,,,,,,,,,,,,,,,
,3834069149.29125,177.423309326172,9999.755859375,0.00115164839726876,9.24705047847576E-7,1,2,13.4005146026611,4.99487292270968,31.5500013530254,1.53220294918924,0.228372236918728,1,1.04088482799255E-5,,,,,,,,,,,,,,,,,,,,,177.349044799805,177.497573852539,9999.755859375,9999.755859375,47.2248226891492,5.27714821414785,12.6499300003052,27,1,0,0,1,0.294113159179687,40.0782012939453,2,1,1,177.497573852539,0,177.423309326172,,,,,,,,,,,,,,,,,,,,,,,,,,,,,,,,,
,3834069191.62201,180.956535339355,9999.755859375,0.00112608730998843,1.24572941087244E-7,1,2,13.4005146026611,4.99479720371645,31.5600000321865,1.49809100185569,0.223822755323123,1,1.05711311203076E-5,,,,,,,,,,,,,,,,,,,,,180.875183105469,181.037887573242,9999.755859375,9999.755859375,47.2091901187646,5.27731942036627,12.652530670166,27,1,0,0,1,0.294876098632812,40.0782012939453,2,1,1,181.037887573242,0,180.956535339355,,,,,,,,,,,,,,,,,,,,,,,,,,,,,,,,,
,3834069225.95706,183.820137023926,9999.755859375,0.00110819114100762,1.01346967166842E-7,1,2,13.4005146026611,4.99473259645988,31.5699987113476,1.47428320376984,0.220072214563165,1,1.02608199666868E-5,,,,,,,,,,,,,,,,,,,,,183.743637084961,183.896636962891,9999.755859375,9999.755859375,47.3643433798319,5.27732436149387,12.6530599594116,27,1,0,0,1,0.28472900390625,39.5894432067871,2,1,1,183.896636962891,0,183.820137023926,,,,,,,,,,,,,,,,,,,,,,,,,,,,,,,,,
,3834069256.09214,186.291641235352,9999.755859375,0.00109273136783019,1.03501155056706E-7,1,2,13.4005146026611,4.99471215503327,31.580001115799,1.45366936438342,0.217278130474523,1,1.03258047615561E-5,,,,,,,,,,,,,,,,,,,,,186.219345092773,186.36393737793,9999.755859375,9999.755859375,47.3432394098127,5.2781754977768,12.6652927398682,27,1,0,0,1,0.276565551757813,39.5894432067871,2,1,1,186.36393737793,0,186.291641235352,,,,,,,,,,,,,,,,,,,,,,,,,,,,,,,,,
,3834069296.41884,189.63655090332,9999.755859375,0.00107271366966347,9.78454375326796E-8,1,2,13.4005146026611,4.99463347389388,31.58999979496,1.42701659529266,0.213237917608589,1,1.0095130549665E-5,,,,,,,,,,,,,,,,,,,,,189.555740356445,189.717361450195,9999.755859375,9999.755859375,47.2791458712358,5.27756260422348,12.6921968460083,27,1,0,0,1,0.284881591796875,39.5894432067871,2,1,1,189.717361450195,0,189.63655090332,,,,,,,,,,,,,,,,,,,,,,,,,,,,,,,,,
,3834069336.83363,192.964332580566,9999.755859375,0.0010534472566278,9.78084896723838E-8,1,2,13.4005146026611,4.99471586626208,31.6100008785725,1.40146339981873,0.209091065855026,1,9.67228615560566E-6,,,,,,,,,,,,,,,,,,,,,192.896682739258,193.031982421875,9999.755859375,9999.755859375,47.3338598675819,5.2764954469717,12.7105674743652,27,1,0,0,1,0.284271240234375,39.5894432067871,2,1,1,193.031982421875,0,192.964332580566,,,,,,,,,,,,,,,,,,,,,,,,,,,,,,,,,
,3834069368.96897,195.655342102051,9999.755859375,0.0010384998778165,7.87615578707871E-8,1,2,13.4005146026611,4.99459372033236,31.6199995577335,1.38153366239232,0.206103542023405,1,9.52466918325135E-6,,,,,,,,,,,,,,,,,,,,,195.580963134766,195.729721069336,9999.755859375,9999.755859375,47.2814907567935,5.27797793405798,12.7193078994751,27,1,0,0,1,0.295028686523438,39.5894432067871,2,1,1,195.729721069336,0,195.655342102051,,,,,,,,,,,,,,,,,,,,,,,,,,,,,,,,,
,3834069401.29492,198.335983276367,9999.755859375,0.00102430905039804,2.40041785401909E-7,1,2,13.4005146026611,4.99447116129519,31.6299982368946,1.36261306221016,0.203255317870214,1,9.37571820190263E-6,,,,,,,,,,,,,,,,,,,,,198.259811401367,198.412155151367,9999.755859375,9999.755859375,47.3076753121877,5.27863587989475,12.7379179000854,27,1,0,0,1,0.286178588867187,39.5894432067871,2,1,1,198.412155151367,0,198.335983276367,,,,,,,,,,,,,,,,,,,,,,,,,,,,,,,,,
,3834069443.78607,201.847808837891,9999.755859375,0.00100511241076386,1.37561512144846E-7,1,2,13.4005146026611,4.99429107854591,31.649999320507,1.33698121005892,0.199643572370676,1,9.35566823619471E-6,,,,,,,,,,,,,,,,,,,,,201.791381835938,201.904235839844,9999.755859375,9999.755859375,47.3022039125531,5.27869181691912,12.7408800125122,25,1,64,0,0,0.286941528320313,39.5894432067871,2,1,1,201.904235839844,0,201.847808837891,,,,,,,,,,,,,,,,,,,,,,,,,,,,,,,,,
,3834069485.1032,205.342864990234,9999.755859375,0.000987153449420427,5.4144634475279E-8,1,2,13.4005146026611,4.99409591627839,31.6600017249584,1.31307320079643,0.195701496474003,1,8.91488075391304E-6,,,,,,,,,,,,,,,,,,,,,205.191970825195,205.493759155273,9999.755859375,9999.755859375,47.3170548544185,5.28109659882586,12.7560806274414,27,1,0,0,1,0.276947021484375,39.5894432067871,2,1,1,205.493759155273,0,205.342864990234,,,,,,,,,,,,,,,,,,,,,,,,,,,,,,,,,
,3834069517.99663,208.039184570313,9999.755859375,0.000973790997657518,1.3846534585502E-7,1,2,13.4005146026611,4.99396882368388,31.6700004041195,1.29527154991914,0.192918906854755,1,8.69901469398834E-6,,,,,,,,,,,,,,,,,,,,,207.951263427734,208.127105712891,9999.755859375,9999.755859375,47.3342506818415,5.28172653406681,12.7769889831543,27,1,0,0,1,0.275039672851562,40.0782012939453,2,1,1,208.127105712891,0,208.039184570313,,,,,,,,,,,,,,,,,,,,,,,,,,,,,,,,,
,3834069562.33228,211.705810546875,9999.755859375,0.000955923128199738,9.82265149443178E-8,1,2,13.4005146026611,4.99407337320351,31.6900014877319,1.27152202952321,0.189522888344078,1,8.64329624977239E-6,,,,,,,,,,,,,,,,,,,,,211.626922607422,211.784698486328,9999.755859375,9999.755859375,47.34597510963,5.28156757618391,12.7836608886719,27,1,0,0,1,0.284500122070313,39.5894432067871,2,1,1,211.784698486328,0,211.705810546875,,,,,,,,,,,,,,,,,,,,,,,,,,,,,,,,,
,3834069605.90681,215.30541229248,9999.755859375,0.000938694338601423,6.81181207160026E-8,1,2,13.4005146026611,4.99401815367517,31.7099988460541,1.24861505280431,0.185898080178894,1,8.33270451365733E-6,,,,,,,,,,,,,,,,,,,,,215.156051635742,215.454772949219,9999.755859375,9999.755859375,47.28500808513,5.28125186099627,12.7892036437988,27,1,0,0,1,0.277328491210938,39.5894432067871,2,1,1,215.454772949219,0,215.30541229248,,,,,,,,,,,,,,,,,,,,,,,,,,,,,,,,,
,3834069636.88787,217.874450683594,9999.755859375,0.000927226492129288,6.49494410608494E-8,1,2,13.4005146026611,4.994014061095,31.7200012505054,1.23333763588706,0.183783739352726,1,8.34874942240926E-6,,,,,,,,,,,,,,,,,,,,,217.800674438477,217.948226928711,9999.755859375,9999.755859375,47.3260435823896,5.28074388377007,12.7808389663696,27,1,0,0,1,0.273208618164062,39.5894432067871,2,1,1,217.948226928711,0,217.874450683594,,,,,,,,,,,,,,,,,,,,,,,,,,,,,,,,,
,3834069670.41159,220.678573608398,9999.755859375,0.000914696206484012,2.10812395861221E-7,1,2,13.4005146026611,4.99389681927421,31.7299999296665,1.21667341696379,0.180994615813063,1,8.01089628476321E-6,,,,,,,,,,,,,,,,,,,,,220.561920166016,220.795227050781,9999.755859375,9999.755859375,47.3158824116396,5.2811700470552,12.7650136947632,27,1,0,0,1,0.275955200195313,40.0782012939453,2,1,1,220.795227050781,0,220.678573608398,,,,,,,,,,,,,,,,,,,,,,,,,,,,,,,,,
,3834069711.47773,224.143226623535,9999.755859375,0.000900049421085921,7.32237676680671E-8,1,2,13.4005146026611,4.99395739432837,31.7399986088276,1.19718356804344,0.178295889661476,1,8.03018978099674E-6,,,,,,,,,,,,,,,,,,,,,224.048767089844,224.237686157227,9999.755859375,9999.755859375,47.29516925588,5.28125895380565,12.7545356750488,27,1,0,0,1,0.286178588867187,39.5894432067871,2,1,1,224.237686157227,0,224.143226623535,,,,,,,,,,,,,,,,,,,,,,,,,,,,,,,,,
,3834069745.66578,226.891090393066,9999.755859375,0.000888105311797735,1.24996968297087E-7,1,2,13.4005146026611,4.99413893284327,31.75999969244,1.18130435702539,0.176302008489003,1,8.19650168026623E-6,,,,,,,,,,,,,,,,,,,,,226.809158325195,226.973022460938,9999.755859375,9999.755859375,47.3334690533223,5.27989761001901,12.7377481460571,27,1,0,0,1,0.2740478515625,39.5894432067871,2,1,1,226.973022460938,0,226.891090393066,,,,,,,,,,,,,,,,,,,,,,,,,,,,,,,,,
,3834069776.02821,229.450897216797,9999.755859375,0.000877878118049551,5.52548651426316E-8,1,2,13.4005146026611,4.99420048704961,31.7699983716011,1.1677670184098,0.173941832976614,1,7.8521885800067E-6,,,,,,,,,,,,,,,,,,,,,229.37825012207,229.523544311523,9999.755859375,9999.755859375,47.2975141414377,5.2796325125668,12.7320528030396,25,1,64,0,0,0.274429321289062,39.5894432067871,2,1,1,229.523544311523,0,229.450897216797,,,,,,,,,,,,,,,,,,,,,,,,,,,,,,,,,
,3834069810.14293,232.275825500488,9999.755859375,0.000866438203174524,8.83812728664158E-8,1,2,13.4005146026611,4.99425020562154,31.7800007760525,1.1525600837168,0.171713978724195,1,7.77726622219044E-6,,,,,,,,,,,,,,,,,,,,,232.185638427734,232.366012573242,9999.755859375,9999.755859375,47.3240895110916,5.2791464843962,12.717267036438,27,1,0,0,1,0.295181274414063,39.5894432067871,2,1,1,232.366012573242,0,232.275825500488,,,,,,,,,,,,,,,,,,,,,,,,,,,,,,,,,
,3834069842.81113,234.996810913086,9999.755859375,0.000855984301325163,1.16738256447557E-7,1,2,13.4005146026611,4.99417153322366,31.8000018596649,1.13860697703672,0.169799180039858,1,7.80405492001905E-6,,,,,,,,,,,,,,,,,,,,,234.905120849609,235.088500976562,9999.755859375,9999.755859375,47.3448026668512,5.27942663000761,12.7232007980347,25,1,64,0,0,0.27557373046875,40.0782012939453,2,1,1,235.088500976562,0,234.996810913086,,,,,,,,,,,,,,,,,,,,,,,,,,,,,,,,,
,3834069874.62992,237.601638793945,9999.755859375,0.000845880772424219,9.65436666703521E-8,1,2,13.4005146026611,4.99409852425497,31.810000538826,1.12518668616454,0.167493494593985,1,7.48810317423415E-6,,,,,,,,,,,,,,,,,,,,,237.526504516602,237.676773071289,9999.755859375,9999.755859375,47.2529613158415,5.27951810753916,12.7195596694946,27,1,0,0,1,0.276870727539062,40.0782012939453,2,1,1,237.676773071289,0,237.601638793945,,,,,,,,,,,,,,,,,,,,,,,,,,,,,,,,,
,3834069907.20598,240.379661560059,9999.755859375,0.000835831231749446,1.01006684911247E-7,1,2,13.4005146026611,4.99407922421917,31.8300016224384,1.11180734638867,0.165542756285149,1,7.42921541569488E-6,,,,,,,,,,,,,,,,,,,,,240.323791503906,240.435531616211,9999.755859375,9999.755859375,47.2861805279088,5.28045124953718,12.7283544540405,26,1,64,0,0,0.276260375976562,40.0782012939453,2,1,1,240.493255615234,0,240.379661560059,,,,,,,,,,,,,,,,,,,,,,,,,,,,,,,,,
,3834069939.12619,242.979698181152,9999.755859375,0.000826108746666755,9.40156831235076E-8,1,2,13.4005146026611,4.99391074901502,31.8400003015995,1.09882714063972,0.16358630531005,1,7.32532027544548E-6,,,,,,,,,,,,,,,,,,,,,242.895919799805,243.0634765625,9999.755859375,9999.755859375,47.3096293834858,5.28093756907056,12.7510643005371,27,1,0,0,1,0.274276733398438,39.5894432067871,2,1,1,243.0634765625,0,242.979698181152,,,,,,,,,,,,,,,,,,,,,,,,,,,,,,,,,
,3834069971.71351,245.737129211426,9999.755859375,0.000816424595280844,1.18564628892548E-7,1,2,13.4005146026611,4.99391872785889,31.8499989807606,1.0859461068708,0.161685363826753,1,7.25173514431568E-6,,,,,,,,,,,,,,,,,,,,,245.642196655273,245.832061767578,9999.755859375,9999.755859375,47.2572602726973,5.28085802743256,12.7590675354004,27,1,0,0,1,0.276031494140625,40.0782012939453,2,1,1,245.832061767578,0,245.737129211426,,,,,,,,,,,,,,,,,,,,,,,,,,,,,,,,,
,3834070005.56526,248.508567810059,9999.755859375,0.000806375191288883,1.20573774286471E-7,1,2,13.4005146026611,4.9937146997305,31.8600013852119,1.07252923019446,0.159613871434029,1,7.10813573935135E-6,,,,,,,,,,,,,,,,,,,,,248.423568725586,248.593566894531,9999.755859375,9999.755859375,47.2947784416204,5.28216193959105,12.7853450775146,27,1,0,0,1,0.277633666992187,39.5894432067871,2,1,1,248.593566894531,0,248.508567810059,,,,,,,,,,,,,,,,,,,,,,,,,,,,,,,,,
,3834070036.19464,251.117691040039,9999.755859375,0.000797910123817232,9.004920214568E-8,1,2,13.4005146026611,4.99341831716906,31.8799987435341,1.06116529453183,0.158058232452707,1,7.13323161548234E-6,,,,,,,,,,,,,,,,,,,,,251.012680053711,251.222702026367,9999.755859375,9999.755859375,47.290088670505,5.28299869094724,12.7991037368774,27,1,0,0,1,0.2850341796875,40.0782012939453,2,1,1,251.222702026367,0,251.117691040039,,,,,,,,,,,,,,,,,,,,,,,,,,,,,,,,,
,3834070070.05503,253.854858398438,9999.755859375,0.000788290306003195,7.76647434052581E-8,1,2,13.4005146026611,4.99323404609749,31.8999998271465,1.04830179480429,0.156264870497613,1,7.13744828638546E-6,,,,,,,,,,,,,,,,,,,,,253.768112182617,253.941604614258,9999.755859375,9999.755859375,47.2603867867742,5.28348578312897,12.8049974441528,27,1,0,0,1,0.277252197265625,40.0782012939453,2,1,1,253.941604614258,0,253.854858398438,,,,,,,,,,,,,,,,,,,,,,,,,,,,,,,,,
,3834070100.66238,256.403930664062,9999.755859375,0.000780064713065584,6.32939000747078E-8,1,2,13.4005146026611,4.99298803788399,31.9099985063076,1.0373372927623,0.154307214092027,1,6.8251560135031E-6,,,,,,,,,,,,,,,,,,,,,256.301391601562,256.506469726562,9999.755859375,9999.755859375,47.2810999425338,5.28546271552206,12.817174911499,27,1,0,0,1,0.274276733398438,40.0782012939453,2,1,1,256.506469726562,0,256.403930664062,,,,,,,,,,,,,,,,,,,,,,,,,,,,,,,,,
,3834070134.5293,259.240814208984,9999.755859375,0.000771906336984643,3.96147706726911E-7,1,2,13.4005146026611,4.99304499216719,31.920000910759,1.02656428719569,0.152266405895946,1,6.43130176281627E-6,,,,,,,,,,,,,,,,,,,,,259.168243408203,259.313385009766,9999.755859375,9999.755859375,47.2939968131012,5.28486476225926,12.8582201004028,27,1,0,0,1,0.274276733398438,40.0782012939453,2,1,1,259.313385009766,0,259.240814208984,,,,,,,,,,,,,,,,,,,,,,,,,,,,,,,,,
,3834070165.06845,261.805068969727,9999.755859375,0.000762771474890527,4.96919850435988E-8,1,2,13.4005146026611,4.99300339032498,31.9399982690811,1.01431871656237,0.151073979358236,1,6.81427045002333E-6,,,,,,,,,,,,,,,,,,,,,261.711547851562,261.898590087891,9999.755859375,9999.755859375,47.2842264566108,5.28510983832274,12.8881196975708,27,1,0,0,1,0.275115966796875,39.5894432067871,2,1,1,261.898590087891,0,261.805068969727,,,,,,,,,,,,,,,,,,,,,,,,,,,,,,,,,
,3834070199.00556,264.584289550781,9999.755859375,0.00075425603255011,1.45080856409558E-7,1,2,13.4005146026611,4.99290178344026,31.9500006735325,1.00296973041034,0.149364276299255,1,6.72394547287927E-6,,,,,,,,,,,,,,,,,,,,,264.499603271484,264.668975830078,9999.755859375,9999.755859375,47.3291700964665,5.28503978806423,12.9404392242432,27,1,0,0,1,0.273971557617187,40.0782012939453,2,1,1,264.668975830078,0,264.584289550781,,,,,,,,,,,,,,,,,,,,,,,,,,,,,,,,,
,3834070229.52722,267.107116699219,9999.755859375,0.000746262959057815,1.04532567607786E-7,1,2,13.4005146026611,4.99288525142206,31.9700017571449,0.99235044294505,0.147680757323473,1,6.57758758403509E-6,,,,,,,,,,,,,,,,,,,,,267.013580322266,267.200653076172,9999.755859375,9999.755859375,47.3291700964665,5.2856621639365,12.9749841690063,27,1,0,0,1,0.276641845703125,40.0782012939453,2,1,1,267.200653076172,0,267.107116699219,,,,,,,,,,,,,,,,,,,,,,,,,,,,,,,,,
,3834070261.47017,269.757141113281,9999.755859375,0.000738160870429446,4.67425321577743E-8,1,2,13.4005146026611,4.99251399147882,31.980000436306,0.981497449604116,0.145913350012893,1,6.39412414435245E-6,,,,,,,,,,,,,,,,,,,,,269.680541992187,269.833740234375,9999.755859375,9999.755859375,47.3874014211492,5.28600207212411,12.9464864730835,27,1,0,0,1,0.275344848632813,40.0782012939453,2,1,1,269.833740234375,0,269.757141113281,,,,,,,,,,,,,,,,,,,,,,,,,,,,,,,,,
,3834070294.00341,272.473022460938,9999.755859375,0.000730257640408831,8.52979403757722E-8,1,2,13.4005146026611,4.99266600122699,32.0000015199184,0.971043565958732,0.14425592272817,1,6.24964429554011E-6,,,,,,,,,,,,,,,,,,,,,272.364044189453,272.582000732422,9999.755859375,9999.755859375,47.2768009856781,5.28561192099532,12.8765354156494,27,1,0,0,1,0.278244018554687,39.5894432067871,2,1,1,272.582000732422,0,272.473022460938,,,,,,,,,,,,,,,,,,,,,,,,,,,,,,,,,
,3834070325.92721,275.131469726562,9999.755859375,0.000722426138964507,5.83654839817626E-8,1,2,13.4005146026611,4.99272551278339,32.0100001990795,0.960640572620786,0.142746419943168,1,6.20906808524248E-6,,,,,,,,,,,,,,,,,,,,,275.045501708984,275.217437744141,9999.755859375,9999.755859375,47.2795366854954,5.28598459938823,12.8444328308105,27,1,0,0,1,0.278244018554687,40.0782012939453,2,1,1,275.217437744141,0,275.131469726562,,,,,,,,,,,,,,,,,,,,,,,,,,,,,,,,,
,3834070358.50247,277.862640380859,9999.755859375,0.000714743720823991,5.43270880914809E-8,1,2,13.4005146026611,4.99256939496658,32.030001282692,0.950382729854671,0.141232964366996,1,6.15099357938619E-6,,,,,,,,,,,,,,,,,,,,,277.741882324219,277.9833984375,9999.755859375,9999.755859375,47.4143676050627,5.28711244707279,12.8189744949341,27,1,0,0,1,0.276260375976562,40.0782012939453,2,1,1,277.9833984375,0,277.862640380859,,,,,,,,,,,,,,,,,,,,,,,,,,,,,,,,,
,3834070390.42881,280.472015380859,9999.755859375,0.000707138492345987,8.29895540878381E-8,1,2,13.4005146026611,4.99248315844289,32.039999961853,0.940195972510513,0.140098451939192,1,6.36466737710643E-6,,,,,,,,,,,,,,,,,,,,,280.381103515625,280.562927246094,9999.755859375,9999.755859375,47.3236986968319,5.28663247402408,12.8084535598755,27,1,0,0,1,0.275726318359375,40.0782012939453,2,1,1,280.562927246094,0,280.472015380859,,,,,,,,,,,,,,,,,,,,,,,,,,,,,,,,,
,3834070423.00572,283.211410522461,9999.755859375,0.000699671863188985,7.78988321329918E-8,1,2,13.4005146026611,4.99256184586456,32.0600010454655,0.930321418530719,0.138387423434997,1,6.12114290908964E-6,,,,,,,,,,,,,,,,,,,,,283.100372314453,283.322448730469,9999.755859375,9999.755859375,47.3424577812935,5.28677011522075,12.7922706604004,27,1,0,0,1,0.2752685546875,40.0782012939453,2,1,1,283.322448730469,0,283.211410522461,,,,,,,,,,,,,,,,,,,,,,,,,,,,,,,,,
,3834070456.88647,285.907150268555,9999.755859375,0.000691739685144321,6.61229575248326E-8,1,2,13.4005146026611,4.9924666666772,32.0799984037876,0.919755255618602,0.1367797753169,1,6.02532436020037E-6,,,,,,,,,,,,,,,,,,,,,285.836395263672,285.977905273438,9999.755859375,9999.755859375,47.2764101714185,5.28731909813666,12.7906799316406,27,1,0,0,1,0.277557373046875,40.0782012939453,2,1,1,285.977905273438,0,285.907150268555,,,,,,,,,,,,,,,,,,,,,,,,,,,,,,,,,
,3834070490.74673,288.652694702148,9999.755859375,0.000685057388896139,4.67227204243356E-8,1,2,13.4005146026611,4.99205016909327,32.090000808239,0.910786170970371,0.135299852871106,1,5.85959482368353E-6,,,,,,,,,,,,,,,,,,,,,288.540222167969,288.765167236328,9999.755859375,9999.755859375,47.340894524255,5.2881658047767,12.7927417755127,27,1,0,0,1,0.277175903320313,39.5894432067871,2,1,1,288.765167236328,0,288.652694702148,,,,,,,,,,,,,,,,,,,,,,,,,,,,,,,,,
,3834070523.64853,291.403717041016,9999.755859375,0.000677724416046351,5.24410249066668E-8,1,2,13.4005146026611,4.99194368085619,32.1099981665611,0.901004513075556,0.133891314022474,1,5.82966425742029E-6,,,,,,,,,,,,,,,,,,,,,291.297149658203,291.510284423828,9999.755859375,9999.755859375,47.3436302240723,5.28873753654439,12.8077735900879,27,1,0,0,1,0.27740478515625,39.5894432067871,2,1,1,291.510284423828,0,291.403717041016,,,,,,,,,,,,,,,,,,,,,,,,,,,,,,,,,
,3834070554.90836,294.093688964844,9999.755859375,0.000670561520414436,5.9687048389224E-8,1,2,13.4005146026611,4.99219593182943,32.1299992501736,0.891540816407426,0.132504586369623,1,5.78247409051401E-6,,,,,,,,,,,,,,,,,,,,,293.943695068359,294.243682861328,9999.755859375,9999.755859375,47.3295609107262,5.28836683193725,12.8096790313721,27,1,0,0,1,0.276412963867187,39.5894432067871,2,1,1,294.243682861328,0,294.093688964844,,,,,,,,,,,,,,,,,,,,,,,,,,,,,,,,,
,3834070588.08531,296.915634155273,9999.755859375,0.000663192984230057,5.92980626081463E-8,1,2,13.4005146026611,4.99224897173204,32.1400016546249,0.881761041919031,0.131020578898745,1,5.69649008094643E-6,,,,,,,,,,,,,,,,,,,,,296.820373535156,297.010894775391,9999.755859375,9999.755859375,47.2932151845819,5.28763997070283,12.8495569229126,27,1,0,0,1,0.278167724609375,40.0782012939453,2,1,1,297.010894775391,0,296.915634155273,,,,,,,,,,,,,,,,,,,,,,,,,,,,,,,,,
,3834070622.13174,299.310180664063,9999.755859375,0.000658367334462224,4.28828665457461E-8,1,2,13.4005146026611,4.99227012323324,32.1599990129471,0.875356411230989,0.130022759465349,1,5.62107170631077E-6,,,,,,,,,,,,,,,,,,,,,299.279754638672,299.340606689453,9999.755859375,9999.755859375,47.4014707344954,5.28747185998098,12.8695249557495,27,1,0,0,1,0.276947021484375,39.5894432067871,6,1,1,299.340606689453,0,299.310180664063,,,,,,,,,,,,,,,,,,,,,,,,,,,,,,,,,
,3834070652.53251,299.771545410156,9999.755859375,0.000657851869758641,6.75084532117019E-8,1,2,13.4005146026611,4.99226571053103,32.1599990129471,0.874679097455609,0.129855713268628,1,5.56777532828883E-6,,,,,,,,,,,,,,,,,,,,,299.763244628906,299.779846191406,9999.755859375,9999.755859375,47.3467567381492,5.28757787949331,12.894326210022,27,1,0,0,1,0.277175903320313,39.5894432067871,5,1,1,299.779846191406,0,299.771545410156,,,,,,,,,,,,,,,,,,,,,,,,,,,,,,,,,
,3834070683.8571,299.90478515625,9999.755859375,0.000657549574383362,5.79065749785502E-8,1,2,13.4005146026611,4.99235249513555,32.1599990129471,0.87428506917147,0.129891576392462,1,5.63465915428678E-6,,,,,,,,,,,,,,,,,,,,,299.90087890625,299.90869140625,9999.755859375,9999.755859375,47.3401128957358,5.28729437476072,12.9065980911255,27,1,0,0,1,0.276870727539062,39.5894432067871,5,1,1,299.90869140625,0,299.90478515625,,,,,,,,,,,,,,,,,,,,,,,,,,,,,,,,,
,3834070692.94718,299.923690795898,9999.755859375,0.000657541974941971,7.86812783497628E-8,1,2,13.4005146026611,4.99235312893146,32.1599990129471,0.874279785715153,0.129856707183491,1,5.60951104825919E-6,,,,,,,,,,,,,,,,,,,,,299.922882080078,299.924499511719,9999.755859375,9999.755859375,47.3072844979281,5.2872541997927,12.9227380752563,27,1,0,0,1,0.277633666992187,39.5894432067871,1,1,1,299.924499511719,0,299.923690795898,,,,,,,,,,,,,,,,,,,,,,,,,,,,,,,,,