File: SI Fig S11-13 SQUID all/Michaela_HO_ZFC1T.dat
[Header]
; MPMS3 Data File (default extension .dat)
; Copyright (c) 2007, Quantum Design, Inc. All rights reserved.
TITLE,
FILEOPENTIME,3834055031.54384,06/28/2021,3:18 pm
BYAPP,MPMS3 w/ AC,1.0,1.1
INFO,MPMS3 Measurement Release 1.1.16 Build 424, MultiVu Release 2.3.4.19,APPNAME
INFO,Linear Motor Servo Controller,MOTOR_MODULE_NAME
INFO,3101-100 E1,MOTOR_HW_VERSION
INFO,MMC211,MOTOR_SERIAL_NUMBER
INFO,01.04.28,MOTOR_SOFTWARE_VERSION
INFO,Quantum Design Squid Module,SQUID_MODULE_NAME
INFO,3101-501 B0,SQUID_HW_VERSION
INFO,SQM059,SQUID_SERIAL_NUMBER
INFO,01.03.04,SQUID_SOFTWARE_VERSION
INFO,SQUID AC,AC_MODULE_NAME
INFO,3101-401 F1,AC_HW_VERSION
INFO,SAC057,AC_SERIAL_NUMBER
INFO,SQUID AC 00.95.07,AC_SOFTWARE_VERSION
INFO,TCIXXX,COIL_SERIAL_NUMBER
INFO,0,MOMENT_UNITS
INFO,Michaela_HO,SAMPLE_MATERIAL
INFO,Michaela_HO,SAMPLE_COMMENT
INFO,1.06,SAMPLE_MASS
INFO,,SAMPLE_VOLUME
INFO,,SAMPLE_MOLECULAR_WEIGHT
INFO,,SAMPLE_SIZE
INFO,,SAMPLE_SHAPE
INFO,Straw,SAMPLE_HOLDER
INFO,Standard,SAMPLE_HOLDER_DETAIL
INFO,52.84,SAMPLE_OFFSET
DATATYPE,COMMENT,1
DATATYPE,TIME,2
STARTUPAXIS,X,2
STARTUPAXIS,Y1,5
FIELDGROUP, VSM,2,3,4,5,6,8,9,10,11,14,15
FIELDGROUP, DC, 2,3,4,14,56,57,58,59,60,61,62,63,64,65,66,67,68,69
FIELDGROUP, AC, 2,3,4,11,16,17,18,19,20,21,22,23,24,25,26,27,28,29,30
STARTUPGROUP, All
[Data]
Comment,Time Stamp (sec),Temperature (K),Magnetic Field (Oe),Moment (emu),M. Std. Err. (emu),Transport Action,Averaging Time (sec),Frequency (Hz),Peak Amplitude (mm),Center Position (mm),Lockin Signal' (V),Lockin Signal (V),Range,M. Quad. Signal (emu),AC Moment (emu),AC M. Std Err. (emu),AC Phase (deg),AC Phase Std. Err. (deg),AC Susceptibility (emu/Oe),AC Suscept. Std Err. (emu/Oe),AC X' (emu/Oe),AC X' Std Err. (emu/Oe),AC X'' (emu/Oe),AC X'' Std Err. (emu/Oe),AC Drive (Oe),AC Frequency (Hz),AC Averaging Time (sec),AC Cycles,AC Range,AC Measure Type,AC Signal' (V),AC Signal'' (V),AC Trim Coil Ratio,AC Trim Coil Phase,Min. Temperature (K),Max. Temperature (K),Min. Field (Oe),Max. Field (Oe),Mass (grams),Motor Lag (deg),Pressure (Torr),Measure Count,Measurement Number,SQUID Status (code),Motor Status (code),Measure Status (code),Motor Current (amps),Motor Temp. (C),Temp. Status (code),Field Status (code),Chamber Status (code),Chamber Temp (K),Redirection State,Average Temp (K),Rotation Angle (deg),Rotator state,DC Moment Fixed Ctr (emu),DC Moment Err Fixed Ctr (emu),DC Moment Free Ctr (emu),DC Moment Err Free Ctr (emu),DC Fixed Fit,DC Free Fit,DC Calculated Center (mm),DC Calculated Center Err (mm),DC Scan Length (mm),DC Scan Time (s),DC Number of Points,DC Squid Drift,DC Min V (V),DC Max V (V),DC Scans per Measure,Map 01,Map 02,Map 03,Map 04,Map 05,Map 06,Map 07,Map 08,Map 09,Map 10,Map 11,Map 12,Map 13,Map 14,Map 15,Map 16
,3834055064.01393,7.99880266189575,9999.6064453125,0.0152000891959865,2.34644099078482E-6,1,2,13.4005146026611,4.99584143772522,33.3499982953072,20.2299710512986,3.00252371330045,100,0.000128031235425328,,,,,,,,,,,,,,,,,,,,,7.99880266189575,7.99880266189575,9999.6064453125,9999.6064453125,47.5163701268223,5.27414549963288,6.57654047012329,27,1,0,0,1,0.2838134765625,39.5894432067871,1,1,1,7.99880266189575,0,7.99880266189575,,,,,,,,,,,,,,,,,,,,,,,,,,,,,,,,,
,3834055105.28962,10.9283967018127,9999.6064453125,0.0120108892010638,6.81484770306404E-6,1,2,13.4005146026611,4.99585519880743,33.3499982953072,15.9859660018248,2.36914745977153,100,9.86077761663552E-5,,,,,,,,,,,,,,,,,,,,,10.8460664749146,11.0107269287109,9999.6064453125,9999.6064453125,47.4694724156685,5.27472474667624,7.1451473236084,27,1,0,0,1,0.292205810546875,40.0782012939453,6,1,1,11.0107269287109,0,10.9283967018127,,,,,,,,,,,,,,,,,,,,,,,,,,,,,,,,,
,3834055137.43986,13.4097428321838,9999.6064453125,0.0101827492970513,5.14462029774678E-6,1,2,13.4005146026611,4.99585087720419,33.3499982953072,13.5531178561182,2.00609978636944,100,8.17642532813198E-5,,,,,,,,,,,,,,,,,,,,,13.3432521820068,13.4762334823608,9999.6064453125,9999.6064453125,47.4929212712454,5.27484225059831,7.5418381690979,27,1,0,0,1,0.291824340820313,40.0782012939453,6,1,1,13.4762334823608,0,13.4097428321838,,,,,,,,,,,,,,,,,,,,,,,,,,,,,,,,,
,3834055175.75034,16.4992895126343,9999.6064453125,0.00859760514030066,3.72730097036146E-6,1,2,13.4005146026611,4.99577759558021,33.3499982953072,11.4407252792531,1.71061784054335,10,8.16749260416706E-5,,,,,,,,,,,,,,,,,,,,,16.4169826507568,16.5815963745117,9999.6064453125,9999.6064453125,47.51871501238,5.27579204842491,7.93324661254883,27,1,0,0,1,0.291900634765625,40.5669593811035,2,1,1,16.5815963745117,0,16.4992895126343,,,,,,,,,,,,,,,,,,,,,,,,,,,,,,,,,
,3834055216.10477,19.6887502670288,9999.6064453125,0.0074077058008013,2.72722638544875E-6,1,2,13.4005146026611,4.99574925032869,33.3499982953072,9.85741637029688,1.47277292574813,10,6.95563236503224E-5,,,,,,,,,,,,,,,,,,,,,19.6032218933105,19.7742786407471,9999.6064453125,9999.6064453125,47.6156369487647,5.27595902593699,8.23385906219482,27,1,0,0,1,0.283355712890625,40.5669593811035,2,1,1,19.7742786407471,0,19.6887502670288,,,,,,,,,,,,,,,,,,,,,,,,,,,,,,,,,
,3834055257.63618,22.9827709197998,9999.6064453125,0.00647463696769632,2.05875305927426E-6,1,2,13.4005146026611,4.99572309005205,33.3499982953072,8.61615114038921,1.28418597691452,10,5.84922240146479E-5,,,,,,,,,,,,,,,,,,,,,22.8572082519531,23.1083335876465,9999.6064453125,9999.6064453125,47.5241864120146,5.27657575977032,8.46017932891846,27,1,0,0,1,0.29205322265625,41.055721282959,2,1,1,23.1083335876465,0,22.9827709197998,,,,,,,,,,,,,,,,,,,,,,,,,,,,,,,,,
,3834055290.79109,25.6040773391724,9999.6064453125,0.0059133303571712,1.75889122002051E-6,1,2,13.4005146026611,4.99576023835357,33.3499982953072,7.86943877279448,1.17166138891192,10,5.2515936312544E-5,,,,,,,,,,,,,,,,,,,,,25.5203323364258,25.6878223419189,9999.6064453125,9999.6064453125,47.4960477853223,5.27583686108947,8.61344623565674,27,1,0,0,1,0.292892456054687,41.055721282959,2,1,1,25.6878223419189,0,25.6040773391724,,,,,,,,,,,,,,,,,,,,,,,,,,,,,,,,,
,3834055322.08201,28.0776100158691,9999.6064453125,0.00543651909824712,1.51774424066653E-6,1,2,13.4005146026611,4.99573576161488,33.3499982953072,7.23495021952141,1.07647330306473,10,4.77515878452576E-5,,,,,,,,,,,,,,,,,,,,,27.938549041748,28.2166709899902,9999.6064453125,9999.6064453125,47.5534974814858,5.27588955739967,8.75855731964111,27,1,0,0,1,0.283660888671875,41.055721282959,2,1,1,28.2166709899902,0,28.0776100158691,,,,,,,,,,,,,,,,,,,,,,,,,,,,,,,,,
,3834055355.26616,30.754997253418,9999.6064453125,0.00503198549990569,1.2528403605942E-6,1,2,13.4005146026611,4.99568718725321,33.3600006997585,6.69661738301882,0.99555864949376,10,4.35975373896456E-5,,,,,,,,,,,,,,,,,,,,,30.6665229797363,30.8434715270996,9999.6064453125,9999.6064453125,47.5425546822166,5.27574465787379,8.8560209274292,27,1,0,0,1,0.291976928710937,41.055721282959,2,1,1,30.8434715270996,0,30.754997253418,,,,,,,,,,,,,,,,,,,,,,,,,,,,,,,,,
,3834055397.34534,34.0660285949707,9999.6064453125,0.00459022294528522,1.18496056773178E-6,1,2,13.4005146026611,4.99565505224785,33.3600006997585,6.10870458457276,0.907841294709704,10,3.95386405419956E-5,,,,,,,,,,,,,,,,,,,,,33.9840850830078,34.1479721069336,9999.6064453125,9999.6064453125,47.5206690836781,5.27609517722379,8.99458885192871,27,1,0,0,1,0.284271240234375,41.055721282959,2,1,1,34.1479721069336,0,34.0660285949707,,,,,,,,,,,,,,,,,,,,,,,,,,,,,,,,,
,3834055437.8642,37.3286571502686,9999.6064453125,0.00423771560624537,9.20567616063127E-7,1,2,13.4005146026611,4.99566156856472,33.3600006997585,5.6398735594359,0.836133625571964,10,3.50077836741393E-5,,,,,,,,,,,,,,,,,,,,,37.2325973510742,37.4247169494629,9999.6064453125,9999.6064453125,47.493312085505,5.27559604040529,9.12772083282471,27,1,0,0,1,0.29296875,41.055721282959,2,1,1,37.4247169494629,0,37.3286571502686,,,,,,,,,,,,,,,,,,,,,,,,,,,,,,,,,
,3834055469.26479,39.8413581848145,9999.6064453125,0.00399498073343093,8.06380040885698E-7,1,2,13.4005146026611,4.99575908269786,33.3600006997585,5.3168494048482,0.789093134139313,10,3.36268708889949E-5,,,,,,,,,,,,,,,,,,,,,39.715404510498,39.9673118591309,9999.6064453125,9999.6064453125,47.5132436127454,5.27563384917372,9.21461009979248,27,1,0,0,1,0.292205810546875,41.055721282959,2,1,1,39.9673118591309,0,39.8413581848145,,,,,,,,,,,,,,,,,,,,,,,,,,,,,,,,,
,3834055502.36318,42.4820404052734,9999.6064453125,0.0037824834242482,6.09200443030294E-7,1,2,13.4005146026611,4.99574913780172,33.3600006997585,5.03404994640275,0.746952543159831,10,3.1713755884421E-5,,,,,,,,,,,,,,,,,,,,,42.3917541503906,42.5723266601562,9999.6064453125,9999.6064453125,47.6144645059858,5.27642082230363,9.28901958465576,27,1,0,0,1,0.282669067382813,41.055721282959,2,1,1,42.5723266601562,0,42.4820404052734,,,,,,,,,,,,,,,,,,,,,,,,,,,,,,,,,
,3834055536.38654,45.2297096252441,9999.6064453125,0.00358867667061125,6.60802610276623E-7,1,2,13.4005146026611,4.99575546955891,33.3699993789196,4.77623561355593,0.707881488280753,10,2.94884418771375E-5,,,,,,,,,,,,,,,,,,,,,45.1499366760254,45.3094825744629,9999.6064453125,9999.6064453125,47.5800728511397,5.27690977498143,9.40081596374512,27,1,0,0,1,0.290451049804687,41.055721282959,2,1,1,45.3094825744629,0,45.2297096252441,,,,,,,,,,,,,,,,,,,,,,,,,,,,,,,,,
,3834055566.81686,47.6889743804932,9999.6064453125,0.00342503240306544,6.19296792184278E-7,1,2,13.4005146026611,4.99579048134259,33.3699993789196,4.55859004749186,0.674837228311343,10,2.75649641390848E-5,,,,,,,,,,,,,,,,,,,,,47.5958290100098,47.7821197509766,9999.6064453125,9999.6064453125,47.5824177366973,5.27697600696933,9.48567962646484,27,1,0,0,1,0.291213989257812,41.055721282959,2,1,1,47.7821197509766,0,47.6889743804932,,,,,,,,,,,,,,,,,,,,,,,,,,,,,,,,,
,3834055600.86779,50.4439888000488,9999.6064453125,0.00324689496745685,5.6471648198511E-7,1,2,13.4005146026611,4.99576413883664,33.3699993789196,4.32155394506812,0.639094831217724,10,2.56515836513438E-5,,,,,,,,,,,,,,,,,,,,,50.3675765991211,50.5204010009766,9999.6064453125,9999.6064453125,47.5194966408993,5.27602392231146,9.60855865478516,27,1,0,0,1,0.283432006835938,41.055721282959,2,1,1,50.5204010009766,0,50.4439888000488,,,,,,,,,,,,,,,,,,,,,,,,,,,,,,,,,
,3834055631.28455,52.8626289367676,9999.6064453125,0.00311881740088274,6.04089284783352E-7,1,2,13.4005146026611,4.99576663388569,33.3699993789196,4.15110356780702,0.613774345685431,10,2.45563747266611E-5,,,,,,,,,,,,,,,,,,,,,52.7654495239258,52.9598083496094,9999.6064453125,9999.6064453125,47.5816361081781,5.27722575619266,9.75540351867676,27,1,0,0,1,0.282974243164062,41.055721282959,2,1,1,52.9598083496094,0,52.8626289367676,,,,,,,,,,,,,,,,,,,,,,,,,,,,,,,,,
,3834055662.59711,55.3974323272705,9999.6064453125,0.00298861676481455,4.50000181577119E-7,1,2,13.4005146026611,4.99577285059722,33.380001783371,3.97782145432614,0.588106580763513,10,2.34969612859837E-5,,,,,,,,,,,,,,,,,,,,,55.2719078063965,55.5229568481445,9999.6064453125,9999.6064453125,47.4636102017743,5.27668953090547,9.86475086212158,27,1,0,0,1,0.293121337890625,41.055721282959,2,1,1,55.5229568481445,0,55.3974323272705,,,,,,,,,,,,,,,,,,,,,,,,,,,,,,,,,
,3834055695.76261,58.1086483001709,9999.6064453125,0.00286708340962474,5.4660451853283E-7,1,2,13.4005146026611,4.99570580048688,33.380001783371,3.81606884691108,0.563627601283512,10,2.21264114001982E-5,,,,,,,,,,,,,,,,,,,,,58.021125793457,58.1961708068848,9999.6064453125,9999.6064453125,47.5550607385243,5.27722360798885,9.95372295379639,27,1,0,0,1,0.292129516601562,41.055721282959,2,1,1,58.1961708068848,0,58.1086483001709,,,,,,,,,,,,,,,,,,,,,,,,,,,,,,,,,
,3834055729.79732,60.860668182373,9999.6064453125,0.00274702369253274,4.95506174191127E-7,1,2,13.4005146026611,4.99569750553766,33.380001783371,3.65627325355441,0.539942798480983,10,2.11386584749021E-5,,,,,,,,,,,,,,,,,,,,,60.7782783508301,60.943058013916,9999.6064453125,9999.6064453125,47.6070390350531,5.27678821885802,10.0377035140991,27,1,0,0,1,0.283355712890625,41.055721282959,2,1,1,60.943058013916,0,60.860668182373,,,,,,,,,,,,,,,,,,,,,,,,,,,,,,,,,
,3834055763.5771,63.5936813354492,9999.6064453125,0.00263645809592503,5.30460782627113E-7,1,2,13.4005146026611,4.9957500039471,33.390000462532,3.50903982613221,0.519088672285918,10,2.09413016995049E-5,,,,,,,,,,,,,,,,,,,,,63.4789619445801,63.7084007263184,9999.6064453125,9999.6064453125,47.4854958003127,5.27605262271161,10.1569051742554,27,1,0,0,1,0.291976928710937,41.055721282959,2,1,1,63.7084007263184,0,63.5936813354492,,,,,,,,,,,,,,,,,,,,,,,,,,,,,,,,,
,3834055796.44574,66.284252166748,9999.6064453125,0.00254450956619509,4.74851911597393E-7,1,2,13.4005146026611,4.99575602560061,33.390000462532,3.38674289432845,0.500428208645573,10,1.97924283169795E-5,,,,,,,,,,,,,,,,,,,,,66.1905975341797,66.3779067993164,9999.6064453125,9999.6064453125,47.5464628248127,5.27727612498013,10.3521146774292,27,1,0,0,1,0.291213989257812,41.055721282959,2,1,1,66.3779067993164,0,66.284252166748,,,,,,,,,,,,,,,,,,,,,,,,,,,,,,,,,
,3834055828.50974,68.8976364135742,9999.6064453125,0.00245894410137635,4.57657646968933E-7,1,2,13.4005146026611,4.99566579993107,33.3999991416931,3.27280646439774,0.48335790015616,10,1.89540883540371E-5,,,,,,,,,,,,,,,,,,,,,68.8247146606445,68.9705581665039,9999.6064453125,9999.6064453125,47.4948753425435,5.27707307038338,10.5945901870728,27,1,0,0,1,0.292434692382812,41.055721282959,2,1,1,68.9705581665039,0,68.8976364135742,,,,,,,,,,,,,,,,,,,,,,,,,,,,,,,,,
,3834055860.95838,71.5277938842773,9999.6064453125,0.0023826244283339,4.27597072436929E-7,1,2,13.4005146026611,4.99570820423975,33.3999991416931,3.17127490687676,0.468278383317092,10,1.83037302449424E-5,,,,,,,,,,,,,,,,,,,,,71.4420776367187,71.6135101318359,9999.6064453125,9999.6064453125,47.577727965582,5.27627332751395,11.1388082504272,26,1,64,0,0,0.291748046875,41.055721282959,2,1,1,71.6135101318359,0,71.5277938842773,,,,,,,,,,,,,,,,,,,,,,,,,,,,,,,,,
,3834055893.02957,74.1341705322266,9999.6064453125,0.00231086792237518,3.98296305435645E-7,1,2,13.4005146026611,4.995741744229,33.3999991416931,3.0758279808,0.453945364749782,10,1.75766794470873E-5,,,,,,,,,,,,,,,,,,,,,74.0572509765625,74.2110900878906,9999.6064453125,9999.6064453125,47.537083282582,5.27639467117509,11.4887647628784,27,1,0,0,1,0.293121337890625,41.055721282959,2,1,1,74.2110900878906,0,74.1341705322266,,,,,,,,,,,,,,,,,,,,,,,,,,,,,,,,,
,3834055923.23849,76.5908699035645,9999.6064453125,0.00224310342612854,1.78351518935125E-7,1,2,13.4005146026611,4.99574392852215,33.4100015461445,2.98562639866803,0.440683970650593,10,1.70987473715386E-5,,,,,,,,,,,,,,,,,,,,,76.5164489746094,76.6652908325195,9999.6064453125,9999.6064453125,47.4788519578993,5.27642805613825,11.6516752243042,27,1,0,0,1,0.292510986328125,41.055721282959,2,1,1,76.6652908325195,0,76.5908699035645,,,,,,,,,,,,,,,,,,,,,,,,,,,,,,,,,
,3834055956.72517,79.2997589111328,9999.6064453125,0.00217202054973107,1.66695472316857E-7,1,2,13.4005146026611,4.99579410561107,33.4100015461445,2.89106590450925,0.426633167814251,10,1.64881448937539E-5,,,,,,,,,,,,,,,,,,,,,79.1604919433594,79.4390258789063,9999.6064453125,9999.6064453125,47.5824177366973,5.27635568799722,11.7805442810059,27,1,0,0,1,0.291061401367188,41.055721282959,2,1,1,79.4390258789063,0,79.2997589111328,,,,,,,,,,,,,,,,,,,,,,,,,,,,,,,,,
,3834055989.87456,82.0359306335449,9999.6064453125,0.00210798895874394,2.34943046607835E-7,1,2,13.4005146026611,4.99577263882986,33.4100015461445,2.80586497124949,0.413733314163814,10,1.57617723669292E-5,,,,,,,,,,,,,,,,,,,,,81.9384460449219,82.133415222168,9999.6064453125,9999.6064453125,47.5374740968416,5.27648483316096,11.8018131256104,27,1,0,0,1,0.283279418945313,41.055721282959,2,1,1,82.133415222168,0,82.0359306335449,,,,,,,,,,,,,,,,,,,,,,,,,,,,,,,,,
,3834056023.93923,84.8355026245117,9999.6064453125,0.0020411281276621,2.93593718725861E-7,1,2,13.4005146026611,4.99576797361627,33.4200002253056,2.71685092138551,0.400714730721339,10,1.53403832630998E-5,,,,,,,,,,,,,,,,,,,,,84.7494430541992,84.9215621948242,9999.6064453125,9999.6064453125,47.5347383970243,5.2766785638318,11.8454122543335,27,1,0,0,1,0.2923583984375,41.055721282959,2,1,1,84.9215621948242,0,84.8355026245117,,,,,,,,,,,,,,,,,,,,,,,,,,,,,,,,,
,3834056056.31828,87.4721260070801,9999.6064453125,0.00198393995545486,3.03954266012748E-7,1,2,13.4005146026611,4.99579122057046,33.4200002253056,2.64077904479791,0.389262482488768,10,1.47398140991695E-5,,,,,,,,,,,,,,,,,,,,,87.4126052856445,87.5316467285156,9999.6064453125,9999.6064453125,47.5718657516877,5.27593791736288,11.8674001693726,27,1,0,0,1,0.292739868164063,41.055721282959,2,1,1,87.5316467285156,0,87.4721260070801,,,,,,,,,,,,,,,,,,,,,,,,,,,,,,,,,
,3834056090.50659,90.3038101196289,9999.6064453125,0.00192547249137062,4.48900256606539E-7,1,2,13.4005146026611,4.99582534494485,33.4299989044666,2.56295151506185,0.377985593482801,10,1.44489859051198E-5,,,,,,,,,,,,,,,,,,,,,90.2127151489258,90.394905090332,9999.6064453125,9999.6064453125,47.6300970763704,5.27678598756511,11.8751621246338,27,1,0,0,1,0.290603637695313,41.055721282959,2,1,1,90.394905090332,0,90.3038101196289,,,,,,,,,,,,,,,,,,,,,,,,,,,,,,,,,
,3834056123.00603,92.9621620178223,9999.6064453125,0.00187542713255723,1.5783806157469E-7,1,2,13.4005146026611,4.99580998494191,33.4299989044666,2.49636226545302,0.367906042731051,10,1.38830426479517E-5,,,,,,,,,,,,,,,,,,,,,92.9188995361328,93.0054244995117,9999.6064453125,9999.6064453125,47.5972686785627,5.27618680950065,11.9119138717651,27,1,0,0,1,0.29083251953125,41.055721282959,2,1,1,93.0054244995117,0,92.9621620178223,,,,,,,,,,,,,,,,,,,,,,,,,,,,,,,,,
,3834056154.9528,95.6578750610352,9999.6064453125,0.00182662295090061,2.30564429144468E-7,1,2,13.4005146026611,4.99582251247461,33.440001308918,2.43143127680228,0.358165783469244,10,1.33960717266523E-5,,,,,,,,,,,,,,,,,,,,,95.5695343017578,95.7462158203125,9999.6064453125,9999.6064453125,47.5789004083608,5.27607743158527,11.9350681304932,27,1,0,0,1,0.290985107421875,41.055721282959,2,1,1,95.7462158203125,0,95.6578750610352,,,,,,,,,,,,,,,,,,,,,,,,,,,,,,,,,
,3834056187.53379,98.3122444152832,9999.6064453125,0.00178200367633113,1.70902201876432E-7,1,2,13.4005146026611,4.99582976005111,33.440001308918,2.37204871375961,0.349376232556399,10,1.303787847663E-5,,,,,,,,,,,,,,,,,,,,,98.2727279663086,98.3517608642578,9999.6064453125,9999.6064453125,47.5214507121973,5.27662067032461,11.9822483062744,27,1,0,0,1,0.29266357421875,41.055721282959,2,1,1,98.3517608642578,0,98.3122444152832,,,,,,,,,,,,,,,,,,,,,,,,,,,,,,,,,
,3834056219.47023,101.004524230957,9999.6064453125,0.00173827722215295,1.82529395749054E-7,1,2,13.4005146026611,4.99583585044295,33.4499999880791,2.31384194925531,0.340845109894284,10,1.27489023700422E-5,,,,,,,,,,,,,,,,,,,,,100.907997131348,101.101051330566,9999.6064453125,9999.6064453125,47.5171517553416,5.27660392192113,11.9930562973022,27,1,0,0,1,0.2911376953125,41.5444793701172,2,1,1,101.101051330566,0,101.004524230957,,,,,,,,,,,,,,,,,,,,,,,,,,,,,,,,,
,3834056251.62922,103.58910369873,9999.6064453125,0.00169798712981945,2.89831361817266E-7,1,2,13.4005146026611,4.99582494478486,33.4499999880791,2.26022930894379,0.332766940389375,10,1.23205655218154E-5,,,,,,,,,,,,,,,,,,,,,103.513771057129,103.664436340332,9999.6064453125,9999.6064453125,47.4139767908031,5.27673629699822,12.0285520553589,27,1,0,0,1,0.291976928710937,41.055721282959,2,1,1,103.664436340332,0,103.58910369873,,,,,,,,,,,,,,,,,,,,,,,,,,,,,,,,,
,3834056283.92217,106.316104888916,9999.6064453125,0.00165828799251401,2.07041457644687E-7,1,2,13.4005146026611,4.99578561934345,33.4599986672401,2.20734942877878,0.325066669972508,10,1.20950727505743E-5,,,,,,,,,,,,,,,,,,,,,106.23656463623,106.395645141602,9999.6064453125,9999.6064453125,47.5132436127454,5.27684797530237,12.0546617507935,27,1,0,0,1,0.283203125,41.5444793701172,2,1,1,106.395645141602,0,106.316104888916,,,,,,,,,,,,,,,,,,,,,,,,,,,,,,,,,
,3834056316.0867,108.958450317383,9999.6064453125,0.00162053897074818,1.37483414008912E-7,1,2,13.4005146026611,4.99569865013518,33.4700010716915,2.15704615768777,0.317688378145739,10,1.18415461744245E-5,,,,,,,,,,,,,,,,,,,,,108.889083862305,109.027816772461,9999.6064453125,9999.6064453125,47.5015191849569,5.27562198913555,12.1038417816162,27,1,0,0,1,0.293121337890625,41.055721282959,2,1,1,109.027816772461,0,108.958450317383,,,,,,,,,,,,,,,,,,,,,,,,,,,,,,,,,
,3834056348.37162,111.648296356201,9999.6064453125,0.00158564130689302,1.28175819845541E-7,1,2,13.4005146026611,4.99576375812016,33.4700010716915,2.11063875775287,0.310809312295201,10,1.15540305188045E-5,,,,,,,,,,,,,,,,,,,,,111.564476013184,111.732116699219,9999.6064453125,9999.6064453125,47.4995651136589,5.275738738829,12.1183729171753,27,1,0,0,1,0.292205810546875,41.055721282959,2,1,1,111.732116699219,0,111.648296356201,,,,,,,,,,,,,,,,,,,,,,,,,,,,,,,,,
,3834056380.92461,114.324481964111,9999.6064453125,0.0015511554422698,1.51643717154416E-7,1,2,13.4005146026611,4.99573436299213,33.4799997508526,2.06470732530219,0.304124648057897,10,1.1360929577608E-5,,,,,,,,,,,,,,,,,,,,,114.278038024902,114.37092590332,9999.6064453125,9999.6064453125,47.5062089560723,5.27648898960759,12.1508150100708,27,1,0,0,1,0.292587280273438,41.055721282959,2,1,1,114.37092590332,0,114.324481964111,,,,,,,,,,,,,,,,,,,,,,,,,,,,,,,,,
,3834056412.8666,116.995639801025,9999.6064453125,0.00151906151801597,1.42481474674496E-7,1,2,13.4005146026611,4.99569345818872,33.4799997508526,2.02197772128462,0.29773906209505,10,1.10584683887361E-5,,,,,,,,,,,,,,,,,,,,,116.913307189941,117.077972412109,9999.6064453125,9999.6064453125,47.5409914251781,5.27646400769846,12.1730880737305,27,1,0,0,1,0.290908813476562,41.055721282959,2,1,1,117.077972412109,0,116.995639801025,,,,,,,,,,,,,,,,,,,,,,,,,,,,,,,,,
,3834056445.39719,119.695446014404,9999.6064453125,0.00148745401255476,1.18717263527838E-7,1,2,13.4005146026611,4.99580898253446,33.4899984300137,1.9799847631438,0.29143770417521,10,1.07417218253768E-5,,,,,,,,,,,,,,,,,,,,,119.646278381348,119.744613647461,9999.6064453125,9999.6064453125,47.4921396427262,5.27624073171757,12.1998825073242,27,1,0,0,1,0.292129516601562,41.055721282959,2,1,1,119.744613647461,0,119.695446014404,,,,,,,,,,,,,,,,,,,,,,,,,,,,,,,,,
,3834056479.39601,122.524234771729,9999.6064453125,0.00145522646957784,1.34142508715465E-7,1,2,13.4005146026611,4.99581045835717,33.500000834465,1.9371260991439,0.284841763830581,10,1.02975807846428E-5,,,,,,,,,,,,,,,,,,,,,122.461212158203,122.587257385254,9999.6064453125,9999.6064453125,47.4448511173127,5.27630507267935,12.2218294143677,27,1,0,0,1,0.283203125,41.5444793701172,2,1,1,122.587257385254,0,122.524234771729,,,,,,,,,,,,,,,,,,,,,,,,,,,,,,,,,
,3834056509.50782,124.981418609619,9999.6064453125,0.00142891643728456,1.30406395019501E-7,1,2,13.4005146026611,4.99579190841526,33.500000834465,1.90208750024062,0.279735556015274,10,1.01452233019907E-5,,,,,,,,,,,,,,,,,,,,,124.902160644531,125.060676574707,9999.6064453125,9999.6064453125,47.4514949597262,5.27602334497804,12.2434120178223,27,1,0,0,1,0.291748046875,41.055721282959,2,1,1,125.060676574707,0,124.981418609619,,,,,,,,,,,,,,,,,,,,,,,,,,,,,,,,,
,3834056543.85152,127.833660125732,9999.6064453125,0.00139932233596773,1.1175947989338E-7,1,2,13.4005146026611,4.99579289165766,33.5099995136261,1.86268882978126,0.273979878059253,10,9.96348645142741E-6,,,,,,,,,,,,,,,,,,,,,127.764106750488,127.903213500977,9999.6064453125,9999.6064453125,47.4808060291973,5.27596704017759,12.2490463256836,27,1,0,0,1,0.291366577148438,41.055721282959,2,1,1,127.903213500977,0,127.833660125732,,,,,,,,,,,,,,,,,,,,,,,,,,,,,,,,,
,3834056573.97162,130.333045959473,9999.6064453125,0.00137406475235671,1.49473018814074E-7,1,2,13.4005146026611,4.99579871099194,33.5199981927872,1.8290393942641,0.269257189624862,10,9.95039267203723E-6,,,,,,,,,,,,,,,,,,,,,130.237518310547,130.428573608398,9999.6064453125,9999.6064453125,47.4096778339473,5.27567872489833,12.2819604873657,27,1,0,0,1,0.292129516601562,41.055721282959,2,1,1,130.428573608398,0,130.333045959473,,,,,,,,,,,,,,,,,,,,,,,,,,,,,,,,,
,3834056608.32842,133.168830871582,9999.6064453125,0.0013466432027709,1.23031546894327E-7,1,2,13.4005146026611,4.99587479836325,33.5300005972385,1.79259094503716,0.263778993018696,10,9.66906651032901E-6,,,,,,,,,,,,,,,,,,,,,133.103820800781,133.233840942383,9999.6064453125,9999.6064453125,47.5159793125627,5.27549380164968,12.2661056518555,27,1,0,0,1,0.291290283203125,41.055721282959,2,1,1,133.233840942383,0,133.168830871582,,,,,,,,,,,,,,,,,,,,,,,,,,,,,,,,,
,3834056638.44745,135.686363220215,9999.6064453125,0.00132322196080067,1.37153408813947E-7,1,2,13.4005146026611,4.99585182974944,33.5399992763996,1.76142450935834,0.25903256737916,10,9.38302427130483E-6,,,,,,,,,,,,,,,,,,,,,135.594955444336,135.777770996094,9999.6064453125,9999.6064453125,47.5312210686877,5.27632853137407,12.2963352203369,27,1,0,0,1,0.290985107421875,41.055721282959,2,1,1,135.777770996094,0,135.686363220215,,,,,,,,,,,,,,,,,,,,,,,,,,,,,,,,,
,3834056672.79162,138.510322570801,9999.6064453125,0.00129854230192733,7.08689292423391E-8,1,2,13.4005146026611,4.99584509541142,33.5399992763996,1.72857685086769,0.254142265720724,10,9.16406586733251E-6,,,,,,,,,,,,,,,,,,,,,138.440353393555,138.580291748047,9999.6064453125,9999.6064453125,47.5273129260916,5.27602742743249,12.2975587844849,27,1,0,0,1,0.291213989257812,41.055721282959,2,1,1,138.580291748047,0,138.510322570801,,,,,,,,,,,,,,,,,,,,,,,,,,,,,,,,,
,3834056702.90847,141.011810302734,9999.6064453125,0.00127683600535765,9.21386709967514E-8,1,2,13.4005146026611,4.995860992007,33.550001680851,1.69967036281808,0.250032362398935,10,9.11386284641372E-6,,,,,,,,,,,,,,,,,,,,,140.897994995117,141.125625610352,9999.6064453125,9999.6064453125,47.5871075078127,5.27580121133726,12.3201713562012,27,1,0,0,1,0.290756225585937,41.055721282959,2,1,1,141.125625610352,0,141.011810302734,,,,,,,,,,,,,,,,,,,,,,,,,,,,,,,,,
,3834056737.29428,143.945999145508,9999.6064453125,0.00125308635571919,1.33832941019811E-7,1,2,13.4005146026611,4.99584786577535,33.5600003600121,1.6680527948054,0.245359545202122,10,8.92840553366484E-6,,,,,,,,,,,,,,,,,,,,,143.866180419922,144.025817871094,9999.6064453125,9999.6064453125,47.4620469447358,5.27571728692777,12.3324327468872,27,1,0,0,1,0.291824340820313,41.055721282959,2,1,1,144.025817871094,0,143.945999145508,,,,,,,,,,,,,,,,,,,,,,,,,,,,,,,,,
,3834056767.40077,146.443290710449,9999.6064453125,0.00123281072347176,1.44935458338786E-7,1,2,13.4005146026611,4.9958774813268,33.5699990391731,1.64108373530062,0.241336843048244,10,8.74295675526143E-6,,,,,,,,,,,,,,,,,,,,,146.345611572266,146.540969848633,9999.6064453125,9999.6064453125,47.5210598979377,5.27558912862729,12.345027923584,27,1,0,0,1,0.292205810546875,41.055721282959,2,1,1,146.540969848633,0,146.443290710449,,,,,,,,,,,,,,,,,,,,,,,,,,,,,,,,,
,3834056799.72203,149.05989074707,9999.6064453125,0.0012125357313536,1.2817504690468E-7,1,2,13.4005146026611,4.99587296956135,33.5699990391731,1.61410762954005,0.237257327189483,10,8.516496658095E-6,,,,,,,,,,,,,,,,,,,,,148.970428466797,149.149353027344,9999.6064453125,9999.6064453125,47.4741621867839,5.27514768742154,12.346905708313,27,1,0,0,1,0.291366577148438,41.055721282959,2,1,1,149.149353027344,0,149.05989074707,,,,,,,,,,,,,,,,,,,,,,,,,,,,,,,,,
,3834056830.1171,151.596221923828,9999.6064453125,0.00119348586326517,1.50115822435405E-7,1,2,13.4005146026611,4.99591554541421,33.5800014436245,1.58878249320243,0.233423918054714,10,8.30116540829865E-6,,,,,,,,,,,,,,,,,,,,,151.539627075195,151.652816772461,9999.6064453125,9999.6064453125,47.4710356727069,5.27561815473325,12.3694591522217,27,1,0,0,1,0.291671752929687,41.055721282959,2,1,1,151.652816772461,0,151.596221923828,,,,,,,,,,,,,,,,,,,,,,,,,,,,,,,,,
,3834056862.1451,154.233047485352,9999.6064453125,0.00117380032367997,1.42908806170506E-7,1,2,13.4005146026611,4.995913786223,33.5900001227856,1.56256415421223,0.22965923135721,10,8.22845004624351E-6,,,,,,,,,,,,,,,,,,,,,154.143615722656,154.322479248047,9999.6064453125,9999.6064453125,47.44758681713,5.27539965585181,12.3939371109009,27,1,0,0,1,0.292129516601562,41.055721282959,2,1,1,154.322479248047,0,154.233047485352,,,,,,,,,,,,,,,,,,,,,,,,,,,,,,,,,
,3834056899.78409,157.366348266602,9999.6064453125,0.0011508810925529,1.77256532551099E-7,1,2,13.4005146026611,4.99587984324167,33.5999988019466,1.53155121297202,0.228667203646397,1,1.0690171131507E-5,,,,,,,,,,,,,,,,,,,,,157.206268310547,157.526428222656,9999.6064453125,9999.6064453125,47.4550122880627,5.27635824287215,12.4073133468628,27,1,0,0,1,0.292129516601562,41.5444793701172,2,1,1,157.526428222656,0,157.366348266602,,,,,,,,,,,,,,,,,,,,,,,,,,,,,,,,,
,3834056942.26739,160.874404907227,9999.6064453125,0.00112645137534432,1.29056309866055E-7,1,2,13.4005146026611,4.99590240220735,33.6199998855591,1.4990361923447,0.223915531031915,1,1.05389394416864E-5,,,,,,,,,,,,,,,,,,,,,160.75146484375,160.997344970703,9999.6064453125,9999.6064453125,47.5452903820339,5.27475886212387,12.4236793518066,27,1,0,0,1,0.291595458984375,41.055721282959,2,1,1,160.997344970703,0,160.874404907227,,,,,,,,,,,,,,,,,,,,,,,,,,,,,,,,,
,3834056975.20826,163.643074035645,9999.6064453125,0.00110963112407348,2.1156584035385E-7,1,2,13.4005146026611,4.99589327723604,33.6199998855591,1.47675899915938,0.219783203795193,1,9.79001161955633E-6,,,,,,,,,,,,,,,,,,,,,163.543045043945,163.743103027344,9999.6064453125,9999.6064453125,47.4589204306589,5.27665876983832,12.4347066879272,27,1,0,0,1,0.290298461914063,41.055721282959,2,1,1,163.743103027344,0,163.643074035645,,,,,,,,,,,,,,,,,,,,,,,,,,,,,,,,,
,3834057006.47481,166.242858886719,9999.6064453125,0.00109269208538026,1.27168931704284E-7,1,2,13.4005146026611,4.99585888250779,33.6299985647202,1.45419410055267,0.216481629126902,1,9.6822587215031E-6,,,,,,,,,,,,,,,,,,,,,166.101547241211,166.384170532227,9999.6064453125,9999.6064453125,47.4667367158512,5.27714485476847,12.4389944076538,27,1,0,0,1,0.292282104492188,41.055721282959,2,1,1,166.384170532227,0,166.242858886719,,,,,,,,,,,,,,,,,,,,,,,,,,,,,,,,,
,3834057039.6438,168.999145507813,9999.6064453125,0.0010761425818193,1.7909238284408E-7,1,2,13.4005146026611,4.99589552180852,33.6400009691715,1.43217326436045,0.213280439575205,1,9.59221388356056E-6,,,,,,,,,,,,,,,,,,,,,168.886001586914,169.112289428711,9999.6064453125,9999.6064453125,47.567566794832,5.27622390433104,12.460000038147,27,1,0,0,1,0.290451049804687,41.055721282959,2,1,1,169.112289428711,0,168.999145507813,,,,,,,,,,,,,,,,,,,,,,,,,,,,,,,,,
,3834057070.9441,171.595260620117,9999.6064453125,0.0010599717347093,1.1426215841806E-7,1,2,13.4005146026611,4.99592654050535,33.6499996483326,1.41065741585718,0.210127675007633,1,9.48585701486579E-6,,,,,,,,,,,,,,,,,,,,,171.455657958984,171.73486328125,9999.6064453125,9999.6064453125,47.4300001754473,5.27603213127872,12.4699048995972,27,1,0,0,1,0.291748046875,41.5444793701172,2,1,1,171.73486328125,0,171.595260620117,,,,,,,,,,,,,,,,,,,,,,,,,,,,,,,,,
,3834057101.86276,174.147094726562,9999.6064453125,0.00104534590042136,1.42023061418411E-7,1,2,13.4005146026611,4.9959393966465,33.6599983274937,1.39121050815373,0.207136747915822,1,9.28573999134857E-6,,,,,,,,,,,,,,,,,,,,,174.07373046875,174.220458984375,9999.6064453125,9999.6064453125,47.4772887008608,5.27554724580678,12.4810371398926,27,1,0,0,1,0.291900634765625,41.055721282959,2,1,1,174.220458984375,0,174.147094726562,,,,,,,,,,,,,,,,,,,,,,,,,,,,,,,,,
,3834057132.44274,176.678421020508,9999.6064453125,0.00103101453925504,1.361966381888E-7,1,2,13.4005146026611,4.99591905775114,33.670000731945,1.37214284896274,0.204202516960811,1,9.08840768526933E-6,,,,,,,,,,,,,,,,,,,,,176.577545166016,176.779296875,9999.6064453125,9999.6064453125,47.5245772262743,5.27635172040382,12.4716873168945,27,1,0,0,1,0.290603637695313,41.055721282959,2,1,1,176.779296875,0,176.678421020508,,,,,,,,,,,,,,,,,,,,,,,,,,,,,,,,,
,3834057166.33456,179.461563110352,9999.6064453125,0.00101531448275821,1.05240205406569E-7,1,2,13.4005146026611,4.9959086686896,33.6799994111061,1.3512411788523,0.201114852733291,1,8.96686567618644E-6,,,,,,,,,,,,,,,,,,,,,179.392700195313,179.530426025391,9999.6064453125,9999.6064453125,47.4847141717935,5.27619144526432,12.4844522476196,27,1,0,0,1,0.291976928710937,41.5444793701172,2,1,1,179.530426025391,0,179.461563110352,,,,,,,,,,,,,,,,,,,,,,,,,,,,,,,,,
,3834057199.85118,182.271507263184,9999.6064453125,0.00100018794757963,1.30204543797062E-7,1,2,13.4005146026611,4.99594024413164,33.6900018155575,1.33111991235118,0.198130957316786,1,8.84128429883307E-6,,,,,,,,,,,,,,,,,,,,,182.144271850586,182.398742675781,9999.6064453125,9999.6064453125,47.5456811962935,5.27559302912129,12.4987001419067,27,1,0,0,1,0.291519165039063,41.055721282959,2,1,1,182.398742675781,0,182.271507263184,,,,,,,,,,,,,,,,,,,,,,,,,,,,,,,,,
,3834057242.96865,185.854331970215,9999.6064453125,0.000981585922754096,1.31018978191354E-7,1,2,13.4005146026611,4.99593673879804,33.7099991738796,1.30635149392311,0.194519422378209,1,8.73208054266434E-6,,,,,,,,,,,,,,,,,,,,,185.774353027344,185.934310913086,9999.6064453125,9999.6064453125,47.5081630273704,5.27563346797778,12.4963846206665,27,1,0,0,1,0.290985107421875,41.5444793701172,2,1,1,185.934310913086,0,185.854331970215,,,,,,,,,,,,,,,,,,,,,,,,,,,,,,,,,
,3834057291.5703,189.909225463867,9999.6064453125,0.000961724763055719,5.71251327349616E-8,1,2,13.4005146026611,4.99592440427546,33.720001578331,1.27987738971424,0.190850351534418,1,8.75609420792846E-6,,,,,,,,,,,,,,,,,,,,,189.859848022461,189.958602905273,9999.6064453125,9999.6064453125,47.4659550873319,5.27588576978608,12.5169858932495,27,1,0,0,1,0.291671752929687,41.055721282959,2,1,1,189.958602905273,0,189.909225463867,,,,,,,,,,,,,,,,,,,,,,,,,,,,,,,,,
,3834057323.53115,192.522796630859,9999.6064453125,0.000948853128452725,8.36098649156409E-8,1,2,13.4005146026611,4.99591321335357,33.7300002574921,1.26280167354869,0.187881225351875,1,8.32804189317455E-6,,,,,,,,,,,,,,,,,,,,,192.434280395508,192.611312866211,9999.6064453125,9999.6064453125,47.4448511173127,5.27622061309678,12.520959854126,27,1,0,0,1,0.291976928710937,41.5444793701172,2,1,1,192.611312866211,0,192.522796630859,,,,,,,,,,,,,,,,,,,,,,,,,,,,,,,,,
,3834057356.0582,195.231452941895,9999.6064453125,0.000936131722876307,1.23418199394827E-7,1,2,13.4005146026611,4.99595084405083,33.7399989366531,1.2458895355742,0.18532437867355,1,8.18651148135228E-6,,,,,,,,,,,,,,,,,,,,,195.176696777344,195.286209106445,9999.6064453125,9999.6064453125,47.4905763856877,5.27577951054425,12.5468282699585,27,1,0,0,1,0.2911376953125,41.055721282959,2,1,1,195.286209106445,0,195.231452941895,,,,,,,,,,,,,,,,,,,,,,,,,,,,,,,,,
,3834057388.00496,197.908767700195,9999.6064453125,0.000923454704431092,1.16926046049708E-7,1,2,13.4005146026611,4.9960414033196,33.7600000202656,1.22903979519327,0.182880202273975,1,8.12137641264041E-6,,,,,,,,,,,,,,,,,,,,,197.817932128906,197.999603271484,9999.6064453125,9999.6064453125,47.5011283706973,5.27459658819558,12.5479593276978,27,1,0,0,1,0.291748046875,41.055721282959,2,1,1,197.999603271484,0,197.908767700195,,,,,,,,,,,,,,,,,,,,,,,,,,,,,,,,,
,3834057422.21814,200.757522583008,9999.6064453125,0.000910835040143837,2.14629075727096E-7,1,2,13.4005146026611,4.99592406156564,33.7699986994266,1.21221077724436,0.180334592785062,1,7.97990890000106E-6,,,,,,,,,,,,,,,,,,,,,200.66796875,200.847076416016,9999.6064453125,9999.6064453125,47.5394281681396,5.27608109434465,12.5583944320679,27,1,0,0,1,0.291519165039063,41.055721282959,2,1,1,200.847076416016,0,200.757522583008,,,,,,,,,,,,,,,,,,,,,,,,,,,,,,,,,
,3834057454.79078,203.455635070801,9999.6064453125,0.000899171808662815,1.43877464802844E-7,1,2,13.4005146026611,4.99594572227278,33.780001103878,1.19670625915148,0.17794980103535,1,7.82019110276595E-6,,,,,,,,,,,,,,,,,,,,,203.33073425293,203.580535888672,9999.6064453125,9999.6064453125,47.521841526457,5.27603550029404,12.5564060211182,27,1,0,0,1,0.291290283203125,41.055721282959,2,1,1,203.580535888672,0,203.455635070801,,,,,,,,,,,,,,,,,,,,,,,,,,,,,,,,,
,3834057488.69865,206.245445251465,9999.6064453125,0.000887178821574702,1.03651044228994E-7,1,2,13.4005146026611,4.99593134550669,33.7899997830391,1.18073801905646,0.175590951430495,1,7.72737183392549E-6,,,,,,,,,,,,,,,,,,,,,206.169845581055,206.321044921875,9999.6064453125,9999.6064453125,47.5589688811204,5.27609363140403,12.5698299407959,27,1,0,0,1,0.290756225585937,41.5444793701172,2,1,1,206.321044921875,0,206.245445251465,,,,,,,,,,,,,,,,,,,,,,,,,,,,,,,,,
,3834057519.25987,208.810668945313,9999.6064453125,0.000876763488931737,1.36392015452413E-7,1,2,13.4005146026611,4.99593301997048,33.7999984622002,1.16688634681162,0.173461956441955,1,7.5858731268322E-6,,,,,,,,,,,,,,,,,,,,,208.698822021484,208.922515869141,9999.6064453125,9999.6064453125,47.5757738942839,5.2763015787565,12.5700254440308,27,1,0,0,1,0.290985107421875,41.5444793701172,2,1,1,208.922515869141,0,208.810668945313,,,,,,,,,,,,,,,,,,,,,,,,,,,,,,,,,
,3834057551.16556,211.455497741699,9999.6064453125,0.000865860295841573,8.87987571418525E-8,1,2,13.4005146026611,4.99594993867799,33.8100008666515,1.15238483106327,0.171275432983373,1,7.46887933738758E-6,,,,,,,,,,,,,,,,,,,,,211.358596801758,211.552398681641,9999.6064453125,9999.6064453125,47.5054273275531,5.27620231192742,12.5921506881714,27,1,0,0,1,0.282516479492187,41.055721282959,2,1,1,211.552398681641,0,211.455497741699,,,,,,,,,,,,,,,,,,,,,,,,,,,,,,,,,
,3834057583.98916,214.181465148926,9999.6064453125,0.000854959750998277,6.71116693111131E-8,1,2,13.4005146026611,4.9958680523598,33.8299982249737,1.1378514432611,0.169116586008519,1,7.37573828547766E-6,,,,,,,,,,,,,,,,,,,,,214.108169555664,214.254760742187,9999.6064453125,9999.6064453125,47.4022523630146,5.27614281553632,12.5658922195435,26,1,64,0,0,0.291900634765625,41.055721282959,2,1,1,214.254760742187,0,214.181465148926,,,,,,,,,,,,,,,,,,,,,,,,,,,,,,,,,
,3834057617.64238,216.955505371094,9999.6064453125,0.000844240839654282,1.49302793535528E-7,1,2,13.4005146026611,4.99583751883597,33.840000629425,1.12357785470322,0.166984658740176,1,7.27556695305886E-6,,,,,,,,,,,,,,,,,,,,,216.886413574219,217.024597167969,9999.6064453125,9999.6064453125,47.5382557253608,5.27615696152652,12.5914649963379,27,1,0,0,1,0.291824340820313,41.055721282959,2,1,1,217.024597167969,0,216.955505371094,,,,,,,,,,,,,,,,,,,,,,,,,,,,,,,,,
,3834057648.18742,219.542030334473,9999.6064453125,0.000834521001059568,9.38181514134011E-8,1,2,13.4005146026611,4.99578268262839,33.8499993085861,1.1105947607018,0.165277941808814,1,7.35561809880314E-6,,,,,,,,,,,,,,,,,,,,,219.442687988281,219.641372680664,9999.6064453125,9999.6064453125,47.562486209457,5.27660222804202,12.5747766494751,27,1,0,0,1,0.292434692382812,41.5444793701172,2,1,1,219.641372680664,0,219.542030334473,,,,,,,,,,,,,,,,,,,,,,,,,,,,,,,,,
,3834057680.10312,222.180381774902,9999.6064453125,0.000824700075137736,1.63499330282706E-7,1,2,13.4005146026611,4.99582867545605,33.8600017130375,1.09755536652699,0.163216075453357,1,7.17983799663059E-6,,,,,,,,,,,,,,,,,,,,,222.105865478516,222.254898071289,9999.6064453125,9999.6064453125,47.5515434101877,5.27666438203048,12.6019420623779,27,1,0,0,1,0.283660888671875,41.5444793701172,2,1,1,222.254898071289,0,222.180381774902,,,,,,,,,,,,,,,,,,,,,,,,,,,,,,,,,
,3834057712.65244,224.913772583008,9999.6064453125,0.000814796537510943,5.12114508333417E-8,1,2,13.4005146026611,4.99582518863768,33.8799990713596,1.08436137585098,0.16134740195103,1,7.16227650995158E-6,,,,,,,,,,,,,,,,,,,,,224.798980712891,225.028564453125,9999.6064453125,9999.6064453125,47.5769463370627,5.27629084426921,12.6132860183716,27,1,0,0,1,0.28228759765625,41.055721282959,2,1,1,225.028564453125,0,224.913772583008,,,,,,,,,,,,,,,,,,,,,,,,,,,,,,,,,
,3834057746.64699,227.700897216797,9999.6064453125,0.000804834440891562,9.39385954988905E-8,1,2,13.4005146026611,4.99583339144135,33.890001475811,1.07112150850524,0.159263116548635,1,6.99070382077787E-6,,,,,,,,,,,,,,,,,,,,,227.624313354492,227.777481079102,9999.6064453125,9999.6064453125,47.51871501238,5.27612014304642,12.6110134124756,27,1,0,0,1,0.292282104492188,41.055721282959,2,1,1,227.777481079102,0,227.700897216797,,,,,,,,,,,,,,,,,,,,,,,,,,,,,,,,,
,3834057780.20386,230.473854064941,9999.6064453125,0.000795026702905388,9.1233297322861E-8,1,2,13.4005146026611,4.99586121439769,33.9000001549721,1.0580953806852,0.157191063319198,1,6.80610092089139E-6,,,,,,,,,,,,,,,,,,,,,230.326171875,230.621536254883,9999.6064453125,9999.6064453125,47.5597505096396,5.27648300699216,12.6191110610962,27,1,0,0,1,0.291976928710937,41.055721282959,2,1,1,230.621536254883,0,230.473854064941,,,,,,,,,,,,,,,,,,,,,,,,,,,,,,,,,
,3834057811.12285,233.041885375977,9999.6064453125,0.000786594418519732,1.19548145406804E-7,1,2,13.4005146026611,4.99587844963123,33.9099988341331,1.04687060627922,0.15557646296481,1,6.77284710856993E-6,,,,,,,,,,,,,,,,,,,,,232.952621459961,233.131149291992,9999.6064453125,9999.6064453125,47.5687392376108,5.27630411310888,12.6494474411011,27,1,0,0,1,0.291213989257812,41.5444793701172,2,1,1,233.131149291992,0,233.041885375977,,,,,,,,,,,,,,,,,,,,,,,,,,,,,,,,,
,3834057844.58995,235.835235595703,9999.6064453125,0.000777231944851421,5.67543727228577E-8,1,2,13.4005146026611,4.99587239625737,33.9200012385845,1.03440968927278,0.153715714182693,1,6.68567524219075E-6,,,,,,,,,,,,,,,,,,,,,235.702224731445,235.968246459961,9999.6064453125,9999.6064453125,47.483150914755,5.27620652087468,12.6492176055908,27,1,0,0,1,0.28350830078125,41.055721282959,2,1,1,235.968246459961,0,235.835235595703,,,,,,,,,,,,,,,,,,,,,,,,,,,,,,,,,
,3834057875.66524,238.439407348633,9999.6064453125,0.000768794042663199,9.62566975757607E-8,1,2,13.4005146026611,4.99586804761459,33.9399985969067,1.02314813960407,0.152264275244966,1,6.77634689511711E-6,,,,,,,,,,,,,,,,,,,,,238.369415283203,238.509399414062,9999.6064453125,9999.6064453125,47.6046941494954,5.27679636171099,12.6761207580566,26,1,64,0,0,0.291290283203125,41.055721282959,2,1,1,238.509399414062,0,238.439407348633,,,,,,,,,,,,,,,,,,,,,,,,,,,,,,,,,
,3834057909.05498,241.211090087891,9999.6064453125,0.000760006912878067,9.76653819713632E-8,1,2,13.4005146026611,4.99587788654709,33.950001001358,1.01150886636587,0.150150046681292,1,6.41799996709581E-6,,,,,,,,,,,,,,,,,,,,,241.041091918945,241.381088256836,9999.6064453125,9999.6064453125,47.6074298493127,5.276828845792,12.7012376785278,27,1,0,0,1,0.291519165039063,41.5444793701172,2,1,1,241.381088256836,0,241.211090087891,,,,,,,,,,,,,,,,,,,,,,,,,,,,,,,,,
,3834057944.19129,244.132148742676,9999.6064453125,0.000751022143527863,9.81681949065729E-8,1,2,13.4005146026611,4.99586193112951,33.9699983596802,0.999542332371684,0.148403988936586,1,6.36438481442589E-6,,,,,,,,,,,,,,,,,,,,,244.053039550781,244.21125793457,9999.6064453125,9999.6064453125,47.5128527984858,5.27669094196088,12.7339267730713,27,1,0,0,1,0.29144287109375,41.055721282959,2,1,1,244.21125793457,0,244.132148742676,,,,,,,,,,,,,,,,,,,,,,,,,,,,,,,,,
,3834057976.30404,246.76830291748,9999.6064453125,0.000742961899762814,6.93016218074235E-8,1,2,13.4005146026611,4.9958579141129,33.9800007641315,0.988817258116601,0.146786299415275,1,6.27746654753819E-6,,,,,,,,,,,,,,,,,,,,,246.68244934082,246.854156494141,9999.6064453125,9999.6064453125,47.5761647085435,5.27684622561936,12.7619209289551,27,1,0,0,1,0.291824340820313,41.5444793701172,2,1,1,246.854156494141,0,246.76830291748,,,,,,,,,,,,,,,,,,,,,,,,,,,,,,,,,
,3834058008.6958,249.469146728516,9999.6064453125,0.000734911724059578,7.3887045731377E-8,1,2,13.4005146026611,4.99584008957484,34.000001847744,0.978094087617249,0.145225959794459,1,6.23259025118958E-6,,,,,,,,,,,,,,,,,,,,,249.399337768555,249.538955688477,9999.6064453125,9999.6064453125,47.49839267088,5.27671407682534,12.7826194763184,27,1,0,0,1,0.291824340820313,41.055721282959,2,1,1,249.538955688477,0,249.469146728516,,,,,,,,,,,,,,,,,,,,,,,,,,,,,,,,,
,3834058042.92889,252.311820983887,9999.6064453125,0.000726689072144084,7.37808759539984E-8,1,2,13.4005146026611,4.99585563660976,34.0100005269051,0.967159190789919,0.143569444318126,1,6.13865421826167E-6,,,,,,,,,,,,,,,,,,,,,252.225692749023,252.39794921875,9999.6064453125,9999.6064453125,47.5761647085435,5.27680126989649,12.7924661636353,27,1,0,0,1,0.292129516601562,41.055721282959,2,1,1,252.39794921875,0,252.311820983887,,,,,,,,,,,,,,,,,,,,,,,,,,,,,,,,,
,3834058074.99991,254.95613861084,9999.6064453125,0.00071914308068045,7.75945685300294E-8,1,2,13.4005146026611,4.99586634419718,34.0199992060661,0.957124283152889,0.142040883850307,1,6.04628527621541E-6,,,,,,,,,,,,,,,,,,,,,254.87678527832,255.035491943359,9999.6064453125,9999.6064453125,47.5429454964762,5.27646590330281,12.8232107162476,27,1,0,0,1,0.292282104492188,41.055721282959,2,1,1,255.035491943359,0,254.95613861084,,,,,,,,,,,,,,,,,,,,,,,,,,,,,,,,,
,3834058109.39145,257.844879150391,9999.6064453125,0.000711163352982486,6.84617752505444E-8,1,2,13.4005146026611,4.99583319522825,34.0400002896786,0.94645851669708,0.140726398005349,1,6.17649580483262E-6,,,,,,,,,,,,,,,,,,,,,257.787322998047,257.902435302734,9999.6064453125,9999.6064453125,47.618372648582,5.27722561234235,12.8623094558716,27,1,0,0,1,0.291595458984375,41.5444793701172,2,1,1,257.902435302734,0,257.844879150391,,,,,,,,,,,,,,,,,,,,,,,,,,,,,,,,,
,3834058141.50564,260.554809570313,9999.6064453125,0.000703738285508491,1.14268175375072E-7,1,2,13.4005146026611,4.99577226614954,34.060001373291,0.936550838300052,0.139328533705347,1,6.16735671176815E-6,,,,,,,,,,,,,,,,,,,,,260.463531494141,260.646087646484,9999.6064453125,9999.6064453125,47.56952086613,5.27667641984439,12.8959646224976,27,1,0,0,1,0.289764404296875,41.055721282959,2,1,1,260.646087646484,0,260.554809570313,,,,,,,,,,,,,,,,,,,,,,,,,,,,,,,,,
,3834058173.84652,263.227325439453,9999.6064453125,0.000696597696018429,8.99273256135229E-8,1,2,13.4005146026611,4.99585789831707,34.0700000524521,0.927078609416325,0.137854654528291,1,6.05719956530095E-6,,,,,,,,,,,,,,,,,,,,,263.163299560547,263.291351318359,9999.6064453125,9999.6064453125,47.567566794832,5.27678480108594,12.9553003311157,27,1,0,0,1,0.291290283203125,41.055721282959,2,1,1,263.291351318359,0,263.227325439453,,,,,,,,,,,,,,,,,,,,,,,,,,,,,,,,,
,3834058203.96215,265.742233276367,9999.6064453125,0.00069016122819684,8.40513801282898E-8,1,2,13.4005146026611,4.99583061236411,34.0799987316132,0.918531122716211,0.136397753529099,1,5.86455326471677E-6,,,,,,,,,,,,,,,,,,,,,265.666412353516,265.818054199219,9999.6064453125,9999.6064453125,47.5406006109185,5.27648864642788,13.0004959106445,27,1,0,0,1,0.291213989257812,41.5444793701172,2,1,1,265.818054199219,0,265.742233276367,,,,,,,,,,,,,,,,,,,,,,,,,,,,,,,,,
,3834058238.35028,268.570449829102,9999.6064453125,0.000682709663690052,6.21080181561626E-8,1,2,13.4005146026611,4.99584593133,34.0999998152256,0.908595283415673,0.135085975011067,1,5.92155165052189E-6,,,,,,,,,,,,,,,,,,,,,268.492767333984,268.648132324219,9999.6064453125,9999.6064453125,47.4897947571685,5.27684484512921,12.9664669036865,27,1,0,0,1,0.292282104492188,41.055721282959,2,1,1,268.648132324219,0,268.570449829102,,,,,,,,,,,,,,,,,,,,,,,,,,,,,,,,,
,3834058268.44065,271.014938354492,9999.6064453125,0.000676475927553454,7.26539832434898E-8,1,2,13.4005146026611,4.99582904561057,34.1099984943867,0.900299585051976,0.133818010448778,1,5.84204746937773E-6,,,,,,,,,,,,,,,,,,,,,270.926849365234,271.10302734375,9999.6064453125,9999.6064453125,47.5519342244473,5.27694820035267,12.9514818191528,27,1,0,0,1,0.291748046875,41.5444793701172,2,1,1,271.10302734375,0,271.014938354492,,,,,,,,,,,,,,,,,,,,,,,,,,,,,,,,,
,3834058302.78981,273.913223266602,9999.6064453125,0.000669425838962435,1.16529241360391E-7,1,2,13.4005146026611,4.99583149517486,34.1299995779991,0.890963188961195,0.132096368121122,1,5.53567396529628E-6,,,,,,,,,,,,,,,,,,,,,273.843444824219,273.983001708984,9999.6064453125,9999.6064453125,47.4327358752646,5.27707398081537,12.9356117248535,27,1,0,0,1,0.292434692382812,41.055721282959,2,1,1,273.983001708984,0,273.913223266602,,,,,,,,,,,,,,,,,,,,,,,,,,,,,,,,,
,3834058332.92075,276.407501220703,9999.6064453125,0.000663347222591706,7.28664282344015E-8,1,2,13.4005146026611,4.9958176951584,34.1500006616116,0.882850844665415,0.131030509454744,1,5.58606086991743E-6,,,,,,,,,,,,,,,,,,,,,276.336212158203,276.478790283203,9999.6064453125,9999.6064453125,47.6160277630243,5.27684695101194,12.9192628860474,27,1,0,0,1,0.282821655273438,41.055721282959,2,1,1,276.478790283203,0,276.407501220703,,,,,,,,,,,,,,,,,,,,,,,,,,,,,,,,,
,3834058367.24995,279.243743896484,9999.6064453125,0.000656556524690211,5.84513413154735E-8,1,2,13.4005146026611,4.9958128483243,34.1599993407726,0.873776650437421,0.129941243073998,1,5.71819961357588E-6,,,,,,,,,,,,,,,,,,,,,279.165313720703,279.322174072266,9999.6064453125,9999.6064453125,47.6011768211589,5.27683972800899,12.9448909759521,27,1,0,0,1,0.291824340820313,41.055721282959,2,1,1,279.322174072266,0,279.243743896484,,,,,,,,,,,,,,,,,,,,,,,,,,,,,,,,,
,3834058399.6931,281.898391723633,9999.6064453125,0.000650300292529421,9.08218460151698E-8,1,2,13.4005146026611,4.99589596805429,34.1800004243851,0.865499047318662,0.128500250886697,1,5.50931493265327E-6,,,,,,,,,,,,,,,,,,,,,281.84375,281.953033447266,9999.6064453125,9999.6064453125,47.5050365132935,5.27586302524896,12.948317527771,25,1,64,0,0,0.29205322265625,41.055721282959,2,1,1,281.953033447266,0,281.898391723633,,,,,,,,,,,,,,,,,,,,,,,,,,,,,,,,,
,3834058431.71954,284.604248046875,9999.6064453125,0.000644174562280463,6.75864311148068E-8,1,2,13.4005146026611,4.99582907238547,34.1899991035461,0.857320665835342,0.127357466714502,1,5.50995419738468E-6,,,,,,,,,,,,,,,,,,,,,284.539001464844,284.669494628906,9999.6064453125,9999.6064453125,47.6531551176877,5.2770109866241,12.930004119873,27,1,0,0,1,0.2911376953125,41.5444793701172,2,1,1,284.669494628906,0,284.604248046875,,,,,,,,,,,,,,,,,,,,,,,,,,,,,,,,,
,3834058463.86663,287.200393676758,9999.6064453125,0.000638257318062867,6.11496418821586E-8,1,2,13.4005146026611,4.99582081349582,34.2100001871586,0.849436521334918,0.126237826677483,1,5.49725772812927E-6,,,,,,,,,,,,,,,,,,,,,287.117523193359,287.283264160156,9999.6064453125,9999.6064453125,47.5413822394377,5.27705577636278,12.9390392303467,27,1,0,0,1,0.290985107421875,41.055721282959,2,1,1,287.283264160156,0,287.200393676758,,,,,,,,,,,,,,,,,,,,,,,,,,,,,,,,,
,3834058498.43396,290.002380371094,9999.6064453125,0.000632803848337005,8.42977417878228E-8,1,2,13.4005146026611,4.99580249090346,34.230001270771,0.842211123867522,0.124896220904908,1,5.25338817388011E-6,,,,,,,,,,,,,,,,,,,,,289.948974609375,290.055786132812,9999.6064453125,9999.6064453125,47.56952086613,5.27704017376555,12.9387636184692,27,1,0,0,1,0.291748046875,41.055721282959,2,1,1,290.055786132812,0,290.002380371094,,,,,,,,,,,,,,,,,,,,,,,,,,,,,,,,,
,3834058528.33214,292.484420776367,9999.6064453125,0.00062730804369743,6.16581907866557E-8,1,2,13.4005146026611,4.99581676526888,34.2399999499321,0.834862651628886,0.124078517572339,1,5.40778009725361E-6,,,,,,,,,,,,,,,,,,,,,292.418792724609,292.550048828125,9999.6064453125,9999.6064453125,47.5890615791108,5.27655308420159,12.9673595428467,27,1,0,0,1,0.27557373046875,41.5444793701172,2,1,1,292.550048828125,0,292.484420776367,,,,,,,,,,,,,,,,,,,,,,,,,,,,,,,,,
,3834058560.63352,295.272811889648,9999.6064453125,0.000621435301494897,5.83669304050781E-8,1,2,13.4005146026611,4.99577933269961,34.2600010335445,0.827089487391546,0.122549807117604,1,5.08258658892817E-6,,,,,,,,,,,,,,,,,,,,,295.196868896484,295.348754882812,9999.6064453125,9999.6064453125,47.5331751399858,5.27725658353298,12.9843101501465,27,1,0,0,1,0.291824340820313,41.5444793701172,2,1,1,295.348754882812,0,295.272811889648,,,,,,,,,,,,,,,,,,,,,,,,,,,,,,,,,
,3834058592.80954,297.963577270508,9999.6064453125,0.000615473914067036,1.04538428964277E-7,1,2,13.4005146026611,4.99581269062496,34.2699997127056,0.819118973896069,0.121688495658771,1,5.26887481547067E-6,,,,,,,,,,,,,,,,,,,,,297.880889892578,298.046264648438,9999.6064453125,9999.6064453125,47.5445087535146,5.27777147736439,13.0158309936523,27,1,0,0,1,0.291290283203125,41.055721282959,2,1,1,298.046264648438,0,297.963577270508,,,,,,,,,,,,,,,,,,,,,,,,,,,,,,,,,
,3834058627.34731,299.596054077148,9999.6064453125,0.000613337825834769,5.80831741723322E-8,1,2,13.4005146026611,4.99587854000449,34.2799983918667,0.81628452387454,0.121313546545091,1,5.28450870638015E-6,,,,,,,,,,,,,,,,,,,,,299.583129882812,299.608978271484,9999.6064453125,9999.6064453125,47.65081023213,5.2773262035992,13.0390357971191,27,1,0,0,1,0.290069580078125,41.055721282959,6,1,1,299.608978271484,0,299.596054077148,,,,,,,,,,,,,,,,,,,,,,,,,,,,,,,,,
,3834058659.31382,299.859588623047,9999.6064453125,0.000613055538173052,8.36565358600769E-8,1,2,13.4005146026611,4.995928059457,34.2799983918667,0.815923140954894,0.12123623056567,1,5.26471995671286E-6,,,,,,,,,,,,,,,,,,,,,299.855407714844,299.86376953125,9999.6064453125,9999.6064453125,47.5359108398031,5.2774100138908,13.066309928894,27,1,0,0,1,0.291671752929687,41.055721282959,5,1,1,299.86376953125,0,299.859588623047,,,,,,,,,,,,,,,,,,,,,,,,,,,,,,,,,
,3834058685.50928,299.931823730469,9999.6064453125,0.000612969230789671,4.11708856078456E-8,1,2,13.4005146026611,4.99594284609614,34.2799983918667,0.815818406836486,0.12117083238151,1,5.22734011746877E-6,,,,,,,,,,,,,,,,,,,,,299.930267333984,299.933380126953,9999.6064453125,9999.6064453125,47.5851534365146,5.27752169257408,13.0723962783813,27,1,0,0,1,0.283050537109375,41.055721282959,1,1,1,299.933380126953,0,299.931823730469,,,,,,,,,,,,,,,,,,,,,,,,,,,,,,,,,