File: SI Fig S11-13 SQUID all/Michaela_Er_FC1T.dat
[Header]
; MPMS3 Data File (default extension .dat)
; Copyright (c) 2007, Quantum Design, Inc. All rights reserved.
TITLE,
FILEOPENTIME,3832834717.17197,06/14/2021,12:18 pm
BYAPP,MPMS3 w/ AC,1.0,1.1
INFO,MPMS3 Measurement Release 1.1.16 Build 424, MultiVu Release 2.3.4.19,APPNAME
INFO,Linear Motor Servo Controller,MOTOR_MODULE_NAME
INFO,3101-100 E1,MOTOR_HW_VERSION
INFO,MMC211,MOTOR_SERIAL_NUMBER
INFO,01.04.28,MOTOR_SOFTWARE_VERSION
INFO,Quantum Design Squid Module,SQUID_MODULE_NAME
INFO,3101-501 B0,SQUID_HW_VERSION
INFO,SQM059,SQUID_SERIAL_NUMBER
INFO,01.03.04,SQUID_SOFTWARE_VERSION
INFO,SQUID AC,AC_MODULE_NAME
INFO,3101-401 F1,AC_HW_VERSION
INFO,SAC057,AC_SERIAL_NUMBER
INFO,SQUID AC 00.95.07,AC_SOFTWARE_VERSION
INFO,TCIXXX,COIL_SERIAL_NUMBER
INFO,0,MOMENT_UNITS
INFO,Michaela_Er,SAMPLE_MATERIAL
INFO,Michaela_Er,SAMPLE_COMMENT
INFO,1.11,SAMPLE_MASS
INFO,,SAMPLE_VOLUME
INFO,,SAMPLE_MOLECULAR_WEIGHT
INFO,,SAMPLE_SIZE
INFO,,SAMPLE_SHAPE
INFO,Straw,SAMPLE_HOLDER
INFO,Standard,SAMPLE_HOLDER_DETAIL
INFO,53.51,SAMPLE_OFFSET
DATATYPE,COMMENT,1
DATATYPE,TIME,2
STARTUPAXIS,X,2
STARTUPAXIS,Y1,5
FIELDGROUP, VSM,2,3,4,5,6,8,9,10,11,14,15
FIELDGROUP, DC, 2,3,4,14,56,57,58,59,60,61,62,63,64,65,66,67,68,69
FIELDGROUP, AC, 2,3,4,11,16,17,18,19,20,21,22,23,24,25,26,27,28,29,30
STARTUPGROUP, All
[Data]
Comment,Time Stamp (sec),Temperature (K),Magnetic Field (Oe),Moment (emu),M. Std. Err. (emu),Transport Action,Averaging Time (sec),Frequency (Hz),Peak Amplitude (mm),Center Position (mm),Lockin Signal' (V),Lockin Signal (V),Range,M. Quad. Signal (emu),AC Moment (emu),AC M. Std Err. (emu),AC Phase (deg),AC Phase Std. Err. (deg),AC Susceptibility (emu/Oe),AC Suscept. Std Err. (emu/Oe),AC X' (emu/Oe),AC X' Std Err. (emu/Oe),AC X'' (emu/Oe),AC X'' Std Err. (emu/Oe),AC Drive (Oe),AC Frequency (Hz),AC Averaging Time (sec),AC Cycles,AC Range,AC Measure Type,AC Signal' (V),AC Signal'' (V),AC Trim Coil Ratio,AC Trim Coil Phase,Min. Temperature (K),Max. Temperature (K),Min. Field (Oe),Max. Field (Oe),Mass (grams),Motor Lag (deg),Pressure (Torr),Measure Count,Measurement Number,SQUID Status (code),Motor Status (code),Measure Status (code),Motor Current (amps),Motor Temp. (C),Temp. Status (code),Field Status (code),Chamber Status (code),Chamber Temp (K),Redirection State,Average Temp (K),Rotation Angle (deg),Rotator state,DC Moment Fixed Ctr (emu),DC Moment Err Fixed Ctr (emu),DC Moment Free Ctr (emu),DC Moment Err Free Ctr (emu),DC Fixed Fit,DC Free Fit,DC Calculated Center (mm),DC Calculated Center Err (mm),DC Scan Length (mm),DC Scan Time (s),DC Number of Points,DC Squid Drift,DC Min V (V),DC Max V (V),DC Scans per Measure,Map 01,Map 02,Map 03,Map 04,Map 05,Map 06,Map 07,Map 08,Map 09,Map 10,Map 11,Map 12,Map 13,Map 14,Map 15,Map 16
,3832834723.33959,299.916656494141,9999.6435546875,0.000399378872110081,5.13198826020174E-8,1,2,13.4005146026611,4.98163493978189,33.7099991738796,0.529483514448596,0.0784598276079715,1,3.27107160833317E-6,,,,,,,,,,,,,,,,,,,,,299.916656494141,299.916656494141,9999.6435546875,9999.6435546875,47.496438599582,5.28612124315502,14.6178150177002,27,1,0,0,1,0.275421142578125,40.5669593811035,1,1,1,299.916656494141,0,299.916656494141,,,,,,,,,,,,,,,,,,,,,,,,,,,,,,,,,
,3832834775.30836,298.28840637207,9999.6435546875,0.00040272486496133,5.57533287473068E-8,1,2,13.4005146026611,4.9811828024556,33.7099991738796,0.533846861209029,0.0791511634606698,1,3.33152445199493E-6,,,,,,,,,,,,,,,,,,,,,298.2080078125,298.368804931641,9999.6435546875,9999.6435546875,47.4808060291973,5.28801597516227,14.7185153961182,27,1,0,0,1,0.278854370117187,40.5669593811035,2,1,1,298.2080078125,0,298.28840637207,,,,,,,,,,,,,,,,,,,,,,,,,,,,,,,,,
,3832834829.6625,295.415603637695,9999.6435546875,0.000407300552135067,3.92332333452291E-8,1,2,13.4005146026611,4.98126487055606,33.6900018155575,0.539923978327888,0.0800563348626833,1,3.37243535811686E-6,,,,,,,,,,,,,,,,,,,,,295.331695556641,295.49951171875,9999.6435546875,9999.6435546875,47.4479776313896,5.28696709028041,14.8161306381226,27,1,0,0,1,0.276565551757813,40.5669593811035,2,1,1,295.331695556641,0,295.415603637695,,,,,,,,,,,,,,,,,,,,,,,,,,,,,,,,,
,3832834882.93994,292.696731567383,9999.6435546875,0.000411406783053798,2.92403438684134E-8,1,2,13.4005146026611,4.98114593646042,33.670000731945,0.545338911010775,0.0809356832552268,1,3.46287728259217E-6,,,,,,,,,,,,,,,,,,,,,292.661102294922,292.732360839844,9999.6435546875,9999.6435546875,47.4561847308416,5.28736221410225,14.7703132629395,27,1,0,0,1,0.275650024414062,40.5669593811035,2,1,1,292.661102294922,0,292.696731567383,,,,,,,,,,,,,,,,,,,,,,,,,,,,,,,,,
,3832834935.16647,290.116333007812,9999.6435546875,0.000415722612084553,4.92868995653968E-8,1,2,13.4005146026611,4.98111439894316,33.670000731945,0.551060059100181,0.0817475079417555,1,3.47169050008329E-6,,,,,,,,,,,,,,,,,,,,,290.075469970703,290.157196044922,9999.6435546875,9999.6435546875,47.5910156504089,5.28743021287099,14.6895503997803,27,1,0,0,1,0.278167724609375,40.5669593811035,2,1,1,290.075469970703,0,290.116333007812,,,,,,,,,,,,,,,,,,,,,,,,,,,,,,,,,
,3832834987.50752,287.481246948242,9999.6435546875,0.000419989352718517,4.25765972922004E-8,1,2,13.4005146026611,4.98103661705956,33.6499996483326,0.556705882532278,0.082570500347252,1,3.49658632618414E-6,,,,,,,,,,,,,,,,,,,,,287.429077148438,287.533416748047,9999.6435546875,9999.6435546875,47.5609229524185,5.28728579328372,14.6391286849976,27,1,0,0,1,0.27679443359375,40.0782012939453,2,1,1,287.429077148438,0,287.481246948242,,,,,,,,,,,,,,,,,,,,,,,,,,,,,,,,,
,3832835038.17275,284.968505859375,9999.6435546875,0.000424205657343553,4.99494280991465E-8,1,2,13.4005146026611,4.98106311050188,33.6400009691715,0.562305062059071,0.0833552619615646,1,3.49794635918539E-6,,,,,,,,,,,,,,,,,,,,,284.906188964844,285.030822753906,9999.6435546875,9999.6435546875,47.54919852463,5.28730510061674,14.5882616043091,27,1,0,0,1,0.2764892578125,40.5669593811035,2,1,1,284.906188964844,0,284.968505859375,,,,,,,,,,,,,,,,,,,,,,,,,,,,,,,,,
,3832835094.4389,282.150436401367,9999.6435546875,0.000428907981914961,3.16263543406948E-8,1,2,13.4005146026611,4.98107182487676,33.6199998855591,0.568525869961482,0.0843775534896777,1,3.61063901471678E-6,,,,,,,,,,,,,,,,,,,,,282.115997314453,282.184875488281,9999.6435546875,9999.6435546875,47.5046456990339,5.28737638379962,14.5227327346802,27,1,0,0,1,0.27740478515625,40.5669593811035,2,1,1,282.115997314453,0,282.150436401367,,,,,,,,,,,,,,,,,,,,,,,,,,,,,,,,,
,3832835144.6627,279.651809692383,9999.6435546875,0.000433357888765831,3.932059127011E-8,1,2,13.4005146026611,4.98116837298512,33.6199998855591,0.574450562693384,0.0851767963238006,1,3.58899336919112E-6,,,,,,,,,,,,,,,,,,,,,279.586547851562,279.717071533203,9999.6435546875,9999.6435546875,47.5194966408993,5.28729392033099,14.4792385101318,27,1,0,0,1,0.277252197265625,40.5669593811035,2,1,1,279.586547851562,0,279.651809692383,,,,,,,,,,,,,,,,,,,,,,,,,,,,,,,,,
,3832835197.31179,276.992904663086,9999.6435546875,0.000437817618032984,5.47056286323515E-8,1,2,13.4005146026611,4.98106561859633,33.5999988019466,0.580337829423981,0.0861083086050324,1,3.66917086877914E-6,,,,,,,,,,,,,,,,,,,,,276.964630126953,277.021179199219,9999.6435546875,9999.6435546875,47.4733805582646,5.28773586991644,14.4312953948975,27,1,0,0,1,0.2752685546875,40.5669593811035,2,1,1,276.964630126953,0,276.992904663086,,,,,,,,,,,,,,,,,,,,,,,,,,,,,,,,,
,3832835249.66065,274.360122680664,9999.6435546875,0.000442434451430751,4.31944408250867E-8,1,2,13.4005146026611,4.98094942546957,33.5800014436245,0.586454865617859,0.0868984312495877,1,3.62111927059551E-6,,,,,,,,,,,,,,,,,,,,,274.2939453125,274.426300048828,9999.6435546875,9999.6435546875,47.5917972789281,5.28835258131175,14.3996152877808,27,1,0,0,1,0.275497436523438,40.0782012939453,2,1,1,274.2939453125,0,274.360122680664,,,,,,,,,,,,,,,,,,,,,,,,,,,,,,,,,
,3832835303.9111,271.664672851562,9999.6435546875,0.00044735300686094,6.03279588892797E-8,1,2,13.4005146026611,4.98098070508112,33.5800014436245,0.592966277872502,0.0879606107555698,1,3.7332414365585E-6,,,,,,,,,,,,,,,,,,,,,271.613708496094,271.715637207031,9999.6435546875,9999.6435546875,47.5843718079954,5.28831204697858,14.3633899688721,27,1,0,0,1,0.277328491210938,40.5669593811035,2,1,1,271.613708496094,0,271.664672851562,,,,,,,,,,,,,,,,,,,,,,,,,,,,,,,,,
,3832835356.27646,269.053314208984,9999.6435546875,0.000452038892817717,7.33245298355971E-8,1,2,13.4005146026611,4.98101580239087,33.5600003600121,0.599181843824656,0.0888926388067466,1,3.77973650209736E-6,,,,,,,,,,,,,,,,,,,,,269.024993896484,269.081634521484,9999.6435546875,9999.6435546875,47.5101170986685,5.28731759045034,14.3565111160278,25,1,64,0,0,0.276718139648438,40.5669593811035,2,1,1,269.008697509766,0,269.053314208984,,,,,,,,,,,,,,,,,,,,,,,,,,,,,,,,,
,3832835412.64774,266.202041625977,9999.6435546875,0.000457267964137962,5.97308098573763E-8,1,2,13.4005146026611,4.98088887964459,33.550001680851,0.606093287632421,0.0899072970009813,1,3.81555961123567E-6,,,,,,,,,,,,,,,,,,,,,266.152954101562,266.251129150391,9999.6435546875,9999.6435546875,47.3909187494858,5.28904089299127,14.3316516876221,27,1,0,0,1,0.278549194335938,40.5669593811035,2,1,1,266.152954101562,0,266.202041625977,,,,,,,,,,,,,,,,,,,,,,,,,,,,,,,,,
,3832835463.15137,263.757049560547,9999.6435546875,0.000461969523330883,6.0428948408217E-8,1,2,13.4005146026611,4.98084295662529,33.5399992763996,0.61232059866268,0.0908069285307636,1,3.83698223800586E-6,,,,,,,,,,,,,,,,,,,,,263.721008300781,263.793090820313,9999.6435546875,9999.6435546875,47.3889646781877,5.28892798082799,14.3008413314819,27,1,0,0,1,0.276641845703125,40.5669593811035,2,1,1,263.721008300781,0,263.757049560547,,,,,,,,,,,,,,,,,,,,,,,,,,,,,,,,,
,3832835515.44816,261.134689331055,9999.6435546875,0.00046698006640045,5.61013299426284E-8,1,2,13.4005146026611,4.98099592894687,33.5199981927872,0.618987530348487,0.0917987508551802,1,3.88090068705875E-6,,,,,,,,,,,,,,,,,,,,,261.092956542969,261.176422119141,9999.6435546875,9999.6435546875,47.371378036505,5.28782348878128,14.2749605178833,27,1,0,0,1,0.27740478515625,40.5669593811035,2,1,1,261.092956542969,0,261.134689331055,,,,,,,,,,,,,,,,,,,,,,,,,,,,,,,,,
,3832835569.79467,258.402557373047,9999.6435546875,0.000472276033776451,4.36998126447899E-8,1,2,13.4005146026611,4.98102243996079,33.5199981927872,0.626007862240628,0.0928698988523063,1,3.94706051069038E-6,,,,,,,,,,,,,,,,,,,,,258.347198486328,258.457916259766,9999.6435546875,9999.6435546875,47.5335659542454,5.28754738620469,14.2423267364502,27,1,0,0,1,0.276260375976562,40.5669593811035,2,1,1,258.347198486328,0,258.402557373047,,,,,,,,,,,,,,,,,,,,,,,,,,,,,,,,,
,3832835624.17875,255.674446105957,9999.6435546875,0.000477622588447764,4.49534445176935E-8,1,2,13.4005146026611,4.98098228418625,33.500000834465,0.633100586132599,0.0938286377092088,1,3.92273008968338E-6,,,,,,,,,,,,,,,,,,,,,255.615493774414,255.7333984375,9999.6435546875,9999.6435546875,47.4081145769089,5.2875560513203,14.2274379730225,27,1,0,0,1,0.27679443359375,40.5669593811035,2,1,1,255.615493774414,0,255.674446105957,,,,,,,,,,,,,,,,,,,,,,,,,,,,,,,,,
,3832835674.69449,253.135612487793,9999.6435546875,0.000482668258497668,7.65626218564348E-8,1,2,13.4005146026611,4.98081610557529,33.500000834465,0.639758845509871,0.0948197613740786,1,3.9673720739947E-6,,,,,,,,,,,,,,,,,,,,,253.093368530273,253.177856445313,9999.6435546875,9999.6435546875,47.4241379615531,5.28880474199085,14.2120389938354,27,1,0,0,1,0.278396606445313,40.5669593811035,2,1,1,253.093368530273,0,253.135612487793,,,,,,,,,,,,,,,,,,,,,,,,,,,,,,,,,
,3832835724.95189,250.68505859375,9999.6435546875,0.000487837015612245,4.70359329570941E-8,1,2,13.4005146026611,4.98087914165192,33.4799997508526,0.646604451265089,0.0959557327697802,1,4.09946357637388E-6,,,,,,,,,,,,,,,,,,,,,250.625442504883,250.744674682617,9999.6435546875,9999.6435546875,47.3592627944569,5.28777120772163,14.2016687393188,27,1,0,0,1,0.2777099609375,40.0782012939453,2,1,1,250.625442504883,0,250.68505859375,,,,,,,,,,,,,,,,,,,,,,,,,,,,,,,,,
,3832835779.31361,247.954582214355,9999.6435546875,0.000493475994268998,4.807993312291E-8,1,2,13.4005146026611,4.98091990944847,33.4799997508526,0.654081884769455,0.0970953954124477,1,4.16900890371751E-6,,,,,,,,,,,,,,,,,,,,,247.897872924805,248.011291503906,9999.6435546875,9999.6435546875,47.3553546518608,5.28724339945644,14.1746444702148,27,1,0,0,1,0.277252197265625,40.5669593811035,2,1,1,247.897872924805,0,247.954582214355,,,,,,,,,,,,,,,,,,,,,,,,,,,,,,,,,
,3832835829.90334,245.405937194824,9999.6435546875,0.000498917125397641,4.70289079486866E-8,1,2,13.4005146026611,4.98091257222955,33.4599986672401,0.661302359694597,0.0980955535513481,1,4.16205405936911E-6,,,,,,,,,,,,,,,,,,,,,245.338287353516,245.473587036133,9999.6435546875,9999.6435546875,47.4225747045146,5.28805752143442,14.1594820022583,27,1,0,0,1,0.276336669921875,40.5669593811035,2,1,1,245.338287353516,0,245.405937194824,,,,,,,,,,,,,,,,,,,,,,,,,,,,,,,,,
,3832835882.07728,242.796188354492,9999.6435546875,0.000504454510990749,3.53542027915508E-8,1,2,13.4005146026611,4.98103111621749,33.4599986672401,0.668643397865796,0.0993340080263971,1,4.31861886160693E-6,,,,,,,,,,,,,,,,,,,,,242.742630004883,242.849746704102,9999.6435546875,9999.6435546875,47.3971717776396,5.28713775813889,14.1400785446167,27,1,0,0,1,0.272369384765625,40.0782012939453,2,1,1,242.742630004883,0,242.796188354492,,,,,,,,,,,,,,,,,,,,,,,,,,,,,,,,,
,3832835932.60401,240.257598876953,9999.6435546875,0.000510012884823583,4.46333970700574E-8,1,2,13.4005146026611,4.98083421582892,33.4499999880791,0.675996620118487,0.100262798585373,1,4.24542073980102E-6,,,,,,,,,,,,,,,,,,,,,240.222473144531,240.292724609375,9999.6435546875,9999.6435546875,47.3694239652069,5.28778219901513,14.1358757019043,27,1,0,0,1,0.277252197265625,40.5669593811035,2,1,1,240.222473144531,0,240.257598876953,,,,,,,,,,,,,,,,,,,,,,,,,,,,,,,,,
,3832835984.89473,237.663940429687,9999.6435546875,0.000515866759564044,5.46182268919512E-8,1,2,13.4005146026611,4.98117234080529,33.440001308918,0.683815837538935,0.101448326590122,1,4.31319006827933E-6,,,,,,,,,,,,,,,,,,,,,237.604888916016,237.722991943359,9999.6435546875,9999.6435546875,47.5163701268223,5.28647757589019,14.12744140625,27,1,0,0,1,0.276336669921875,40.5669593811035,2,1,1,237.604888916016,0,237.663940429687,,,,,,,,,,,,,,,,,,,,,,,,,,,,,,,,,
,3832836037.20698,235.056427001953,9999.6435546875,0.000521876721166987,3.74435291841561E-8,1,2,13.4005146026611,4.9812253354366,33.4200002253056,0.691797026871287,0.102599687410474,1,4.33930224931824E-6,,,,,,,,,,,,,,,,,,,,,235.003402709961,235.109451293945,9999.6435546875,9999.6435546875,47.4147584193223,5.28639810809564,14.096866607666,27,1,0,0,1,0.275650024414062,40.5669593811035,2,1,1,235.003402709961,0,235.056427001953,,,,,,,,,,,,,,,,,,,,,,,,,,,,,,,,,
,3832836087.84168,232.558639526367,9999.6435546875,0.000527678059144282,6.71705991065145E-8,1,2,13.4005146026611,4.98124949620038,33.4200002253056,0.699484698279326,0.103792470913116,1,4.42639236390437E-6,,,,,,,,,,,,,,,,,,,,,232.508651733398,232.608627319336,9999.6435546875,9999.6435546875,47.4956569710627,5.28559161480248,14.0808067321777,27,1,0,0,1,0.276260375976562,40.5669593811035,2,1,1,232.508651733398,0,232.558639526367,,,,,,,,,,,,,,,,,,,,,,,,,,,,,,,,,
,3832836140.00173,229.925071716309,9999.6435546875,0.000534015681203152,4.19833527915813E-8,1,2,13.4005146026611,4.98143621994017,33.3999991416931,0.707915906013903,0.105089605582011,1,4.51356630539585E-6,,,,,,,,,,,,,,,,,,,,,229.885513305664,229.964630126953,9999.6435546875,9999.6435546875,47.2674214434473,5.28540841727007,14.0788745880127,27,1,0,0,1,0.277786254882813,40.5669593811035,2,1,1,229.885513305664,0,229.925071716309,,,,,,,,,,,,,,,,,,,,,,,,,,,,,,,,,
,3832836190.48427,227.415832519531,9999.6435546875,0.000539982136220611,7.1560134057593E-8,1,2,13.4005146026611,4.98159055710274,33.3999991416931,0.715856637340737,0.106262020918357,1,4.55928603786639E-6,,,,,,,,,,,,,,,,,,,,,227.387054443359,227.444610595703,9999.6435546875,9999.6435546875,47.4100686482069,5.28477087833017,14.0460195541382,27,1,0,0,1,0.2752685546875,40.5669593811035,2,1,1,227.387054443359,0,227.415832519531,,,,,,,,,,,,,,,,,,,,,,,,,,,,,,,,,
,3832836240.71631,224.910400390625,9999.6435546875,0.000546248445815087,3.94346462867933E-8,1,2,13.4005146026611,4.98160784747398,33.380001783371,0.724160144967539,0.107547280793093,1,4.65108131997321E-6,,,,,,,,,,,,,,,,,,,,,224.861663818359,224.959136962891,9999.6435546875,9999.6435546875,47.3283884679473,5.28382443052942,14.0486354827881,27,1,0,0,1,0.277786254882813,40.5669593811035,2,1,1,224.861663818359,0,224.910400390625,,,,,,,,,,,,,,,,,,,,,,,,,,,,,,,,,
,3832836293.3818,222.277725219727,9999.6435546875,0.000552853380184516,6.6352538809693E-8,1,2,13.4005146026611,4.98169078623336,33.3699993789196,0.732941381639722,0.108790522845118,1,4.66238041606668E-6,,,,,,,,,,,,,,,,,,,,,222.25032043457,222.305130004883,9999.6435546875,9999.6435546875,47.3131467118223,5.28312142180562,14.0359306335449,27,1,0,0,1,0.276336669921875,40.5669593811035,2,1,1,222.25032043457,0,222.277725219727,,,,,,,,,,,,,,,,,,,,,,,,,,,,,,,,,
,3832836345.74077,219.651504516602,9999.6435546875,0.000559647187746445,4.30823291174076E-8,1,2,13.4005146026611,4.98155932361632,33.3600006997585,0.74191629533095,0.110159520497608,1,4.74687472803407E-6,,,,,,,,,,,,,,,,,,,,,219.597366333008,219.705642700195,9999.6435546875,9999.6435546875,47.4358623893416,5.28350702371704,14.0170421600342,27,1,0,0,1,0.275039672851562,40.5669593811035,2,1,1,219.597366333008,0,219.651504516602,,,,,,,,,,,,,,,,,,,,,,,,,,,,,,,,,
,3832836397.89689,217.028442382813,9999.6435546875,0.000566680731481263,5.42615722115166E-8,1,2,13.4005146026611,4.98142940939348,33.3399996161461,0.751213521456496,0.111541030096193,1,4.80731508602191E-6,,,,,,,,,,,,,,,,,,,,,216.976943969727,217.079940795898,9999.6435546875,9999.6435546875,47.4522765882454,5.28456158958011,13.9915170669556,27,1,0,0,1,0.275497436523438,40.0782012939453,2,1,1,216.976943969727,0,217.028442382813,,,,,,,,,,,,,,,,,,,,,,,,,,,,,,,,,
,3832836450.57134,214.425888061523,9999.6435546875,0.000573546276970811,5.06142508949384E-8,1,2,13.4005146026611,4.9816615811736,33.3399996161461,0.760358342616906,0.11293578655222,1,4.89280995625779E-6,,,,,,,,,,,,,,,,,,,,,214.401626586914,214.450149536133,9999.6435546875,9999.6435546875,47.3862289783704,5.28318174171969,13.9859781265259,27,1,0,0,1,0.274734497070313,40.5669593811035,2,1,1,214.401626586914,0,214.425888061523,,,,,,,,,,,,,,,,,,,,,,,,,,,,,,,,,
,3832836502.93796,211.805519104004,9999.6435546875,0.000581024838083304,9.27187793640228E-8,1,2,13.4005146026611,4.98168921620989,33.3199985325336,0.770236445149798,0.114711037180345,1,5.18397942081589E-6,,,,,,,,,,,,,,,,,,,,,211.741577148438,211.86946105957,9999.6435546875,9999.6435546875,47.4002982917166,5.28322395009402,13.9860000610352,27,1,0,0,1,0.275955200195313,40.5669593811035,2,1,1,211.741577148438,0,211.805519104004,,,,,,,,,,,,,,,,,,,,,,,,,,,,,,,,,
,3832836553.00079,209.346481323242,9999.6435546875,0.000588099841235354,4.67029264245084E-8,1,2,13.4005146026611,4.98172818157925,33.3199985325336,0.779655072400688,0.115885471760929,1,5.07862770442604E-6,,,,,,,,,,,,,,,,,,,,,209.289245605469,209.403717041016,9999.6435546875,9999.6435546875,47.5652219092743,5.28276943989117,13.9735841751099,27,1,0,0,1,0.274658203125,40.5669593811035,2,1,1,209.289245605469,0,209.346481323242,,,,,,,,,,,,,,,,,,,,,,,,,,,,,,,,,
,3832836605.61703,206.67259979248,9999.6435546875,0.000595832741774548,7.25388356413939E-8,1,2,13.4005146026611,4.98163864714691,33.3000011742115,0.789888826550532,0.117394964013402,1,5.13682940833882E-6,,,,,,,,,,,,,,,,,,,,,206.643829345703,206.701370239258,9999.6435546875,9999.6435546875,47.4428970460146,5.28360509650393,13.9415578842163,27,1,0,0,1,0.275344848632813,40.5669593811035,2,1,1,206.643829345703,0,206.67259979248,,,,,,,,,,,,,,,,,,,,,,,,,,,,,,,,,
,3832836657.88473,204.043395996094,9999.6435546875,0.000603383586806649,6.57205208964833E-8,1,2,13.4005146026611,4.98164977415818,33.3000011742115,0.799916560695555,0.118774264083555,1,5.11996894765896E-6,,,,,,,,,,,,,,,,,,,,,203.99267578125,204.094116210938,9999.6435546875,9999.6435546875,47.3846657213319,5.2830831127891,13.928295135498,27,1,0,0,1,0.275344848632813,40.5669593811035,2,1,1,203.99267578125,0,204.043395996094,,,,,,,,,,,,,,,,,,,,,,,,,,,,,,,,,
,3832836708.1318,201.544891357422,9999.6435546875,0.000611218545285836,5.34883468419921E-8,1,2,13.4005146026611,4.98173280823203,33.2800000905991,0.810320348978574,0.120331466002713,1,5.19561357937333E-6,,,,,,,,,,,,,,,,,,,,,201.490524291992,201.599258422852,9999.6435546875,9999.6435546875,47.3565270946396,5.28322577981052,13.9132680892944,27,1,0,0,1,0.2764892578125,40.5669593811035,2,1,1,201.490524291992,0,201.544891357422,,,,,,,,,,,,,,,,,,,,,,,,,,,,,,,,,
,3832836760.84686,198.858299255371,9999.6435546875,0.000619221611842515,4.53918497603269E-8,1,2,13.4005146026611,4.98153741390531,33.2800000905991,0.820881119462821,0.121936638238483,1,5.29088831615525E-6,,,,,,,,,,,,,,,,,,,,,198.799407958984,198.917190551758,9999.6435546875,9999.6435546875,47.45774798788,5.28471278545889,13.8870849609375,27,1,0,0,1,0.27557373046875,40.5669593811035,2,1,1,198.799407958984,0,198.858299255371,,,,,,,,,,,,,,,,,,,,,,,,,,,,,,,,,
,3832836812.93096,196.314315795898,9999.6435546875,0.000627489321266973,7.17581622967927E-8,1,2,13.4005146026611,4.98164901057255,33.270001411438,0.831865386206045,0.12357951864598,1,5.36982556320434E-6,,,,,,,,,,,,,,,,,,,,,196.25634765625,196.372283935547,9999.6435546875,9999.6435546875,47.4116319052454,5.28423881692492,13.8767862319946,27,1,0,0,1,0.275421142578125,40.5669593811035,2,1,1,196.25634765625,0,196.314315795898,,,,,,,,,,,,,,,,,,,,,,,,,,,,,,,,,
,3832836863.47517,193.807487487793,9999.6435546875,0.000635961584722609,7.87282549850468E-8,1,2,13.4005146026611,4.98161414122054,33.2500003278255,0.843078011007018,0.12532547263937,1,5.50155155354602E-6,,,,,,,,,,,,,,,,,,,,,193.771209716797,193.843765258789,9999.6435546875,9999.6435546875,47.2361563026781,5.28478571884903,13.8635301589966,27,1,0,0,1,0.277175903320313,40.5669593811035,2,1,1,193.771209716797,0,193.807487487793,,,,,,,,,,,,,,,,,,,,,,,,,,,,,,,,,
,3832836915.72777,191.190185546875,9999.6435546875,0.000644378851607329,6.65040072427768E-8,1,2,13.4005146026611,4.98150574717285,33.2500003278255,0.854214817630868,0.126953467054194,1,5.55405672091292E-6,,,,,,,,,,,,,,,,,,,,,191.141265869141,191.239105224609,9999.6435546875,9999.6435546875,47.4514949597262,5.28482427361365,13.8466129302979,27,1,0,0,1,0.2752685546875,40.0782012939453,2,1,1,191.141265869141,0,191.190185546875,,,,,,,,,,,,,,,,,,,,,,,,,,,,,,,,,
,3832836968.06193,188.570991516113,9999.6435546875,0.000653672012615714,7.79822369695564E-8,1,2,13.4005146026611,4.98160213088909,33.2299992442131,0.866547825172017,0.128855044294328,1,5.68482243100393E-6,,,,,,,,,,,,,,,,,,,,,188.514312744141,188.627670288086,9999.6435546875,9999.6435546875,47.4511041454666,5.28329213029086,13.8391752243042,27,1,0,0,1,0.274734497070313,40.0782012939453,2,1,1,188.514312744141,0,188.570991516113,,,,,,,,,,,,,,,,,,,,,,,,,,,,,,,,,
,3832837018.68298,186.030349731445,9999.6435546875,0.000662202841851971,5.57370314256901E-8,1,2,13.4005146026611,4.9814986827437,33.2299992442131,0.877812653614215,0.130669824140962,1,5.86213110149786E-6,,,,,,,,,,,,,,,,,,,,,185.975952148438,186.084747314453,9999.6435546875,9999.6435546875,47.3971717776396,5.28489857231342,13.8096504211426,27,1,0,0,1,0.276260375976562,40.0782012939453,2,1,1,185.975952148438,0,186.030349731445,,,,,,,,,,,,,,,,,,,,,,,,,,,,,,,,,
,3832837070.80826,183.430419921875,9999.6435546875,0.000671816938341886,8.47387119375011E-8,1,2,13.4005146026611,4.98164601691227,33.2099981606007,0.8905905651279,0.132591242742133,1,5.96149774566574E-6,,,,,,,,,,,,,,,,,,,,,183.372406005859,183.488433837891,9999.6435546875,9999.6435546875,47.4303909897069,5.28303272037691,13.7950401306152,27,1,0,0,1,0.274734497070313,40.5669593811035,2,1,1,183.372406005859,0,183.430419921875,,,,,,,,,,,,,,,,,,,,,,,,,,,,,,,,,
,3832837121.3717,180.923896789551,9999.6435546875,0.000680900450949565,6.33208675390556E-8,1,2,13.4005146026611,4.98164411236327,33.2099981606007,0.902629751100611,0.134397149537463,1,6.05207398452143E-6,,,,,,,,,,,,,,,,,,,,,180.888473510742,180.959320068359,9999.6435546875,9999.6435546875,47.4092870196877,5.28291495382849,13.7823038101196,27,1,0,0,1,0.274658203125,40.0782012939453,2,1,1,180.888473510742,0,180.923896789551,,,,,,,,,,,,,,,,,,,,,,,,,,,,,,,,,
,3832837173.65621,178.297966003418,9999.6435546875,0.000691180655316545,8.9938811092439E-8,1,2,13.4005146026611,4.98148997911884,33.1900008022785,0.916250877435742,0.136190304655712,1,5.97002567060768E-6,,,,,,,,,,,,,,,,,,,,,178.233322143555,178.362609863281,9999.6435546875,9999.6435546875,47.4405521604569,5.28417356500529,13.7697610855103,27,1,0,0,1,0.275497436523438,40.0782012939453,2,1,1,178.233322143555,0,178.297966003418,,,,,,,,,,,,,,,,,,,,,,,,,,,,,,,,,
,3832837226.01245,175.695777893066,9999.6435546875,0.000700975949474903,9.85049259052519E-8,1,2,13.4005146026611,4.98157205277262,33.1900008022785,0.929253447911022,0.138147806151814,1,6.07294889023948E-6,,,,,,,,,,,,,,,,,,,,,175.644973754883,175.74658203125,9999.6435546875,9999.6435546875,47.4362532036012,5.28383944125866,13.7632455825806,25,1,64,0,0,0.275802612304687,40.0782012939453,2,1,1,175.644973754883,0,175.695777893066,,,,,,,,,,,,,,,,,,,,,,,,,,,,,,,,,
,3832837276.57778,173.149490356445,9999.6435546875,0.000711283180627058,4.27179122050236E-8,1,2,13.4005146026611,4.98157988576406,33.1699997186661,0.942911257384701,0.140237207979796,1,6.20576267662105E-6,,,,,,,,,,,,,,,,,,,,,173.082885742187,173.216094970703,9999.6435546875,9999.6435546875,47.30533042663,5.28392026623221,13.7407369613647,27,1,0,0,1,0.277328491210938,40.5669593811035,2,1,1,173.082885742187,0,173.149490356445,,,,,,,,,,,,,,,,,,,,,,,,,,,,,,,,,
,3832837330.85735,170.422927856445,9999.6435546875,0.000722098170372533,5.90313438508706E-8,1,2,13.4005146026611,4.98133214026798,33.1699997186661,0.957191111621018,0.142300124136945,1,6.25517115692093E-6,,,,,,,,,,,,,,,,,,,,,170.377471923828,170.468383789062,9999.6435546875,9999.6435546875,47.4569663593608,5.2853880042266,13.7255249023437,27,1,0,0,1,0.275802612304687,40.5669593811035,2,1,1,170.377471923828,0,170.422927856445,,,,,,,,,,,,,,,,,,,,,,,,,,,,,,,,,
,3832837385.18385,167.731651306152,9999.6435546875,0.000733776646059807,8.11738558962292E-8,1,2,13.4005146026611,4.98140565035374,33.1499986350536,0.972658148532792,0.144842615832733,1,6.53577001937029E-6,,,,,,,,,,,,,,,,,,,,,167.689163208008,167.774139404297,9999.6435546875,9999.6435546875,47.4085053911685,5.28512045002768,13.7130861282349,27,1,0,0,1,0.2752685546875,40.5669593811035,2,1,1,167.689163208008,0,167.731651306152,,,,,,,,,,,,,,,,,,,,,,,,,,,,,,,,,
,3832837437.48142,165.141044616699,9999.6435546875,0.000744819453968358,7.0617579492359E-8,1,2,13.4005146026611,4.98137521046532,33.1499986350536,0.987304455365649,0.146901091732973,1,6.54366151328777E-6,,,,,,,,,,,,,,,,,,,,,165.086441040039,165.195648193359,9999.6435546875,9999.6435546875,47.4139767908031,5.28520585241893,13.692512512207,27,1,0,0,1,0.275115966796875,40.0782012939453,2,1,1,165.086441040039,0,165.141044616699,,,,,,,,,,,,,,,,,,,,,,,,,,,,,,,,,
,3832837491.16482,162.456771850586,9999.6435546875,0.000756963705634181,8.60533661545977E-8,1,2,13.4005146026611,4.98108401190772,33.1399999558926,1.00333467820396,0.149192816419827,1,6.58140050966822E-6,,,,,,,,,,,,,,,,,,,,,162.374435424805,162.539108276367,9999.6435546875,9999.6435546875,47.4573571736204,5.28704599254286,13.6874122619629,27,1,0,0,1,0.276031494140625,40.0782012939453,2,1,1,162.374435424805,0,162.456771850586,,,,,,,,,,,,,,,,,,,,,,,,,,,,,,,,,
,3832837544.42843,159.794052124023,9999.6435546875,0.000769019003194377,1.11033664016556E-7,1,2,13.4005146026611,4.98098298425044,33.1300012767315,1.01927078454357,0.151668145933332,1,6.76422755363101E-6,,,,,,,,,,,,,,,,,,,,,159.763122558594,159.824981689453,9999.6435546875,9999.6435546875,47.4718173012262,5.28704784002979,13.6562013626099,27,1,0,0,1,0.277023315429687,40.5669593811035,2,1,1,159.763122558594,0,159.794052124023,,,,,,,,,,,,,,,,,,,,,,,,,,,,,,,,,
,3832837594.65848,157.27515411377,9999.6435546875,0.000781438345843747,1.12287175957141E-7,1,2,13.4005146026611,4.98133494660527,33.110000193119,1.03584142308857,0.154065622884462,1,6.82309419280818E-6,,,,,,,,,,,,,,,,,,,,,157.224517822266,157.325790405273,9999.6435546875,9999.6435546875,47.4862774288319,5.28436740774309,13.6509456634521,27,1,0,0,1,0.277252197265625,40.5669593811035,2,1,1,157.224517822266,0,157.27515411377,,,,,,,,,,,,,,,,,,,,,,,,,,,,,,,,,
,3832837645.12231,154.761245727539,9999.6435546875,0.000793364666038238,8.80567335811194E-8,1,2,13.4005146026611,4.98158355527021,33.110000193119,1.0517040173125,0.15655991329442,1,7.02684762941802E-6,,,,,,,,,,,,,,,,,,,,,154.72248840332,154.800003051758,9999.6435546875,9999.6435546875,47.4124135337646,5.28384063130118,13.6362476348877,25,1,64,0,0,0.276641845703125,40.5669593811035,2,1,1,154.72248840332,0,154.761245727539,,,,,,,,,,,,,,,,,,,,,,,,,,,,,,,,,
,3832837697.40058,152.208335876465,9999.6435546875,0.000807002486258326,9.67678200114829E-8,1,2,13.4005146026611,4.98134576055078,33.0899991095066,1.0697255791793,0.159147492975095,1,7.07739499930351E-6,,,,,,,,,,,,,,,,,,,,,152.148284912109,152.26838684082,9999.6435546875,9999.6435546875,47.4413337889762,5.28475936617437,13.6161251068115,27,1,0,0,1,0.27435302734375,40.5669593811035,2,1,1,152.148284912109,0,152.208335876465,,,,,,,,,,,,,,,,,,,,,,,,,,,,,,,,,
,3832837749.04553,149.549850463867,9999.6435546875,0.000820123514099295,6.23162459503811E-8,1,2,13.4005146026611,4.98187440891518,33.0899991095066,1.08724809791794,0.161962527664684,1,7.34607441165378E-6,,,,,,,,,,,,,,,,,,,,,149.46076965332,149.638931274414,9999.6435546875,9999.6435546875,47.4030339915339,5.28320770921671,13.5963306427002,27,1,0,0,1,0.274734497070313,40.0782012939453,2,1,1,149.46076965332,0,149.549850463867,,,,,,,,,,,,,,,,,,,,,,,,,,,,,,,,,
,3832837800.31976,147.014701843262,9999.6435546875,0.000834132200084364,9.60010934671915E-8,1,2,13.4005146026611,4.98182844298983,33.0700017511845,1.105814520142,0.164663035287476,1,7.42339934283183E-6,,,,,,,,,,,,,,,,,,,,,146.951217651367,147.078186035156,9999.6435546875,9999.6435546875,47.4030339915339,5.28308930483463,13.5813522338867,27,1,0,0,1,0.27496337890625,40.5669593811035,2,1,1,146.951217651367,0,147.014701843262,,,,,,,,,,,,,,,,,,,,,,,,,,,,,,,,,
,3832837850.54132,144.516990661621,9999.6435546875,0.000847558565774001,7.70601109697691E-8,1,2,13.4005146026611,4.98179731149513,33.0700017511845,1.12354734372399,0.167719412386012,1,7.84978730499126E-6,,,,,,,,,,,,,,,,,,,,,144.46337890625,144.570602416992,9999.6435546875,9999.6435546875,47.5065997703319,5.28296957953191,13.5616846084595,27,1,0,0,1,0.275497436523438,40.5669593811035,2,1,1,144.46337890625,0,144.516990661621,,,,,,,,,,,,,,,,,,,,,,,,,,,,,,,,,
,3832837903.33309,141.83910369873,9999.6435546875,0.000862059608069666,6.82455823989537E-8,1,2,13.4005146026611,4.98177627365571,33.0700017511845,1.14276099810306,0.170607333296456,1,7.99868109871902E-6,,,,,,,,,,,,,,,,,,,,,141.790832519531,141.88737487793,9999.6435546875,9999.6435546875,47.4382072748993,5.28362876182711,13.5537118911743,27,1,0,0,1,0.274734497070313,40.0782012939453,2,1,1,141.790832519531,0,141.83910369873,,,,,,,,,,,,,,,,,,,,,,,,,,,,,,,,,
,3832837965.42596,138.761878967285,9999.6435546875,0.000881003912146061,1.00835834074977E-7,1,2,13.4005146026611,4.98178372282096,33.050000667572,1.16793369749418,0.173946317369125,1,7.8651339269587E-6,,,,,,,,,,,,,,,,,,,,,138.715057373047,138.808700561523,9999.6435546875,9999.6435546875,47.4725989297454,5.2831853997054,13.5428409576416,27,1,0,0,1,0.2752685546875,40.5669593811035,2,1,1,138.715057373047,0,138.761878967285,,,,,,,,,,,,,,,,,,,,,,,,,,,,,,,,,
,3832838027.8736,135.628288269043,9999.6435546875,0.000899549149452192,9.53818462333413E-8,1,2,13.4005146026611,4.98179618023211,33.050000667572,1.19246912644201,0.177993353055401,1,8.32062421274245E-6,,,,,,,,,,,,,,,,,,,,,135.573013305664,135.683563232422,9999.6435546875,9999.6435546875,47.3412853385146,5.28336491412333,13.5069351196289,27,1,0,0,1,0.275650024414062,40.0782012939453,2,1,1,135.573013305664,0,135.628288269043,,,,,,,,,,,,,,,,,,,,,,,,,,,,,,,,,
,3832838088.52261,132.610618591309,9999.6435546875,0.000919407017114522,1.20379011640588E-7,1,2,13.4005146026611,4.9817322452786,33.0299995839596,1.21882038389615,0.181572182932486,1,8.24270208584977E-6,,,,,,,,,,,,,,,,,,,,,132.580810546875,132.640426635742,9999.6435546875,9999.6435546875,47.5577964383416,5.28357266809743,13.5046920776367,27,1,0,0,1,0.276947021484375,40.0782012939453,2,1,1,132.580810546875,0,132.610618591309,,,,,,,,,,,,,,,,,,,,,,,,,,,,,,,,,
,3832838156.77993,129.191375732422,9999.6435546875,0.000942818807187003,7.72523865352087E-8,1,2,13.4005146026611,4.98176351990783,33.0099985003471,1.24984740089945,0.186339025385161,1,8.55933586982449E-6,,,,,,,,,,,,,,,,,,,,,129.139083862305,129.243667602539,9999.6435546875,9999.6435546875,47.4741621867839,5.28329328564342,13.4548778533936,27,1,0,0,1,0.27587890625,40.0782012939453,2,1,1,129.139083862305,0,129.191375732422,,,,,,,,,,,,,,,,,,,,,,,,,,,,,,,,,
,3832838207.28481,126.642616271973,9999.6435546875,0.000959866825131737,6.75374883883232E-8,1,2,13.4005146026611,4.98187729456972,33.0099985003471,1.27242907047762,0.190128621768331,1,9.02620425434011E-6,,,,,,,,,,,,,,,,,,,,,126.601173400879,126.684059143066,9999.6435546875,9999.6435546875,47.3076753121877,5.28255407603117,13.4404830932617,27,1,0,0,1,0.275497436523438,40.5669593811035,2,1,1,126.601173400879,0,126.642616271973,,,,,,,,,,,,,,,,,,,,,,,,,,,,,,,,,
,3832838275.64524,123.275802612305,9999.6435546875,0.000983837615543591,1.05676665488159E-7,1,2,13.4005146026611,4.9819451653813,33.0099985003471,1.30429895139686,0.194386371173135,1,8.87947181603061E-6,,,,,,,,,,,,,,,,,,,,,123.223770141602,123.327835083008,9999.6435546875,9999.6435546875,47.3549638376012,5.28241891506714,13.4108591079712,27,1,0,0,1,0.275115966796875,40.0782012939453,2,1,1,123.223770141602,0,123.275802612305,,,,,,,,,,,,,,,,,,,,,,,,,,,,,,,,,
,3832838338.11223,120.152671813965,9999.6435546875,0.0010081724234776,1.15378911590883E-7,1,2,13.4005146026611,4.98191391847431,32.990001142025,1.3364870373877,0.199633922770356,1,9.43148495751839E-6,,,,,,,,,,,,,,,,,,,,,120.097602844238,120.207740783691,9999.6435546875,9999.6435546875,47.4202298189569,5.28240395139883,13.3927440643311,27,1,0,0,1,0.274581909179687,40.0782012939453,2,1,1,120.097602844238,0,120.152671813965,,,,,,,,,,,,,,,,,,,,,,,,,,,,,,,,,
,3832838388.50986,117.638271331787,9999.6435546875,0.00102749326684477,6.46568102551345E-8,1,2,13.4005146026611,4.98191336831142,32.990001142025,1.36204818600776,0.203827213987746,1,9.88908573375947E-6,,,,,,,,,,,,,,,,,,,,,117.592544555664,117.68399810791,9999.6435546875,9999.6435546875,47.4346899465627,5.28305027686359,13.3827428817749,27,1,0,0,1,0.2752685546875,40.5669593811035,2,1,1,117.592544555664,0,117.638271331787,,,,,,,,,,,,,,,,,,,,,,,,,,,,,,,,,
,3832838448.92363,114.624820709229,9999.6435546875,0.00105316051437659,1.61343408395218E-7,1,2,13.4005146026611,4.98177013153006,32.9700000584126,1.39613455009156,0.208074695537782,1,9.50631073118984E-6,,,,,,,,,,,,,,,,,,,,,114.58512878418,114.664512634277,9999.6435546875,9999.6435546875,47.5042548847743,5.28334132935837,13.3558959960938,27,1,0,0,1,0.273590087890625,40.0782012939453,2,1,1,114.58512878418,0,114.624820709229,,,,,,,,,,,,,,,,,,,,,,,,,,,,,,,,,
,3832838501.37302,112.004138946533,9999.6435546875,0.00107490504840727,1.11347251198236E-7,1,2,13.4005146026611,4.98172420361285,32.9700000584126,1.42485090707552,0.213022543522475,1,1.01956342398273E-5,,,,,,,,,,,,,,,,,,,,,111.964530944824,112.043746948242,9999.6435546875,9999.6435546875,47.4174941191396,5.28370410956886,13.3324308395386,27,1,0,0,1,0.27435302734375,40.5669593811035,2,1,1,111.930793762207,0,112.004138946533,,,,,,,,,,,,,,,,,,,,,,,,,,,,,,,,,
,3832838561.76411,108.980499267578,9999.6435546875,0.0011014020292211,8.39867628175427E-8,1,2,13.4005146026611,4.98173331278057,32.9700000584126,1.46003723110596,0.217849906932209,1,1.01272935786245E-5,,,,,,,,,,,,,,,,,,,,,108.931159973145,109.029838562012,9999.6435546875,9999.6435546875,47.4417246032358,5.28394363921376,13.2998380661011,27,1,0,0,1,0.274734497070313,40.5669593811035,2,1,1,108.931159973145,0,108.980499267578,,,,,,,,,,,,,,,,,,,,,,,,,,,,,,,,,
,3832838620.39646,106.034271240234,9999.6435546875,0.00112974746044926,1.41718655123783E-7,1,2,13.4005146026611,4.98188279377524,32.9499989748001,1.49766027942984,0.22356454512726,1,1.04624334390387E-5,,,,,,,,,,,,,,,,,,,,,105.984405517578,106.084136962891,9999.6435546875,9999.6435546875,47.3932636350435,5.28305938538242,13.2628002166748,27,1,0,0,1,0.274505615234375,40.5669593811035,2,1,1,105.984405517578,0,106.034271240234,,,,,,,,,,,,,,,,,,,,,,,,,,,,,,,,,
,3832838672.57447,103.441883087158,9999.6435546875,0.0011548311514992,6.96063639721316E-8,1,2,13.4005146026611,4.98171872553003,32.9499989748001,1.53086611024992,0.228356250818621,1,1.05728694737327E-5,,,,,,,,,,,,,,,,,,,,,103.386573791504,103.497192382813,9999.6435546875,9999.6435546875,47.3999074774569,5.28355882135227,13.2378263473511,27,1,0,0,1,0.275115966796875,40.5669593811035,2,1,1,103.386573791504,0,103.441883087158,,,,,,,,,,,,,,,,,,,,,,,,,,,,,,,,,
,3832838762.629,98.929630279541,9999.6435546875,0.00120264077196632,1.09508780345626E-7,1,2,13.4005146026611,4.98184730697395,32.930001616478,1.5941915353221,0.238593868255911,1,1.15946865178716E-5,,,,,,,,,,,,,,,,,,,,,98.8522796630859,99.0069808959961,9999.6435546875,9999.6435546875,47.3690331509473,5.28275531830531,13.2001390457153,27,1,0,0,1,0.27435302734375,40.5669593811035,2,1,1,98.8522796630859,0,98.929630279541,,,,,,,,,,,,,,,,,,,,,,,,,,,,,,,,,
,3832838823.74954,95.8981819152832,9999.6435546875,0.00123541908089534,1.16178952373478E-7,1,2,13.4005146026611,4.98204874057639,32.930001616478,1.6378043657558,0.24459694057323,1,1.15238868340103E-5,,,,,,,,,,,,,,,,,,,,,95.8544921875,95.9418716430664,9999.6435546875,9999.6435546875,47.4280461041493,5.28219795011091,13.1669788360596,27,1,0,0,1,0.273971557617187,40.0782012939453,2,1,1,95.8544921875,0,95.8981819152832,,,,,,,,,,,,,,,,,,,,,,,,,,,,,,,,,
,3832838894.18469,92.4077911376953,9999.6435546875,0.00127790358679544,1.66687488274819E-7,1,2,13.4005146026611,4.9819991370068,32.9100005328655,1.69411933387495,0.252889755331083,1,1.18334634169429E-5,,,,,,,,,,,,,,,,,,,,,92.3518447875977,92.463737487793,9999.6435546875,9999.6435546875,47.4167124906204,5.28258009654674,13.1339817047119,27,1,0,0,1,0.273895263671875,40.0782012939453,2,1,1,92.3518447875977,0,92.4077911376953,,,,,,,,,,,,,,,,,,,,,,,,,,,,,,,,,
,3832838952.67534,89.4794769287109,9999.6435546875,0.0013133935414918,1.68862545054454E-7,1,2,13.4005146026611,4.98188916163979,32.9100005328655,1.74106456568211,0.260270657605236,1,1.24374727987274E-5,,,,,,,,,,,,,,,,,,,,,89.4375228881836,89.5214309692383,9999.6435546875,9999.6435546875,47.42726447563,5.28277930814921,13.0828628540039,27,1,0,0,1,0.274810791015625,40.5669593811035,2,1,1,89.4065093994141,0,89.4794769287109,,,,,,,,,,,,,,,,,,,,,,,,,,,,,,,,,
,3832839011.04692,86.5258941650391,9999.6435546875,0.00135224120230177,1.12306536801462E-7,1,2,13.4005146026611,4.98150734417776,32.9000018537045,1.79237372919226,0.267937763688803,1,1.28030845420324E-5,,,,,,,,,,,,,,,,,,,,,86.4740905761719,86.5776977539063,9999.6435546875,9999.6435546875,47.3944360778223,5.28448694010098,13.0558805465698,27,1,0,0,1,0.274276733398438,40.5669593811035,2,1,1,86.4740905761719,0,86.5258941650391,,,,,,,,,,,,,,,,,,,,,,,,,,,,,,,,,
,3832839069.4993,83.6212043762207,9999.6435546875,0.00139203327803022,1.37806572375283E-7,1,2,13.4005146026611,4.98150892511257,32.9000018537045,1.84510354707555,0.275927811520548,1,1.32592413931338E-5,,,,,,,,,,,,,,,,,,,,,83.5769805908203,83.6654281616211,9999.6435546875,9999.6435546875,47.3412853385146,5.28456443350493,13.0190296173096,27,1,0,0,1,0.274810791015625,40.5669593811035,2,1,1,83.5769805908203,0,83.6212043762207,,,,,,,,,,,,,,,,,,,,,,,,,,,,,,,,,
,3832839130.30156,80.5158042907715,9999.6435546875,0.0014380676175593,1.30155444393058E-7,1,2,13.4005146026611,4.98140793814664,32.880000770092,1.9060489911895,0.285179317287977,1,1.37990984458321E-5,,,,,,,,,,,,,,,,,,,,,80.4897537231445,80.5418548583984,9999.6435546875,9999.6435546875,47.4065513198704,5.28582165830672,12.9881191253662,27,1,0,0,1,0.27557373046875,40.5669593811035,2,1,1,80.4897537231445,0,80.5158042907715,,,,,,,,,,,,,,,,,,,,,,,,,,,,,,,,,
,3832839200.61589,77.0267486572266,9999.6435546875,0.00149253205412992,1.59320103635513E-7,1,2,13.4005146026611,4.98160143896322,32.880000770092,1.97831918584852,0.296165753678866,1,1.44497652754783E-5,,,,,,,,,,,,,,,,,,,,,76.9771881103516,77.0763092041016,9999.6435546875,9999.6435546875,47.3893554924473,5.28433761484968,12.9144601821899,27,1,0,0,1,0.274581909179687,40.5669593811035,2,1,1,76.9771881103516,0,77.0267486572266,,,,,,,,,,,,,,,,,,,,,,,,,,,,,,,,,
,3832839254.93389,74.2723159790039,9999.6435546875,0.00153739206125757,1.60522020809911E-7,1,2,13.4005146026611,4.981877247443,32.880000770092,2.03791895863425,0.305205689383869,1,1.49707827463841E-5,,,,,,,,,,,,,,,,,,,,,74.2151031494141,74.3295288085938,9999.6435546875,9999.6435546875,47.3330782390627,5.28278647045682,12.8892383575439,27,1,0,0,1,0.2740478515625,40.5669593811035,2,1,1,74.2151031494141,0,74.2723159790039,,,,,,,,,,,,,,,,,,,,,,,,,,,,,,,,,
,3832839319.39715,71.0313034057617,9999.6435546875,0.00159784861900152,1.79061074492494E-7,1,2,13.4005146026611,4.98183770804288,32.8599996864796,2.11863304768212,0.312928445112427,10,1.23382730084366E-5,,,,,,,,,,,,,,,,,,,,,70.9900665283203,71.0725402832031,9999.6435546875,9999.6435546875,47.4268736613704,5.28388423088083,12.8288106918335,27,1,0,0,1,0.274429321289062,40.5669593811035,2,1,1,70.9900665283203,0,71.0313034057617,,,,,,,,,,,,,,,,,,,,,,,,,,,,,,,,,
,3832839371.69835,68.3950881958008,9999.6435546875,0.00164744279472181,1.66046539754117E-7,1,2,13.4005146026611,4.98200980672925,32.8599996864796,2.18448732700484,0.322711129258834,10,1.27624225079141E-5,,,,,,,,,,,,,,,,,,,,,68.3432846069336,68.446891784668,9999.6435546875,9999.6435546875,47.4491500741685,5.28331154487338,12.8129978179932,27,1,0,0,1,0.274734497070313,40.5669593811035,2,1,1,68.3432846069336,0,68.3950881958008,,,,,,,,,,,,,,,,,,,,,,,,,,,,,,,,,
,3832839422.34867,65.8504486083984,9999.6435546875,0.00169785606801711,1.44354049220538E-7,1,2,13.4005146026611,4.98198293477636,32.8599996864796,2.25130679182335,0.33266401179915,10,1.32132968649533E-5,,,,,,,,,,,,,,,,,,,,,65.791145324707,65.9097518920898,9999.6435546875,9999.6435546875,47.3717688507646,5.28318557432301,12.7534217834473,27,1,0,0,1,0.27496337890625,40.5669593811035,2,1,1,65.791145324707,0,65.8504486083984,,,,,,,,,,,,,,,,,,,,,,,,,,,,,,,,,
,3832839474.48192,63.2161502838135,9999.6435546875,0.0017537073885557,1.43221426754217E-7,1,2,13.4005146026611,4.9819152946371,32.8599996864796,2.32534739451847,0.343409348773573,10,1.3503826741571E-5,,,,,,,,,,,,,,,,,,,,,63.1636199951172,63.2686805725098,9999.6435546875,9999.6435546875,47.4014707344954,5.28334941331952,12.6836557388306,27,1,0,0,1,0.275192260742187,40.5669593811035,2,1,1,63.1636199951172,0,63.2161502838135,,,,,,,,,,,,,,,,,,,,,,,,,,,,,,,,,
,3832839526.83679,60.5943832397461,9999.6435546875,0.00181678717692401,2.07601887034654E-7,1,2,13.4005146026611,4.98195275787193,32.8399986028671,2.40901445513401,0.35575909516582,10,1.39849167981818E-5,,,,,,,,,,,,,,,,,,,,,60.5407981872559,60.6479682922363,9999.6435546875,9999.6435546875,47.3670790796492,5.2835419117291,12.6367959976196,27,1,0,0,1,0.27496337890625,40.5669593811035,2,1,1,60.5407981872559,0,60.5943832397461,,,,,,,,,,,,,,,,,,,,,,,,,,,,,,,,,
,3832839587.43562,57.5622806549072,9999.6435546875,0.00189110659882666,3.02037704568968E-7,1,2,13.4005146026611,4.98250268053737,32.8399986028671,2.50785357352694,0.370987276275763,10,1.50232586551615E-5,,,,,,,,,,,,,,,,,,,,,57.5151824951172,57.6093788146973,9999.6435546875,9999.6435546875,47.3870106068896,5.28100290637727,12.5703601837158,27,1,0,0,1,0.273284912109375,40.5669593811035,2,1,1,57.5151824951172,0,57.5622806549072,,,,,,,,,,,,,,,,,,,,,,,,,,,,,,,,,
,3832839646.0058,54.618106842041,9999.6435546875,0.0019676814501255,4.71963818367468E-6,1,2,13.4005146026611,4.98252100405633,32.8399986028671,2.60850432474074,0.392524169276824,10,2.0537305538332E-5,,,,,,,,,,,,,,,,,,,,,54.5893211364746,54.6468925476074,9999.6435546875,9999.6435546875,47.3870106068896,5.28083991178817,12.5327138900757,27,1,0,0,1,0.273895263671875,40.5669593811035,2,1,1,54.5893211364746,0,54.618106842041,,,,,,,,,,,,,,,,,,,,,,,,,,,,,,,,,
,3832839698.3385,51.9712734222412,9999.6435546875,0.00204522729106724,2.16847766952597E-7,1,2,13.4005146026611,4.98286512105917,32.8399986028671,2.71253534642942,0.401069888875038,10,1.61029884898934E-5,,,,,,,,,,,,,,,,,,,,,51.9189643859863,52.0235824584961,9999.6435546875,9999.6435546875,47.3659066368704,5.27986298048599,12.4554080963135,27,1,0,0,1,0.272903442382813,40.0782012939453,2,1,1,51.9189643859863,0,51.9712734222412,,,,,,,,,,,,,,,,,,,,,,,,,,,,,,,,,
,3832839758.54015,48.9741821289063,9999.6435546875,0.0021447051393404,2.72106288969865E-7,1,2,13.4005146026611,4.98285087191078,32.820001244545,2.84441048922576,0.420924538764504,10,1.71488163503427E-5,,,,,,,,,,,,,,,,,,,,,48.927677154541,49.0206871032715,9999.6435546875,9999.6435546875,47.4335175037839,5.27975835942069,12.3355674743652,27,1,0,0,1,0.272979736328125,40.5669593811035,2,1,1,48.927677154541,0,48.9741821289063,,,,,,,,,,,,,,,,,,,,,,,,,,,,,,,,,
,3832839809.19313,46.4199848175049,9999.6435546875,0.00223177786971174,1.70488130580949E-7,1,2,13.4005146026611,4.98296111857056,32.820001244545,2.95996756786482,0.438118668926902,10,1.79141353185642E-5,,,,,,,,,,,,,,,,,,,,,46.3691177368164,46.4708518981934,9999.6435546875,9999.6435546875,47.4608745019569,5.2793545481912,12.2454824447632,27,1,0,0,1,0.272445678710938,40.5669593811035,2,1,1,46.3691177368164,0,46.4199848175049,,,,,,,,,,,,,,,,,,,,,,,,,,,,,,,,,
,3832839861.31158,43.7915077209473,9999.6435546875,0.00232767622511659,1.01813794276537E-5,1,2,13.4005146026611,4.98297659150617,32.820001244545,3.08514726424882,0.471405880631131,10,2.95739147894801E-5,,,,,,,,,,,,,,,,,,,,,43.7505683898926,43.832447052002,9999.6435546875,9999.6435546875,47.3420669670339,5.27949228135303,12.1586904525757,27,1,0,0,1,0.271530151367187,40.5669593811035,2,1,1,43.7505683898926,0,43.7915077209473,,,,,,,,,,,,,,,,,,,,,,,,,,,,,,,,,
,3832839913.72858,41.1640777587891,9999.6435546875,0.00242951438610108,1.4248220525844E-5,1,2,13.4005146026611,4.98300480532627,32.820001244545,3.21994151800598,0.493529282991182,10,3.19938108698328E-5,,,,,,,,,,,,,,,,,,,,,41.1195526123047,41.2086029052734,9999.6435546875,9999.6435546875,47.4257012185916,5.27954696092936,12.0579719543457,27,1,0,0,1,0.2728271484375,40.5669593811035,2,1,1,41.1195526123047,0,41.1640777587891,,,,,,,,,,,,,,,,,,,,,,,,,,,,,,,,,
,3832839994.43843,37.1078300476074,9999.6435546875,0.00263540391594029,4.41906242551391E-7,1,2,13.4005146026611,4.98302920349532,32.8000001609325,3.49521198790582,0.518388256733613,10,2.19254473420069E-5,,,,,,,,,,,,,,,,,,,,,37.0689697265625,37.1466903686523,9999.6435546875,9999.6435546875,47.3705964079858,5.27930561063209,11.8673496246338,26,1,68,0,0,0.273284912109375,40.5669593811035,2,1,1,37.0689697265625,0,37.1078300476074,,,,,,,,,,,,,,,,,,,,,,,,,,,,,,,,,
,3832840054.76121,34.0667037963867,9999.6435546875,0.00280193965688727,3.02997884467671E-7,1,2,13.4005146026611,4.9830700548557,32.8000001609325,3.71612888907975,0.551105226531108,10,2.3275494332081E-5,,,,,,,,,,,,,,,,,,,,,34.0236129760742,34.1097946166992,9999.6435546875,9999.6435546875,47.3827116500339,5.2791452038033,11.7108182907104,27,1,0,0,1,0.27252197265625,40.5669593811035,2,1,1,34.0236129760742,0,34.0667037963867,,,,,,,,,,,,,,,,,,,,,,,,,,,,,,,,,
,3832840125.5771,30.4984607696533,9999.6435546875,0.00302946011767548,3.76517553959165E-7,1,2,13.4005146026611,4.98303944505984,32.8000001609325,4.01778106398843,0.596333585722056,10,2.55292907298831E-5,,,,,,,,,,,,,,,,,,,,,30.4696617126465,30.5272598266602,9999.6435546875,9999.6435546875,47.4210114474762,5.27909031518367,11.5049257278442,27,1,0,0,1,0.272979736328125,40.5669593811035,2,1,1,30.4696617126465,0,30.4984607696533,,,,,,,,,,,,,,,,,,,,,,,,,,,,,,,,,
,3832840177.9211,27.8821496963501,9999.6435546875,0.00323282408155838,4.89999003588263E-6,1,2,13.4005146026611,4.98298144498977,32.8000001609325,4.28667661033095,0.64168064195237,10,3.12543050735606E-5,,,,,,,,,,,,,,,,,,,,,27.8299388885498,27.9343605041504,9999.6435546875,9999.6435546875,47.4042064343127,5.27896403833634,11.2705087661743,27,1,0,0,1,0.271759033203125,40.5669593811035,2,1,1,27.8299388885498,0,27.8821496963501,,,,,,,,,,,,,,,,,,,,,,,,,,,,,,,,,
,3832840268.3298,23.3767375946045,9999.6435546875,0.00366197093669388,5.73310468341387E-7,1,2,13.4005146026611,4.98299446975062,32.8000001609325,4.85637453686415,0.722300137167542,10,3.19658135791573E-5,,,,,,,,,,,,,,,,,,,,,23.3317317962646,23.4217433929443,9999.6435546875,9999.6435546875,47.5448995677743,5.27873752566134,10.7836608886719,27,1,0,0,1,0.272903442382813,40.5669593811035,2,1,1,23.3317317962646,0,23.3767375946045,,,,,,,,,,,,,,,,,,,,,,,,,,,,,,,,,
,3832840332.82318,20.1683235168457,9999.6435546875,0.00408037946742344,8.7910587795836E-7,1,2,13.4005146026611,4.98290750094149,32.7799990773201,5.41096567196961,0.805936561443675,10,3.64672000472387E-5,,,,,,,,,,,,,,,,,,,,,20.1194458007813,20.2172012329102,9999.6435546875,9999.6435546875,47.2979049556973,5.27893935597827,10.2728891372681,27,1,0,0,1,0.27313232421875,40.5669593811035,2,1,1,20.1194458007813,0,20.1683235168457,,,,,,,,,,,,,,,,,,,,,,,,,,,,,,,,,
,3832840408.50625,16.4276866912842,9999.6435546875,0.00473073612376652,1.15420280941919E-6,1,2,13.4005146026611,4.98292757529271,32.7799990773201,6.27303734411891,0.937235666700113,10,4.44175173915141E-5,,,,,,,,,,,,,,,,,,,,,16.4276866912842,16.4276866912842,9999.6435546875,9999.6435546875,47.4499317026877,5.2792325719949,9.55137252807617,27,1,0,0,1,0.272750854492187,40.5669593811035,2,1,1,16.4276866912842,0,16.4276866912842,,,,,,,,,,,,,,,,,,,,,,,,,,,,,,,,,
,3832840487.90444,12.5378499031067,9999.6435546875,0.00581907277432197,1.98140515689156E-6,1,2,13.4005146026611,4.98281980255685,32.7799990773201,7.71628055592969,1.15053576112956,10,5.29166821687877E-5,,,,,,,,,,,,,,,,,,,,,12.4949626922607,12.5807371139526,9999.6435546875,9999.6435546875,47.4186665619185,5.2794675314514,8.54771327972412,27,1,0,0,1,0.273361206054687,40.5669593811035,2,1,1,12.4949626922607,0,12.5378499031067,,,,,,,,,,,,,,,,,,,,,,,,,,,,,,,,,
,3832840546.57303,9.95607614517212,9999.6435546875,0.00695761395391884,1.77430854224739E-6,1,2,13.4005146026611,4.98291143193224,32.7900014817715,9.22599029814918,1.37758248482241,10,6.47025732575492E-5,,,,,,,,,,,,,,,,,,,,,9.92055320739746,9.99159908294678,9999.6435546875,9999.6435546875,47.4151492335819,5.27787901400102,7.72906732559204,27,1,0,0,1,0.2728271484375,40.5669593811035,6,1,1,9.92055320739746,0,9.95607614517212,,,,,,,,,,,,,,,,,,,,,,,,,,,,,,,,,
,3832840608.90202,7.99990487098694,9999.6435546875,0.00823939147650646,8.78950017279752E-7,1,2,13.4005146026611,4.98292887786702,32.7799990773201,10.9255592032665,1.63249600941122,10,7.74647948170276E-5,,,,,,,,,,,,,,,,,,,,,7.99945306777954,8.00035667419434,9999.6435546875,9999.6435546875,47.3545730233415,5.27772592482877,7.43510675430298,27,1,0,0,1,0.273056030273438,40.5669593811035,5,1,1,8.00035667419434,0,7.99990487098694,,,,,,,,,,,,,,,,,,,,,,,,,,,,,,,,,
,3832840647.35695,7.99991583824158,9999.6435546875,0.00823941118100919,9.00566518981531E-7,1,2,13.4005146026611,4.98289527184183,32.7799990773201,10.9255719555517,1.63185713016528,10,7.69922464850169E-5,,,,,,,,,,,,,,,,,,,,,7.99983072280884,8.00000095367432,9999.6435546875,9999.6435546875,47.532002697207,5.27759608861216,7.45731067657471,27,1,0,0,1,0.273284912109375,40.5669593811035,1,1,1,7.99983072280884,0,7.99991583824158,,,,,,,,,,,,,,,,,,,,,,,,,,,,,,,,,