File: SI Fig S11-13 SQUID all/Michaela_Dy_FC1T.dat
[Header]
; MPMS3 Data File (default extension .dat)
; Copyright (c) 2007, Quantum Design, Inc. All rights reserved.
TITLE,
FILEOPENTIME,3832420205.03638,06/09/2021,5:10 pm
BYAPP,MPMS3 w/ AC,1.0,1.1
INFO,MPMS3 Measurement Release 1.1.16 Build 424, MultiVu Release 2.3.4.19,APPNAME
INFO,Linear Motor Servo Controller,MOTOR_MODULE_NAME
INFO,3101-100 E1,MOTOR_HW_VERSION
INFO,MMC211,MOTOR_SERIAL_NUMBER
INFO,01.04.28,MOTOR_SOFTWARE_VERSION
INFO,Quantum Design Squid Module,SQUID_MODULE_NAME
INFO,3101-501 B0,SQUID_HW_VERSION
INFO,SQM059,SQUID_SERIAL_NUMBER
INFO,01.03.04,SQUID_SOFTWARE_VERSION
INFO,SQUID AC,AC_MODULE_NAME
INFO,3101-401 F1,AC_HW_VERSION
INFO,SAC057,AC_SERIAL_NUMBER
INFO,SQUID AC 00.95.07,AC_SOFTWARE_VERSION
INFO,TCIXXX,COIL_SERIAL_NUMBER
INFO,0,MOMENT_UNITS
INFO,Michaela_Dy,SAMPLE_MATERIAL
INFO,Michaela_Dy,SAMPLE_COMMENT
INFO,.85,SAMPLE_MASS
INFO,,SAMPLE_VOLUME
INFO,,SAMPLE_MOLECULAR_WEIGHT
INFO,,SAMPLE_SIZE
INFO,,SAMPLE_SHAPE
INFO,Straw,SAMPLE_HOLDER
INFO,Standard,SAMPLE_HOLDER_DETAIL
INFO,54.24,SAMPLE_OFFSET
DATATYPE,COMMENT,1
DATATYPE,TIME,2
STARTUPAXIS,X,2
STARTUPAXIS,Y1,5
FIELDGROUP, VSM,2,3,4,5,6,8,9,10,11,14,15
FIELDGROUP, DC, 2,3,4,14,56,57,58,59,60,61,62,63,64,65,66,67,68,69
FIELDGROUP, AC, 2,3,4,11,16,17,18,19,20,21,22,23,24,25,26,27,28,29,30
STARTUPGROUP, All
[Data]
Comment,Time Stamp (sec),Temperature (K),Magnetic Field (Oe),Moment (emu),M. Std. Err. (emu),Transport Action,Averaging Time (sec),Frequency (Hz),Peak Amplitude (mm),Center Position (mm),Lockin Signal' (V),Lockin Signal (V),Range,M. Quad. Signal (emu),AC Moment (emu),AC M. Std Err. (emu),AC Phase (deg),AC Phase Std. Err. (deg),AC Susceptibility (emu/Oe),AC Suscept. Std Err. (emu/Oe),AC X' (emu/Oe),AC X' Std Err. (emu/Oe),AC X'' (emu/Oe),AC X'' Std Err. (emu/Oe),AC Drive (Oe),AC Frequency (Hz),AC Averaging Time (sec),AC Cycles,AC Range,AC Measure Type,AC Signal' (V),AC Signal'' (V),AC Trim Coil Ratio,AC Trim Coil Phase,Min. Temperature (K),Max. Temperature (K),Min. Field (Oe),Max. Field (Oe),Mass (grams),Motor Lag (deg),Pressure (Torr),Measure Count,Measurement Number,SQUID Status (code),Motor Status (code),Measure Status (code),Motor Current (amps),Motor Temp. (C),Temp. Status (code),Field Status (code),Chamber Status (code),Chamber Temp (K),Redirection State,Average Temp (K),Rotation Angle (deg),Rotator state,DC Moment Fixed Ctr (emu),DC Moment Err Fixed Ctr (emu),DC Moment Free Ctr (emu),DC Moment Err Free Ctr (emu),DC Fixed Fit,DC Free Fit,DC Calculated Center (mm),DC Calculated Center Err (mm),DC Scan Length (mm),DC Scan Time (s),DC Number of Points,DC Squid Drift,DC Min V (V),DC Max V (V),DC Scans per Measure,Map 01,Map 02,Map 03,Map 04,Map 05,Map 06,Map 07,Map 08,Map 09,Map 10,Map 11,Map 12,Map 13,Map 14,Map 15,Map 16
,3832420212.77964,299.921325683594,9999.7802734375,0.000273924037895028,4.18244709082178E-8,1,2,13.4005146026611,5.0034339906439,33.100001513958,0.36535450276047,0.0540266046178632,1,2.1611585397836E-6,,,,,,,,,,,,,,,,,,,,,299.921203613281,299.921447753906,9999.7802734375,9999.7802734375,47.3834932785531,5.27208530467886,8.21032810211182,27,1,0,0,1,0.281524658203125,40.0782012939453,1,1,1,299.921447753906,0,299.921325683594,,,,,,,,,,,,,,,,,,,,,,,,,,,,,,,,,
,3832420263.95395,298.317489624023,9999.7802734375,0.000276536491299371,3.16784325575276E-8,1,2,13.4005146026611,5.00346455819635,33.100001513958,0.36884099694722,0.0545496673866911,1,2.18727237587002E-6,,,,,,,,,,,,,,,,,,,,,298.263031005859,298.371948242188,9999.7802734375,9999.7802734375,47.3920911922646,5.27201599077385,8.20451068878174,26,1,64,0,0,0.282821655273438,40.0782012939453,2,1,1,298.263031005859,0,298.317489624023,,,,,,,,,,,,,,,,,,,,,,,,,,,,,,,,,
,3832420316.53869,295.589218139648,9999.7802734375,0.000279888799313241,3.39674450494059E-8,1,2,13.4005146026611,5.00340895029104,33.0899991095066,0.373309880096994,0.055186567049126,1,2.19615915781262E-6,,,,,,,,,,,,,,,,,,,,,295.560028076172,295.618408203125,9999.7802734375,9999.7802734375,47.3995166631973,5.27248396566004,8.17830657958984,27,1,0,0,1,0.280532836914062,40.0782012939453,2,1,1,295.560028076172,0,295.589218139648,,,,,,,,,,,,,,,,,,,,,,,,,,,,,,,,,
,3832420368.87053,292.941680908203,9999.7802734375,0.000282696819775795,3.08322346057416E-8,1,2,13.4005146026611,5.00332050601578,33.0599993467331,0.377042186140485,0.0557664624773407,1,2.23884601218384E-6,,,,,,,,,,,,,,,,,,,,,292.894653320313,292.988708496094,9999.7802734375,9999.7802734375,47.3944360778223,5.27315562276854,8.15887928009033,27,1,0,0,1,0.281753540039062,40.0782012939453,2,1,1,292.894653320313,0,292.941680908203,,,,,,,,,,,,,,,,,,,,,,,,,,,,,,,,,
,3832420421.04397,290.340560913086,9999.7802734375,0.000286157595163851,3.11878302977595E-8,1,2,13.4005146026611,5.00344871843114,33.0599993467331,0.381676651956275,0.0564129769327847,1,2.23767706412473E-6,,,,,,,,,,,,,,,,,,,,,290.304077148438,290.377044677734,9999.7802734375,9999.7802734375,47.3850565355916,5.27236791209132,8.14479637145996,27,1,0,0,1,0.281524658203125,40.0782012939453,2,1,1,290.304077148438,0,290.340560913086,,,,,,,,,,,,,,,,,,,,,,,,,,,,,,,,,
,3832420473.70415,287.746810913086,9999.7802734375,0.000289284768316168,3.45308423380733E-8,1,2,13.4005146026611,5.00341524174906,33.050000667572,0.385844541297293,0.0570260759428531,1,2.25998243813375E-6,,,,,,,,,,,,,,,,,,,,,287.716125488281,287.777496337891,9999.7802734375,9999.7802734375,47.3498832522262,5.27243276265296,8.12544059753418,27,1,0,0,1,0.281753540039062,40.0782012939453,2,1,1,287.716125488281,0,287.746810913086,,,,,,,,,,,,,,,,,,,,,,,,,,,,,,,,,
,3832420525.90004,285.125350952148,9999.7802734375,0.00029296671737273,4.04863387569994E-8,1,2,13.4005146026611,5.00338914583781,33.050000667572,0.390751418584484,0.0577605908941102,1,2.29557152436437E-6,,,,,,,,,,,,,,,,,,,,,285.064331054687,285.186370849609,9999.7802734375,9999.7802734375,47.3889646781877,5.2724627387829,8.12269020080566,27,1,0,0,1,0.279464721679687,40.0782012939453,2,1,1,285.064331054687,0,285.125350952148,,,,,,,,,,,,,,,,,,,,,,,,,,,,,,,,,
,3832420576.53197,282.539398193359,9999.7802734375,0.000296120961660522,3.96388199761516E-8,1,2,13.4005146026611,5.00327669717959,33.0200009047985,0.394954188747495,0.0583244391787939,1,2.27816595340016E-6,,,,,,,,,,,,,,,,,,,,,282.519409179687,282.559387207031,9999.7802734375,9999.7802734375,47.4405521604569,5.2723543391099,8.10486698150635,27,1,0,0,1,0.281600952148438,40.0782012939453,2,1,1,282.519409179687,0,282.539398193359,,,,,,,,,,,,,,,,,,,,,,,,,,,,,,,,,
,3832420628.63949,279.923110961914,9999.7802734375,0.000299502536842659,5.00740994059306E-8,1,2,13.4005146026611,5.00331368382658,32.9999998211861,0.399464712190529,0.0590177153031187,1,2.32413306175213E-6,,,,,,,,,,,,,,,,,,,,,279.890075683594,279.956146240234,9999.7802734375,9999.7802734375,47.3799759502165,5.27230908401587,8.10136032104492,27,1,0,0,1,0.282974243164062,40.0782012939453,2,1,1,279.890075683594,0,279.923110961914,,,,,,,,,,,,,,,,,,,,,,,,,,,,,,,,,
,3832420678.89867,277.401245117187,9999.7802734375,0.000303081380689728,2.73350279506092E-8,1,2,13.4005146026611,5.0032981187955,32.9999998211861,0.404223463384319,0.0598145821882809,1,2.42073402194841E-6,,,,,,,,,,,,,,,,,,,,,277.343963623047,277.458526611328,9999.7802734375,9999.7802734375,47.2975141414377,5.27281392906419,8.09900569915772,27,1,0,0,1,0.279693603515625,40.0782012939453,2,1,1,277.343963623047,0,277.401245117187,,,,,,,,,,,,,,,,,,,,,,,,,,,,,,,,,
,3832420729.5352,274.93391418457,9999.7802734375,0.000306417293295075,3.42030580273554E-8,1,2,13.4005146026611,5.00328514350066,32.9799987375736,0.408688116288731,0.0603514719795842,1,2.35656461233514E-6,,,,,,,,,,,,,,,,,,,,,274.874908447266,274.992919921875,9999.7802734375,9999.7802734375,47.4440694887935,5.27375885525583,8.08198642730713,27,1,0,0,1,0.28106689453125,40.0782012939453,2,1,1,274.874908447266,0,274.93391418457,,,,,,,,,,,,,,,,,,,,,,,,,,,,,,,,,
,3832420781.6829,272.296875,9999.7802734375,0.000309837191868704,3.92244387812686E-8,1,2,13.4005146026611,5.00332021519338,32.9700000584126,0.41324841331642,0.0610613993060263,1,2.4096514983437E-6,,,,,,,,,,,,,,,,,,,,,272.237976074219,272.355773925781,9999.7802734375,9999.7802734375,47.3827116500339,5.27282245070773,8.0719575881958,27,1,0,0,1,0.279922485351562,40.0782012939453,2,1,1,272.237976074219,0,272.296875,,,,,,,,,,,,,,,,,,,,,,,,,,,,,,,,,
,3832420832.18627,269.760848999023,9999.7802734375,0.0003136105319182,3.92382879434272E-8,1,2,13.4005146026611,5.00338597145179,32.9600013792515,0.418282822916927,0.0618479119228002,1,2.47027841426027E-6,,,,,,,,,,,,,,,,,,,,,269.725463867187,269.796234130859,9999.7802734375,9999.7802734375,47.3678607081685,5.2722470899236,8.06327056884766,27,1,0,0,1,0.281295776367187,40.0782012939453,2,1,1,269.725463867187,0,269.760848999023,,,,,,,,,,,,,,,,,,,,,,,,,,,,,,,,,
,3832420884.43615,267.191055297852,9999.7802734375,0.00031715905852556,3.17641587335353E-8,1,2,13.4005146026611,5.00342193285931,32.940000295639,0.42301049923893,0.0626154560374343,1,2.5484941319629E-6,,,,,,,,,,,,,,,,,,,,,267.150360107422,267.231750488281,9999.7802734375,9999.7802734375,47.3854473498512,5.27213403210421,8.05045986175537,27,1,0,0,1,0.283126831054687,40.0782012939453,2,1,1,267.150360107422,0,267.191055297852,,,,,,,,,,,,,,,,,,,,,,,,,,,,,,,,,
,3832420938.8757,264.475112915039,9999.7802734375,0.000321314093597573,4.01242070731517E-8,1,2,13.4005146026611,5.00329075103088,32.940000295639,0.428551094393807,0.0633319880105177,1,2.50585918745719E-6,,,,,,,,,,,,,,,,,,,,,264.432678222656,264.517547607422,9999.7802734375,9999.7802734375,47.3874014211492,5.27273157637852,8.04253196716309,27,1,0,0,1,0.281829833984375,40.0782012939453,2,1,1,264.432678222656,0,264.475112915039,,,,,,,,,,,,,,,,,,,,,,,,,,,,,,,,,
,3832420989.45426,261.917785644531,9999.7802734375,0.000324856534269588,3.96168563856327E-8,1,2,13.4005146026611,5.0033562040053,32.9199992120266,0.433284163416559,0.0640270517066396,1,2.53025946557715E-6,,,,,,,,,,,,,,,,,,,,,261.883605957031,261.951965332031,9999.7802734375,9999.7802734375,47.3108018262646,5.27223741832535,8.02993106842041,26,1,64,0,0,0.279159545898438,40.0782012939453,2,1,1,261.883605957031,0,261.917785644531,,,,,,,,,,,,,,,,,,,,,,,,,,,,,,,,,
,3832421039.6298,259.415756225586,9999.7802734375,0.000328801130442567,3.80844377632617E-8,1,2,13.4005146026611,5.00331007997815,32.9199992120266,0.438542280793536,0.0647860904600524,1,2.54780370643661E-6,,,,,,,,,,,,,,,,,,,,,259.375335693359,259.456176757813,9999.7802734375,9999.7802734375,47.2674214434473,5.27263437653465,8.01743316650391,26,1,64,0,0,0.278854370117187,40.0782012939453,2,1,1,259.375335693359,0,259.415756225586,,,,,,,,,,,,,,,,,,,,,,,,,,,,,,,,,
,3832421092.23622,256.799209594727,9999.7802734375,0.000332649902453939,3.36386343151306E-8,1,2,13.4005146026611,5.00324682735411,32.9000018537045,0.443660700460886,0.0655951687005249,1,2.61646807548217E-6,,,,,,,,,,,,,,,,,,,,,256.778411865234,256.820007324219,9999.7802734375,9999.7802734375,47.3905279352262,5.27239138848459,8.0122709274292,27,1,0,0,1,0.282363891601562,40.0782012939453,2,1,1,256.769989013672,0,256.799209594727,,,,,,,,,,,,,,,,,,,,,,,,,,,,,,,,,
,3832421144.65136,254.17310333252,9999.7802734375,0.00033675722547254,5.2670464929173E-8,1,2,13.4005146026611,5.00325867999548,32.9100005328655,0.449144712556466,0.0663727531213207,1,2.62439354137594E-6,,,,,,,,,,,,,,,,,,,,,254.114685058594,254.231521606445,9999.7802734375,9999.7802734375,47.3745045505819,5.27261432333787,8.00533580780029,27,1,0,0,1,0.281295776367187,40.0782012939453,2,1,1,254.114685058594,0,254.17310333252,,,,,,,,,,,,,,,,,,,,,,,,,,,,,,,,,
,3832421196.72247,251.580596923828,9999.7802734375,0.000340722074221235,3.7451761982687E-8,1,2,13.4005146026611,5.00330559988333,32.880000770092,0.454440510492642,0.0671413815418415,1,2.6450464545036E-6,,,,,,,,,,,,,,,,,,,,,251.541763305664,251.619430541992,9999.7802734375,9999.7802734375,47.31549159738,5.27237554874476,7.99631357192993,27,1,0,0,1,0.278244018554687,40.0782012939453,2,1,1,251.541763305664,0,251.580596923828,,,,,,,,,,,,,,,,,,,,,,,,,,,,,,,,,
,3832421247.27895,249.05842590332,9999.7802734375,0.000344717115238865,3.28853283761658E-8,1,2,13.4005146026611,5.00322766944098,32.880000770092,0.4597520913947,0.0679775117981532,1,2.71375571443616E-6,,,,,,,,,,,,,,,,,,,,,249.037826538086,249.079025268555,9999.7802734375,9999.7802734375,47.3440210383319,5.27393579756731,7.97533750534058,27,1,0,0,1,0.283889770507813,40.0782012939453,2,1,1,249.037826538086,0,249.05842590332,,,,,,,,,,,,,,,,,,,,,,,,,,,,,,,,,
,3832421299.56242,246.411682128906,9999.7802734375,0.000348820195850846,4.51111980489824E-8,1,2,13.4005146026611,5.00313187471881,32.8500010073185,0.465213472783928,0.0687758611295288,1,2.73933990247098E-6,,,,,,,,,,,,,,,,,,,,,246.367706298828,246.455657958984,9999.7802734375,9999.7802734375,47.2904794847646,5.2749429437552,7.98085832595825,27,1,0,0,1,0.281600952148438,40.0782012939453,2,1,1,246.367706298828,0,246.411682128906,,,,,,,,,,,,,,,,,,,,,,,,,,,,,,,,,
,3832421353.86235,243.71753692627,9999.7802734375,0.000353407623311827,4.5267341565321E-8,1,2,13.4005146026611,5.0031918889912,32.8500010073185,0.471336096974642,0.0697047863183585,1,2.79281076812303E-6,,,,,,,,,,,,,,,,,,,,,243.659759521484,243.775314331055,9999.7802734375,9999.7802734375,47.4522765882454,5.27288301524173,7.95627546310425,27,1,0,0,1,0.283050537109375,40.0782012939453,2,1,1,243.659759521484,0,243.71753692627,,,,,,,,,,,,,,,,,,,,,,,,,,,,,,,,,
,3832421404.50266,241.168151855469,9999.7802734375,0.000357467156703016,4.20391731423078E-8,1,2,13.4005146026611,5.0032419432821,32.8399986028671,0.476750475471855,0.070551524993869,1,2.85865947199537E-6,,,,,,,,,,,,,,,,,,,,,241.134872436523,241.201431274414,9999.7802734375,9999.7802734375,47.3440210383319,5.27232011924303,7.95976448059082,27,1,0,0,1,0.28076171875,40.0782012939453,2,1,1,241.134872436523,0,241.168151855469,,,,,,,,,,,,,,,,,,,,,,,,,,,,,,,,,
,3832421456.758,238.532775878906,9999.7802734375,0.000362015568487631,5.75444699182514E-8,1,2,13.4005146026611,5.00327426654923,32.8299999237061,0.482826709452653,0.0714084133198036,1,2.86399588555616E-6,,,,,,,,,,,,,,,,,,,,,238.475646972656,238.589904785156,9999.7802734375,9999.7802734375,47.3924820065242,5.27276579193619,7.95217514038086,27,1,0,0,1,0.281524658203125,40.0782012939453,2,1,1,238.475646972656,0,238.532775878906,,,,,,,,,,,,,,,,,,,,,,,,,,,,,,,,,
,3832421506.99788,236.110931396484,9999.7802734375,0.000366329593690879,6.91315348198199E-8,1,2,13.4005146026611,5.00327229677853,32.8099988400936,0.488579201284119,0.0722660376865973,1,2.90315203377627E-6,,,,,,,,,,,,,,,,,,,,,236.051574707031,236.170288085938,9999.7802734375,9999.7802734375,47.3690331509473,5.27240251679757,7.93678140640259,27,1,0,0,1,0.281982421875,39.5894432067871,2,1,1,236.051574707031,0,236.110931396484,,,,,,,,,,,,,,,,,,,,,,,,,,,,,,,,,
,3832421559.8105,233.361267089844,9999.7802734375,0.000371044967121317,5.72057991800872E-8,1,2,13.4005146026611,5.00327074465914,32.8099988400936,0.494867224503203,0.0732014326108404,1,2.94443206689515E-6,,,,,,,,,,,,,,,,,,,,,233.30615234375,233.416381835938,9999.7802734375,9999.7802734375,47.3135375260819,5.27232875505841,7.91781139373779,27,1,0,0,1,0.2813720703125,40.0782012939453,2,1,1,233.30615234375,0,233.361267089844,,,,,,,,,,,,,,,,,,,,,,,,,,,,,,,,,
,3832421613.97269,230.717864990234,9999.7802734375,0.000375901586066952,3.16306478073527E-8,1,2,13.4005146026611,5.00331515197322,32.7900014817715,0.501344220225867,0.0742064110708978,1,3.01738008121158E-6,,,,,,,,,,,,,,,,,,,,,230.666748046875,230.768981933594,9999.7802734375,9999.7802734375,47.2263859461877,5.27201586666764,7.92689943313599,27,1,0,0,1,0.282058715820313,40.0782012939453,2,1,1,230.666748046875,0,230.717864990234,,,,,,,,,,,,,,,,,,,,,,,,,,,,,,,,,
,3832421666.21187,228.120697021484,9999.7802734375,0.000380807661209644,3.32891913033692E-8,1,2,13.4005146026611,5.00329849445354,32.7900014817715,0.507891154587649,0.0751319523420463,1,3.02484082047898E-6,,,,,,,,,,,,,,,,,,,,,228.084579467773,228.156814575195,9999.7802734375,9999.7802734375,47.3029855410723,5.27220689206048,7.91506719589233,27,1,0,0,1,0.281753540039062,39.5894432067871,2,1,1,228.084579467773,0,228.120697021484,,,,,,,,,,,,,,,,,,,,,,,,,,,,,,,,,
,3832421718.90283,225.52571105957,9999.7802734375,0.000385684118898971,4.18887157025704E-8,1,2,13.4005146026611,5.00326026432739,32.7799990773201,0.514388811218837,0.0760989880253629,1,3.06786256547534E-6,,,,,,,,,,,,,,,,,,,,,225.488754272461,225.56266784668,9999.7802734375,9999.7802734375,47.3057212408896,5.27257323421428,7.9054651260376,27,1,0,0,1,0.280380249023438,39.5894432067871,2,1,1,225.488754272461,0,225.52571105957,,,,,,,,,,,,,,,,,,,,,,,,,,,,,,,,,
,3832421768.94971,223.004455566406,9999.7802734375,0.000390569332475261,4.05155274479502E-8,1,2,13.4005146026611,5.00326001202851,32.770000398159,0.520903042874636,0.0770712179186179,1,3.11296609030212E-6,,,,,,,,,,,,,,,,,,,,,222.958801269531,223.050109863281,9999.7802734375,9999.7802734375,47.3311241677646,5.2727201923549,7.90290451049805,27,1,0,0,1,0.283050537109375,39.5894432067871,2,1,1,222.958801269531,0,223.004455566406,,,,,,,,,,,,,,,,,,,,,,,,,,,,,,,,,
,3832421823.35581,220.2587890625,9999.7802734375,0.000395857191983951,5.40246787166397E-8,1,2,13.4005146026611,5.00330578153265,32.760001718998,0.527964305533145,0.078099718764156,1,3.14317958202845E-6,,,,,,,,,,,,,,,,,,,,,220.200714111328,220.316864013672,9999.7802734375,9999.7802734375,47.3365955673992,5.27174438402624,7.89886903762817,27,1,0,0,1,0.27862548828125,40.0782012939453,2,1,1,220.200714111328,0,220.2587890625,,,,,,,,,,,,,,,,,,,,,,,,,,,,,,,,,
,3832421873.87572,217.716499328613,9999.7802734375,0.000400976295368793,4.25381082368225E-8,1,2,13.4005146026611,5.00323157925444,32.7499993145466,0.53476565574552,0.0792172990685011,1,3.26563076288746E-6,,,,,,,,,,,,,,,,,,,,,217.689193725586,217.743804931641,9999.7802734375,9999.7802734375,47.3248711396108,5.27174704472743,7.88913631439209,27,1,0,0,1,0.283279418945313,40.0782012939453,2,1,1,217.689193725586,0,217.716499328613,,,,,,,,,,,,,,,,,,,,,,,,,,,,,,,,,
,3832421928.14966,215.061134338379,9999.7802734375,0.000406544554995897,6.86964533218865E-8,1,2,13.4005146026611,5.00318423435921,32.7400006353855,0.54219309255796,0.0802569990094907,1,3.26654204847285E-6,,,,,,,,,,,,,,,,,,,,,215.020629882813,215.101638793945,9999.7802734375,9999.7802734375,47.3846657213319,5.27240852410794,7.87410688400269,27,1,0,0,1,0.27801513671875,40.0782012939453,2,1,1,215.020629882813,0,215.061134338379,,,,,,,,,,,,,,,,,,,,,,,,,,,,,,,,,
,3832421980.49716,212.409286499023,9999.7802734375,0.000412092571031144,6.47554440593027E-8,1,2,13.4005146026611,5.0031840654847,32.7299982309341,0.549579789911445,0.0814413307326957,1,3.37784384479153E-6,,,,,,,,,,,,,,,,,,,,,212.354598999023,212.463973999023,9999.7802734375,9999.7802734375,47.3252619538704,5.2720310007407,7.87232732772827,27,1,0,0,1,0.282974243164062,40.0782012939453,2,1,1,212.354598999023,0,212.409286499023,,,,,,,,,,,,,,,,,,,,,,,,,,,,,,,,,
,3832422031.06468,209.869483947754,9999.7802734375,0.000417574924223931,8.83387079959718E-8,1,2,13.4005146026611,5.00314702239314,32.710000872612,0.556880888271309,0.0825575947817241,1,3.44796941511282E-6,,,,,,,,,,,,,,,,,,,,,209.834335327148,209.904632568359,9999.7802734375,9999.7802734375,47.3268252109089,5.27200982213052,7.86996507644653,27,1,0,0,1,0.281906127929687,40.0782012939453,2,1,1,209.834335327148,0,209.869483947754,,,,,,,,,,,,,,,,,,,,,,,,,,,,,,,,,
,3832422085.36789,207.180053710938,9999.7802734375,0.000423582941927803,7.35731768325325E-8,1,2,13.4005146026611,5.00300398846252,32.710000872612,0.564866212303887,0.0837773225322263,1,3.52392427626719E-6,,,,,,,,,,,,,,,,,,,,,207.144134521484,207.215972900391,9999.7802734375,9999.7802734375,47.3018130982935,5.27250338544952,7.85258054733276,27,1,0,0,1,0.2838134765625,39.5894432067871,2,1,1,207.144134521484,0,207.180053710938,,,,,,,,,,,,,,,,,,,,,,,,,,,,,,,,,
,3832422137.63481,204.558547973633,9999.7802734375,0.000429465537461924,6.62123928447144E-8,1,2,13.4005146026611,5.00309512350708,32.6999984681606,0.572735151336692,0.0848716030930615,1,3.51945217746893E-6,,,,,,,,,,,,,,,,,,,,,204.501434326172,204.615661621094,9999.7802734375,9999.7802734375,47.3088477549665,5.27180897537063,7.84286880493164,27,1,0,0,1,0.28350830078125,40.0782012939453,2,1,1,204.501434326172,0,204.558547973633,,,,,,,,,,,,,,,,,,,,,,,,,,,,,,,,,
,3832422189.34305,202.016845703125,9999.7802734375,0.000435530818715409,6.69213223212806E-8,1,2,13.4005146026611,5.00304145644178,32.6800011098385,0.580807601568317,0.0861239275428595,1,3.61032040174613E-6,,,,,,,,,,,,,,,,,,,,,201.926116943359,202.107574462891,9999.7802734375,9999.7802734375,47.3006406555146,5.27239900749159,7.8377833366394,27,1,0,0,1,0.285415649414062,40.0782012939453,2,1,1,201.926116943359,0,202.016845703125,,,,,,,,,,,,,,,,,,,,,,,,,,,,,,,,,
,3832422242.61324,199.356903076172,9999.7802734375,0.000441730616947564,2.74814665266301E-8,1,2,13.4005146026611,5.00302661957583,32.660000026226,0.589058046764963,0.0874567145372023,1,3.74197974581269E-6,,,,,,,,,,,,,,,,,,,,,199.319641113281,199.394165039062,9999.7802734375,9999.7802734375,47.3897463067069,5.27269711604608,7.81883239746094,27,1,0,0,1,0.284881591796875,39.5894432067871,2,1,1,199.319641113281,0,199.356903076172,,,,,,,,,,,,,,,,,,,,,,,,,,,,,,,,,
,3832422294.83564,196.733367919922,9999.7802734375,0.000448084772099581,5.53133117041812E-8,1,2,13.4005146026611,5.00298067891801,32.660000026226,0.597534428056052,0.088638727996948,1,3.73969882707834E-6,,,,,,,,,,,,,,,,,,,,,196.683685302734,196.783050537109,9999.7802734375,9999.7802734375,47.3870106068896,5.27365157628048,7.79848289489746,27,1,0,0,1,0.283432006835938,40.0782012939453,2,1,1,196.683685302734,0,196.733367919922,,,,,,,,,,,,,,,,,,,,,,,,,,,,,,,,,
,3832422347.15904,194.087707519531,9999.7802734375,0.00045460067529413,2.84135356735338E-8,1,2,13.4005146026611,5.00290585186439,32.6399989426136,0.606203285510943,0.0899822724910019,1,3.83634726464722E-6,,,,,,,,,,,,,,,,,,,,,194.036987304687,194.138427734375,9999.7802734375,9999.7802734375,47.2982957699569,5.27488372884507,7.78826951980591,27,1,0,0,1,0.28228759765625,39.5894432067871,2,1,1,194.036987304687,0,194.087707519531,,,,,,,,,,,,,,,,,,,,,,,,,,,,,,,,,
,3832422397.85272,191.578804016113,9999.7802734375,0.000460997576335759,6.70672081997313E-8,1,2,13.4005146026611,5.00292484569064,32.6399989426136,0.614742366009484,0.0912080591510433,1,3.8597173519409E-6,,,,,,,,,,,,,,,,,,,,,191.509216308594,191.648391723633,9999.7802734375,9999.7802734375,47.3455842953704,5.27385387161619,7.77955913543701,27,1,0,0,1,0.277938842773438,40.0782012939453,2,1,1,191.509216308594,0,191.578804016113,,,,,,,,,,,,,,,,,,,,,,,,,,,,,,,,,
,3832422449.92871,188.998908996582,9999.7802734375,0.000467976911949019,5.00701508886556E-8,1,2,13.4005146026611,5.00294657777397,32.6200015842915,0.624050272903141,0.0926093303046096,1,3.93303069654193E-6,,,,,,,,,,,,,,,,,,,,,188.961456298828,189.036361694336,9999.7802734375,9999.7802734375,47.3678607081685,5.27381718746081,7.77100276947021,27,1,0,0,1,0.282974243164062,40.0782012939453,2,1,1,188.961456298828,0,188.998908996582,,,,,,,,,,,,,,,,,,,,,,,,,,,,,,,,,
,3832422502.32091,186.343734741211,9999.7802734375,0.00047489392938761,4.73896933727142E-8,1,2,13.4005146026611,5.00283287243571,32.6200015842915,0.633254367446066,0.0939759749204406,1,3.9917161382743E-6,,,,,,,,,,,,,,,,,,,,,186.293594360352,186.39387512207,9999.7802734375,9999.7802734375,47.3346414961012,5.27402822475628,7.75327253341675,27,1,0,0,1,0.283355712890625,40.0782012939453,2,1,1,186.293594360352,0,186.343734741211,,,,,,,,,,,,,,,,,,,,,,,,,,,,,,,,,
,3832422554.7476,183.784873962402,9999.7802734375,0.000482234016388123,6.06601755019318E-8,1,2,13.4005146026611,5.00285722791601,32.600000500679,0.643051361803809,0.0953936298874002,1,4.02682353107183E-6,,,,,,,,,,,,,,,,,,,,,183.739837646484,183.82991027832,9999.7802734375,9999.7802734375,47.3721596650242,5.27366348136968,7.7379846572876,27,1,0,0,1,0.28472900390625,39.5894432067871,2,1,1,183.739837646484,0,183.784873962402,,,,,,,,,,,,,,,,,,,,,,,,,,,,,,,,,
,3832422607.06997,181.131019592285,9999.7802734375,0.000489563794380712,4.88961155167829E-8,1,2,13.4005146026611,5.00282505344242,32.600000500679,0.652796038380924,0.0970123811281859,1,4.21510961278938E-6,,,,,,,,,,,,,,,,,,,,,181.096755981445,181.165283203125,9999.7802734375,9999.7802734375,47.4128043480242,5.27383048760318,7.72872304916382,27,1,0,0,1,0.283584594726562,40.0782012939453,2,1,1,181.096755981445,0,181.131019592285,,,,,,,,,,,,,,,,,,,,,,,,,,,,,,,,,
,3832422661.45792,178.415176391602,9999.7802734375,0.00049765441959245,4.78035734119579E-8,1,2,13.4005146026611,5.00266630790699,32.5799994170666,0.66356393337762,0.0985507726984888,1,4.23939564674749E-6,,,,,,,,,,,,,,,,,,,,,178.357635498047,178.472717285156,9999.7802734375,9999.7802734375,47.3674698939089,5.27380052880563,7.72014713287353,27,1,0,0,1,0.284957885742187,39.5894432067871,2,1,1,178.357635498047,0,178.415176391602,,,,,,,,,,,,,,,,,,,,,,,,,,,,,,,,,
,3832422715.86224,175.702819824219,9999.7802734375,0.000505694579627834,4.79116053540281E-8,1,2,13.4005146026611,5.00262135266051,32.5900018215179,0.67427688957205,0.100137208048509,1,4.3044939115886E-6,,,,,,,,,,,,,,,,,,,,,175.659210205078,175.746429443359,9999.7802734375,9999.7802734375,47.4315634324858,5.27410479871909,7.72306394577026,27,1,0,0,1,0.283050537109375,39.5894432067871,2,1,1,175.659210205078,0,175.702819824219,,,,,,,,,,,,,,,,,,,,,,,,,,,,,,,,,
,3832422769.52926,173.005859375,9999.7802734375,0.000514161209201589,1.44123612307445E-7,1,2,13.4005146026611,5.00259746663308,32.5599983334541,0.685568430838638,0.101763834429884,1,4.33965945691473E-6,,,,,,,,,,,,,,,,,,,,,172.924331665039,173.087387084961,9999.7802734375,9999.7802734375,47.3819300215146,5.27429013234663,7.72839069366455,27,1,0,0,1,0.284957885742187,39.5894432067871,2,1,1,172.924331665039,0,173.005859375,,,,,,,,,,,,,,,,,,,,,,,,,,,,,,,,,
,3832422820.78743,170.448112487793,9999.7802734375,0.000522097142994672,6.17374560951905E-8,1,2,13.4005146026611,5.00248674943201,32.5700007379055,0.696128324332935,0.103335574517528,1,4.40976681054867E-6,,,,,,,,,,,,,,,,,,,,,170.400573730469,170.495651245117,9999.7802734375,9999.7802734375,47.4026431772743,5.2747530724131,7.72398376464844,27,1,0,0,1,0.284576416015625,39.5894432067871,2,1,1,170.400573730469,0,170.448112487793,,,,,,,,,,,,,,,,,,,,,,,,,,,,,,,,,
,3832422873.02623,167.834762573242,9999.7802734375,0.000530770877708979,5.77003782377731E-8,1,2,13.4005146026611,5.00240888772857,32.5499996542931,0.707695115395336,0.104929198064266,1,4.39247241232908E-6,,,,,,,,,,,,,,,,,,,,,167.785598754883,167.883926391602,9999.7802734375,9999.7802734375,47.3502740664858,5.27543050119133,7.71384763717651,27,1,0,0,1,0.285263061523438,39.5894432067871,2,1,1,167.785598754883,0,167.834762573242,,,,,,,,,,,,,,,,,,,,,,,,,,,,,,,,,
,3832422925.73728,165.173599243164,9999.7802734375,0.000539562213986826,5.65463110475115E-8,1,2,13.4005146026611,5.00247084618313,32.540000975132,0.719413086092652,0.106783502137492,1,4.55101472346282E-6,,,,,,,,,,,,,,,,,,,,,165.142196655273,165.205001831055,9999.7802734375,9999.7802734375,47.3115834547839,5.27503760973356,7.71276187896729,27,1,0,0,1,0.28594970703125,39.5894432067871,2,1,1,165.142196655273,0,165.173599243164,,,,,,,,,,,,,,,,,,,,,,,,,,,,,,,,,
,3832422978.02927,162.607597351074,9999.7802734375,0.000548712808004477,5.66176458019174E-8,1,2,13.4005146026611,5.00216657997205,32.5199998915195,0.731522333573361,0.108804341492056,1,4.79219510571534E-6,,,,,,,,,,,,,,,,,,,,,162.535339355469,162.67985534668,9999.7802734375,9999.7802734375,47.1908218485627,5.27590548586909,7.70442581176758,27,1,0,0,1,0.284652709960938,39.5894432067871,2,1,1,162.535339355469,0,162.607597351074,,,,,,,,,,,,,,,,,,,,,,,,,,,,,,,,,
,3832423030.17502,159.978088378906,9999.7802734375,0.000557920119639309,5.41955210604873E-8,1,2,13.4005146026611,5.00268183629671,32.5299985706806,0.743928113840984,0.1104587815664,1,4.73262718409586E-6,,,,,,,,,,,,,,,,,,,,,159.92236328125,160.033813476562,9999.7802734375,9999.7802734375,47.3397220814762,5.27382593131763,7.70026683807373,27,1,0,0,1,0.279388427734375,39.5894432067871,2,1,1,159.92236328125,0,159.978088378906,,,,,,,,,,,,,,,,,,,,,,,,,,,,,,,,,
,3832423080.71895,157.491325378418,9999.7802734375,0.00056738476121233,5.0713820685546E-8,1,2,13.4005146026611,5.00263833661794,32.4999988079071,0.756512844086998,0.112519947553628,1,4.95423655602832E-6,,,,,,,,,,,,,,,,,,,,,157.457061767578,157.525588989258,9999.7802734375,9999.7802734375,47.3455842953704,5.2742513770765,7.68501663208008,27,1,0,0,1,0.28533935546875,39.5894432067871,2,1,1,157.457061767578,0,157.491325378418,,,,,,,,,,,,,,,,,,,,,,,,,,,,,,,,,
,3832423132.97972,154.844635009766,9999.7802734375,0.000577189937779828,6.16121566276766E-8,1,2,13.4005146026611,5.00261659459544,32.4999988079071,0.76956592826442,0.11457752053409,1,5.12506629099545E-6,,,,,,,,,,,,,,,,,,,,,154.791229248047,154.898040771484,9999.7802734375,9999.7802734375,47.3084569407069,5.27440565020338,7.67022752761841,27,1,0,0,1,0.284805297851562,39.5894432067871,2,1,1,154.791229248047,0,154.844635009766,,,,,,,,,,,,,,,,,,,,,,,,,,,,,,,,,
,3832423185.31377,152.238578796387,9999.7802734375,0.000587397181922512,6.82380057045249E-8,1,2,13.4005146026611,5.00253443624546,32.4999988079071,0.783186731799614,0.116392959604422,1,5.05975631587766E-6,,,,,,,,,,,,,,,,,,,,,152.198822021484,152.278335571289,9999.7802734375,9999.7802734375,47.2662490006685,5.27419360814054,7.66233968734741,27,1,0,0,1,0.285720825195313,39.5894432067871,2,1,1,152.198822021484,0,152.238578796387,,,,,,,,,,,,,,,,,,,,,,,,,,,,,,,,,
,3832423237.93553,149.633392333984,9999.7802734375,0.000598158034769576,4.86662618764693E-8,1,2,13.4005146026611,5.00253660858809,32.480001449585,0.797518843503764,0.118639668804636,1,5.23812544371339E-6,,,,,,,,,,,,,,,,,,,,,149.60986328125,149.656921386719,9999.7802734375,9999.7802734375,47.3006406555146,5.27428489235765,7.66368532180786,27,1,0,0,1,0.285720825195313,39.1006851196289,2,1,1,149.60986328125,0,149.633392333984,,,,,,,,,,,,,,,,,,,,,,,,,,,,,,,,,
,3832423292.21267,146.916030883789,9999.7802734375,0.000609404605344655,6.16531105011233E-8,1,2,13.4005146026611,5.00254692390815,32.480001449585,0.812532263433828,0.120754996585767,1,5.24995876636733E-6,,,,,,,,,,,,,,,,,,,,,146.883483886719,146.948577880859,9999.7802734375,9999.7802734375,47.2650765578896,5.27384173172767,7.64564943313599,27,1,0,0,1,0.277099609375,39.1006851196289,2,1,1,146.883483886719,0,146.916030883789,,,,,,,,,,,,,,,,,,,,,,,,,,,,,,,,,
,3832423344.47006,144.304931640625,9999.7802734375,0.000621059246908768,7.25627349753751E-8,1,2,13.4005146026611,5.00250938231474,32.4699990451336,0.828065264988486,0.123047970670676,1,5.33900744761502E-6,,,,,,,,,,,,,,,,,,,,,144.243591308594,144.366271972656,9999.7802734375,9999.7802734375,47.2873529706877,5.27429345455282,7.64958572387695,27,1,0,0,1,0.284957885742187,39.1006851196289,2,1,1,144.243591308594,0,144.304931640625,,,,,,,,,,,,,,,,,,,,,,,,,,,,,,,,,
,3832423398.96428,141.587814331055,9999.7802734375,0.000633101663893314,5.8347172735713E-8,1,2,13.4005146026611,5.0024699166294,32.4600003659725,0.844101034136197,0.125514132446679,1,5.50365960079631E-6,,,,,,,,,,,,,,,,,,,,,141.548599243164,141.627029418945,9999.7802734375,9999.7802734375,47.2662490006685,5.27420937791716,7.63663578033447,25,1,64,0,0,0.285491943359375,39.1006851196289,2,1,1,141.548599243164,0,141.587814331055,,,,,,,,,,,,,,,,,,,,,,,,,,,,,,,,,
,3832423463.38086,138.323371887207,9999.7802734375,0.000648407598229256,6.28499572826449E-8,1,2,13.4005146026611,5.0024336783521,32.4399992823601,0.864487626776065,0.128632532209006,1,5.70056514463692E-6,,,,,,,,,,,,,,,,,,,,,138.270385742188,138.376358032227,9999.7802734375,9999.7802734375,47.2650765578896,5.2747039531291,7.61111450195313,27,1,0,0,1,0.286178588867187,39.1006851196289,2,1,1,138.270385742188,0,138.323371887207,,,,,,,,,,,,,,,,,,,,,,,,,,,,,,,,,
,3832423513.87651,135.835578918457,9999.7802734375,0.000660404458789749,8.84300046228868E-8,1,2,13.4005146026611,5.00240438653106,32.4399992823601,0.880478670735039,0.130987724389906,1,5.78826632946707E-6,,,,,,,,,,,,,,,,,,,,,135.784698486328,135.886459350586,9999.7802734375,9999.7802734375,47.3182272971973,5.27463448747051,7.6097559928894,27,1,0,0,1,0.285110473632813,39.1006851196289,2,1,1,135.784698486328,0,135.835578918457,,,,,,,,,,,,,,,,,,,,,,,,,,,,,,,,,
,3832423566.14494,133.225280761719,9999.7802734375,0.000673706470418665,8.5081075132914E-8,1,2,13.4005146026611,5.00243795580447,32.430000603199,0.898209504433501,0.133714644622515,1,5.97026090919588E-6,,,,,,,,,,,,,,,,,,,,,133.183029174805,133.267532348633,9999.7802734375,9999.7802734375,47.2752377286396,5.27404640666854,7.58200359344482,27,1,0,0,1,0.2850341796875,39.5894432067871,2,1,1,133.183029174805,0,133.225280761719,,,,,,,,,,,,,,,,,,,,,,,,,,,,,,,,,
,3832423626.59125,130.173431396484,9999.7802734375,0.000689901759145283,6.12762605030897E-8,1,2,13.4005146026611,5.00235015372132,32.4099995195866,0.919790640204606,0.136846439730549,1,6.05437741623556E-6,,,,,,,,,,,,,,,,,,,,,130.114837646484,130.232025146484,9999.7802734375,9999.7802734375,47.2916519275435,5.27426299089221,7.5825834274292,27,1,0,0,1,0.284881591796875,39.1006851196289,2,1,1,130.114837646484,0,130.173431396484,,,,,,,,,,,,,,,,,,,,,,,,,,,,,,,,,
,3832423676.98601,127.707153320312,9999.7802734375,0.000703324422222486,8.10421441135876E-8,1,2,13.4005146026611,5.00238204423886,32.4099995195866,0.93769373694734,0.139513284645435,1,6.17453563950856E-6,,,,,,,,,,,,,,,,,,,,,127.662719726563,127.751586914062,9999.7802734375,9999.7802734375,47.2005922050531,5.27435782115654,7.5435962677002,27,1,0,0,1,0.284423828125,39.5894432067871,2,1,1,127.662719726563,0,127.707153320312,,,,,,,,,,,,,,,,,,,,,,,,,,,,,,,,,
,3832423729.31541,125.03369140625,9999.7802734375,0.000718646401787008,8.03067623123492E-8,1,2,13.4005146026611,5.00235248068669,32.3899984359741,0.958112388760522,0.142560988599786,1,6.31620151065638E-6,,,,,,,,,,,,,,,,,,,,,124.980712890625,125.086669921875,9999.7802734375,9999.7802734375,47.2490531732454,5.27467051970891,7.52453136444092,27,1,0,0,1,0.285186767578125,39.1006851196289,2,1,1,124.980712890625,0,125.03369140625,,,,,,,,,,,,,,,,,,,,,,,,,,,,,,,,,
,3832423782.99461,122.36304473877,9999.7802734375,0.000734434131815383,8.67800750349572E-8,1,2,13.4005146026611,5.00233229723536,32.3899984359741,0.979162691964415,0.145640419195291,1,6.41627035658016E-6,,,,,,,,,,,,,,,,,,,,,122.283348083496,122.442741394043,9999.7802734375,9999.7802734375,47.3483199951877,5.27466169575787,7.51745319366455,27,1,0,0,1,0.284194946289062,39.1006851196289,2,1,1,122.283348083496,0,122.36304473877,,,,,,,,,,,,,,,,,,,,,,,,,,,,,,,,,
,3832423836.18457,119.711463928223,9999.7802734375,0.000750284539974096,6.62047998690804E-8,1,2,13.4005146026611,5.00234078453292,32.3899984359741,1.00029111429018,0.148826786276677,1,6.58683822197867E-6,,,,,,,,,,,,,,,,,,,,,119.664962768555,119.757965087891,9999.7802734375,9999.7802734375,47.35613628038,5.27458587481328,7.49843692779541,27,1,0,0,1,0.278396606445313,39.1006851196289,2,1,1,119.664962768555,0,119.711463928223,,,,,,,,,,,,,,,,,,,,,,,,,,,,,,,,,
,3832423886.456,117.226070404053,9999.7802734375,0.000766937040148986,9.24371454780173E-8,1,2,13.4005146026611,5.00230161817494,32.370001077652,1.02244066834303,0.152420633137825,1,6.95199432204597E-6,,,,,,,,,,,,,,,,,,,,,117.171882629395,117.280258178711,9999.7802734375,9999.7802734375,47.2306849030435,5.27507362100377,7.48408365249634,27,1,0,0,1,0.285415649414062,39.1006851196289,2,1,1,117.171882629395,0,117.226070404053,,,,,,,,,,,,,,,,,,,,,,,,,,,,,,,,,
,3832423937.18541,114.638938903809,9999.7802734375,0.000783455022749182,8.46380397004383E-8,1,2,13.4005146026611,5.00232047969877,32.379999756813,1.04447168517046,0.155670516425523,1,7.07648138304269E-6,,,,,,,,,,,,,,,,,,,,,114.575820922852,114.702056884766,9999.7802734375,9999.7802734375,47.2592143439954,5.27521547763576,7.46858644485474,27,1,0,0,1,0.28472900390625,39.1006851196289,2,1,1,114.575820922852,0,114.638938903809,,,,,,,,,,,,,,,,,,,,,,,,,,,,,,,,,
,3832423989.24124,112.064121246338,9999.7802734375,0.000801391429669176,1.01470955096411E-7,1,2,13.4005146026611,5.00228130046119,32.370001077652,1.06835817661396,0.159334128948999,1,7.31445522611661E-6,,,,,,,,,,,,,,,,,,,,,112.009567260742,112.118675231934,9999.7802734375,9999.7802734375,47.2588235297358,5.27504814309685,7.4418683052063,27,1,0,0,1,0.28656005859375,39.1006851196289,2,1,1,112.009567260742,0,112.064121246338,,,,,,,,,,,,,,,,,,,,,,,,,,,,,,,,,
,3832424041.59681,109.482913970947,9999.7802734375,0.000820994929394154,8.72802853669949E-8,1,2,13.4005146026611,5.00221510945143,32.3499999940395,1.09448457791883,0.163141367346721,1,7.42789471977082E-6,,,,,,,,,,,,,,,,,,,,,109.429428100586,109.536399841309,9999.7802734375,9999.7802734375,47.1771433494761,5.27568823572307,7.43046426773071,27,1,0,0,1,0.285415649414062,39.1006851196289,2,1,1,109.429428100586,0,109.482913970947,,,,,,,,,,,,,,,,,,,,,,,,,,,,,,,,,
,3832424096.35153,106.744640350342,9999.7802734375,0.000841478528474031,1.17776671836599E-7,1,2,13.4005146026611,5.0022182424486,32.3499999940395,1.12181235915484,0.167070743013866,1,7.5075105837969E-6,,,,,,,,,,,,,,,,,,,,,106.716384887695,106.772895812988,9999.7802734375,9999.7802734375,47.2334206028608,5.27536405178777,7.4026198387146,27,1,0,0,1,0.286483764648438,39.1006851196289,2,1,1,106.716384887695,0,106.744640350342,,,,,,,,,,,,,,,,,,,,,,,,,,,,,,,,,
,3832424172.55279,102.931156158447,9999.7802734375,0.000872423567589824,1.00664133203873E-7,1,2,13.4005146026611,5.00218651149871,32.3400013148785,1.16301630275496,0.173500469528965,1,7.99881208129188E-6,,,,,,,,,,,,,,,,,,,,,102.872314453125,102.98999786377,9999.7802734375,9999.7802734375,47.1142222536781,5.27522963252511,7.38283824920654,27,1,0,0,1,0.284957885742187,39.1006851196289,2,1,1,102.872314453125,0,102.931156158447,,,,,,,,,,,,,,,,,,,,,,,,,,,,,,,,,
,3832424231.31543,99.9957847595215,9999.7802734375,0.000897704956068846,1.06028313290351E-7,1,2,13.4005146026611,5.0022352538063,32.3299989104271,1.1967291900637,0.178568881304353,1,8.25927925531969E-6,,,,,,,,,,,,,,,,,,,,,99.9476852416992,100.043884277344,9999.7802734375,9999.7802734375,47.3299517249858,5.27491994943778,7.37105703353882,25,1,64,0,0,0.281600952148438,39.1006851196289,2,1,1,99.9476852416992,0,99.9957847595215,,,,,,,,,,,,,,,,,,,,,,,,,,,,,,,,,
,3832424283.3954,97.411994934082,9999.7802734375,0.000921723031841091,9.22869189366596E-8,1,2,13.4005146026611,5.00219982869336,32.320000231266,1.22874212851846,0.183299066931262,1,8.44606061410816E-6,,,,,,,,,,,,,,,,,,,,,97.3482513427734,97.4757385253906,9999.7802734375,9999.7802734375,47.1310272668415,5.27539655298848,7.35446548461914,27,1,0,0,1,0.278167724609375,39.1006851196289,2,1,1,97.3482513427734,0,97.411994934082,,,,,,,,,,,,,,,,,,,,,,,,,,,,,,,,,
,3832424333.91381,94.8626441955566,9999.7802734375,0.00094541791116821,7.62795124692989E-8,1,2,13.4005146026611,5.00227717056137,32.320000231266,1.26036696650692,0.187938556963895,1,8.60581027740591E-6,,,,,,,,,,,,,,,,,,,,,94.8207244873047,94.9045639038086,9999.7802734375,9999.7802734375,47.24436340213,5.27441694884714,7.33695697784424,27,1,0,0,1,0.286483764648438,39.1006851196289,2,1,1,94.8207244873047,0,94.8626441955566,,,,,,,,,,,,,,,,,,,,,,,,,,,,,,,,,
,3832424384.16823,92.3768463134766,9999.7802734375,0.000970980908461008,1.00589440867289E-7,1,2,13.4005146026611,5.00217899827747,32.3100015521049,1.29439763667522,0.193111020060183,1,8.91042754379107E-6,,,,,,,,,,,,,,,,,,,,,92.3234024047852,92.430290222168,9999.7802734375,9999.7802734375,47.2818815710531,5.27453515557188,7.32362127304077,27,1,0,0,1,0.2789306640625,39.1006851196289,2,1,1,92.3234024047852,0,92.3768463134766,,,,,,,,,,,,,,,,,,,,,,,,,,,,,,,,,
,3832424444.82788,89.3016624450684,9999.7802734375,0.00100402228518875,1.01124218562953E-7,1,2,13.4005146026611,5.00203808013548,32.2900004684925,1.33840137303844,0.199614263255498,1,9.16838072125402E-6,,,,,,,,,,,,,,,,,,,,,89.2674179077148,89.3359069824219,9999.7802734375,9999.7802734375,47.2416277023127,5.27582577012702,7.30569219589233,27,1,0,0,1,0.2850341796875,39.1006851196289,2,1,1,89.2674179077148,0,89.3016624450684,,,,,,,,,,,,,,,,,,,,,,,,,,,,,,,,,
,3832424494.94811,86.8405570983887,9999.7802734375,0.00103216014935578,1.31561098276554E-7,1,2,13.4005146026611,5.00212158018989,32.2900004684925,1.37587544618694,0.205686899822147,1,9.78024132825913E-6,,,,,,,,,,,,,,,,,,,,,86.7981414794922,86.8829727172852,9999.7802734375,9999.7802734375,47.24436340213,5.2756695736621,7.28278255462647,27,1,0,0,1,0.284881591796875,38.6119270324707,2,1,1,86.7981414794922,0,86.8405570983887,,,,,,,,,,,,,,,,,,,,,,,,,,,,,,,,,
,3832424553.68008,83.8415260314941,9999.7802734375,0.00106675499266058,1.0621046556944E-7,1,2,13.4005146026611,5.00216518589196,32.2900004684925,1.42204884956475,0.212287936117758,1,9.88666681051183E-6,,,,,,,,,,,,,,,,,,,,,83.7776336669922,83.9054183959961,9999.7802734375,9999.7802734375,47.2893070419858,5.2756731613162,7.2676157951355,27,1,0,0,1,0.286102294921875,39.1006851196289,2,1,1,83.7776336669922,0,83.8415260314941,,,,,,,,,,,,,,,,,,,,,,,,,,,,,,,,,
,3832424615.08493,80.8053779602051,9999.7802734375,0.00110775744799025,1.31101360511507E-7,1,2,13.4005146026611,5.00204245666594,32.2699993848801,1.47657746243846,0.221016356765807,1,1.06983626166315E-5,,,,,,,,,,,,,,,,,,,,,80.7175369262695,80.8932189941406,9999.7802734375,9999.7802734375,47.3627801227935,5.27547763306207,7.25719547271729,27,1,0,0,1,0.280838012695313,39.1006851196289,2,1,1,80.7175369262695,0,80.8053779602051,,,,,,,,,,,,,,,,,,,,,,,,,,,,,,,,,
,3832424676.26525,77.7425422668457,9999.7802734375,0.00114898796667466,1.16149650093398E-7,1,2,13.4005146026611,5.00204629676118,32.2699993848801,1.53158637378329,0.228889662225491,1,1.0831992901573E-5,,,,,,,,,,,,,,,,,,,,,77.7035675048828,77.7815170288086,9999.7802734375,9999.7802734375,47.18339637763,5.27565698130807,7.23532485961914,27,1,0,0,1,0.281448364257813,39.1006851196289,2,1,1,77.7035675048828,0,77.7425422668457,,,,,,,,,,,,,,,,,,,,,,,,,,,,,,,,,
,3832424728.7236,75.0961799621582,9999.7802734375,0.00118714530089798,1.41908431433391E-7,1,2,13.4005146026611,5.00200961526574,32.2699993848801,1.58242733644508,0.236534386691622,1,1.12260189965155E-5,,,,,,,,,,,,,,,,,,,,,75.0594100952148,75.1329498291016,9999.7802734375,9999.7802734375,47.1599475220531,5.27568069498666,7.21190309524536,27,1,0,0,1,0.286788940429687,38.6119270324707,2,1,1,75.0594100952148,0,75.0961799621582,,,,,,,,,,,,,,,,,,,,,,,,,,,,,,,,,
,3832424798.85095,71.5752716064453,9999.7802734375,0.00124322297140762,1.60263839826955E-7,1,2,13.4005146026611,5.00190990146198,32.2499983012676,1.65712556770316,0.247746229731174,1,1.17902679750528E-5,,,,,,,,,,,,,,,,,,,,,71.5752716064453,71.5752716064453,9999.7802734375,9999.7802734375,47.1998105765338,5.27596409422786,7.17736005783081,27,1,0,0,1,0.271530151367187,39.1006851196289,2,1,1,71.5752716064453,0,71.5752716064453,,,,,,,,,,,,,,,,,,,,,,,,,,,,,,,,,
,3832424861.66793,68.4210929870605,9999.7802734375,0.00129889664302227,2.22009499687711E-7,1,2,13.4005146026611,5.00181984990111,32.2499983012676,1.73127140037985,0.258980702863636,1,1.2427906160863E-5,,,,,,,,,,,,,,,,,,,,,68.3633575439453,68.4788284301758,9999.7802734375,9999.7802734375,47.1927759198608,5.27637681863624,7.16314840316772,27,1,0,0,1,0.285110473632813,39.1006851196289,2,1,1,68.3633575439453,0,68.4210929870605,,,,,,,,,,,,,,,,,,,,,,,,,,,,,,,,,
,3832424932.31051,64.8407096862793,9999.7802734375,0.00136661994267386,1.66392185458313E-7,1,2,13.4005146026611,5.00191686684799,32.2499983012676,1.82208256635674,0.268944348326536,10,1.0418653627982E-5,,,,,,,,,,,,,,,,,,,,,64.8071517944336,64.874267578125,9999.7802734375,9999.7802734375,47.1939483626396,5.27534305914177,7.14101791381836,27,1,0,0,1,0.287094116210938,39.1006851196289,2,1,1,64.8071517944336,0,64.8407096862793,,,,,,,,,,,,,,,,,,,,,,,,,,,,,,,,,
,3832424984.59203,62.2500667572022,9999.7802734375,0.00142123982355649,1.92733857468476E-7,1,2,13.4005146026611,5.00183813055762,32.2499983012676,1.89487050550139,0.279649090954122,10,1.08064602626066E-5,,,,,,,,,,,,,,,,,,,,,62.205078125,62.2950553894043,9999.7802734375,9999.7802734375,47.2521796873223,5.27513972531979,7.12006187438965,27,1,0,0,1,0.279388427734375,39.1006851196289,2,1,1,62.205078125,0,62.2500667572022,,,,,,,,,,,,,,,,,,,,,,,,,,,,,,,,,
,3832425036.92913,59.6013965606689,9999.7802734375,0.00165864030560648,0.000163994839482217,1,2,13.4005146026611,5.0020304317179,32.2300009429455,2.21405198183447,0.308136848102264,10,-1.05501908186023E-6,,,,,,,,,,,,,,,,,,,,,59.547176361084,59.6556167602539,9999.7802734375,9999.7802734375,47.1712811355819,5.27493634963861,7.0871639251709,27,1,0,0,1,0.286102294921875,39.1006851196289,2,1,1,59.547176361084,0,59.6013965606689,,,,,,,,,,,,,,,,,,,,,,,,,,,,,,,,,
,3832425087.5557,57.0687294006348,9999.7802734375,0.00154523329385841,2.25779058224864E-7,1,2,13.4005146026611,5.00195106373244,32.2300009429455,2.06020145723361,0.304393593148898,10,1.20022150414311E-5,,,,,,,,,,,,,,,,,,,,,57.007999420166,57.1294593811035,9999.7802734375,9999.7802734375,47.0798305988319,5.27477345024788,7.04736185073853,27,1,0,0,1,0.279617309570313,38.6119270324707,2,1,1,57.007999420166,0,57.0687294006348,,,,,,,,,,,,,,,,,,,,,,,,,,,,,,,,,
,3832425141.84708,54.3076152801514,9999.7802734375,0.00161853980642222,1.64297737820084E-7,1,2,13.4005146026611,5.00182499691707,32.2300009429455,2.15785408384594,0.318893050597912,10,1.26239729397925E-5,,,,,,,,,,,,,,,,,,,,,54.2490768432617,54.366153717041,9999.7802734375,9999.7802734375,47.320572182755,5.27541142928262,7.01167869567871,27,1,0,0,1,0.280303955078125,38.6119270324707,2,1,1,54.2490768432617,0,54.3076152801514,,,,,,,,,,,,,,,,,,,,,,,,,,,,,,,,,
,3832425194.06074,51.6951675415039,9999.7802734375,0.00169633468517493,2.6213553885874E-7,1,2,13.4005146026611,5.00200692558016,32.2300009429455,2.26165375667667,0.334450519943019,10,1.33905406596102E-5,,,,,,,,,,,,,,,,,,,,,51.6577224731445,51.7326126098633,9999.7802734375,9999.7802734375,47.1837871918896,5.27409934892804,6.96422863006592,27,1,0,0,1,0.280609130859375,38.6119270324707,2,1,1,51.6577224731445,0,51.6951675415039,,,,,,,,,,,,,,,,,,,,,,,,,,,,,,,,,
,3832425254.67238,48.6660823822022,9999.7802734375,0.00179929124224837,1.79571691581419E-7,1,2,13.4005146026611,5.00215213329928,32.209999859333,2.39902525988084,0.354703203023292,10,1.41580139589118E-5,,,,,,,,,,,,,,,,,,,,,48.6313362121582,48.7008285522461,9999.7802734375,9999.7802734375,47.1134406251588,5.27405379931768,6.92702102661133,27,1,0,0,1,0.286102294921875,38.6119270324707,2,1,1,48.6313362121582,0,48.6660823822022,,,,,,,,,,,,,,,,,,,,,,,,,,,,,,,,,
,3832425325.1343,45.0788421630859,9999.7802734375,0.00189963069742252,3.49466714757451E-5,1,2,13.4005146026611,5.00239003600297,32.209999859333,2.53528305095251,0.35799630077789,10,2.57806368853326E-6,,,,,,,,,,,,,,,,,,,,,45.028507232666,45.1291770935059,9999.7802734375,9999.7802734375,47.1896494057838,5.27220003306745,6.85346698760986,27,1,0,0,1,0.285263061523438,38.6119270324707,2,1,1,45.028507232666,0,45.0788421630859,,,,,,,,,,,,,,,,,,,,,,,,,,,,,,,,,
,3832425383.66,42.1439380645752,9999.7802734375,0.00205852003557885,3.17986482827786E-7,1,2,13.4005146026611,5.00231008645463,32.209999859333,2.74473380709307,0.40613949655732,10,1.64343075737218E-5,,,,,,,,,,,,,,,,,,,,,42.1101913452148,42.1776847839355,9999.7802734375,9999.7802734375,47.2662490006685,5.27267807165785,6.80230093002319,27,1,0,0,1,0.277557373046875,38.1231689453125,2,1,1,42.1101913452148,0,42.1439380645752,,,,,,,,,,,,,,,,,,,,,,,,,,,,,,,,,
,3832425433.85003,39.6214218139648,9999.7802734375,0.00218229135191496,3.12153208599455E-7,1,2,13.4005146026611,5.00233547326786,32.209999859333,2.90970550644838,0.431129737227163,10,1.78476294272525E-5,,,,,,,,,,,,,,,,,,,,,39.5733642578125,39.6694793701172,9999.7802734375,9999.7802734375,47.23420223138,5.27208458807015,6.75582265853882,27,1,0,0,1,0.286331176757813,38.1231689453125,2,1,1,39.5733642578125,0,39.6214218139648,,,,,,,,,,,,,,,,,,,,,,,,,,,,,,,,,
,3832425486.53655,36.9608097076416,9999.7802734375,0.00232808268108329,4.29397808724956E-7,1,2,13.4005146026611,5.00243034251088,32.209999859333,3.10422622427747,0.459566163143949,10,1.87569526035808E-5,,,,,,,,,,,,,,,,,,,,,36.9276657104492,36.993953704834,9999.7802734375,9999.7802734375,47.1564301937165,5.27191302072957,6.68316841125488,27,1,0,0,1,0.285720825195313,38.1231689453125,2,1,1,36.9276657104492,0,36.9608097076416,,,,,,,,,,,,,,,,,,,,,,,,,,,,,,,,,
,3832425554.71208,33.57057762146,9999.7802734375,0.00255680012531433,3.98749793414812E-7,1,2,13.4005146026611,5.00244465448056,32.200001180172,3.40881304231288,0.507538768446549,10,2.27133776480682E-5,,,,,,,,,,,,,,,,,,,,,33.5287666320801,33.6123886108398,9999.7802734375,9999.7802734375,47.1458782087069,5.2719657680446,6.56968879699707,27,1,0,0,1,0.2789306640625,38.1231689453125,2,1,1,33.4969673156738,0,33.57057762146,,,,,,,,,,,,,,,,,,,,,,,,,,,,,,,,,
,3832425634.55142,29.5576725006103,9999.7802734375,0.00285602849457403,9.05723775212959E-5,1,2,13.4005146026611,5.0020905615668,32.1899987757206,3.78998522697571,0.691330136701309,10,0.000118607472615402,,,,,,,,,,,,,,,,,,,,,29.4674835205078,29.6478614807129,9999.7802734375,9999.7802734375,47.24436340213,5.27318746657617,6.42558145523071,27,1,0,0,1,0.286026000976562,38.1231689453125,2,1,1,29.4674835205078,0,29.5576725006103,,,,,,,,,,,,,,,,,,,,,,,,,,,,,,,,,
,3832425705.90073,25.9668970108032,9999.7802734375,0.00325078966398916,6.81746931642038E-7,1,2,13.4005146026611,5.00204197183333,32.1899987757206,4.3335050209662,0.645809036311216,10,2.93134576738154E-5,,,,,,,,,,,,,,,,,,,,,25.9336109161377,26.0001831054687,9999.7802734375,9999.7802734375,47.1619015933511,5.27351617754685,6.24779462814331,27,1,0,0,1,0.286102294921875,38.1231689453125,2,1,1,25.9336109161377,0,25.9668970108032,,,,,,,,,,,,,,,,,,,,,,,,,,,,,,,,,
,3832425784.46738,22.0411996841431,9999.7802734375,0.00384586457082763,5.24891213187281E-5,1,2,13.4005146026611,5.00184819009552,32.1899987757206,5.12685984861532,0.761450737600922,10,3.27788401754718E-5,,,,,,,,,,,,,,,,,,,,,21.9955883026123,22.0868110656738,9999.7802734375,9999.7802734375,47.0985896832934,5.27413006486639,5.97902965545654,27,1,0,0,1,0.286178588867187,38.1231689453125,2,1,1,21.9955883026123,0,22.0411996841431,,,,,,,,,,,,,,,,,,,,,,,,,,,,,,,,,
,3832425874.38807,17.5790224075317,9999.7802734375,0.00469197132552588,1.40911976263647E-6,1,2,13.4005146026611,5.00132680662177,32.1700014173985,6.25335068729395,0.932761744465864,10,4.29285928707726E-5,,,,,,,,,,,,,,,,,,,,,17.5062637329102,17.6517810821533,9999.7802734375,9999.7802734375,47.1876953344858,5.27640025986079,5.50259780883789,27,1,0,0,1,0.273590087890625,38.1231689453125,2,1,1,17.5062637329102,0,17.5790224075317,,,,,,,,,,,,,,,,,,,,,,,,,,,,,,,,,
,3832425953.92778,13.6834077835083,9999.7802734375,0.00587811531732303,1.93309845474333E-6,1,2,13.4005146026611,5.00156760683299,32.1700014173985,7.83440032244179,1.17101632401415,10,5.55589451982418E-5,,,,,,,,,,,,,,,,,,,,,13.6339778900146,13.732837677002,9999.7802734375,9999.7802734375,47.2478807304665,5.27573819563802,4.90274858474731,27,1,0,0,1,0.27313232421875,38.1231689453125,2,1,1,13.6339778900146,0,13.6834077835083,,,,,,,,,,,,,,,,,,,,,,,,,,,,,,,,,
,3832426026.27647,10.1982660293579,9999.7802734375,0.00762099342098243,3.22766800490811E-6,1,2,13.4005146026611,5.00159052637139,32.1700014173985,10.1574618294497,1.51769501195637,10,7.16273051049431E-5,,,,,,,,,,,,,,,,,,,,,10.1541013717651,10.2424306869507,9999.7802734375,9999.7802734375,47.1228201673896,5.27513590093865,4.32987880706787,27,1,0,0,1,0.280838012695313,38.1231689453125,2,1,1,10.1541013717651,0,10.1982660293579,,,,,,,,,,,,,,,,,,,,,,,,,,,,,,,,,
,3832426084.85905,7.99792551994324,9999.7802734375,0.00924407272243464,6.0615456487185E-7,1,2,13.4005146026611,5.00153008063,32.1700014173985,12.3201307797075,1.84383026982817,10,8.90813128453508E-5,,,,,,,,,,,,,,,,,,,,,7.99791383743286,7.99793720245361,9999.7802734375,9999.7802734375,47.2017646478319,5.2748847484628,4.16358470916748,27,1,0,0,1,0.28076171875,38.1231689453125,5,1,1,7.99791383743286,0,7.99792551994324,,,,,,,,,,,,,,,,,,,,,,,,,,,,,,,,,
,3832426134.98403,7.99965596199036,9999.7802734375,0.00924283178973691,6.79661440497881E-7,1,2,13.4005146026611,5.00160151262416,32.1700014173985,12.3187099445333,1.84367393066938,10,8.91106774268145E-5,,,,,,,,,,,,,,,,,,,,,7.9996509552002,7.99966096878052,9999.7802734375,9999.7802734375,47.2603867867742,5.27495422634267,4.16432332992554,27,1,0,0,1,0.28045654296875,38.1231689453125,5,1,1,7.9996509552002,0,7.99965596199036,,,,,,,,,,,,,,,,,,,,,,,,,,,,,,,,,
,3832426137.12693,7.99952387809753,9999.7802734375,0.00924342182866724,1.05822348985684E-6,1,2,13.4005146026611,5.00154203275741,32.1700014173985,12.3193834390838,1.84313531050577,10,8.86470647103659E-5,,,,,,,,,,,,,,,,,,,,,7.99939680099487,7.9996509552002,9999.7802734375,9999.7802734375,47.2787550569762,5.27511999242431,4.14853525161743,27,1,0,0,1,0.280532836914062,38.1231689453125,1,1,1,7.99939680099487,0,7.99952387809753,,,,,,,,,,,,,,,,,,,,,,,,,,,,,,,,,