File: SI Fig S11-13 SQUID all/Michaela_Gd_ZFC1T.dat
[Header]
; MPMS3 Data File (default extension .dat)
; Copyright (c) 2007, Quantum Design, Inc. All rights reserved.
TITLE,
FILEOPENTIME,3832337553.59413,06/08/2021,6:12 pm
BYAPP,MPMS3 w/ AC,1.0,1.1
INFO,MPMS3 Measurement Release 1.1.16 Build 424, MultiVu Release 2.3.4.19,APPNAME
INFO,Linear Motor Servo Controller,MOTOR_MODULE_NAME
INFO,3101-100 E1,MOTOR_HW_VERSION
INFO,MMC211,MOTOR_SERIAL_NUMBER
INFO,01.04.28,MOTOR_SOFTWARE_VERSION
INFO,Quantum Design Squid Module,SQUID_MODULE_NAME
INFO,3101-501 B0,SQUID_HW_VERSION
INFO,SQM059,SQUID_SERIAL_NUMBER
INFO,01.03.04,SQUID_SOFTWARE_VERSION
INFO,SQUID AC,AC_MODULE_NAME
INFO,3101-401 F1,AC_HW_VERSION
INFO,SAC057,AC_SERIAL_NUMBER
INFO,SQUID AC 00.95.07,AC_SOFTWARE_VERSION
INFO,TCIXXX,COIL_SERIAL_NUMBER
INFO,0,MOMENT_UNITS
INFO,Michaela_Gd,SAMPLE_MATERIAL
INFO,Michaela_Gd,SAMPLE_COMMENT
INFO,0.9,SAMPLE_MASS
INFO,,SAMPLE_VOLUME
INFO,,SAMPLE_MOLECULAR_WEIGHT
INFO,,SAMPLE_SIZE
INFO,,SAMPLE_SHAPE
INFO,Straw,SAMPLE_HOLDER
INFO,Standard,SAMPLE_HOLDER_DETAIL
INFO,54.44,SAMPLE_OFFSET
DATATYPE,COMMENT,1
DATATYPE,TIME,2
STARTUPAXIS,X,2
STARTUPAXIS,Y1,5
FIELDGROUP, VSM,2,3,4,5,6,8,9,10,11,14,15
FIELDGROUP, DC, 2,3,4,14,56,57,58,59,60,61,62,63,64,65,66,67,68,69
FIELDGROUP, AC, 2,3,4,11,16,17,18,19,20,21,22,23,24,25,26,27,28,29,30
STARTUPGROUP, All
[Data]
Comment,Time Stamp (sec),Temperature (K),Magnetic Field (Oe),Moment (emu),M. Std. Err. (emu),Transport Action,Averaging Time (sec),Frequency (Hz),Peak Amplitude (mm),Center Position (mm),Lockin Signal' (V),Lockin Signal (V),Range,M. Quad. Signal (emu),AC Moment (emu),AC M. Std Err. (emu),AC Phase (deg),AC Phase Std. Err. (deg),AC Susceptibility (emu/Oe),AC Suscept. Std Err. (emu/Oe),AC X' (emu/Oe),AC X' Std Err. (emu/Oe),AC X'' (emu/Oe),AC X'' Std Err. (emu/Oe),AC Drive (Oe),AC Frequency (Hz),AC Averaging Time (sec),AC Cycles,AC Range,AC Measure Type,AC Signal' (V),AC Signal'' (V),AC Trim Coil Ratio,AC Trim Coil Phase,Min. Temperature (K),Max. Temperature (K),Min. Field (Oe),Max. Field (Oe),Mass (grams),Motor Lag (deg),Pressure (Torr),Measure Count,Measurement Number,SQUID Status (code),Motor Status (code),Measure Status (code),Motor Current (amps),Motor Temp. (C),Temp. Status (code),Field Status (code),Chamber Status (code),Chamber Temp (K),Redirection State,Average Temp (K),Rotation Angle (deg),Rotator state,DC Moment Fixed Ctr (emu),DC Moment Err Fixed Ctr (emu),DC Moment Free Ctr (emu),DC Moment Err Free Ctr (emu),DC Fixed Fit,DC Free Fit,DC Calculated Center (mm),DC Calculated Center Err (mm),DC Scan Length (mm),DC Scan Time (s),DC Number of Points,DC Squid Drift,DC Min V (V),DC Max V (V),DC Scans per Measure,Map 01,Map 02,Map 03,Map 04,Map 05,Map 06,Map 07,Map 08,Map 09,Map 10,Map 11,Map 12,Map 13,Map 14,Map 15,Map 16
,3832337576.64092,7.99885129928589,9999.8056640625,0.00933660232204454,1.48675525426188E-5,1,2,13.4005146026611,4.98617752107363,31.649999320507,12.3952336257143,1.825233760915,10,6.79820308773578E-5,,,,,,,,,,,,,,,,,,,,,7.99885129928589,7.99885129928589,9999.8056640625,9999.8056640625,46.997368790053,5.32227515151508,4.89921951293945,27,1,0,0,1,0.2838134765625,36.6568908691406,1,1,1,7.99885129928589,0,7.99885129928589,,,,,,,,,,,,,,,,,,,,,,,,,,,,,,,,,
,3832337632.81931,10.4715571403503,9999.8056640625,0.00714361907104773,3.35160407527043E-6,1,2,13.4005146026611,4.99417931225877,31.649999320507,9.50230434915918,1.41679950298755,10,6.49312994947364E-5,,,,,,,,,,,,,,,,,,,,,10.4212980270386,10.5218162536621,9999.8056640625,9999.8056640625,47.0610715143704,5.26461647684323,5.40254163742065,27,1,0,0,1,0.28564453125,38.1231689453125,6,1,1,10.5218162536621,0,10.4715571403503,,,,,,,,,,,,,,,,,,,,,,,,,,,,,,,,,
,3832337689.17746,13.1316089630127,9999.8056640625,0.00571259227345519,2.18054304635913E-6,1,2,13.4005146026611,4.99411752737649,31.649999320507,7.59886487364375,1.13143618364853,10,5.07772344006645E-5,,,,,,,,,,,,,,,,,,,,,13.0780935287476,13.1851243972778,9999.8056640625,9999.8056640625,47.1271191242454,5.26515150906325,5.7970380783081,27,1,0,0,1,0.27587890625,38.1231689453125,6,1,1,13.1851243972778,0,13.1316089630127,,,,,,,,,,,,,,,,,,,,,,,,,,,,,,,,,
,3832337745.58766,15.9088797569275,9999.8056640625,0.00473434950784994,1.66781400359634E-6,1,2,13.4005146026611,4.99403262050401,31.649999320507,6.29757523465364,0.936868018275681,10,4.14846475069473E-5,,,,,,,,,,,,,,,,,,,,,15.8686990737915,15.9490604400635,9999.8056640625,9999.8056640625,47.08178467013,5.26489447833198,6.10214471817017,27,1,0,0,1,0.276870727539062,38.1231689453125,2,1,1,15.9490604400635,0,15.9088797569275,,,,,,,,,,,,,,,,,,,,,,,,,,,,,,,,,
,3832337802.10585,18.6098318099976,9999.8056640625,0.00404947331552026,1.18470208342432E-6,1,2,13.4005146026611,4.99401397593318,31.649999320507,5.38658453549348,0.80097086054734,10,3.52095927797769E-5,,,,,,,,,,,,,,,,,,,,,18.5661373138428,18.6535263061523,9999.8056640625,9999.8056640625,47.0376226587934,5.26549448096992,6.32075071334839,27,1,0,0,1,0.286865234375,38.1231689453125,2,1,1,18.6535263061523,0,18.6098318099976,,,,,,,,,,,,,,,,,,,,,,,,,,,,,,,,,
,3832337866.66957,21.7134943008423,9999.8056640625,0.00347004598750616,8.67242571728407E-7,1,2,13.4005146026611,4.99403002916339,31.6600017249584,4.61606226979904,0.684877124693525,10,2.90541551536712E-5,,,,,,,,,,,,,,,,,,,,,21.6617469787598,21.7652416229248,9999.8056640625,9999.8056640625,47.0489562723223,5.26618140934935,6.53182363510132,27,1,0,0,1,0.284500122070313,38.1231689453125,2,1,1,21.7652416229248,0,21.7134943008423,,,,,,,,,,,,,,,,,,,,,,,,,,,,,,,,,
,3832337922.89919,24.4396600723267,9999.8056640625,0.00308100398714335,7.15833197169516E-7,1,2,13.4005146026611,4.99389772207029,31.6600017249584,4.09849358694975,0.607305431380051,10,2.52223005677984E-5,,,,,,,,,,,,,,,,,,,,,24.388090133667,24.4912300109863,9999.8056640625,9999.8056640625,47.0470022010242,5.26556761415164,6.69762086868286,27,1,0,0,1,0.284347534179687,38.1231689453125,2,1,1,24.4912300109863,0,24.4396600723267,,,,,,,,,,,,,,,,,,,,,,,,,,,,,,,,,
,3832337979.40052,27.1571245193481,9999.8056640625,0.00277005538717334,5.87852694604572E-7,1,2,13.4005146026611,4.99391931916265,31.6600017249584,3.68490802616823,0.545796620463633,10,2.2511496778111E-5,,,,,,,,,,,,,,,,,,,,,27.1005458831787,27.2137031555176,9999.8056640625,9999.8056640625,47.1193028390531,5.2668849692913,6.82178211212158,27,1,0,0,1,0.272293090820313,38.6119270324707,2,1,1,27.2137031555176,0,27.1571245193481,,,,,,,,,,,,,,,,,,,,,,,,,,,,,,,,,
,3832338035.71394,29.8774518966675,9999.8056640625,0.00251551272040632,4.2323948157479E-7,1,2,13.4005146026611,4.99389263355105,31.6600017249584,3.34634987243103,0.495098793704342,10,2.00370471637293E-5,,,,,,,,,,,,,,,,,,,,,29.8372497558594,29.9176540374756,9999.8056640625,9999.8056640625,47.0759224562358,5.26606676975492,6.94574785232544,27,1,0,0,1,0.285110473632813,38.1231689453125,2,1,1,29.9176540374756,0,29.8774518966675,,,,,,,,,,,,,,,,,,,,,,,,,,,,,,,,,
,3832338092.12471,32.6268787384033,9999.8056640625,0.00230253708771168,4.35742866698381E-7,1,2,13.4005146026611,4.99378979573424,31.6600017249584,3.0630286313159,0.452570920083166,10,1.78918751087406E-5,,,,,,,,,,,,,,,,,,,,,32.5839920043945,32.6697654724121,9999.8056640625,9999.8056640625,47.0935090979185,5.26673695338706,7.05188798904419,27,1,0,0,1,0.27587890625,38.6119270324707,2,1,1,32.6697654724121,0,32.6268787384033,,,,,,,,,,,,,,,,,,,,,,,,,,,,,,,,,
,3832338148.55065,35.3642711639404,9999.8056640625,0.00212173150288437,3.50067392134447E-7,1,2,13.4005146026611,4.99376745282913,31.6700004041195,2.82253426513547,0.416703304221242,10,1.62412637916736E-5,,,,,,,,,,,,,,,,,,,,,35.3132476806641,35.4152946472168,9999.8056640625,9999.8056640625,47.0759224562358,5.26681689940705,7.14775133132935,27,1,0,0,1,0.284500122070313,38.6119270324707,2,1,1,35.4152946472168,0,35.3642711639404,,,,,,,,,,,,,,,,,,,,,,,,,,,,,,,,,
,3832338204.98548,38.1092834472656,9999.8056640625,0.00196648264593973,2.77570230554889E-7,1,2,13.4005146026611,4.99373203854157,31.6600017249584,2.61604803422999,0.3857343840351,10,1.46964626887759E-5,,,,,,,,,,,,,,,,,,,,,38.0630149841309,38.1555519104004,9999.8056640625,9999.8056640625,47.0434848726877,5.26717714061903,7.22577285766602,27,1,0,0,1,0.27557373046875,38.6119270324707,2,1,1,38.1555519104004,0,38.1092834472656,,,,,,,,,,,,,,,,,,,,,,,,,,,,,,,,,
,3832338261.54075,40.8918113708496,9999.8056640625,0.00183121888483827,1.974551851205E-7,1,2,13.4005146026611,4.99368089110339,31.6700004041195,2.43611482990389,0.358875970491536,10,1.34446906144211E-5,,,,,,,,,,,,,,,,,,,,,40.8553199768066,40.9283027648926,9999.8056640625,9999.8056640625,47.0981988690338,5.26748638184938,7.28376388549805,27,1,0,0,1,0.295867919921875,38.6119270324707,2,1,1,40.9283027648926,0,40.8918113708496,,,,,,,,,,,,,,,,,,,,,,,,,,,,,,,,,
,3832338317.85487,43.6317901611328,9999.8056640625,0.00171322736841927,2.59836976757585E-7,1,2,13.4005146026611,4.9937094245513,31.6700004041195,2.27915554317524,0.335827679354442,10,1.26329597843216E-5,,,,,,,,,,,,,,,,,,,,,43.5931854248047,43.6703948974609,9999.8056640625,9999.8056640625,47.1048427114473,5.26734253697977,7.35989809036255,27,1,0,0,1,0.286788940429687,38.6119270324707,2,1,1,43.6703948974609,0,43.6317901611328,,,,,,,,,,,,,,,,,,,,,,,,,,,,,,,,,
,3832338374.26926,46.3570442199707,9999.8056640625,0.00160942118433867,2.41398677193947E-7,1,2,13.4005146026611,4.99358718399058,31.6700004041195,2.14101620320723,0.315262859983561,10,1.17127474858057E-5,,,,,,,,,,,,,,,,,,,,,46.3105621337891,46.4035263061523,9999.8056640625,9999.8056640625,47.1544761224185,5.26756456095975,7.40306329727173,27,1,0,0,1,0.28717041015625,38.6119270324707,2,1,1,46.4035263061523,0,46.3570442199707,,,,,,,,,,,,,,,,,,,,,,,,,,,,,,,,,
,3832338430.62591,49.1262493133545,9999.8056640625,0.00151700350908404,1.78783804988418E-7,1,2,13.4005146026611,4.9936210490557,31.6700004041195,2.01809775860218,0.297117816178179,10,1.10067589259246E-5,,,,,,,,,,,,,,,,,,,,,49.0813026428223,49.1711959838867,9999.8056640625,9999.8056640625,47.1763617209569,5.26790544254081,7.46283197402954,27,1,0,0,1,0.275955200195313,38.6119270324707,2,1,1,49.1711959838867,0,49.1262493133545,,,,,,,,,,,,,,,,,,,,,,,,,,,,,,,,,
,3832338487.14193,51.9222812652588,9999.8056640625,0.0014336988335782,2.22612847471983E-7,1,2,13.4005146026611,4.99361624775159,31.6900014877319,1.90727886340816,0.280763163749824,10,1.03735240106658E-5,,,,,,,,,,,,,,,,,,,,,51.8633918762207,51.9811706542969,9999.8056640625,9999.8056640625,47.127509938505,5.26772508783603,7.51905584335327,27,1,0,0,1,0.273056030273438,38.6119270324707,2,1,1,51.9811706542969,0,51.9222812652588,,,,,,,,,,,,,,,,,,,,,,,,,,,,,,,,,
,3832338543.45825,54.6553173065186,9999.8056640625,0.0013590668269681,1.31846097979034E-7,1,2,13.4005146026611,4.99359823432168,31.6799990832806,1.8080098437986,0.265972051234681,10,9.70247657636687E-6,,,,,,,,,,,,,,,,,,,,,54.6085662841797,54.7020683288574,9999.8056640625,9999.8056640625,47.0333237019377,5.26721153440317,7.57595014572144,27,1,0,0,1,0.2850341796875,38.6119270324707,2,1,1,54.7020683288574,0,54.6553173065186,,,,,,,,,,,,,,,,,,,,,,,,,,,,,,,,,
,3832338599.90698,57.4234352111816,9999.8056640625,0.00129160593373504,1.18068704240607E-7,1,2,13.4005146026611,4.99355746461447,31.6900014877319,1.71825503555522,0.25269700400151,10,9.16830929335876E-6,,,,,,,,,,,,,,,,,,,,,57.3839073181152,57.462963104248,9999.8056640625,9999.8056640625,47.1321997096204,5.26750122124764,7.60445261001587,27,1,0,0,1,0.274276733398438,38.6119270324707,2,1,1,57.462963104248,0,57.4234352111816,,,,,,,,,,,,,,,,,,,,,,,,,,,,,,,,,
,3832338656.28158,60.2226982116699,9999.8056640625,0.0012298936539718,1.07937754472566E-7,1,2,13.4005146026611,4.99346013215666,31.700000166893,1.63612101873774,0.240566501179898,10,8.69244740869642E-6,,,,,,,,,,,,,,,,,,,,,60.1754341125488,60.269962310791,9999.8056640625,9999.8056640625,47.1298548240627,5.2679029497471,7.64536380767822,27,1,0,0,1,0.274124145507813,38.6119270324707,2,1,1,60.269962310791,0,60.2226982116699,,,,,,,,,,,,,,,,,,,,,,,,,,,,,,,,,
,3832338716.81033,63.1997528076172,9999.8056640625,0.00116968956265954,1.8356219920534E-7,1,2,13.4005146026611,4.99351044682154,31.6900014877319,1.55553685023746,0.232487530749365,1,1.10408098660928E-5,,,,,,,,,,,,,,,,,,,,,63.1565856933594,63.242919921875,9999.8056640625,9999.8056640625,47.1310272668415,5.26796682089848,7.69502830505371,27,1,0,0,1,0.285263061523438,38.6119270324707,2,1,1,63.242919921875,0,63.1997528076172,,,,,,,,,,,,,,,,,,,,,,,,,,,,,,,,,
,3832338781.19139,66.3245277404785,9999.8056640625,0.00111170648928285,1.85332423397953E-7,1,2,13.4005146026611,4.99349954039149,31.6900014877319,1.47848424491174,0.220519748042877,1,1.01612734214348E-5,,,,,,,,,,,,,,,,,,,,,66.2708969116211,66.3781585693359,9999.8056640625,9999.8056640625,47.0946815406973,5.2686356359181,7.72149038314819,27,1,0,0,1,0.28533935546875,38.6119270324707,2,1,1,66.3781585693359,0,66.3245277404785,,,,,,,,,,,,,,,,,,,,,,,,,,,,,,,,,
,3832338837.61289,69.0993614196777,9999.8056640625,0.00106512343274074,1.12362604155065E-7,1,2,13.4005146026611,4.99346954170469,31.700000166893,1.41653999345802,0.211139719832601,1,9.63185542158808E-6,,,,,,,,,,,,,,,,,,,,,69.0514526367187,69.1472702026367,9999.8056640625,9999.8056640625,47.1064059684858,5.2688950560592,7.74744892120361,27,1,0,0,1,0.286865234375,38.6119270324707,2,1,1,69.1472702026367,0,69.0993614196777,,,,,,,,,,,,,,,,,,,,,,,,,,,,,,,,,
,3832338904.1026,72.4090957641602,9999.8056640625,0.00101515991628748,1.14033246526495E-7,1,2,13.4005146026611,4.99347605381107,31.700000166893,1.35011659728009,0.201077103177574,1,9.06086383444353E-6,,,,,,,,,,,,,,,,,,,,,72.353630065918,72.4645614624023,9999.8056640625,9999.8056640625,47.0638072141877,5.26857326153647,7.78648519515991,27,1,0,0,1,0.276336669921875,38.6119270324707,2,1,1,72.4645614624023,0,72.4090957641602,,,,,,,,,,,,,,,,,,,,,,,,,,,,,,,,,
,3832338960.52016,75.1701164245606,9999.8056640625,0.000975760273483296,1.42064608952445E-7,1,2,13.4005146026611,4.9934593323748,31.7099988460541,1.29772679381115,0.193158536347154,1,8.62387282937422E-6,,,,,,,,,,,,,,,,,,,,,75.108024597168,75.2322082519531,9999.8056640625,9999.8056640625,47.05130115788,5.26863765757071,7.81560373306274,27,1,0,0,1,0.296173095703125,38.6119270324707,2,1,1,75.2322082519531,0,75.1701164245606,,,,,,,,,,,,,,,,,,,,,,,,,,,,,,,,,
,3832339016.93129,77.9375686645508,9999.8056640625,0.000939303487644104,1.08853565502151E-7,1,2,13.4005146026611,4.99343482357723,31.7099988460541,1.2492409413599,0.185877545872192,1,8.25445341982393E-6,,,,,,,,,,,,,,,,,,,,,77.8917541503906,77.9833831787109,9999.8056640625,9999.8056640625,47.01065647488,5.26898433466406,7.84610652923584,27,1,0,0,1,0.286788940429687,38.6119270324707,2,1,1,77.9833831787109,0,77.9375686645508,,,,,,,,,,,,,,,,,,,,,,,,,,,,,,,,,
,3832339081.59855,81.1323699951172,9999.8056640625,0.000900682306702132,1.00938643315485E-7,1,2,13.4005146026611,4.99334210878903,31.7099988460541,1.19781189931299,0.178471626199746,1,8.09627906452199E-6,,,,,,,,,,,,,,,,,,,,,81.0944061279297,81.1703338623047,9999.8056640625,9999.8056640625,47.0325420734184,5.26924556681708,7.8699779510498,27,1,0,0,1,0.285491943359375,38.6119270324707,2,1,1,81.1703338623047,0,81.1323699951172,,,,,,,,,,,,,,,,,,,,,,,,,,,,,,,,,
,3832339137.80827,83.8853721618652,9999.8056640625,0.000869283045939892,7.85524322221235E-8,1,2,13.4005146026611,4.99343299955515,31.7200012505054,1.15610553699146,0.172093266400043,1,7.69324055183435E-6,,,,,,,,,,,,,,,,,,,,,83.8451385498047,83.9256057739258,9999.8056640625,9999.8056640625,47.1873045202262,5.26869780074846,7.88778734207153,27,1,0,0,1,0.272445678710938,38.6119270324707,2,1,1,83.9256057739258,0,83.8853721618652,,,,,,,,,,,,,,,,,,,,,,,,,,,,,,,,,
,3832339194.33623,86.7311477661133,9999.8056640625,0.000839907610138697,9.75494855120552E-8,1,2,13.4005146026611,4.99335963341041,31.7200012505054,1.11702010263918,0.16623865491088,1,7.40640586748111E-6,,,,,,,,,,,,,,,,,,,,,86.6908264160156,86.7714691162109,9999.8056640625,9999.8056640625,47.1282915670242,5.26850653775236,7.91072130203247,27,1,0,0,1,0.28533935546875,38.6119270324707,2,1,1,86.7714691162109,0,86.7311477661133,,,,,,,,,,,,,,,,,,,,,,,,,,,,,,,,,
,3832339250.68473,89.5261726379395,9999.8056640625,0.000812305384570649,1.13827339041976E-7,1,2,13.4005146026611,4.99337299013929,31.7299999296665,1.08031979797362,0.160741589258189,1,7.13710728254775E-6,,,,,,,,,,,,,,,,,,,,,89.4643478393555,89.5879974365234,9999.8056640625,9999.8056640625,47.1302456383223,5.26832138531741,7.93114566802979,27,1,0,0,1,0.285415649414062,38.6119270324707,2,1,1,89.5879974365234,0,89.5261726379395,,,,,,,,,,,,,,,,,,,,,,,,,,,,,,,,,
,3832339307.1447,92.3512649536133,9999.8056640625,0.000786396508697054,1.07992824604598E-7,1,2,13.4005146026611,4.99333015743501,31.7299999296665,1.04585589903696,0.155571920462331,1,6.87874362373002E-6,,,,,,,,,,,,,,,,,,,,,92.2960662841797,92.4064636230469,9999.8056640625,9999.8056640625,47.1638556646492,5.26859267270367,7.96706533432007,27,1,0,0,1,0.286788940429687,38.6119270324707,2,1,1,92.4064636230469,0,92.3512649536133,,,,,,,,,,,,,,,,,,,,,,,,,,,,,,,,,
,3832339363.46663,95.1293754577637,9999.8056640625,0.000761953070641061,9.11975966419805E-8,1,2,13.4005146026611,4.99326064865936,31.7399986088276,1.0133300534965,0.150721581892427,1,6.65603620042952E-6,,,,,,,,,,,,,,,,,,,,,95.0819854736328,95.1767654418945,9999.8056640625,9999.8056640625,47.0712326851204,5.26917929333359,7.98305606842041,27,1,0,0,1,0.276260375976562,38.6119270324707,2,1,1,95.1767654418945,0,95.1293754577637,,,,,,,,,,,,,,,,,,,,,,,,,,,,,,,,,
,3832339419.8947,97.9279937744141,9999.8056640625,0.000738953625492586,7.39928267633375E-8,1,2,13.4005146026611,4.99329694224953,31.7399986088276,0.982785836462879,0.145935948118502,1,6.2767011350162E-6,,,,,,,,,,,,,,,,,,,,,97.8856735229492,97.9703140258789,9999.8056640625,9999.8056640625,47.0696694280819,5.26970306347077,8.00642967224121,27,1,0,0,1,0.278167724609375,38.6119270324707,2,1,1,97.9703140258789,0,97.9279937744141,,,,,,,,,,,,,,,,,,,,,,,,,,,,,,,,,
,3832339476.3159,100.744651794434,9999.8056640625,0.00071699507395099,1.01437240344952E-7,1,2,13.4005146026611,4.99330209791945,31.750001013279,0.953580935439845,0.141614178310395,1,6.101167077004E-6,,,,,,,,,,,,,,,,,,,,,100.694023132324,100.795280456543,9999.8056640625,9999.8056640625,47.0712326851204,5.26939127730742,8.02573585510254,27,1,0,0,1,0.273818969726562,38.6119270324707,2,1,1,100.795280456543,0,100.744651794434,,,,,,,,,,,,,,,,,,,,,,,,,,,,,,,,,
,3832339532.75331,103.547416687012,9999.8056640625,0.000696417523457192,8.28470387691204E-8,1,2,13.4005146026611,4.99328437330409,31.75999969244,0.926185492601321,0.137716878275849,1,6.05197520118969E-6,,,,,,,,,,,,,,,,,,,,,103.493232727051,103.601600646973,9999.8056640625,9999.8056640625,47.0571633717742,5.26903295977384,8.05267429351807,27,1,0,0,1,0.272750854492187,38.6119270324707,2,1,1,103.601600646973,0,103.547416687012,,,,,,,,,,,,,,,,,,,,,,,,,,,,,,,,,
,3832339589.28929,106.379421234131,9999.8056640625,0.000676756753568233,7.14578497245459E-8,1,2,13.4005146026611,4.99323827971556,31.75999969244,0.900042357329119,0.13371521064941,1,5.79696968223522E-6,,,,,,,,,,,,,,,,,,,,,106.34156036377,106.417282104492,9999.8056640625,9999.8056640625,47.1318088953607,5.27009002787496,8.06938552856445,27,1,0,0,1,0.27587890625,38.6119270324707,2,1,1,106.417282104492,0,106.379421234131,,,,,,,,,,,,,,,,,,,,,,,,,,,,,,,,,
,3832339645.56236,109.168312072754,9999.8056640625,0.000658167494034442,7.47109331813312E-8,1,2,13.4005146026611,4.99320176685005,31.7699983716011,0.875342297778541,0.12981775433494,1,5.47007676737025E-6,,,,,,,,,,,,,,,,,,,,,109.113090515137,109.223533630371,9999.8056640625,9999.8056640625,47.1419700661108,5.26953901206818,8.07857990264893,27,1,0,0,1,0.276641845703125,38.6119270324707,2,1,1,109.223533630371,0,109.168312072754,,,,,,,,,,,,,,,,,,,,,,,,,,,,,,,,,
,3832339702.22987,112.00691986084,9999.8056640625,0.000640603198088797,8.58686572070663E-8,1,2,13.4005146026611,4.99314974274639,31.7699983716011,0.851957411101665,0.126442776342763,1,5.39261471982235E-6,,,,,,,,,,,,,,,,,,,,,111.95866394043,112.05517578125,9999.8056640625,9999.8056640625,47.0810030416108,5.26920290519346,8.09590435028076,27,1,0,0,1,0.285110473632813,38.6119270324707,2,1,1,112.05517578125,0,112.00691986084,,,,,,,,,,,,,,,,,,,,,,,,,,,,,,,,,
,3832339758.47643,114.806701660156,9999.8056640625,0.00062371416318448,5.97945629079377E-8,1,2,13.4005146026611,4.99316722414087,31.7800007760525,0.829495120123891,0.123145814559793,1,5.27749371337352E-6,,,,,,,,,,,,,,,,,,,,,114.759582519531,114.853820800781,9999.8056640625,9999.8056640625,47.0755316419761,5.26976926341564,8.10251140594482,27,1,0,0,1,0.287246704101562,38.6119270324707,2,1,1,114.853820800781,0,114.806701660156,,,,,,,,,,,,,,,,,,,,,,,,,,,,,,,,,
,3832339814.83075,117.587509155273,9999.8056640625,0.000607849255509812,8.71876381723279E-8,1,2,13.4005146026611,4.99321957679761,31.7899994552135,0.808422368036119,0.119909162537428,1,5.06363371902307E-6,,,,,,,,,,,,,,,,,,,,,117.541023254395,117.633995056152,9999.8056640625,9999.8056640625,47.1329813381396,5.27002705830857,8.1151123046875,27,1,0,0,1,0.275726318359375,38.6119270324707,2,1,1,117.633995056152,0,117.587509155273,,,,,,,,,,,,,,,,,,,,,,,,,,,,,,,,,
,3832339871.20596,120.384323120117,9999.8056640625,0.000592420227357499,5.21915924173705E-8,1,2,13.4005146026611,4.99317699042102,31.7899994552135,0.787901849164669,0.116800767597359,1,4.88750581630782E-6,,,,,,,,,,,,,,,,,,,,,120.340217590332,120.428428649902,9999.8056640625,9999.8056640625,47.0954631692165,5.27104369126207,8.12701988220215,27,1,0,0,1,0.285110473632813,38.6119270324707,2,1,1,120.428428649902,0,120.384323120117,,,,,,,,,,,,,,,,,,,,,,,,,,,,,,,,,
,3832339927.65576,123.183982849121,9999.8056640625,0.000577680349670566,5.22064381314584E-8,1,2,13.4005146026611,4.99317104121541,31.8000018596649,0.768293166262847,0.113921775929554,1,4.78639537201833E-6,,,,,,,,,,,,,,,,,,,,,123.138679504395,123.229286193848,9999.8056640625,9999.8056640625,47.0981988690338,5.27018454933884,8.13941192626953,27,1,0,0,1,0.286636352539062,38.6119270324707,2,1,1,123.229286193848,0,123.183982849121,,,,,,,,,,,,,,,,,,,,,,,,,,,,,,,,,
,3832339984.03215,126.033790588379,9999.8056640625,0.000563793959566102,4.16442976029452E-8,1,2,13.4005146026611,4.99313069316346,31.810000538826,0.749815856020205,0.111186580469736,1,4.67472548312488E-6,,,,,,,,,,,,,,,,,,,,,125.989456176758,126.078125,9999.8056640625,9999.8056640625,47.0387951015723,5.26993087570794,8.15813446044922,27,1,0,0,1,0.276718139648438,38.6119270324707,2,1,1,126.078125,0,126.033790588379,,,,,,,,,,,,,,,,,,,,,,,,,,,,,,,,,
,3832340040.44469,128.840217590332,9999.8056640625,0.000550318051589843,7.2540438839318E-8,1,2,13.4005146026611,4.9931081139733,31.810000538826,0.731902569047321,0.108431853652681,1,4.49054973106249E-6,,,,,,,,,,,,,,,,,,,,,128.786651611328,128.893783569336,9999.8056640625,9999.8056640625,47.0860836269858,5.27004097571167,8.17564010620117,27,1,0,0,1,0.276336669921875,38.6119270324707,2,1,1,128.893783569336,0,128.840217590332,,,,,,,,,,,,,,,,,,,,,,,,,,,,,,,,,
,3832340097.0042,131.628952026367,9999.8056640625,0.000537379733314097,7.14473049732821E-8,1,2,13.4005146026611,4.99314925760343,31.8199992179871,0.714684270403776,0.106018818676073,1,4.48641597928347E-6,,,,,,,,,,,,,,,,,,,,,131.590759277344,131.667144775391,9999.8056640625,9999.8056640625,47.1126589966396,5.27098925343652,8.17442798614502,27,1,0,0,1,0.285110473632813,38.6119270324707,2,1,1,131.667144775391,0,131.628952026367,,,,,,,,,,,,,,,,,,,,,,,,,,,,,,,,,
,3832340153.29972,134.430770874023,9999.8056640625,0.000525126618680071,4.69753993818502E-8,1,2,13.4005146026611,4.99313204987118,31.8300016224384,0.698380140030863,0.103635915964327,1,4.41039331310584E-6,,,,,,,,,,,,,,,,,,,,,134.376739501953,134.484802246094,9999.8056640625,9999.8056640625,47.1189120247934,5.27027836559636,8.18717002868652,27,1,0,0,1,0.275802612304687,38.6119270324707,2,1,1,134.484802246094,0,134.430770874023,,,,,,,,,,,,,,,,,,,,,,,,,,,,,,,,,
,3832340209.87397,137.281181335449,9999.8056640625,0.000513318451512043,4.37173866793968E-8,1,2,13.4005146026611,4.99315801092452,31.8400003015995,0.682700371045693,0.101167719067661,1,4.20718082685542E-6,,,,,,,,,,,,,,,,,,,,,137.233871459961,137.328491210938,9999.8056640625,9999.8056640625,47.0255074167454,5.26975497450862,8.20372295379639,27,1,0,0,1,0.2783203125,38.6119270324707,2,1,1,137.328491210938,0,137.281181335449,,,,,,,,,,,,,,,,,,,,,,,,,,,,,,,,,
,3832340266.15172,140.048332214355,9999.8056640625,0.000501843896046121,8.05507668715237E-8,1,2,13.4005146026611,4.99311738816972,31.8499989807606,0.66744751936768,0.0987946237372554,1,4.03012825629539E-6,,,,,,,,,,,,,,,,,,,,,140.003402709961,140.09326171875,9999.8056640625,9999.8056640625,47.0473930152838,5.27042026795996,8.21558284759522,27,1,0,0,1,0.2783203125,38.6119270324707,2,1,1,140.09326171875,0,140.048332214355,,,,,,,,,,,,,,,,,,,,,,,,,,,,,,,,,
,3832340322.62646,142.874725341797,9999.8056640625,0.000490963130310061,4.48254392929809E-8,1,2,13.4005146026611,4.99312789223569,31.8600013852119,0.652971836998902,0.0966975911420959,1,3.97632899985111E-6,,,,,,,,,,,,,,,,,,,,,142.815872192383,142.933578491211,9999.8056640625,9999.8056640625,47.1099232968223,5.27107162873237,8.22606182098389,27,1,0,0,1,0.274276733398438,38.6119270324707,2,1,1,142.933578491211,0,142.874725341797,,,,,,,,,,,,,,,,,,,,,,,,,,,,,,,,,
,3832340378.96008,145.682678222656,9999.8056640625,0.000480394188651159,4.87951439665789E-8,1,2,13.4005146026611,4.99314381517715,31.870000064373,0.638898402314747,0.0947575127338199,1,3.99671155100531E-6,,,,,,,,,,,,,,,,,,,,,145.639175415039,145.726181030273,9999.8056640625,9999.8056640625,47.0524736006588,5.27084837010315,8.22244071960449,27,1,0,0,1,0.2740478515625,38.6119270324707,2,1,1,145.726181030273,0,145.682678222656,,,,,,,,,,,,,,,,,,,,,,,,,,,,,,,,,
,3832340435.68326,148.499954223633,9999.8056640625,0.000470035135678987,6.79100422628704E-8,1,2,13.4005146026611,4.99310055955443,31.8799987435341,0.625120530882727,0.0926663787442394,1,3.87544251260918E-6,,,,,,,,,,,,,,,,,,,,,148.471130371094,148.528778076172,9999.8056640625,9999.8056640625,47.1251650529473,5.27118607972494,8.23138046264648,25,1,64,0,0,0.276641845703125,38.6119270324707,2,1,1,148.528778076172,0,148.499954223633,,,,,,,,,,,,,,,,,,,,,,,,,,,,,,,,,
,3832340491.74987,151.305892944336,9999.8056640625,0.000460381927014667,4.33204676624734E-8,1,2,13.4005146026611,4.99308219805323,31.8799987435341,0.612282682644331,0.0907380202689269,1,3.77723134615416E-6,,,,,,,,,,,,,,,,,,,,,151.251998901367,151.359786987305,9999.8056640625,9999.8056640625,47.1677638072454,5.2713442665527,8.24646949768066,27,1,0,0,1,0.285797119140625,38.6119270324707,2,1,1,151.359786987305,0,151.305892944336,,,,,,,,,,,,,,,,,,,,,,,,,,,,,,,,,
,3832340548.17145,154.126182556152,9999.8056640625,0.000450889237902457,6.18061330324658E-8,1,2,13.4005146026611,4.99308257071402,31.8900011479855,0.59965888489682,0.0888606780157941,1,3.69453417266442E-6,,,,,,,,,,,,,,,,,,,,,154.071441650391,154.180923461914,9999.8056640625,9999.8056640625,47.0692786138223,5.27109282103791,8.25311183929443,27,1,0,0,1,0.287246704101562,38.6119270324707,2,1,1,154.180923461914,0,154.126182556152,,,,,,,,,,,,,,,,,,,,,,,,,,,,,,,,,
,3832340604.72295,156.968864440918,9999.8056640625,0.000441794155981979,6.05510195225071E-8,1,2,13.4005146026611,4.993066395154,31.8999998271465,0.587555350400957,0.0871032276459539,1,3.64658482428511E-6,,,,,,,,,,,,,,,,,,,,,156.916000366211,157.021728515625,9999.8056640625,9999.8056640625,47.0899917695819,5.27176110069658,8.27295112609863,27,1,0,0,1,0.276260375976562,38.6119270324707,2,1,1,157.021728515625,0,156.968864440918,,,,,,,,,,,,,,,,,,,,,,,,,,,,,,,,,
,3832340661.01063,159.744117736816,9999.8056640625,0.00043306668821381,4.03560038934337E-8,1,2,13.4005146026611,4.99306540521375,31.9099985063076,0.575964830811352,0.0852640850997595,1,3.48560113920525E-6,,,,,,,,,,,,,,,,,,,,,159.695068359375,159.793167114258,9999.8056640625,9999.8056640625,47.1314180811011,5.27086371971237,8.27650356292725,27,1,0,0,1,0.28564453125,38.6119270324707,2,1,1,159.793167114258,0,159.744117736816,,,,,,,,,,,,,,,,,,,,,,,,,,,,,,,,,
,3832340717.47519,162.618644714355,9999.8056640625,0.000424584264107654,5.06874518143889E-8,1,2,13.4005146026611,4.99301762864282,31.920000910759,0.564675765783312,0.0835951384581657,1,3.4189863902447E-6,,,,,,,,,,,,,,,,,,,,,162.579956054687,162.657333374023,9999.8056640625,9999.8056640625,47.1857412631877,5.27123472659555,8.28620338439941,27,1,0,0,1,0.27313232421875,38.6119270324707,2,1,1,162.657333374023,0,162.618644714355,,,,,,,,,,,,,,,,,,,,,,,,,,,,,,,,,
,3832340773.83173,165.356498718262,9999.8056640625,0.00041636255691395,5.39565995014001E-8,1,2,13.4005146026611,4.99300518244465,31.9399982690811,0.553747197563823,0.0819204596775682,1,3.31098307105224E-6,,,,,,,,,,,,,,,,,,,,,165.310562133789,165.402435302734,9999.8056640625,9999.8056640625,47.1865228917069,5.27135437005082,8.28974151611328,27,1,0,0,1,0.274276733398438,38.6119270324707,2,1,1,165.402435302734,0,165.356498718262,,,,,,,,,,,,,,,,,,,,,,,,,,,,,,,,,
,3832340830.33228,168.219551086426,9999.8056640625,0.000408518301984171,5.01455132979999E-8,1,2,13.4005146026611,4.99299766288136,31.9399982690811,0.543301796901242,0.0804606150291232,1,3.31146817076919E-6,,,,,,,,,,,,,,,,,,,,,168.169876098633,168.269226074219,9999.8056640625,9999.8056640625,47.1533036796396,5.27190805913387,8.29804515838623,27,1,0,0,1,0.2783203125,38.6119270324707,2,1,1,168.269226074219,0,168.219551086426,,,,,,,,,,,,,,,,,,,,,,,,,,,,,,,,,
,3832340886.65171,170.975364685059,9999.8056640625,0.000400807101444032,5.07712002859882E-8,1,2,13.4005146026611,4.99296454820001,31.9500006735325,0.53305913203678,0.0788155588754327,1,3.15465439896006E-6,,,,,,,,,,,,,,,,,,,,,170.926803588867,171.02392578125,9999.8056640625,9999.8056640625,47.1255558672069,5.27213716846138,8.30498027801514,27,1,0,0,1,0.28533935546875,38.6119270324707,2,1,1,171.02392578125,0,170.975364685059,,,,,,,,,,,,,,,,,,,,,,,,,,,,,,,,,
,3832340943.07015,173.767997741699,9999.8056640625,0.000393379370802775,5.2970021581817E-8,1,2,13.4005146026611,4.99302061848045,31.9700017571449,0.523173641548807,0.0774628867582345,1,3.17636246323952E-6,,,,,,,,,,,,,,,,,,,,,173.722549438477,173.813446044922,9999.8056640625,9999.8056640625,47.0247257882261,5.27267847247598,8.31895923614502,27,1,0,0,1,0.285415649414062,38.6119270324707,2,1,1,173.813446044922,0,173.767997741699,,,,,,,,,,,,,,,,,,,,,,,,,,,,,,,,,
,3832340999.50624,176.625923156738,9999.8056640625,0.000386132065177446,5.51877082796077E-8,1,2,13.4005146026611,4.99301842136342,31.9700017571449,0.513554124434694,0.0758975253444047,1,3.0140458769146E-6,,,,,,,,,,,,,,,,,,,,,176.570709228516,176.681137084961,9999.8056640625,9999.8056640625,47.1490047227838,5.27169066190877,8.3328447341919,27,1,0,0,1,0.28778076171875,38.6119270324707,2,1,1,176.681137084961,0,176.625923156738,,,,,,,,,,,,,,,,,,,,,,,,,,,,,,,,,
,3832341055.90423,179.452781677246,9999.8056640625,0.000379018018050282,6.62397701246527E-8,1,2,13.4005146026611,4.99301148644258,31.980000436306,0.504074339989873,0.0746218594819455,1,3.0507475674437E-6,,,,,,,,,,,,,,,,,,,,,179.405044555664,179.500518798828,9999.8056640625,9999.8056640625,47.1216477246108,5.272257468861,8.34248638153076,27,1,0,0,1,0.276336669921875,38.6119270324707,2,1,1,179.500518798828,0,179.452781677246,,,,,,,,,,,,,,,,,,,,,,,,,,,,,,,,,
,3832341112.48223,182.245994567871,9999.8056640625,0.000372260860505492,5.22863479912753E-8,1,2,13.4005146026611,4.99296385343353,31.9899991154671,0.495076349280719,0.0733252174956866,1,3.02240540860019E-6,,,,,,,,,,,,,,,,,,,,,182.205184936523,182.286804199219,9999.8056640625,9999.8056640625,47.1208660960915,5.27246761015001,8.35046482086182,27,1,0,0,1,0.27862548828125,38.6119270324707,2,1,1,182.286804199219,0,182.245994567871,,,,,,,,,,,,,,,,,,,,,,,,,,,,,,,,,
,3832341168.73879,185.044921875,9999.8056640625,0.00036582243124425,4.07031543662717E-8,1,2,13.4005146026611,4.99302336998218,32.0000015199184,0.48653819514122,0.0719403297282669,1,2.88160389198977E-6,,,,,,,,,,,,,,,,,,,,,184.993591308594,185.096252441406,9999.8056640625,9999.8056640625,47.1357170379569,5.27182966683533,8.3566837310791,27,1,0,0,1,0.27496337890625,38.6119270324707,2,1,1,185.096252441406,0,185.044921875,,,,,,,,,,,,,,,,,,,,,,,,,,,,,,,,,
,3832341225.50298,187.867256164551,9999.8056640625,0.000359403777280717,5.00491856700171E-8,1,2,13.4005146026611,4.99297763174639,32.0199988782406,0.478004715478859,0.0706111684917298,1,2.78145660711098E-6,,,,,,,,,,,,,,,,,,,,,187.840179443359,187.894332885742,9999.8056640625,9999.8056640625,47.1263374957261,5.27167992991691,8.34820175170898,25,1,64,0,0,0.276412963867187,38.6119270324707,2,1,1,187.894332885742,0,187.867256164551,,,,,,,,,,,,,,,,,,,,,,,,,,,,,,,,,
,3832341281.56465,190.67195892334,9999.8056640625,0.000353288228436689,4.9490275791395E-8,1,2,13.4005146026611,4.99293430990229,32.030001282692,0.469833932356661,0.0696345229313072,1,2.90363608966731E-6,,,,,,,,,,,,,,,,,,,,,190.627853393555,190.716064453125,9999.8056640625,9999.8056640625,47.19355754838,5.2723666694065,8.36227321624756,27,1,0,0,1,0.275192260742187,38.6119270324707,2,1,1,190.716064453125,0,190.67195892334,,,,,,,,,,,,,,,,,,,,,,,,,,,,,,,,,
,3832341338.04701,193.506271362305,9999.8056640625,0.000347208900666784,5.08343448949994E-8,1,2,13.4005146026611,4.99290026287887,32.039999961853,0.461774512802936,0.0682230464355276,1,2.69400710061734E-6,,,,,,,,,,,,,,,,,,,,,193.456909179687,193.555633544922,9999.8056640625,9999.8056640625,47.1384527377742,5.27194387736552,8.37164115905762,27,1,0,0,1,0.275726318359375,38.6119270324707,2,1,1,193.555633544922,0,193.506271362305,,,,,,,,,,,,,,,,,,,,,,,,,,,,,,,,,
,3832341394.42687,196.277503967285,9999.8056640625,0.000341179908758698,5.63018427899626E-8,1,2,13.4005146026611,4.99291344185218,32.0499986410141,0.453763839867141,0.0669956432655041,1,2.61492417568791E-6,,,,,,,,,,,,,,,,,,,,,196.233703613281,196.321304321289,9999.8056640625,9999.8056640625,47.1232109816492,5.27227268268678,8.37195205688477,27,1,0,0,1,0.275115966796875,39.1006851196289,2,1,1,196.321304321289,0,196.277503967285,,,,,,,,,,,,,,,,,,,,,,,,,,,,,,,,,
,3832341450.80032,199.090980529785,9999.8056640625,0.000335571040275539,3.67703187218211E-8,1,2,13.4005146026611,4.99293357597837,32.0600010454655,0.4462893009569,0.0660183495461457,1,2.66486315650635E-6,,,,,,,,,,,,,,,,,,,,,199.038391113281,199.143569946289,9999.8056640625,9999.8056640625,47.1236017959088,5.27227540311458,8.37185382843018,27,1,0,0,1,0.27496337890625,38.6119270324707,2,1,1,199.154586791992,0,199.090980529785,,,,,,,,,,,,,,,,,,,,,,,,,,,,,,,,,
,3832341507.47827,201.947807312012,9999.8056640625,0.000329994023848409,4.18251644470578E-8,1,2,13.4005146026611,4.99295867617826,32.0699997246265,0.438861657220018,0.0650186626232242,1,2.69347111876284E-6,,,,,,,,,,,,,,,,,,,,,201.918167114258,201.977447509766,9999.8056640625,9999.8056640625,47.1708903213223,5.27206199014644,8.38641738891602,25,1,64,0,0,0.284881591796875,38.6119270324707,2,1,1,201.977447509766,0,201.947807312012,,,,,,,,,,,,,,,,,,,,,,,,,,,,,,,,,
,3832341563.65677,204.726898193359,9999.8056640625,0.000324541249844881,5.66427096327486E-8,1,2,13.4005146026611,4.99294403286051,32.0799984037876,0.431632184528613,0.0637727636252478,1,2.52031796876595E-6,,,,,,,,,,,,,,,,,,,,,204.675247192383,204.778549194336,9999.8056640625,9999.8056640625,47.1419700661108,5.2719679369067,8.3982982635498,27,1,0,0,1,0.275802612304687,38.6119270324707,2,1,1,204.778549194336,0,204.726898193359,,,,,,,,,,,,,,,,,,,,,,,,,,,,,,,,,
,3832341620.19136,207.535766601562,9999.8056640625,0.0003192048139897,4.66565938039084E-8,1,2,13.4005146026611,4.99300949575939,32.090000808239,0.424535549597055,0.0627748287818509,1,2.51609497605083E-6,,,,,,,,,,,,,,,,,,,,,207.494689941406,207.576843261719,9999.8056640625,9999.8056640625,47.0321512591588,5.27141437012869,8.40858554840088,27,1,0,0,1,0.28778076171875,38.6119270324707,2,1,1,207.576843261719,0,207.535766601562,,,,,,,,,,,,,,,,,,,,,,,,,,,,,,,,,
,3832341676.75926,210.432929992676,9999.8056640625,0.000314201175802511,5.42834616472069E-8,1,2,13.4005146026611,4.99309484412437,32.1099981665611,0.417882755581119,0.0618484090528945,1,2.51882451276553E-6,,,,,,,,,,,,,,,,,,,,,210.408309936523,210.457550048828,9999.8056640625,9999.8056640625,47.1239926101684,5.27124948405901,8.40508270263672,26,1,64,0,0,0.273971557617187,38.6119270324707,2,1,1,210.457550048828,0,210.432929992676,,,,,,,,,,,,,,,,,,,,,,,,,,,,,,,,,
,3832341733.03143,213.187568664551,9999.8056640625,0.000309348342369798,5.39026749243088E-8,1,2,13.4005146026611,4.99298100796176,32.1200005710125,0.411429989718143,0.0607891163495435,1,2.4032053022053E-6,,,,,,,,,,,,,,,,,,,,,213.133209228516,213.241928100586,9999.8056640625,9999.8056640625,47.02081764563,5.27108735202409,8.42703819274902,27,1,0,0,1,0.285491943359375,38.6119270324707,2,1,1,213.241928100586,0,213.187568664551,,,,,,,,,,,,,,,,,,,,,,,,,,,,,,,,,
,3832341789.3093,215.980125427246,9999.8056640625,0.000304304679965362,5.6569017535487E-8,1,2,13.4005146026611,4.99298365543489,32.1299992501736,0.40472185041499,0.0598010219396014,1,2.3662591107022E-6,,,,,,,,,,,,,,,,,,,,,215.929443359375,216.030807495117,9999.8056640625,9999.8056640625,47.1439241374088,5.27171442159694,8.43542194366455,27,1,0,0,1,0.276641845703125,38.6119270324707,2,1,1,216.030807495117,0,215.980125427246,,,,,,,,,,,,,,,,,,,,,,,,,,,,,,,,,
,3832341845.72835,218.807579040527,9999.8056640625,0.000299831378903564,4.02133255086914E-8,1,2,13.4005146026611,4.99286009638967,32.150000333786,0.39875222599195,0.058967583718061,1,2.36725648430927E-6,,,,,,,,,,,,,,,,,,,,,218.750274658203,218.864883422852,9999.8056640625,9999.8056640625,47.1779249779954,5.27302294423064,8.44720840454102,27,1,0,0,1,0.286865234375,38.6119270324707,2,1,1,218.864883422852,0,218.807579040527,,,,,,,,,,,,,,,,,,,,,,,,,,,,,,,,,
,3832341902.12448,221.588645935059,9999.8056640625,0.000295090847316377,4.00459569661342E-8,1,2,13.4005146026611,4.99300008583558,32.1599990129471,0.392457302854395,0.0580765904937335,1,2.3591902369601E-6,,,,,,,,,,,,,,,,,,,,,221.540863037109,221.636428833008,9999.8056640625,9999.8056640625,47.1423608803704,5.27149473824667,8.45041465759277,27,1,0,0,1,0.2740478515625,38.6119270324707,2,1,1,221.636428833008,0,221.588645935059,,,,,,,,,,,,,,,,,,,,,,,,,,,,,,,,,
,3832341958.53284,224.434776306152,9999.8056640625,0.000290535112666841,5.34593990975787E-8,1,2,13.4005146026611,4.99301458090004,32.1700014173985,0.386429380462832,0.0569695194267453,1,2.16452824035371E-6,,,,,,,,,,,,,,,,,,,,,224.37922668457,224.490325927734,9999.8056640625,9999.8056640625,47.1876953344858,5.27347581019286,8.46722030639648,27,1,0,0,1,0.273818969726562,38.6119270324707,2,1,1,224.490325927734,0,224.434776306152,,,,,,,,,,,,,,,,,,,,,,,,,,,,,,,,,
,3832342015.16452,227.242286682129,9999.8056640625,0.0002861976682357,5.92929298800825E-8,1,2,13.4005146026611,4.99303415341343,32.1800000965595,0.38065548691053,0.0561684711050868,1,2.16913353603059E-6,,,,,,,,,,,,,,,,,,,,,227.206558227539,227.278015136719,9999.8056640625,9999.8056640625,47.14275169463,5.27275377662353,8.47507858276367,27,1,0,0,1,0.287551879882813,38.6119270324707,2,1,1,227.278015136719,0,227.242286682129,,,,,,,,,,,,,,,,,,,,,,,,,,,,,,,,,
,3832342071.37462,230.061805725098,9999.8056640625,0.00028207932692003,4.92906997104909E-8,1,2,13.4005146026611,4.99302067531041,32.200001180172,0.375188090965089,0.0552772843409163,1,2.07578765535158E-6,,,,,,,,,,,,,,,,,,,,,230.01008605957,230.113525390625,9999.8056640625,9999.8056640625,47.1130498108992,5.27256645084773,8.48788642883301,27,1,0,0,1,0.277786254882813,38.6119270324707,2,1,1,230.113525390625,0,230.061805725098,,,,,,,,,,,,,,,,,,,,,,,,,,,,,,,,,
,3832342127.92188,232.864585876465,9999.8056640625,0.000277683727606304,4.34652326814534E-8,1,2,13.4005146026611,4.99303247062766,32.209999859333,0.369320872138897,0.0545728210865859,1,2.16116045686762E-6,,,,,,,,,,,,,,,,,,,,,232.827224731445,232.901947021484,9999.8056640625,9999.8056640625,47.1185212105338,5.27343762949829,8.49676609039307,27,1,0,0,1,0.276031494140625,38.6119270324707,2,1,1,232.901947021484,0,232.864585876465,,,,,,,,,,,,,,,,,,,,,,,,,,,,,,,,,
,3832342184.18613,235.688369750977,9999.8056640625,0.000273557031982077,4.86536926699924E-8,1,2,13.4005146026611,4.99301265954391,32.2300009429455,0.363822981519799,0.0538143303358302,1,2.1687110229758E-6,,,,,,,,,,,,,,,,,,,,,235.64404296875,235.732696533203,9999.8056640625,9999.8056640625,47.1568210079761,5.27282015597877,8.51419162750244,27,1,0,0,1,0.275039672851562,38.6119270324707,2,1,1,235.732696533203,0,235.688369750977,,,,,,,,,,,,,,,,,,,,,,,,,,,,,,,,,
,3832342240.77712,238.48267364502,9999.8056640625,0.000269857516289491,5.05563086070596E-8,1,2,13.4005146026611,4.99296855263771,32.2499983012676,0.358916081484517,0.0529593704743533,1,2.04433686307387E-6,,,,,,,,,,,,,,,,,,,,,238.427703857422,238.537643432617,9999.8056640625,9999.8056640625,47.1142222536781,5.27198009588855,8.52816677093506,27,1,0,0,1,0.274124145507813,38.6119270324707,2,1,1,238.537643432617,0,238.48267364502,,,,,,,,,,,,,,,,,,,,,,,,,,,,,,,,,
,3832342297.54653,241.316505432129,9999.8056640625,0.000266130049644611,3.88800529678223E-8,1,2,13.4005146026611,4.99301067123567,32.260000705719,0.353947607504239,0.0523354383610996,1,2.09644560565133E-6,,,,,,,,,,,,,,,,,,,,,241.291641235352,241.341369628906,9999.8056640625,9999.8056640625,47.0958539834761,5.27257292367858,8.55432987213135,26,1,64,0,0,0.287857055664062,38.6119270324707,2,1,1,241.341369628906,0,241.316505432129,,,,,,,,,,,,,,,,,,,,,,,,,,,,,,,,,
,3832342353.46722,244.130485534668,9999.8056640625,0.000262097705780689,3.94464671904641E-8,1,2,13.4005146026611,4.9930023959835,32.2699993848801,0.348574488679992,0.0516095104270267,1,2.11512534235605E-6,,,,,,,,,,,,,,,,,,,,,244.068466186523,244.192504882813,9999.8056640625,9999.8056640625,47.1040610829281,5.27243709828389,8.57815265655518,27,1,0,0,1,0.278091430664062,38.6119270324707,2,1,1,244.192504882813,0,244.130485534668,,,,,,,,,,,,,,,,,,,,,,,,,,,,,,,,,
,3832342409.83578,246.880485534668,9999.8056640625,0.000258372376931775,3.00016182693509E-8,1,2,13.4005146026611,4.99296769476889,32.2800017893314,0.343634619202491,0.0507476632828038,1,1.98906732434393E-6,,,,,,,,,,,,,,,,,,,,,246.835174560547,246.925796508789,9999.8056640625,9999.8056640625,47.1298548240627,5.27252845313151,8.58832263946533,27,1,0,0,1,0.275726318359375,38.6119270324707,2,1,1,246.925796508789,0,246.880485534668,,,,,,,,,,,,,,,,,,,,,,,,,,,,,,,,,
,3832342466.26834,249.700149536133,9999.8056640625,0.000254803060065637,4.21112648674269E-8,1,2,13.4005146026611,4.99298627709127,32.2999991476536,0.338880087394929,0.0501117808994451,1,2.01035009197878E-6,,,,,,,,,,,,,,,,,,,,,249.647445678711,249.752853393555,9999.8056640625,9999.8056640625,47.1407976233319,5.27275502305524,8.6419506072998,27,1,0,0,1,0.278472900390625,38.6119270324707,2,1,1,249.752853393555,0,249.700149536133,,,,,,,,,,,,,,,,,,,,,,,,,,,,,,,,,
,3832342522.84424,252.546180725098,9999.8056640625,0.000251268554119962,3.3275755847228E-8,1,2,13.4005146026611,4.9929945210279,32.3100015521049,0.334167578532159,0.0495060424364142,1,2.04951592516029E-6,,,,,,,,,,,,,,,,,,,,,252.508651733398,252.583709716797,9999.8056640625,9999.8056640625,47.1384527377742,5.27217240142347,8.6777925491333,27,1,0,0,1,0.277099609375,38.6119270324707,2,1,1,252.583709716797,0,252.546180725098,,,,,,,,,,,,,,,,,,,,,,,,,,,,,,,,,
,3832342579.40039,255.397079467773,9999.8056640625,0.000247983385353399,3.66230185515659E-8,1,2,13.4005146026611,4.99290376366648,32.3299989104271,0.329803230312276,0.0487654163982288,1,1.9535069636063E-6,,,,,,,,,,,,,,,,,,,,,255.365753173828,255.428405761719,9999.8056640625,9999.8056640625,47.1490047227838,5.27142637294335,8.71928024291992,25,1,64,0,0,0.274734497070313,38.6119270324707,2,1,1,255.428405761719,0,255.397079467773,,,,,,,,,,,,,,,,,,,,,,,,,,,,,,,,,
,3832342635.68303,258.188323974609,9999.8056640625,0.000244478723319524,3.97933786563701E-8,1,2,13.4005146026611,4.99296619114617,32.3400013148785,0.325128978696563,0.0482117220030727,1,2.02704289722569E-6,,,,,,,,,,,,,,,,,,,,,258.151031494141,258.225616455078,9999.8056640625,9999.8056640625,47.1837871918896,5.27204372933433,8.76281452178955,27,1,0,0,1,0.278091430664062,38.6119270324707,2,1,1,258.225616455078,0,258.188323974609,,,,,,,,,,,,,,,,,,,,,,,,,,,,,,,,,
,3832342691.91802,261.013580322266,9999.8056640625,0.000241435255489986,2.56156152689451E-8,1,2,13.4005146026611,4.99284280456164,32.3599986732006,0.321066315341626,0.0476408517133791,1,2.02503279992548E-6,,,,,,,,,,,,,,,,,,,,,260.960235595703,261.066925048828,9999.8056640625,9999.8056640625,47.1880861487454,5.27259957841173,8.75874423980713,27,1,0,0,1,0.286331176757813,38.6119270324707,2,1,1,261.066925048828,0,261.013580322266,,,,,,,,,,,,,,,,,,,,,,,,,,,,,,,,,
,3832342748.36208,263.818801879883,9999.8056640625,0.000238014612517873,3.80365573803795E-8,1,2,13.4005146026611,4.99288154845496,32.370001077652,0.316523985119563,0.0469438062879027,1,1.97938896208241E-6,,,,,,,,,,,,,,,,,,,,,263.774139404297,263.863464355469,9999.8056640625,9999.8056640625,47.2599959725146,5.27235591286786,8.72904872894287,27,1,0,0,1,0.286407470703125,38.6119270324707,2,1,1,263.876312255859,0,263.818801879883,,,,,,,,,,,,,,,,,,,,,,,,,,,,,,,,,
,3832342804.77343,266.590835571289,9999.8056640625,0.000234799607882236,4.18771274029213E-8,1,2,13.4005146026611,4.99292122855787,32.3899984359741,0.312262621342027,0.0462335936428833,1,1.89510498390584E-6,,,,,,,,,,,,,,,,,,,,,266.542755126953,266.638916015625,9999.8056640625,9999.8056640625,47.1607291505723,5.27240731085902,8.7242317199707,27,1,0,0,1,0.274887084960938,38.6119270324707,2,1,1,266.638916015625,0,266.590835571289,,,,,,,,,,,,,,,,,,,,,,,,,,,,,,,,,
,3832342861.22769,269.412490844727,9999.8056640625,0.000231372720652813,3.49091230580395E-8,1,2,13.4005146026611,4.99289620152324,32.4000008404255,0.307677390579898,0.0457420348667571,1,2.00529360459823E-6,,,,,,,,,,,,,,,,,,,,,269.354797363281,269.470184326172,9999.8056640625,9999.8056640625,47.1474414657454,5.27221297647203,8.71967124938965,27,1,0,0,1,0.278396606445313,38.6119270324707,2,1,1,269.470184326172,0,269.412490844727,,,,,,,,,,,,,,,,,,,,,,,,,,,,,,,,,
,3832342917.58283,272.212158203125,9999.8056640625,0.000228377225994319,3.33513675587041E-8,1,2,13.4005146026611,4.99289938307096,32.4199981987476,0.303712276803482,0.0450211109255998,1,1.88262304594431E-6,,,,,,,,,,,,,,,,,,,,,272.161895751953,272.262420654297,9999.8056640625,9999.8056640625,47.1556485651973,5.27248951771732,8.72845363616943,27,1,0,0,1,0.275955200195313,39.1006851196289,2,1,1,272.262420654297,0,272.212158203125,,,,,,,,,,,,,,,,,,,,,,,,,,,,,,,,,
,3832342973.99978,275.045822143555,9999.8056640625,0.00022500262515887,3.70257131255453E-8,1,2,13.4005146026611,4.99291908933867,32.430000603199,0.299225075071457,0.0443635080911213,1,1.86036913775688E-6,,,,,,,,,,,,,,,,,,,,,274.984344482422,275.107299804687,9999.8056640625,9999.8056640625,47.14275169463,5.27231993659219,8.74756240844727,27,1,0,0,1,0.274810791015625,38.6119270324707,2,1,1,275.107299804687,0,275.045822143555,,,,,,,,,,,,,,,,,,,,,,,,,,,,,,,,,
,3832343030.85757,277.876739501953,9999.8056640625,0.000222194204318624,4.12511134644489E-8,1,2,13.4005146026611,4.9928599987303,32.4600003659725,0.295460584863475,0.0439868123953505,1,1.97065389394087E-6,,,,,,,,,,,,,,,,,,,,,277.845550537109,277.907928466797,9999.8056640625,9999.8056640625,47.1685454357646,5.27128381276496,8.77437686920166,26,1,64,0,0,0.277786254882813,38.6119270324707,2,1,1,277.907928466797,0,277.876739501953,,,,,,,,,,,,,,,,,,,,,,,,,,,,,,,,,
,3832343086.83588,280.65104675293,9999.8056640625,0.000218908767690164,3.91516779015447E-8,1,2,13.4005146026611,4.99279490415698,32.4699990451336,0.291092348533033,0.0432945701002389,1,1.91067125580759E-6,,,,,,,,,,,,,,,,,,,,,280.602508544922,280.699584960938,9999.8056640625,9999.8056640625,47.1576026364954,5.27372910137207,8.81493759155273,27,1,0,0,1,0.276260375976562,38.6119270324707,2,1,1,280.699584960938,0,280.65104675293,,,,,,,,,,,,,,,,,,,,,,,,,,,,,,,,,
,3832343143.40085,283.472412109375,9999.8056640625,0.000215850592381167,3.40851234999871E-8,1,2,13.4005146026611,4.99295585931255,32.490000128746,0.287035421948968,0.0427132249020046,1,1.90020069812281E-6,,,,,,,,,,,,,,,,,,,,,283.426971435547,283.517852783203,9999.8056640625,9999.8056640625,47.15291286538,5.27123521234663,8.86451244354248,27,1,0,0,1,0.276641845703125,38.6119270324707,2,1,1,283.517852783203,0,283.472412109375,,,,,,,,,,,,,,,,,,,,,,,,,,,,,,,,,
,3832343199.66354,286.156982421875,9999.8056640625,0.000212470490521396,3.32419309157934E-8,1,2,13.4005146026611,4.99291553334156,32.4999988079071,0.282533812336426,0.0420701084664359,1,1.89013389427726E-6,,,,,,,,,,,,,,,,,,,,,286.107818603516,286.206146240234,9999.8056640625,9999.8056640625,47.1990289480146,5.27152038001022,8.93278408050537,27,1,0,0,1,0.277023315429687,38.6119270324707,2,1,1,286.206146240234,0,286.156982421875,,,,,,,,,,,,,,,,,,,,,,,,,,,,,,,,,
,3832343256.15002,288.992218017578,9999.8056640625,0.000209154316289181,3.19510981609252E-8,1,2,13.4005146026611,4.99286303315708,32.5199998915195,0.278087451933282,0.0416464194536948,1,2.036032380423E-6,,,,,,,,,,,,,,,,,,,,,288.946960449219,289.037475585937,9999.8056640625,9999.8056640625,47.1759709066973,5.27148254875965,9.03940200805664,27,1,0,0,1,0.285720825195313,38.6119270324707,2,1,1,289.037475585937,0,288.992218017578,,,,,,,,,,,,,,,,,,,,,,,,,,,,,,,,,
,3832343312.7908,291.945037841797,9999.8056640625,0.000206338150069555,4.06922116223695E-8,1,2,13.4005146026611,4.99287271238925,32.540000975132,0.274356262957404,0.0409970854686393,1,1.94200134630755E-6,,,,,,,,,,,,,,,,,,,,,291.919128417969,291.970947265625,9999.8056640625,9999.8056640625,47.2056727904281,5.27167390540182,9.16398906707764,26,1,64,0,0,0.2764892578125,38.6119270324707,2,1,1,291.970947265625,0,291.945037841797,,,,,,,,,,,,,,,,,,,,,,,,,,,,,,,,,
,3832343368.997,294.813903808594,9999.8056640625,0.000203363618417931,3.53517039609427E-8,1,2,13.4005146026611,4.9929305220755,32.5599983334541,0.270427558429179,0.0402488544659738,1,1.79543600299473E-6,,,,,,,,,,,,,,,,,,,,,294.764434814453,294.863372802734,9999.8056640625,9999.8056640625,47.097026426255,5.2710618089281,9.23071193695068,27,1,0,0,1,0.2783203125,38.6119270324707,2,1,1,294.863372802734,0,294.813903808594,,,,,,,,,,,,,,,,,,,,,,,,,,,,,,,,,
,3832343425.33387,297.663375854492,9999.8056640625,0.000200304073045163,2.85244113910793E-8,1,2,13.4005146026611,4.99292738958836,32.5700007379055,0.266341731896831,0.0397655515803657,1,1.86025371766839E-6,,,,,,,,,,,,,,,,,,,,,297.620880126953,297.705871582031,9999.8056640625,9999.8056640625,47.1255558672069,5.27096999085783,9.22114849090576,27,1,0,0,1,0.274810791015625,38.6119270324707,2,1,1,297.705871582031,0,297.663375854492,,,,,,,,,,,,,,,,,,,,,,,,,,,,,,,,,
,3832343481.70506,299.642349243164,9999.8056640625,0.000198676519955657,2.42565560319619E-8,1,2,13.4005146026611,4.9928563615159,32.5799994170666,0.264195621004133,0.0392759228292751,1,1.72064565673338E-6,,,,,,,,,,,,,,,,,,,,,299.631896972656,299.652801513672,9999.8056640625,9999.8056640625,47.2283400174858,5.27160569899927,9.20016574859619,27,1,0,0,1,0.276641845703125,38.6119270324707,5,1,1,299.652801513672,0,299.642349243164,,,,,,,,,,,,,,,,,,,,,,,,,,,,,,,,,
,3832343532.1697,299.893127441406,9999.8056640625,0.000198449043473882,2.59374355029232E-8,1,2,13.4005146026611,4.99290573094389,32.5799994170666,0.263886522737362,0.0393042979321166,1,1.77336419539698E-6,,,,,,,,,,,,,,,,,,,,,299.891052246094,299.895202636719,9999.8056640625,9999.8056640625,47.17323520688,5.27131370003656,9.18054580688477,27,1,0,0,1,0.28778076171875,38.6119270324707,1,1,1,299.895202636719,0,299.893127441406,,,,,,,,,,,,,,,,,,,,,,,,,,,,,,,,,