File: SI Fig S11-13 SQUID all/Michaela_La_ZFC1T_00001.dat
[Header]
; MPMS3 Data File (default extension .dat)
; Copyright (c) 2007, Quantum Design, Inc. All rights reserved.
TITLE,
FILEOPENTIME,3834155537.61898,06/29/2021,7:13 pm
BYAPP,MPMS3 w/ AC,1.0,1.1
INFO,MPMS3 Measurement Release 1.1.16 Build 424, MultiVu Release 2.3.4.19,APPNAME
INFO,Linear Motor Servo Controller,MOTOR_MODULE_NAME
INFO,3101-100 E1,MOTOR_HW_VERSION
INFO,MMC211,MOTOR_SERIAL_NUMBER
INFO,01.04.28,MOTOR_SOFTWARE_VERSION
INFO,Quantum Design Squid Module,SQUID_MODULE_NAME
INFO,3101-501 B0,SQUID_HW_VERSION
INFO,SQM059,SQUID_SERIAL_NUMBER
INFO,01.03.04,SQUID_SOFTWARE_VERSION
INFO,SQUID AC,AC_MODULE_NAME
INFO,3101-401 F1,AC_HW_VERSION
INFO,SAC057,AC_SERIAL_NUMBER
INFO,SQUID AC 00.95.07,AC_SOFTWARE_VERSION
INFO,TCIXXX,COIL_SERIAL_NUMBER
INFO,0,MOMENT_UNITS
INFO,La_02,SAMPLE_MATERIAL
INFO,La_02,SAMPLE_COMMENT
INFO,0.07,SAMPLE_MASS
INFO,,SAMPLE_VOLUME
INFO,,SAMPLE_MOLECULAR_WEIGHT
INFO,,SAMPLE_SIZE
INFO,,SAMPLE_SHAPE
INFO,Straw,SAMPLE_HOLDER
INFO,Standard,SAMPLE_HOLDER_DETAIL
INFO,58.69,SAMPLE_OFFSET
DATATYPE,COMMENT,1
DATATYPE,TIME,2
STARTUPAXIS,X,2
STARTUPAXIS,Y1,5
FIELDGROUP, VSM,2,3,4,5,6,8,9,10,11,14,15
FIELDGROUP, DC, 2,3,4,14,56,57,58,59,60,61,62,63,64,65,66,67,68,69
FIELDGROUP, AC, 2,3,4,11,16,17,18,19,20,21,22,23,24,25,26,27,28,29,30
STARTUPGROUP, All
[Data]
Comment,Time Stamp (sec),Temperature (K),Magnetic Field (Oe),Moment (emu),M. Std. Err. (emu),Transport Action,Averaging Time (sec),Frequency (Hz),Peak Amplitude (mm),Center Position (mm),Lockin Signal' (V),Lockin Signal (V),Range,M. Quad. Signal (emu),AC Moment (emu),AC M. Std Err. (emu),AC Phase (deg),AC Phase Std. Err. (deg),AC Susceptibility (emu/Oe),AC Suscept. Std Err. (emu/Oe),AC X' (emu/Oe),AC X' Std Err. (emu/Oe),AC X'' (emu/Oe),AC X'' Std Err. (emu/Oe),AC Drive (Oe),AC Frequency (Hz),AC Averaging Time (sec),AC Cycles,AC Range,AC Measure Type,AC Signal' (V),AC Signal'' (V),AC Trim Coil Ratio,AC Trim Coil Phase,Min. Temperature (K),Max. Temperature (K),Min. Field (Oe),Max. Field (Oe),Mass (grams),Motor Lag (deg),Pressure (Torr),Measure Count,Measurement Number,SQUID Status (code),Motor Status (code),Measure Status (code),Motor Current (amps),Motor Temp. (C),Temp. Status (code),Field Status (code),Chamber Status (code),Chamber Temp (K),Redirection State,Average Temp (K),Rotation Angle (deg),Rotator state,DC Moment Fixed Ctr (emu),DC Moment Err Fixed Ctr (emu),DC Moment Free Ctr (emu),DC Moment Err Free Ctr (emu),DC Fixed Fit,DC Free Fit,DC Calculated Center (mm),DC Calculated Center Err (mm),DC Scan Length (mm),DC Scan Time (s),DC Number of Points,DC Squid Drift,DC Min V (V),DC Max V (V),DC Scans per Measure,Map 01,Map 02,Map 03,Map 04,Map 05,Map 06,Map 07,Map 08,Map 09,Map 10,Map 11,Map 12,Map 13,Map 14,Map 15,Map 16
,3834155557.2659,7.99890279769897,9999.53125,-9.85244182599796E-5,6.85103494826231E-7,1,2,13.4005146026611,4.97473398468424,27.4599995464087,-0.130330442078427,-0.0196158062541659,1,-1.03118326218057E-6,,,,,,,,,,,,,,,,,,,,,7.99890279769897,7.99890279769897,9999.53125,9999.53125,46.5494956485338,5.25480453340625,3.77122282981873,27,1,0,0,1,0.274734497070313,35.6793746948242,1,1,1,7.99890279769897,0,7.99890279769897,,,,,,,,,,,,,,,,,,,,,,,,,,,,,,,,,
,3834155589.98765,10.1776585578918,9999.53125,-0.000110935556240392,5.5731484673878E-8,1,2,13.4005146026611,4.98555023751321,27.4599995464087,-0.147220582578016,-0.0219091091862031,1,-9.77691082473045E-7,,,,,,,,,,,,,,,,,,,,,10.1049690246582,10.2503480911255,9999.53125,9999.53125,46.7081662379376,5.25994746356247,3.99301028251648,27,1,0,0,1,0.2728271484375,35.6793746948242,6,1,1,10.2503480911255,0,10.1776585578918,,,,,,,,,,,,,,,,,,,,,,,,,,,,,,,,,
,3834155624.19785,12.8134889602661,9999.53125,-0.000113400690241968,5.21388006354043E-8,1,2,13.4005146026611,4.98541904645333,27.4599995464087,-0.150488432418876,-0.0223819327173618,1,-9.8946903196817E-7,,,,,,,,,,,,,,,,,,,,,12.7440233230591,12.8829545974731,9999.53125,9999.53125,46.6737745830915,5.26072637283909,4.19576406478882,27,1,0,0,1,0.274581909179687,36.6568908691406,6,1,1,12.8829545974731,0,12.8134889602661,,,,,,,,,,,,,,,,,,,,,,,,,,,,,,,,,
,3834155666.7117,16.2235813140869,9999.53125,-0.000115530306962365,3.25158353779876E-8,1,2,13.4005146026611,4.98530044391503,27.4599995464087,-0.153292848954062,-0.0229208633912867,1,-1.09788167980579E-6,,,,,,,,,,,,,,,,,,,,,16.1361389160156,16.3110237121582,9999.53125,9999.53125,46.5979566167261,5.26188102597531,4.40103769302368,27,1,0,0,1,0.273818969726562,36.6568908691406,2,1,1,16.3110237121582,0,16.2235813140869,,,,,,,,,,,,,,,,,,,,,,,,,,,,,,,,,
,3834155701.05841,18.9239835739136,9999.53125,-0.000116493904072053,3.01468854658106E-8,1,2,13.4005146026611,4.98523318113286,27.4599995464087,-0.154578594283198,-0.023039763507036,1,-1.0529617961468E-6,,,,,,,,,,,,,,,,,,,,,18.8680591583252,18.979907989502,9999.53125,9999.53125,46.6843265681011,5.26209221772603,4.54695177078247,26,1,64,0,0,0.2764892578125,36.6568908691406,2,1,1,18.979907989502,0,18.9239835739136,,,,,,,,,,,,,,,,,,,,,,,,,,,,,,,,,
,3834155733.15554,21.4883975982666,9999.53125,-0.000117471169399986,3.12730450710042E-8,1,2,13.4005146026611,4.98520781343024,27.4599995464087,-0.155876678608545,-0.0232156059652585,1,-1.04879222723809E-6,,,,,,,,,,,,,,,,,,,,,21.4342861175537,21.5425090789795,9999.53125,9999.53125,46.6612685267838,5.26275094762373,4.67204332351685,27,1,0,0,1,0.276565551757813,37.1456527709961,2,1,1,21.5425090789795,0,21.4883975982666,,,,,,,,,,,,,,,,,,,,,,,,,,,,,,,,,
,3834155767.34386,24.1618146896362,9999.53125,-0.000117978461921211,2.99262216609391E-8,1,2,13.4005146026611,4.98513064544121,27.4599995464087,-0.156553219280796,-0.0232672970272131,1,-1.01714025737051E-6,,,,,,,,,,,,,,,,,,,,,24.0796699523926,24.2439594268799,9999.53125,9999.53125,46.6718205117934,5.261965130633,4.77543878555298,27,1,0,0,1,0.275497436523438,37.1456527709961,2,1,1,24.2439594268799,0,24.1618146896362,,,,,,,,,,,,,,,,,,,,,,,,,,,,,,,,,
,3834155799.53146,26.7191467285156,9999.53125,-0.000118663145721733,4.09915716965609E-8,1,2,13.4005146026611,4.98504501043439,27.4599995464087,-0.157454989950827,-0.023423725818104,1,-1.03956474443321E-6,,,,,,,,,,,,,,,,,,,,,26.6284675598145,26.8098258972168,9999.53125,9999.53125,46.7167641516492,5.26251293210872,4.86434698104858,27,1,0,0,1,0.274276733398438,37.1456527709961,2,1,1,26.8098258972168,0,26.7191467285156,,,,,,,,,,,,,,,,,,,,,,,,,,,,,,,,,
,3834155831.88212,29.2822208404541,9999.53125,-0.000119120566838726,3.08138832643617E-8,1,2,13.4005146026611,4.98511325673463,27.4599995464087,-0.158074218845942,-0.0234479161799802,1,-9.9348411437612E-7,,,,,,,,,,,,,,,,,,,,,29.1860542297363,29.3783874511719,9999.53125,9999.53125,46.6440726993607,5.26260373106719,4.93547058105469,27,1,0,0,1,0.276031494140625,37.1456527709961,2,1,1,29.3783874511719,0,29.2822208404541,,,,,,,,,,,,,,,,,,,,,,,,,,,,,,,,,
,3834155863.97673,31.8495216369629,9999.53125,-0.000119439911124446,2.83042184713614E-8,1,2,13.4005146026611,4.98505785458328,27.4700000882149,-0.158486720980712,-0.0235737423830493,1,-1.04381216230631E-6,,,,,,,,,,,,,,,,,,,,,31.7455921173096,31.9534511566162,9999.53125,9999.53125,46.6905795962549,5.26244257763848,7.31259822845459,27,1,0,0,1,0.27313232421875,37.1456527709961,2,1,1,31.9534511566162,0,31.8495216369629,,,,,,,,,,,,,,,,,,,,,,,,,,,,,,,,,
,3834155898.39092,34.6195125579834,9999.53125,-0.000119597938784979,2.63280072385255E-8,1,2,13.4005146026611,4.98505376445647,27.4700000882149,-0.158725368066451,-0.0233965236332611,1,-8.88342608015883E-7,,,,,,,,,,,,,,,,,,,,,34.5602607727051,34.6787643432617,9999.53125,9999.53125,46.6745562116107,5.26288823821278,7.40398502349854,27,1,0,0,1,0.274734497070313,37.1456527709961,2,1,1,34.6787643432617,0,34.6195125579834,,,,,,,,,,,,,,,,,,,,,,,,,,,,,,,,,
,3834155930.47949,37.1686611175537,9999.53125,-0.000119974222238254,2.63167454115422E-8,1,2,13.4005146026611,4.98497285947931,27.4700000882149,-0.159192320163983,-0.0236762308751947,1,-1.04666453016328E-6,,,,,,,,,,,,,,,,,,,,,37.1082992553711,37.2290229797363,9999.53125,9999.53125,46.6190605867453,5.26324943009204,7.45521974563599,27,1,0,0,1,0.282440185546875,37.1456527709961,2,1,1,37.2290229797363,0,37.1686611175537,,,,,,,,,,,,,,,,,,,,,,,,,,,,,,,,,
,3834155962.83806,39.7394390106201,9999.53125,-0.000120170669821708,2.80547284675866E-8,1,2,13.4005146026611,4.9849273519886,27.4800006300211,-0.159478988112129,-0.0235144367934422,1,-8.97632318714195E-7,,,,,,,,,,,,,,,,,,,,,39.6721572875977,39.8067207336426,9999.53125,9999.53125,46.7191090372069,5.26306817107927,7.51190376281738,27,1,0,0,1,0.274124145507813,37.1456527709961,2,1,1,39.8067207336426,0,39.7394390106201,,,,,,,,,,,,,,,,,,,,,,,,,,,,,,,,,
,3834155994.94948,42.3128452301025,9999.53125,-0.000120458291324666,2.76270846227001E-8,1,2,13.4005146026611,4.98486690978203,27.4700000882149,-0.159841038208871,-0.0236918652819196,1,-9.91269640653157E-7,,,,,,,,,,,,,,,,,,,,,42.2260360717773,42.3996543884277,9999.53125,9999.53125,46.5952209169088,5.26293540063153,7.57372856140137,27,1,0,0,1,0.27374267578125,37.1456527709961,2,1,1,42.3996543884277,0,42.3128452301025,,,,,,,,,,,,,,,,,,,,,,,,,,,,,,,,,
,3834156029.51695,45.1263332366943,9999.53125,-0.000120443905235761,2.99623600957328E-8,1,2,13.4005146026611,4.9848383430442,27.4800006300211,-0.159831274068356,-0.0236131668476465,1,-9.34180972237431E-7,,,,,,,,,,,,,,,,,,,,,45.0747375488281,45.1779289245605,9999.53125,9999.53125,46.7222355512838,5.26385213070993,7.61239385604858,27,1,0,0,1,0.272293090820313,37.1456527709961,2,1,1,45.1779289245605,0,45.1263332366943,,,,,,,,,,,,,,,,,,,,,,,,,,,,,,,,,
,3834156061.46638,47.6749229431152,9999.53125,-0.000120767530229034,2.64140727588806E-8,1,2,13.4005146026611,4.9848030126956,27.4800006300211,-0.160235918870439,-0.0238426878359914,1,-1.06187806270363E-6,,,,,,,,,,,,,,,,,,,,,47.5956001281738,47.7542457580566,9999.53125,9999.53125,46.6237503578607,5.26374575162139,7.66863203048706,27,1,0,0,1,0.272369384765625,37.1456527709961,2,1,1,47.7542457580566,0,47.6749229431152,,,,,,,,,,,,,,,,,,,,,,,,,,,,,,,,,
,3834156095.66235,50.435619354248,9999.53125,-0.00012082786766236,2.92216143505383E-8,1,2,13.4005146026611,4.98478600647912,27.4800006300211,-0.160316621254964,-0.0238445014931185,1,-1.05489085136631E-6,,,,,,,,,,,,,,,,,,,,,50.3421363830566,50.5291023254395,9999.53125,9999.53125,46.7245804368415,5.2635955430562,7.71009874343872,27,1,0,0,1,0.27252197265625,37.1456527709961,2,1,1,50.5291023254395,0,50.435619354248,,,,,,,,,,,,,,,,,,,,,,,,,,,,,,,,,
,3834156127.96697,53.0540561676025,9999.53125,-0.00012105752268438,2.9846008919275E-8,1,2,13.4005146026611,4.9847100260669,27.4800006300211,-0.160646387975365,-0.0236860947313884,1,-9.03910316914102E-7,,,,,,,,,,,,,,,,,,,,,52.9915504455566,53.1165618896484,9999.53125,9999.53125,46.6655674836396,5.26403342496819,7.76272535324097,27,1,0,0,1,0.2728271484375,37.1456527709961,2,1,1,53.1641082763672,0,53.0540561676025,,,,,,,,,,,,,,,,,,,,,,,,,,,,,,,,,
,3834156160.12698,55.6835346221924,9999.53125,-0.000121027743739551,3.52051424059359E-8,1,2,13.4005146026611,4.98472906032414,27.4899993091822,-0.160589741305029,-0.0238089187219423,1,-1.00043940172302E-6,,,,,,,,,,,,,,,,,,,,,55.6076126098633,55.7594566345215,9999.53125,9999.53125,46.6917520390338,5.26437688244298,7.80398607254028,27,1,0,0,1,0.277481079101562,37.1456527709961,2,1,1,55.7594566345215,0,55.6835346221924,,,,,,,,,,,,,,,,,,,,,,,,,,,,,,,,,
,3834156190.41975,58.1288337707519,9999.53125,-0.000121287341000565,2.29521475949611E-8,1,2,13.4005146026611,4.9846761851248,27.4899993091822,-0.160919803499124,-0.0239458266023006,1,-1.06746520058561E-6,,,,,,,,,,,,,,,,,,,,,58.0416717529297,58.2159957885742,9999.53125,9999.53125,46.7116835662742,5.26441155361219,7.83499431610107,27,1,0,0,1,0.274276733398438,37.1456527709961,2,1,1,58.2159957885742,0,58.1288337707519,,,,,,,,,,,,,,,,,,,,,,,,,,,,,,,,,
,3834156224.62178,60.8775806427002,9999.53125,-0.000121432529831283,2.60873824267825E-8,1,2,13.4005146026611,4.98462961509771,27.4999998509884,-0.161121714748193,-0.0238930433247065,1,-1.0076607506761E-6,,,,,,,,,,,,,,,,,,,,,60.8031959533691,60.9519653320312,9999.53125,9999.53125,46.7191090372069,5.26469514977548,7.87058591842651,27,1,0,0,1,0.273971557617187,37.6344108581543,2,1,1,60.9519653320312,0,60.8775806427002,,,,,,,,,,,,,,,,,,,,,,,,,,,,,,,,,
,3834156257.23272,63.5490112304687,9999.53125,-0.000121691495209274,2.56850881544992E-8,1,2,13.4005146026611,4.98464540181675,27.4999998509884,-0.161495120896202,-0.0237359903174625,1,-8.53145379513515E-7,,,,,,,,,,,,,,,,,,,,,63.4447021484375,63.6533203125,9999.53125,9999.53125,46.6530614273319,5.26517105537439,7.89703607559204,27,1,0,0,1,0.277023315429687,37.6344108581543,2,1,1,63.6533203125,0,63.5490112304687,,,,,,,,,,,,,,,,,,,,,,,,,,,,,,,,,
,3834156291.07977,66.2554779052734,9999.53125,-0.000121766310868424,2.5534772472726E-8,1,2,13.4005146026611,4.98458967386319,27.4999998509884,-0.161562928037548,-0.0239576305646011,1,-1.0098101734412E-6,,,,,,,,,,,,,,,,,,,,,66.1769180297852,66.3340377807617,9999.53125,9999.53125,46.7964902606107,5.26449148282477,7.93070125579834,27,1,0,0,1,0.276947021484375,37.6344108581543,2,1,1,66.3340377807617,0,66.2554779052734,,,,,,,,,,,,,,,,,,,,,,,,,,,,,,,,,
,3834156321.67558,68.7840232849121,9999.53125,-0.000121898540356327,2.78462221737469E-8,1,2,13.4005146026611,4.98457069570899,27.5100003927946,-0.161768338088103,-0.023763174586519,1,-8.45027963905993E-7,,,,,,,,,,,,,,,,,,,,,68.6704864501953,68.8975601196289,9999.53125,9999.53125,46.7257528796203,5.26475239580225,7.9588942527771,27,1,0,0,1,0.276107788085938,37.6344108581543,2,1,1,68.8975601196289,0,68.7840232849121,,,,,,,,,,,,,,,,,,,,,,,,,,,,,,,,,
,3834156355.65504,71.5447769165039,9999.53125,-0.000122078508927688,2.4931510410238E-8,1,2,13.4005146026611,4.9845620349934,27.5100003927946,-0.16196868028772,-0.0240707132350955,1,-1.05142499453861E-6,,,,,,,,,,,,,,,,,,,,,71.4740753173828,71.615478515625,9999.53125,9999.53125,46.7753862905915,5.2648069796229,7.9802098274231,25,1,64,0,0,0.274810791015625,37.6344108581543,2,1,1,71.615478515625,0,71.5447769165039,,,,,,,,,,,,,,,,,,,,,,,,,,,,,,,,,
,3834156386.24785,74.0105934143066,9999.53125,-0.000122228561227852,3.86351762009393E-8,1,2,13.4005146026611,4.98451104676122,27.5100003927946,-0.162184892520838,-0.0239611746881528,1,-9.48236008856849E-7,,,,,,,,,,,,,,,,,,,,,73.9130477905273,74.1081390380859,9999.53125,9999.53125,46.6917520390338,5.26441995108285,7.99223518371582,27,1,0,0,1,0.273284912109375,37.6344108581543,2,1,1,74.1081390380859,0,74.0105934143066,,,,,,,,,,,,,,,,,,,,,,,,,,,,,,,,,
,3834156420.05662,76.7652778625488,9999.53125,-0.000122090718949459,3.50824192904833E-8,1,2,13.4005146026611,4.98450558405363,27.5199990719557,-0.161998136317884,-0.02395993428431,1,-9.66602678938541E-7,,,,,,,,,,,,,,,,,,,,,76.6845703125,76.8459854125977,9999.53125,9999.53125,46.7570180203896,5.26511240550142,8.00970077514648,27,1,0,0,1,0.2764892578125,37.6344108581543,2,1,1,76.8459854125977,0,76.7652778625488,,,,,,,,,,,,,,,,,,,,,,,,,,,,,,,,,
,3834156454.29689,79.5963478088379,9999.53125,-0.000122381645030602,2.35071616416685E-8,1,2,13.4005146026611,4.98450547842644,27.5199990719557,-0.162382194896605,-0.0240310225775369,1,-9.79442165998873E-7,,,,,,,,,,,,,,,,,,,,,79.5098266601562,79.6828689575195,9999.53125,9999.53125,46.7558455776107,5.26515896043849,8.0286111831665,27,1,0,0,1,0.274276733398438,37.6344108581543,2,1,1,79.6828689575195,0,79.5963478088379,,,,,,,,,,,,,,,,,,,,,,,,,,,,,,,,,
,3834156489.87373,82.4587326049805,9999.53125,-0.000122343866011996,3.18227284075178E-8,1,2,13.4005146026611,4.98448489685274,27.5299996137619,-0.162338510001024,-0.0239708152565911,1,-9.39501417333853E-7,,,,,,,,,,,,,,,,,,,,,82.3365859985352,82.5808792114258,9999.53125,9999.53125,46.7347416075915,5.26516012091422,8.05112743377686,27,1,0,0,1,0.274505615234375,37.6344108581543,2,1,1,82.5808792114258,0,82.4587326049805,,,,,,,,,,,,,,,,,,,,,,,,,,,,,,,,,
,3834156523.00399,85.1827774047852,9999.53125,-0.000122476186159474,3.1652118553647E-8,1,2,13.4005146026611,4.98443511814256,27.5299996137619,-0.16248623996301,-0.0241796380545453,1,-1.07845668819167E-6,,,,,,,,,,,,,,,,,,,,,85.0860900878906,85.2794647216797,9999.53125,9999.53125,46.7261436938799,5.2649837294339,8.06404590606689,27,1,0,0,1,0.272750854492187,37.6344108581543,2,1,1,85.2794647216797,0,85.1827774047852,,,,,,,,,,,,,,,,,,,,,,,,,,,,,,,,,
,3834156557.06392,87.9832420349121,9999.53125,-0.000122463607057412,3.20885193188553E-8,1,2,13.4005146026611,4.98440315818862,27.5299996137619,-0.162481588804744,-0.0240806280872298,1,-1.00583682260463E-6,,,,,,,,,,,,,,,,,,,,,87.9131622314453,88.0533218383789,9999.53125,9999.53125,46.6995683242261,5.26505886736245,8.073410987854,27,1,0,0,1,0.272064208984375,37.6344108581543,2,1,1,88.0533218383789,0,87.9832420349121,,,,,,,,,,,,,,,,,,,,,,,,,,,,,,,,,
,3834156589.4981,90.6418609619141,9999.53125,-0.000122521947532065,2.96685920176045E-8,1,2,13.4005146026611,4.98440268732137,27.5400001555681,-0.162554446412682,-0.0241244663335078,1,-1.03068518585298E-6,,,,,,,,,,,,,,,,,,,,,90.5799331665039,90.7037887573242,9999.53125,9999.53125,46.7269253223992,5.26559742872641,8.1041259765625,27,1,0,0,1,0.273895263671875,37.6344108581543,2,1,1,90.7037887573242,0,90.6418609619141,,,,,,,,,,,,,,,,,,,,,,,,,,,,,,,,,
,3834156623.639,93.4894905090332,9999.53125,-0.000122683807404749,2.22444638139481E-8,1,2,13.4005146026611,4.98438251493243,27.5400001555681,-0.162756306153649,-0.0242418959503828,1,-1.0965609788951E-6,,,,,,,,,,,,,,,,,,,,,93.4006042480469,93.5783767700195,9999.53125,9999.53125,46.7210631085049,5.26558990079386,8.11152362823486,27,1,0,0,1,0.273361206054687,37.6344108581543,2,1,1,93.5783767700195,0,93.4894905090332,,,,,,,,,,,,,,,,,,,,,,,,,,,,,,,,,
,3834156653.95718,96.0227470397949,9999.53125,-0.000122717613397777,2.67433174097911E-8,1,2,13.4005146026611,4.9844093572452,27.5500006973743,-0.162810335465359,-0.0241916960420009,1,-1.05390676153545E-6,,,,,,,,,,,,,,,,,,,,,95.9691619873047,96.0763320922852,9999.53125,9999.53125,46.6765102829088,5.26499587999026,8.14335918426514,27,1,0,0,1,0.2728271484375,37.6344108581543,2,1,1,96.0763320922852,0,96.0227470397949,,,,,,,,,,,,,,,,,,,,,,,,,,,,,,,,,
,3834156688.12921,98.8390426635742,9999.53125,-0.000122801553644311,1.92852484340036E-8,1,2,13.4005146026611,4.98435754798395,27.5500006973743,-0.162937602622319,-0.0240775402273606,1,-9.56487495411815E-7,,,,,,,,,,,,,,,,,,,,,98.7533721923828,98.9247131347656,9999.53125,9999.53125,46.7327875362934,5.26528298301767,8.1554536819458,27,1,0,0,1,0.272979736328125,37.6344108581543,2,1,1,98.9247131347656,0,98.8390426635742,,,,,,,,,,,,,,,,,,,,,,,,,,,,,,,,,
,3834156720.64044,101.504493713379,9999.53125,-0.000122779914449231,3.55920287630562E-8,1,2,13.4005146026611,4.98433276664784,27.5599993765354,-0.162930582734523,-0.0239100451336998,1,-8.33537008059299E-7,,,,,,,,,,,,,,,,,,,,,101.465614318848,101.54337310791,9999.53125,9999.53125,46.6835449395819,5.26559650409189,8.18011665344238,26,1,64,0,0,0.27313232421875,37.6344108581543,2,1,1,101.54337310791,0,101.504493713379,,,,,,,,,,,,,,,,,,,,,,,,,,,,,,,,,
,3834156754.6105,104.379421234131,9999.53125,-0.000122945578195215,2.92242166589645E-8,1,2,13.4005146026611,4.98435753361734,27.5699999183416,-0.163113746365116,-0.024212719771612,1,-1.03811992763054E-6,,,,,,,,,,,,,,,,,,,,,104.304847717285,104.453994750977,9999.53125,9999.53125,46.6710388832742,5.26492279592279,8.18741226196289,27,1,0,0,1,0.27435302734375,37.6344108581543,2,1,1,104.453994750977,0,104.379421234131,,,,,,,,,,,,,,,,,,,,,,,,,,,,,,,,,
,3834156786.78443,106.992347717285,9999.53125,-0.00012291578321799,2.54590754142523E-8,1,2,13.4005146026611,4.98431244003045,27.5699999183416,-0.163111104369879,-0.0239282542635442,1,-8.28349281306708E-7,,,,,,,,,,,,,,,,,,,,,106.92667388916,107.05802154541,9999.53125,9999.53125,46.7464660353799,5.26551001113151,8.19332599639893,27,1,0,0,1,0.274124145507813,37.6344108581543,2,1,1,107.05802154541,0,106.992347717285,,,,,,,,,,,,,,,,,,,,,,,,,,,,,,,,,
,3834156819.08266,109.698348999023,9999.53125,-0.000122936738367316,2.86765363661585E-8,1,2,13.4005146026611,4.98430193226918,27.5800004601479,-0.163097425134022,-0.024225602811762,1,-1.0493341357758E-6,,,,,,,,,,,,,,,,,,,,,109.624114990234,109.772583007813,9999.53125,9999.53125,46.7366956788896,5.26479660191527,8.21251487731934,27,1,0,0,1,0.2728271484375,37.6344108581543,2,1,1,109.772583007813,0,109.698348999023,,,,,,,,,,,,,,,,,,,,,,,,,,,,,,,,,
,3834156851.20751,112.325710296631,9999.53125,-0.000122954328921939,3.29888375284082E-8,1,2,13.4005146026611,4.98429099276872,27.5800004601479,-0.163163320430933,-0.023921106998987,1,-8.17685201043882E-7,,,,,,,,,,,,,,,,,,,,,112.246322631836,112.405097961426,9999.53125,9999.53125,46.6905795962549,5.2651642683078,8.22109889984131,27,1,0,0,1,0.27618408203125,37.6344108581543,2,1,1,112.405097961426,0,112.325710296631,,,,,,,,,,,,,,,,,,,,,,,,,,,,,,,,,
,3834156885.75028,115.200344085693,9999.53125,-0.000123086385067261,2.67043605135453E-8,1,2,13.4005146026611,4.98426483672337,27.5899991393089,-0.163305626116503,-0.0241737708050899,1,-9.89573751894253E-7,,,,,,,,,,,,,,,,,,,,,115.14631652832,115.254371643066,9999.53125,9999.53125,46.6788551684665,5.26488818991687,8.22213459014893,27,1,0,0,1,0.273208618164062,37.6344108581543,2,1,1,115.254371643066,0,115.200344085693,,,,,,,,,,,,,,,,,,,,,,,,,,,,,,,,,
,3834156917.70689,117.808837890625,9999.53125,-0.000122958509354304,2.50331168225418E-7,1,2,13.4005146026611,4.984238314876,27.5999996811152,-0.163103136641015,-0.0243747564535283,1,-1.15890376132269E-6,,,,,,,,,,,,,,,,,,,,,117.718490600586,117.899185180664,9999.53125,9999.53125,46.7226263655434,5.26373003237142,8.24365997314453,27,1,0,0,1,0.272598266601562,37.6344108581543,2,1,1,117.899185180664,0,117.808837890625,,,,,,,,,,,,,,,,,,,,,,,,,,,,,,,,,
,3834156950.21804,120.517185211182,9999.53125,-0.00012318917565754,3.59138932261074E-8,1,2,13.4005146026611,4.98421667252336,27.5999996811152,-0.163451511403429,-0.0241101414776535,1,-9.27537447483798E-7,,,,,,,,,,,,,,,,,,,,,120.462783813477,120.571586608887,9999.53125,9999.53125,46.707775423678,5.2641365596097,8.24333381652832,27,1,0,0,1,0.271987915039062,37.6344108581543,2,1,1,120.571586608887,0,120.517185211182,,,,,,,,,,,,,,,,,,,,,,,,,,,,,,,,,
,3834156982.18742,123.198307037354,9999.53125,-0.00012298368714893,3.00844649756065E-8,1,2,13.4005146026611,4.98418522916756,27.6100002229214,-0.163182709718873,-0.0240320962628984,1,-8.97667108384369E-7,,,,,,,,,,,,,,,,,,,,,123.127815246582,123.268798828125,9999.53125,9999.53125,46.6858898251396,5.26355918476682,8.24674415588379,27,1,0,0,1,0.274429321289062,37.6344108581543,2,1,1,123.268798828125,0,123.198307037354,,,,,,,,,,,,,,,,,,,,,,,,,,,,,,,,,
,3834157016.41965,126.057140350342,9999.53125,-0.00012314573326455,3.51848958474025E-8,1,2,13.4005146026611,4.98417646806637,27.6200007647276,-0.163404873042222,-0.024009747570173,1,-8.5822710159811E-7,,,,,,,,,,,,,,,,,,,,,125.969863891602,126.144416809082,9999.53125,9999.53125,46.7546731348319,5.26384025823167,8.24734401702881,27,1,0,0,1,0.272216796875,37.6344108581543,2,1,1,126.144416809082,0,126.057140350342,,,,,,,,,,,,,,,,,,,,,,,,,,,,,,,,,
,3834157048.92862,128.732856750488,9999.53125,-0.000123210588330745,2.82819124250853E-8,1,2,13.4005146026611,4.98417903816051,27.6200007647276,-0.163492571202953,-0.0240115039976185,1,-8.50468557194465E-7,,,,,,,,,,,,,,,,,,,,,128.628402709961,128.837310791016,9999.53125,9999.53125,46.7218447370242,5.26398169088558,8.25903606414795,27,1,0,0,1,0.272369384765625,37.6344108581543,2,1,1,128.837310791016,0,128.732856750488,,,,,,,,,,,,,,,,,,,,,,,,,,,,,,,,,
,3834157080.90703,131.399429321289,9999.53125,-0.000123138979199334,4.83894592289769E-8,1,2,13.4005146026611,4.98422244444977,27.6399999856949,-0.163393324286131,-0.0240420271328554,1,-8.83245262946976E-7,,,,,,,,,,,,,,,,,,,,,131.329193115234,131.469665527344,9999.53125,9999.53125,46.738258935928,5.2632435078112,8.2565860748291,27,1,0,0,1,0.27313232421875,37.6344108581543,2,1,1,131.469665527344,0,131.399429321289,,,,,,,,,,,,,,,,,,,,,,,,,,,,,,,,,
,3834157113.41035,134.072319030762,9999.53125,-0.000123256400764404,2.9882911923512E-8,1,2,13.4005146026611,4.98416145411804,27.6399999856949,-0.163548587061067,-0.0240487982650822,1,-8.72229068192892E-7,,,,,,,,,,,,,,,,,,,,,133.961990356445,134.182647705078,9999.53125,9999.53125,46.7066029808992,5.26405811423871,8.27907562255859,27,1,0,0,1,0.27252197265625,37.6344108581543,2,1,1,134.182647705078,0,134.072319030762,,,,,,,,,,,,,,,,,,,,,,,,,,,,,,,,,
,3834157147.53436,136.956504821777,9999.53125,-0.000123164471551506,3.17241199354341E-8,1,2,13.4005146026611,4.98416851182087,27.6500005275011,-0.163429529372031,-0.0240122750043431,1,-8.57549562582536E-7,,,,,,,,,,,,,,,,,,,,,136.896240234375,137.01676940918,9999.53125,9999.53125,46.7648343055819,5.26410224594912,8.28491592407227,26,1,64,0,0,0.2740478515625,37.6344108581543,2,1,1,137.01676940918,0,136.956504821777,,,,,,,,,,,,,,,,,,,,,,,,,,,,,,,,,
,3834157180.94816,139.737937927246,9999.53125,-0.000123220334461682,2.74638996797534E-8,1,2,13.4005146026611,4.98416542412803,27.6599992066622,-0.163496711865996,-0.0240718089007909,1,-8.9457663695122E-7,,,,,,,,,,,,,,,,,,,,,139.593994140625,139.881881713867,9999.53125,9999.53125,46.7378681216684,5.26419496810176,8.30976486206055,27,1,0,0,1,0.270843505859375,37.6344108581543,2,1,1,139.881881713867,0,139.737937927246,,,,,,,,,,,,,,,,,,,,,,,,,,,,,,,,,
,3834157211.89248,142.206680297852,9999.53125,-0.000123326084481927,4.88455410189806E-8,1,2,13.4005146026611,4.98409257247134,27.6599992066622,-0.163633778220222,-0.0240917507006506,1,-8.95168332263467E-7,,,,,,,,,,,,,,,,,,,,,142.128036499023,142.28532409668,9999.53125,9999.53125,46.7617077915049,5.26418680667581,8.31234073638916,27,1,0,0,1,0.27191162109375,37.6344108581543,2,1,1,142.28532409668,0,142.206680297852,,,,,,,,,,,,,,,,,,,,,,,,,,,,,,,,,
,3834157245.36702,145.025650024414,9999.53125,-0.000123341343450264,2.19493482569332E-8,1,2,13.4005146026611,4.9840935457339,27.6699997484684,-0.163665248718119,-0.0240147757566232,1,-8.3507502303957E-7,,,,,,,,,,,,,,,,,,,,,144.877395629883,145.173904418945,9999.53125,9999.53125,46.6733837688319,5.2639497572259,8.34084701538086,27,1,0,0,1,0.274658203125,37.6344108581543,2,1,1,145.173904418945,0,145.025650024414,,,,,,,,,,,,,,,,,,,,,,,,,,,,,,,,,
,3834157278.58018,147.803329467773,9999.53125,-0.000123314784995817,2.29586338826288E-8,1,2,13.4005146026611,4.98411693733033,27.6800002902746,-0.163588603129317,-0.0243134194981209,1,-1.06352129935478E-6,,,,,,,,,,,,,,,,,,,,,147.697891235352,147.908767700195,9999.53125,9999.53125,46.7601445344665,5.26441869268899,8.34414672851562,27,1,0,0,1,0.2740478515625,37.6344108581543,2,1,1,147.908767700195,0,147.803329467773,,,,,,,,,,,,,,,,,,,,,,,,,,,,,,,,,
,3834157310.65498,150.441215515137,9999.53125,-0.000123315106045074,2.31956465925962E-8,1,2,13.4005146026611,4.98408216586123,27.6900008320808,-0.163626319163503,-0.0240353510292384,1,-8.54291534670395E-7,,,,,,,,,,,,,,,,,,,,,150.366226196289,150.516204833984,9999.53125,9999.53125,46.7234079940626,5.26462101238772,8.34860610961914,27,1,0,0,1,0.273056030273438,37.6344108581543,2,1,1,150.516204833984,0,150.441215515137,,,,,,,,,,,,,,,,,,,,,,,,,,,,,,,,,
,3834157343.0035,153.151695251465,9999.53125,-0.000123460534154363,2.77919280529555E-8,1,2,13.4005146026611,4.98403845769988,27.6999995112419,-0.1637917374125,-0.0242463413362019,1,-9.93033634631642E-7,,,,,,,,,,,,,,,,,,,,,153.053421020508,153.249969482422,9999.53125,9999.53125,46.6862806393992,5.26400707118222,8.3673677444458,27,1,0,0,1,0.271377563476562,37.6344108581543,2,1,1,153.249969482422,0,153.151695251465,,,,,,,,,,,,,,,,,,,,,,,,,,,,,,,,,
,3834157375.10687,155.77001953125,9999.53125,-0.000123381726625894,5.54114407861054E-8,1,2,13.4005146026611,4.98404617461854,27.7100000530481,-0.163694861288318,-0.0241785071290272,1,-9.52940387461516E-7,,,,,,,,,,,,,,,,,,,,,155.691513061523,155.848526000977,9999.53125,9999.53125,46.6937061103319,5.2644919268666,8.37839698791504,27,1,0,0,1,0.272674560546875,37.6344108581543,2,1,1,155.848526000977,0,155.77001953125,,,,,,,,,,,,,,,,,,,,,,,,,,,,,,,,,
,3834157409.49514,158.671615600586,9999.53125,-0.000123467467190194,3.08933091868226E-8,1,2,13.4005146026611,4.9840194476538,27.7200005948544,-0.163789799063244,-0.024321089837469,1,-1.04843956021223E-6,,,,,,,,,,,,,,,,,,,,,158.611389160156,158.731842041016,9999.53125,9999.53125,46.7343507933319,5.26450303480085,8.38500213623047,27,1,0,0,1,0.272903442382813,37.6344108581543,2,1,1,158.731842041016,0,158.671615600586,,,,,,,,,,,,,,,,,,,,,,,,,,,,,,,,,
,3834157443.66737,161.479187011719,9999.53125,-0.000123333222002664,5.57927494835915E-8,1,2,13.4005146026611,4.98402141351238,27.7299992740154,-0.163619920108002,-0.0242365862052567,1,-1.00357546814424E-6,,,,,,,,,,,,,,,,,,,,,161.389678955078,161.568695068359,9999.53125,9999.53125,46.6929244818126,5.26313505304904,8.38466358184814,27,1,0,0,1,0.272140502929687,37.6344108581543,2,1,1,161.568695068359,0,161.479187011719,,,,,,,,,,,,,,,,,,,,,,,,,,,,,,,,,
,3834157473.98269,164.009284973145,9999.53125,-0.000123358746018954,2.15258100842467E-8,1,2,13.4005146026611,4.98398240774179,27.7299992740154,-0.163683140716446,-0.0240187950023424,1,-8.362212800512E-7,,,,,,,,,,,,,,,,,,,,,163.938369750977,164.080200195313,9999.53125,9999.53125,46.7351324218511,5.26466131416375,8.39595890045166,27,1,0,0,1,0.271224975585938,37.6344108581543,2,1,1,164.080200195313,0,164.009284973145,,,,,,,,,,,,,,,,,,,,,,,,,,,,,,,,,
,3834157508.11995,166.844680786133,9999.53125,-0.000123446560522491,2.17559983123561E-8,1,2,13.4005146026611,4.98394434022316,27.7399998158216,-0.16378112941955,-0.0241558964324447,1,-9.27361225880982E-7,,,,,,,,,,,,,,,,,,,,,166.761657714844,166.927703857422,9999.53125,9999.53125,46.7577996489088,5.2650498292647,8.39236831665039,27,1,0,0,1,0.274200439453125,37.6344108581543,2,1,1,166.927703857422,0,166.844680786133,,,,,,,,,,,,,,,,,,,,,,,,,,,,,,,,,
,3834157540.28055,169.46842956543,9999.53125,-0.000123335375426809,3.60308394181705E-8,1,2,13.4005146026611,4.98396069681094,27.7500003576279,-0.16361070221307,-0.0243033982236497,1,-1.05388447870886E-6,,,,,,,,,,,,,,,,,,,,,169.394470214844,169.542388916016,9999.53125,9999.53125,46.7183274086876,5.26452157230558,8.39626789093018,27,1,0,0,1,0.272750854492187,37.6344108581543,2,1,1,169.542388916016,0,169.46842956543,,,,,,,,,,,,,,,,,,,,,,,,,,,,,,,,,
,3834157574.63187,172.366645812988,9999.53125,-0.000123513709730628,2.77734778880874E-8,1,2,13.4005146026611,4.98393859930893,27.7699995785952,-0.163862747168303,-0.0242205818309848,1,-9.66705175325486E-7,,,,,,,,,,,,,,,,,,,,,172.280563354492,172.452728271484,9999.53125,9999.53125,46.7640526770626,5.26409460356289,8.403151512146,27,1,0,0,1,0.272903442382813,37.6344108581543,2,1,1,172.452728271484,0,172.366645812988,,,,,,,,,,,,,,,,,,,,,,,,,,,,,,,,,
,3834157607.41665,175.052871704102,9999.53125,-0.000123461495143003,5.58180257257112E-8,1,2,13.4005146026611,4.98390087057828,27.7800001204014,-0.16379662112305,-0.0241754224708674,1,-9.40192800861157E-7,,,,,,,,,,,,,,,,,,,,,175.036773681641,175.068969726562,9999.53125,9999.53125,46.7187182229473,5.26309136545348,8.41640186309814,25,1,64,0,0,0.272445678710938,37.6344108581543,2,1,1,175.068969726562,0,175.052871704102,,,,,,,,,,,,,,,,,,,,,,,,,,,,,,,,,
,3834157639.09713,177.721374511719,9999.53125,-0.000123474976005142,2.2615911931617E-8,1,2,13.4005146026611,4.98389724580278,27.7800001204014,-0.163800895178749,-0.0242742143071764,1,-1.01271105936384E-6,,,,,,,,,,,,,,,,,,,,,177.643569946289,177.799179077148,9999.53125,9999.53125,46.7601445344665,5.26431215765289,8.40339374542236,27,1,0,0,1,0.271072387695313,37.6344108581543,2,1,1,177.799179077148,0,177.721374511719,,,,,,,,,,,,,,,,,,,,,,,,,,,,,,,,,
,3834157671.22736,180.329513549805,9999.53125,-0.000123338184175624,5.04288026874035E-8,1,2,13.4005146026611,4.98388298726532,27.7900006622076,-0.163613729401514,-0.0242833904332557,1,-1.0388184516199E-6,,,,,,,,,,,,,,,,,,,,,180.232559204102,180.426467895508,9999.53125,9999.53125,46.7144192660915,5.26498270536742,8.41087436676025,27,1,0,0,1,0.272979736328125,37.6344108581543,2,1,1,180.426467895508,0,180.329513549805,,,,,,,,,,,,,,,,,,,,,,,,,,,,,,,,,
,3834157703.55021,183.070007324219,9999.53125,-0.00012353251214575,2.63498905699631E-8,1,2,13.4005146026611,4.98388319066078,27.7999993413687,-0.163888006537201,-0.0242037658774039,1,-9.51692861742991E-7,,,,,,,,,,,,,,,,,,,,,183.005966186523,183.134048461914,9999.53125,9999.53125,46.6511073560338,5.26441065337745,8.41054725646973,27,1,0,0,1,0.2728271484375,37.6344108581543,2,1,1,183.134048461914,0,183.070007324219,,,,,,,,,,,,,,,,,,,,,,,,,,,,,,,,,
,3834157737.75423,185.892906188965,9999.53125,-0.000123506757186222,3.20878989180138E-8,1,2,13.4005146026611,4.98388602387636,27.8099998831749,-0.163843453531173,-0.024273921962579,1,-1.00810371715821E-6,,,,,,,,,,,,,,,,,,,,,185.809188842773,185.976623535156,9999.53125,9999.53125,46.6808092397646,5.26392768183876,8.43149375915527,27,1,0,0,1,0.272979736328125,38.1231689453125,2,1,1,185.976623535156,0,185.892906188965,,,,,,,,,,,,,,,,,,,,,,,,,,,,,,,,,
,3834157771.98072,188.787445068359,9999.53125,-0.000123535058230933,2.7601877443751E-8,1,2,13.4005146026611,4.98385813877521,27.8399996459484,-0.163873800463841,-0.0243217714582556,1,-1.04031547453344E-6,,,,,,,,,,,,,,,,,,,,,188.701568603516,188.873321533203,9999.53125,9999.53125,46.8644919417838,5.26439177338217,8.421555519104,27,1,0,0,1,0.273666381835938,38.1231689453125,2,1,1,188.873321533203,0,188.787445068359,,,,,,,,,,,,,,,,,,,,,,,,,,,,,,,,,
,3834157804.49104,191.426345825195,9999.53125,-0.000123556137849141,2.79634897547525E-8,1,2,13.4005146026611,4.98385161444614,27.8399996459484,-0.16392963212249,-0.0241244555257562,1,-8.88830699477126E-7,,,,,,,,,,,,,,,,,,,,,191.313705444336,191.538986206055,9999.53125,9999.53125,46.7796852474473,5.26459342655002,8.42533206939697,27,1,0,0,1,0.272750854492187,37.6344108581543,2,1,1,191.538986206055,0,191.426345825195,,,,,,,,,,,,,,,,,,,,,,,,,,,,,,,,,
,3834157836.43416,194.078918457031,9999.53125,-0.000123403716651758,2.53020852458324E-8,1,2,13.4005146026611,4.9838490147781,27.8600007295609,-0.163690242573287,-0.0243596269844901,1,-1.08722947026424E-6,,,,,,,,,,,,,,,,,,,,,193.995559692383,194.16227722168,9999.53125,9999.53125,46.7359140503703,5.26397032177157,8.44861793518066,27,1,0,0,1,0.271682739257813,38.1231689453125,2,1,1,194.16227722168,0,194.078918457031,,,,,,,,,,,,,,,,,,,,,,,,,,,,,,,,,
,3834157868.94936,196.853775024414,9999.53125,-0.000123495225110254,2.53702457660239E-8,1,2,13.4005146026611,4.98381742954065,27.8600007295609,-0.163849351300568,-0.0240974716035028,1,-8.77200707036659E-7,,,,,,,,,,,,,,,,,,,,,196.755798339844,196.951751708984,9999.53125,9999.53125,46.7632710485434,5.26445072305146,8.46354389190674,27,1,0,0,1,0.2734375,38.1231689453125,2,1,1,196.951751708984,0,196.853775024414,,,,,,,,,,,,,,,,,,,,,,,,,,,,,,,,,
,3834157902.96904,199.649391174316,9999.53125,-0.000123422591839882,2.76992732438982E-8,1,2,13.4005146026611,4.9838327294379,27.8699994087219,-0.163752243921673,-0.0240936266818125,1,-8.84384898401188E-7,,,,,,,,,,,,,,,,,,,,,199.579940795898,199.718841552734,9999.53125,9999.53125,46.7605353487261,5.26402954740299,8.46737384796143,27,1,0,0,1,0.276718139648438,37.6344108581543,2,1,1,199.718841552734,0,199.649391174316,,,,,,,,,,,,,,,,,,,,,,,,,,,,,,,,,
,3834157935.43181,202.311737060547,9999.53125,-0.00012346112898463,2.87277084942711E-8,1,2,13.4005146026611,4.98381269471152,27.8799999505281,-0.163764680142774,-0.0243712869950255,1,-1.08816499471945E-6,,,,,,,,,,,,,,,,,,,,,202.257217407227,202.366256713867,9999.53125,9999.53125,46.7812485044857,5.2635611571969,8.4747953414917,27,1,0,0,1,0.27191162109375,37.6344108581543,2,1,1,202.366256713867,0,202.311737060547,,,,,,,,,,,,,,,,,,,,,,,,,,,,,,,,,
,3834157967.41081,204.977928161621,9999.53125,-0.000123582620789958,2.88807360862428E-8,1,2,13.4005146026611,4.98378509587625,27.8900004923344,-0.163952558372613,-0.0241950325065077,1,-9.38602895023319E-7,,,,,,,,,,,,,,,,,,,,,204.887817382813,205.06803894043,9999.53125,9999.53125,46.7652251198415,5.26453899334971,8.48245620727539,27,1,0,0,1,0.27313232421875,37.6344108581543,2,1,1,205.06803894043,0,204.977928161621,,,,,,,,,,,,,,,,,,,,,,,,,,,,,,,,,
,3834158000.22113,207.717163085938,9999.53125,-0.000123407422806227,2.82522280443834E-8,1,2,13.4005146026611,4.98376846140357,27.9099997133017,-0.163730664663876,-0.0240799115140857,1,-8.76499760687745E-7,,,,,,,,,,,,,,,,,,,,,207.683029174805,207.75129699707,9999.53125,9999.53125,46.7007407670049,5.26318032355747,8.49563503265381,25,1,64,0,0,0.273208618164062,38.1231689453125,2,1,1,207.75129699707,0,207.717163085938,,,,,,,,,,,,,,,,,,,,,,,,,,,,,,,,,
,3834158032.17667,210.371101379395,9999.53125,-0.000123407752845971,5.27846670039696E-8,1,2,13.4005146026611,4.98378893549926,27.9200002551079,-0.163716847508896,-0.0241886652608271,1,-9.58239628381827E-7,,,,,,,,,,,,,,,,,,,,,210.312088012695,210.430114746094,9999.53125,9999.53125,46.6948785531107,5.26454008705341,8.49677085876465,25,1,64,0,0,0.273590087890625,37.6344108581543,2,1,1,210.430114746094,0,210.371101379395,,,,,,,,,,,,,,,,,,,,,,,,,,,,,,,,,
,3834158064.36476,213.000106811523,9999.53125,-0.000123365239474963,3.94410995612762E-8,1,2,13.4005146026611,4.9837960748655,27.9300007969141,-0.163676722393481,-0.0240662861173629,1,-8.72000549950131E-7,,,,,,,,,,,,,,,,,,,,,212.943710327148,213.056503295898,9999.53125,9999.53125,46.7550639490915,5.26405667391242,8.49083232879639,27,1,0,0,1,0.27313232421875,38.1231689453125,2,1,1,213.056503295898,0,213.000106811523,,,,,,,,,,,,,,,,,,,,,,,,,,,,,,,,,
,3834158096.38489,215.675903320313,9999.53125,-0.000123448396858648,2.28553009556524E-8,1,2,13.4005146026611,4.98380944295969,27.9399994760752,-0.163740629558793,-0.0244189262097968,1,-1.12583232077151E-6,,,,,,,,,,,,,,,,,,,,,215.600173950195,215.75163269043,9999.53125,9999.53125,46.7640526770626,5.26417119644823,8.50142288208008,27,1,0,0,1,0.272369384765625,38.1231689453125,2,1,1,215.75163269043,0,215.675903320313,,,,,,,,,,,,,,,,,,,,,,,,,,,,,,,,,
,3834158129.83875,218.446105957031,9999.53125,-0.000123331022299211,3.00982742063376E-8,1,2,13.4005146026611,4.98382651138814,27.9500000178814,-0.163596007387347,-0.0243222059259388,1,-1.0693307583375E-6,,,,,,,,,,,,,,,,,,,,,218.311752319336,218.580459594727,9999.53125,9999.53125,46.7312242792549,5.26444867226436,8.51043510437012,27,1,0,0,1,0.272979736328125,38.1231689453125,2,1,1,218.580459594727,0,218.446105957031,,,,,,,,,,,,,,,,,,,,,,,,,,,,,,,,,
,3834158162.98401,221.18083190918,9999.53125,-0.000123341155104861,2.59549046902806E-8,1,2,13.4005146026611,4.98371629217835,27.9699992388487,-0.163628830724832,-0.0241493294937097,1,-9.38296563101686E-7,,,,,,,,,,,,,,,,,,,,,221.089065551758,221.272598266602,9999.53125,9999.53125,46.7339599790723,5.26372140919937,8.52368259429932,27,1,0,0,1,0.273895263671875,38.1231689453125,2,1,1,221.272598266602,0,221.18083190918,,,,,,,,,,,,,,,,,,,,,,,,,,,,,,,,,
,3834158195.10071,223.877311706543,9999.53125,-0.000123497399805105,2.74060559457456E-8,1,2,13.4005146026611,4.98381523196292,27.9799997806549,-0.163838503198736,-0.0241953931186006,1,-9.5063898424675E-7,,,,,,,,,,,,,,,,,,,,,223.801284790039,223.953338623047,9999.53125,9999.53125,46.7835933900434,5.26405702665766,8.53804588317871,27,1,0,0,1,0.271148681640625,38.1231689453125,2,1,1,223.953338623047,0,223.877311706543,,,,,,,,,,,,,,,,,,,,,,,,,,,,,,,,,
,3834158229.50851,226.737098693848,9999.53125,-0.000123350259619085,4.54512057415332E-8,1,2,13.4005146026611,4.98385863433976,27.9900003224611,-0.163629072427135,-0.0242825892477215,1,-1.03664939738018E-6,,,,,,,,,,,,,,,,,,,,,226.66471862793,226.809478759766,9999.53125,9999.53125,46.7742138478126,5.26397561586707,8.53641796112061,27,1,0,0,1,0.27191162109375,37.6344108581543,2,1,1,226.809478759766,0,226.737098693848,,,,,,,,,,,,,,,,,,,,,,,,,,,,,,,,,
,3834158263.71696,229.586029052734,9999.53125,-0.000123308087786601,4.82868442874903E-8,1,2,13.4005146026611,4.98380920698972,28.0099995434284,-0.163580262775425,-0.0242070196650166,1,-9.8589352618876E-7,,,,,,,,,,,,,,,,,,,,,229.487777709961,229.684280395508,9999.53125,9999.53125,46.7323967220338,5.26336494658296,8.56166172027588,27,1,0,0,1,0.2728271484375,38.1231689453125,2,1,1,229.684280395508,0,229.586029052734,,,,,,,,,,,,,,,,,,,,,,,,,,,,,,,,,
,3834158293.99664,232.141563415527,9999.53125,-0.000123358011353879,4.82526806224735E-8,1,2,13.4005146026611,4.98383163306829,28.0200000852346,-0.163654494179455,-0.024166961091273,1,-9.48638044218007E-7,,,,,,,,,,,,,,,,,,,,,232.092514038086,232.190612792969,9999.53125,9999.53125,46.8117320167357,5.26407199690065,8.5704517364502,27,1,0,0,1,0.273818969726562,38.1231689453125,2,1,1,232.190612792969,0,232.141563415527,,,,,,,,,,,,,,,,,,,,,,,,,,,,,,,,,
,3834158328.18708,234.989051818848,9999.53125,-0.000123381505728515,5.20547224378221E-8,1,2,13.4005146026611,4.98382082229737,28.0300006270409,-0.163676441961382,-0.0242339575435233,1,-9.95853023707221E-7,,,,,,,,,,,,,,,,,,,,,234.91487121582,235.063232421875,9999.53125,9999.53125,46.86840008438,5.2637985585416,8.59192848205566,27,1,0,0,1,0.272369384765625,38.1231689453125,2,1,1,235.063232421875,0,234.989051818848,,,,,,,,,,,,,,,,,,,,,,,,,,,,,,,,,
,3834158360.35661,237.604469299316,9999.53125,-0.000121260974208032,3.80058235320757E-8,1,2,13.4005146026611,4.9838337483805,28.0499998480082,-0.160855105535887,-0.0238807406992086,1,-1.02632625816516E-6,,,,,,,,,,,,,,,,,,,,,237.522308349609,237.686630249023,9999.53125,9999.53125,46.8316635439761,5.26355915910293,8.59112167358398,27,1,0,0,1,0.272598266601562,38.1231689453125,2,1,1,237.686630249023,0,237.604469299316,,,,,,,,,,,,,,,,,,,,,,,,,,,,,,,,,
,3834158394.70021,240.455604553223,9999.53125,-0.000121248526727774,6.16444695355215E-8,1,2,13.4005146026611,4.98382348995717,28.0600003898144,-0.160836892556834,-0.0238871390091197,1,-1.03293516561327E-6,,,,,,,,,,,,,,,,,,,,,240.3818359375,240.529373168945,9999.53125,9999.53125,46.7828117615242,5.26353389667814,8.60796356201172,27,1,0,0,1,0.271835327148438,38.1231689453125,2,1,1,240.529373168945,0,240.455604553223,,,,,,,,,,,,,,,,,,,,,,,,,,,,,,,,,
,3834158424.77341,242.943557739258,9999.53125,-0.000121230521028364,4.33501805935898E-8,1,2,13.4005146026611,4.98383491217298,28.0699990689754,-0.160816826257874,-0.0238599754892868,1,-1.0149431427926E-6,,,,,,,,,,,,,,,,,,,,,242.861083984375,243.026031494141,9999.53125,9999.53125,46.7796852474473,5.26400315066697,8.62129783630371,27,1,0,0,1,0.27252197265625,38.1231689453125,2,1,1,243.026031494141,0,242.943557739258,,,,,,,,,,,,,,,,,,,,,,,,,,,,,,,,,
,3834158459.13345,245.807624816895,9999.53125,-0.000121312069656806,5.39169579961775E-8,1,2,13.4005146026611,4.9838752169581,28.0900001525879,-0.160938624408386,-0.0237916483130085,1,-9.51894435961032E-7,,,,,,,,,,,,,,,,,,,,,245.738189697266,245.877059936523,9999.53125,9999.53125,46.8418247147261,5.26335593761967,8.64127826690674,27,1,0,0,1,0.270156860351562,38.1231689453125,2,1,1,245.877059936523,0,245.807624816895,,,,,,,,,,,,,,,,,,,,,,,,,,,,,,,,,
,3834158491.25705,248.513076782227,9999.53125,-0.000121285719372374,4.42761465372995E-8,1,2,13.4005146026611,4.98386974398231,28.1000006943941,-0.160889092669445,-0.0238889441328769,1,-1.02886491642939E-6,,,,,,,,,,,,,,,,,,,,,248.434310913086,248.591842651367,9999.53125,9999.53125,46.7609261629857,5.26380833097943,8.65180015563965,27,1,0,0,1,0.274658203125,38.1231689453125,2,1,1,248.591842651367,0,248.513076782227,,,,,,,,,,,,,,,,,,,,,,,,,,,,,,,,,
,3834158523.59767,251.212623596191,9999.53125,-0.000121138299716908,5.31281341351041E-8,1,2,13.4005146026611,4.98388272655331,28.1199999153614,-0.160705134936357,-0.0237811473834562,1,-9.68247530427938E-7,,,,,,,,,,,,,,,,,,,,,251.142868041992,251.282379150391,9999.53125,9999.53125,46.8113412024761,5.26405400545216,8.68734359741211,27,1,0,0,1,0.270538330078125,38.1231689453125,2,1,1,251.282379150391,0,251.212623596191,,,,,,,,,,,,,,,,,,,,,,,,,,,,,,,,,
,3834158557.78317,254.064414978027,9999.53125,-0.000121078982351118,2.67216106938065E-8,1,2,13.4005146026611,4.98389325199634,28.1300004571676,-0.160638380782377,-0.0236875225100153,1,-9.05994853654488E-7,,,,,,,,,,,,,,,,,,,,,253.977783203125,254.15104675293,9999.53125,9999.53125,46.8324451724953,5.26369431998069,8.72635650634766,27,1,0,0,1,0.270919799804687,38.1231689453125,2,1,1,254.15104675293,0,254.064414978027,,,,,,,,,,,,,,,,,,,,,,,,,,,,,,,,,
,3834158592.31761,256.915100097656,9999.53125,-0.000121221486741619,5.45162005542274E-8,1,2,13.4005146026611,4.98389290047677,28.1499996781349,-0.160819393688353,-0.0237728690142337,1,-9.50332834166842E-7,,,,,,,,,,,,,,,,,,,,,256.854064941406,256.976135253906,9999.53125,9999.53125,46.8269737728607,5.26257476475099,8.75017547607422,25,1,64,0,0,0.272140502929687,38.1231689453125,2,1,1,256.976135253906,0,256.915100097656,,,,,,,,,,,,,,,,,,,,,,,,,,,,,,,,,
,3834158626.56516,259.721588134766,9999.53125,-0.000121197298428494,5.43093197128513E-8,1,2,13.4005146026611,4.98384444148481,28.1600002199411,-0.160782480017025,-0.0237869653108412,1,-9.64567654278846E-7,,,,,,,,,,,,,,,,,,,,,259.675842285156,259.767333984375,9999.53125,9999.53125,46.8981019681107,5.26381792689282,8.71496200561523,27,1,0,0,1,0.273284912109375,38.1231689453125,2,1,1,259.767333984375,0,259.721588134766,,,,,,,,,,,,,,,,,,,,,,,,,,,,,,,,,
,3834158656.49091,262.222671508789,9999.53125,-0.00012113377035527,4.93809035115122E-8,1,2,13.4005146026611,4.9839092648585,28.1799994409084,-0.160691571568992,-0.0238428609495864,1,-1.01521686945551E-6,,,,,,,,,,,,,,,,,,,,,262.141571044922,262.303771972656,9999.53125,9999.53125,46.8086055026588,5.26366084543468,8.68952941894531,27,1,0,0,1,0.272903442382813,38.1231689453125,2,1,1,262.303771972656,0,262.222671508789,,,,,,,,,,,,,,,,,,,,,,,,,,,,,,,,,
,3834158690.75367,265.047286987305,9999.53125,-0.000121134996973064,5.12707578638344E-8,1,2,13.4005146026611,4.98392318886897,28.1899999827147,-0.160691318585203,-0.0238610471135494,1,-1.02866964914559E-6,,,,,,,,,,,,,,,,,,,,,264.950775146484,265.143798828125,9999.53125,9999.53125,46.7210631085049,5.26408374534107,8.67680358886719,27,1,0,0,1,0.272750854492187,38.1231689453125,2,1,1,265.143798828125,0,265.047286987305,,,,,,,,,,,,,,,,,,,,,,,,,,,,,,,,,
,3834158723.04724,267.7763671875,9999.53125,-0.000121106093153606,4.78841316773016E-8,1,2,13.4005146026611,4.98388321231635,28.2000005245209,-0.160666655015353,-0.0237446135520402,1,-9.45240170803954E-7,,,,,,,,,,,,,,,,,,,,,267.678863525391,267.873870849609,9999.53125,9999.53125,46.8543307710338,5.26405486719302,8.66157722473145,27,1,0,0,1,0.274505615234375,38.1231689453125,2,1,1,267.873870849609,0,267.7763671875,,,,,,,,,,,,,,,,,,,,,,,,,,,,,,,,,
,3834158755.24189,270.420684814453,9999.53125,-0.000121029538279537,4.14707200575945E-8,1,2,13.4005146026611,4.98388718860915,28.2199997454882,-0.160549480424472,-0.0238425456109143,1,-1.02966247433833E-6,,,,,,,,,,,,,,,,,,,,,270.353790283203,270.487579345703,9999.53125,9999.53125,46.7898464181973,5.2638937620525,8.65113067626953,27,1,0,0,1,0.272979736328125,38.1231689453125,2,1,1,270.487579345703,0,270.420684814453,,,,,,,,,,,,,,,,,,,,,,,,,,,,,,,,,
,3834158787.79757,273.127639770508,9999.53125,-0.000121050859784109,5.58715670953454E-8,1,2,13.4005146026611,4.98394688238718,28.2400008291006,-0.160590772349993,-0.0237729804022072,1,-9.74007992106236E-7,,,,,,,,,,,,,,,,,,,,,273.068176269531,273.187103271484,9999.53125,9999.53125,46.8148585308126,5.26243915854501,8.65371131896973,25,1,64,0,0,0.272445678710938,38.1231689453125,2,1,1,273.187103271484,0,273.127639770508,,,,,,,,,,,,,,,,,,,,,,,,,,,,,,,,,
,3834158819.67106,275.819274902344,9999.53125,-0.000120979681752059,4.6118509877734E-8,1,2,13.4005146026611,4.98387138174591,28.2499995082617,-0.160495357280755,-0.0237417071857183,1,-9.60785117742681E-7,,,,,,,,,,,,,,,,,,,,,275.739044189453,275.899505615234,9999.53125,9999.53125,46.7152008946107,5.26365417529317,8.64630031585693,27,1,0,0,1,0.273818969726562,38.1231689453125,2,1,1,275.899505615234,0,275.819274902344,,,,,,,,,,,,,,,,,,,,,,,,,,,,,,,,,
,3834158849.90235,278.303741455078,9999.53125,-0.000121053755700185,5.02170891580358E-8,1,2,13.4005146026611,4.98396460483101,28.2700005918741,-0.160597079820229,-0.0237616359445565,1,-9.64974115937295E-7,,,,,,,,,,,,,,,,,,,,,278.233093261719,278.374389648438,9999.53125,9999.53125,46.7718689622549,5.26309715634452,8.64695835113525,27,1,0,0,1,0.273056030273438,38.1231689453125,2,1,1,278.374389648438,0,278.303741455078,,,,,,,,,,,,,,,,,,,,,,,,,,,,,,,,,
,3834158882.566,280.983856201172,9999.53125,-0.000120940075170073,5.01526737912412E-8,1,2,13.4005146026611,4.98389052638641,28.2799992710352,-0.160436104849122,-0.0237880922912599,1,-1.00115432609507E-6,,,,,,,,,,,,,,,,,,,,,280.929656982422,281.038055419922,9999.53125,9999.53125,46.7773403618896,5.26317491745038,8.65312767028809,25,1,64,0,0,0.271453857421875,38.1231689453125,2,1,1,281.038055419922,0,280.983856201172,,,,,,,,,,,,,,,,,,,,,,,,,,,,,,,,,
,3834158914.47023,283.632766723633,9999.53125,-0.000120815523624426,4.41486131283229E-8,1,2,13.4005146026611,4.9838787738837,28.3000003546476,-0.160270323940772,-0.0237637690710263,1,-1.00031311469507E-6,,,,,,,,,,,,,,,,,,,,,283.559173583984,283.706359863281,9999.53125,9999.53125,46.7007407670049,5.26379979916822,8.66035842895508,25,1,64,0,0,0.27374267578125,38.1231689453125,2,1,1,283.706359863281,0,283.632766723633,,,,,,,,,,,,,,,,,,,,,,,,,,,,,,,,,
,3834158946.75878,286.234649658203,9999.53125,-0.000120899781676465,5.07294976527811E-8,1,2,13.4005146026611,4.98383367013319,28.3100008964539,-0.160382170276576,-0.0237652851839557,1,-9.89895811744302E-7,,,,,,,,,,,,,,,,,,,,,286.164672851562,286.304626464844,9999.53125,9999.53125,46.7906280467165,5.26432617020239,8.66749477386475,27,1,0,0,1,0.274429321289062,38.1231689453125,2,1,1,286.304626464844,0,286.234649658203,,,,,,,,,,,,,,,,,,,,,,,,,,,,,,,,,
,3834158978.84193,288.815551757812,9999.53125,-0.000120704644307829,4.57854694632246E-8,1,2,13.4005146026611,4.98387802938949,28.3300001174211,-0.160118767801449,-0.0237736671434218,1,-1.02327288194963E-6,,,,,,,,,,,,,,,,,,,,,288.721069335937,288.910034179687,9999.53125,9999.53125,46.9410915366684,5.26346787678314,8.67448616027832,27,1,0,0,1,0.273361206054687,38.1231689453125,2,1,1,288.910034179687,0,288.815551757812,,,,,,,,,,,,,,,,,,,,,,,,,,,,,,,,,
,3834159011.23276,291.546844482422,9999.53125,-0.000120724906461383,5.44697697479105E-8,1,2,13.4005146026611,4.98384723772952,28.3499993383884,-0.16014654021038,-0.0237613513103153,1,-1.01131827254276E-6,,,,,,,,,,,,,,,,,,,,,291.487823486328,291.605865478516,9999.53125,9999.53125,46.8766071838319,5.26339004227648,8.69840908050537,27,1,0,0,1,0.273513793945313,38.1231689453125,2,1,1,291.605865478516,0,291.546844482422,,,,,,,,,,,,,,,,,,,,,,,,,,,,,,,,,
,3834159045.44428,294.507614135742,9999.53125,-0.000120524227852721,4.94884248306069E-8,1,2,13.4005146026611,4.98386572764315,28.3599998801947,-0.159892987234578,-0.023637284747542,1,-9.45870063338538E-7,,,,,,,,,,,,,,,,,,,,,294.428680419922,294.586547851562,9999.53125,9999.53125,46.8168126021107,5.26348641039943,8.74064445495606,27,1,0,0,1,0.27587890625,37.6344108581543,2,1,1,294.586547851562,0,294.507614135742,,,,,,,,,,,,,,,,,,,,,,,,,,,,,,,,,
,3834159075.75229,297.103164672852,9999.53125,-0.000120516335268754,5.58592174626288E-8,1,2,13.4005146026611,4.98384499378921,28.379999101162,-0.159874599273489,-0.02368569765941,1,-9.83528108508903E-7,,,,,,,,,,,,,,,,,,,,,297.047943115234,297.158386230469,9999.53125,9999.53125,46.9938514617165,5.26370758441083,8.77614116668701,27,1,0,0,1,0.272445678710938,38.1231689453125,2,1,1,297.158386230469,0,297.103164672852,,,,,,,,,,,,,,,,,,,,,,,,,,,,,,,,,
,3834159109.9244,299.336029052734,9999.53125,-0.000120460268868222,5.63314308428227E-8,1,2,13.4005146026611,4.98382062001375,28.4000001847744,-0.159803074614603,-0.0236464521989256,1,-9.61936736590817E-7,,,,,,,,,,,,,,,,,,,,,299.302276611328,299.369781494141,9999.53125,9999.53125,46.8410430862069,5.26359405170223,8.82417488098145,27,1,0,0,1,0.272674560546875,38.1231689453125,6,1,1,299.369781494141,0,299.336029052734,,,,,,,,,,,,,,,,,,,,,,,,,,,,,,,,,
,3834159140.2219,299.783752441406,9999.53125,-0.000120342725654314,5.73512389024809E-8,1,2,13.4005146026611,4.98384405512991,28.3899996429682,-0.159638407544453,-0.0236933627022972,1,-1.01357856787722E-6,,,,,,,,,,,,,,,,,,,,,299.776306152344,299.791198730469,9999.53125,9999.53125,46.8922397542165,5.26353069573334,8.87724781036377,27,1,0,0,1,0.270767211914062,38.1231689453125,5,1,1,299.791198730469,0,299.783752441406,,,,,,,,,,,,,,,,,,,,,,,,,,,,,,,,,
,3834159174.35422,299.916519165039,9999.53125,-0.000120413285473013,5.16419664668721E-8,1,2,13.4005146026611,4.98384111225976,28.3899996429682,-0.159729057609015,-0.0237274062455616,1,-1.02936060638666E-6,,,,,,,,,,,,,,,,,,,,,299.914184570313,299.918853759766,9999.53125,9999.53125,46.9156886097934,5.2636415056818,8.92963218688965,27,1,0,0,1,0.27496337890625,38.1231689453125,5,1,1,299.918853759766,0,299.916519165039,,,,,,,,,,,,,,,,,,,,,,,,,,,,,,,,,
,3834159178.61766,299.924987792969,9999.53125,-0.000120329422202333,4.97158163994408E-8,1,2,13.4005146026611,4.98381947721639,28.3899996429682,-0.159615741578674,-0.0237187491805202,1,-1.03467449965025E-6,,,,,,,,,,,,,,,,,,,,,299.923980712891,299.925994873047,9999.53125,9999.53125,46.8394798291684,5.26345144119975,8.9368896484375,27,1,0,0,1,0.273208618164062,38.1231689453125,1,1,1,299.925994873047,0,299.924987792969,,,,,,,,,,,,,,,,,,,,,,,,,,,,,,,,,