File: SI Fig S11-13 SQUID all/Michaela_Er_ZFC1T.dat
[Header]
; MPMS3 Data File (default extension .dat)
; Copyright (c) 2007, Quantum Design, Inc. All rights reserved.
TITLE,
FILEOPENTIME,3832828736.33822,06/14/2021,10:39 am
BYAPP,MPMS3 w/ AC,1.0,1.1
INFO,MPMS3 Measurement Release 1.1.16 Build 424, MultiVu Release 2.3.4.19,APPNAME
INFO,Linear Motor Servo Controller,MOTOR_MODULE_NAME
INFO,3101-100 E1,MOTOR_HW_VERSION
INFO,MMC211,MOTOR_SERIAL_NUMBER
INFO,01.04.28,MOTOR_SOFTWARE_VERSION
INFO,Quantum Design Squid Module,SQUID_MODULE_NAME
INFO,3101-501 B0,SQUID_HW_VERSION
INFO,SQM059,SQUID_SERIAL_NUMBER
INFO,01.03.04,SQUID_SOFTWARE_VERSION
INFO,SQUID AC,AC_MODULE_NAME
INFO,3101-401 F1,AC_HW_VERSION
INFO,SAC057,AC_SERIAL_NUMBER
INFO,SQUID AC 00.95.07,AC_SOFTWARE_VERSION
INFO,TCIXXX,COIL_SERIAL_NUMBER
INFO,0,MOMENT_UNITS
INFO,Michaela_Er,SAMPLE_MATERIAL
INFO,Michaela_Er,SAMPLE_COMMENT
INFO,1.11,SAMPLE_MASS
INFO,,SAMPLE_VOLUME
INFO,,SAMPLE_MOLECULAR_WEIGHT
INFO,,SAMPLE_SIZE
INFO,,SAMPLE_SHAPE
INFO,Straw,SAMPLE_HOLDER
INFO,Standard,SAMPLE_HOLDER_DETAIL
INFO,53.51,SAMPLE_OFFSET
DATATYPE,COMMENT,1
DATATYPE,TIME,2
STARTUPAXIS,X,2
STARTUPAXIS,Y1,5
FIELDGROUP, VSM,2,3,4,5,6,8,9,10,11,14,15
FIELDGROUP, DC, 2,3,4,14,56,57,58,59,60,61,62,63,64,65,66,67,68,69
FIELDGROUP, AC, 2,3,4,11,16,17,18,19,20,21,22,23,24,25,26,27,28,29,30
STARTUPGROUP, All
[Data]
Comment,Time Stamp (sec),Temperature (K),Magnetic Field (Oe),Moment (emu),M. Std. Err. (emu),Transport Action,Averaging Time (sec),Frequency (Hz),Peak Amplitude (mm),Center Position (mm),Lockin Signal' (V),Lockin Signal (V),Range,M. Quad. Signal (emu),AC Moment (emu),AC M. Std Err. (emu),AC Phase (deg),AC Phase Std. Err. (deg),AC Susceptibility (emu/Oe),AC Suscept. Std Err. (emu/Oe),AC X' (emu/Oe),AC X' Std Err. (emu/Oe),AC X'' (emu/Oe),AC X'' Std Err. (emu/Oe),AC Drive (Oe),AC Frequency (Hz),AC Averaging Time (sec),AC Cycles,AC Range,AC Measure Type,AC Signal' (V),AC Signal'' (V),AC Trim Coil Ratio,AC Trim Coil Phase,Min. Temperature (K),Max. Temperature (K),Min. Field (Oe),Max. Field (Oe),Mass (grams),Motor Lag (deg),Pressure (Torr),Measure Count,Measurement Number,SQUID Status (code),Motor Status (code),Measure Status (code),Motor Current (amps),Motor Temp. (C),Temp. Status (code),Field Status (code),Chamber Status (code),Chamber Temp (K),Redirection State,Average Temp (K),Rotation Angle (deg),Rotator state,DC Moment Fixed Ctr (emu),DC Moment Err Fixed Ctr (emu),DC Moment Free Ctr (emu),DC Moment Err Free Ctr (emu),DC Fixed Fit,DC Free Fit,DC Calculated Center (mm),DC Calculated Center Err (mm),DC Scan Length (mm),DC Scan Time (s),DC Number of Points,DC Squid Drift,DC Min V (V),DC Max V (V),DC Scans per Measure,Map 01,Map 02,Map 03,Map 04,Map 05,Map 06,Map 07,Map 08,Map 09,Map 10,Map 11,Map 12,Map 13,Map 14,Map 15,Map 16
,3832828755.89152,8.00322437286377,9999.6435546875,0.00691138054898252,8.68616291772899E-7,1,2,13.4005146026611,5.0036860805785,32.7900014817715,9.21699594765364,1.37685032081866,10,6.47207023685444E-5,,,,,,,,,,,,,,,,,,,,,8.00322437286377,8.00322437286377,9999.6435546875,9999.6435546875,47.2842264566108,5.26872292836353,8.08656883239746,27,1,0,0,1,0.283355712890625,38.6119270324707,1,1,1,8.00322437286377,0,8.00322437286377,,,,,,,,,,,,,,,,,,,,,,,,,,,,,,,,,
,3832828810.13311,10.3281102180481,9999.6435546875,0.00671923397891885,2.63644451614233E-6,1,2,13.4005146026611,4.98383831061266,32.7900014817715,8.91228924540077,1.32984621064626,10,6.1824988799623E-5,,,,,,,,,,,,,,,,,,,,,10.2828235626221,10.3733968734741,9999.6435546875,9999.6435546875,47.3100201977454,5.26777192410278,8.76826000213623,27,1,0,0,1,0.27496337890625,39.5894432067871,6,1,1,10.3733968734741,0,10.3281102180481,,,,,,,,,,,,,,,,,,,,,,,,,,,,,,,,,
,3832828864.51938,12.8853058815002,9999.6435546875,0.0056514268347995,1.72342224355404E-6,1,2,13.4005146026611,4.98393503791709,32.7799990773201,7.49638934967704,1.11694089605592,10,5.07962207785107E-5,,,,,,,,,,,,,,,,,,,,,12.8295774459839,12.9410343170166,9999.6435546875,9999.6435546875,47.3619984942742,5.26699537935564,9.34915256500244,27,1,0,0,1,0.273513793945313,40.0782012939453,6,1,1,12.9410343170166,0,12.8853058815002,,,,,,,,,,,,,,,,,,,,,,,,,,,,,,,,,
,3832828919.24357,15.5782780647278,9999.6435546875,0.0049027780812438,1.6982971737842E-6,1,2,13.4005146026611,4.98390675306017,32.7900014817715,6.50341614144688,0.968043278341361,10,4.33684199687393E-5,,,,,,,,,,,,,,,,,,,,,15.5322408676147,15.6243152618408,9999.6435546875,9999.6435546875,47.3170548544185,5.26728994129948,9.85599899291992,27,1,0,0,1,0.273513793945313,40.0782012939453,2,1,1,15.6243152618408,0,15.5782780647278,,,,,,,,,,,,,,,,,,,,,,,,,,,,,,,,,
,3832828969.30101,17.9665985107422,9999.6435546875,0.00441036694675798,9.4682526792491E-7,1,2,13.4005146026611,4.98399925166076,32.7799990773201,5.85057411161549,0.869549813645818,10,3.80413608272569E-5,,,,,,,,,,,,,,,,,,,,,17.9256057739258,18.0075912475586,9999.6435546875,9999.6435546875,47.3991258489377,5.26682204580536,10.1176500320435,27,1,0,0,1,0.2734375,40.5669593811035,2,1,1,18.0075912475586,0,17.9665985107422,,,,,,,,,,,,,,,,,,,,,,,,,,,,,,,,,
,3832829031.76499,20.9723749160767,9999.6435546875,0.00394287059133949,8.37062367606503E-7,1,2,13.4005146026611,4.98412442358679,32.7900014817715,5.23068160240279,0.776799015127126,10,3.35528826359508E-5,,,,,,,,,,,,,,,,,,,,,20.9237499237061,21.0209999084473,9999.6435546875,9999.6435546875,47.3862289783704,5.26589017332765,10.4059200286865,27,1,0,0,1,0.273590087890625,40.5669593811035,2,1,1,21.0209999084473,0,20.9723749160767,,,,,,,,,,,,,,,,,,,,,,,,,,,,,,,,,
,3832829094.52469,24.0131921768188,9999.6435546875,0.00358035258880706,5.62066197007428E-7,1,2,13.4005146026611,4.98423992041796,32.7799990773201,4.74995360980168,0.705087698952537,10,3.02324560167689E-5,,,,,,,,,,,,,,,,,,,,,23.9831256866455,24.0432586669922,9999.6435546875,9999.6435546875,47.4053788770916,5.2662002652699,10.6307010650635,27,1,0,0,1,0.272750854492187,40.5669593811035,2,1,1,24.0432586669922,0,24.0131921768188,,,,,,,,,,,,,,,,,,,,,,,,,,,,,,,,,
,3832829146.95244,26.5604619979858,9999.6435546875,0.00333366033095792,4.88044350211361E-7,1,2,13.4005146026611,4.98444602408636,32.7799990773201,4.4230702583309,0.655503332504322,10,2.73665161720742E-5,,,,,,,,,,,,,,,,,,,,,26.5081386566162,26.6127853393555,9999.6435546875,9999.6435546875,47.4393797176781,5.26520921150906,10.8146848678589,27,1,0,0,1,0.273818969726562,40.5669593811035,2,1,1,26.6127853393555,0,26.5604619979858,,,,,,,,,,,,,,,,,,,,,,,,,,,,,,,,,
,3832829201.19623,29.1595249176025,9999.6435546875,0.00311646161968153,4.91843235753444E-7,1,2,13.4005146026611,4.98480210599366,32.7799990773201,4.13533116494733,0.612620347784937,10,2.54066744549137E-5,,,,,,,,,,,,,,,,,,,,,29.1019077301025,29.2171421051025,9999.6435546875,9999.6435546875,47.3819300215146,5.26423003383554,10.9796924591064,27,1,0,0,1,0.272979736328125,40.5669593811035,2,1,1,29.2171421051025,0,29.1595249176025,,,,,,,,,,,,,,,,,,,,,,,,,,,,,,,,,
,3832829261.47613,32.0778713226318,9999.6435546875,0.00290734711678715,5.05722327647002E-7,1,2,13.4005146026611,4.9850195684926,32.7900014817715,3.85803957124628,0.571847403037621,10,2.39274423346931E-5,,,,,,,,,,,,,,,,,,,,,32.0272483825684,32.1284942626953,9999.6435546875,9999.6435546875,47.4096778339473,5.26310262687547,11.0860376358032,27,1,0,0,1,0.276260375976562,40.5669593811035,2,1,1,32.1284942626953,0,32.0778713226318,,,,,,,,,,,,,,,,,,,,,,,,,,,,,,,,,
,3832829317.86315,34.8252334594727,9999.6435546875,0.0027409459258659,2.89986899616307E-7,1,2,13.4005146026611,4.98490915170781,32.7900014817715,3.63720048033306,0.53849174219167,10,2.20989793658834E-5,,,,,,,,,,,,,,,,,,,,,34.7743377685547,34.8761291503906,9999.6435546875,9999.6435546875,47.4167124906204,5.26318719931882,11.2147226333618,27,1,0,0,1,0.275192260742187,40.5669593811035,2,1,1,34.8761291503906,0,34.8252334594727,,,,,,,,,,,,,,,,,,,,,,,,,,,,,,,,,
,3832829370.23345,37.3553123474121,9999.6435546875,0.00260410788028487,4.01329879256499E-7,1,2,13.4005146026611,4.98499217854915,32.7900014817715,3.45572153648105,0.511445208891025,10,2.086418108179E-5,,,,,,,,,,,,,,,,,,,,,37.306022644043,37.4046020507812,9999.6435546875,9999.6435546875,47.3428485955531,5.26273225669887,11.3195972442627,27,1,0,0,1,0.274200439453125,40.5669593811035,2,1,1,37.4046020507812,0,37.3553123474121,,,,,,,,,,,,,,,,,,,,,,,,,,,,,,,,,
,3832829424.93821,40.0537433624268,9999.6435546875,0.00247735709047646,2.59176911296822E-7,1,2,13.4005146026611,4.98502732449808,32.7900014817715,3.28763853767594,0.485934475643819,10,1.9380717674172E-5,,,,,,,,,,,,,,,,,,,,,40.0286140441895,40.0788726806641,9999.6435546875,9999.6435546875,47.3608260514954,5.26293514987632,11.3981437683105,27,1,0,0,1,0.276947021484375,40.5669593811035,2,1,1,40.0788726806641,0,40.0537433624268,,,,,,,,,,,,,,,,,,,,,,,,,,,,,,,,,
,3832829479.31246,42.688606262207,9999.6435546875,0.0023621477139888,3.21580533736536E-7,1,2,13.4005146026611,4.98510933742502,32.7900014817715,3.13477209129831,0.463673643557945,10,1.87256017119197E-5,,,,,,,,,,,,,,,,,,,,,42.6584625244141,42.71875,9999.6435546875,9999.6435546875,47.3393312672166,5.26235367941229,11.5075826644897,27,1,0,0,1,0.275497436523438,40.5669593811035,2,1,1,42.71875,0,42.688606262207,,,,,,,,,,,,,,,,,,,,,,,,,,,,,,,,,
,3832829533.58145,45.3498649597168,9999.6435546875,0.00225611338971686,2.88450291867993E-7,1,2,13.4005146026611,4.98502539265498,32.8000001609325,2.99405623310333,0.442349394509127,10,1.75085257644387E-5,,,,,,,,,,,,,,,,,,,,,45.3123664855957,45.3873634338379,9999.6435546875,9999.6435546875,47.4038156200531,5.26275385093687,11.5601930618286,27,1,0,0,1,0.272369384765625,41.055721282959,2,1,1,45.3873634338379,0,45.3498649597168,,,,,,,,,,,,,,,,,,,,,,,,,,,,,,,,,
,3832829588.16232,48.0004768371582,9999.6435546875,0.00216147881216775,2.90684426640977E-7,1,2,13.4005146026611,4.98493536098163,32.8000001609325,2.86844339761636,0.423451895037442,10,1.65239987282012E-5,,,,,,,,,,,,,,,,,,,,,47.9462738037109,48.0546798706055,9999.6435546875,9999.6435546875,47.37645862188,5.2632309992861,11.6589670181274,27,1,0,0,1,0.2728271484375,40.5669593811035,2,1,1,48.0546798706055,0,48.0004768371582,,,,,,,,,,,,,,,,,,,,,,,,,,,,,,,,,
,3832829642.38599,50.6593360900879,9999.6435546875,0.0020747525642482,3.33468338129508E-7,1,2,13.4005146026611,4.98492092380284,32.8000001609325,2.75338754394217,0.406121737718251,10,1.56064671478829E-5,,,,,,,,,,,,,,,,,,,,,50.6018486022949,50.7168235778809,9999.6435546875,9999.6435546875,47.3983442204185,5.26334157155043,11.746940612793,27,1,0,0,1,0.274581909179687,40.5669593811035,2,1,1,50.7168235778809,0,50.6593360900879,,,,,,,,,,,,,,,,,,,,,,,,,,,,,,,,,
,3832829696.65949,53.3250751495361,9999.6435546875,0.00199438274071303,2.926849539591E-7,1,2,13.4005146026611,4.98482671394361,32.8000001609325,2.6466424650658,0.390510485514148,10,1.51004052123516E-5,,,,,,,,,,,,,,,,,,,,,53.2758522033691,53.3742980957031,9999.6435546875,9999.6435546875,47.3608260514954,5.26359612570132,11.8074827194214,27,1,0,0,1,0.272216796875,40.5669593811035,2,1,1,53.3742980957031,0,53.3250751495361,,,,,,,,,,,,,,,,,,,,,,,,,,,,,,,,,
,3832829753.30561,56.1381359100342,9999.6435546875,0.00191562630186851,2.0154204196393E-7,1,2,13.4005146026611,4.9847835821912,32.8099988400936,2.54215244116435,0.374700581814554,10,1.42146424687054E-5,,,,,,,,,,,,,,,,,,,,,56.0787315368652,56.1975402832031,9999.6435546875,9999.6435546875,47.3999074774569,5.26371128701162,11.8855648040771,27,1,0,0,1,0.272750854492187,40.5669593811035,2,1,1,56.1975402832031,0,56.1381359100342,,,,,,,,,,,,,,,,,,,,,,,,,,,,,,,,,
,3832829807.59407,58.7700138092041,9999.6435546875,0.00184714475806538,2.12425549716727E-7,1,2,13.4005146026611,4.98467778898798,32.820001244545,2.45117791448871,0.361466381846609,10,1.38355553096504E-5,,,,,,,,,,,,,,,,,,,,,58.712230682373,58.8277969360352,9999.6435546875,9999.6435546875,47.3780218789185,5.26419347252666,11.9833765029907,27,1,0,0,1,0.274276733398438,41.055721282959,2,1,1,58.8277969360352,0,58.7700138092041,,,,,,,,,,,,,,,,,,,,,,,,,,,,,,,,,
,3832829861.86507,61.4410419464111,9999.6435546875,0.00178333118777514,2.49166221413036E-7,1,2,13.4005146026611,4.9845633022107,32.8099988400936,2.36646248583994,0.348679220888105,10,1.31403666497054E-5,,,,,,,,,,,,,,,,,,,,,61.3986320495606,61.4834518432617,9999.6435546875,9999.6435546875,47.4264828471108,5.26436770210177,12.0473146438599,27,1,0,0,1,0.272674560546875,40.5669593811035,2,1,1,61.4834518432617,0,61.4410419464111,,,,,,,,,,,,,,,,,,,,,,,,,,,,,,,,,
,3832829916.25549,64.1235313415527,9999.6435546875,0.00172196973336339,1.87468411916E-7,1,2,13.4005146026611,4.98447995357073,32.8299999237061,2.28496197028655,0.336831754373655,10,1.28069715687888E-5,,,,,,,,,,,,,,,,,,,,,64.07763671875,64.1694259643555,9999.6435546875,9999.6435546875,47.3690331509473,5.26555892129552,12.1132478713989,27,1,0,0,1,0.273284912109375,41.055721282959,2,1,1,64.1694259643555,0,64.1235313415527,,,,,,,,,,,,,,,,,,,,,,,,,,,,,,,,,
,3832829970.69088,66.7787818908691,9999.6435546875,0.00166587456187983,8.06501289545079E-8,1,2,13.4005146026611,4.98442428965515,32.820001244545,2.21049722322444,0.32582240678271,10,1.23659294692055E-5,,,,,,,,,,,,,,,,,,,,,66.7369995117187,66.8205642700195,9999.6435546875,9999.6435546875,47.3870106068896,5.26560412977701,12.1276473999023,27,1,0,0,1,0.274124145507813,40.5669593811035,2,1,1,66.8205642700195,0,66.7787818908691,,,,,,,,,,,,,,,,,,,,,,,,,,,,,,,,,
,3832830025.0572,69.4546661376953,9999.6435546875,0.00161320368419071,8.85971746958774E-8,1,2,13.4005146026611,4.98437005515127,32.8299999237061,2.14056253163516,0.315603358426113,10,1.20407254609764E-5,,,,,,,,,,,,,,,,,,,,,69.4066696166992,69.5026626586914,9999.6435546875,9999.6435546875,47.3440210383319,5.26606651227082,12.1822195053101,27,1,0,0,1,0.274505615234375,41.055721282959,2,1,1,69.5026626586914,0,69.4546661376953,,,,,,,,,,,,,,,,,,,,,,,,,,,,,,,,,
,3832830078.69941,72.1097106933594,9999.6435546875,0.0015624818005351,2.03803318126082E-7,1,2,13.4005146026611,4.98428261106144,32.8299999237061,2.07322337225166,0.305574899043768,10,1.15883704275089E-5,,,,,,,,,,,,,,,,,,,,,72.028434753418,72.1909866333008,9999.6435546875,9999.6435546875,47.3928728207839,5.26644815343707,12.1750478744507,27,1,0,0,1,0.271682739257813,41.055721282959,2,1,1,72.1909866333008,0,72.1097106933594,,,,,,,,,,,,,,,,,,,,,,,,,,,,,,,,,
,3832830132.01864,74.7130889892578,9999.6435546875,0.00151764322974608,7.79627638416803E-8,1,2,13.4005146026611,4.98416917825384,32.8299999237061,2.01365307542118,0.296882903589801,10,1.1320840469001E-5,,,,,,,,,,,,,,,,,,,,,74.6755447387695,74.7506332397461,9999.6435546875,9999.6435546875,47.3725504792839,5.26717180723127,12.2307987213135,27,1,0,0,1,0.273361206054687,41.055721282959,2,1,1,74.7506332397461,0,74.7130889892578,,,,,,,,,,,,,,,,,,,,,,,,,,,,,,,,,
,3832830186.59786,77.4058456420898,9999.6435546875,0.00147365294327248,1.8602869077815E-7,1,2,13.4005146026611,4.9841226303405,32.8299999237061,1.95526312864528,0.288254466991261,10,1.09781512144429E-5,,,,,,,,,,,,,,,,,,,,,77.3481369018555,77.4635543823242,9999.6435546875,9999.6435546875,47.3522281377839,5.26727893808284,12.2480611801147,27,1,0,0,1,0.27374267578125,40.5669593811035,2,1,1,77.4635543823242,0,77.4058456420898,,,,,,,,,,,,,,,,,,,,,,,,,,,,,,,,,
,3832830242.85455,80.2178573608398,9999.6435546875,0.00142947796926677,1.68963257173972E-7,1,2,13.4005146026611,4.98406213716367,32.8399986028671,1.89664256127051,0.279444519774859,10,1.05252655882018E-5,,,,,,,,,,,,,,,,,,,,,80.1857147216797,80.25,9999.6435546875,9999.6435546875,47.43742564638,5.26696080514357,12.2727851867676,27,1,0,0,1,0.273818969726562,41.055721282959,2,1,1,80.25,0,80.2178573608398,,,,,,,,,,,,,,,,,,,,,,,,,,,,,,,,,
,3832830299.39848,83.0102157592773,9999.6435546875,0.00138890696989976,1.30178024052555E-7,1,2,13.4005146026611,4.9839389146716,32.8500010073185,1.84274787981483,0.271520205191628,10,1.02385915304223E-5,,,,,,,,,,,,,,,,,,,,,82.9812774658203,83.0391540527344,9999.6435546875,9999.6435546875,47.371378036505,5.26747880790536,12.2882204055786,27,1,0,0,1,0.273590087890625,41.055721282959,2,1,1,83.0391540527344,0,83.0102157592773,,,,,,,,,,,,,,,,,,,,,,,,,,,,,,,,,
,3832830349.49762,85.4711952209473,9999.6435546875,0.001353441628323,1.08649508919239E-7,1,2,13.4005146026611,4.98396330236362,32.8500010073185,1.79571228805942,0.264543098259612,10,9.94274821400846E-6,,,,,,,,,,,,,,,,,,,,,85.4215621948242,85.5208282470703,9999.6435546875,9999.6435546875,47.3717688507646,5.2671759907686,12.3155326843262,27,1,0,0,1,0.2728271484375,41.055721282959,2,1,1,85.5208282470703,0,85.4711952209473,,,,,,,,,,,,,,,,,,,,,,,,,,,,,,,,,
,3832830406.10468,88.2784461975098,9999.6435546875,0.00131679208365917,1.35334765089252E-7,1,2,13.4005146026611,4.98395492668138,32.8599996864796,1.74707798603103,0.257411752300838,10,9.69817035681468E-6,,,,,,,,,,,,,,,,,,,,,88.2180023193359,88.3388900756836,9999.6435546875,9999.6435546875,47.3842749070723,5.26714667658255,12.3757057189941,27,1,0,0,1,0.275421142578125,41.055721282959,2,1,1,88.3388900756836,0,88.2784461975098,,,,,,,,,,,,,,,,,,,,,,,,,,,,,,,,,
,3832830462.3869,91.0804443359375,9999.6435546875,0.00128109247682143,1.23556997396211E-7,1,2,13.4005146026611,4.98382562643569,32.8599996864796,1.69962457977484,0.250622846207197,10,9.58486483743348E-6,,,,,,,,,,,,,,,,,,,,,91.0428237915039,91.1180648803711,9999.6435546875,9999.6435546875,47.3584811659377,5.2685189286005,12.3987913131714,27,1,0,0,1,0.272064208984375,40.5669593811035,2,1,1,91.1180648803711,0,91.0804443359375,,,,,,,,,,,,,,,,,,,,,,,,,,,,,,,,,
,3832830514.66439,93.6649360656738,9999.6435546875,0.00125045764008003,8.48306756740653E-8,1,2,13.4005146026611,4.98379292441715,32.8599996864796,1.65899257011014,0.244440474784768,10,9.21484859202904E-6,,,,,,,,,,,,,,,,,,,,,93.6151657104492,93.7147064208984,9999.6435546875,9999.6435546875,47.3881830496685,5.26796419876577,12.4063730239868,27,1,0,0,1,0.273818969726562,41.055721282959,2,1,1,93.7147064208984,0,93.6649360656738,,,,,,,,,,,,,,,,,,,,,,,,,,,,,,,,,
,3832830569.33981,96.4035758972168,9999.6435546875,0.0012193226267041,1.72186398499877E-7,1,2,13.4005146026611,4.98366467799434,32.880000770092,1.61762677101883,0.238357118744212,10,8.993962482189E-6,,,,,,,,,,,,,,,,,,,,,96.3705902099609,96.4365615844727,9999.6435546875,9999.6435546875,47.4253104043319,5.26869162216646,12.4489231109619,25,1,64,0,0,0.272598266601562,41.055721282959,2,1,1,96.4365615844727,0,96.4035758972168,,,,,,,,,,,,,,,,,,,,,,,,,,,,,,,,,
,3832830623.51677,99.1079483032227,9999.6435546875,0.00119005399944439,1.01396711652483E-7,1,2,13.4005146026611,4.98371311806914,32.8699983656406,1.57884395369877,0.23245528789272,10,8.63996751702624E-6,,,,,,,,,,,,,,,,,,,,,99.0633392333984,99.1525573730469,9999.6435546875,9999.6435546875,47.3909187494858,5.26888009062345,12.4678468704224,25,1,64,0,0,0.272979736328125,40.5669593811035,2,1,1,99.1525573730469,0,99.1079483032227,,,,,,,,,,,,,,,,,,,,,,,,,,,,,,,,,
,3832830679.86826,101.903076171875,9999.6435546875,0.00116067770128197,8.5526756447361E-8,1,2,13.4005146026611,4.98357803890636,32.880000770092,1.53981365133059,0.226705187693842,10,8.42402251330999E-6,,,,,,,,,,,,,,,,,,,,,101.866966247559,101.939186096191,9999.6435546875,9999.6435546875,47.3881830496685,5.26947199870344,12.4886207580566,27,1,0,0,1,0.2734375,40.5669593811035,2,1,1,101.948371887207,0,101.903076171875,,,,,,,,,,,,,,,,,,,,,,,,,,,,,,,,,
,3832830740.58601,104.9338722229,9999.6435546875,0.00113069123435277,9.38579714236959E-8,1,2,13.4005146026611,4.98363202496795,32.880000770092,1.49956448985732,0.224355230895838,1,1.0844721974059E-5,,,,,,,,,,,,,,,,,,,,,104.904228210449,104.963516235352,9999.6435546875,9999.6435546875,47.3029855410723,5.2694563890604,12.5282363891602,27,1,0,0,1,0.275421142578125,40.5669593811035,2,1,1,104.963516235352,0,104.9338722229,,,,,,,,,,,,,,,,,,,,,,,,,,,,,,,,,
,3832830792.91885,107.539405822754,9999.6435546875,0.00110577499757907,9.05554048654223E-8,1,2,13.4005146026611,4.98354510898918,32.8899994492531,1.46654180641889,0.218996556877512,1,1.02974085157122E-5,,,,,,,,,,,,,,,,,,,,,107.478622436523,107.600189208984,9999.6435546875,9999.6435546875,47.3666882653896,5.26912772796096,12.536642074585,27,1,0,0,1,0.271759033203125,41.055721282959,2,1,1,107.600189208984,0,107.539405822754,,,,,,,,,,,,,,,,,,,,,,,,,,,,,,,,,
,3832830849.22569,110.315692901611,9999.6435546875,0.00108076617890967,5.23790335413161E-8,1,2,13.4005146026611,4.98335312446753,32.8899994492531,1.43327449017647,0.214199725498961,1,1.01906034747921E-5,,,,,,,,,,,,,,,,,,,,,110.276153564453,110.35523223877,9999.6435546875,9999.6435546875,47.3944360778223,5.27008763828847,12.5698318481445,27,1,0,0,1,0.273590087890625,40.5669593811035,2,1,1,110.35523223877,0,110.315692901611,,,,,,,,,,,,,,,,,,,,,,,,,,,,,,,,,
,3832830910.63272,113.422264099121,9999.6435546875,0.00105447608428779,9.01605704919724E-8,1,2,13.4005146026611,4.98348738494237,32.9100005328655,1.39854023069492,0.208431662798245,1,9.51703018386146E-6,,,,,,,,,,,,,,,,,,,,,113.422264099121,113.422264099121,9999.6435546875,9999.6435546875,47.4264828471108,5.27040840749563,12.5806856155396,27,1,0,0,1,0.272979736328125,40.5669593811035,2,1,1,113.422264099121,0,113.422264099121,,,,,,,,,,,,,,,,,,,,,,,,,,,,,,,,,
,3832830963.97782,116.040451049805,9999.6435546875,0.00103181541301447,6.97612804526822E-8,1,2,13.4005146026611,4.98332738542859,32.9100005328655,1.36843350194877,0.203885009888303,1,9.26847512573212E-6,,,,,,,,,,,,,,,,,,,,,115.992897033691,116.088005065918,9999.6435546875,9999.6435546875,47.43742564638,5.27063969836751,12.593165397644,27,1,0,0,1,0.272979736328125,40.5669593811035,2,1,1,116.088005065918,0,116.040451049805,,,,,,,,,,,,,,,,,,,,,,,,,,,,,,,,,
,3832831017.69058,118.732891082764,9999.6435546875,0.00100986367811006,8.67768765536168E-8,1,2,13.4005146026611,4.98335946065089,32.930001616478,1.33932930466309,0.19956909433487,1,9.08631153221227E-6,,,,,,,,,,,,,,,,,,,,,118.658950805664,118.806831359863,9999.6435546875,9999.6435546875,47.4088962054281,5.27039990346985,12.619176864624,27,1,0,0,1,0.272216796875,40.5669593811035,2,1,1,118.806831359863,0,118.732891082764,,,,,,,,,,,,,,,,,,,,,,,,,,,,,,,,,
,3832831072.75173,121.470825195313,9999.6435546875,0.000988900050154394,5.32440280914152E-8,1,2,13.4005146026611,4.98329516024524,32.930001616478,1.31152136121028,0.195292321064133,1,8.79942638602304E-6,,,,,,,,,,,,,,,,,,,,,121.421035766602,121.520614624023,9999.6435546875,9999.6435546875,47.3702055937262,5.27056238680062,12.6476211547852,27,1,0,0,1,0.272979736328125,41.055721282959,2,1,1,121.520614624023,0,121.470825195313,,,,,,,,,,,,,,,,,,,,,,,,,,,,,,,,,
,3832831127.4618,124.184299468994,9999.6435546875,0.000969124762477146,7.27162915403112E-8,1,2,13.4005146026611,4.98335035789587,32.940000295639,1.28525093931446,0.191841444049765,1,8.96348681375009E-6,,,,,,,,,,,,,,,,,,,,,124.159873962402,124.208724975586,9999.6435546875,9999.6435546875,47.3369863816589,5.27022029994899,12.6607694625854,27,1,0,0,1,0.273818969726562,41.055721282959,2,1,1,124.219505310059,0,124.184299468994,,,,,,,,,,,,,,,,,,,,,,,,,,,,,,,,,
,3832831189.69999,127.310874938965,9999.6435546875,0.000947065721487213,5.67229805494153E-8,1,2,13.4005146026611,4.98320042278846,32.940000295639,1.25592825924185,0.187582668043596,1,8.84653822041673E-6,,,,,,,,,,,,,,,,,,,,,127.266738891602,127.355010986328,9999.6435546875,9999.6435546875,47.3229170683127,5.2709897810361,12.6843729019165,27,1,0,0,1,0.273513793945313,40.5669593811035,2,1,1,127.355010986328,0,127.310874938965,,,,,,,,,,,,,,,,,,,,,,,,,,,,,,,,,
,3832831252.20269,130.390899658203,9999.6435546875,0.000925876143436937,8.26995030848203E-8,1,2,13.4005146026611,4.98314100288533,32.9499989748001,1.22786646681355,0.182965405101019,1,8.33433550645032E-6,,,,,,,,,,,,,,,,,,,,,130.341354370117,130.440444946289,9999.6435546875,9999.6435546875,47.3741137363223,5.27170078962526,12.6946506500244,27,1,0,0,1,0.273208618164062,41.055721282959,2,1,1,130.440444946289,0,130.390899658203,,,,,,,,,,,,,,,,,,,,,,,,,,,,,,,,,
,3832831304.45107,133.013641357422,9999.6435546875,0.000908451191047796,9.21639879291588E-8,1,2,13.4005146026611,4.98283499197042,32.9600013792515,1.20461899930793,0.179775237687498,1,8.37960788930093E-6,,,,,,,,,,,,,,,,,,,,,132.960021972656,133.067260742188,9999.6435546875,9999.6435546875,47.3717688507646,5.27307096088254,12.7222328186035,27,1,0,0,1,0.272140502929687,41.055721282959,2,1,1,133.067260742188,0,133.013641357422,,,,,,,,,,,,,,,,,,,,,,,,,,,,,,,,,
,3832831357.15345,135.630531311035,9999.6435546875,0.000892451705913799,9.38886836143324E-8,1,2,13.4005146026611,4.98280552769716,32.9700000584126,1.18343590243495,0.176306897855393,1,8.0055213276609E-6,,,,,,,,,,,,,,,,,,,,,135.594863891602,135.666198730469,9999.6435546875,9999.6435546875,47.391700378005,5.27250238655124,12.7400674819946,27,1,0,0,1,0.27374267578125,40.5669593811035,2,1,1,135.666198730469,0,135.630531311035,,,,,,,,,,,,,,,,,,,,,,,,,,,,,,,,,
,3832831411.5277,138.341575622559,9999.6435546875,0.000875827497565393,9.29371245478289E-8,1,2,13.4005146026611,4.98279927836087,32.9700000584126,1.16140376276206,0.172919463306048,1,7.77884556883584E-6,,,,,,,,,,,,,,,,,,,,,138.310028076172,138.373123168945,9999.6435546875,9999.6435546875,47.4772887008608,5.27249938191216,12.7573900222778,25,1,64,0,0,0.272445678710938,40.5669593811035,2,1,1,138.373123168945,0,138.341575622559,,,,,,,,,,,,,,,,,,,,,,,,,,,,,,,,,
,3832831465.78564,141.049751281738,9999.6435546875,0.000859796831154277,1.08043604531501E-7,1,2,13.4005146026611,4.98265925333312,32.9799987375736,1.14009117091647,0.169825958289974,1,7.69526541677987E-6,,,,,,,,,,,,,,,,,,,,,141.000762939453,141.098739624023,9999.6435546875,9999.6435546875,47.4010799202358,5.27313116454697,12.765682220459,27,1,0,0,1,0.271759033203125,41.055721282959,2,1,1,141.098739624023,0,141.049751281738,,,,,,,,,,,,,,,,,,,,,,,,,,,,,,,,,
,3832831518.02677,143.646835327148,9999.6435546875,0.000844747467814868,8.144983353532E-8,1,2,13.4005146026611,4.98261440164957,32.990001142025,1.12004662747897,0.167389460440076,1,7.96587196351606E-6,,,,,,,,,,,,,,,,,,,,,143.601440429688,143.692230224609,9999.6435546875,9999.6435546875,47.4663459015916,5.27201757915882,12.7876358032227,27,1,0,0,1,0.273590087890625,40.5669593811035,2,1,1,143.692230224609,0,143.646835327148,,,,,,,,,,,,,,,,,,,,,,,,,,,,,,,,,
,3832831572.4206,146.35733795166,9999.6435546875,0.000830256397210156,8.1411201249659E-8,1,2,13.4005146026611,4.98240356258885,32.990001142025,1.10083983734555,0.164002149262111,1,7.44784707716969E-6,,,,,,,,,,,,,,,,,,,,,146.305038452148,146.409637451172,9999.6435546875,9999.6435546875,47.4022523630146,5.27462538712483,12.7933101654053,27,1,0,0,1,0.2734375,40.5669593811035,2,1,1,146.409637451172,0,146.35733795166,,,,,,,,,,,,,,,,,,,,,,,,,,,,,,,,,
,3832831624.82225,148.961715698242,9999.6435546875,0.00081618978693455,5.420161275924E-8,1,2,13.4005146026611,4.9823873703111,32.9999998211861,1.08218599251363,0.161208876763551,1,7.31115510419366E-6,,,,,,,,,,,,,,,,,,,,,148.909210205078,149.014221191406,9999.6435546875,9999.6435546875,47.4085053911685,5.27457684048953,12.7989339828491,27,1,0,0,1,0.273208618164062,40.5669593811035,2,1,1,149.014221191406,0,148.961715698242,,,,,,,,,,,,,,,,,,,,,,,,,,,,,,,,,
,3832831681.23098,151.781776428223,9999.6435546875,0.000801581230491585,1.14933434353513E-7,1,2,13.4005146026611,4.98250792411857,33.0099985003471,1.0628648652387,0.158235359625865,1,7.10995808022733E-6,,,,,,,,,,,,,,,,,,,,,151.729736328125,151.83381652832,9999.6435546875,9999.6435546875,47.4448511173127,5.27468117008918,12.8283252716064,27,1,0,0,1,0.272750854492187,40.5669593811035,2,1,1,151.83381652832,0,151.781776428223,,,,,,,,,,,,,,,,,,,,,,,,,,,,,,,,,
,3832831737.63031,154.586402893066,9999.6435546875,0.000787478837982444,7.74146360000378E-8,1,2,13.4005146026611,4.98239510944154,33.0200009047985,1.04412546982233,0.155501944319027,1,7.02651510111556E-6,,,,,,,,,,,,,,,,,,,,,154.541351318359,154.631454467773,9999.6435546875,9999.6435546875,47.3991258489377,5.27542148686734,12.8410902023315,27,1,0,0,1,0.274200439453125,40.5669593811035,2,1,1,154.631454467773,0,154.586402893066,,,,,,,,,,,,,,,,,,,,,,,,,,,,,,,,,
,3832831790.06092,157.237731933594,9999.6435546875,0.000774655387078574,7.85670326974625E-8,1,2,13.4005146026611,4.98230404414225,33.0299995839596,1.02708106602684,0.153079612403448,1,6.99776307493986E-6,,,,,,,,,,,,,,,,,,,,,157.184768676758,157.29069519043,9999.6435546875,9999.6435546875,47.4198390046973,5.27588852126055,12.8548612594604,27,1,0,0,1,0.273818969726562,40.5669593811035,2,1,1,157.29069519043,0,157.237731933594,,,,,,,,,,,,,,,,,,,,,,,,,,,,,,,,,
,3832831842.72668,159.806785583496,9999.6435546875,0.000762712498087643,6.84708118751564E-8,1,2,13.4005146026611,4.98217802636406,33.0299995839596,1.01124885450939,0.150446547891734,1,6.68814532321053E-6,,,,,,,,,,,,,,,,,,,,,159.743850708008,159.869720458984,9999.6435546875,9999.6435546875,47.3729412935435,5.2764157550558,12.8668069839478,27,1,0,0,1,0.275421142578125,41.055721282959,2,1,1,159.869720458984,0,159.806785583496,,,,,,,,,,,,,,,,,,,,,,,,,,,,,,,,,
,3832831897.01881,162.541793823242,9999.6435546875,0.00075026415057361,9.1007566386837E-8,1,2,13.4005146026611,4.98211503793698,33.0399982631207,0.994720591855203,0.148033225497573,1,6.61266575615298E-6,,,,,,,,,,,,,,,,,,,,,162.477325439453,162.606262207031,9999.6435546875,9999.6435546875,47.4194481904377,5.27721854059067,12.8641138076782,27,1,0,0,1,0.274887084960938,40.5669593811035,2,1,1,162.606262207031,0,162.541793823242,,,,,,,,,,,,,,,,,,,,,,,,,,,,,,,,,
,3832831953.28989,165.35041809082,9999.6435546875,0.000737384887449343,8.3039861966984E-8,1,2,13.4005146026611,4.98195057704964,33.0599993467331,0.97759781555162,0.145505451628114,1,6.51421974509638E-6,,,,,,,,,,,,,,,,,,,,,165.311935424805,165.388900756836,9999.6435546875,9999.6435546875,47.3440210383319,5.27784828322701,12.8899869918823,27,1,0,0,1,0.275497436523438,40.5669593811035,2,1,1,165.388900756836,0,165.35041809082,,,,,,,,,,,,,,,,,,,,,,,,,,,,,,,,,
,3832832007.8375,168.054222106934,9999.6435546875,0.000725749811381026,6.93639644894024E-8,1,2,13.4005146026611,4.9818286498299,33.0700017511845,0.962112026382537,0.143405742968548,1,6.56286882905868E-6,,,,,,,,,,,,,,,,,,,,,167.99836730957,168.110076904297,9999.6435546875,9999.6435546875,47.3576995374185,5.27810965614676,12.9043188095093,27,1,0,0,1,0.274658203125,40.5669593811035,2,1,1,168.110076904297,0,168.054222106934,,,,,,,,,,,,,,,,,,,,,,,,,,,,,,,,,
,3832832062.1132,170.771781921387,9999.6435546875,0.000714483434196433,7.19429672583433E-8,1,2,13.4005146026611,4.98198324254563,33.0800004303455,0.947216688495432,0.141186107978718,1,6.46140211998988E-6,,,,,,,,,,,,,,,,,,,,,170.720321655273,170.8232421875,9999.6435546875,9999.6435546875,47.4229655187742,5.27732446623987,12.9232788085938,27,1,0,0,1,0.27435302734375,40.5669593811035,2,1,1,170.8232421875,0,170.771781921387,,,,,,,,,,,,,,,,,,,,,,,,,,,,,,,,,
,3832832114.41772,173.37230682373,9999.6435546875,0.000703917103001527,1.02995010952077E-7,1,2,13.4005146026611,4.98204257670241,33.0899991095066,0.933262189574434,0.138825682848736,1,6.15888278748332E-6,,,,,,,,,,,,,,,,,,,,,173.320922851562,173.423690795898,9999.6435546875,9999.6435546875,47.4421154174954,5.27767654163592,12.9278707504272,27,1,0,0,1,0.273666381835938,40.5669593811035,2,1,1,173.423690795898,0,173.37230682373,,,,,,,,,,,,,,,,,,,,,,,,,,,,,,,,,
,3832832168.08131,176.045585632324,9999.6435546875,0.000693481111604615,4.69655602596982E-8,1,2,13.4005146026611,4.98185279521471,33.0899991095066,0.919356015555271,0.136917159515621,1,6.18570407922681E-6,,,,,,,,,,,,,,,,,,,,,175.96028137207,176.130889892578,9999.6435546875,9999.6435546875,47.4038156200531,5.27795595509499,12.9499073028564,27,1,0,0,1,0.274658203125,40.5669593811035,2,1,1,176.130889892578,0,176.045585632324,,,,,,,,,,,,,,,,,,,,,,,,,,,,,,,,,
,3832832221.35687,178.698616027832,9999.6435546875,0.000683435157649624,8.32435002285046E-8,1,2,13.4005146026611,4.98215919496222,33.100001513958,0.906111227272922,0.134968363845034,1,6.1135959686484E-6,,,,,,,,,,,,,,,,,,,,,178.665710449219,178.731521606445,9999.6435546875,9999.6435546875,47.381539207255,5.27699265630479,12.9532718658447,27,1,0,0,1,0.273818969726562,40.5669593811035,2,1,1,178.731521606445,0,178.698616027832,,,,,,,,,,,,,,,,,,,,,,,,,,,,,,,,,
,3832832275.95207,181.432518005371,9999.6435546875,0.000673320593029159,6.83202493823898E-8,1,2,13.4005146026611,4.9822014247401,33.110000193119,0.8927389083697,0.132776652258333,1,5.87563529543323E-6,,,,,,,,,,,,,,,,,,,,,181.37255859375,181.492477416992,9999.6435546875,9999.6435546875,47.3877922354089,5.2768249257555,12.9651927947998,27,1,0,0,1,0.273895263671875,40.5669593811035,2,1,1,181.492477416992,0,181.432518005371,,,,,,,,,,,,,,,,,,,,,,,,,,,,,,,,,
,3832832332.19288,184.22924041748,9999.6435546875,0.000663181971053409,3.62434429805643E-8,1,2,13.4005146026611,4.98217188733809,33.1199988722801,0.879297390665591,0.130717757565303,1,5.7430735703924E-6,,,,,,,,,,,,,,,,,,,,,184.190368652344,184.268112182617,9999.6435546875,9999.6435546875,47.5015191849569,5.27738050071168,12.9713668823242,27,1,0,0,1,0.274429321289062,40.5669593811035,2,1,1,184.268112182617,0,184.22924041748,,,,,,,,,,,,,,,,,,,,,,,,,,,,,,,,,
,3832832386.49683,186.953399658203,9999.6435546875,0.00065362035528666,6.00870226182221E-8,1,2,13.4005146026611,4.98219535830681,33.1300012767315,0.866615522197035,0.128905101137154,1,5.71388432608741E-6,,,,,,,,,,,,,,,,,,,,,186.916687011719,186.990112304687,9999.6435546875,9999.6435546875,47.422183890255,5.27744092743401,12.9942960739136,27,1,0,0,1,0.273208618164062,40.5669593811035,2,1,1,186.990112304687,0,186.953399658203,,,,,,,,,,,,,,,,,,,,,,,,,,,,,,,,,
,3832832441.08121,189.650314331055,9999.6435546875,0.000644299405270066,5.49714931218618E-8,1,2,13.4005146026611,4.98224959187598,33.1399999558926,0.854278491130088,0.127007454061337,1,5.58622849521633E-6,,,,,,,,,,,,,,,,,,,,,189.588928222656,189.711700439453,9999.6435546875,9999.6435546875,47.4733805582646,5.27763491697703,12.9971570968628,27,1,0,0,1,0.274658203125,40.5669593811035,2,1,1,189.711700439453,0,189.650314331055,,,,,,,,,,,,,,,,,,,,,,,,,,,,,,,,,
,3832832497.37692,192.487091064453,9999.6435546875,0.000634760220900842,5.22357080440252E-8,1,2,13.4005146026611,4.98217574108051,33.160001039505,0.841603806829054,0.125192627948605,1,5.55484462577829E-6,,,,,,,,,,,,,,,,,,,,,192.452651977539,192.521530151367,9999.6435546875,9999.6435546875,47.3752861791012,5.27762181472937,13.0125074386597,27,1,0,0,1,0.275344848632813,40.5669593811035,2,1,1,192.521530151367,0,192.487091064453,,,,,,,,,,,,,,,,,,,,,,,,,,,,,,,,,
,3832832551.9198,195.200874328613,9999.6435546875,0.000625958100872033,6.67347539571705E-8,1,2,13.4005146026611,4.98209610371076,33.1699997186661,0.829911954866275,0.123477161327678,1,5.49534534525824E-6,,,,,,,,,,,,,,,,,,,,,195.146408081055,195.255340576172,9999.6435546875,9999.6435546875,47.4292185469281,5.27831908444078,13.0385875701904,27,1,0,0,1,0.2752685546875,40.5669593811035,2,1,1,195.255340576172,0,195.200874328613,,,,,,,,,,,,,,,,,,,,,,,,,,,,,,,,,
,3832832608.19772,197.993560791016,9999.6435546875,0.000617116278294844,7.0659717528937E-8,1,2,13.4005146026611,4.98206571299305,33.1799983978271,0.818202448337934,0.121588460268713,1,5.30959386939594E-6,,,,,,,,,,,,,,,,,,,,,197.95036315918,198.036758422852,9999.6435546875,9999.6435546875,47.4542306595435,5.27900672776463,13.0426597595215,27,1,0,0,1,0.27557373046875,41.055721282959,2,1,1,198.036758422852,0,197.993560791016,,,,,,,,,,,,,,,,,,,,,,,,,,,,,,,,,
,3832832662.80956,200.750053405762,9999.6435546875,0.000608751854666817,6.50441236706777E-8,1,2,13.4005146026611,4.98222912393688,33.1999994814396,0.807124926695957,0.120116832984674,1,5.3664314655806E-6,,,,,,,,,,,,,,,,,,,,,200.695816040039,200.804290771484,9999.6435546875,9999.6435546875,47.4198390046973,5.27842522941078,13.0539016723633,27,1,0,0,1,0.275192260742187,40.5669593811035,2,1,1,200.804290771484,0,200.750053405762,,,,,,,,,,,,,,,,,,,,,,,,,,,,,,,,,
,3832832717.036,203.424049377441,9999.6435546875,0.000600646047122259,5.75605707247289E-8,1,2,13.4005146026611,4.98219964254874,33.1999994814396,0.796373065022632,0.118503283454121,1,5.28504906166679E-6,,,,,,,,,,,,,,,,,,,,,203.365615844727,203.482482910156,9999.6435546875,9999.6435546875,47.4350807608223,5.27833195586125,13.0843544006348,27,1,0,0,1,0.273590087890625,40.5669593811035,2,1,1,203.482482910156,0,203.424049377441,,,,,,,,,,,,,,,,,,,,,,,,,,,,,,,,,
,3832832771.30072,206.137512207031,9999.6435546875,0.000592537138608627,5.03103613436823E-8,1,2,13.4005146026611,4.98211605024285,33.220000565052,0.785599370542029,0.116931625328426,1,5.23695083407103E-6,,,,,,,,,,,,,,,,,,,,,206.082717895508,206.192306518555,9999.6435546875,9999.6435546875,47.3979534061589,5.27782152651961,13.0758590698242,27,1,0,0,1,0.2752685546875,40.5669593811035,2,1,1,206.192306518555,0,206.137512207031,,,,,,,,,,,,,,,,,,,,,,,,,,,,,,,,,
,3832832827.87563,208.948448181152,9999.6435546875,0.000584517456934849,9.2482473748884E-8,1,2,13.4005146026611,4.9821477633175,33.2299992442131,0.774998737253901,0.115169270114622,1,5.02990730359792E-6,,,,,,,,,,,,,,,,,,,,,208.880920410156,209.015975952148,9999.6435546875,9999.6435546875,47.3823208357742,5.27849067730734,13.0999402999878,27,1,0,0,1,0.274505615234375,40.5669593811035,2,1,1,209.015975952148,0,208.948448181152,,,,,,,,,,,,,,,,,,,,,,,,,,,,,,,,,
,3832832882.21971,211.661071777344,9999.6435546875,0.000576972323463848,4.86088568716155E-8,1,2,13.4005146026611,4.98217508225944,33.2400016486645,0.764984880174189,0.11379570110106,1,5.04951253778831E-6,,,,,,,,,,,,,,,,,,,,,211.607391357422,211.714752197266,9999.6435546875,9999.6435546875,47.4690816014089,5.27855320618493,13.1092834472656,27,1,0,0,1,0.273056030273438,40.5669593811035,2,1,1,211.714752197266,0,211.661071777344,,,,,,,,,,,,,,,,,,,,,,,,,,,,,,,,,
,3832832934.43761,214.259925842285,9999.6435546875,0.000569821046995544,8.58477472195692E-8,1,2,13.4005146026611,4.98204919470587,33.2500003278255,0.755503695985318,0.112190997914398,1,4.84351830206579E-6,,,,,,,,,,,,,,,,,,,,,214.21076965332,214.30908203125,9999.6435546875,9999.6435546875,47.3901371209666,5.27850040831499,13.1250867843628,27,1,0,0,1,0.274810791015625,40.5669593811035,2,1,1,214.30908203125,0,214.259925842285,,,,,,,,,,,,,,,,,,,,,,,,,,,,,,,,,
,3832832988.16396,216.948425292969,9999.6435546875,0.000562590940845285,6.56985979200873E-8,1,2,13.4005146026611,4.98225673382011,33.2599990069866,0.745948233969329,0.110859631712751,1,4.84671015119737E-6,,,,,,,,,,,,,,,,,,,,,216.856246948242,217.040603637695,9999.6435546875,9999.6435546875,47.3709872222454,5.27816632374389,13.1304187774658,27,1,0,0,1,0.274200439453125,41.055721282959,2,1,1,217.040603637695,0,216.948425292969,,,,,,,,,,,,,,,,,,,,,,,,,,,,,,,,,
,3832833041.39095,219.635856628418,9999.6435546875,0.000555788634366816,5.7228638159916E-8,1,2,13.4005146026611,4.98208977639052,33.270001411438,0.736896366228522,0.10950476217657,1,4.78100918535205E-6,,,,,,,,,,,,,,,,,,,,,219.594207763672,219.677505493164,9999.6435546875,9999.6435546875,47.3834932785531,5.27914086532724,13.1565866470337,27,1,0,0,1,0.273666381835938,40.5669593811035,2,1,1,219.677505493164,0,219.635856628418,,,,,,,,,,,,,,,,,,,,,,,,,,,,,,,,,
,3832833095.77644,222.308746337891,9999.6435546875,0.000548797695571388,5.8285764976283E-8,1,2,13.4005146026611,4.98202983364229,33.2899987697601,0.727605315758711,0.108197427871496,1,4.77499700992565E-6,,,,,,,,,,,,,,,,,,,,,222.270736694336,222.346755981445,9999.6435546875,9999.6435546875,47.4088962054281,5.27972637264832,13.1560363769531,25,1,64,0,0,0.27374267578125,40.5669593811035,2,1,1,222.346755981445,0,222.308746337891,,,,,,,,,,,,,,,,,,,,,,,,,,,,,,,,,
,3832833148.02348,224.935569763184,9999.6435546875,0.000542370337096623,9.75605615561693E-8,1,2,13.4005146026611,4.98217544924921,33.3000011742115,0.719136663383908,0.106762919540708,1,4.58979003905036E-6,,,,,,,,,,,,,,,,,,,,,224.886901855469,224.984237670898,9999.6435546875,9999.6435546875,47.4620469447358,5.27937371211837,13.1880521774292,27,1,0,0,1,0.2740478515625,40.5669593811035,2,1,1,224.984237670898,0,224.935569763184,,,,,,,,,,,,,,,,,,,,,,,,,,,,,,,,,
,3832833202.37904,227.631683349609,9999.6435546875,0.000535700566180236,6.99141361206915E-8,1,2,13.4005146026611,4.98211851119619,33.3099998533726,0.710280751458547,0.105457100895259,1,4.5399366790699E-6,,,,,,,,,,,,,,,,,,,,,227.578643798828,227.684722900391,9999.6435546875,9999.6435546875,47.450713331207,5.28009472987658,13.2099256515503,27,1,0,0,1,0.274810791015625,40.5669593811035,2,1,1,227.684722900391,0,227.631683349609,,,,,,,,,,,,,,,,,,,,,,,,,,,,,,,,,
,3832833254.78716,230.255523681641,9999.6435546875,0.000529471696764476,4.88188747263841E-8,1,2,13.4005146026611,4.98218061856308,33.330000936985,0.702031245927266,0.104252097726862,1,4.50177592992569E-6,,,,,,,,,,,,,,,,,,,,,230.211059570313,230.299987792969,9999.6435546875,9999.6435546875,47.4163216763608,5.28001701927419,13.2167634963989,27,1,0,0,1,0.273666381835938,40.5669593811035,2,1,1,230.299987792969,0,230.255523681641,,,,,,,,,,,,,,,,,,,,,,,,,,,,,,,,,
,3832833309.52025,232.989356994629,9999.6435546875,0.000523133840988267,6.72062436064779E-8,1,2,13.4005146026611,4.9824212508383,33.3399996161461,0.693660913282352,0.103103284331998,1,4.5173920998635E-6,,,,,,,,,,,,,,,,,,,,,232.949401855469,233.029312133789,9999.6435546875,9999.6435546875,47.4092870196877,5.27825896966931,13.2234830856323,27,1,0,0,1,0.27435302734375,39.1006851196289,2,1,1,233.029312133789,0,232.989356994629,,,,,,,,,,,,,,,,,,,,,,,,,,,,,,,,,
,3832833364.81456,235.730850219727,9999.6435546875,0.000516796432250683,6.10366635830551E-8,1,2,13.4005146026611,4.98239542175247,33.3499982953072,0.685268319876356,0.101742602691412,1,4.37910723420599E-6,,,,,,,,,,,,,,,,,,,,,235.641540527344,235.820159912109,9999.6435546875,9999.6435546875,47.3518373235242,5.2789183168603,13.253701210022,27,1,0,0,1,0.274429321289062,40.5669593811035,2,1,1,235.820159912109,0,235.730850219727,,,,,,,,,,,,,,,,,,,,,,,,,,,,,,,,,
,3832833421.9915,238.597145080566,9999.6435546875,0.000510525545349105,5.49995121794841E-8,1,2,13.4005146026611,4.9823795528206,33.3600006997585,0.676952209022607,0.100493303623341,1,4.31519932546851E-6,,,,,,,,,,,,,,,,,,,,,238.539276123047,238.655014038086,9999.6435546875,9999.6435546875,47.4100686482069,5.27855245328034,13.2845487594604,27,1,0,0,1,0.274276733398438,40.5669593811035,2,1,1,238.655014038086,0,238.597145080566,,,,,,,,,,,,,,,,,,,,,,,,,,,,,,,,,
,3832833476.40911,241.306663513184,9999.6435546875,0.000504513976150267,7.53834934038857E-8,1,2,13.4005146026611,4.98227053956855,33.380001783371,0.668954487631884,0.0993523513535091,1,4.29855940123748E-6,,,,,,,,,,,,,,,,,,,,,241.262100219727,241.351226806641,9999.6435546875,9999.6435546875,47.50855384163,5.27910986588113,13.2999086380005,27,1,0,0,1,0.273590087890625,40.5669593811035,2,1,1,241.351226806641,0,241.306663513184,,,,,,,,,,,,,,,,,,,,,,,,,,,,,,,,,
,3832833531.15314,244.045402526855,9999.6435546875,0.000498710696886467,3.37931315838796E-8,1,2,13.4005146026611,4.98193276157275,33.3999991416931,0.661217404472217,0.098062718414705,1,4.14539899102953E-6,,,,,,,,,,,,,,,,,,,,,244.022979736328,244.067825317383,9999.6435546875,9999.6435546875,47.4569663593608,5.27962439119343,13.3392000198364,27,1,0,0,1,0.273971557617187,40.5669593811035,2,1,1,244.067825317383,0,244.045402526855,,,,,,,,,,,,,,,,,,,,,,,,,,,,,,,,,
,3832833583.47145,246.658790588379,9999.6435546875,0.000493220792342831,5.86253492614427E-8,1,2,13.4005146026611,4.98218185962194,33.4100015461445,0.653962754709109,0.0971381132112587,1,4.21142875008171E-6,,,,,,,,,,,,,,,,,,,,,246.597732543945,246.719848632813,9999.6435546875,9999.6435546875,47.3897463067069,5.27993309438794,13.3524990081787,27,1,0,0,1,0.274734497070313,40.5669593811035,2,1,1,246.719848632813,0,246.658790588379,,,,,,,,,,,,,,,,,,,,,,,,,,,,,,,,,
,3832833637.7054,249.352851867676,9999.6435546875,0.000487705643068211,4.13941602790385E-8,1,2,13.4005146026611,4.98190093764575,33.4200002253056,0.646614944618953,0.095938681714686,1,4.08462583502863E-6,,,,,,,,,,,,,,,,,,,,,249.29508972168,249.410614013672,9999.6435546875,9999.6435546875,47.5202782694185,5.28066984817874,13.3852119445801,27,1,0,0,1,0.273590087890625,40.5669593811035,2,1,1,249.410614013672,0,249.352851867676,,,,,,,,,,,,,,,,,,,,,,,,,,,,,,,,,
,3832833690.02796,251.966011047363,9999.6435546875,0.000482304916683124,3.6845732718026E-8,1,2,13.4005146026611,4.98193558253319,33.4299989044666,0.639443481043028,0.0949996382584611,1,4.13164266284164E-6,,,,,,,,,,,,,,,,,,,,,251.917144775391,252.014877319336,9999.6435546875,9999.6435546875,47.4108502767262,5.28122678171014,13.4375133514404,27,1,0,0,1,0.274658203125,40.5669593811035,2,1,1,252.014877319336,0,251.966011047363,,,,,,,,,,,,,,,,,,,,,,,,,,,,,,,,,
,3832833744.38567,254.645545959473,9999.6435546875,0.000476928798912674,4.15140402515265E-8,1,2,13.4005146026611,4.98185433268921,33.4499999880791,0.632317036302221,0.0938283925174018,1,4.00256080177211E-6,,,,,,,,,,,,,,,,,,,,,254.592071533203,254.699020385742,9999.6435546875,9999.6435546875,47.4202298189569,5.28184221694239,13.4743394851685,27,1,0,0,1,0.275497436523438,40.5669593811035,2,1,1,254.699020385742,0,254.645545959473,,,,,,,,,,,,,,,,,,,,,,,,,,,,,,,,,
,3832833800.80867,257.492156982422,9999.6435546875,0.000471445267581637,5.94229815197232E-8,1,2,13.4005146026611,4.98182293868203,33.4700010716915,0.625037365532012,0.0927784133307855,1,3.97885867053152E-6,,,,,,,,,,,,,,,,,,,,,257.449157714844,257.53515625,9999.6435546875,9999.6435546875,47.4214022617358,5.28240465811288,13.5238780975342,27,1,0,0,1,0.276641845703125,40.5669593811035,2,1,1,257.53515625,0,257.492156982422,,,,,,,,,,,,,,,,,,,,,,,,,,,,,,,,,
,3832833855.17591,260.195098876953,9999.6435546875,0.000466284193950814,4.51124835979066E-8,1,2,13.4005146026611,4.98185217856842,33.4799997508526,0.618186804263238,0.0918567600752862,1,4.00557865658844E-6,,,,,,,,,,,,,,,,,,,,,260.152160644531,260.238037109375,9999.6435546875,9999.6435546875,47.4897947571685,5.28276562747983,13.6071290969849,27,1,0,0,1,0.27435302734375,40.5669593811035,2,1,1,260.238037109375,0,260.195098876953,,,,,,,,,,,,,,,,,,,,,,,,,,,,,,,,,
,3832833908.89577,262.881240844727,9999.6435546875,0.000461179614952437,6.00339859186212E-8,1,2,13.4005146026611,4.98171074169822,33.4899984300137,0.611397579633342,0.0908324931491581,1,3.95032368310441E-6,,,,,,,,,,,,,,,,,,,,,262.796997070313,262.965484619141,9999.6435546875,9999.6435546875,47.5073813988512,5.28339967507664,13.6817321777344,27,1,0,0,1,0.274658203125,40.5669593811035,2,1,1,262.965484619141,0,262.881240844727,,,,,,,,,,,,,,,,,,,,,,,,,,,,,,,,,
,3832833962.14666,265.530456542969,9999.6435546875,0.000456368527123438,5.25227486303862E-8,1,2,13.4005146026611,4.98142797958499,33.5099995136261,0.604978115418756,0.0898359776448442,1,3.87751744524294E-6,,,,,,,,,,,,,,,,,,,,,265.491363525391,265.569549560547,9999.6435546875,9999.6435546875,47.5214507121973,5.28468153131048,13.7650365829468,27,1,0,0,1,0.276031494140625,40.5669593811035,2,1,1,265.569549560547,0,265.530456542969,,,,,,,,,,,,,,,,,,,,,,,,,,,,,,,,,
,3832834019.68264,268.410079956055,9999.6435546875,0.000451136797157515,3.66559299218178E-8,1,2,13.4005146026611,4.98167523221079,33.5199981927872,0.598081594048744,0.0888258234194317,1,3.84335653289789E-6,,,,,,,,,,,,,,,,,,,,,268.323883056641,268.496276855469,9999.6435546875,9999.6435546875,47.4960477853223,5.28374793626875,13.870997428894,27,1,0,0,1,0.275039672851562,40.5669593811035,2,1,1,268.496276855469,0,268.410079956055,,,,,,,,,,,,,,,,,,,,,,,,,,,,,,,,,
,3832834076.82474,271.253646850586,9999.6435546875,0.000446100804823276,2.97464204761043E-8,1,2,13.4005146026611,4.98158948085583,33.5399992763996,0.591390344532454,0.0878390036297134,1,3.80558373898664E-6,,,,,,,,,,,,,,,,,,,,,271.205780029297,271.301513671875,9999.6435546875,9999.6435546875,47.4042064343127,5.2836842421621,13.9726095199585,27,1,0,0,1,0.27557373046875,40.5669593811035,2,1,1,271.301513671875,0,271.253646850586,,,,,,,,,,,,,,,,,,,,,,,,,,,,,,,,,
,3832834131.22062,273.948593139648,9999.6435546875,0.000441370638308352,5.35879907989878E-8,1,2,13.4005146026611,4.98160901114935,33.550001680851,0.585138762408248,0.086793708391234,1,3.67905946206518E-6,,,,,,,,,,,,,,,,,,,,,273.900207519531,273.996978759766,9999.6435546875,9999.6435546875,47.4249195900723,5.28402869986522,13.9341344833374,27,1,0,0,1,0.275802612304687,40.5669593811035,2,1,1,273.996978759766,0,273.948593139648,,,,,,,,,,,,,,,,,,,,,,,,,,,,,,,,,
,3832834184.90537,276.666030883789,9999.6435546875,0.000436698038143606,4.75286800096288E-8,1,2,13.4005146026611,4.98151757350776,33.5699990391731,0.578921067110532,0.0859334538683728,1,3.68588759918706E-6,,,,,,,,,,,,,,,,,,,,,276.58251953125,276.749542236328,9999.6435546875,9999.6435546875,47.4788519578993,5.28480618367632,13.8985776901245,27,1,0,0,1,0.275039672851562,40.5669593811035,2,1,1,276.749542236328,0,276.666030883789,,,,,,,,,,,,,,,,,,,,,,,,,,,,,,,,,
,3832834240.34226,279.418258666992,9999.6435546875,0.00043212533679589,4.96765554579012E-8,1,2,13.4005146026611,4.98152330007863,33.5900001227856,0.572848908038385,0.0851133924837186,1,3.70728176491116E-6,,,,,,,,,,,,,,,,,,,,,279.394226074219,279.442291259766,9999.6435546875,9999.6435546875,47.496438599582,5.28557772855142,13.8760652542114,27,1,0,0,1,0.274887084960938,40.5669593811035,2,1,1,279.442291259766,0,279.418258666992,,,,,,,,,,,,,,,,,,,,,,,,,,,,,,,,,
,3832834295.71443,282.159683227539,9999.6435546875,0.000427372947512604,4.22346468920905E-8,1,2,13.4005146026611,4.98153781920528,33.5999988019466,0.566571085244615,0.0840350913515151,1,3.55908102029176E-6,,,,,,,,,,,,,,,,,,,,,282.084411621094,282.234954833984,9999.6435546875,9999.6435546875,47.3842749070723,5.28571580997351,13.9048557281494,27,1,0,0,1,0.276412963867187,40.5669593811035,2,1,1,282.234954833984,0,282.159683227539,,,,,,,,,,,,,,,,,,,,,,,,,,,,,,,,,
,3832834348.97134,284.824172973633,9999.6435546875,0.000423061553762747,3.99293456764351E-8,1,2,13.4005146026611,4.98152026822178,33.6199998855591,0.560855967652788,0.0831637748166307,1,3.5057289464201E-6,,,,,,,,,,,,,,,,,,,,,284.78466796875,284.863677978516,9999.6435546875,9999.6435546875,47.4917488284666,5.2859152118289,13.9006385803223,27,1,0,0,1,0.27679443359375,40.5669593811035,2,1,1,284.863677978516,0,284.824172973633,,,,,,,,,,,,,,,,,,,,,,,,,,,,,,,,,
,3832834401.20722,287.252792358398,9999.6435546875,0.000419254165256384,6.18623723634311E-8,1,2,13.4005146026611,4.98162414549949,33.6400009691715,0.555793804526464,0.0826364758101907,1,3.63901394691761E-6,,,,,,,,,,,,,,,,,,,,,287.206848144531,287.298736572266,9999.6435546875,9999.6435546875,47.4307818039666,5.28501741524506,13.9435768127441,27,1,0,0,1,0.27679443359375,40.5669593811035,2,1,1,287.298736572266,0,287.252792358398,,,,,,,,,,,,,,,,,,,,,,,,,,,,,,,,,
,3832834457.78521,290.165817260742,9999.6435546875,0.000414389645631644,5.38675052147281E-8,1,2,13.4005146026611,4.98149370688658,33.6499996483326,0.54935179976207,0.0814851720829671,1,3.45397286550789E-6,,,,,,,,,,,,,,,,,,,,,290.105346679687,290.226287841797,9999.6435546875,9999.6435546875,47.4640010160339,5.28493484799362,14.0143003463745,27,1,0,0,1,0.2752685546875,40.5669593811035,2,1,1,290.226287841797,0,290.165817260742,,,,,,,,,,,,,,,,,,,,,,,,,,,,,,,,,
,3832834512.06552,292.988479614258,9999.6435546875,0.000409841192509654,5.26083534793145E-8,1,2,13.4005146026611,4.98154681313134,33.670000731945,0.54332827293822,0.0806037104639125,1,3.42492316536852E-6,,,,,,,,,,,,,,,,,,,,,292.94091796875,293.036041259766,9999.6435546875,9999.6435546875,47.4518857739858,5.28570279733784,14.1106796264648,27,1,0,0,1,0.275497436523438,40.5669593811035,2,1,1,293.036041259766,0,292.988479614258,,,,,,,,,,,,,,,,,,,,,,,,,,,,,,,,,
,3832834566.43093,295.74186706543,9999.6435546875,0.000405411051839073,3.63359215690515E-8,1,2,13.4005146026611,4.98178617403744,33.6900018155575,0.537484799893203,0.0797796728343222,1,3.41952972092284E-6,,,,,,,,,,,,,,,,,,,,,295.6904296875,295.793304443359,9999.6435546875,9999.6435546875,47.5406006109185,5.28503848761126,14.231273651123,27,1,0,0,1,0.27679443359375,40.5669593811035,2,1,1,295.793304443359,0,295.74186706543,,,,,,,,,,,,,,,,,,,,,,,,,,,,,,,,,
,3832834622.97801,298.600189208984,9999.6435546875,0.000400884360829429,4.01435041562209E-8,1,2,13.4005146026611,4.98158872056239,33.7000004947186,0.531448751190826,0.0789256706945293,1,3.41230278347798E-6,,,,,,,,,,,,,,,,,,,,,298.549499511719,298.65087890625,9999.6435546875,9999.6435546875,47.4839325432743,5.28591190652222,14.3581571578979,27,1,0,0,1,0.275344848632813,40.5669593811035,2,1,1,298.65087890625,0,298.600189208984,,,,,,,,,,,,,,,,,,,,,,,,,,,,,,,,,
,3832834677.22861,299.772750854492,9999.6435546875,0.000399662330631661,5.38124239786393E-8,1,2,13.4005146026611,4.98147801772345,33.7099991738796,0.529825583895036,0.0785894772500909,1,3.3316788305237E-6,,,,,,,,,,,,,,,,,,,,,299.767822265625,299.777679443359,9999.6435546875,9999.6435546875,47.4620469447358,5.28655640157563,14.4985446929932,27,1,0,0,1,0.275421142578125,40.5669593811035,5,1,1,299.777679443359,0,299.772750854492,,,,,,,,,,,,,,,,,,,,,,,,,,,,,,,,,
,3832834709.74793,299.890060424805,9999.6435546875,0.000399435048745929,3.84312968119709E-8,1,2,13.4005146026611,4.98146686992337,33.7099991738796,0.529523620653682,0.0785376245083621,1,3.32457118953038E-6,,,,,,,,,,,,,,,,,,,,,299.888549804687,299.891571044922,9999.6435546875,9999.6435546875,47.5468536390723,5.28671835635057,14.5658950805664,27,1,0,0,1,0.275802612304687,40.5669593811035,1,1,1,299.891571044922,0,299.890060424805,,,,,,,,,,,,,,,,,,,,,,,,,,,,,,,,,