File: SI Fig S11-13 SQUID all/Michaela_Y_Hyst300K.dat
[Header]
; MPMS3 Data File (default extension .dat)
; Copyright (c) 2007, Quantum Design, Inc. All rights reserved.
TITLE,
FILEOPENTIME,3833432996.14445,06/21/2021,10:30 am
BYAPP,MPMS3 w/ AC,1.0,1.1
INFO,MPMS3 Measurement Release 1.1.16 Build 424, MultiVu Release 2.3.4.19,APPNAME
INFO,Linear Motor Servo Controller,MOTOR_MODULE_NAME
INFO,3101-100 E1,MOTOR_HW_VERSION
INFO,MMC211,MOTOR_SERIAL_NUMBER
INFO,01.04.28,MOTOR_SOFTWARE_VERSION
INFO,Quantum Design Squid Module,SQUID_MODULE_NAME
INFO,3101-501 B0,SQUID_HW_VERSION
INFO,SQM059,SQUID_SERIAL_NUMBER
INFO,01.03.04,SQUID_SOFTWARE_VERSION
INFO,SQUID AC,AC_MODULE_NAME
INFO,3101-401 F1,AC_HW_VERSION
INFO,SAC057,AC_SERIAL_NUMBER
INFO,SQUID AC 00.95.07,AC_SOFTWARE_VERSION
INFO,TCIXXX,COIL_SERIAL_NUMBER
INFO,0,MOMENT_UNITS
INFO,Michaela_Y,SAMPLE_MATERIAL
INFO,Michaela_Y,SAMPLE_COMMENT
INFO,1.14,SAMPLE_MASS
INFO,,SAMPLE_VOLUME
INFO,,SAMPLE_MOLECULAR_WEIGHT
INFO,,SAMPLE_SIZE
INFO,,SAMPLE_SHAPE
INFO,Straw,SAMPLE_HOLDER
INFO,Standard,SAMPLE_HOLDER_DETAIL
INFO,56.41,SAMPLE_OFFSET
DATATYPE,COMMENT,1
DATATYPE,TIME,2
STARTUPAXIS,X,2
STARTUPAXIS,Y1,5
FIELDGROUP, VSM,2,3,4,5,6,8,9,10,11,14,15
FIELDGROUP, DC, 2,3,4,14,56,57,58,59,60,61,62,63,64,65,66,67,68,69
FIELDGROUP, AC, 2,3,4,11,16,17,18,19,20,21,22,23,24,25,26,27,28,29,30
STARTUPGROUP, All
[Data]
Comment,Time Stamp (sec),Temperature (K),Magnetic Field (Oe),Moment (emu),M. Std. Err. (emu),Transport Action,Averaging Time (sec),Frequency (Hz),Peak Amplitude (mm),Center Position (mm),Lockin Signal' (V),Lockin Signal (V),Range,M. Quad. Signal (emu),AC Moment (emu),AC M. Std Err. (emu),AC Phase (deg),AC Phase Std. Err. (deg),AC Susceptibility (emu/Oe),AC Suscept. Std Err. (emu/Oe),AC X' (emu/Oe),AC X' Std Err. (emu/Oe),AC X'' (emu/Oe),AC X'' Std Err. (emu/Oe),AC Drive (Oe),AC Frequency (Hz),AC Averaging Time (sec),AC Cycles,AC Range,AC Measure Type,AC Signal' (V),AC Signal'' (V),AC Trim Coil Ratio,AC Trim Coil Phase,Min. Temperature (K),Max. Temperature (K),Min. Field (Oe),Max. Field (Oe),Mass (grams),Motor Lag (deg),Pressure (Torr),Measure Count,Measurement Number,SQUID Status (code),Motor Status (code),Measure Status (code),Motor Current (amps),Motor Temp. (C),Temp. Status (code),Field Status (code),Chamber Status (code),Chamber Temp (K),Redirection State,Average Temp (K),Rotation Angle (deg),Rotator state,DC Moment Fixed Ctr (emu),DC Moment Err Fixed Ctr (emu),DC Moment Free Ctr (emu),DC Moment Err Free Ctr (emu),DC Fixed Fit,DC Free Fit,DC Calculated Center (mm),DC Calculated Center Err (mm),DC Scan Length (mm),DC Scan Time (s),DC Number of Points,DC Squid Drift,DC Min V (V),DC Max V (V),DC Scans per Measure,Map 01,Map 02,Map 03,Map 04,Map 05,Map 06,Map 07,Map 08,Map 09,Map 10,Map 11,Map 12,Map 13,Map 14,Map 15,Map 16
,3833433022.14925,299.696197509766,0.0872390866279602,2.89474155024971E-7,1.13354750682697E-8,1,2,13.4005146026611,5.00568631410063,30.7899992913008,0.000389178501803144,3.67754623156859E-5,1,-1.29497856222162E-8,,,,,,,,,,,,,,,,,,,,,299.696197509766,299.696197509766,0.0872390866279602,0.0872390866279602,46.8480777428799,5.25527720200199,10.026985168457,27,1,0,0,1,0.290145874023438,36.6568908691406,1,1,1,299.696197509766,0,299.696197509766,,,,,,,,,,,,,,,,,,,,,,,,,,,,,,,,,
,3833433041.54976,299.741287231445,1578.50415039062,-2.1521518246834E-5,2.79696807492023E-8,1,2,13.4005146026611,5.00560731915265,30.7899992913008,-0.0287735933450639,-0.00387849728785149,1,1.06210224377107E-7,,,,,,,,,,,,,,,,,,,,,299.737060546875,299.745513916016,1578.50415039062,1578.50415039062,46.9024009249665,5.25498114895938,10.8226900100708,27,1,0,0,1,0.285873413085938,37.1456527709961,1,1,1,299.745513916016,0,299.741287231445,,,,,,,,,,,,,,,,,,,,,,,,,,,,,,,,,
,3833433066.16112,299.842132568359,3684.05712890625,-5.17105322953376E-5,2.20060528027217E-8,1,2,13.4005146026611,5.00557693246386,30.7899992913008,-0.069033669735583,-0.0100420814969616,1,-2.86072457710228E-7,,,,,,,,,,,,,,,,,,,,,299.839477539063,299.844787597656,3684.05712890625,3684.05712890625,46.8926305684761,5.2549538750233,11.5817613601685,27,1,0,0,1,0.282211303710938,37.6344108581543,1,1,1,299.844787597656,0,299.842132568359,,,,,,,,,,,,,,,,,,,,,,,,,,,,,,,,,
,3833433088.05855,299.908981323242,5789.2607421875,-8.22004668269883E-5,2.51305020556934E-8,1,2,13.4005146026611,5.00548900841476,30.7899992913008,-0.109719924345307,-0.0160717526544316,1,-5.36313121683931E-7,,,,,,,,,,,,,,,,,,,,,299.906463623047,299.911499023438,5789.2607421875,5789.2607421875,46.9012284821876,5.25450003411325,12.1418342590332,27,1,0,0,1,0.283050537109375,37.6344108581543,1,1,1,299.911499023438,0,299.908981323242,,,,,,,,,,,,,,,,,,,,,,,,,,,,,,,,,
,3833433113.1096,299.959991455078,7894.56396484375,-0.00011267038829737,3.10436321803294E-8,1,2,13.4005146026611,5.0055116887994,30.7899992913008,-0.150389357013093,-0.0220456709302929,1,-7.47338166921525E-7,,,,,,,,,,,,,,,,,,,,,299.958831787109,299.961151123047,7894.56396484375,7894.56396484375,46.9407007224088,5.25470054391447,12.6690530776978,27,1,0,0,1,0.276260375976562,37.6344108581543,1,1,1,299.961151123047,0,299.959991455078,,,,,,,,,,,,,,,,,,,,,,,,,,,,,,,,,
,3833433136.69511,299.986831665039,9999.8056640625,-0.000143004409312328,2.9665172224327E-8,1,2,13.4005146026611,5.00546098488555,30.7899992913008,-0.190841060357165,-0.0282285917671504,1,-1.13416993579149E-6,,,,,,,,,,,,,,,,,,,,,299.985809326172,299.987854003906,9999.8056640625,9999.8056640625,46.9688393491011,5.25434968203416,13.0797328948975,27,1,0,0,1,0.279769897460938,37.6344108581543,1,1,1,299.987854003906,0,299.986831665039,,,,,,,,,,,,,,,,,,,,,,,,,,,,,,,,,
,3833433172.40393,300.017059326172,13332.9375,-0.000191182320845667,4.68895127046441E-8,1,2,13.4005146026611,5.00545992076164,30.7899992913008,-0.255147467309476,-0.0376493862241561,1,-1.44938822475961E-6,,,,,,,,,,,,,,,,,,,,,300.016693115234,300.017425537109,13332.9375,13332.9375,47.0630255856684,5.25451523893309,13.5742378234863,27,1,0,0,1,0.274276733398438,38.1231689453125,1,1,1,300.016693115234,0,300.017059326172,,,,,,,,,,,,,,,,,,,,,,,,,,,,,,,,,
,3833433198.17725,300.018020629883,17777.544921875,-0.000255369105083232,7.11498334413335E-8,1,2,13.4005146026611,5.00539109176432,30.7899992913008,-0.34077380590998,-0.0504992358971135,1,-2.0935948768922E-6,,,,,,,,,,,,,,,,,,,,,300.017456054687,300.018585205078,17777.544921875,17777.544921875,46.9840811052261,5.25459043753343,13.8824739456177,27,1,0,0,1,0.281906127929687,38.1231689453125,1,1,1,300.017456054687,0,300.018020629883,,,,,,,,,,,,,,,,,,,,,,,,,,,,,,,,,
,3833433233.97634,300.04638671875,21999.62890625,-0.000316164220079943,6.97695304322284E-8,1,2,13.4005146026611,5.00549749080157,30.7899992913008,-0.421895812377596,-0.0626482057778964,1,-2.68551424384561E-6,,,,,,,,,,,,,,,,,,,,,300.04638671875,300.04638671875,21999.62890625,21999.62890625,46.9563332927934,5.25507896191301,14.2336463928223,27,1,0,0,1,0.283126831054687,38.6119270324707,1,1,1,300.046356201172,0,300.04638671875,,,,,,,,,,,,,,,,,,,,,,,,,,,,,,,,,
,3833433270.94325,300.029037475586,34999.78515625,-0.000503906421377587,1.24924613882749E-7,1,2,13.4005146026611,5.00544611733929,30.7899992913008,-0.672381344793971,-0.100076591404336,1,-4.45124919467669E-6,,,,,,,,,,,,,,,,,,,,,300.027587890625,300.030487060547,34999.78515625,34999.78515625,46.8738714840146,5.25565787869756,14.5375547409058,27,1,0,0,1,0.278701782226562,38.1231689453125,1,1,1,300.027587890625,0,300.029037475586,,,,,,,,,,,,,,,,,,,,,,,,,,,,,,,,,
,3833433332.23895,300.002487182617,58332.953125,-0.000840340776357792,2.38389558213109E-7,1,2,13.4005146026611,5.00541018069656,30.7899992913008,-1.12123297242819,-0.167280496014204,1,-7.71443110298499E-6,,,,,,,,,,,,,,,,,,,,,300.002044677734,300.0029296875,58332.953125,58332.953125,46.910998838678,5.25464194116204,14.967490196228,27,1,0,0,1,0.274810791015625,38.6119270324707,1,1,1,300.002044677734,0,300.002487182617,,,,,,,,,,,,,,,,,,,,,,,,,,,,,,,,,
,3833433394.12533,299.995483398438,58333.00390625,-0.000838554463821795,2.03748436815561E-7,1,2,13.4005146026611,5.00546656054017,30.7899992913008,-1.11890124340564,-0.166681148857743,1,-7.51365303256076E-6,,,,,,,,,,,,,,,,,,,,,299.995300292969,299.995666503906,58333.00390625,58333.00390625,47.0286339308223,5.25474565445831,15.3276863098145,27,1,0,0,1,0.280914306640625,38.6119270324707,1,1,1,299.995300292969,0,299.995483398438,,,,,,,,,,,,,,,,,,,,,,,,,,,,,,,,,
,3833433448.54165,299.99299621582,34999.7734375,-0.000500658813082772,1.3429657437482E-7,1,2,13.4005146026611,5.00543719533663,30.7899992913008,-0.668102621631303,-0.0990286315769127,1,-4.12110782494681E-6,,,,,,,,,,,,,,,,,,,,,299.992889404297,299.993103027344,34999.7734375,34999.7734375,46.92936710888,5.25615647569963,15.5441761016846,27,1,0,0,1,0.28045654296875,38.6119270324707,1,1,1,299.992889404297,0,299.99299621582,,,,,,,,,,,,,,,,,,,,,,,,,,,,,,,,,
,3833433495.17518,299.998687744141,21999.73046875,-0.000313004187244839,4.84460351413588E-8,1,2,13.4005146026611,5.00548152415674,30.7899992913008,-0.417696773543788,-0.0618816390500512,1,-2.55378283952798E-6,,,,,,,,,,,,,,,,,,,,,299.997772216797,299.999603271484,21999.73046875,21999.73046875,47.0806122273511,5.25523725554634,15.7211694717407,27,1,0,0,1,0.281906127929687,38.6119270324707,1,1,1,299.997772216797,0,299.998687744141,,,,,,,,,,,,,,,,,,,,,,,,,,,,,,,,,
,3833433533.32722,299.998870849609,17777.53125,-0.000252030803086587,6.36649086371676E-8,1,2,13.4005146026611,5.00548402961932,30.7899992913008,-0.336289282993689,-0.0501143512092882,1,-2.27131526728642E-6,,,,,,,,,,,,,,,,,,,,,299.998565673828,299.999176025391,17777.53125,17777.53125,47.05130115788,5.25537027750064,15.8605175018311,27,1,0,0,1,0.282974243164062,38.6119270324707,1,1,1,299.998565673828,0,299.998870849609,,,,,,,,,,,,,,,,,,,,,,,,,,,,,,,,,
,3833433563.75255,300.000503540039,13332.8740234375,-0.000188054474519228,4.6889620892709E-8,1,2,13.4005146026611,5.00552568142712,30.7899992913008,-0.250921281811118,-0.0374370548533174,1,-1.72729413623861E-6,,,,,,,,,,,,,,,,,,,,,300.000183105469,300.000823974609,13332.8740234375,13332.8740234375,47.0872560697646,5.25542885282701,15.9233083724976,27,1,0,0,1,0.283279418945313,38.6119270324707,1,1,1,300.000183105469,0,300.000503540039,,,,,,,,,,,,,,,,,,,,,,,,,,,,,,,,,
,3833433609.43022,300.000640869141,9999.6435546875,-0.000140245618171917,2.56428684669532E-8,1,2,13.4005146026611,5.00548718804899,30.7899992913008,-0.187145021899128,-0.0277967797016378,1,-1.19654565529599E-6,,,,,,,,,,,,,,,,,,,,,300.000640869141,300.000640869141,9999.6435546875,9999.6435546875,47.0344961447165,5.25576331163916,16.0294036865234,27,1,0,0,1,0.2825927734375,38.6119270324707,1,1,1,300.000640869141,0,300.000640869141,,,,,,,,,,,,,,,,,,,,,,,,,,,,,,,,,
,3833433631.87858,300.001312255859,7894.4775390625,-0.000109939396066067,3.45073195888714E-8,1,2,13.4005146026611,5.00548662926812,30.7899992913008,-0.146668211773856,-0.0220467511455817,1,-1.130111708748E-6,,,,,,,,,,,,,,,,,,,,,300.001098632812,300.001525878906,7894.4775390625,7894.4775390625,46.9918973904184,5.2548595015956,16.0955085754395,27,1,0,0,1,0.2825927734375,39.1006851196289,1,1,1,300.001098632812,0,300.001312255859,,,,,,,,,,,,,,,,,,,,,,,,,,,,,,,,,
,3833433657.61763,300.008743286133,5789.23583984375,-7.98946188717622E-5,2.15397876067856E-8,1,2,13.4005146026611,5.00550360925148,30.7899992913008,-0.106615966866582,-0.0158110221969428,1,-6.63516519997391E-7,,,,,,,,,,,,,,,,,,,,,300.006378173828,300.011108398438,5789.23583984375,5789.23583984375,47.0407491728704,5.2561382685243,16.1378498077393,27,1,0,0,1,0.2825927734375,38.6119270324707,1,1,1,300.011108398438,0,300.008743286133,,,,,,,,,,,,,,,,,,,,,,,,,,,,,,,,,
,3833433681.06981,300.027603149414,3683.7578125,-4.97925511206563E-5,2.59827928512042E-8,1,2,13.4005146026611,5.00547219414739,30.7899992913008,-0.0664018923835146,-0.0101654429159345,1,-6.46799532468393E-7,,,,,,,,,,,,,,,,,,,,,300.027557373047,300.027648925781,3683.7578125,3683.7578125,47.1271191242454,5.25532758406132,16.1621017456055,25,1,68,0,0,0.275039672851562,39.1006851196289,1,1,1,300.027648925781,0,300.027603149414,,,,,,,,,,,,,,,,,,,,,,,,,,,,,,,,,
,3833433704.14691,300.023330688477,1578.65368652344,-2.00458596855841E-5,2.61559897455375E-8,1,2,13.4005146026611,5.00544480946877,30.7899992913008,-0.0267127312139492,-0.00423292863322567,1,-3.65543214797264E-7,,,,,,,,,,,,,,,,,,,,,300.022735595703,300.02392578125,1578.65368652344,1578.65368652344,47.0587266288127,5.25626973048098,16.2370567321777,26,1,68,0,0,0.274200439453125,39.1006851196289,1,1,1,300.022735595703,0,300.023330688477,,,,,,,,,,,,,,,,,,,,,,,,,,,,,,,,,
,3833433727.25139,300.015625,-526.163879394531,6.94357034110028E-6,2.21654973579281E-8,1,2,13.4005146026611,5.00545113919197,30.7899992913008,0.00927545969743465,0.00130477415099061,1,5.7729814548255E-9,,,,,,,,,,,,,,,,,,,,,300.014739990234,300.016510009766,-526.163879394531,-526.163879394531,47.0196452028511,5.2558656743911,16.2487754821777,27,1,0,0,1,0.279769897460938,39.1006851196289,1,1,1,300.014739990234,0,300.015625,,,,,,,,,,,,,,,,,,,,,,,,,,,,,,,,,
,3833433752.53317,300.013198852539,-2631.5048828125,3.57460175089854E-5,1.75332855719082E-8,1,2,13.4005146026611,5.00546085835901,30.7899992913008,0.0477204053856978,0.00693507768730942,1,1.92883218328562E-7,,,,,,,,,,,,,,,,,,,,,300.012451171875,300.013946533203,-2631.5048828125,-2631.5048828125,47.076704084755,5.25540666429136,16.2904148101807,27,1,0,0,1,0.282669067382813,39.1006851196289,1,1,1,300.012451171875,0,300.013198852539,,,,,,,,,,,,,,,,,,,,,,,,,,,,,,,,,
,3833433776.13959,300.004745483398,-4736.5966796875,6.54618253513212E-5,1.7308357884031E-8,1,2,13.4005146026611,5.00552575149383,30.7899992913008,0.0873695250661346,0.0128620535990655,1,4.74179003951428E-7,,,,,,,,,,,,,,,,,,,,,300.004241943359,300.005249023438,-4736.5966796875,-4736.5966796875,47.0442665012069,5.2550204327165,16.3088550567627,27,1,0,0,1,0.283737182617187,39.1006851196289,1,1,1,300.004241943359,0,300.004745483398,,,,,,,,,,,,,,,,,,,,,,,,,,,,,,,,,
,3833433802.00717,299.911682128906,-6841.68798828125,9.52782901962638E-5,2.63060564979872E-8,1,2,13.4005146026611,5.00552301400275,30.7899992913008,0.127162275090002,0.0187355180156879,1,7.01450260736123E-7,,,,,,,,,,,,,,,,,,,,,299.903594970703,299.919769287109,-6841.68798828125,-6841.68798828125,47.0212084598896,5.25479892978946,16.34375,27,1,0,0,1,0.281143188476562,39.1006851196289,1,1,1,299.903594970703,0,299.911682128906,,,,,,,,,,,,,,,,,,,,,,,,,,,,,,,,,
,3833433827.85562,299.790252685547,-8946.94140625,0.000125165837415441,1.69845183303151E-8,1,2,13.4005146026611,5.00551924640223,30.7899992913008,0.167048467085772,0.0246323910163282,1,9.36315621948391E-7,,,,,,,,,,,,,,,,,,,,,299.789093017578,299.791412353516,-8946.94140625,-8946.94140625,47.1701086928031,5.25534313344274,16.386209487915,27,1,0,0,1,0.280303955078125,39.1006851196289,1,1,1,299.788940429687,0,299.790252685547,,,,,,,,,,,,,,,,,,,,,,,,,,,,,,,,,
,3833433865.77395,299.870758056641,-11999.88671875,0.000168421408663782,3.47367503739371E-8,1,2,13.4005146026611,5.00553246845422,30.7899992913008,0.224763924208803,0.0332522580683848,1,1.34008360935849E-6,,,,,,,,,,,,,,,,,,,,,299.870758056641,299.870758056641,-11999.88671875,-11999.88671875,47.0403583586107,5.25549878563532,16.4161911010742,27,1,0,0,1,0.283660888671875,39.1006851196289,1,1,1,299.871398925781,0,299.870758056641,,,,,,,,,,,,,,,,,,,,,,,,,,,,,,,,,
,3833433897.50924,299.950820922852,-14999.615234375,0.000211029528245502,3.6455398207026E-8,1,2,13.4005146026611,5.00552196164216,30.7899992913008,0.281629841393266,0.0416302460419254,1,1.6534908462934E-6,,,,,,,,,,,,,,,,,,,,,299.947662353516,299.953979492188,-14999.615234375,-14999.615234375,47.1716719498415,5.25532348860126,16.4574794769287,27,1,0,0,1,0.282974243164062,39.1006851196289,1,1,1,299.953979492188,0,299.950820922852,,,,,,,,,,,,,,,,,,,,,,,,,,,,,,,,,
,3833433935.76799,300.000854492188,-19999.537109375,0.000281989302321308,1.2351238372235E-7,1,2,13.4005146026611,5.00546928075333,30.7899992913008,0.376327320170002,0.0556035210596085,1,2.19128907482315E-6,,,,,,,,,,,,,,,,,,,,,300.000854492188,300.000854492188,-19999.537109375,-19999.537109375,47.053255229178,5.2565142539213,16.5021743774414,27,1,0,0,1,0.278244018554687,39.5894432067871,1,1,1,300.000854492188,0,300.000854492188,,,,,,,,,,,,,,,,,,,,,,,,,,,,,,,,,
,3833433972.28753,300.015014648438,-25555.232421875,0.000360881873633032,1.6552319957369E-7,1,2,13.4005146026611,5.00549625627369,30.7899992913008,0.481622456882895,0.0711179371123068,1,2.77262109122906E-6,,,,,,,,,,,,,,,,,,,,,300.014801025391,300.015228271484,-25555.232421875,-25555.232421875,47.0630255856684,5.25575958699135,16.5597763061523,27,1,0,0,1,0.281753540039062,39.1006851196289,1,1,1,300.014801025391,0,300.015014648438,,,,,,,,,,,,,,,,,,,,,,,,,,,,,,,,,
,3833434027.54531,300.023345947266,-43333.07421875,0.000613307349445362,8.98890364805045E-8,1,2,13.4005146026611,5.0055142513176,30.7899992913008,0.818427071355465,0.121429080689848,1,5.13547942120298E-6,,,,,,,,,,,,,,,,,,,,,300.023345947266,300.023345947266,-43333.07421875,-43333.07421875,47.0481746438031,5.25591329619889,16.5979328155518,27,1,0,0,1,0.28167724609375,39.5894432067871,1,1,1,300.023345947266,0,300.023345947266,,,,,,,,,,,,,,,,,,,,,,,,,,,,,,,,,
,3833434072.41652,300.010360717773,-61110.99609375,0.000866040098067071,2.2569348507336E-7,1,2,13.4005146026611,5.00548554738327,30.7899992913008,1.15567597040859,0.171472700078785,1,7.25640174538765E-6,,,,,,,,,,,,,,,,,,,,,300.010345458984,300.010375976562,-61110.99609375,-61110.99609375,46.9020101107069,5.25555915135772,16.623908996582,26,1,68,0,0,0.282363891601562,39.5894432067871,1,1,1,300.010375976562,0,300.010360717773,,,,,,,,,,,,,,,,,,,,,,,,,,,,,,,,,
,3833434136.91339,299.997344970703,-61110.78515625,0.000864744459451599,1.67357021271556E-7,1,2,13.4005146026611,5.00553475646675,30.7899992913008,1.15387673450224,0.171832116631419,1,7.70485502523426E-6,,,,,,,,,,,,,,,,,,,,,299.997344970703,299.997344970703,-61110.78515625,-61110.78515625,46.8981019681107,5.25590266708804,16.6671028137207,27,1,0,0,1,0.28289794921875,39.5894432067871,1,1,1,299.997344970703,0,299.997344970703,,,,,,,,,,,,,,,,,,,,,,,,,,,,,,,,,
,3833434183.21971,300.016494750977,-43333.08984375,0.000611331814602193,1.32118441535392E-7,1,2,13.4005146026611,5.005452987066,30.7899992913008,0.815718129251213,0.121458160149294,1,5.43498956049616E-6,,,,,,,,,,,,,,,,,,,,,300.016326904297,300.016662597656,-43333.08984375,-43333.08984375,46.9989320470915,5.25669139703684,16.6776790618896,27,1,0,0,1,0.281982421875,39.5894432067871,1,1,1,300.016326904297,0,300.016494750977,,,,,,,,,,,,,,,,,,,,,,,,,,,,,,,,,
,3833434230.42083,300.005859375,-25555.095703125,0.000358739090822916,4.89955194177758E-8,1,2,13.4005146026611,5.00545327622911,30.7899992913008,0.478689275849843,0.0711801943856513,1,3.11945381020136E-6,,,,,,,,,,,,,,,,,,,,,300.005340576172,300.006378173828,-25555.095703125,-25555.095703125,47.0747500134569,5.2566677971878,16.7120361328125,27,1,0,0,1,0.282669067382813,39.5894432067871,1,1,1,300.005340576172,0,300.005859375,,,,,,,,,,,,,,,,,,,,,,,,,,,,,,,,,
,3833434270.33721,299.993713378906,-19999.84765625,0.000279932810731748,5.16303113943942E-8,1,2,13.4005146026611,5.00544540398988,30.7899992913008,0.373542631553444,0.0554677983274499,1,2.37751293685148E-6,,,,,,,,,,,,,,,,,,,,,299.993713378906,299.993713378906,-19999.84765625,-19999.84765625,47.0860836269858,5.25616496055403,16.7248477935791,27,1,0,0,1,0.283737182617187,39.5894432067871,1,1,1,299.993713378906,0,299.993713378906,,,,,,,,,,,,,,,,,,,,,,,,,,,,,,,,,
,3833434299.69119,299.997116088867,-14999.58984375,0.000209060402405861,2.81991315169315E-8,1,2,13.4005146026611,5.00547798469877,30.7899992913008,0.278972348730629,0.0414289658848334,1,1.77853291142485E-6,,,,,,,,,,,,,,,,,,,,,299.996856689453,299.997375488281,-14999.58984375,-14999.58984375,47.002449375428,5.25616730747772,16.7700347900391,27,1,0,0,1,0.282211303710938,39.1006851196289,1,1,1,299.997375488281,0,299.997116088867,,,,,,,,,,,,,,,,,,,,,,,,,,,,,,,,,
,3833434344.2234,299.999420166016,-9999.6435546875,0.000138350375802796,3.26622691485756E-8,1,2,13.4005146026611,5.0053799342796,30.7899992913008,0.184624186071143,0.0273230550143596,1,1.10755737162515E-6,,,,,,,,,,,,,,,,,,,,,299.999420166016,299.999420166016,-9999.6435546875,-9999.6435546875,47.0595082573319,5.2561814888237,16.7657451629639,27,1,0,0,1,0.282058715820313,39.1006851196289,1,1,1,299.999420166016,0,299.999420166016,,,,,,,,,,,,,,,,,,,,,,,,,,,,,,,,,
,3833434376.99095,299.998657226562,-8947.1162109375,0.000123358754467627,3.07340858684365E-8,1,2,13.4005146026611,5.0053863425702,30.7899992913008,0.164602288296567,0.0244792614391496,1,1.07503365666488E-6,,,,,,,,,,,,,,,,,,,,,299.998504638672,299.998809814453,-8947.1162109375,-8947.1162109375,47.1060151542261,5.25638303069609,16.7591323852539,27,1,0,0,1,0.275955200195313,39.1006851196289,1,1,1,299.998809814453,0,299.998657226562,,,,,,,,,,,,,,,,,,,,,,,,,,,,,,,,,
,3833434402.95816,299.998901367188,-6841.85009765625,9.36388008061039E-5,2.50082628233206E-8,1,2,13.4005146026611,5.00542608125226,30.7899992913008,0.124945622624106,0.0185929699269136,1,8.24358627919896E-7,,,,,,,,,,,,,,,,,,,,,299.998474121094,299.999328613281,-6841.85009765625,-6841.85009765625,47.15291286538,5.25638229175212,16.7674827575684,27,1,0,0,1,0.282669067382813,39.1006851196289,1,1,1,299.998474121094,0,299.998901367188,,,,,,,,,,,,,,,,,,,,,,,,,,,,,,,,,
,3833434434.1077,300.007125854492,-4736.68408203125,6.38715907380343E-5,3.12552240101381E-8,1,2,13.4005146026611,5.00544787141752,30.7899992913008,0.0851844853362408,0.0129841560942529,1,7.88128049913127E-7,,,,,,,,,,,,,,,,,,,,,300.006591796875,300.007659912109,-4736.68408203125,-4736.68408203125,47.0544276719569,5.2562932271586,16.7684783935547,27,1,0,0,1,0.283126831054687,39.1006851196289,1,1,1,300.007659912109,0,300.007125854492,,,,,,,,,,,,,,,,,,,,,,,,,,,,,,,,,
,3833434456.74571,300.029312133789,-2631.56713867187,3.43467182167643E-5,2.94170797975464E-8,1,2,13.4005146026611,5.00543359416059,30.7899992913008,0.0457996103239617,0.00703838218221648,1,4.65899010444912E-7,,,,,,,,,,,,,,,,,,,,,300.028381347656,300.030242919922,-2631.56713867187,-2631.56713867187,47.0798305988319,5.25642336882548,16.753023147583,27,1,0,0,1,0.274505615234375,39.1006851196289,1,1,1,300.028381347656,0,300.029312133789,,,,,,,,,,,,,,,,,,,,,,,,,,,,,,,,,
,3833434482.42974,300.017776489258,-526.724731445313,5.52343895938948E-6,1.78075591044011E-7,1,2,13.4005146026611,5.00545554290917,30.7899992913008,0.00733800879126934,0.00132685282810341,1,2.2086308234431E-7,,,,,,,,,,,,,,,,,,,,,300.017700195313,300.017852783203,-526.724731445313,-526.724731445313,47.1720627641012,5.25641361524609,16.7438278198242,27,1,0,0,1,0.274581909179687,39.1006851196289,1,1,1,300.017852783203,0,300.017776489258,,,,,,,,,,,,,,,,,,,,,,,,,,,,,,,,,
,3833434506.05606,300.019927978516,1578.71594238281,-2.08092930559315E-5,1.43836871128006E-8,1,2,13.4005146026611,5.00543597924123,30.7899992913008,-0.0277763454829441,-0.00406267295166276,1,-1.31367888998589E-7,,,,,,,,,,,,,,,,,,,,,300.017547607422,300.022308349609,1578.71594238281,1578.71594238281,47.1114865538608,5.25642222741611,16.7630348205566,27,1,0,0,1,0.281219482421875,39.1006851196289,1,1,1,300.017547607422,0,300.019927978516,,,,,,,,,,,,,,,,,,,,,,,,,,,,,,,,,
,3833434530.98251,300.031265258789,3683.74536132812,-4.99162035370792E-5,2.42342746917807E-8,1,2,13.4005146026611,5.00543004744138,30.7899992913008,-0.0666393538359754,-0.00966612584004184,1,-2.55852475683977E-7,,,,,,,,,,,,,,,,,,,,,300.031127929687,300.031402587891,3683.74536132812,3683.74536132812,47.0427032441684,5.25663744781323,16.7823638916016,27,1,0,0,1,0.282669067382813,39.1006851196289,1,1,1,300.031127929687,0,300.031265258789,,,,,,,,,,,,,,,,,,,,,,,,,,,,,,,,,
,3833434554.99793,300.03337097168,5789.2607421875,-7.93442274578822E-5,1.64256293378302E-8,1,2,13.4005146026611,5.00545139228505,30.7899992913008,-0.105889410869784,-0.015634445343412,1,-6.08472702104009E-7,,,,,,,,,,,,,,,,,,,,,300.030029296875,300.036712646484,5789.2607421875,5789.2607421875,47.0770948990146,5.25643340226126,16.7742290496826,27,1,0,0,1,0.289840698242188,38.6119270324707,1,1,1,300.036712646484,0,300.03337097168,,,,,,,,,,,,,,,,,,,,,,,,,,,,,,,,,
,3833434578.36568,300.074234008789,7894.501953125,-0.000108873687384869,3.97804809013593E-8,1,2,13.4005146026611,5.00544764053578,30.7899992913008,-0.145324042331152,-0.0212669366997985,1,-6.95598175399624E-7,,,,,,,,,,,,,,,,,,,,,300.070159912109,300.078308105469,7894.501953125,7894.501953125,47.1415792518511,5.25656239436836,16.7703018188477,27,1,0,0,1,0.274124145507813,39.1006851196289,1,1,1,300.070159912109,0,300.074234008789,,,,,,,,,,,,,,,,,,,,,,,,,,,,,,,,,
,3833434601.55863,299.867126464844,9999.6806640625,-0.00013836758834233,3.1309627767722E-8,1,2,13.4005146026611,5.00544666083825,30.7899992913008,-0.184663374884,-0.0272350276596432,1,-1.03888852102711E-6,,,,,,,,,,,,,,,,,,,,,299.856689453125,299.877563476562,9999.6806640625,9999.6806640625,47.1017161973704,5.25655965774783,16.7868270874023,27,1,0,0,1,0.279312133789062,38.6119270324707,1,1,1,299.856689453125,0,299.867126464844,,,,,,,,,,,,,,,,,,,,,,,,,,,,,,,,,
,3833434637.14156,299.872497558594,13333.037109375,-0.000185184096775209,3.75259429476928E-8,1,2,13.4005146026611,5.00542579606001,30.7899992913008,-0.247152805143478,-0.0363767626823632,1,-1.33575644832681E-6,,,,,,,,,,,,,,,,,,,,,299.868499755859,299.876495361328,13333.037109375,13333.037109375,47.0556001147357,5.25670427470434,16.7709484100342,27,1,0,0,1,0.279693603515625,38.6119270324707,1,1,1,299.876495361328,0,299.872497558594,,,,,,,,,,,,,,,,,,,,,,,,,,,,,,,,,
,3833434663.07137,299.928756713867,17777.568359375,-0.000247588174362874,5.57095956892035E-8,1,2,13.4005146026611,5.00542878785232,30.7899992913008,-0.330428001810139,-0.048718253793414,1,-1.8480597961037E-6,,,,,,,,,,,,,,,,,,,,,299.927856445313,299.929656982422,17777.568359375,17777.568359375,47.0981988690338,5.25689776475889,16.8081398010254,27,1,0,0,1,0.281982421875,38.6119270324707,1,1,1,299.929656982422,0,299.928756713867,,,,,,,,,,,,,,,,,,,,,,,,,,,,,,,,,
,3833434699.21619,299.979919433594,21999.767578125,-0.000306767292819977,9.78959921690944E-8,1,2,13.4005146026611,5.00540472052692,30.7899992913008,-0.40935592595502,-0.0607136027806818,1,-2.5525115384092E-6,,,,,,,,,,,,,,,,,,,,,299.979919433594,299.979919433594,21999.767578125,21999.767578125,47.0145646174761,5.25670351769858,16.8094940185547,27,1,0,0,1,0.283889770507813,38.6119270324707,1,1,1,299.979919433594,0,299.979919433594,,,,,,,,,,,,,,,,,,,,,,,,,,,,,,,,,
,3833434735.92819,300.012741088867,34999.734375,-0.000489483110885155,8.61282734807084E-8,1,2,13.4005146026611,5.00539779814499,30.7899992913008,-0.653190595594098,-0.096757096085105,1,-3.98422248736875E-6,,,,,,,,,,,,,,,,,,,,,300.012512207031,300.012969970703,34999.734375,34999.734375,46.9704026061396,5.25625928517844,16.8249225616455,27,1,0,0,1,0.283660888671875,38.6119270324707,1,1,1,300.012969970703,0,300.012741088867,,,,,,,,,,,,,,,,,,,,,,,,,,,,,,,,,
,3833434791.93795,300.015060424805,58333.203125,-0.000817899751482104,1.92689174806658E-7,1,2,13.4005146026611,5.00540899015152,30.7899992913008,-1.09136570060848,-0.162275144143947,1,-7.10562148126208E-6,,,,,,,,,,,,,,,,,,,,,300.014923095703,300.015197753906,58333.203125,58333.203125,46.9184243096107,5.25562605759498,16.8481025695801,27,1,0,0,1,0.283279418945313,38.6119270324707,1,1,1,300.014923095703,0,300.015060424805,,,,,,,,,,,,,,,,,,,,,,,,,,,,,,,,,
,3833434846.82426,300.004486083984,58332.85546875,-0.000817097813529327,1.2896042093503E-7,1,2,13.4005146026611,5.00543620390933,30.7899992913008,-1.09029110224795,-0.162207624457123,1,-7.16630746083207E-6,,,,,,,,,,,,,,,,,,,,,300.003936767578,300.005035400391,58332.85546875,58332.85546875,46.82775540138,5.25591394604384,16.834981918335,27,1,0,0,1,0.283432006835938,38.6119270324707,1,1,1,300.005035400391,0,300.004486083984,,,,,,,,,,,,,,,,,,,,,,,,,,,,,,,,,
,3833434901.05742,300.01350402832,34999.72265625,-0.000488265511245779,5.8804160752561E-8,1,2,13.4005146026611,5.00541009672409,30.7899992913008,-0.651566237213779,-0.0965290519866457,1,-3.98353108751E-6,,,,,,,,,,,,,,,,,,,,,300.013305664063,300.013702392578,34999.72265625,34999.72265625,47.0536460434377,5.2560616828127,16.8490505218506,27,1,0,0,1,0.281906127929687,38.1231689453125,1,1,1,300.013305664063,0,300.01350402832,,,,,,,,,,,,,,,,,,,,,,,,,,,,,,,,,
,3833434941.39147,300.028442382812,21999.580078125,-0.000305461243450772,5.17466804720974E-8,1,2,13.4005146026611,5.00543307158513,30.7899992913008,-0.40760993407589,-0.0605008770095798,1,-2.57554571182319E-6,,,,,,,,,,,,,,,,,,,,,300.027191162109,300.029693603516,21999.580078125,21999.580078125,47.0321512591588,5.25606044247569,16.9161376953125,27,1,0,0,1,0.283355712890625,38.1231689453125,1,1,1,300.029693603516,0,300.028442382812,,,,,,,,,,,,,,,,,,,,,,,,,,,,,,,,,