File: SI Fig S11-13 SQUID all/Michaela_Lu_FC1T.dat
[Header]
; MPMS3 Data File (default extension .dat)
; Copyright (c) 2007, Quantum Design, Inc. All rights reserved.
TITLE,
FILEOPENTIME,3832577930.02185,06/11/2021,12:58 pm
BYAPP,MPMS3 w/ AC,1.0,1.1
INFO,MPMS3 Measurement Release 1.1.16 Build 424, MultiVu Release 2.3.4.19,APPNAME
INFO,Linear Motor Servo Controller,MOTOR_MODULE_NAME
INFO,3101-100 E1,MOTOR_HW_VERSION
INFO,MMC211,MOTOR_SERIAL_NUMBER
INFO,01.04.28,MOTOR_SOFTWARE_VERSION
INFO,Quantum Design Squid Module,SQUID_MODULE_NAME
INFO,3101-501 B0,SQUID_HW_VERSION
INFO,SQM059,SQUID_SERIAL_NUMBER
INFO,01.03.04,SQUID_SOFTWARE_VERSION
INFO,SQUID AC,AC_MODULE_NAME
INFO,3101-401 F1,AC_HW_VERSION
INFO,SAC057,AC_SERIAL_NUMBER
INFO,SQUID AC 00.95.07,AC_SOFTWARE_VERSION
INFO,TCIXXX,COIL_SERIAL_NUMBER
INFO,0,MOMENT_UNITS
INFO,Michaela_Cu,SAMPLE_MATERIAL
INFO,Michaela_Cu,SAMPLE_COMMENT
INFO,1.44,SAMPLE_MASS
INFO,,SAMPLE_VOLUME
INFO,,SAMPLE_MOLECULAR_WEIGHT
INFO,,SAMPLE_SIZE
INFO,,SAMPLE_SHAPE
INFO,Straw,SAMPLE_HOLDER
INFO,Standard,SAMPLE_HOLDER_DETAIL
INFO,57.09,SAMPLE_OFFSET
DATATYPE,COMMENT,1
DATATYPE,TIME,2
STARTUPAXIS,X,2
STARTUPAXIS,Y1,5
FIELDGROUP, VSM,2,3,4,5,6,8,9,10,11,14,15
FIELDGROUP, DC, 2,3,4,14,56,57,58,59,60,61,62,63,64,65,66,67,68,69
FIELDGROUP, AC, 2,3,4,11,16,17,18,19,20,21,22,23,24,25,26,27,28,29,30
STARTUPGROUP, All
[Data]
Comment,Time Stamp (sec),Temperature (K),Magnetic Field (Oe),Moment (emu),M. Std. Err. (emu),Transport Action,Averaging Time (sec),Frequency (Hz),Peak Amplitude (mm),Center Position (mm),Lockin Signal' (V),Lockin Signal (V),Range,M. Quad. Signal (emu),AC Moment (emu),AC M. Std Err. (emu),AC Phase (deg),AC Phase Std. Err. (deg),AC Susceptibility (emu/Oe),AC Suscept. Std Err. (emu/Oe),AC X' (emu/Oe),AC X' Std Err. (emu/Oe),AC X'' (emu/Oe),AC X'' Std Err. (emu/Oe),AC Drive (Oe),AC Frequency (Hz),AC Averaging Time (sec),AC Cycles,AC Range,AC Measure Type,AC Signal' (V),AC Signal'' (V),AC Trim Coil Ratio,AC Trim Coil Phase,Min. Temperature (K),Max. Temperature (K),Min. Field (Oe),Max. Field (Oe),Mass (grams),Motor Lag (deg),Pressure (Torr),Measure Count,Measurement Number,SQUID Status (code),Motor Status (code),Measure Status (code),Motor Current (amps),Motor Temp. (C),Temp. Status (code),Field Status (code),Chamber Status (code),Chamber Temp (K),Redirection State,Average Temp (K),Rotation Angle (deg),Rotator state,DC Moment Fixed Ctr (emu),DC Moment Err Fixed Ctr (emu),DC Moment Free Ctr (emu),DC Moment Err Free Ctr (emu),DC Fixed Fit,DC Free Fit,DC Calculated Center (mm),DC Calculated Center Err (mm),DC Scan Length (mm),DC Scan Time (s),DC Number of Points,DC Squid Drift,DC Min V (V),DC Max V (V),DC Scans per Measure,Map 01,Map 02,Map 03,Map 04,Map 05,Map 06,Map 07,Map 08,Map 09,Map 10,Map 11,Map 12,Map 13,Map 14,Map 15,Map 16
,3832577937.99228,299.928070068359,9999.494140625,-7.83557961265995E-5,3.0905449813419E-8,1,2,13.4005146026611,4.99232799527007,30.1399994641542,-0.104195038278673,-0.0153850913448932,1,-6.01494774529985E-7,,,,,,,,,,,,,,,,,,,,,299.928070068359,299.928070068359,9999.494140625,9999.494140625,47.1540853081588,5.27092796226934,8.92325019836426,27,1,0,0,1,0.27587890625,40.5669593811035,1,1,1,299.928070068359,0,299.928070068359,,,,,,,,,,,,,,,,,,,,,,,,,,,,,,,,,
,3832577992.99673,298.019500732422,9999.494140625,-7.80024712041041E-5,2.88795034614047E-8,1,2,13.4005146026611,4.9923964475854,30.1399994641542,-0.103727354792788,-0.0153145191504409,1,-5.97667008723422E-7,,,,,,,,,,,,,,,,,,,,,297.962585449219,298.076416015625,9999.494140625,9999.494140625,47.1130498108992,5.2703886945162,8.89113521575928,27,1,0,0,1,0.274887084960938,40.5669593811035,2,1,1,297.962585449219,0,298.019500732422,,,,,,,,,,,,,,,,,,,,,,,,,,,,,,,,,
,3832578047.43343,295.222534179687,9999.494140625,-7.7819167597913E-5,3.23100045583828E-8,1,2,13.4005146026611,4.99225242137194,30.120000243187,-0.103482819483541,-0.0152542362085484,1,-5.78465975652805E-7,,,,,,,,,,,,,,,,,,,,,295.183990478516,295.261077880859,9999.494140625,9999.494140625,47.1263374957261,5.27075997953437,8.85245323181152,26,1,64,0,0,0.275497436523438,41.055721282959,2,1,1,295.183990478516,0,295.222534179687,,,,,,,,,,,,,,,,,,,,,,,,,,,,,,,,,
,3832578101.5953,292.540496826172,9999.494140625,-7.75902339268595E-5,2.81105501293814E-8,1,2,13.4005146026611,4.99232484570206,30.120000243187,-0.103177246706094,-0.0152324876237084,1,-5.93910417181623E-7,,,,,,,,,,,,,,,,,,,,,292.494262695313,292.586730957031,9999.494140625,9999.494140625,47.078658156053,5.27059571035696,8.83049488067627,27,1,0,0,1,0.275497436523438,41.055721282959,2,1,1,292.494262695313,0,292.540496826172,,,,,,,,,,,,,,,,,,,,,,,,,,,,,,,,,
,3832578155.963,289.764511108398,9999.494140625,-7.73434026974224E-5,3.755330833599E-8,1,2,13.4005146026611,4.99225459478918,30.0999991595745,-0.102843585474304,-0.0152084025460228,1,-6.10550296201919E-7,,,,,,,,,,,,,,,,,,,,,289.705780029297,289.8232421875,9999.494140625,9999.494140625,47.1368894807358,5.27091121917572,8.80592250823975,27,1,0,0,1,0.2764892578125,40.5669593811035,2,1,1,289.705780029297,0,289.764511108398,,,,,,,,,,,,,,,,,,,,,,,,,,,,,,,,,
,3832578208.35445,287.155838012695,9999.494140625,-7.71059899850761E-5,3.29947199155993E-8,1,2,13.4005146026611,4.99221871319336,30.0799999386072,-0.102529264205335,-0.015144572737326,1,-5.95907663888853E-7,,,,,,,,,,,,,,,,,,,,,287.103729248047,287.207946777344,9999.494140625,9999.494140625,47.1919942913415,5.27157059254277,8.79460048675537,27,1,0,0,1,0.278167724609375,40.5669593811035,2,1,1,287.103729248047,0,287.155838012695,,,,,,,,,,,,,,,,,,,,,,,,,,,,,,,,,
,3832578263.06868,284.374496459961,9999.494140625,-7.69573240395689E-5,3.34269981154169E-8,1,2,13.4005146026611,4.99218198877314,30.0600007176399,-0.102325026617712,-0.0151547139769318,1,-6.24427534750629E-7,,,,,,,,,,,,,,,,,,,,,284.340454101562,284.408538818359,9999.494140625,9999.494140625,47.0935090979185,5.27182725928559,8.76528644561768,27,1,0,0,1,0.276031494140625,41.055721282959,2,1,1,284.340454101562,0,284.374496459961,,,,,,,,,,,,,,,,,,,,,,,,,,,,,,,,,
,3832578318.46102,281.611083984375,9999.494140625,-7.65536289038367E-5,2.86178928601629E-8,1,2,13.4005146026611,4.9921269042285,30.0600007176399,-0.101793722342785,-0.0150249142884786,1,-5.83533664253876E-7,,,,,,,,,,,,,,,,,,,,,281.538024902344,281.684143066406,9999.494140625,9999.494140625,47.2025462763511,5.27158709246024,8.75075531005859,27,1,0,0,1,0.275497436523438,41.055721282959,2,1,1,281.538024902344,0,281.611083984375,,,,,,,,,,,,,,,,,,,,,,,,,,,,,,,,,
,3832578371.69509,278.940612792969,9999.494140625,-7.63743117781958E-5,2.80774146939527E-8,1,2,13.4005146026611,4.99201716440698,30.0399996340275,-0.101557156892702,-0.0149539883192674,1,-5.55661768049724E-7,,,,,,,,,,,,,,,,,,,,,278.895690917969,278.985534667969,9999.494140625,9999.494140625,47.0645888427069,5.27223230959302,8.73548221588135,27,1,0,0,1,0.277633666992187,40.5669593811035,2,1,1,278.895690917969,0,278.940612792969,,,,,,,,,,,,,,,,,,,,,,,,,,,,,,,,,
,3832578424.29793,276.323654174805,9999.494140625,-7.6182265793876E-5,3.4513938911709E-8,1,2,13.4005146026611,4.99192535446728,30.0200004130602,-0.101296758247209,-0.0149337187786961,1,-5.6756891368057E-7,,,,,,,,,,,,,,,,,,,,,276.294403076172,276.352905273438,9999.494140625,9999.494140625,47.1064059684858,5.27343979162146,8.70928001403809,25,1,64,0,0,0.276870727539062,40.5669593811035,2,1,1,276.294403076172,0,276.323654174805,,,,,,,,,,,,,,,,,,,,,,,,,,,,,,,,,
,3832578478.3569,273.64372253418,9999.494140625,-7.58592032298901E-5,2.37264645670903E-8,1,2,13.4005146026611,4.9921174444558,30.0200004130602,-0.100867242611138,-0.0149088708560193,1,-5.93481479771409E-7,,,,,,,,,,,,,,,,,,,,,273.598846435547,273.688598632813,9999.494140625,9999.494140625,47.1314180811011,5.27183996576507,8.69968605041504,27,1,0,0,1,0.276641845703125,40.5669593811035,2,1,1,273.598846435547,0,273.64372253418,,,,,,,,,,,,,,,,,,,,,,,,,,,,,,,,,
,3832578532.73828,270.910263061523,9999.494140625,-7.57443555908413E-5,4.86575527737493E-8,1,2,13.4005146026611,4.99213556265652,29.9999993294477,-0.100725833832017,-0.0148091392964434,1,-5.34561293416042E-7,,,,,,,,,,,,,,,,,,,,,270.860443115234,270.960083007813,9999.494140625,9999.494140625,47.09194584088,5.27177062717607,8.69119071960449,27,1,0,0,1,0.275650024414062,41.055721282959,2,1,1,270.860443115234,0,270.910263061523,,,,,,,,,,,,,,,,,,,,,,,,,,,,,,,,,
,3832578587.79034,268.171371459961,9999.494140625,-7.54655948542895E-5,2.64755144033328E-8,1,2,13.4005146026611,4.99197266070119,29.9900006502867,-0.100344325147533,-0.0147991846005396,1,-5.66556933169371E-7,,,,,,,,,,,,,,,,,,,,,268.155548095703,268.187194824219,9999.494140625,9999.494140625,47.1896494057838,5.27289123998721,8.66466617584228,26,1,64,0,0,0.274429321289062,41.055721282959,2,1,1,268.155548095703,0,268.171371459961,,,,,,,,,,,,,,,,,,,,,,,,,,,,,,,,,
,3832578640.81041,265.504440307617,9999.494140625,-7.53795645335221E-5,2.99473719488509E-8,1,2,13.4005146026611,4.99206670575583,29.9699995666742,-0.100231294856885,-0.0147914656387692,1,-5.72499847822662E-7,,,,,,,,,,,,,,,,,,,,,265.432525634766,265.576354980469,9999.494140625,9999.494140625,47.1482230942646,5.27243815581826,8.64909648895264,27,1,0,0,1,0.2752685546875,41.055721282959,2,1,1,265.432525634766,0,265.504440307617,,,,,,,,,,,,,,,,,,,,,,,,,,,,,,,,,
,3832578694.10111,262.873764038086,9999.494140625,-7.50461364050804E-5,3.97845919868538E-8,1,2,13.4005146026611,4.99193119157015,29.9699995666742,-0.0997823378879276,-0.0147390011034739,1,-5.80117932755929E-7,,,,,,,,,,,,,,,,,,,,,262.836578369141,262.910949707031,9999.494140625,9999.494140625,47.1236017959088,5.2729746714454,8.64192485809326,27,1,0,0,1,0.276947021484375,41.055721282959,2,1,1,262.836578369141,0,262.873764038086,,,,,,,,,,,,,,,,,,,,,,,,,,,,,,,,,
,3832578746.33949,260.227447509766,9999.494140625,-7.49708780414792E-5,3.37686955629571E-8,1,2,13.4005146026611,4.99204212911628,29.9500003457069,-0.0996882479657958,-0.0147036530471036,1,-5.63747755929677E-7,,,,,,,,,,,,,,,,,,,,,260.188201904297,260.266693115234,9999.494140625,9999.494140625,47.1353262236973,5.27253804047368,8.62896633148193,27,1,0,0,1,0.275802612304687,41.055721282959,2,1,1,260.188201904297,0,260.227447509766,,,,,,,,,,,,,,,,,,,,,,,,,,,,,,,,,
,3832578802.92881,257.418685913086,9999.494140625,-7.46787551341256E-5,2.59506101504213E-8,1,2,13.4005146026611,4.99207957890683,29.9500003457069,-0.0992939142011526,-0.0146960094225359,1,-5.98737001442981E-7,,,,,,,,,,,,,,,,,,,,,257.366149902344,257.471221923828,9999.494140625,9999.494140625,47.1955116196781,5.27147816660202,8.62748336791992,27,1,0,0,1,0.27618408203125,40.5669593811035,2,1,1,257.366149902344,0,257.418685913086,,,,,,,,,,,,,,,,,,,,,,,,,,,,,,,,,
,3832578859.31305,254.585945129395,9999.494140625,-7.45585521838603E-5,2.76744665802279E-8,1,2,13.4005146026611,4.99219619741025,29.9299992620945,-0.0991421525680112,-0.0146378655948672,1,-5.7151108862402E-7,,,,,,,,,,,,,,,,,,,,,254.553146362305,254.618743896484,9999.494140625,9999.494140625,47.1329813381396,5.27139074248214,8.62221336364746,25,1,64,0,0,0.27679443359375,41.055721282959,2,1,1,254.553146362305,0,254.585945129395,,,,,,,,,,,,,,,,,,,,,,,,,,,,,,,,,
,3832578911.6002,252.017097473145,9999.494140625,-7.43245743573125E-5,2.98041995353189E-8,1,2,13.4005146026611,4.99219472669301,29.9299992620945,-0.0988318674285362,-0.0145856280366192,1,-5.64988229881982E-7,,,,,,,,,,,,,,,,,,,,,251.980743408203,252.053451538086,9999.494140625,9999.494140625,47.1853504489281,5.27108864931943,8.59450531005859,25,1,64,0,0,0.276565551757813,40.5669593811035,2,1,1,251.980743408203,0,252.017097473145,,,,,,,,,,,,,,,,,,,,,,,,,,,,,,,,,
,3832578965.96125,249.259857177734,9999.494140625,-7.4218675237393E-5,3.09599872739691E-8,1,2,13.4005146026611,4.99237307750857,29.9100000411272,-0.0986994027116877,-0.0145403785372455,1,-5.45267604058317E-7,,,,,,,,,,,,,,,,,,,,,249.206481933594,249.313232421875,9999.494140625,9999.494140625,47.1517404226011,5.27135355047444,8.59004497528076,27,1,0,0,1,0.279388427734375,41.055721282959,2,1,1,249.206481933594,0,249.259857177734,,,,,,,,,,,,,,,,,,,,,,,,,,,,,,,,,
,3832579018.31506,246.64338684082,9999.494140625,-7.39558368747832E-5,2.67508475778438E-8,1,2,13.4005146026611,4.99246778226052,29.9100000411272,-0.0983481530190615,-0.0145198148908665,1,-5.66287272253336E-7,,,,,,,,,,,,,,,,,,,,,246.592208862305,246.694564819336,9999.494140625,9999.494140625,47.0622439571492,5.27104203380692,8.5918025970459,27,1,0,0,1,0.2764892578125,40.5669593811035,2,1,1,246.592208862305,0,246.64338684082,,,,,,,,,,,,,,,,,,,,,,,,,,,,,,,,,
,3832579074.71433,243.83088684082,9999.494140625,-7.38414064463176E-5,2.39564273752252E-8,1,2,13.4005146026611,4.99237007411497,29.8900008201599,-0.0981907342858042,-0.0145156468205881,1,-5.79448638943225E-7,,,,,,,,,,,,,,,,,,,,,243.785858154297,243.875915527344,9999.494140625,9999.494140625,47.1263374957261,5.27139691831939,8.5708589553833,27,1,0,0,1,0.274810791015625,40.5669593811035,2,1,1,243.785858154297,0,243.83088684082,,,,,,,,,,,,,,,,,,,,,,,,,,,,,,,,,
,3832579129.11296,241.087020874023,9999.494140625,-7.36819242314998E-5,2.89498351548117E-8,1,2,13.4005146026611,4.99242585997746,29.8800002783537,-0.0979845371299799,-0.0144532338678756,1,-5.54697158772488E-7,,,,,,,,,,,,,,,,,,,,,241.026702880859,241.147338867187,9999.494140625,9999.494140625,47.1048427114473,5.27112866902642,8.5604190826416,27,1,0,0,1,0.275115966796875,40.5669593811035,2,1,1,241.026702880859,0,241.087020874023,,,,,,,,,,,,,,,,,,,,,,,,,,,,,,,,,
,3832579183.83416,238.38809967041,9999.494140625,-7.36303467893865E-5,3.18061590367976E-8,1,2,13.4005146026611,4.99236784741419,29.8699997365475,-0.0979115006865113,-0.0144635404812775,1,-5.69823983623795E-7,,,,,,,,,,,,,,,,,,,,,238.367477416992,238.408721923828,9999.494140625,9999.494140625,47.1525220511204,5.27129863525242,8.56495952606201,27,1,0,0,1,0.2740478515625,41.055721282959,2,1,1,238.359024047852,0,238.38809967041,,,,,,,,,,,,,,,,,,,,,,,,,,,,,,,,,
,3832579241.94468,235.450500488281,9999.494140625,-7.33327138811165E-5,2.5526982796071E-8,1,2,13.4005146026611,4.99252427635101,29.8599991947412,-0.0975191315022866,-0.0144112219463651,1,-5.71673241985573E-7,,,,,,,,,,,,,,,,,,,,,235.394958496094,235.506042480469,9999.494140625,9999.494140625,47.117348767755,5.27050444812826,8.55829620361328,27,1,0,0,1,0.2764892578125,40.5669593811035,2,1,1,235.394958496094,0,235.450500488281,,,,,,,,,,,,,,,,,,,,,,,,,,,,,,,,,
,3832579294.31919,232.870788574219,9999.494140625,-7.33126665787097E-5,2.82885034138489E-8,1,2,13.4005146026611,4.99216192963965,29.839999973774,-0.0974892146202533,-0.014359795708534,1,-5.36919765609106E-7,,,,,,,,,,,,,,,,,,,,,232.813186645508,232.92839050293,9999.494140625,9999.494140625,47.1521312368608,5.271059486196,8.55192756652832,27,1,0,0,1,0.275955200195313,41.055721282959,2,1,1,232.813186645508,0,232.870788574219,,,,,,,,,,,,,,,,,,,,,,,,,,,,,,,,,
,3832579349.10856,230.14281463623,9999.494140625,-7.30034482592136E-5,4.14295253693508E-8,1,2,13.4005146026611,4.99215269449238,29.839999973774,-0.097072482765364,-0.0143370660248418,1,-5.63107109601056E-7,,,,,,,,,,,,,,,,,,,,,230.118743896484,230.166885375977,9999.494140625,9999.494140625,47.1126589966396,5.27104247199383,8.53755855560303,26,1,64,0,0,0.27618408203125,40.5669593811035,2,1,1,230.118743896484,0,230.14281463623,,,,,,,,,,,,,,,,,,,,,,,,,,,,,,,,,
,3832579401.46835,227.488586425781,9999.494140625,-7.29600502773108E-5,3.22751698948289E-8,1,2,13.4005146026611,4.992101638478,29.8200007528067,-0.0970091338449641,-0.0143589737539598,1,-5.85784246370691E-7,,,,,,,,,,,,,,,,,,,,,227.434051513672,227.543121337891,9999.494140625,9999.494140625,47.2326389743415,5.27183952957315,8.53426647186279,26,1,64,0,0,0.2777099609375,41.055721282959,2,1,1,227.434051513672,0,227.488586425781,,,,,,,,,,,,,,,,,,,,,,,,,,,,,,,,,
,3832579455.66965,224.779418945313,9999.494140625,-7.2716054187112E-5,3.7393239018623E-8,1,2,13.4005146026611,4.99222878075767,29.8200007528067,-0.096691264457819,-0.0142887251438201,1,-5.66751237102451E-7,,,,,,,,,,,,,,,,,,,,,224.714920043945,224.84391784668,9999.494140625,9999.494140625,47.1435333231492,5.27169114623158,8.533371925354,27,1,0,0,1,0.2777099609375,41.055721282959,2,1,1,224.714920043945,0,224.779418945313,,,,,,,,,,,,,,,,,,,,,,,,,,,,,,,,,
,3832579507.92505,222.172424316406,9999.494140625,-7.26754796389845E-5,3.04323634950676E-8,1,2,13.4005146026611,4.99247209477657,29.7999996691942,-0.0966472685880507,-0.0142566622419456,1,-5.47622697599359E-7,,,,,,,,,,,,,,,,,,,,,222.111755371094,222.233093261719,9999.494140625,9999.494140625,47.1236017959088,5.27086366849685,8.51159381866455,27,1,0,0,1,0.274887084960938,40.5669593811035,2,1,1,222.111755371094,0,222.172424316406,,,,,,,,,,,,,,,,,,,,,,,,,,,,,,,,,
,3832579562.33927,219.472457885742,9999.494140625,-7.25121342973444E-5,2.71011163505512E-8,1,2,13.4005146026611,4.99248908879232,29.789999127388,-0.0964293991268927,-0.0142325165775137,1,-5.52274458291849E-7,,,,,,,,,,,,,,,,,,,,,219.417114257813,219.527801513672,9999.494140625,9999.494140625,47.1282915670242,5.27047575302004,8.52380752563477,27,1,0,0,1,0.27374267578125,40.5669593811035,2,1,1,219.417114257813,0,219.472457885742,,,,,,,,,,,,,,,,,,,,,,,,,,,,,,,,,
,3832579616.68357,216.739028930664,9999.494140625,-7.23966583945658E-5,2.77697864227155E-8,1,2,13.4005146026611,4.99243755077522,29.7800004482269,-0.0962793232595667,-0.0141749602711786,1,-5.25336538636766E-7,,,,,,,,,,,,,,,,,,,,,216.700256347656,216.777801513672,9999.494140625,9999.494140625,47.2162247754377,5.27049802824782,8.50998783111572,27,1,0,0,1,0.274505615234375,41.055721282959,2,1,1,216.700256347656,0,216.739028930664,,,,,,,,,,,,,,,,,,,,,,,,,,,,,,,,,
,3832579671.38733,214.019889831543,9999.494140625,-7.2229368954368E-5,3.46289484694705E-8,1,2,13.4005146026611,4.99257601725825,29.7699999064207,-0.0960578336944504,-0.014161800795757,1,-5.38437759343511E-7,,,,,,,,,,,,,,,,,,,,,213.99235534668,214.047424316406,9999.494140625,9999.494140625,47.1959024339377,5.27062655907376,8.49848651885986,27,1,0,0,1,0.27679443359375,40.5669593811035,2,1,1,213.99235534668,0,214.019889831543,,,,,,,,,,,,,,,,,,,,,,,,,,,,,,,,,
,3832579726.79514,211.244255065918,9999.494140625,-7.22201829482167E-5,3.39966726687193E-8,1,2,13.4005146026611,4.99255269892612,29.7599993646145,-0.0960426277059852,-0.0141768933576232,1,-5.51127138887678E-7,,,,,,,,,,,,,,,,,,,,,211.15266418457,211.335845947266,9999.494140625,9999.494140625,47.0946815406973,5.269989377366,8.48995685577393,27,1,0,0,1,0.274200439453125,41.055721282959,2,1,1,211.15266418457,0,211.244255065918,,,,,,,,,,,,,,,,,,,,,,,,,,,,,,,,,
,3832579782.23927,208.500205993652,9999.494140625,-7.19841677629345E-5,2.97242280907228E-8,1,2,13.4005146026611,4.99260223285308,29.7500006854534,-0.0957317569749864,-0.0141186364601276,1,-5.40222898920675E-7,,,,,,,,,,,,,,,,,,,,,208.467330932617,208.533081054687,9999.494140625,9999.494140625,47.0559909289954,5.27025396381899,8.48018264770508,27,1,0,0,1,0.278472900390625,40.5669593811035,2,1,1,208.467330932617,0,208.500205993652,,,,,,,,,,,,,,,,,,,,,,,,,,,,,,,,,
,3832579836.61333,205.756629943848,9999.494140625,-7.19688192940407E-5,4.47575028639146E-8,1,2,13.4005146026611,4.99260758354377,29.729999601841,-0.0957114413198847,-0.014115963600383,1,-5.40345664670556E-7,,,,,,,,,,,,,,,,,,,,,205.728256225586,205.785003662109,9999.494140625,9999.494140625,47.0638072141877,5.26966852735734,8.46329307556152,27,1,0,0,1,0.274734497070313,40.5669593811035,2,1,1,205.728256225586,0,205.756629943848,,,,,,,,,,,,,,,,,,,,,,,,,,,,,,,,,
,3832579890.9237,203.113502502441,9999.494140625,-7.16870515900804E-5,3.25489559671617E-8,1,2,13.4005146026611,4.99245936731625,29.729999601841,-0.0953335038015439,-0.0140553739375513,1,-5.34660763566073E-7,,,,,,,,,,,,,,,,,,,,,203.081008911133,203.14599609375,9999.494140625,9999.494140625,47.1013253831108,5.27118661719073,8.457106590271,27,1,0,0,1,0.275802612304687,41.055721282959,2,1,1,203.081008911133,0,203.113502502441,,,,,,,,,,,,,,,,,,,,,,,,,,,,,,,,,
,3832579945.30891,200.369995117187,9999.494140625,-7.1769059200036E-5,4.14391667229855E-8,1,2,13.4005146026611,4.9924795397884,29.7100003808737,-0.0954435279689841,-0.0140684031580167,1,-5.32923046319996E-7,,,,,,,,,,,,,,,,,,,,,200.333511352539,200.406478881836,9999.494140625,9999.494140625,47.1407976233319,5.27077713003796,8.45887851715088,26,1,64,0,0,0.27587890625,40.5669593811035,2,1,1,200.333511352539,0,200.369995117187,,,,,,,,,,,,,,,,,,,,,,,,,,,,,,,,,
,3832579997.60201,197.737342834473,9999.494140625,-7.15742316757039E-5,3.11801545569015E-8,1,2,13.4005146026611,4.99252394411418,29.7100003808737,-0.0951797432969558,-0.0140722192653784,1,-5.62901877718094E-7,,,,,,,,,,,,,,,,,,,,,197.699935913086,197.774749755859,9999.494140625,9999.494140625,47.1239926101684,5.26998649929241,8.45032787322998,25,1,64,0,0,0.277786254882813,41.055721282959,2,1,1,197.699935913086,0,197.737342834473,,,,,,,,,,,,,,,,,,,,,,,,,,,,,,,,,
,3832580054.10455,194.90592956543,9999.494140625,-7.15348652635086E-5,3.03588939562726E-8,1,2,13.4005146026611,4.99252795356476,29.6899992972612,-0.0951193094308366,-0.0141230618012511,1,-6.06585526305701E-7,,,,,,,,,,,,,,,,,,,,,194.857849121094,194.954010009766,9999.494140625,9999.494140625,47.0415308013896,5.27066404823067,8.44327831268311,27,1,0,0,1,0.286407470703125,40.5669593811035,2,1,1,194.857849121094,0,194.90592956543,,,,,,,,,,,,,,,,,,,,,,,,,,,,,,,,,
,3832580110.38532,192.101982116699,9999.494140625,-7.14392791397843E-5,3.76455883155952E-8,1,2,13.4005146026611,4.99252424966704,29.6899992972612,-0.0949929150674946,-0.0140984381019044,1,-6.01464911705045E-7,,,,,,,,,,,,,,,,,,,,,192.05940246582,192.144561767578,9999.494140625,9999.494140625,47.1345445951781,5.2702032506348,8.43202686309814,27,1,0,0,1,0.274887084960938,40.5669593811035,2,1,1,192.03630065918,0,192.101982116699,,,,,,,,,,,,,,,,,,,,,,,,,,,,,,,,,
,3832580164.93799,189.354820251465,9999.494140625,-7.1234728003711E-5,3.273048619691E-8,1,2,13.4005146026611,4.99254999470041,29.6700000762939,-0.0947252903023076,-0.0140317229931837,1,-5.79877184700186E-7,,,,,,,,,,,,,,,,,,,,,189.284027099609,189.42561340332,9999.494140625,9999.494140625,47.0200360171107,5.26977207511108,8.43343544006348,27,1,0,0,1,0.274276733398438,41.055721282959,2,1,1,189.284027099609,0,189.354820251465,,,,,,,,,,,,,,,,,,,,,,,,,,,,,,,,,
,3832580221.2303,186.546920776367,9999.494140625,-7.11755943640476E-5,2.8634063606368E-8,1,2,13.4005146026611,4.99255866757439,29.6500008553266,-0.0946461370510479,-0.0140254354836984,1,-5.83397359045265E-7,,,,,,,,,,,,,,,,,,,,,186.511779785156,186.582061767578,9999.494140625,9999.494140625,47.1107049253415,5.27055322024235,8.42684173583984,27,1,0,0,1,0.276870727539062,40.5669593811035,2,1,1,186.511779785156,0,186.546920776367,,,,,,,,,,,,,,,,,,,,,,,,,,,,,,,,,
,3832580273.55667,183.97745513916,9999.494140625,-7.09240304457099E-5,4.05999358751381E-8,1,2,13.4005146026611,4.99256305387023,29.6500008553266,-0.0943162093472356,-0.0139438595279724,1,-5.57282571696279E-7,,,,,,,,,,,,,,,,,,,,,183.935485839844,184.019424438477,9999.494140625,9999.494140625,47.0735775706781,5.27026487016499,8.405442237854,27,1,0,0,1,0.276641845703125,40.5669593811035,2,1,1,183.906692504883,0,183.97745513916,,,,,,,,,,,,,,,,,,,,,,,,,,,,,,,,,
,3832580327.91233,181.233001708984,9999.494140625,-7.08872539184036E-5,2.52381297514639E-8,1,2,13.4005146026611,4.99252609322292,29.6299997717142,-0.0942695306002828,-0.0139137173917291,1,-5.39889340250481E-7,,,,,,,,,,,,,,,,,,,,,181.194351196289,181.27165222168,9999.494140625,9999.494140625,47.0806122273511,5.27037303540949,8.40323734283447,27,1,0,0,1,0.27801513671875,40.5669593811035,2,1,1,181.194351196289,0,181.233001708984,,,,,,,,,,,,,,,,,,,,,,,,,,,,,,,,,
,3832580382.32288,178.513549804687,9999.494140625,-7.0684897426195E-5,2.76225755045304E-8,1,2,13.4005146026611,4.99255198491408,29.6299997717142,-0.093997869923503,-0.0138971600140605,1,-5.55671696167218E-7,,,,,,,,,,,,,,,,,,,,,178.452926635742,178.574172973633,9999.494140625,9999.494140625,47.1505679798223,5.27013885606346,8.38805198669434,27,1,0,0,1,0.274581909179687,41.055721282959,2,1,1,178.452926635742,0,178.513549804687,,,,,,,,,,,,,,,,,,,,,,,,,,,,,,,,,
,3832580436.72951,175.800979614258,9999.494140625,-7.06952953686471E-5,2.61530355012024E-8,1,2,13.4005146026611,4.99249994344192,29.6100005507469,-0.0940098710034657,-0.0139024624383684,1,-5.5834997214018E-7,,,,,,,,,,,,,,,,,,,,,175.747131347656,175.854827880859,9999.494140625,9999.494140625,47.1024978258896,5.27021764682192,8.37697982788086,27,1,0,0,1,0.276641845703125,40.5669593811035,2,1,1,175.747131347656,0,175.800979614258,,,,,,,,,,,,,,,,,,,,,,,,,,,,,,,,,
,3832580493.15026,172.97452545166,9999.494140625,-7.04154770945081E-5,2.72746696610831E-8,1,2,13.4005146026611,4.99249441680401,29.6100005507469,-0.0936318786914165,-0.0138885439052844,1,-5.87035311611053E-7,,,,,,,,,,,,,,,,,,,,,172.919799804687,173.029251098633,9999.494140625,9999.494140625,47.1247742386877,5.27030455748568,8.36745262145996,27,1,0,0,1,0.272674560546875,40.5669593811035,2,1,1,172.919799804687,0,172.97452545166,,,,,,,,,,,,,,,,,,,,,,,,,,,,,,,,,
,3832580547.56139,170.274955749512,9999.494140625,-7.03892609412489E-5,3.56904977940109E-8,1,2,13.4005146026611,4.99254200993331,29.6000000089407,-0.0935993287359233,-0.0138757798709979,1,-5.80976781948535E-7,,,,,,,,,,,,,,,,,,,,,170.222274780273,170.32763671875,9999.494140625,9999.494140625,47.0567725575146,5.27032767724609,8.34717273712158,27,1,0,0,1,0.273666381835938,40.5669593811035,2,1,1,170.222274780273,0,170.274955749512,,,,,,,,,,,,,,,,,,,,,,,,,,,,,,,,,
,3832580603.96851,167.476211547852,9999.494140625,-7.01152227096407E-5,2.77795696413661E-8,1,2,13.4005146026611,4.9925269535121,29.5899994671345,-0.0932374597976679,-0.0138008491986724,1,-5.63051234135417E-7,,,,,,,,,,,,,,,,,,,,,167.433898925781,167.518524169922,9999.494140625,9999.494140625,47.1677638072454,5.2701821842796,8.34012413024902,27,1,0,0,1,0.27374267578125,40.5669593811035,2,1,1,167.433898925781,0,167.476211547852,,,,,,,,,,,,,,,,,,,,,,,,,,,,,,,,,
,3832580660.48959,164.634757995605,9999.494140625,-7.01681920210946E-5,3.18316496691668E-8,1,2,13.4005146026611,4.99253716542142,29.5700002461672,-0.0932958570054656,-0.0138992945321471,1,-6.2956416397719E-7,,,,,,,,,,,,,,,,,,,,,164.587646484375,164.681869506836,9999.494140625,9999.494140625,47.0673245425242,5.27008241473948,8.33061027526855,27,1,0,0,1,0.276107788085938,40.5669593811035,2,1,1,164.587646484375,0,164.634757995605,,,,,,,,,,,,,,,,,,,,,,,,,,,,,,,,,
,3832580714.79065,161.923324584961,9999.494140625,-6.9838797590276E-5,2.53060292041192E-8,1,2,13.4005146026611,4.99266448529646,29.5700002461672,-0.0928719078936276,-0.0137575060023343,1,-5.68753568924377E-7,,,,,,,,,,,,,,,,,,,,,161.883651733398,161.962997436523,9999.494140625,9999.494140625,47.1533036796396,5.26936031852213,8.32483291625977,27,1,0,0,1,0.286026000976562,41.055721282959,2,1,1,161.883651733398,0,161.923324584961,,,,,,,,,,,,,,,,,,,,,,,,,,,,,,,,,
,3832580769.15303,159.170745849609,9999.494140625,-6.95408407714112E-5,2.61430873439514E-8,1,2,13.4005146026611,4.99253589106521,29.5700002461672,-0.0924778502719629,-0.013659488626486,1,-5.37152352691788E-7,,,,,,,,,,,,,,,,,,,,,159.130569458008,159.210922241211,9999.494140625,9999.494140625,47.1482230942646,5.27051962981765,8.31923007965088,27,1,0,0,1,0.27435302734375,41.055721282959,2,1,1,159.130569458008,0,159.170745849609,,,,,,,,,,,,,,,,,,,,,,,,,,,,,,,,,
,3832580821.53986,156.569122314453,9999.494140625,-6.95307439169895E-5,2.68874793189171E-8,1,2,13.4005146026611,4.99253865957973,29.5499991625547,-0.0924599100923618,-0.0136902953062317,1,-5.61697067315242E-7,,,,,,,,,,,,,,,,,,,,,156.530044555664,156.608200073242,9999.494140625,9999.494140625,47.11226818238,5.27002999923563,8.3024730682373,27,1,0,0,1,0.276031494140625,40.5669593811035,2,1,1,156.530044555664,0,156.569122314453,,,,,,,,,,,,,,,,,,,,,,,,,,,,,,,,,
,3832580876.24757,153.868522644043,9999.494140625,-6.92237637492311E-5,2.93454744916901E-8,1,2,13.4005146026611,4.9927310676328,29.5400004833937,-0.0920593858040797,-0.0136103522585766,1,-5.4402960748869E-7,,,,,,,,,,,,,,,,,,,,,153.839660644531,153.897384643555,9999.494140625,9999.494140625,47.1228201673896,5.27097142141747,8.30112743377686,27,1,0,0,1,0.284805297851562,41.055721282959,2,1,1,153.839660644531,0,153.868522644043,,,,,,,,,,,,,,,,,,,,,,,,,,,,,,,,,
,3832580930.58574,151.119110107422,9999.494140625,-6.90741892888177E-5,2.96978136183855E-8,1,2,13.4005146026611,4.99277643443247,29.5299999415874,-0.0918620634448831,-0.0135778940358557,1,-5.40436336805575E-7,,,,,,,,,,,,,,,,,,,,,151.090225219727,151.147994995117,9999.494140625,9999.494140625,47.0794397845723,5.26982398994153,8.28599166870117,27,1,0,0,1,0.2862548828125,41.055721282959,2,1,1,151.090225219727,0,151.119110107422,,,,,,,,,,,,,,,,,,,,,,,,,,,,,,,,,
,3832580984.92156,148.412780761719,9999.494140625,-6.90128366649472E-5,3.8458440176008E-8,1,2,13.4005146026611,4.99275758892842,29.5100007206202,-0.0917789592304439,-0.0135731758167527,1,-5.45523592549627E-7,,,,,,,,,,,,,,,,,,,,,148.38395690918,148.441604614258,9999.494140625,9999.494140625,47.0419216156492,5.26950494598424,8.27804851531982,25,1,64,0,0,0.276718139648438,41.055721282959,2,1,1,148.38395690918,0,148.412780761719,,,,,,,,,,,,,,,,,,,,,,,,,,,,,,,,,
,3832581039.39988,145.74243927002,9999.494140625,-6.89216367389645E-5,3.44640994880377E-8,1,2,13.4005146026611,4.99256423572051,29.5100007206202,-0.091655925876164,-0.013532233349209,1,-5.28062264576489E-7,,,,,,,,,,,,,,,,,,,,,145.68440246582,145.800476074219,9999.494140625,9999.494140625,47.0853019984665,5.27005444578443,8.27248477935791,27,1,0,0,1,0.28717041015625,41.055721282959,2,1,1,145.68440246582,0,145.74243927002,,,,,,,,,,,,,,,,,,,,,,,,,,,,,,,,,
,3832581089.52775,143.196792602539,9999.494140625,-6.85997783975373E-5,3.68039157077662E-8,1,2,13.4005146026611,4.99264201134096,29.4899996370077,-0.0912169907640165,-0.0135612799900189,1,-5.94666115093767E-7,,,,,,,,,,,,,,,,,,,,,143.134521484375,143.259063720703,9999.494140625,9999.494140625,47.0888193268031,5.2703176417991,8.26991939544678,25,1,32,0,0,0.276565551757813,41.055721282959,2,1,1,143.134521484375,0,143.196792602539,,,,,,,,,,,,,,,,,,,,,,,,,,,,,,,,,
,3832581145.9215,140.382026672363,9999.494140625,-6.82302003294819E-5,3.130265090224E-8,1,2,13.4005146026611,4.99279224442986,29.4899996370077,-0.0907374016941163,-0.0134308658676655,1,-5.47966045498508E-7,,,,,,,,,,,,,,,,,,,,,140.328521728516,140.435531616211,9999.494140625,9999.494140625,47.1177395820146,5.26976535408269,8.25132083892822,27,1,0,0,1,0.275344848632813,41.055721282959,2,1,1,140.328521728516,0,140.382026672363,,,,,,,,,,,,,,,,,,,,,,,,,,,,,,,,,
,3832581198.97021,137.752647399902,9999.494140625,-6.81282162628586E-5,3.7219296275481E-8,1,2,13.4005146026611,4.99280757520619,29.4799990952015,-0.0906083911200358,-0.0133662624595828,1,-5.136592565604E-7,,,,,,,,,,,,,,,,,,,,,137.74723815918,137.758056640625,9999.494140625,9999.494140625,47.015737060255,5.27292298517908,8.23718547821045,26,1,64,0,0,0.274734497070313,41.055721282959,2,1,1,137.74723815918,0,137.752647399902,,,,,,,,,,,,,,,,,,,,,,,,,,,,,,,,,
,3832581250.9911,135.138214111328,9999.494140625,-6.7993381958573E-5,2.66348153701975E-8,1,2,13.4005146026611,4.99282125380118,29.4700004160404,-0.0904260486116034,-0.0133638653750112,1,-5.30673875038226E-7,,,,,,,,,,,,,,,,,,,,,135.072814941406,135.20361328125,9999.494140625,9999.494140625,47.0266798595242,5.26979990488573,8.23314476013184,27,1,0,0,1,0.275421142578125,40.5669593811035,2,1,1,135.072814941406,0,135.138214111328,,,,,,,,,,,,,,,,,,,,,,,,,,,,,,,,,
,3832581307.23246,132.341415405273,9999.494140625,-6.77344030141165E-5,2.93533603218853E-8,1,2,13.4005146026611,4.99279159332429,29.4700004160404,-0.0900827727348748,-0.0132994110622937,1,-5.18554315898612E-7,,,,,,,,,,,,,,,,,,,,,132.304504394531,132.378326416016,9999.494140625,9999.494140625,47.078658156053,5.26992265838495,8.21498489379883,27,1,0,0,1,0.276336669921875,41.055721282959,2,1,1,132.304504394531,0,132.341415405273,,,,,,,,,,,,,,,,,,,,,,,,,,,,,,,,,
,3832581359.61404,129.74853515625,9999.494140625,-6.77297930850297E-5,3.20173373117629E-8,1,2,13.4005146026611,4.99286463647409,29.449999332428,-0.0900755437745089,-0.0133195408624346,1,-5.34117976980391E-7,,,,,,,,,,,,,,,,,,,,,129.693252563477,129.803817749023,9999.494140625,9999.494140625,46.9489078218607,5.26983538384405,8.22014236450195,26,1,64,0,0,0.27862548828125,41.055721282959,2,1,1,129.693252563477,0,129.74853515625,,,,,,,,,,,,,,,,,,,,,,,,,,,,,,,,,
,3832581415.9817,126.878067016602,9999.494140625,-6.73692516172696E-5,3.05505522598043E-8,1,2,13.4005146026611,4.99292098668863,29.449999332428,-0.0895933471006853,-0.0132780888539175,1,-5.53240951891251E-7,,,,,,,,,,,,,,,,,,,,,126.818389892578,126.937744140625,9999.494140625,9999.494140625,46.9743107487357,5.26951815616767,8.19175052642822,27,1,0,0,1,0.27252197265625,41.055721282959,2,1,1,126.818389892578,0,126.878067016602,,,,,,,,,,,,,,,,,,,,,,,,,,,,,,,,,
,3832581468.31442,124.285808563232,9999.494140625,-6.74052524827362E-5,2.48518515132117E-8,1,2,13.4005146026611,4.99289911440885,29.4300001114607,-0.0896449708616991,-0.0132544594645547,1,-5.30519414665915E-7,,,,,,,,,,,,,,,,,,,,,124.230087280273,124.341529846191,9999.494140625,9999.494140625,47.0806122273511,5.27019282421561,8.17662525177002,27,1,0,0,1,0.2764892578125,41.055721282959,2,1,1,124.230087280273,0,124.285808563232,,,,,,,,,,,,,,,,,,,,,,,,,,,,,,,,,
,3832581522.0211,121.624938964844,9999.494140625,-6.71639929960562E-5,3.90502722294377E-8,1,2,13.4005146026611,4.99290974598893,29.4300001114607,-0.0893258464864291,-0.0131965027339805,1,-5.20693326123233E-7,,,,,,,,,,,,,,,,,,,,,121.54704284668,121.702835083008,9999.494140625,9999.494140625,47.012610546178,5.26984739729399,8.16746234893799,27,1,0,0,1,0.287399291992187,41.055721282959,2,1,1,121.54704284668,0,121.624938964844,,,,,,,,,,,,,,,,,,,,,,,,,,,,,,,,,
,3832581577.08842,118.840686798096,9999.494140625,-6.6922075619058E-5,3.12107660338216E-8,1,2,13.4005146026611,4.99286229161982,29.4199995696545,-0.0890002552332264,-0.0131680386197747,1,-5.3326851083794E-7,,,,,,,,,,,,,,,,,,,,,118.786026000977,118.895347595215,9999.494140625,9999.494140625,47.0653704712261,5.27013941439975,8.13919544219971,27,1,0,0,1,0.275192260742187,41.055721282959,2,1,1,118.786026000977,0,118.840686798096,,,,,,,,,,,,,,,,,,,,,,,,,,,,,,,,,
,3832581632.06958,116.110397338867,9999.494140625,-6.67757604575023E-5,3.09353924128564E-8,1,2,13.4005146026611,4.99293015033602,29.4100008904934,-0.0888161339002189,-0.0130764807533861,1,-4.84775111185638E-7,,,,,,,,,,,,,,,,,,,,,116.095054626465,116.12574005127,9999.494140625,9999.494140625,47.0173003172934,5.27155161234561,8.12980079650879,26,1,64,0,0,0.275115966796875,40.5669593811035,2,1,1,116.095054626465,0,116.110397338867,,,,,,,,,,,,,,,,,,,,,,,,,,,,,,,,,
,3832581686.14963,113.390277862549,9999.494140625,-6.65324081656633E-5,3.60837885911775E-8,1,2,13.4005146026611,4.99283232271461,29.4100008904934,-0.0884813736229649,-0.0130907685815037,1,-5.29796335348256E-7,,,,,,,,,,,,,,,,,,,,,113.356544494629,113.424011230469,9999.494140625,9999.494140625,47.0133921746973,5.27058121869048,8.11704158782959,27,1,0,0,1,0.275039672851562,41.055721282959,2,1,1,113.356544494629,0,113.390277862549,,,,,,,,,,,,,,,,,,,,,,,,,,,,,,,,,
,3832581740.47488,110.673603057861,9999.494140625,-6.65223010181316E-5,3.36128329627233E-8,1,2,13.4005146026611,4.99277692734022,29.389999806881,-0.0884694411632752,-0.0130681685856735,1,-5.1438392128947E-7,,,,,,,,,,,,,,,,,,,,,110.63304901123,110.714157104492,9999.494140625,9999.494140625,47.1591658935338,5.27107673762731,8.0913610458374,25,1,64,0,0,0.274429321289062,41.055721282959,2,1,1,110.63304901123,0,110.673603057861,,,,,,,,,,,,,,,,,,,,,,,,,,,,,,,,,
,3832581794.93313,107.985847473145,9999.494140625,-6.6342685743405E-5,2.79500258142798E-8,1,2,13.4005146026611,4.99272896655197,29.389999806881,-0.0882289648173474,-0.0130358637102245,1,-5.15362380053334E-7,,,,,,,,,,,,,,,,,,,,,107.922073364258,108.049621582031,9999.494140625,9999.494140625,47.0446573154665,5.27118659059151,8.07703495025635,27,1,0,0,1,0.277023315429687,41.055721282959,2,1,1,107.922073364258,0,107.985847473145,,,,,,,,,,,,,,,,,,,,,,,,,,,,,,,,,
,3832581847.09135,105.366580963135,9999.494140625,-6.60256902973462E-5,2.9405653468003E-8,1,2,13.4005146026611,4.9927299380967,29.389999806881,-0.0878101669385106,-0.0129539110430319,1,-4.9812626575899E-7,,,,,,,,,,,,,,,,,,,,,105.309951782227,105.423210144043,9999.494140625,9999.494140625,47.0712326851204,5.27118830963142,8.05238723754883,27,1,0,0,1,0.276412963867187,41.055721282959,2,1,1,105.309951782227,0,105.366580963135,,,,,,,,,,,,,,,,,,,,,,,,,,,,,,,,,
,3832581899.45583,102.766757965088,9999.494140625,-6.61026402012721E-5,3.91755088784055E-8,1,2,13.4005146026611,4.99277540127545,29.3700005859137,-0.0879030456814323,-0.0130446731378554,1,-5.55418030697781E-7,,,,,,,,,,,,,,,,,,,,,102.718078613281,102.815437316895,9999.494140625,9999.494140625,47.1103141110819,5.27136342189044,8.04359722137451,27,1,0,0,1,0.27496337890625,41.055721282959,2,1,1,102.718078613281,0,102.766757965088,,,,,,,,,,,,,,,,,,,,,,,,,,,,,,,,,
,3832581955.2089,99.9388961791992,9999.494140625,-6.58618645018797E-5,2.87714922028356E-8,1,2,13.4005146026611,4.99277335820846,29.3700005859137,-0.0875897670100888,-0.0129474231203473,1,-5.16043558446652E-7,,,,,,,,,,,,,,,,,,,,,99.8490142822266,100.028778076172,9999.494140625,9999.494140625,47.0184727600723,5.27045405262513,8.03106784820557,26,1,68,0,0,0.275115966796875,40.5669593811035,2,1,1,99.8490142822266,0,99.9388961791992,,,,,,,,,,,,,,,,,,,,,,,,,,,,,,,,,
,3832582010.2639,97.2267341613769,9999.494140625,-6.57919737799037E-5,2.9648129818611E-8,1,2,13.4005146026611,4.99280799800652,29.3499995023012,-0.0875014629972563,-0.0129065443634644,1,-4.95019114100794E-7,,,,,,,,,,,,,,,,,,,,,97.1844177246094,97.2690505981445,9999.494140625,9999.494140625,47.053255229178,5.27083158802087,7.99610710144043,27,1,0,0,1,0.28594970703125,41.055721282959,2,1,1,97.1844177246094,0,97.2267341613769,,,,,,,,,,,,,,,,,,,,,,,,,,,,,,,,,
,3832582066.67632,94.4011383056641,9999.494140625,-6.54967664641104E-5,2.99943653265708E-8,1,2,13.4005146026611,4.99285165569932,29.3499995023012,-0.0871039791828232,-0.0128910565786321,1,-5.24546541571558E-7,,,,,,,,,,,,,,,,,,,,,94.3470458984375,94.4552307128906,9999.494140625,9999.494140625,47.0657612854857,5.27084169511402,7.97593927383423,27,1,0,0,1,0.277481079101562,41.055721282959,2,1,1,94.3470458984375,0,94.4011383056641,,,,,,,,,,,,,,,,,,,,,,,,,,,,,,,,,
,3832582121.08853,91.693733215332,9999.494140625,-6.52094706855834E-5,2.44926790737045E-8,1,2,13.4005146026611,4.9928395697523,29.3499995023012,-0.0867231368083259,-0.012823603262615,1,-5.1408478602692E-7,,,,,,,,,,,,,,,,,,,,,91.6331787109375,91.7542877197266,9999.494140625,9999.494140625,47.0466113867646,5.27064876271099,7.96295118331909,27,1,0,0,1,0.276336669921875,41.055721282959,2,1,1,91.6331787109375,0,91.693733215332,,,,,,,,,,,,,,,,,,,,,,,,,,,,,,,,,
,3832582175.48535,88.9519996643066,9999.494140625,-6.52565183018078E-5,2.38847124629892E-8,1,2,13.4005146026611,4.99293734824081,29.3300002813339,-0.086784373646331,-0.0128593870235731,1,-5.34124429510724E-7,,,,,,,,,,,,,,,,,,,,,88.9167404174805,88.9872589111328,9999.494140625,9999.494140625,47.0978080547742,5.27036219762798,7.94517278671265,27,1,0,0,1,0.276260375976562,41.055721282959,2,1,1,88.9167404174805,0,88.9519996643066,,,,,,,,,,,,,,,,,,,,,,,,,,,,,,,,,
,3832582238.11455,85.8474731445313,9999.494140625,-6.45870281236777E-5,2.42039393928199E-8,1,2,13.4005146026611,4.99302409863947,29.3300002813339,-0.0858985586037009,-0.0127099371775253,1,-5.15257926001307E-7,,,,,,,,,,,,,,,,,,,,,85.8104095458984,85.8845367431641,9999.494140625,9999.494140625,47.0434848726877,5.26971640351378,7.91225099563599,27,1,0,0,1,0.27557373046875,41.055721282959,2,1,1,85.8104095458984,0,85.8474731445313,,,,,,,,,,,,,,,,,,,,,,,,,,,,,,,,,
,3832582290.35506,83.2720108032227,9999.494140625,-6.43704034491241E-5,2.74465017008888E-8,1,2,13.4005146026611,4.99291754940853,29.3300002813339,-0.0856076176349878,-0.0126693270603637,1,-5.15324376479488E-7,,,,,,,,,,,,,,,,,,,,,83.2202529907227,83.3237686157227,9999.494140625,9999.494140625,47.0720143136396,5.26956712892516,7.89790964126587,27,1,0,0,1,0.276718139648438,40.5669593811035,2,1,1,83.2202529907227,0,83.2720108032227,,,,,,,,,,,,,,,,,,,,,,,,,,,,,,,,,
,3832582344.72824,80.5018196105957,9999.494140625,-6.42706425050118E-5,3.25433931412112E-8,1,2,13.4005146026611,4.99298814268547,29.3099991977215,-0.0854742916893741,-0.0126664418929964,1,-5.26921809074354E-7,,,,,,,,,,,,,,,,,,,,,80.4424896240234,80.561149597168,9999.494140625,9999.494140625,47.0579450002934,5.27006870792855,7.87098836898804,27,1,0,0,1,0.285797119140625,41.055721282959,2,1,1,80.4424896240234,0,80.5018196105957,,,,,,,,,,,,,,,,,,,,,,,,,,,,,,,,,
,3832582399.13968,77.7555389404297,9999.494140625,-6.38818219480965E-5,2.33474924586188E-8,1,2,13.4005146026611,4.9929484397754,29.3099991977215,-0.084958978452833,-0.0125702973185084,1,-5.09179172352608E-7,,,,,,,,,,,,,,,,,,,,,77.7005233764648,77.8105545043945,9999.494140625,9999.494140625,47.0950723549569,5.27072927525033,7.84923410415649,27,1,0,0,1,0.275039672851562,40.5669593811035,2,1,1,77.7005233764648,0,77.7555389404297,,,,,,,,,,,,,,,,,,,,,,,,,,,,,,,,,
,3832582451.89857,75.114315032959,9999.494140625,-6.35744055189395E-5,2.18579309952964E-8,1,2,13.4005146026611,4.99295885760654,29.3199997395277,-0.0845532645123154,-0.0124891746712881,1,-4.9120659386983E-7,,,,,,,,,,,,,,,,,,,,,75.0934371948242,75.1351928710937,9999.494140625,9999.494140625,47.0473930152838,5.26958282449163,7.83899736404419,27,1,0,0,1,0.275421142578125,41.055721282959,2,1,1,75.0934371948242,0,75.114315032959,,,,,,,,,,,,,,,,,,,,,,,,,,,,,,,,,
,3832582504.25897,72.4378700256348,9999.494140625,-6.31467119279263E-5,3.39056373732035E-8,1,2,13.4005146026611,4.99281076325572,29.3099991977215,-0.0839820799145073,-0.0123970925264575,1,-4.82225443022246E-7,,,,,,,,,,,,,,,,,,,,,72.3720703125,72.5036697387695,9999.494140625,9999.494140625,47.0892101410627,5.27075859602545,7.80019664764404,27,1,0,0,1,0.276031494140625,41.055721282959,2,1,1,72.3720703125,0,72.4378700256348,,,,,,,,,,,,,,,,,,,,,,,,,,,,,,,,,
,3832582558.46927,69.7755355834961,9999.494140625,-6.2960980765216E-5,4.86239083471175E-8,1,2,13.4005146026611,4.99278382631963,29.2899999767542,-0.0837244623947211,-0.012431950115003,1,-5.34445408209825E-7,,,,,,,,,,,,,,,,,,,,,69.724365234375,69.8267059326172,9999.494140625,9999.494140625,47.1486139085242,5.27098185235413,7.78730201721191,27,1,0,0,1,0.276107788085938,40.5669593811035,2,1,1,69.724365234375,0,69.7755355834961,,,,,,,,,,,,,,,,,,,,,,,,,,,,,,,,,
,3832582610.67794,67.1173133850098,9999.494140625,-6.25019683288285E-5,3.46782949001791E-8,1,2,13.4005146026611,4.9926508780926,29.2899999767542,-0.0831144047806088,-0.0123168184183895,1,-5.12486377794612E-7,,,,,,,,,,,,,,,,,,,,,67.069709777832,67.1649169921875,9999.494140625,9999.494140625,47.0602898858511,5.27118237237279,7.75107526779175,27,1,0,0,1,0.276641845703125,40.5669593811035,2,1,1,67.069709777832,0,67.1173133850098,,,,,,,,,,,,,,,,,,,,,,,,,,,,,,,,,
,3832582665.08118,64.3566741943359,9999.494140625,-6.19614288045826E-5,2.7822982733801E-8,1,2,13.4005146026611,4.99276987347671,29.2899999767542,-0.0824048280352086,-0.0121639562165454,1,-4.72946661413656E-7,,,,,,,,,,,,,,,,,,,,,64.305534362793,64.4078140258789,9999.494140625,9999.494140625,46.9961963472742,5.27109279217858,7.70882081985474,27,1,0,0,1,0.27679443359375,40.5669593811035,2,1,1,64.305534362793,0,64.3566741943359,,,,,,,,,,,,,,,,,,,,,,,,,,,,,,,,,
,3832582721.52265,61.5478191375732,9999.494140625,-6.12625641029166E-5,2.83804403222069E-8,1,2,13.4005146026611,4.99278870446339,29.2899999767542,-0.0814756552578165,-0.0120278757265332,1,-4.6840466823413E-7,,,,,,,,,,,,,,,,,,,,,61.4904670715332,61.6051712036133,9999.494140625,9999.494140625,47.0430940584281,5.27135036704778,7.68720149993896,27,1,0,0,1,0.278472900390625,40.5669593811035,2,1,1,61.4904670715332,0,61.5478191375732,,,,,,,,,,,,,,,,,,,,,,,,,,,,,,,,,
,3832582775.90722,58.831169128418,9999.494140625,-6.07338088328312E-5,2.89615708650628E-8,1,2,13.4005146026611,4.99290275694742,29.2700007557869,-0.080775506317998,-0.0119206002220333,1,-4.61480306384979E-7,,,,,,,,,,,,,,,,,,,,,58.7735595703125,58.8887786865234,9999.494140625,9999.494140625,47.1361078522165,5.27016939203553,7.65629196166992,27,1,0,0,1,0.2764892578125,40.5669593811035,2,1,1,58.7735595703125,0,58.831169128418,,,,,,,,,,,,,,,,,,,,,,,,,,,,,,,,,
,3832582828.60416,56.1718101501465,9999.494140625,-5.98656751268711E-5,3.33593277626356E-8,1,2,13.4005146026611,4.99295489884982,29.2700007557869,-0.079614638847288,-0.0118032676837505,1,-4.94610660875897E-7,,,,,,,,,,,,,,,,,,,,,56.1423416137695,56.2012786865234,9999.494140625,9999.494140625,47.0571633717742,5.26950733565955,7.61246156692505,27,1,0,0,1,0.285186767578125,40.5669593811035,2,1,1,56.1423416137695,0,56.1718101501465,,,,,,,,,,,,,,,,,,,,,,,,,,,,,,,,,
,3832582882.93501,53.4426307678223,9999.494140625,-5.89083561021073E-5,2.59100836534886E-8,1,2,13.4005146026611,4.99293110475185,29.2700007557869,-0.0783478802683652,-0.0115652386597016,1,-4.49743869329211E-7,,,,,,,,,,,,,,,,,,,,,53.3949775695801,53.4902839660645,9999.494140625,9999.494140625,47.0821754843896,5.2698237598197,7.57638168334961,27,1,0,0,1,0.276947021484375,40.5669593811035,2,1,1,53.3949775695801,0,53.4426307678223,,,,,,,,,,,,,,,,,,,,,,,,,,,,,,,,,
,3832582937.16586,50.6952152252197,9999.494140625,-5.79489141020518E-5,2.42513537210383E-8,1,2,13.4005146026611,4.99288408710816,29.2700007557869,-0.0770713545340058,-0.0113729889510965,1,-4.39610149024476E-7,,,,,,,,,,,,,,,,,,,,,50.6624031066895,50.72802734375,9999.494140625,9999.494140625,47.0888193268031,5.27022968136412,7.52022409439087,27,1,0,0,1,0.285415649414062,41.055721282959,2,1,1,50.6624031066895,0,50.6952152252197,,,,,,,,,,,,,,,,,,,,,,,,,,,,,,,,,
,3832582991.71945,47.9581394195557,9999.494140625,-5.73063974979722E-5,2.55300650837407E-8,1,2,13.4005146026611,4.9929979953306,29.2499996721745,-0.0762113110238439,-0.0113036481404668,1,-4.77101391198489E-7,,,,,,,,,,,,,,,,,,,,,47.8919067382812,48.0243721008301,9999.494140625,9999.494140625,47.0880376982838,5.26932846920769,7.48102760314941,27,1,0,0,1,0.28533935546875,41.055721282959,2,1,1,47.8919067382812,0,47.9581394195557,,,,,,,,,,,,,,,,,,,,,,,,,,,,,,,,,
,3832583046.09141,45.2251300811768,9999.494140625,-5.63820522627013E-5,2.2947197586088E-8,1,2,13.4005146026611,4.99307960714517,29.2499996721745,-0.0749896056345878,-0.0110794144669765,1,-4.37744372622605E-7,,,,,,,,,,,,,,,,,,,,,45.1776313781738,45.2726287841797,9999.494140625,9999.494140625,47.086865255505,5.26887737157136,7.4281644821167,27,1,0,0,1,0.283737182617187,40.5669593811035,2,1,1,45.1776313781738,0,45.2251300811768,,,,,,,,,,,,,,,,,,,,,,,,,,,,,,,,,
,3832583102.34956,42.4087657928467,9999.494140625,-5.5464631784493E-5,3.66729339202935E-8,1,2,13.4005146026611,4.99318303496031,29.2499996721745,-0.073774194981079,-0.010880215616865,1,-4.16179705437978E-7,,,,,,,,,,,,,,,,,,,,,42.3569869995117,42.4605445861816,9999.494140625,9999.494140625,47.0368410302742,5.26881703442229,7.37747383117676,27,1,0,0,1,0.274581909179687,41.055721282959,2,1,1,42.3569869995117,0,42.4087657928467,,,,,,,,,,,,,,,,,,,,,,,,,,,,,,,,,
,3832583156.97831,39.6557369232178,9999.494140625,-5.46377851509457E-5,2.88728139298422E-8,1,2,13.4005146026611,4.99320297498457,29.2499996721745,-0.0726699840491077,-0.0107524743604603,1,-4.35809452680615E-7,,,,,,,,,,,,,,,,,,,,,39.6063385009766,39.705135345459,9999.494140625,9999.494140625,47.0763132704954,5.26831891659788,7.28536367416382,27,1,0,0,1,0.276107788085938,40.5669593811035,2,1,1,39.6063385009766,0,39.6557369232178,,,,,,,,,,,,,,,,,,,,,,,,,,,,,,,,,
,3832583241.4965,35.3871593475342,9999.494140625,-5.33563316933977E-5,5.59361526737718E-8,1,2,13.4005146026611,4.99326007270947,29.2300004512072,-0.0709736859160128,-0.0104506512726195,1,-3.88185335229945E-7,,,,,,,,,,,,,,,,,,,,,35.3526077270508,35.4217109680176,9999.494140625,9999.494140625,47.0606807001108,5.26833302562529,7.1690845489502,25,1,32,0,0,0.27801513671875,40.5669593811035,2,1,1,35.3526077270508,0,35.3871593475342,,,,,,,,,,,,,,,,,,,,,,,,,,,,,,,,,
,3832583298.0368,32.5801563262939,9999.494140625,-5.22817629119233E-5,3.40746065789378E-8,1,2,13.4005146026611,4.99329488265259,29.2399991303682,-0.0695361560245142,-0.0103033664393042,1,-4.27746869084125E-7,,,,,,,,,,,,,,,,,,,,,32.5584259033203,32.6018867492676,9999.494140625,9999.494140625,47.0602898858511,5.26819557275172,7.05187797546387,27,1,0,0,1,0.284271240234375,40.5669593811035,2,1,1,32.5584259033203,0,32.5801563262939,,,,,,,,,,,,,,,,,,,,,,,,,,,,,,,,,
,3832583360.28033,29.4454660415649,9999.494140625,-5.08005183433408E-5,3.58824617033704E-8,1,2,13.4005146026611,4.99324957990242,29.2300004512072,-0.067567902462799,-0.00999214825735237,1,-4.01224119265932E-7,,,,,,,,,,,,,,,,,,,,,29.4067401885986,29.4841918945313,9999.494140625,9999.494140625,47.0763132704954,5.26869579193037,6.92630624771118,27,1,0,0,1,0.2764892578125,40.5669593811035,2,1,1,29.4067401885986,0,29.4454660415649,,,,,,,,,,,,,,,,,,,,,,,,,,,,,,,,,
,3832583422.6969,26.3106565475464,9999.494140625,-4.92335726932675E-5,4.80279509530721E-8,1,2,13.4005146026611,4.99312519420162,29.2300004512072,-0.0654761742457824,-0.00972191625852122,1,-4.17618460789616E-7,,,,,,,,,,,,,,,,,,,,,26.2691822052002,26.3521308898926,9999.494140625,9999.494140625,46.9508618931588,5.26888923123036,6.75855827331543,27,1,0,0,1,0.287628173828125,40.5669593811035,2,1,1,26.2691822052002,0,26.3106565475464,,,,,,,,,,,,,,,,,,,,,,,,,,,,,,,,,
,3832583498.52286,22.4979190826416,9999.494140625,-4.70288383922646E-5,4.42579719905114E-8,1,2,13.4005146026611,4.99308026404722,29.2199999094009,-0.0625414088259139,-0.00930001875038285,1,-4.0911271401461E-7,,,,,,,,,,,,,,,,,,,,,22.4979190826416,22.4979190826416,9999.494140625,9999.494140625,47.0466113867646,5.26919744371928,6.47851848602295,27,1,0,0,1,0.287094116210938,40.5669593811035,2,1,1,22.4979190826416,0,22.4979190826416,,,,,,,,,,,,,,,,,,,,,,,,,,,,,,,,,
,3832583569.8004,18.9831066131592,9999.494140625,-4.41066340437968E-5,3.92042015937652E-8,1,2,13.4005146026611,4.99305846742409,29.2199999094009,-0.0586541770432985,-0.00872768045399354,1,-3.87885703352251E-7,,,,,,,,,,,,,,,,,,,,,18.9397487640381,19.0264644622803,9999.494140625,9999.494140625,47.10210701163,5.26928576361806,6.12616205215454,27,1,0,0,1,0.2764892578125,40.5669593811035,2,1,1,18.9397487640381,0,18.9831066131592,,,,,,,,,,,,,,,,,,,,,,,,,,,,,,,,,
,3832583632.2284,15.9039039611816,9999.494140625,-4.0692725177528E-5,3.55140303956565E-8,1,2,13.4005146026611,4.99294899340963,29.2199999094009,-0.054114757633415,-0.00803679035717971,1,-3.46510543011963E-7,,,,,,,,,,,,,,,,,,,,,15.8484888076782,15.9593191146851,9999.494140625,9999.494140625,47.0774857132742,5.26984500863618,5.70013904571533,27,1,0,0,1,0.277938842773438,40.5669593811035,2,1,1,15.8484888076782,0,15.9039039611816,,,,,,,,,,,,,,,,,,,,,,,,,,,,,,,,,
,3832583692.8723,12.9275908470154,9999.494140625,-3.59882369446467E-5,3.96560394409803E-8,1,2,13.4005146026611,4.9929742023255,29.2099993675947,-0.0478516388922871,-0.00715948382240572,1,-3.45339419160823E-7,,,,,,,,,,,,,,,,,,,,,12.8980083465576,12.9571733474731,9999.494140625,9999.494140625,47.0403583586107,5.26946629894772,5.2433934211731,27,1,0,0,1,0.285263061523438,40.5669593811035,2,1,1,12.8980083465576,0,12.9275908470154,,,,,,,,,,,,,,,,,,,,,,,,,,,,,,,,,
,3832583747.14704,10.3345170021057,9999.494140625,-2.9272408564542E-5,4.66088889222418E-8,1,2,13.4005146026611,4.99288056307976,29.2099993675947,-0.0389209269386358,-0.00582352588589297,1,-2.81071997811635E-7,,,,,,,,,,,,,,,,,,,,,10.2923803329468,10.3766536712646,9999.494140625,9999.494140625,47.1830055633704,5.26996998685969,4.55131959915161,27,1,0,0,1,0.275650024414062,40.5669593811035,2,1,1,10.2923803329468,0,10.3345170021057,,,,,,,,,,,,,,,,,,,,,,,,,,,,,,,,,
,3832583797.42037,8.091148853302,9999.494140625,-2.05175772194581E-5,4.25981115318246E-8,1,2,13.4005146026611,4.99290319830671,29.2099993675947,-0.0272839105989457,-0.00405797440407582,1,-1.7908104635344E-7,,,,,,,,,,,,,,,,,,,,,8.05918598175049,8.12311172485352,9999.494140625,9999.494140625,47.0759224562358,5.26980727553643,4.32936477661133,27,1,0,0,1,0.274887084960938,40.5669593811035,2,1,1,8.05918598175049,0,8.091148853302,,,,,,,,,,,,,,,,,,,,,,,,,,,,,,,,,
,3832583853.84231,8.00000548362732,9999.494140625,-2.01587864976674E-5,4.35951024218742E-8,1,2,13.4005146026611,4.99288326638775,29.2099993675947,-0.0267979843799308,-0.00404896997131994,1,-2.22501323354034E-7,,,,,,,,,,,,,,,,,,,,,7.99999284744263,8.00001811981201,9999.494140625,9999.494140625,47.1286823812838,5.27036586870964,4.31125164031982,27,1,0,0,1,0.287857055664062,40.5669593811035,5,1,1,7.99999284744263,0,8.00000548362732,,,,,,,,,,,,,,,,,,,,,,,,,,,,,,,,,
,3832583861.89099,7.99996972084045,9999.494140625,-2.01780874392609E-5,3.13850826173539E-8,1,2,13.4005146026611,4.99288624097607,29.2099993675947,-0.0268259125968757,-0.00403676728427056,1,-2.10634851073757E-7,,,,,,,,,,,,,,,,,,,,,7.99992036819458,8.00001907348633,9999.494140625,9999.494140625,47.1216477246108,5.27025934207917,4.30785036087036,27,1,0,0,1,0.285568237304687,40.5669593811035,1,1,1,7.99992036819458,0,7.99996972084045,,,,,,,,,,,,,,,,,,,,,,,,,,,,,,,,,