File: SI Fig S11-13 SQUID all/Michaela_Dy_ZFC1T.dat
[Header]
; MPMS3 Data File (default extension .dat)
; Copyright (c) 2007, Quantum Design, Inc. All rights reserved.
TITLE,
FILEOPENTIME,3832414223.70455,06/09/2021,3:30 pm
BYAPP,MPMS3 w/ AC,1.0,1.1
INFO,MPMS3 Measurement Release 1.1.16 Build 424, MultiVu Release 2.3.4.19,APPNAME
INFO,Linear Motor Servo Controller,MOTOR_MODULE_NAME
INFO,3101-100 E1,MOTOR_HW_VERSION
INFO,MMC211,MOTOR_SERIAL_NUMBER
INFO,01.04.28,MOTOR_SOFTWARE_VERSION
INFO,Quantum Design Squid Module,SQUID_MODULE_NAME
INFO,3101-501 B0,SQUID_HW_VERSION
INFO,SQM059,SQUID_SERIAL_NUMBER
INFO,01.03.04,SQUID_SOFTWARE_VERSION
INFO,SQUID AC,AC_MODULE_NAME
INFO,3101-401 F1,AC_HW_VERSION
INFO,SAC057,AC_SERIAL_NUMBER
INFO,SQUID AC 00.95.07,AC_SOFTWARE_VERSION
INFO,TCIXXX,COIL_SERIAL_NUMBER
INFO,0,MOMENT_UNITS
INFO,Michaela_Dy,SAMPLE_MATERIAL
INFO,Michaela_Dy,SAMPLE_COMMENT
INFO,.85,SAMPLE_MASS
INFO,,SAMPLE_VOLUME
INFO,,SAMPLE_MOLECULAR_WEIGHT
INFO,,SAMPLE_SIZE
INFO,,SAMPLE_SHAPE
INFO,Straw,SAMPLE_HOLDER
INFO,Standard,SAMPLE_HOLDER_DETAIL
INFO,54.24,SAMPLE_OFFSET
DATATYPE,COMMENT,1
DATATYPE,TIME,2
STARTUPAXIS,X,2
STARTUPAXIS,Y1,5
FIELDGROUP, VSM,2,3,4,5,6,8,9,10,11,14,15
FIELDGROUP, DC, 2,3,4,14,56,57,58,59,60,61,62,63,64,65,66,67,68,69
FIELDGROUP, AC, 2,3,4,11,16,17,18,19,20,21,22,23,24,25,26,27,28,29,30
STARTUPGROUP, All
[Data]
Comment,Time Stamp (sec),Temperature (K),Magnetic Field (Oe),Moment (emu),M. Std. Err. (emu),Transport Action,Averaging Time (sec),Frequency (Hz),Peak Amplitude (mm),Center Position (mm),Lockin Signal' (V),Lockin Signal (V),Range,M. Quad. Signal (emu),AC Moment (emu),AC M. Std Err. (emu),AC Phase (deg),AC Phase Std. Err. (deg),AC Susceptibility (emu/Oe),AC Suscept. Std Err. (emu/Oe),AC X' (emu/Oe),AC X' Std Err. (emu/Oe),AC X'' (emu/Oe),AC X'' Std Err. (emu/Oe),AC Drive (Oe),AC Frequency (Hz),AC Averaging Time (sec),AC Cycles,AC Range,AC Measure Type,AC Signal' (V),AC Signal'' (V),AC Trim Coil Ratio,AC Trim Coil Phase,Min. Temperature (K),Max. Temperature (K),Min. Field (Oe),Max. Field (Oe),Mass (grams),Motor Lag (deg),Pressure (Torr),Measure Count,Measurement Number,SQUID Status (code),Motor Status (code),Measure Status (code),Motor Current (amps),Motor Temp. (C),Temp. Status (code),Field Status (code),Chamber Status (code),Chamber Temp (K),Redirection State,Average Temp (K),Rotation Angle (deg),Rotator state,DC Moment Fixed Ctr (emu),DC Moment Err Fixed Ctr (emu),DC Moment Free Ctr (emu),DC Moment Err Free Ctr (emu),DC Fixed Fit,DC Free Fit,DC Calculated Center (mm),DC Calculated Center Err (mm),DC Scan Length (mm),DC Scan Time (s),DC Number of Points,DC Squid Drift,DC Min V (V),DC Max V (V),DC Scans per Measure,Map 01,Map 02,Map 03,Map 04,Map 05,Map 06,Map 07,Map 08,Map 09,Map 10,Map 11,Map 12,Map 13,Map 14,Map 15,Map 16
,3832414243.829,7.99981117248535,9999.7802734375,0.0078500123918533,7.84497614230707E-7,1,2,13.4005146026611,5.00339496384846,32.1800000965595,10.4675561849324,1.56631263670055,10,7.54555751636407E-5,,,,,,,,,,,,,,,,,,,,,7.99981117248535,7.99981117248535,9999.7802734375,9999.7802734375,46.9829086624473,5.26860776905218,4.52684259414673,27,1,0,0,1,0.287551879882813,37.6344108581543,1,1,1,7.99981117248535,0,7.99981117248535,,,,,,,,,,,,,,,,,,,,,,,,,,,,,,,,,
,3832414301.37137,10.5085706710815,9999.7802734375,0.00736860441519097,3.04086734822618E-6,1,2,13.4005146026611,5.00348211104584,32.1800000965595,9.82622527784209,1.46767600035328,10,6.88687863412989E-5,,,,,,,,,,,,,,,,,,,,,10.422758102417,10.5943832397461,9999.7802734375,9999.7802734375,47.1150038821973,5.2683097700737,4.94539165496826,27,1,0,0,1,0.278854370117187,38.6119270324707,6,1,1,10.5943832397461,0,10.5085706710815,,,,,,,,,,,,,,,,,,,,,,,,,,,,,,,,,
,3832414356.48423,13.1005024909973,9999.7802734375,0.00608062381716467,2.52235402825953E-6,1,2,13.4005146026611,5.00352896539082,32.1700014173985,8.10896867196554,1.20975673921816,10,5.57860908364087E-5,,,,,,,,,,,,,,,,,,,,,13.0537338256836,13.147271156311,9999.7802734375,9999.7802734375,47.1314180811011,5.26812218208515,5.35955619812012,27,1,0,0,1,0.28228759765625,39.1006851196289,6,1,1,13.147271156311,0,13.1005024909973,,,,,,,,,,,,,,,,,,,,,,,,,,,,,,,,,
,3832414414.915,15.9609122276306,9999.7802734375,0.00510095151191699,1.55998674402427E-6,1,2,13.4005146026611,5.00356287453512,32.1700014173985,6.80264309081357,1.0142999937181,10,4.63805470714016E-5,,,,,,,,,,,,,,,,,,,,,15.9140119552612,16.0078125,9999.7802734375,9999.7802734375,47.08178467013,5.26692149559691,5.66000652313232,27,1,0,0,1,0.280532836914062,39.1006851196289,2,1,1,16.0078125,0,15.9609122276306,,,,,,,,,,,,,,,,,,,,,,,,,,,,,,,,,
,3832414469.34427,18.6125116348267,9999.7802734375,0.00442981541184775,1.15415066053203E-6,1,2,13.4005146026611,5.00342839429241,32.1700014173985,5.90757521299305,0.879540299177347,10,3.93232850121255E-5,,,,,,,,,,,,,,,,,,,,,18.573787689209,18.6512355804443,9999.7802734375,9999.7802734375,47.1107049253415,5.26752613363957,5.85224103927612,27,1,0,0,1,0.280838012695313,39.5894432067871,2,1,1,18.6512355804443,0,18.6125116348267,,,,,,,,,,,,,,,,,,,,,,,,,,,,,,,,,
,3832414527.95427,21.405387878418,9999.7802734375,0.00388563167496484,1.06596934257678E-6,1,2,13.4005146026611,5.00338182230029,32.1700014173985,5.18186701036715,0.770925325105562,10,3.40751231094485E-5,,,,,,,,,,,,,,,,,,,,,21.3522930145264,21.4584827423096,9999.7802734375,9999.7802734375,47.1040610829281,5.26739194452634,6.03038644790649,27,1,0,0,1,0.277786254882813,39.1006851196289,2,1,1,21.4584827423096,0,21.405387878418,,,,,,,,,,,,,,,,,,,,,,,,,,,,,,,,,
,3832414592.42209,24.5232734680176,9999.7802734375,0.00342053395142699,6.87928745614307E-7,1,2,13.4005146026611,5.00332128268698,32.1800000965595,4.56166952807124,0.677700010316964,10,2.92948444761613E-5,,,,,,,,,,,,,,,,,,,,,24.4653453826904,24.5812015533447,9999.7802734375,9999.7802734375,47.168154621505,5.26760460441769,6.19468021392822,27,1,0,0,1,0.283126831054687,39.1006851196289,2,1,1,24.5812015533447,0,24.5232734680176,,,,,,,,,,,,,,,,,,,,,,,,,,,,,,,,,
,3832414648.77445,27.2463493347168,9999.7802734375,0.0030970982549963,5.821827850698E-7,1,2,13.4005146026611,5.00340503947782,32.1800000965595,4.13052980463721,0.612890110904484,10,2.59686422335203E-5,,,,,,,,,,,,,,,,,,,,,27.1983890533447,27.2943096160889,9999.7802734375,9999.7802734375,47.2486623589858,5.26682592909306,6.32418251037598,27,1,0,0,1,0.278091430664062,39.1006851196289,2,1,1,27.2943096160889,0,27.2463493347168,,,,,,,,,,,,,,,,,,,,,,,,,,,,,,,,,
,3832414705.41886,29.979923248291,9999.7802734375,0.00283004886723467,4.92229807364553E-7,1,2,13.4005146026611,5.00357461193998,32.1800000965595,3.77465338799229,0.559308823085599,10,2.31600289564654E-5,,,,,,,,,,,,,,,,,,,,,29.9488754272461,30.0109710693359,9999.7802734375,9999.7802734375,47.2091901187646,5.26707086581162,6.42318058013916,27,1,0,0,1,0.280838012695313,39.1006851196289,2,1,1,30.0109710693359,0,29.979923248291,,,,,,,,,,,,,,,,,,,,,,,,,,,,,,,,,
,3832414761.46704,32.6949405670166,9999.7802734375,0.0026031340919897,4.67496196030726E-7,1,2,13.4005146026611,5.0035411256867,32.1899987757206,3.47203606111737,0.513971320951616,10,2.09382397070946E-5,,,,,,,,,,,,,,,,,,,,,32.644603729248,32.7452774047852,9999.7802734375,9999.7802734375,47.1587750792742,5.26749142699089,6.52627372741699,27,1,0,0,1,0.274200439453125,39.5894432067871,2,1,1,32.7452774047852,0,32.6949405670166,,,,,,,,,,,,,,,,,,,,,,,,,,,,,,,,,
,3832414819.87552,35.5496711730957,9999.7802734375,0.00240568886283166,3.29199630165175E-7,1,2,13.4005146026611,5.00377744411531,32.1899987757206,3.20892474637351,0.47478894706085,10,1.91787358266994E-5,,,,,,,,,,,,,,,,,,,,,35.5095672607422,35.5897750854492,9999.7802734375,9999.7802734375,47.12242935313,5.26603428146512,6.60216999053955,27,1,0,0,1,0.280990600585938,39.5894432067871,2,1,1,35.5897750854492,0,35.5496711730957,,,,,,,,,,,,,,,,,,,,,,,,,,,,,,,,,
,3832414876.43311,38.2968006134033,9999.7802734375,0.00224194552699313,3.76779951200688E-7,1,2,13.4005146026611,5.00402744939498,32.1800000965595,2.99079823224833,0.441896631568415,10,1.74195455808953E-5,,,,,,,,,,,,,,,,,,,,,38.2411804199219,38.3524208068848,9999.7802734375,9999.7802734375,47.2400644452742,5.26526601688269,6.66939878463745,27,1,0,0,1,0.278549194335938,39.5894432067871,2,1,1,38.3524208068848,0,38.2968006134033,,,,,,,,,,,,,,,,,,,,,,,,,,,,,,,,,
,3832414945.15788,41.6323833465576,9999.7802734375,0.00207082357691521,2.795079345952E-7,1,2,13.4005146026611,5.00404481643476,32.1800000965595,2.76255028527666,0.408034598275667,10,1.59887679117824E-5,,,,,,,,,,,,,,,,,,,,,41.6084022521973,41.656364440918,9999.7802734375,9999.7802734375,47.2244318748896,5.26617429724531,6.73961973190308,27,1,0,0,1,0.280609130859375,39.1006851196289,2,1,1,41.6713485717773,0,41.6323833465576,,,,,,,,,,,,,,,,,,,,,,,,,,,,,,,,,
,3832415000.48327,44.3386707305908,9999.7802734375,0.00194867019856186,2.33547551325237E-7,1,2,13.4005146026611,5.00398076373974,32.1800000965595,2.59958698800341,0.383679523707309,10,1.48364987559481E-5,,,,,,,,,,,,,,,,,,,,,44.2630615234375,44.4142799377441,9999.7802734375,9999.7802734375,47.2322481600819,5.26606952641233,6.79817771911621,27,1,0,0,1,0.279617309570313,39.5894432067871,2,1,1,44.4142799377441,0,44.3386707305908,,,,,,,,,,,,,,,,,,,,,,,,,,,,,,,,,
,3832415057.63498,47.135814666748,9999.7802734375,0.00183862363001287,3.02479883419746E-7,1,2,13.4005146026611,5.00382238756822,32.200001180172,2.45270277033559,0.361799545060543,10,1.38511898959332E-5,,,,,,,,,,,,,,,,,,,,,47.0921249389648,47.1795043945313,9999.7802734375,9999.7802734375,47.2009830193127,5.26691795218136,6.83904600143433,27,1,0,0,1,0.276412963867187,39.5894432067871,2,1,1,47.1795043945313,0,47.135814666748,,,,,,,,,,,,,,,,,,,,,,,,,,,,,,,,,
,3832415114.05679,49.9153633117676,9999.7802734375,0.00174188423780598,2.43162788726995E-7,1,2,13.4005146026611,5.00385581092659,32.200001180172,2.32368568045221,0.342688481978585,10,1.30639460733953E-5,,,,,,,,,,,,,,,,,,,,,49.863582611084,49.9671440124512,9999.7802734375,9999.7802734375,47.19355754838,5.26702488995035,6.89873886108398,27,1,0,0,1,0.27923583984375,39.5894432067871,2,1,1,49.9671440124512,0,49.9153633117676,,,,,,,,,,,,,,,,,,,,,,,,,,,,,,,,,
,3832415168.4416,52.5584926605225,9999.7802734375,0.00165763965865387,2.46245200291799E-7,1,2,13.4005146026611,5.0037316847344,32.1899987757206,2.21121760139795,0.326176511327447,10,1.24867113273095E-5,,,,,,,,,,,,,,,,,,,,,52.5224723815918,52.5945129394531,9999.7802734375,9999.7802734375,47.2107533758031,5.2679043781399,6.9364185333252,27,1,0,0,1,0.279006958007813,39.5894432067871,2,1,1,52.5945129394531,0,52.5584926605225,,,,,,,,,,,,,,,,,,,,,,,,,,,,,,,,,
,3832415227.02251,55.4541893005371,9999.7802734375,0.00157491674750387,1.50301536302819E-7,1,2,13.4005146026611,5.00380142594718,32.200001180172,2.10092732793848,0.309773595768651,10,1.17652511770314E-5,,,,,,,,,,,,,,,,,,,,,55.40185546875,55.5065231323242,9999.7802734375,9999.7802734375,47.2349838598992,5.26806138377851,6.97081899642944,27,1,0,0,1,0.277862548828125,39.1006851196289,2,1,1,55.5065231323242,0,55.4541893005371,,,,,,,,,,,,,,,,,,,,,,,,,,,,,,,,,
,3832415281.33589,58.1005458831787,9999.7802734375,0.00150585554155912,1.56019076451413E-7,1,2,13.4005146026611,5.00361954797737,32.200001180172,2.00870765299375,0.296122578256527,10,1.12100192760876E-5,,,,,,,,,,,,,,,,,,,,,58.0468902587891,58.1542015075684,9999.7802734375,9999.7802734375,47.2056727904281,5.26902382831163,7.00800371170044,27,1,0,0,1,0.276336669921875,39.5894432067871,2,1,1,58.1542015075684,0,58.1005458831787,,,,,,,,,,,,,,,,,,,,,,,,,,,,,,,,,
,3832415337.85822,60.89182472229,9999.7802734375,0.0014404905934686,1.59712513376122E-7,1,2,13.4005146026611,5.00362163348097,32.200001180172,1.92153601313134,0.283128666467763,10,1.06184109155587E-5,,,,,,,,,,,,,,,,,,,,,60.8386421203613,60.9450073242188,9999.7802734375,9999.7802734375,47.2205237322935,5.2692827713547,7.03219890594482,27,1,0,0,1,0.281448364257813,39.5894432067871,2,1,1,60.9450073242188,0,60.89182472229,,,,,,,,,,,,,,,,,,,,,,,,,,,,,,,,,
,3832415392.14022,63.5488872528076,9999.7802734375,0.00138132141077074,1.68156759509099E-7,1,2,13.4005146026611,5.00361330001331,32.209999859333,1.84256248372538,0.271790591188955,10,1.04011181609375E-5,,,,,,,,,,,,,,,,,,,,,63.4924011230469,63.6053733825684,9999.7802734375,9999.7802734375,47.2252135034088,5.26896154139968,7.04929208755493,27,1,0,0,1,0.276260375976562,39.5894432067871,2,1,1,63.6053733825684,0,63.5488872528076,,,,,,,,,,,,,,,,,,,,,,,,,,,,,,,,,
,3832415450.72835,66.4236564636231,9999.7802734375,0.00132412605034281,1.17559660416542E-7,1,2,13.4005146026611,5.00348750774374,32.209999859333,1.76625975941706,0.260158415886998,10,9.69381240891557E-6,,,,,,,,,,,,,,,,,,,,,66.38330078125,66.4640121459961,9999.7802734375,9999.7802734375,47.2252135034088,5.26921776170221,7.06724071502686,27,1,0,0,1,0.280990600585938,39.5894432067871,2,1,1,66.4640121459961,0,66.4236564636231,,,,,,,,,,,,,,,,,,,,,,,,,,,,,,,,,
,3832415507.22874,69.2206077575684,9999.7802734375,0.00127307139646343,1.59851215416515E-7,1,2,13.4005146026611,5.00346850050825,32.2199985384941,1.69814722159099,0.250137576316898,10,9.32862246391255E-6,,,,,,,,,,,,,,,,,,,,,69.1983032226563,69.2429122924805,9999.7802734375,9999.7802734375,47.2009830193127,5.26989003350838,7.10560321807861,27,1,0,0,1,0.280685424804687,39.5894432067871,2,1,1,69.251838684082,0,69.2206077575684,,,,,,,,,,,,,,,,,,,,,,,,,,,,,,,,,
,3832415561.61792,71.8987846374512,9999.7802734375,0.00122655998402587,1.84629535082896E-7,1,2,13.4005146026611,5.00348434882102,32.2199985384941,1.63612874440746,0.240886122610312,10,8.90259877540295E-6,,,,,,,,,,,,,,,,,,,,,71.8644790649414,71.9330902099609,9999.7802734375,9999.7802734375,47.2177880324761,5.26983628034932,7.12366151809692,27,1,0,0,1,0.277175903320313,39.5894432067871,2,1,1,71.9330902099609,0,71.8987846374512,,,,,,,,,,,,,,,,,,,,,,,,,,,,,,,,,
,3832415618.06022,74.6895484924316,9999.7802734375,0.00118175383833052,1.30745278640692E-7,1,2,13.4005146026611,5.00332338440273,32.2300009429455,1.57624700183393,0.232396112538264,10,8.81686669610072E-6,,,,,,,,,,,,,,,,,,,,,74.6629638671875,74.7161331176758,9999.7802734375,9999.7802734375,47.2994682127358,5.27066023040689,7.15135860443115,27,1,0,0,1,0.274734497070313,39.5894432067871,2,1,1,74.7161331176758,0,74.6895484924316,,,,,,,,,,,,,,,,,,,,,,,,,,,,,,,,,
,3832415673.45542,77.4147300720215,9999.7802734375,0.001141073496562,9.03901337784877E-8,1,2,13.4005146026611,5.00337619023725,32.2300009429455,1.52204804069246,0.224118190823964,10,8.30273721721558E-6,,,,,,,,,,,,,,,,,,,,,77.3348159790039,77.4946441650391,9999.7802734375,9999.7802734375,47.2170064039569,5.27037927389704,7.17413759231567,27,1,0,0,1,0.28289794921875,39.5894432067871,2,1,1,77.4946441650391,0,77.4147300720215,,,,,,,,,,,,,,,,,,,,,,,,,,,,,,,,,
,3832415734.8676,80.4543418884277,9999.7802734375,0.0010997870065311,2.08319800406175E-7,1,2,13.4005146026611,5.00333880469992,32.2399996221066,1.46651922152617,0.219174204075926,1,1.03744463503764E-5,,,,,,,,,,,,,,,,,,,,,80.3975067138672,80.5111770629883,9999.7802734375,9999.7802734375,47.2658581864089,5.27073167930515,7.17916488647461,27,1,0,0,1,0.27587890625,39.5894432067871,2,1,1,80.5111770629883,0,80.4543418884277,,,,,,,,,,,,,,,,,,,,,,,,,,,,,,,,,
,3832415793.34438,83.3260726928711,9999.7802734375,0.00106252449807149,1.42274668729651E-7,1,2,13.4005146026611,5.00313847532206,32.2499983012676,1.41681734788896,0.211281052907539,1,9.6817170404023E-6,,,,,,,,,,,,,,,,,,,,,83.3013916015625,83.3507537841797,9999.7802734375,9999.7802734375,47.21387988988,5.27130560178775,7.20598316192627,27,1,0,0,1,0.28045654296875,39.5894432067871,2,1,1,83.3507537841797,0,83.3260726928711,,,,,,,,,,,,,,,,,,,,,,,,,,,,,,,,,
,3832415848.70075,86.0781974792481,9999.7802734375,0.00102932426283902,8.66706570023202E-8,1,2,13.4005146026611,5.00333857167261,32.2399996221066,1.37258862750601,0.204927512624652,1,9.55674617795995E-6,,,,,,,,,,,,,,,,,,,,,85.9997329711914,86.1566619873047,9999.7802734375,9999.7802734375,47.2412368880531,5.27058386582326,7.2255802154541,27,1,0,0,1,0.28045654296875,39.5894432067871,2,1,1,86.1566619873047,0,86.0781974792481,,,,,,,,,,,,,,,,,,,,,,,,,,,,,,,,,
,3832415904.21958,88.8354415893555,9999.7802734375,0.00099866294992048,1.83438711267791E-7,1,2,13.4005146026611,5.0032924434864,32.2499983012676,1.33172436511569,0.198542175607706,1,9.06349778828912E-6,,,,,,,,,,,,,,,,,,,,,88.8128967285156,88.8579864501953,9999.7802734375,9999.7802734375,47.2447542163896,5.27032653461165,7.23495531082153,27,1,0,0,1,0.284042358398438,39.5894432067871,2,1,1,88.8677291870117,0,88.8354415893555,,,,,,,,,,,,,,,,,,,,,,,,,,,,,,,,,
,3832415959.59466,91.6049499511719,9999.7802734375,0.000969134454146842,8.13563267769985E-8,1,2,13.4005146026611,5.00332042356793,32.2499983012676,1.29234124404235,0.19279145758623,1,8.8841148933322E-6,,,,,,,,,,,,,,,,,,,,,91.5251159667969,91.6847839355469,9999.7802734375,9999.7802734375,47.2818815710531,5.27076823425538,7.24045085906982,27,1,0,0,1,0.281906127929687,39.5894432067871,2,1,1,91.6847839355469,0,91.6049499511719,,,,,,,,,,,,,,,,,,,,,,,,,,,,,,,,,
,3832416014.65335,94.3024063110352,9999.7802734375,0.000941760977411888,1.35921166660137E-7,1,2,13.4005146026611,5.0034319128181,32.260000705719,1.25591595000728,0.187073014754708,1,8.42445274789801E-6,,,,,,,,,,,,,,,,,,,,,94.2581405639648,94.3466720581055,9999.7802734375,9999.7802734375,47.279927499755,5.27040095242163,7.26350688934326,27,1,0,0,1,0.280609130859375,39.5894432067871,2,1,1,94.3466720581055,0,94.3024063110352,,,,,,,,,,,,,,,,,,,,,,,,,,,,,,,,,
,3832416070.39186,97.1089782714844,9999.7802734375,0.000915512965225618,1.24995703431423E-7,1,2,13.4005146026611,5.00342168849199,32.260000705719,1.2209216276644,0.181765723777597,1,8.12012862334369E-6,,,,,,,,,,,,,,,,,,,,,97.0236740112305,97.1942825317383,9999.7802734375,9999.7802734375,47.2424093308319,5.27043951350462,7.2771692276001,27,1,0,0,1,0.280609130859375,39.5894432067871,2,1,1,97.1942825317383,0,97.1089782714844,,,,,,,,,,,,,,,,,,,,,,,,,,,,,,,,,
,3832416127.4904,99.9451446533203,9999.7802734375,0.000889993886939449,1.15035724574866E-7,1,2,13.4005146026611,5.00334807149058,32.2800017893314,1.18686099011117,0.176729131336497,1,7.9188887328829E-6,,,,,,,,,,,,,,,,,,,,,99.894889831543,99.9953994750977,9999.7802734375,9999.7802734375,47.2756285428992,5.27027702618188,7.30051612854004,27,1,0,0,1,0.276412963867187,39.5894432067871,2,1,1,99.9953994750977,0,99.9451446533203,,,,,,,,,,,,,,,,,,,,,,,,,,,,,,,,,
,3832416186.14794,102.854530334473,9999.7802734375,0.000865479276128554,9.04273830456726E-8,1,2,13.4005146026611,5.00338476893746,32.2800017893314,1.15415786351133,0.172027272186001,1,7.82386472949982E-6,,,,,,,,,,,,,,,,,,,,,102.7919921875,102.917068481445,9999.7802734375,9999.7802734375,47.2275583889665,5.27055254282558,7.3040452003479,27,1,0,0,1,0.28228759765625,39.5894432067871,2,1,1,102.917068481445,0,102.854530334473,,,,,,,,,,,,,,,,,,,,,,,,,,,,,,,,,
,3832416240.4115,105.577926635742,9999.7802734375,0.000843395844520423,1.31020177984364E-7,1,2,13.4005146026611,5.00330022995006,32.2900004684925,1.12469426964763,0.167550222457148,1,7.56150440042233E-6,,,,,,,,,,,,,,,,,,,,,105.516830444336,105.639022827148,9999.7802734375,9999.7802734375,47.198638133755,5.27099589313671,7.31614923477173,27,1,0,0,1,0.278244018554687,39.5894432067871,2,1,1,105.639022827148,0,105.577926635742,,,,,,,,,,,,,,,,,,,,,,,,,,,,,,,,,
,3832416296.97443,108.375297546387,9999.7802734375,0.000821555432030449,7.59274652049559E-8,1,2,13.4005146026611,5.00337779934659,32.2900004684925,1.0955789988967,0.163312425771671,1,7.43878107610519E-6,,,,,,,,,,,,,,,,,,,,,108.314559936523,108.43603515625,9999.7802734375,9999.7802734375,47.3084569407069,5.27034124497122,7.34555053710937,27,1,0,0,1,0.283126831054687,39.5894432067871,2,1,1,108.43603515625,0,108.375297546387,,,,,,,,,,,,,,,,,,,,,,,,,,,,,,,,,
,3832416355.48791,111.265247344971,9999.7802734375,0.00080057846359125,9.34030624271669E-8,1,2,13.4005146026611,5.0032691105031,32.2999991476536,1.06760600723311,0.158906003419377,1,7.07523816457698E-6,,,,,,,,,,,,,,,,,,,,,111.23934173584,111.291152954102,9999.7802734375,9999.7802734375,47.2537429443608,5.27135334134794,7.34465074539185,27,1,0,0,1,0.281906127929687,39.5894432067871,2,1,1,111.291152954102,0,111.265247344971,,,,,,,,,,,,,,,,,,,,,,,,,,,,,,,,,
,3832416410.83722,114.044780731201,9999.7802734375,0.000780836920943122,7.89768828082968E-8,1,2,13.4005146026611,5.00326305512656,32.2999991476536,1.04126829562028,0.155057261930812,1,6.95319148892729E-6,,,,,,,,,,,,,,,,,,,,,113.962265014648,114.127296447754,9999.7802734375,9999.7802734375,47.2920427418031,5.27125554744099,7.35945415496826,27,1,0,0,1,0.281524658203125,39.5894432067871,2,1,1,114.127296447754,0,114.044780731201,,,,,,,,,,,,,,,,,,,,,,,,,,,,,,,,,
,3832416466.28825,116.807727813721,9999.7802734375,0.000763024770187655,5.48448305160783E-8,1,2,13.4005146026611,5.00323806903311,32.2999991476536,1.01752478948557,0.151401427328546,1,6.70643042148968E-6,,,,,,,,,,,,,,,,,,,,,116.785087585449,116.830368041992,9999.7802734375,9999.7802734375,47.2455358449088,5.27166101478718,7.36516618728638,27,1,0,0,1,0.2813720703125,39.5894432067871,2,1,1,116.830368041992,0,116.807727813721,,,,,,,,,,,,,,,,,,,,,,,,,,,,,,,,,
,3832416521.74365,119.567832946777,9999.7802734375,0.000744918093402815,1.04008423971412E-7,1,2,13.4005146026611,5.00322438428454,32.320000231266,0.993344056113038,0.148029961234029,1,6.71345306715916E-6,,,,,,,,,,,,,,,,,,,,,119.480255126953,119.655410766602,9999.7802734375,9999.7802734375,47.2982957699569,5.2713889447872,7.38583087921143,27,1,0,0,1,0.282440185546875,39.5894432067871,2,1,1,119.655410766602,0,119.567832946777,,,,,,,,,,,,,,,,,,,,,,,,,,,,,,,,,
,3832416578.79563,122.398448944092,9999.7802734375,0.000727704880060755,9.1717498897038E-8,1,2,13.4005146026611,5.00321659259413,32.320000231266,0.970395366622594,0.144558266100757,1,6.52028850090582E-6,,,,,,,,,,,,,,,,,,,,,122.344635009766,122.452262878418,9999.7802734375,9999.7802734375,47.320572182755,5.27166999801811,7.38766479492188,27,1,0,0,1,0.282211303710938,39.5894432067871,2,1,1,122.452262878418,0,122.398448944092,,,,,,,,,,,,,,,,,,,,,,,,,,,,,,,,,
,3832416637.4193,125.338077545166,9999.7802734375,0.000710618258740713,9.68260603287176E-8,1,2,13.4005146026611,5.00323802907865,32.3299989104271,0.947625279230211,0.141097691235608,1,6.31689673093432E-6,,,,,,,,,,,,,,,,,,,,,125.281402587891,125.394752502441,9999.7802734375,9999.7802734375,47.2861805279088,5.27159662223928,7.4015302658081,27,1,0,0,1,0.28228759765625,39.5894432067871,2,1,1,125.394752502441,0,125.338077545166,,,,,,,,,,,,,,,,,,,,,,,,,,,,,,,,,
,3832416693.7265,128.121391296387,9999.7802734375,0.00069512985969482,1.28930916389746E-7,1,2,13.4005146026611,5.00328184510536,32.3299989104271,0.926993852947218,0.137941109346294,1,6.11711476050506E-6,,,,,,,,,,,,,,,,,,,,,128.066558837891,128.176223754883,9999.7802734375,9999.7802734375,47.3369863816589,5.27150748386647,7.40826416015625,27,1,0,0,1,0.28228759765625,39.5894432067871,2,1,1,128.202697753906,0,128.121391296387,,,,,,,,,,,,,,,,,,,,,,,,,,,,,,,,,
,3832416750.31352,130.951332092285,9999.7802734375,0.000680013570346228,1.50186786115947E-7,1,2,13.4005146026611,5.0032307533717,32.3499999940395,0.906835022865278,0.13485201756426,1,5.91852757509205E-6,,,,,,,,,,,,,,,,,,,,,130.917617797852,130.985046386719,9999.7802734375,9999.7802734375,47.3225262540531,5.2718822709738,7.41611814498901,27,1,0,0,1,0.283584594726562,39.5894432067871,2,1,1,130.985046386719,0,130.951332092285,,,,,,,,,,,,,,,,,,,,,,,,,,,,,,,,,
,3832416804.51934,133.66423034668,9999.7802734375,0.000665954427467187,1.04988444471841E-7,1,2,13.4005146026611,5.00317040964117,32.3499999940395,0.888075849593018,0.132032405681639,1,5.77414726058865E-6,,,,,,,,,,,,,,,,,,,,,133.616653442383,133.711807250977,9999.7802734375,9999.7802734375,47.3264343966492,5.27211912091531,7.4235463142395,27,1,0,0,1,0.282363891601562,39.5894432067871,2,1,1,133.711807250977,0,133.66423034668,,,,,,,,,,,,,,,,,,,,,,,,,,,,,,,,,
,3832416861.12495,136.487358093262,9999.7802734375,0.000651946518408931,1.18898538708131E-7,1,2,13.4005146026611,5.00310991811522,32.3599986732006,0.869379837531707,0.129264114620576,1,5.66097630568332E-6,,,,,,,,,,,,,,,,,,,,,136.45378112793,136.520935058594,9999.7802734375,9999.7802734375,47.361216865755,5.27233762449745,7.43166017532349,27,1,0,0,1,0.280914306640625,39.5894432067871,2,1,1,136.520935058594,0,136.487358093262,,,,,,,,,,,,,,,,,,,,,,,,,,,,,,,,,
,3832416917.59886,139.275657653809,9999.7802734375,0.000638683083033032,7.35779458578593E-8,1,2,13.4005146026611,5.00308340862199,32.3599986732006,0.851678793097907,0.126689855120249,1,5.5880912116363E-6,,,,,,,,,,,,,,,,,,,,,139.247406005859,139.303909301758,9999.7802734375,9999.7802734375,47.3635617513127,5.27279167708053,7.44227170944214,27,1,0,0,1,0.284271240234375,40.0782012939453,2,1,1,139.303909301758,0,139.275657653809,,,,,,,,,,,,,,,,,,,,,,,,,,,,,,,,,
,3832416975.72285,142.170509338379,9999.7802734375,0.000625352353367043,8.30420443983503E-8,1,2,13.4005146026611,5.00305751776541,32.379999756813,0.833898234156404,0.124032046908985,1,5.46199378350385E-6,,,,,,,,,,,,,,,,,,,,,142.115921020508,142.22509765625,9999.7802734375,9999.7802734375,47.30533042663,5.27254998152384,7.45473861694336,27,1,0,0,1,0.283584594726562,39.5894432067871,2,1,1,142.22509765625,0,142.170509338379,,,,,,,,,,,,,,,,,,,,,,,,,,,,,,,,,
,3832417030.1234,144.890731811523,9999.7802734375,0.000613361775445804,9.76904773841839E-8,1,2,13.4005146026611,5.0029574281205,32.3899984359741,0.817894697455471,0.121592518393077,1,5.31382604255904E-6,,,,,,,,,,,,,,,,,,,,,144.846588134766,144.934875488281,9999.7802734375,9999.7802734375,47.3322966105435,5.27290563399954,7.45933532714844,27,1,0,0,1,0.279388427734375,39.5894432067871,2,1,1,144.934875488281,0,144.890731811523,,,,,,,,,,,,,,,,,,,,,,,,,,,,,,,,,
,3832417088.69212,147.839347839355,9999.7802734375,0.000600910252041515,7.4707085889533E-8,1,2,13.4005146026611,5.0028798475195,32.4000008404255,0.801282544600868,0.119060952473149,1,5.16052003131918E-6,,,,,,,,,,,,,,,,,,,,,147.787307739258,147.891387939453,9999.7802734375,9999.7802734375,47.2619500438127,5.27373691482065,7.46179485321045,27,1,0,0,1,0.285186767578125,40.0782012939453,2,1,1,147.891387939453,0,147.839347839355,,,,,,,,,,,,,,,,,,,,,,,,,,,,,,,,,
,3832417142.94456,150.522247314453,9999.7802734375,0.00058968160962614,7.38439607163885E-8,1,2,13.4005146026611,5.00285561259269,32.4000008404255,0.786312669527513,0.116777137339228,1,5.02045025855999E-6,,,,,,,,,,,,,,,,,,,,,150.46516418457,150.579330444336,9999.7802734375,9999.7802734375,47.2013738335723,5.27376013498923,7.47325849533081,27,1,0,0,1,0.28167724609375,39.5894432067871,2,1,1,150.579330444336,0,150.522247314453,,,,,,,,,,,,,,,,,,,,,,,,,,,,,,,,,
,3832417199.49947,153.341827392578,9999.7802734375,0.000578448253679292,4.81609947116992E-8,1,2,13.4005146026611,5.00280150963536,32.4099995195866,0.771277488992899,0.114869954931631,1,5.16383450405722E-6,,,,,,,,,,,,,,,,,,,,,153.267059326172,153.416595458984,9999.7802734375,9999.7802734375,47.2678122577069,5.27239449642587,7.48895931243896,27,1,0,0,1,0.285720825195313,39.5894432067871,2,1,1,153.416595458984,0,153.341827392578,,,,,,,,,,,,,,,,,,,,,,,,,,,,,,,,,
,3832417253.83086,156.059310913086,9999.7802734375,0.000568050323603442,4.23298278639636E-8,1,2,13.4005146026611,5.00285795946716,32.4199981987476,0.757463600290664,0.112531048646064,1,4.86442949816377E-6,,,,,,,,,,,,,,,,,,,,,156.010437011719,156.108184814453,9999.7802734375,9999.7802734375,47.2979049556973,5.27339775053486,7.49946308135986,27,1,0,0,1,0.284881591796875,40.0782012939453,2,1,1,156.108184814453,0,156.059310913086,,,,,,,,,,,,,,,,,,,,,,,,,,,,,,,,,
,3832417308.1613,158.730773925781,9999.7802734375,0.000557941024116167,5.56945044848321E-8,1,2,13.4005146026611,5.00279364157321,32.430000603199,0.74397210769283,0.110513695494766,1,4.76830787470754E-6,,,,,,,,,,,,,,,,,,,,,158.688949584961,158.772598266602,9999.7802734375,9999.7802734375,47.2787550569762,5.27349795985371,7.48720026016235,27,1,0,0,1,0.2764892578125,40.0782012939453,2,1,1,158.772598266602,0,158.730773925781,,,,,,,,,,,,,,,,,,,,,,,,,,,,,,,,,
,3832417364.74236,161.554588317871,9999.7802734375,0.000547798730988777,5.57092891329254E-8,1,2,13.4005146026611,5.00265296382488,32.4399992823601,0.730421606348252,0.108489299290152,1,4.67316772106739E-6,,,,,,,,,,,,,,,,,,,,,161.4970703125,161.612106323242,9999.7802734375,9999.7802734375,47.3096293834858,5.27434320207393,7.50735092163086,27,1,0,0,1,0.284805297851562,39.5894432067871,2,1,1,161.612106323242,0,161.554588317871,,,,,,,,,,,,,,,,,,,,,,,,,,,,,,,,,
,3832417421.3694,164.394172668457,9999.7802734375,0.000537950902983788,7.41188175955477E-8,1,2,13.4005146026611,5.00270852665744,32.4500016868114,0.71730161970656,0.106540809702338,1,4.58931776252738E-6,,,,,,,,,,,,,,,,,,,,,164.326202392578,164.462142944336,9999.7802734375,9999.7802734375,47.3600444229762,5.27422618439516,7.51126146316528,27,1,0,0,1,0.284805297851562,40.0782012939453,2,1,1,164.462142944336,0,164.394172668457,,,,,,,,,,,,,,,,,,,,,,,,,,,,,,,,,
,3832417477.9129,167.203643798828,9999.7802734375,0.000528523017523723,7.13988268316862E-8,1,2,13.4005146026611,5.00272776900048,32.4600003659725,0.704747611204073,0.104578420621095,1,4.43716165152151E-6,,,,,,,,,,,,,,,,,,,,,167.181549072266,167.225738525391,9999.7802734375,9999.7802734375,47.3330782390627,5.27316757720189,7.51734018325806,25,1,64,0,0,0.285415649414062,40.0782012939453,2,1,1,167.225738525391,0,167.203643798828,,,,,,,,,,,,,,,,,,,,,,,,,,,,,,,,,
,3832417534.18545,170.019493103027,9999.7802734375,0.000519444242010675,5.45518094720452E-8,1,2,13.4005146026611,5.00275980882323,32.4600003659725,0.692645645815434,0.102798195167222,1,4.37239027330817E-6,,,,,,,,,,,,,,,,,,,,,169.99397277832,170.045013427734,9999.7802734375,9999.7802734375,47.3424577812935,5.27405336706469,7.52744626998901,27,1,0,0,1,0.285110473632813,40.0782012939453,2,1,1,170.045013427734,0,170.019493103027,,,,,,,,,,,,,,,,,,,,,,,,,,,,,,,,,
,3832417590.22272,172.803169250488,9999.7802734375,0.00051050406794165,6.80766271770136E-8,1,2,13.4005146026611,5.00288835864547,32.4699990451336,0.680750221405994,0.101019644258036,1,4.28752010087883E-6,,,,,,,,,,,,,,,,,,,,,172.757308959961,172.849029541016,9999.7802734375,9999.7802734375,47.3748953648415,5.27372346157061,7.54628801345825,27,1,0,0,1,0.285491943359375,40.0782012939453,2,1,1,172.849029541016,0,172.803169250488,,,,,,,,,,,,,,,,,,,,,,,,,,,,,,,,,
,3832417646.62928,175.61555480957,9999.7802734375,0.000501879044987106,2.36728342591279E-8,1,2,13.4005146026611,5.00293088793146,32.480001449585,0.669253852208996,0.0993340996907922,1,4.23009134160182E-6,,,,,,,,,,,,,,,,,,,,,175.568054199219,175.663055419922,9999.7802734375,9999.7802734375,47.2611684152935,5.27341526343433,7.54851627349854,27,1,0,0,1,0.283126831054687,39.5894432067871,2,1,1,175.663055419922,0,175.61555480957,,,,,,,,,,,,,,,,,,,,,,,,,,,,,,,,,
,3832417703.10649,178.455345153809,9999.7802734375,0.000493447048833099,5.57866427850758E-8,1,2,13.4005146026611,5.0030186079572,32.490000128746,0.658035645775224,0.0975956992641846,1,4.10520944159593E-6,,,,,,,,,,,,,,,,,,,,,178.407119750977,178.503570556641,9999.7802734375,9999.7802734375,47.2428001450915,5.27336675574603,7.55969524383545,27,1,0,0,1,0.281906127929687,40.0782012939453,2,1,1,178.503570556641,0,178.455345153809,,,,,,,,,,,,,,,,,,,,,,,,,,,,,,,,,
,3832417757.45339,181.173194885254,9999.7802734375,0.000485645730008314,4.792797635124E-8,1,2,13.4005146026611,5.00308199799948,32.4999988079071,0.647643769579533,0.096051986847957,1,4.03850543214633E-6,,,,,,,,,,,,,,,,,,,,,181.130706787109,181.215682983398,9999.7802734375,9999.7802734375,47.4929212712454,5.27344850524184,7.55328369140625,27,1,0,0,1,0.278701782226562,39.5894432067871,2,1,1,181.215682983398,0,181.173194885254,,,,,,,,,,,,,,,,,,,,,,,,,,,,,,,,,
,3832417813.84989,183.970802307129,9999.7802734375,0.000477711786651825,6.96571291434834E-8,1,2,13.4005146026611,5.00292147266493,32.5199998915195,0.6370356063445,0.0944765871250634,1,3.97098483780561E-6,,,,,,,,,,,,,,,,,,,,,183.916213989258,184.025390625,9999.7802734375,9999.7802734375,47.3795851359569,5.27402950344408,7.57568407058716,27,1,0,0,1,0.282745361328125,39.5894432067871,2,1,1,184.025390625,0,183.970802307129,,,,,,,,,,,,,,,,,,,,,,,,,,,,,,,,,
,3832417868.30305,186.650199890137,9999.7802734375,0.000470286255708103,4.26942448446864E-8,1,2,13.4005146026611,5.00315651526896,32.5299985706806,0.627181040147692,0.0929626747099385,1,3.87079972519253E-6,,,,,,,,,,,,,,,,,,,,,186.596527099609,186.703872680664,9999.7802734375,9999.7802734375,47.3729412935435,5.27348490191195,7.58308982849121,27,1,0,0,1,0.28350830078125,39.5894432067871,2,1,1,186.703872680664,0,186.650199890137,,,,,,,,,,,,,,,,,,,,,,,,,,,,,,,,,
,3832417924.796,189.490547180176,9999.7802734375,0.000462849960621875,5.7330481863406E-8,1,2,13.4005146026611,5.00323021272834,32.540000975132,0.617272934968398,0.0915187781834155,1,3.8277267926094E-6,,,,,,,,,,,,,,,,,,,,,189.444625854492,189.536468505859,9999.7802734375,9999.7802734375,47.4092870196877,5.2733007542452,7.58005237579346,26,1,64,0,0,0.283660888671875,40.0782012939453,2,1,1,189.536468505859,0,189.490547180176,,,,,,,,,,,,,,,,,,,,,,,,,,,,,,,,,
,3832417981.1494,192.288711547852,9999.7802734375,0.000455526748093167,4.55950170075997E-8,1,2,13.4005146026611,5.00332222375801,32.5499996542931,0.607500402119764,0.0902255376082934,1,3.88138125655249E-6,,,,,,,,,,,,,,,,,,,,,192.23210144043,192.345321655273,9999.7802734375,9999.7802734375,47.511680355707,5.27301225846827,7.59295082092285,27,1,0,0,1,0.28167724609375,40.0782012939453,2,1,1,192.345321655273,0,192.288711547852,,,,,,,,,,,,,,,,,,,,,,,,,,,,,,,,,
,3832418037.71458,195.124526977539,9999.7802734375,0.000448504826399758,5.482177316455E-8,1,2,13.4005146026611,5.00333866055762,32.5700007379055,0.598154532303559,0.0887204687279121,1,3.735686845471E-6,,,,,,,,,,,,,,,,,,,,,195.063659667969,195.185394287109,9999.7802734375,9999.7802734375,47.3651250083512,5.27255618990315,7.60333824157715,27,1,0,0,1,0.276718139648438,40.0782012939453,2,1,1,195.185394287109,0,195.124526977539,,,,,,,,,,,,,,,,,,,,,,,,,,,,,,,,,
,3832418093.98809,197.925849914551,9999.7802734375,0.000441673297352001,4.24101759052842E-8,1,2,13.4005146026611,5.0034097578555,32.5799994170666,0.589068608999762,0.0872736176492081,1,3.60600624458353E-6,,,,,,,,,,,,,,,,,,,,,197.876617431641,197.975082397461,9999.7802734375,9999.7802734375,47.3303425392454,5.2727624346773,7.61419868469238,27,1,0,0,1,0.279693603515625,40.0782012939453,2,1,1,197.975082397461,0,197.925849914551,,,,,,,,,,,,,,,,,,,,,,,,,,,,,,,,,
,3832418150.58823,200.738502502441,9999.7802734375,0.00043496001522571,3.57178581023304E-8,1,2,13.4005146026611,5.0033441753,32.5799994170666,0.580103956602802,0.0859499137037445,1,3.55446612844161E-6,,,,,,,,,,,,,,,,,,,,,200.705963134766,200.771041870117,9999.7802734375,9999.7802734375,47.4085053911685,5.27234917870237,7.62045240402222,27,1,0,0,1,0.283126831054687,40.0782012939453,2,1,1,200.771041870117,0,200.738502502441,,,,,,,,,,,,,,,,,,,,,,,,,,,,,,,,,
,3832418207.42477,203.552543640137,9999.7802734375,0.000428438098619722,4.36479240116271E-8,1,2,13.4005146026611,5.0034101417765,32.600000500679,0.57141220789569,0.0846899140728319,1,3.52156372175367E-6,,,,,,,,,,,,,,,,,,,,,203.549377441406,203.555709838867,9999.7802734375,9999.7802734375,47.3526189520435,5.27215643072078,7.63779497146606,25,1,64,0,0,0.277099609375,40.0782012939453,2,1,1,203.555709838867,0,203.552543640137,,,,,,,,,,,,,,,,,,,,,,,,,,,,,,,,,
,3832418262.43473,206.33617401123,9999.7802734375,0.00042208277509028,3.62792343455294E-8,1,2,13.4005146026611,5.00333877352574,32.6099991798401,0.562911202882098,0.0835311599741055,1,3.54357510372483E-6,,,,,,,,,,,,,,,,,,,,,206.252853393555,206.419494628906,9999.7802734375,9999.7802734375,47.3659066368704,5.27268905044204,7.63024711608887,27,1,0,0,1,0.280685424804687,40.0782012939453,2,1,1,206.419494628906,0,206.33617401123,,,,,,,,,,,,,,,,,,,,,,,,,,,,,,,,,
,3832418317.55539,209.050682067871,9999.7802734375,0.000416119859020461,5.56033587754153E-8,1,2,13.4005146026611,5.00336951372759,32.6200015842915,0.554984715630354,0.0821994495363949,1,3.37943026159245E-6,,,,,,,,,,,,,,,,,,,,,209.009643554687,209.091720581055,9999.7802734375,9999.7802734375,47.3940452635627,5.27311650720103,7.64364671707153,27,1,0,0,1,0.280685424804687,39.5894432067871,2,1,1,209.091720581055,0,209.050682067871,,,,,,,,,,,,,,,,,,,,,,,,,,,,,,,,,
,3832418373.56857,211.863243103027,9999.7802734375,0.000410019942457539,3.88739570521833E-8,1,2,13.4005146026611,5.00345096641129,32.6300002634525,0.54684168203947,0.0811369680948426,1,3.43524859124766E-6,,,,,,,,,,,,,,,,,,,,,211.794860839844,211.931625366211,9999.7802734375,9999.7802734375,47.3592627944569,5.2720526297101,7.64686441421509,27,1,0,0,1,0.28045654296875,40.0782012939453,2,1,1,211.931625366211,0,211.863243103027,,,,,,,,,,,,,,,,,,,,,,,,,,,,,,,,,
,3832418428.38169,214.583381652832,9999.7802734375,0.000404334904513032,2.89694984779218E-8,1,2,13.4005146026611,5.00346990827547,32.650001347065,0.539285391374434,0.079847720714249,1,3.26429002434716E-6,,,,,,,,,,,,,,,,,,,,,214.536911010742,214.629852294922,9999.7802734375,9999.7802734375,47.3721596650242,5.27273930863794,7.65243721008301,27,1,0,0,1,0.279922485351562,40.0782012939453,2,1,1,214.629852294922,0,214.583381652832,,,,,,,,,,,,,,,,,,,,,,,,,,,,,,,,,
,3832418486.81905,217.492973327637,9999.7802734375,0.000398456142858646,4.53588723530023E-8,1,2,13.4005146026611,5.00356238003292,32.660000026226,0.531459213941084,0.0786799142263892,1,3.21019207087975E-6,,,,,,,,,,,,,,,,,,,,,217.44938659668,217.536560058594,9999.7802734375,9999.7802734375,47.2959508843992,5.2714383098537,7.66812753677368,27,1,0,0,1,0.280990600585938,40.0782012939453,2,1,1,217.536560058594,0,217.492973327637,,,,,,,,,,,,,,,,,,,,,,,,,,,,,,,,,
,3832418543.23764,220.308441162109,9999.7802734375,0.000392794338744592,3.50305494676643E-8,1,2,13.4005146026611,5.00357344008629,32.6800011098385,0.523892688067498,0.0776795808872006,1,3.25251445873843E-6,,,,,,,,,,,,,,,,,,,,,220.247161865234,220.369720458984,9999.7802734375,9999.7802734375,47.4116319052454,5.27132518107526,7.66888666152954,27,1,0,0,1,0.27984619140625,40.0782012939453,2,1,1,220.369720458984,0,220.308441162109,,,,,,,,,,,,,,,,,,,,,,,,,,,,,,,,,
,3832418600.17461,223.130493164062,9999.7802734375,0.000387276318686955,4.14264870676845E-8,1,2,13.4005146026611,5.00345590480852,32.6899997889996,0.516512375046558,0.0766145519791359,1,3.22830453268962E-6,,,,,,,,,,,,,,,,,,,,,223.086868286133,223.174118041992,9999.7802734375,9999.7802734375,47.4053788770916,5.27058535508998,7.6688232421875,26,1,64,0,0,0.280838012695313,39.5894432067871,2,1,1,223.174118041992,0,223.130493164062,,,,,,,,,,,,,,,,,,,,,,,,,,,,,,,,,
,3832418656.15145,225.969825744629,9999.7802734375,0.0003818910249396,3.2382800812618E-8,1,2,13.4005146026611,5.00343411469171,32.6999984681606,0.509352410961491,0.0753666191852082,1,3.04702365781537E-6,,,,,,,,,,,,,,,,,,,,,225.932083129883,226.007568359375,9999.7802734375,9999.7802734375,47.3475383666685,5.27251666443989,7.67417001724243,27,1,0,0,1,0.281219482421875,39.5894432067871,2,1,1,226.007568359375,0,225.969825744629,,,,,,,,,,,,,,,,,,,,,,,,,,,,,,,,,
,3832418713.71852,228.846397399902,9999.7802734375,0.000376415232883506,4.40928496786167E-8,1,2,13.4005146026611,5.00351684912641,32.710000872612,0.502060493480285,0.0742866488718203,1,3.00258689405619E-6,,,,,,,,,,,,,,,,,,,,,228.751373291016,228.941421508789,9999.7802734375,9999.7802734375,47.4167124906204,5.27107686560459,7.6898455619812,27,1,0,0,1,0.280990600585938,39.5894432067871,2,1,1,228.941421508789,0,228.846397399902,,,,,,,,,,,,,,,,,,,,,,,,,,,,,,,,,
,3832418770.89174,231.661575317383,9999.7802734375,0.000371237724877785,3.477247682244E-8,1,2,13.4005146026611,5.00352917534567,32.7199995517731,0.49515524932894,0.0732735536351096,1,2.96761837536811E-6,,,,,,,,,,,,,,,,,,,,,231.610778808594,231.712371826172,9999.7802734375,9999.7802734375,47.36629745113,5.27177464076444,7.698646068573,27,1,0,0,1,0.281295776367187,40.0782012939453,2,1,1,231.712371826172,0,231.661575317383,,,,,,,,,,,,,,,,,,,,,,,,,,,,,,,,,
,3832418827.32642,234.506134033203,9999.7802734375,0.000366380302817939,3.5863267714443E-8,1,2,13.4005146026611,5.00362537148759,32.7400006353855,0.488693913047574,0.0722836715515441,1,2.90404312463739E-6,,,,,,,,,,,,,,,,,,,,,234.446487426758,234.565780639648,9999.7802734375,9999.7802734375,47.3659066368704,5.2711140400294,7.71269035339356,27,1,0,0,1,0.280990600585938,40.0782012939453,2,1,1,234.565780639648,0,234.506134033203,,,,,,,,,,,,,,,,,,,,,,,,,,,,,,,,,
,3832418884.12409,237.310920715332,9999.7802734375,0.000361431899385278,6.86603895291201E-8,1,2,13.4005146026611,5.00356469690736,32.760001718998,0.482096697932267,0.0712262787409449,1,2.80495935773706E-6,,,,,,,,,,,,,,,,,,,,,237.275604248047,237.346237182617,9999.7802734375,9999.7802734375,47.3827116500339,5.2711315306268,7.70900821685791,25,1,64,0,0,0.282058715820313,40.0782012939453,2,1,1,237.346237182617,0,237.310920715332,,,,,,,,,,,,,,,,,,,,,,,,,,,,,,,,,
,3832418942.32629,240.231918334961,9999.7802734375,0.000356481061931472,4.81045897028425E-8,1,2,13.4005146026611,5.00357833960076,32.770000398159,0.475483464811585,0.0703318664471129,1,2.82717680777638E-6,,,,,,,,,,,,,,,,,,,,,240.193313598633,240.270523071289,9999.7802734375,9999.7802734375,47.3088477549665,5.2711606424866,7.72901487350464,27,1,0,0,1,0.279922485351562,40.0782012939453,2,1,1,240.270523071289,0,240.231918334961,,,,,,,,,,,,,,,,,,,,,,,,,,,,,,,,,
,3832418998.86574,243.040374755859,9999.7802734375,0.000351759231181555,3.91015877178184E-8,1,2,13.4005146026611,5.00349645328711,32.7900014817715,0.469175822579683,0.0693918636635315,1,2.78459413789458E-6,,,,,,,,,,,,,,,,,,,,,243.008178710938,243.072570800781,9999.7802734375,9999.7802734375,47.3678607081685,5.27199257044103,7.75276756286621,27,1,0,0,1,0.28045654296875,40.0782012939453,2,1,1,243.072570800781,0,243.040374755859,,,,,,,,,,,,,,,,,,,,,,,,,,,,,,,,,
,3832419054.9809,245.824851989746,9999.7802734375,0.000347273355282931,4.82793277145364E-8,1,2,13.4005146026611,5.00346275553407,32.8000001609325,0.463198142229993,0.0684359238979594,1,2.69637753485499E-6,,,,,,,,,,,,,,,,,,,,,245.769805908203,245.879898071289,9999.7802734375,9999.7802734375,47.3862289783704,5.27244595666116,7.77466011047363,27,1,0,0,1,0.27862548828125,40.0782012939453,2,1,1,245.879898071289,0,245.824851989746,,,,,,,,,,,,,,,,,,,,,,,,,,,,,,,,,
,3832419109.69157,248.564659118652,9999.7802734375,0.000342899239646619,4.52556025104526E-8,1,2,13.4005146026611,5.00346245633394,32.8099988400936,0.457348797388746,0.0676815623145223,1,2.74302484657498E-6,,,,,,,,,,,,,,,,,,,,,248.534622192383,248.594696044922,9999.7802734375,9999.7802734375,47.3491016237069,5.27098250381924,7.78883790969849,27,1,0,0,1,0.276870727539062,40.0782012939453,2,1,1,248.594696044922,0,248.564659118652,,,,,,,,,,,,,,,,,,,,,,,,,,,,,,,,,
,3832419165.79348,251.338203430176,9999.7802734375,0.000338521680393613,4.5310460933991E-8,1,2,13.4005146026611,5.00344349585199,32.820001244545,0.451521978419597,0.0667157587400196,1,2.63205623216656E-6,,,,,,,,,,,,,,,,,,,,,251.280853271484,251.395553588867,9999.7802734375,9999.7802734375,47.4038156200531,5.27219521427144,7.82129144668579,27,1,0,0,1,0.2825927734375,40.0782012939453,2,1,1,251.395553588867,0,251.338203430176,,,,,,,,,,,,,,,,,,,,,,,,,,,,,,,,,
,3832419224.23167,254.306488037109,9999.7802734375,0.000334108956043685,2.99847068021359E-8,1,2,13.4005146026611,5.00345317620788,32.8399986028671,0.445632121011574,0.0658843382673322,1,2.6262532577466E-6,,,,,,,,,,,,,,,,,,,,,254.259780883789,254.35319519043,9999.7802734375,9999.7802734375,47.4366440178608,5.27173258998908,7.85088539123535,27,1,0,0,1,0.279464721679687,40.0782012939453,2,1,1,254.35319519043,0,254.306488037109,,,,,,,,,,,,,,,,,,,,,,,,,,,,,,,,,
,3832419280.768,257.136077880859,9999.7802734375,0.000329821027187669,2.60338346811492E-8,1,2,13.4005146026611,5.00337483258375,32.8500010073185,0.439900054615597,0.0650619589300055,1,2.61094815846621E-6,,,,,,,,,,,,,,,,,,,,,257.088958740234,257.183197021484,9999.7802734375,9999.7802734375,47.5023008134762,5.27217215016169,7.8898754119873,27,1,0,0,1,0.280914306640625,40.0782012939453,2,1,1,257.183197021484,0,257.136077880859,,,,,,,,,,,,,,,,,,,,,,,,,,,,,,,,,
,3832419337.33476,259.948913574219,9999.7802734375,0.000325820218112611,5.02105089678244E-8,1,2,13.4005146026611,5.00348499301518,32.880000770092,0.434582448241627,0.0642360596072309,1,2.55035544393465E-6,,,,,,,,,,,,,,,,,,,,,259.885345458984,260.012481689453,9999.7802734375,9999.7802734375,47.35613628038,5.27164002444725,7.8365330696106,27,1,0,0,1,0.286026000976562,40.0782012939453,2,1,1,260.012481689453,0,259.948913574219,,,,,,,,,,,,,,,,,,,,,,,,,,,,,,,,,
,3832419393.62509,262.735809326172,9999.7802734375,0.000321866101310442,3.12304175582416E-8,1,2,13.4005146026611,5.00336658588161,32.8899994492531,0.42928935250014,0.0634913146289628,1,2.54701839476234E-6,,,,,,,,,,,,,,,,,,,,,262.698211669922,262.773406982422,9999.7802734375,9999.7802734375,47.4167124906204,5.27198071046609,7.81960773468018,27,1,0,0,1,0.280914306640625,40.0782012939453,2,1,1,262.773406982422,0,262.735809326172,,,,,,,,,,,,,,,,,,,,,,,,,,,,,,,,,
,3832419448.18863,265.449569702148,9999.7802734375,0.000318024817483284,2.08025939341994E-8,1,2,13.4005146026611,5.00345294863709,32.9100005328655,0.424182296630085,0.0626903915043681,1,2.48316507211527E-6,,,,,,,,,,,,,,,,,,,,,265.38671875,265.512420654297,9999.7802734375,9999.7802734375,47.3928728207839,5.27247688349145,7.81986331939697,27,1,0,0,1,0.28228759765625,40.0782012939453,2,1,1,265.512420654297,0,265.449569702148,,,,,,,,,,,,,,,,,,,,,,,,,,,,,,,,,
,3832419506.27217,268.345504760742,9999.7802734375,0.000314036397474199,3.25591658482855E-8,1,2,13.4005146026611,5.00343757055922,32.930001616478,0.41885683500954,0.0619320671739282,1,2.47310533309814E-6,,,,,,,,,,,,,,,,,,,,,268.298767089844,268.392242431641,9999.7802734375,9999.7802734375,47.3389404529569,5.27264838876804,7.81935310363769,27,1,0,0,1,0.281524658203125,40.0782012939453,2,1,1,268.392242431641,0,268.345504760742,,,,,,,,,,,,,,,,,,,,,,,,,,,,,,,,,
,3832419562.71195,271.172180175781,9999.7802734375,0.000310127405448182,4.45206870456379E-8,1,2,13.4005146026611,5.00337233544842,32.930001616478,0.413638681285984,0.0611387866705543,1,2.42637969902952E-6,,,,,,,,,,,,,,,,,,,,,271.11865234375,271.225708007813,9999.7802734375,9999.7802734375,47.42726447563,5.27245651238151,7.83217000961304,27,1,0,0,1,0.2801513671875,40.0782012939453,2,1,1,271.225708007813,0,271.172180175781,,,,,,,,,,,,,,,,,,,,,,,,,,,,,,,,,
,3832419621.21285,274.106262207031,9999.7802734375,0.000305990859755122,4.58494323907997E-8,1,2,13.4005146026611,5.0034168679082,32.9499989748001,0.408114395689895,0.0604102446136531,1,2.4585777340795E-6,,,,,,,,,,,,,,,,,,,,,274.051361083984,274.161163330078,9999.7802734375,9999.7802734375,47.4190573761781,5.27299105924181,7.84844064712524,27,1,0,0,1,0.283126831054687,40.0782012939453,2,1,1,274.161163330078,0,274.106262207031,,,,,,,,,,,,,,,,,,,,,,,,,,,,,,,,,
,3832419677.77525,276.917755126953,9999.7802734375,0.000302361617206149,3.62304998841252E-8,1,2,13.4005146026611,5.00343504450886,32.9600013792515,0.403294467081841,0.059561306714776,1,2.33001212888007E-6,,,,,,,,,,,,,,,,,,,,,276.850830078125,276.984680175781,9999.7802734375,9999.7802734375,47.483150914755,5.27239435716687,7.87547254562378,27,1,0,0,1,0.27679443359375,40.0782012939453,2,1,1,276.984680175781,0,276.917755126953,,,,,,,,,,,,,,,,,,,,,,,,,,,,,,,,,
,3832419734.06408,279.716293334961,9999.7802734375,0.000298658061145412,3.30405086596434E-8,1,2,13.4005146026611,5.0033866789546,32.990001142025,0.398339011737618,0.0589048497849681,1,2.35679845645941E-6,,,,,,,,,,,,,,,,,,,,,279.674499511719,279.758087158203,9999.7802734375,9999.7802734375,47.4135859765435,5.27275083851032,7.91499757766724,27,1,0,0,1,0.281906127929687,40.0782012939453,2,1,1,279.758087158203,0,279.716293334961,,,,,,,,,,,,,,,,,,,,,,,,,,,,,,,,,
,3832419788.61313,282.451889038086,9999.7802734375,0.000295134751155083,3.42156350196147E-8,1,2,13.4005146026611,5.00350482862236,32.9999998211861,0.393645705576697,0.0582601828759694,1,2.36521312007921E-6,,,,,,,,,,,,,,,,,,,,,282.397125244141,282.506652832031,9999.7802734375,9999.7802734375,47.4589204306589,5.27190283877392,7.96857833862305,27,1,0,0,1,0.28045654296875,40.0782012939453,2,1,1,282.506652832031,0,282.451889038086,,,,,,,,,,,,,,,,,,,,,,,,,,,,,,,,,
,3832419845.19993,285.237335205078,9999.7802734375,0.000291589060419105,4.63323626499183E-8,1,2,13.4005146026611,5.00344224725769,33.0200009047985,0.388921263773088,0.0574777803510862,1,2.27576742751456E-6,,,,,,,,,,,,,,,,,,,,,285.217010498047,285.257659912109,9999.7802734375,9999.7802734375,47.4124135337646,5.27144596759569,8.03609561920166,26,1,64,0,0,0.282135009765625,40.0782012939453,2,1,1,285.257659912109,0,285.237335205078,,,,,,,,,,,,,,,,,,,,,,,,,,,,,,,,,
,3832419902.60267,288.021591186523,9999.7802734375,0.00028805788574652,3.87884207975159E-8,1,2,13.4005146026611,5.00345680500055,33.0399982631207,0.384205144159327,0.056837520455793,1,2.28982957190771E-6,,,,,,,,,,,,,,,,,,,,,287.954437255859,288.088745117187,9999.7802734375,9999.7802734375,47.371378036505,5.27170750696485,8.11470890045166,27,1,0,0,1,0.2825927734375,40.0782012939453,2,1,1,288.088745117187,0,288.021591186523,,,,,,,,,,,,,,,,,,,,,,,,,,,,,,,,,
,3832419957.59767,290.739273071289,9999.7802734375,0.000284674398477509,3.05204882605315E-8,1,2,13.4005146026611,5.00337992500852,33.050000667572,0.379696735810488,0.0560801086885982,1,2.19655892387529E-6,,,,,,,,,,,,,,,,,,,,,290.687835693359,290.790710449219,9999.7802734375,9999.7802734375,47.4452419315723,5.27256639074492,8.22669887542725,27,1,0,0,1,0.27740478515625,40.0782012939453,2,1,1,290.790710449219,0,290.739273071289,,,,,,,,,,,,,,,,,,,,,,,,,,,,,,,,,
,3832420014.0709,293.670257568359,9999.7802734375,0.000281089219640904,6.1205703682749E-8,1,2,13.4005146026611,5.00355382440979,33.0700017511845,0.374917888010976,0.0554822226526326,1,2.24809292663537E-6,,,,,,,,,,,,,,,,,,,,,293.616394042969,293.72412109375,9999.7802734375,9999.7802734375,47.4010799202358,5.27162453344824,8.25981616973877,27,1,0,0,1,0.279693603515625,40.0782012939453,2,1,1,293.72412109375,0,293.670257568359,,,,,,,,,,,,,,,,,,,,,,,,,,,,,,,,,
,3832420070.44124,296.556350708008,9999.7802734375,0.000277591254656564,3.5552733590779E-8,1,2,13.4005146026611,5.00349743349756,33.0899991095066,0.370244478370368,0.0548059751919065,1,2.2313774738418E-6,,,,,,,,,,,,,,,,,,,,,296.5087890625,296.603912353516,9999.7802734375,9999.7802734375,47.3752861791012,5.27110388913354,8.25801372528076,27,1,0,0,1,0.279998779296875,40.0782012939453,2,1,1,296.603912353516,0,296.556350708008,,,,,,,,,,,,,,,,,,,,,,,,,,,,,,,,,
,3832420129.15082,299.359527587891,9999.7802734375,0.000274367023753015,3.27759713105579E-8,1,2,13.4005146026611,5.00350058516897,33.100001513958,0.365948917755816,0.0541370861700337,1,2.18122333347518E-6,,,,,,,,,,,,,,,,,,,,,299.333343505859,299.385711669922,9999.7802734375,9999.7802734375,47.4307818039666,5.27119789194267,8.23971462249756,27,1,0,0,1,0.273361206054687,40.0782012939453,6,1,1,299.385711669922,0,299.359527587891,,,,,,,,,,,,,,,,,,,,,,,,,,,,,,,,,
,3832420187.57034,299.868911743164,9999.7802734375,0.000273920005806405,2.02236998470919E-8,1,2,13.4005146026611,5.00344884366924,33.100001513958,0.365342681091291,0.0540827250161537,1,2.20358761103492E-6,,,,,,,,,,,,,,,,,,,,,299.866851806641,299.870971679687,9999.7802734375,9999.7802734375,47.5093354701493,5.27196747815277,8.23636245727539,27,1,0,0,1,0.279464721679687,40.0782012939453,5,1,1,299.870971679687,0,299.868911743164,,,,,,,,,,,,,,,,,,,,,,,,,,,,,,,,,
,3832420197.36508,299.893844604492,9999.7802734375,0.000273939141169431,2.54350485091867E-8,1,2,13.4005146026611,5.00345053045218,33.100001513958,0.365379938778875,0.0540037993286651,1,2.14178451180649E-6,,,,,,,,,,,,,,,,,,,,,299.89208984375,299.895599365234,9999.7802734375,9999.7802734375,47.3799759502165,5.27187967216026,8.22306823730469,27,1,0,0,1,0.282516479492187,40.0782012939453,1,1,1,299.895599365234,0,299.893844604492,,,,,,,,,,,,,,,,,,,,,,,,,,,,,,,,,