File: SI Fig S11-13 SQUID all/Michaela_HO_Hyst300K.dat
[Header]
; MPMS3 Data File (default extension .dat)
; Copyright (c) 2007, Quantum Design, Inc. All rights reserved.
TITLE,
FILEOPENTIME,3834051730.97186,06/28/2021,2:23 pm
BYAPP,MPMS3 w/ AC,1.0,1.1
INFO,MPMS3 Measurement Release 1.1.16 Build 424, MultiVu Release 2.3.4.19,APPNAME
INFO,Linear Motor Servo Controller,MOTOR_MODULE_NAME
INFO,3101-100 E1,MOTOR_HW_VERSION
INFO,MMC211,MOTOR_SERIAL_NUMBER
INFO,01.04.28,MOTOR_SOFTWARE_VERSION
INFO,Quantum Design Squid Module,SQUID_MODULE_NAME
INFO,3101-501 B0,SQUID_HW_VERSION
INFO,SQM059,SQUID_SERIAL_NUMBER
INFO,01.03.04,SQUID_SOFTWARE_VERSION
INFO,SQUID AC,AC_MODULE_NAME
INFO,3101-401 F1,AC_HW_VERSION
INFO,SAC057,AC_SERIAL_NUMBER
INFO,SQUID AC 00.95.07,AC_SOFTWARE_VERSION
INFO,TCIXXX,COIL_SERIAL_NUMBER
INFO,0,MOMENT_UNITS
INFO,Michaela_HO,SAMPLE_MATERIAL
INFO,Michaela_HO,SAMPLE_COMMENT
INFO,1.06,SAMPLE_MASS
INFO,,SAMPLE_VOLUME
INFO,,SAMPLE_MOLECULAR_WEIGHT
INFO,,SAMPLE_SIZE
INFO,,SAMPLE_SHAPE
INFO,Straw,SAMPLE_HOLDER
INFO,Standard,SAMPLE_HOLDER_DETAIL
INFO,52.84,SAMPLE_OFFSET
DATATYPE,COMMENT,1
DATATYPE,TIME,2
STARTUPAXIS,X,2
STARTUPAXIS,Y1,5
FIELDGROUP, VSM,2,3,4,5,6,8,9,10,11,14,15
FIELDGROUP, DC, 2,3,4,14,56,57,58,59,60,61,62,63,64,65,66,67,68,69
FIELDGROUP, AC, 2,3,4,11,16,17,18,19,20,21,22,23,24,25,26,27,28,29,30
STARTUPGROUP, All
[Data]
Comment,Time Stamp (sec),Temperature (K),Magnetic Field (Oe),Moment (emu),M. Std. Err. (emu),Transport Action,Averaging Time (sec),Frequency (Hz),Peak Amplitude (mm),Center Position (mm),Lockin Signal' (V),Lockin Signal (V),Range,M. Quad. Signal (emu),AC Moment (emu),AC M. Std Err. (emu),AC Phase (deg),AC Phase Std. Err. (deg),AC Susceptibility (emu/Oe),AC Suscept. Std Err. (emu/Oe),AC X' (emu/Oe),AC X' Std Err. (emu/Oe),AC X'' (emu/Oe),AC X'' Std Err. (emu/Oe),AC Drive (Oe),AC Frequency (Hz),AC Averaging Time (sec),AC Cycles,AC Range,AC Measure Type,AC Signal' (V),AC Signal'' (V),AC Trim Coil Ratio,AC Trim Coil Phase,Min. Temperature (K),Max. Temperature (K),Min. Field (Oe),Max. Field (Oe),Mass (grams),Motor Lag (deg),Pressure (Torr),Measure Count,Measurement Number,SQUID Status (code),Motor Status (code),Measure Status (code),Motor Current (amps),Motor Temp. (C),Temp. Status (code),Field Status (code),Chamber Status (code),Chamber Temp (K),Redirection State,Average Temp (K),Rotation Angle (deg),Rotator state,DC Moment Fixed Ctr (emu),DC Moment Err Fixed Ctr (emu),DC Moment Free Ctr (emu),DC Moment Err Free Ctr (emu),DC Fixed Fit,DC Free Fit,DC Calculated Center (mm),DC Calculated Center Err (mm),DC Scan Length (mm),DC Scan Time (s),DC Number of Points,DC Squid Drift,DC Min V (V),DC Max V (V),DC Scans per Measure,Map 01,Map 02,Map 03,Map 04,Map 05,Map 06,Map 07,Map 08,Map 09,Map 10,Map 11,Map 12,Map 13,Map 14,Map 15,Map 16
,3834051754.62075,299.667541503906,0.311568170785904,-1.08230208013539E-7,1.10057079634503E-8,1,2,13.4005146026611,5.00558126744606,34.2799983918667,-0.000143625400298154,-2.71854454239996E-5,1,-5.21488779936916E-9,,,,,,,,,,,,,,,,,,,,,299.667541503906,299.667541503906,0.311568170785904,0.311568170785904,47.5210598979377,5.27363635995516,8.2561092376709,27,1,0,0,1,0.28350830078125,39.5894432067871,1,1,1,299.667541503906,0,299.667541503906,,,,,,,,,,,,,,,,,,,,,,,,,,,,,,,,,
,3834051783.03783,299.765106201172,1578.67858886719,9.6920062095559E-5,1.82415833403183E-8,1,2,13.4005146026611,5.00565258433738,34.2799983918667,0.129346130427222,0.0191441309902485,1,7.77232088642421E-7,,,,,,,,,,,,,,,,,,,,,299.765106201172,299.765106201172,1578.67858886719,1578.67858886719,47.5663943520531,5.27582885518564,9.15953350067139,27,1,0,0,1,0.276412963867187,40.0782012939453,1,1,1,299.765106201172,0,299.765106201172,,,,,,,,,,,,,,,,,,,,,,,,,,,,,,,,,
,3834051806.35526,299.864639282227,3683.99462890625,0.000225821257092591,4.2585004000195E-8,1,2,13.4005146026611,5.00563704565236,34.2799983918667,0.301331007897027,0.0448974943810023,1,2.02974615893571E-6,,,,,,,,,,,,,,,,,,,,,299.86181640625,299.867462158203,3683.99462890625,3683.99462890625,47.5468536390723,5.27574284878638,9.74842262268066,27,1,0,0,1,0.283889770507813,40.0782012939453,1,1,1,299.867462158203,0,299.864639282227,,,,,,,,,,,,,,,,,,,,,,,,,,,,,,,,,
,3834051828.24768,299.929046630859,5789.173828125,0.00035454971027894,5.32977966049109E-8,1,2,13.4005146026611,5.00563951277603,34.2799983918667,0.473108626545939,0.0704566083988888,1,3.16092694121059E-6,,,,,,,,,,,,,,,,,,,,,299.927062988281,299.931030273438,5789.173828125,5789.173828125,47.5363016540627,5.27693891557314,10.1587028503418,27,1,0,0,1,0.2740478515625,40.5669593811035,1,1,1,299.931030273438,0,299.929046630859,,,,,,,,,,,,,,,,,,,,,,,,,,,,,,,,,
,3834051853.73227,299.97395324707,7894.2275390625,0.000483432899612931,9.08572394078708E-8,1,2,13.4005146026611,5.00558246431874,34.2799983918667,0.645076696373491,0.0960862190740767,1,4.32438037486201E-6,,,,,,,,,,,,,,,,,,,,,299.972351074219,299.975555419922,7894.2275390625,7894.2275390625,47.4894039429089,5.27900778031834,10.5529470443726,27,1,0,0,1,0.28350830078125,40.5669593811035,1,1,1,299.975555419922,0,299.97395324707,,,,,,,,,,,,,,,,,,,,,,,,,,,,,,,,,
,3834051879.55088,299.998092651367,9999.7314453125,0.000612334419398924,5.27497242911125E-8,1,2,13.4005146026611,5.00561295251632,34.2799983918667,0.817114465434509,0.121499437048315,1,5.32172549387086E-6,,,,,,,,,,,,,,,,,,,,,299.997131347656,299.999053955078,9999.7314453125,9999.7314453125,47.5402097966589,5.2778607827627,10.8671846389771,27,1,0,0,1,0.27557373046875,40.5669593811035,1,1,1,299.999053955078,0,299.998092651367,,,,,,,,,,,,,,,,,,,,,,,,,,,,,,,,,
,3834051914.63357,300.009521484375,13332.9873046875,0.000815973659780937,6.33820968706928E-8,1,2,13.4005146026611,5.00560467351063,34.2799983918667,1.08875820015466,0.162585562277864,1,7.60077856262839E-6,,,,,,,,,,,,,,,,,,,,,300.009429931641,300.009613037109,13332.9873046875,13332.9873046875,47.5757738942839,5.27831831616198,11.2023372650146,27,1,0,0,1,0.282745361328125,40.5669593811035,1,1,1,300.009429931641,0,300.009521484375,,,,,,,,,,,,,,,,,,,,,,,,,,,,,,,,,
,3834051951.41672,300.012756347656,17777.37109375,0.00108753085924151,1.4642935345257E-7,1,2,13.4005146026611,5.00555643276814,34.2799983918667,1.45115344756749,0.216161547745588,1,9.73373046108106E-6,,,,,,,,,,,,,,,,,,,,,300.012756347656,300.012756347656,17777.37109375,17777.37109375,47.6113379919089,5.27928299980014,11.4786825180054,27,1,0,0,1,0.27587890625,40.5669593811035,1,1,1,300.012756347656,0,300.012756347656,,,,,,,,,,,,,,,,,,,,,,,,,,,,,,,,,
,3834051989.6315,300.007293701172,21999.6171875,0.0013452246159747,7.18062476672684E-8,1,2,13.4005146026611,5.00572756294207,34.2799983918667,1.79498342436853,0.268175036522952,1,1.26245965478481E-5,,,,,,,,,,,,,,,,,,,,,300.007293701172,300.007293701172,21999.6171875,21999.6171875,47.5312210686877,5.27883000321119,11.715371131897,27,1,0,0,1,0.275497436523438,40.5669593811035,1,1,1,300.007293701172,0,300.007293701172,,,,,,,,,,,,,,,,,,,,,,,,,,,,,,,,,
,3834052050.94504,299.998443603516,34999.72265625,0.00214005358137747,1.63020192313334E-7,1,2,13.4005146026611,5.00564247752959,34.2799983918667,2.85630808958619,0.420744630530651,10,1.56886227930731E-5,,,,,,,,,,,,,,,,,,,,,299.998443603516,299.998443603516,34999.72265625,34999.72265625,47.5023008134762,5.27932354342839,11.9972715377808,27,1,0,0,1,0.27984619140625,40.5669593811035,1,1,1,299.998443603516,0,299.998443603516,,,,,,,,,,,,,,,,,,,,,,,,,,,,,,,,,
,3834052105.98574,299.994491577148,58332.87890625,0.0035644129262695,4.6019027811894E-7,1,2,13.4005146026611,5.00582591276255,34.2799983918667,4.75726104825726,0.703415924177472,10,2.80767584741193E-5,,,,,,,,,,,,,,,,,,,,,299.994445800781,299.994537353516,58332.87890625,58332.87890625,47.450713331207,5.27671651309633,12.2026357650757,27,1,0,0,1,0.282669067382813,40.5669593811035,1,1,1,299.994445800781,0,299.994491577148,,,,,,,,,,,,,,,,,,,,,,,,,,,,,,,,,
,3834052162.84838,299.994415283203,58332.81640625,0.00356422347868314,4.29669688754487E-7,1,2,13.4005146026611,5.00596612672529,34.2799983918667,4.75741629111458,0.70178990435309,10,2.68661653434172E-5,,,,,,,,,,,,,,,,,,,,,299.994140625,299.994689941406,58332.81640625,58332.81640625,47.4131951622839,5.274805515652,12.3458003997803,27,1,0,0,1,0.2825927734375,40.5669593811035,1,1,1,299.994140625,0,299.994415283203,,,,,,,,,,,,,,,,,,,,,,,,,,,,,,,,,
,3834052217.07569,299.997467041016,34999.6015625,0.00213964670645467,3.02936749135826E-7,1,2,13.4005146026611,5.0059420576379,34.2799983918667,2.85592039622201,0.421259437738597,10,1.61050288215408E-5,,,,,,,,,,,,,,,,,,,,,299.997253417969,299.997680664063,34999.6015625,34999.6015625,47.5065997703319,5.27514609980369,12.4749002456665,27,1,0,0,1,0.287399291992187,40.5669593811035,1,1,1,299.997253417969,0,299.997467041016,,,,,,,,,,,,,,,,,,,,,,,,,,,,,,,,,
,3834052256.56322,299.99951171875,21999.705078125,0.00134434587584577,1.56331331522739E-7,1,2,13.4005146026611,5.00598279529793,34.2799983918667,1.79447908397295,0.264134108802712,10,9.70923955823199E-6,,,,,,,,,,,,,,,,,,,,,299.999237060547,299.999786376953,21999.705078125,21999.705078125,47.5992227498608,5.27455667967127,12.5469169616699,27,1,0,0,1,0.281600952148438,41.055721282959,1,1,1,299.999237060547,0,299.99951171875,,,,,,,,,,,,,,,,,,,,,,,,,,,,,,,,,
,3834052292.52729,300.001251220703,17777.544921875,0.00108600362583734,1.23626289635274E-7,1,2,13.4005146026611,5.00599534011217,34.2799983918667,1.44964993841103,0.213304788300979,10,7.78988199016235E-6,,,,,,,,,,,,,,,,,,,,,300.000183105469,300.002319335937,17777.544921875,17777.544921875,47.5534974814858,5.27605236311168,12.6088552474976,27,1,0,0,1,0.279006958007813,41.055721282959,1,1,1,300.000183105469,0,300.001251220703,,,,,,,,,,,,,,,,,,,,,,,,,,,,,,,,,
,3834052317.57557,300.000961303711,13333.048828125,0.000813984887076534,1.31457298202181E-7,1,2,13.4005146026611,5.00595687575325,34.2799983918667,1.08651614701821,0.160008684350558,10,5.93859546871044E-6,,,,,,,,,,,,,,,,,,,,,300.000122070313,300.001800537109,13333.048828125,13333.048828125,47.5738198229858,5.27644858938291,12.6368570327759,27,1,0,0,1,0.282211303710938,41.055721282959,1,1,1,300.000122070313,0,300.000961303711,,,,,,,,,,,,,,,,,,,,,,,,,,,,,,,,,
,3834052355.79422,300.002471923828,9999.85546875,0.000610059551772845,6.89438522743533E-8,1,2,13.4005146026611,5.00614988613342,34.2799983918667,0.814401306259953,0.119613433191768,10,4.2150435251383E-6,,,,,,,,,,,,,,,,,,,,,300.002471923828,300.002471923828,9999.85546875,9999.85546875,47.4788519578993,5.27484941155394,12.695837020874,27,1,0,0,1,0.278244018554687,41.055721282959,1,1,1,300.002471923828,0,300.002471923828,,,,,,,,,,,,,,,,,,,,,,,,,,,,,,,,,
,3834052382.52964,300.001480102539,7894.302734375,0.000481184170783518,5.78222051855201E-8,1,2,13.4005146026611,5.00610927658772,34.2799983918667,0.642245302985843,0.0951035364504087,1,3.89303847704942E-6,,,,,,,,,,,,,,,,,,,,,300.001434326172,300.001525878906,7894.302734375,7894.302734375,47.5945329787454,5.27397053898921,12.7297458648682,26,1,68,0,0,0.282058715820313,41.055721282959,1,1,1,300.001525878906,0,300.001480102539,,,,,,,,,,,,,,,,,,,,,,,,,,,,,,,,,
,3834052405.74137,300.001724243164,5789.173828125,0.000352426659498033,5.43339594067796E-8,1,2,13.4005146026611,5.00592581783004,34.2799983918667,0.47038803308471,0.0694994354451144,1,2.73729191273981E-6,,,,,,,,,,,,,,,,,,,,,300.001251220703,300.002197265625,5789.173828125,5789.173828125,47.6222807911781,5.27437949378958,12.7602729797363,25,1,68,0,0,0.281600952148438,41.055721282959,1,1,1,300.001251220703,0,300.001724243164,,,,,,,,,,,,,,,,,,,,,,,,,,,,,,,,,
,3834052428.79985,300.002868652344,3683.70776367188,0.000223571527802452,2.3893989635637E-8,1,2,13.4005146026611,5.00605819566393,34.2799983918667,0.298411557340643,0.044110470358281,1,1.75144477497148E-6,,,,,,,,,,,,,,,,,,,,,300.00244140625,300.003295898438,3683.70776367188,3683.70776367188,47.633614404707,5.27464314517059,12.7687711715698,27,1,0,0,1,0.285797119140625,41.055721282959,1,1,1,300.003295898438,0,300.002868652344,,,,,,,,,,,,,,,,,,,,,,,,,,,,,,,,,
,3834052454.23757,300.00163269043,1578.60388183594,9.49952564109882E-5,2.14338787968843E-8,1,2,13.4005146026611,5.00606634514049,34.2799983918667,0.126836073612631,0.0184485636540884,1,5.24191569853678E-7,,,,,,,,,,,,,,,,,,,,,300.001525878906,300.001739501953,1578.60388183594,1578.60388183594,47.5910156504089,5.27559400658819,12.7848691940308,27,1,0,0,1,0.29022216796875,41.055721282959,1,1,1,300.001525878906,0,300.00163269043,,,,,,,,,,,,,,,,,,,,,,,,,,,,,,,,,
,3834052477.44055,300.001174926758,-525.852294921875,-3.27205100245848E-5,2.65555526981146E-8,1,2,13.4005146026611,5.00606182198186,34.2799983918667,-0.0436493250853378,-0.00662981363103123,1,-3.86608060717756E-7,,,,,,,,,,,,,,,,,,,,,300.001068115234,300.001281738281,-525.852294921875,-525.852294921875,47.6582357030627,5.27604238528437,12.8105936050415,27,1,0,0,1,0.28228759765625,41.055721282959,1,1,1,300.001068115234,0,300.001174926758,,,,,,,,,,,,,,,,,,,,,,,,,,,,,,,,,
,3834052500.96425,299.825439453125,-2631.10595703125,-0.000160403934210078,1.42632314037744E-8,1,2,13.4005146026611,5.00597813510582,34.2799983918667,-0.214074669573232,-0.031785705743885,1,-1.36050151122986E-6,,,,,,,,,,,,,,,,,,,,,299.80908203125,299.841796875,-2631.10595703125,-2631.10595703125,47.4980018566204,5.2774808399022,12.8282136917114,27,1,0,0,1,0.274124145507813,41.055721282959,1,1,1,299.80908203125,0,299.825439453125,,,,,,,,,,,,,,,,,,,,,,,,,,,,,,,,,
,3834052526.44584,299.745864868164,-4736.52197265625,-0.000288967198853927,4.56264382348792E-8,1,2,13.4005146026611,5.00605320694511,34.2799983918667,-0.385638913890824,-0.0574336671504541,1,-2.57864453119843E-6,,,,,,,,,,,,,,,,,,,,,299.743896484375,299.747833251953,-4736.52197265625,-4736.52197265625,47.5867166935531,5.27580554142245,12.8460903167725,27,1,0,0,1,0.289840698242188,41.055721282959,1,1,1,299.747833251953,0,299.745864868164,,,,,,,,,,,,,,,,,,,,,,,,,,,,,,,,,
,3834052547.67042,299.808319091797,-6841.65087890625,-0.000417720875309648,4.56841257513407E-8,1,2,13.4005146026611,5.00606125730197,34.2799983918667,-0.557461216392706,-0.0830681575884995,1,-3.76043345314481E-6,,,,,,,,,,,,,,,,,,,,,299.80615234375,299.810485839844,-6841.65087890625,-6841.65087890625,47.5304394401685,5.27644718800074,12.8564529418945,26,1,68,0,0,0.290374755859375,41.055721282959,1,1,1,299.810485839844,0,299.808319091797,,,,,,,,,,,,,,,,,,,,,,,,,,,,,,,,,
,3834052582.20271,299.912536621094,-8947.140625,-0.000547269804831049,3.01659462012453E-8,1,2,13.4005146026611,5.00609274660075,34.2799983918667,-0.730369227743131,-0.108725816875304,1,-4.84776259318267E-6,,,,,,,,,,,,,,,,,,,,,299.912536621094,299.912536621094,-8947.140625,-8947.140625,47.552325038707,5.27548320907416,12.8700332641602,27,1,0,0,1,0.278472900390625,41.055721282959,1,1,1,299.912536621094,0,299.912536621094,,,,,,,,,,,,,,,,,,,,,,,,,,,,,,,,,
,3834052618.90146,299.981323242188,-11999.69921875,-0.000734040512516577,5.65317849501474E-8,1,2,13.4005146026611,5.00609060697279,34.2799983918667,-0.979622182094119,-0.145865986539571,1,-6.52809655491196E-6,,,,,,,,,,,,,,,,,,,,,299.981323242188,299.981323242188,-11999.69921875,-11999.69921875,47.58984320763,5.27539606601217,12.9160928726196,27,1,0,0,1,0.280990600585938,41.055721282959,1,1,1,299.981323242188,0,299.981323242188,,,,,,,,,,,,,,,,,,,,,,,,,,,,,,,,,
,3834052652.97878,300.015106201172,-14999.83984375,-0.000917270262344879,1.04348707371632E-7,1,2,13.4005146026611,5.00612447167886,34.2799983918667,-1.22420334358694,-0.182003281132116,1,-7.95169622810014E-6,,,,,,,,,,,,,,,,,,,,,300.015106201172,300.015106201172,-14999.83984375,-14999.83984375,47.5120711699666,5.27543872084179,12.9308595657349,27,1,0,0,1,0.290451049804687,41.055721282959,1,1,1,300.015106201172,0,300.015106201172,,,,,,,,,,,,,,,,,,,,,,,,,,,,,,,,,
,3834052678.89941,300.022521972656,-19999.599609375,-0.00122253123172358,1.51201396593173E-7,1,2,13.4005146026611,5.00612810473782,34.2799983918667,-1.63142803306079,-0.243881923905615,1,-1.15775914320399E-5,,,,,,,,,,,,,,,,,,,,,300.022003173828,300.023040771484,-19999.599609375,-19999.599609375,47.4401613461973,5.27571097067578,12.9429969787598,26,1,68,0,0,0.290374755859375,41.055721282959,1,1,1,300.022003173828,0,300.022521972656,,,,,,,,,,,,,,,,,,,,,,,,,,,,,,,,,
,3834052726.69748,300.036560058594,-25555.5078125,-0.00156189857901863,1.52229377667199E-7,1,2,13.4005146026611,5.00619674379343,34.2799983918667,-2.08441205602493,-0.311085162014988,1,-1.44152144148167E-5,,,,,,,,,,,,,,,,,,,,,300.036560058594,300.036560058594,-25555.5078125,-25555.5078125,47.521841526457,5.27638379386041,12.9779500961304,27,1,0,0,1,0.284957885742187,41.055721282959,1,1,1,300.036560058594,0,300.036560058594,,,,,,,,,,,,,,,,,,,,,,,,,,,,,,,,,
,3834052784.27624,300.010406494141,-43332.96484375,-0.0026478484901289,2.90968209722065E-7,1,2,13.4005146026611,5.00615338230181,34.2799983918667,-3.53428137421629,-0.522574109320843,10,-2.08495608556869E-5,,,,,,,,,,,,,,,,,,,,,300.009948730469,300.010864257812,-43332.96484375,-43332.96484375,47.4765070723416,5.27528279885919,12.9821872711182,27,1,0,0,1,0.286636352539062,41.055721282959,1,1,1,300.009948730469,0,300.010406494141,,,,,,,,,,,,,,,,,,,,,,,,,,,,,,,,,
,3834052830.684,299.999008178711,-61110.78515625,-0.00373226265843575,3.24243053827657E-7,1,2,13.4005146026611,5.00613647050384,34.2799983918667,-4.98156899050937,-0.737575862958222,10,-3.01272920967525E-5,,,,,,,,,,,,,,,,,,,,,299.998687744141,299.999328613281,-61110.78515625,-61110.78515625,47.3123650833031,5.2752640184584,12.9956226348877,27,1,0,0,1,0.282516479492187,41.055721282959,1,1,1,299.998687744141,0,299.999008178711,,,,,,,,,,,,,,,,,,,,,,,,,,,,,,,,,
,3834052877.11073,299.993179321289,-61110.72265625,-0.00373214627742696,5.81371003797901E-7,1,2,13.4005146026611,5.00611795278688,34.2799983918667,-4.98168474434619,-0.73543010547055,10,-2.85405306652038E-5,,,,,,,,,,,,,,,,,,,,,299.993041992188,299.993316650391,-61110.72265625,-61110.72265625,47.4245287758127,5.27486808260803,13.0069808959961,27,1,0,0,1,0.275115966796875,41.5444793701172,1,1,1,299.993041992188,0,299.993179321289,,,,,,,,,,,,,,,,,,,,,,,,,,,,,,,,,
,3834052923.94961,299.991516113281,-43333.13671875,-0.0026476610293411,2.99721691024095E-7,1,2,13.4005146026611,5.00614228379395,34.2799983918667,-3.53422549027809,-0.521069040880834,10,-1.9750613137918E-5,,,,,,,,,,,,,,,,,,,,,299.991516113281,299.991516113281,-43333.13671875,-43333.13671875,47.4772887008608,5.27545038351611,13.0072364807129,27,1,0,0,1,0.286636352539062,41.055721282959,1,1,1,299.991516113281,0,299.991516113281,,,,,,,,,,,,,,,,,,,,,,,,,,,,,,,,,
,3834052969.95136,299.994354248047,-25555.4453125,-0.0015612847265144,1.79151738616261E-7,1,2,13.4005146026611,5.00615976555282,34.2799983918667,-2.08419266810467,-0.306519355996744,10,-1.10865111070387E-5,,,,,,,,,,,,,,,,,,,,,299.994140625,299.994567871094,-25555.4453125,-25555.4453125,47.4796335864185,5.27553980931138,13.0234317779541,27,1,0,0,1,0.289230346679687,41.055721282959,1,1,1,299.994140625,0,299.994354248047,,,,,,,,,,,,,,,,,,,,,,,,,,,,,,,,,
,3834053010.9445,299.996520996094,-19999.72265625,-0.00122148855589866,1.65783497978724E-7,1,2,13.4005146026611,5.00616416846367,34.2799983918667,-1.63059248544306,-0.239815596848662,10,-8.67849359775508E-6,,,,,,,,,,,,,,,,,,,,,299.996520996094,299.996520996094,-19999.72265625,-19999.72265625,47.5323935114666,5.27549199629831,13.0170669555664,27,1,0,0,1,0.2825927734375,41.055721282959,1,1,1,299.996520996094,0,299.996520996094,,,,,,,,,,,,,,,,,,,,,,,,,,,,,,,,,
,3834053040.02077,300.002151489258,-14999.5654296875,-0.000915518442046134,8.34252811843838E-8,1,2,13.4005146026611,5.00619234709622,34.2799983918667,-1.22216744682464,-0.179660380689468,10,-6.44078713694422E-6,,,,,,,,,,,,,,,,,,,,,300.001861572266,300.00244140625,-14999.5654296875,-14999.5654296875,47.55935969538,5.27548276992334,13.024881362915,27,1,0,0,1,0.288848876953125,41.055721282959,1,1,1,300.001861572266,0,300.002151489258,,,,,,,,,,,,,,,,,,,,,,,,,,,,,,,,,
,3834053070.97926,300.010223388672,-9999.8798828125,-0.000609644812647537,6.14617769641549E-8,1,2,13.4005146026611,5.00616359744418,34.2799983918667,-0.813827005838961,-0.119701998545997,10,-4.33897688097742E-6,,,,,,,,,,,,,,,,,,,,,300.009460449219,300.010986328125,-9999.8798828125,-9999.8798828125,47.5781187798416,5.27571799107293,13.0354499816895,27,1,0,0,1,0.28594970703125,41.055721282959,1,1,1,300.009460449219,0,300.010223388672,,,,,,,,,,,,,,,,,,,,,,,,,,,,,,,,,
,3834053101.94971,300.006408691406,-8947.1533203125,-0.000545007595839945,4.64473313705032E-8,1,2,13.4005146026611,5.00615969354528,34.2799983918667,-0.727393280992182,-0.108065043999966,1,-4.6680821268289E-6,,,,,,,,,,,,,,,,,,,,,300.006256103516,300.006561279297,-8947.1533203125,-8947.1533203125,47.5316118829473,5.27559023882668,13.0256099700928,27,1,0,0,1,0.279464721679687,41.055721282959,1,1,1,300.006256103516,0,300.006408691406,,,,,,,,,,,,,,,,,,,,,,,,,,,,,,,,,
,3834053130.33389,300.004806518555,-6841.70068359375,-0.00041626551006571,4.98260195891705E-8,1,2,13.4005146026611,5.00615982556465,34.2799983918667,-0.555590380354016,-0.0823773355498441,1,-3.44526519044827E-6,,,,,,,,,,,,,,,,,,,,,300.004791259766,300.004821777344,-6841.70068359375,-6841.70068359375,47.5874983220723,5.27578466220711,13.0311546325684,25,1,68,0,0,0.290069580078125,41.055721282959,1,1,1,300.004821777344,0,300.004806518555,,,,,,,,,,,,,,,,,,,,,,,,,,,,,,,,,
,3834053155.59389,300.005111694336,-4736.5341796875,-0.000288619512601148,1.42520768049886E-7,1,2,13.4005146026611,5.00615920107757,34.2799983918667,-0.385123485137833,-0.0578137792000771,1,-2.91047645431257E-6,,,,,,,,,,,,,,,,,,,,,300.004943847656,300.005279541016,-4736.5341796875,-4736.5341796875,47.5925789074473,5.2754698425545,13.0364742279053,27,1,0,0,1,0.289840698242188,41.055721282959,1,1,1,300.004943847656,0,300.005111694336,,,,,,,,,,,,,,,,,,,,,,,,,,,,,,,,,
,3834053178.28607,300.002044677734,-2631.1806640625,-0.00015888111019933,2.55783561064502E-8,1,2,13.4005146026611,5.00614291129129,34.2799983918667,-0.212101293378272,-0.0311317864144503,1,-1.08298288120867E-6,,,,,,,,,,,,,,,,,,,,,300.001525878906,300.002563476562,-2631.1806640625,-2631.1806640625,47.6472929037935,5.27552816235966,13.0354442596436,27,1,0,0,1,0.282669067382813,41.055721282959,1,1,1,300.001525878906,0,300.002044677734,,,,,,,,,,,,,,,,,,,,,,,,,,,,,,,,,
,3834053212.81552,299.999114990234,-526.737182617188,-3.04857377015599E-5,1.53511680158676E-8,1,2,13.4005146026611,5.00617234996492,34.2799983918667,-0.0407051663572138,-0.00592107222295386,1,-1.68533311448192E-7,,,,,,,,,,,,,,,,,,,,,299.998992919922,299.999237060547,-526.737182617188,-526.737182617188,47.6039125209762,5.27549705177972,13.0436344146729,27,1,0,0,1,0.288619995117188,41.055721282959,1,1,1,299.999267578125,0,299.999114990234,,,,,,,,,,,,,,,,,,,,,,,,,,,,,,,,,
,3834053236.06634,300.008712768555,1578.57885742187,9.62581081580599E-5,5.27211421602809E-8,1,2,13.4005146026611,5.00616221203108,34.2799983918667,0.128465085028564,0.0191269448455729,1,8.54931621024191E-7,,,,,,,,,,,,,,,,,,,,,300.007843017578,300.009582519531,1578.57885742187,1578.57885742187,47.6250164909954,5.27524949028754,13.0452661514282,27,1,0,0,1,0.289382934570313,41.5444793701172,1,1,1,300.007843017578,0,300.008712768555,,,,,,,,,,,,,,,,,,,,,,,,,,,,,,,,,
,3834053258.21118,300.002105712891,3683.90747070313,0.00022371438297526,2.3868868750609E-8,1,2,13.4005146026611,5.00615442123157,34.2799983918667,0.298576430449722,0.0443804835760627,1,1.9326713478166E-6,,,,,,,,,,,,,,,,,,,,,300.001953125,300.002258300781,3683.90747070313,3683.90747070313,47.5347383970243,5.27558964492477,13.048360824585,27,1,0,0,1,0.286331176757813,41.055721282959,1,1,1,300.001953125,0,300.002105712891,,,,,,,,,,,,,,,,,,,,,,,,,,,,,,,,,
,3834053287.09022,299.772491455078,5789.111328125,0.000352616580542362,4.27254335289588E-8,1,2,13.4005146026611,5.00618200721659,34.2799983918667,0.470601682852456,0.0700622357177879,1,3.128274096248E-6,,,,,,,,,,,,,,,,,,,,,299.764709472656,299.7802734375,5789.111328125,5789.111328125,47.6738682734474,5.27556631512583,13.0465908050537,27,1,0,0,1,0.28564453125,41.055721282959,1,1,1,299.764709472656,0,299.772491455078,,,,,,,,,,,,,,,,,,,,,,,,,,,,,,,,,
,3834053310.65084,299.72119140625,7894.25244140625,0.000482151642555569,4.91645565425656E-8,1,2,13.4005146026611,5.00614927471634,34.2799983918667,0.643500687884679,0.0956029549485833,1,4.13073522079184E-6,,,,,,,,,,,,,,,,,,,,,299.717559814453,299.724822998047,7894.25244140625,7894.25244140625,47.5871075078127,5.27584205591515,13.0545434951782,27,1,0,0,1,0.28961181640625,41.055721282959,1,1,1,299.724822998047,0,299.72119140625,,,,,,,,,,,,,,,,,,,,,,,,,,,,,,,,,
,3834053336.57019,299.81916809082,9999.66796875,0.000611385946092603,8.06285453851766E-8,1,2,13.4005146026611,5.00616756713636,34.2799983918667,0.815962152135183,0.121402956679633,1,5.36836446360797E-6,,,,,,,,,,,,,,,,,,,,,299.81201171875,299.826324462891,9999.66796875,9999.66796875,47.5804636653993,5.27585389456912,13.0636377334595,27,1,0,0,1,0.290069580078125,41.055721282959,1,1,1,299.826324462891,0,299.81916809082,,,,,,,,,,,,,,,,,,,,,,,,,,,,,,,,,
,3834053372.16799,299.932373046875,13332.88671875,0.000815139187373687,1.55364410377291E-7,1,2,13.4005146026611,5.00620366419501,34.2799983918667,1.08785620845081,0.162206435385119,1,7.41382526265439E-6,,,,,,,,,,,,,,,,,,,,,299.930297851562,299.934448242188,13332.88671875,13332.88671875,47.5749922657646,5.27581711547513,13.0638866424561,27,1,0,0,1,0.28564453125,41.055721282959,1,1,1,299.934448242188,0,299.932373046875,,,,,,,,,,,,,,,,,,,,,,,,,,,,,,,,,
,3834053415.05266,300.008819580078,17777.3203125,0.00108648949648645,1.35832865880079E-7,1,2,13.4005146026611,5.0061847141023,34.2799983918667,1.45001364940959,0.215985041892461,1,9.71948116148221E-6,,,,,,,,,,,,,,,,,,,,,300.008819580078,300.008819580078,17777.3203125,17777.3203125,47.6039125209762,5.27572376255421,13.0656518936157,27,1,0,0,1,0.28228759765625,41.055721282959,1,1,1,300.008819580078,0,300.008819580078,,,,,,,,,,,,,,,,,,,,,,,,,,,,,,,,,
,3834053450.84448,300.022155761719,21999.69140625,0.00134441741229084,2.1242427806547E-7,1,2,13.4005146026611,5.00613378935755,34.2799983918667,1.79420142716942,0.26735713198984,1,1.21030960427084E-5,,,,,,,,,,,,,,,,,,,,,300.022155761719,300.022155761719,21999.69140625,21999.69140625,47.5648310950146,5.27588137216487,13.0788516998291,27,1,0,0,1,0.28106689453125,41.055721282959,1,1,1,300.022155761719,0,300.022155761719,,,,,,,,,,,,,,,,,,,,,,,,,,,,,,,,,
,3834053504.8046,300.013702392578,34999.92578125,0.0021391740195052,2.1479119939201E-7,1,2,13.4005146026611,5.0061682215558,34.2799983918667,2.85554619462965,0.420617842944654,10,1.56715002149192E-5,,,,,,,,,,,,,,,,,,,,,300.013702392578,300.013702392578,34999.92578125,34999.92578125,47.4307818039666,5.27575694925413,13.0674571990967,27,1,0,0,1,0.282974243164062,41.5444793701172,1,1,1,300.013702392578,0,300.013702392578,,,,,,,,,,,,,,,,,,,,,,,,,,,,,,,,,
,3834053568.12016,299.999969482422,58333.140625,0.00356327778529293,3.12726128803934E-7,1,2,13.4005146026611,5.00617159878031,34.2799983918667,4.75616194847032,0.70349538776574,10,2.82452361458074E-5,,,,,,,,,,,,,,,,,,,,,299.999908447266,300.000030517578,58333.140625,58333.140625,47.4608745019569,5.27522586939295,13.0848217010498,27,1,0,0,1,0.277862548828125,41.5444793701172,1,1,1,300.000030517578,0,299.999969482422,,,,,,,,,,,,,,,,,,,,,,,,,,,,,,,,,
,3834053622.24683,300.015182495117,58333.0546875,0.00356283311322834,3.56120250211069E-7,1,2,13.4005146026611,5.00615124778108,34.2799983918667,4.75575094931623,0.701909140839526,10,2.71232445867963E-5,,,,,,,,,,,,,,,,,,,,,300.014526367188,300.015838623047,58333.0546875,58333.0546875,47.4808060291973,5.27543371718286,13.0979442596436,27,1,0,0,1,0.286026000976562,41.055721282959,1,1,1,300.014526367188,0,300.015182495117,,,,,,,,,,,,,,,,,,,,,,,,,,,,,,,,,
,3834053676.44144,300.001190185547,34999.51171875,0.00213832780990881,2.36573648669625E-7,1,2,13.4005146026611,5.00618676240558,34.2799983918667,2.85439996639005,0.420675958204249,10,1.58317157217043E-5,,,,,,,,,,,,,,,,,,,,,300.001037597656,300.001342773438,34999.51171875,34999.51171875,47.5198874551589,5.2754434566543,13.0947875976563,27,1,0,0,1,0.282058715820313,41.5444793701172,1,1,1,300.001037597656,0,300.001190185547,,,,,,,,,,,,,,,,,,,,,,,,,,,,,,,,,
,3834053715.15693,299.99577331543,21999.8046875,0.00134334679282164,1.52785952502979E-7,1,2,13.4005146026611,5.00619015233632,34.2799983918667,1.7932469347691,0.263953472403289,10,9.70255690805094E-6,,,,,,,,,,,,,,,,,,,,,299.995697021484,299.995849609375,21999.8046875,21999.8046875,47.6023492639377,5.27562621502703,13.0945014953613,27,1,0,0,1,0.281982421875,41.5444793701172,1,1,1,299.995849609375,0,299.99577331543,,,,,,,,,,,,,,,,,,,,,,,,,,,,,,,,,