File: SI Fig S11-13 SQUID all/Michaela_Lu_ZFC1T.dat
[Header]
; MPMS3 Data File (default extension .dat)
; Copyright (c) 2007, Quantum Design, Inc. All rights reserved.
TITLE,
FILEOPENTIME,3832571945.55602,06/11/2021,11:19 am
BYAPP,MPMS3 w/ AC,1.0,1.1
INFO,MPMS3 Measurement Release 1.1.16 Build 424, MultiVu Release 2.3.4.19,APPNAME
INFO,Linear Motor Servo Controller,MOTOR_MODULE_NAME
INFO,3101-100 E1,MOTOR_HW_VERSION
INFO,MMC211,MOTOR_SERIAL_NUMBER
INFO,01.04.28,MOTOR_SOFTWARE_VERSION
INFO,Quantum Design Squid Module,SQUID_MODULE_NAME
INFO,3101-501 B0,SQUID_HW_VERSION
INFO,SQM059,SQUID_SERIAL_NUMBER
INFO,01.03.04,SQUID_SOFTWARE_VERSION
INFO,SQUID AC,AC_MODULE_NAME
INFO,3101-401 F1,AC_HW_VERSION
INFO,SAC057,AC_SERIAL_NUMBER
INFO,SQUID AC 00.95.07,AC_SOFTWARE_VERSION
INFO,TCIXXX,COIL_SERIAL_NUMBER
INFO,0,MOMENT_UNITS
INFO,Michaela_Cu,SAMPLE_MATERIAL
INFO,Michaela_Cu,SAMPLE_COMMENT
INFO,1.44,SAMPLE_MASS
INFO,,SAMPLE_VOLUME
INFO,,SAMPLE_MOLECULAR_WEIGHT
INFO,,SAMPLE_SIZE
INFO,,SAMPLE_SHAPE
INFO,Straw,SAMPLE_HOLDER
INFO,Standard,SAMPLE_HOLDER_DETAIL
INFO,57.09,SAMPLE_OFFSET
DATATYPE,COMMENT,1
DATATYPE,TIME,2
STARTUPAXIS,X,2
STARTUPAXIS,Y1,5
FIELDGROUP, VSM,2,3,4,5,6,8,9,10,11,14,15
FIELDGROUP, DC, 2,3,4,14,56,57,58,59,60,61,62,63,64,65,66,67,68,69
FIELDGROUP, AC, 2,3,4,11,16,17,18,19,20,21,22,23,24,25,26,27,28,29,30
STARTUPGROUP, All
[Data]
Comment,Time Stamp (sec),Temperature (K),Magnetic Field (Oe),Moment (emu),M. Std. Err. (emu),Transport Action,Averaging Time (sec),Frequency (Hz),Peak Amplitude (mm),Center Position (mm),Lockin Signal' (V),Lockin Signal (V),Range,M. Quad. Signal (emu),AC Moment (emu),AC M. Std Err. (emu),AC Phase (deg),AC Phase Std. Err. (deg),AC Susceptibility (emu/Oe),AC Suscept. Std Err. (emu/Oe),AC X' (emu/Oe),AC X' Std Err. (emu/Oe),AC X'' (emu/Oe),AC X'' Std Err. (emu/Oe),AC Drive (Oe),AC Frequency (Hz),AC Averaging Time (sec),AC Cycles,AC Range,AC Measure Type,AC Signal' (V),AC Signal'' (V),AC Trim Coil Ratio,AC Trim Coil Phase,Min. Temperature (K),Max. Temperature (K),Min. Field (Oe),Max. Field (Oe),Mass (grams),Motor Lag (deg),Pressure (Torr),Measure Count,Measurement Number,SQUID Status (code),Motor Status (code),Measure Status (code),Motor Current (amps),Motor Temp. (C),Temp. Status (code),Field Status (code),Chamber Status (code),Chamber Temp (K),Redirection State,Average Temp (K),Rotation Angle (deg),Rotator state,DC Moment Fixed Ctr (emu),DC Moment Err Fixed Ctr (emu),DC Moment Free Ctr (emu),DC Moment Err Free Ctr (emu),DC Fixed Fit,DC Free Fit,DC Calculated Center (mm),DC Calculated Center Err (mm),DC Scan Length (mm),DC Scan Time (s),DC Number of Points,DC Squid Drift,DC Min V (V),DC Max V (V),DC Scans per Measure,Map 01,Map 02,Map 03,Map 04,Map 05,Map 06,Map 07,Map 08,Map 09,Map 10,Map 11,Map 12,Map 13,Map 14,Map 15,Map 16
,3832571965.80716,7.99991035461426,9999.494140625,-1.58091124727561E-5,8.43101056563353E-7,1,2,13.4005146026611,5.00493201330295,29.2199999094009,-0.022422314003694,0.0063770010902193,1,6.98437576368554E-6,,,,,,,,,,,,,,,,,,,,,7.99991035461426,7.99991035461426,9999.494140625,9999.494140625,46.6679123691972,5.2630053131766,4.60331201553345,27,1,0,0,1,0.279006958007813,39.1006851196289,1,1,1,7.99991035461426,0,7.99991035461426,,,,,,,,,,,,,,,,,,,,,,,,,,,,,,,,,
,3832572022.9234,10.4760909080505,9999.494140625,-3.75279308953116E-5,1.00308959356576E-7,1,2,13.4005146026611,4.99518502578752,29.2099993675947,-0.0499355828836921,-0.00742439162878226,1,-3.25640158605309E-7,,,,,,,,,,,,,,,,,,,,,10.431113243103,10.521068572998,9999.494140625,9999.494140625,47.0567725575146,5.26421332110481,5.08199596405029,27,1,0,0,1,0.293045043945313,40.0782012939453,6,1,1,10.5350828170776,0,10.4760909080505,,,,,,,,,,,,,,,,,,,,,,,,,,,,,,,,,
,3832572087.44272,13.5371074676514,9999.494140625,-4.3696259396421E-5,6.34835363704998E-8,1,2,13.4005146026611,4.99525780897545,29.2099993675947,-0.0581384652951751,-0.00868784512745605,1,-4.11410899295132E-7,,,,,,,,,,,,,,,,,,,,,13.4900722503662,13.5841426849365,9999.494140625,9999.494140625,47.046220572505,5.26385525505858,5.49727153778076,27,1,0,0,1,0.292282104492188,40.5669593811035,6,1,1,13.5841426849365,0,13.5371074676514,,,,,,,,,,,,,,,,,,,,,,,,,,,,,,,,,
,3832572150.02738,16.6160697937012,9999.494140625,-4.77087456348708E-5,9.77492352317065E-8,1,2,13.4005146026611,4.99513606300021,29.2099993675947,-0.0634770173318834,-0.00947097322083323,1,-4.38431504038691E-7,,,,,,,,,,,,,,,,,,,,,16.5746555328369,16.6574840545654,9999.494140625,9999.494140625,47.0583358145531,5.26366190694247,5.80322694778442,27,1,0,0,1,0.284652709960938,40.5669593811035,2,1,1,16.6574840545654,0,16.6160697937012,,,,,,,,,,,,,,,,,,,,,,,,,,,,,,,,,
,3832572208.37435,19.4136123657227,9999.494140625,-5.0382339581168E-5,9.69544474692611E-8,1,2,13.4005146026611,4.99509551876403,29.2099993675947,-0.0670262042212036,-0.0100539261941465,1,-5.02268052659377E-7,,,,,,,,,,,,,,,,,,,,,19.3650035858154,19.4622211456299,9999.494140625,9999.494140625,47.012610546178,5.2634431629047,6.0030689239502,27,1,0,0,1,0.28411865234375,40.5669593811035,2,1,1,19.4622211456299,0,19.4136123657227,,,,,,,,,,,,,,,,,,,,,,,,,,,,,,,,,
,3832572264.96098,22.1355800628662,9999.494140625,-5.24513844128488E-5,8.85447464711891E-8,1,2,13.4005146026611,4.99500094074591,29.2099993675947,-0.0697855975835658,-0.0104046949940975,1,-4.76472018600592E-7,,,,,,,,,,,,,,,,,,,,,22.084810256958,22.1863498687744,9999.494140625,9999.494140625,47.1271191242454,5.26371097821441,6.18400287628174,27,1,0,0,1,0.275192260742187,40.5669593811035,2,1,1,22.1863498687744,0,22.1355800628662,,,,,,,,,,,,,,,,,,,,,,,,,,,,,,,,,
,3832572327.16265,25.135856628418,9999.494140625,-5.41866676183088E-5,9.55914687373043E-8,1,2,13.4005146026611,4.99495435683271,29.2099993675947,-0.0720949002678294,-0.0107383304583185,1,-4.8438915647386E-7,,,,,,,,,,,,,,,,,,,,,25.087495803833,25.1842174530029,9999.494140625,9999.494140625,47.0782673417934,5.26345569823444,6.33476734161377,27,1,0,0,1,0.284271240234375,40.5669593811035,2,1,1,25.1968536376953,0,25.135856628418,,,,,,,,,,,,,,,,,,,,,,,,,,,,,,,,,
,3832572393.87103,28.366024017334,9999.494140625,-5.56579470893927E-5,8.2892753693804E-8,1,2,13.4005146026611,4.99491582661026,29.2099993675947,-0.0740491732716071,-0.0110474420833851,1,-5.10798473488632E-7,,,,,,,,,,,,,,,,,,,,,28.3097610473633,28.4222869873047,9999.494140625,9999.494140625,47.0540368576973,5.26414354418084,6.48020029067993,27,1,0,0,1,0.285186767578125,40.5669593811035,2,1,1,28.4222869873047,0,28.366024017334,,,,,,,,,,,,,,,,,,,,,,,,,,,,,,,,,
,3832572452.38655,31.1973400115967,9999.494140625,-5.67950618763421E-5,1.13542031505181E-7,1,2,13.4005146026611,4.99494247789327,29.2099993675947,-0.0755698098812154,-0.0112215253032324,1,-4.82422688226339E-7,,,,,,,,,,,,,,,,,,,,,31.1696357727051,31.2250442504883,9999.494140625,9999.494140625,47.1243834244281,5.26364608196823,6.59625673294067,27,1,0,0,1,0.27496337890625,40.5669593811035,2,1,1,31.2250442504883,0,31.1973400115967,,,,,,,,,,,,,,,,,,,,,,,,,,,,,,,,,
,3832572510.52373,34.0134963989258,9999.494140625,-5.76190576712083E-5,7.10439432699095E-8,1,2,13.4005146026611,4.99486507846326,29.2199999094009,-0.0766591344482494,-0.0114229389802049,1,-5.18586390512915E-7,,,,,,,,,,,,,,,,,,,,,33.9601249694824,34.0668678283691,9999.494140625,9999.494140625,47.0571633717742,5.26372753330956,6.67781352996826,27,1,0,0,1,0.283737182617187,40.5669593811035,2,1,1,34.0668678283691,0,34.0134963989258,,,,,,,,,,,,,,,,,,,,,,,,,,,,,,,,,
,3832572566.92706,36.7730350494385,9999.494140625,-5.84100466521208E-5,2.86349962526856E-8,1,2,13.4005146026611,4.99503693479676,29.2199999094009,-0.0777145100840826,-0.0115849928470167,1,-5.2922981747436E-7,,,,,,,,,,,,,,,,,,,,,36.7164688110352,36.8296012878418,9999.494140625,9999.494140625,47.0587266288127,5.26437669914191,6.76658916473389,27,1,0,0,1,0.285263061523438,40.5669593811035,2,1,1,36.8296012878418,0,36.7730350494385,,,,,,,,,,,,,,,,,,,,,,,,,,,,,,,,,
,3832572625.5117,39.6221332550049,9999.494140625,-5.91492687594458E-5,3.26573408521341E-8,1,2,13.4005146026611,4.99502648110865,29.2199999094009,-0.0786968759357459,-0.0117383188850429,1,-5.40989275476873E-7,,,,,,,,,,,,,,,,,,,,,39.5791358947754,39.6651306152344,9999.494140625,9999.494140625,47.1462690229665,5.26373101976486,6.83676624298096,27,1,0,0,1,0.284194946289062,40.5669593811035,2,1,1,39.6651306152344,0,39.6221332550049,,,,,,,,,,,,,,,,,,,,,,,,,,,,,,,,,
,3832572680.09296,42.2891674041748,9999.494140625,-5.97832844198752E-5,2.67116669976174E-8,1,2,13.4005146026611,4.99498257046014,29.2199999094009,-0.0795428446729395,-0.0118398108805443,1,-5.28631872200032E-7,,,,,,,,,,,,,,,,,,,,,42.2258682250977,42.352466583252,9999.494140625,9999.494140625,47.1611199648319,5.26446436774293,6.89209461212158,27,1,0,0,1,0.28350830078125,40.5669593811035,2,1,1,42.352466583252,0,42.2891674041748,,,,,,,,,,,,,,,,,,,,,,,,,,,,,,,,,
,3832572736.37079,45.0373229980469,9999.494140625,-6.02233626516299E-5,2.23201508425414E-8,1,2,13.4005146026611,4.99492910080541,29.2300004512072,-0.0801238752011311,-0.0119505881294958,1,-5.50386611231888E-7,,,,,,,,,,,,,,,,,,,,,45.0053863525391,45.0692596435547,9999.494140625,9999.494140625,47.1087508540434,5.2641865035262,6.95781564712524,27,1,0,0,1,0.2935791015625,40.5669593811035,2,1,1,45.0692596435547,0,45.0373229980469,,,,,,,,,,,,,,,,,,,,,,,,,,,,,,,,,
,3832572792.93109,47.8011226654053,9999.494140625,-6.06367366101226E-5,3.90539149665732E-8,1,2,13.4005146026611,4.99487774202747,29.2300004512072,-0.0806761466778564,-0.0120078702722914,1,-5.35714774373968E-7,,,,,,,,,,,,,,,,,,,,,47.7805366516113,47.8217086791992,9999.494140625,9999.494140625,47.1259466814665,5.26399257282443,7.01450252532959,27,1,0,0,1,0.284652709960938,40.5669593811035,2,1,1,47.8217086791992,0,47.8011226654053,,,,,,,,,,,,,,,,,,,,,,,,,,,,,,,,,
,3832572851.03896,50.6692600250244,9999.494140625,-6.10041799647843E-5,3.55241395427059E-8,1,2,13.4005146026611,4.99485199514576,29.2300004512072,-0.0811653046545442,-0.0120744420631636,1,-5.34376214981158E-7,,,,,,,,,,,,,,,,,,,,,50.6213493347168,50.717170715332,9999.494140625,9999.494140625,47.1321997096204,5.26454298730499,7.07483625411987,27,1,0,0,1,0.2850341796875,40.5669593811035,2,1,1,50.717170715332,0,50.6692600250244,,,,,,,,,,,,,,,,,,,,,,,,,,,,,,,,,
,3832572907.42592,53.4031314849854,9999.494140625,-6.11947209573234E-5,2.38405419627611E-8,1,2,13.4005146026611,4.99480579262722,29.2300004512072,-0.0814203819645111,-0.0120934313342543,1,-5.22104417787732E-7,,,,,,,,,,,,,,,,,,,,,53.3490028381348,53.4572601318359,9999.494140625,9999.494140625,47.1701086928031,5.26493135892093,7.11765003204346,27,1,0,0,1,0.285263061523438,40.0782012939453,2,1,1,53.4572601318359,0,53.4031314849854,,,,,,,,,,,,,,,,,,,,,,,,,,,,,,,,,
,3832572966.00782,56.2902450561523,9999.494140625,-6.12801334289812E-5,3.19525598661769E-8,1,2,13.4005146026611,4.9947258526507,29.2399991303682,-0.0815321830201195,-0.0121104296220006,1,-5.23121723647867E-7,,,,,,,,,,,,,,,,,,,,,56.2523880004883,56.3281021118164,9999.494140625,9999.494140625,47.1306364525819,5.26451770644855,7.16618490219116,27,1,0,0,1,0.284957885742187,40.5669593811035,2,1,1,56.3281021118164,0,56.2902450561523,,,,,,,,,,,,,,,,,,,,,,,,,,,,,,,,,
,3832573020.60587,58.9748764038086,9999.494140625,-6.1678595555934E-5,1.26788332685379E-7,1,2,13.4005146026611,4.99464253021377,29.2399991303682,-0.0820596345199859,-0.0121947631902206,1,-5.30927299032769E-7,,,,,,,,,,,,,,,,,,,,,58.9162864685059,59.0334663391113,9999.494140625,9999.494140625,47.1587750792742,5.26451754475981,7.20108699798584,27,1,0,0,1,0.2825927734375,40.5669593811035,2,1,1,59.0334663391113,0,58.9748764038086,,,,,,,,,,,,,,,,,,,,,,,,,,,,,,,,,
,3832573076.92374,61.73512840271,9999.494140625,-6.23948355441178E-5,3.76564381487881E-8,1,2,13.4005146026611,4.99461981984467,29.2399991303682,-0.0830094796977489,-0.0123545467777666,1,-5.50792974932655E-7,,,,,,,,,,,,,,,,,,,,,61.6965560913086,61.7737007141113,9999.494140625,9999.494140625,47.1024978258896,5.26467098369916,7.22613477706909,27,1,0,0,1,0.2850341796875,40.5669593811035,2,1,1,61.7737007141113,0,61.73512840271,,,,,,,,,,,,,,,,,,,,,,,,,,,,,,,,,
,3832573133.42697,64.5104751586914,9999.494140625,-6.28722105521037E-5,3.46184287801737E-8,1,2,13.4005146026611,4.99454956239777,29.2499996721745,-0.0836430340972065,-0.0124483205705711,1,-5.54624603737123E-7,,,,,,,,,,,,,,,,,,,,,64.4767913818359,64.5441589355469,9999.494140625,9999.494140625,47.1595567077935,5.26540307167734,7.26249647140503,27,1,0,0,1,0.27587890625,40.5669593811035,2,1,1,64.5441589355469,0,64.5104751586914,,,,,,,,,,,,,,,,,,,,,,,,,,,,,,,,,
,3832573191.56238,67.3791694641113,9999.494140625,-6.34781062807687E-5,2.97570187460349E-8,1,2,13.4005146026611,4.99452736255624,29.2499996721745,-0.0844480698021809,-0.0125718765686114,1,-5.62723847662941E-7,,,,,,,,,,,,,,,,,,,,,67.3363876342773,67.4219512939453,9999.494140625,9999.494140625,47.1642464789088,5.26585845397762,7.29352426528931,27,1,0,0,1,0.276947021484375,40.5669593811035,2,1,1,67.4219512939453,0,67.3791694641113,,,,,,,,,,,,,,,,,,,,,,,,,,,,,,,,,
,3832573245.91588,70.0461120605469,9999.494140625,-6.39594119920071E-5,3.49136035788465E-8,1,2,13.4005146026611,4.99449641335381,29.2499996721745,-0.0850912422791462,-0.0126414165789393,1,-5.47714615841311E-7,,,,,,,,,,,,,,,,,,,,,70.0072479248047,70.0849761962891,9999.494140625,9999.494140625,47.0274614880434,5.26522476437999,7.33561086654663,27,1,0,0,1,0.28594970703125,40.5669593811035,2,1,1,70.0849761962891,0,70.0461120605469,,,,,,,,,,,,,,,,,,,,,,,,,,,,,,,,,
,3832573304.56277,72.9461631774902,9999.494140625,-6.43420222945315E-5,3.38264989056431E-8,1,2,13.4005146026611,4.99442627414668,29.2600002139807,-0.0855905187299443,-0.0127747197103119,1,-5.94480137422822E-7,,,,,,,,,,,,,,,,,,,,,72.8871536254883,73.0051727294922,9999.494140625,9999.494140625,47.1533036796396,5.26567349870036,7.36846256256104,27,1,0,0,1,0.29266357421875,40.5669593811035,2,1,1,73.0051727294922,0,72.9461631774902,,,,,,,,,,,,,,,,,,,,,,,,,,,,,,,,,
,3832573363.05933,75.8188018798828,9999.494140625,-6.46771869506361E-5,2.39666205325983E-8,1,2,13.4005146026611,4.99430336729928,29.2700007557869,-0.086038153895924,-0.0128073220672136,1,-5.72417932993752E-7,,,,,,,,,,,,,,,,,,,,,75.7914886474609,75.8461151123047,9999.494140625,9999.494140625,47.1189120247934,5.26497804174748,7.40386724472046,27,1,0,0,1,0.286178588867187,40.5669593811035,2,1,1,75.8461151123047,0,75.8188018798828,,,,,,,,,,,,,,,,,,,,,,,,,,,,,,,,,
,3832573418.45194,78.5595092773437,9999.494140625,-6.50182151513798E-5,4.31158896865362E-7,1,2,13.4005146026611,4.99416453274537,29.2700007557869,-0.0865082123591838,-0.0127335202642078,1,-4.69688756603446E-7,,,,,,,,,,,,,,,,,,,,,78.4846954345703,78.6343231201172,9999.494140625,9999.494140625,46.8476869286203,5.26742600240948,7.4218807220459,27,1,0,0,1,0.286331176757813,40.5669593811035,2,1,1,78.6343231201172,0,78.5595092773437,,,,,,,,,,,,,,,,,,,,,,,,,,,,,,,,,
,3832573473.92903,81.2784843444824,9999.494140625,-6.52852010318978E-5,2.97537513694524E-8,1,2,13.4005146026611,4.99429585076077,29.2700007557869,-0.0868462837504315,-0.0129313719066808,1,-5.80560570778076E-7,,,,,,,,,,,,,,,,,,,,,81.2553482055664,81.3016204833984,9999.494140625,9999.494140625,47.1067967827454,5.26642667837351,7.45520496368408,27,1,0,0,1,0.277099609375,40.5669593811035,2,1,1,81.3016204833984,0,81.2784843444824,,,,,,,,,,,,,,,,,,,,,,,,,,,,,,,,,
,3832573529.29046,84.0373039245606,9999.494140625,-6.54040371855442E-5,3.62598117776216E-8,1,2,13.4005146026611,4.99426536785578,29.279999434948,-0.087007882706843,-0.0129244525964431,1,-5.5883083241874E-7,,,,,,,,,,,,,,,,,,,,,83.9583740234375,84.1162338256836,9999.494140625,9999.494140625,47.1384527377742,5.26638749626234,7.47924995422363,27,1,0,0,1,0.285873413085938,40.5669593811035,2,1,1,84.1162338256836,0,84.0373039245606,,,,,,,,,,,,,,,,,,,,,,,,,,,,,,,,,
,3832573582.60865,86.6703453063965,9999.494140625,-6.56836914175529E-5,2.99454364171111E-8,1,2,13.4005146026611,4.99420668958294,29.279999434948,-0.0873785768251948,-0.012978985334375,1,-5.60829374458534E-7,,,,,,,,,,,,,,,,,,,,,86.6328811645508,86.7078094482422,9999.494140625,9999.494140625,47.0911642123608,5.26575940405131,7.48638200759888,27,1,0,0,1,0.286407470703125,40.5669593811035,2,1,1,86.7078094482422,0,86.6703453063965,,,,,,,,,,,,,,,,,,,,,,,,,,,,,,,,,
,3832573640.82016,89.5787086486816,9999.494140625,-6.58783824338009E-5,2.6511669726172E-8,1,2,13.4005146026611,4.99417667831766,29.2899999767542,-0.0876289220310511,-0.0130740599220156,1,-6.05071724749365E-7,,,,,,,,,,,,,,,,,,,,,89.5326461791992,89.6247711181641,9999.494140625,9999.494140625,47.0579450002934,5.2655404863471,7.50629234313965,27,1,0,0,1,0.285797119140625,40.5669593811035,2,1,1,89.6247711181641,0,89.5787086486816,,,,,,,,,,,,,,,,,,,,,,,,,,,,,,,,,
,3832573699.37073,92.4807968139648,9999.494140625,-6.61685158692127E-5,3.5300949804401E-8,1,2,13.4005146026611,4.99418357524947,29.2899999767542,-0.0880190540549541,-0.0131027626745451,1,-5.86036832555596E-7,,,,,,,,,,,,,,,,,,,,,92.4214935302734,92.5401000976563,9999.494140625,9999.494140625,47.015737060255,5.26574332811805,7.52570962905884,27,1,0,0,1,0.28594970703125,40.5669593811035,2,1,1,92.5401000976563,0,92.4807968139648,,,,,,,,,,,,,,,,,,,,,,,,,,,,,,,,,
,3832573755.9032,95.2743301391602,9999.494140625,-6.62182545785208E-5,3.05757924153101E-8,1,2,13.4005146026611,4.99416218698188,29.3000005185604,-0.0880907590091372,-0.0130692078874582,1,-5.5394620867601E-7,,,,,,,,,,,,,,,,,,,,,95.2116775512695,95.3369827270508,9999.494140625,9999.494140625,47.0673245425242,5.26534601682409,7.54839277267456,27,1,0,0,1,0.286026000976562,40.5669593811035,2,1,1,95.3369827270508,0,95.2743301391602,,,,,,,,,,,,,,,,,,,,,,,,,,,,,,,,,
,3832573812.2714,98.1334762573242,9999.494140625,-6.65609773596245E-5,2.74566591648593E-8,1,2,13.4005146026611,4.99408476520461,29.3000005185604,-0.0885407632653212,-0.0131654816081016,1,-5.78520850915189E-7,,,,,,,,,,,,,,,,,,,,,98.09716796875,98.1697845458984,9999.494140625,9999.494140625,47.0864744412454,5.26584197020208,7.55809259414673,27,1,0,0,1,0.295333862304687,40.5669593811035,2,1,1,98.1697845458984,0,98.1334762573242,,,,,,,,,,,,,,,,,,,,,,,,,,,,,,,,,
,3832573866.83296,100.811592102051,9999.494140625,-6.66211244315144E-5,2.86059567284602E-8,1,2,13.4005146026611,4.9939925417319,29.3099991977215,-0.0886208255981598,-0.0131606268934082,1,-5.66715875314621E-7,,,,,,,,,,,,,,,,,,,,,100.751365661621,100.87181854248,9999.494140625,9999.494140625,47.14275169463,5.26479332233065,7.5865650177002,27,1,0,0,1,0.273818969726562,40.5669593811035,2,1,1,100.87181854248,0,100.811592102051,,,,,,,,,,,,,,,,,,,,,,,,,,,,,,,,,
,3832573923.37205,103.599742889404,9999.494140625,-6.6744559262365E-5,3.24769640229907E-8,1,2,13.4005146026611,4.99398880599326,29.3199997395277,-0.088788878699593,-0.0131567578516326,1,-5.46562018759363E-7,,,,,,,,,,,,,,,,,,,,,103.584175109863,103.615310668945,9999.494140625,9999.494140625,47.1282915670242,5.26528210914164,7.62089920043945,26,1,64,0,0,0.276870727539062,40.5669593811035,2,1,1,103.629165649414,0,103.599742889404,,,,,,,,,,,,,,,,,,,,,,,,,,,,,,,,,
,3832573979.59276,106.422298431396,9999.494140625,-6.69740544617352E-5,2.83067331945931E-8,1,2,13.4005146026611,4.99394928885769,29.3199997395277,-0.0890965940213417,-0.0131776178694006,1,-5.30243858641021E-7,,,,,,,,,,,,,,,,,,,,,106.391967773438,106.452629089355,9999.494140625,9999.494140625,46.9989320470915,5.26483355582311,7.63499450683594,27,1,0,0,1,0.28656005859375,40.5669593811035,2,1,1,106.452629089355,0,106.422298431396,,,,,,,,,,,,,,,,,,,,,,,,,,,,,,,,,
,3832574035.70701,109.201740264893,9999.494140625,-6.70647855204831E-5,2.57974112057829E-8,1,2,13.4005146026611,4.99390329642005,29.3300002813339,-0.0892097690613395,-0.0132410766767115,1,-5.65332423140972E-7,,,,,,,,,,,,,,,,,,,,,109.15665435791,109.246826171875,9999.494140625,9999.494140625,47.0731867564184,5.26489042138614,7.64038133621216,27,1,0,0,1,0.274734497070313,40.5669593811035,2,1,1,109.246826171875,0,109.201740264893,,,,,,,,,,,,,,,,,,,,,,,,,,,,,,,,,
,3832574094.13383,112.117767333984,9999.494140625,-6.73651779662137E-5,2.34531750126882E-8,1,2,13.4005146026611,4.99387721726443,29.3300002813339,-0.089615275091175,-0.013253342544427,1,-5.32612421080174E-7,,,,,,,,,,,,,,,,,,,,,112.065307617187,112.170227050781,9999.494140625,9999.494140625,47.0849111842069,5.26528025616617,7.65600967407227,27,1,0,0,1,0.27496337890625,40.5669593811035,2,1,1,112.170227050781,0,112.117767333984,,,,,,,,,,,,,,,,,,,,,,,,,,,,,,,,,
,3832574152.66433,115.03165435791,9999.494140625,-6.75023074905239E-5,3.23823902938192E-8,1,2,13.4005146026611,4.99384441259945,29.3400008231401,-0.0897906012911948,-0.0133251714312608,1,-5.67463975775812E-7,,,,,,,,,,,,,,,,,,,,,114.991806030273,115.071502685547,9999.494140625,9999.494140625,47.0333237019377,5.26495198975129,7.67230081558228,27,1,0,0,1,0.2862548828125,40.5669593811035,2,1,1,115.071502685547,0,115.03165435791,,,,,,,,,,,,,,,,,,,,,,,,,,,,,,,,,
,3832574207.24847,117.771995544434,9999.494140625,-6.75991930505243E-5,3.20053490280193E-8,1,2,13.4005146026611,4.99379262108275,29.3499995023012,-0.0899211920665217,-0.013322703567195,1,-5.52206326290242E-7,,,,,,,,,,,,,,,,,,,,,117.717300415039,117.826690673828,9999.494140625,9999.494140625,47.0829571129088,5.26500228374802,7.70133352279663,27,1,0,0,1,0.276031494140625,40.5669593811035,2,1,1,117.826690673828,0,117.771995544434,,,,,,,,,,,,,,,,,,,,,,,,,,,,,,,,,
,3832574265.75216,120.695911407471,9999.494140625,-6.79153059174082E-5,3.9411152617347E-8,1,2,13.4005146026611,4.99374211306534,29.3499995023012,-0.0903393827323591,-0.0133923585927049,1,-5.60450323668801E-7,,,,,,,,,,,,,,,,,,,,,120.663108825684,120.728713989258,9999.494140625,9999.494140625,47.1419700661108,5.26616619777946,7.70126628875732,27,1,0,0,1,0.273895263671875,40.5669593811035,2,1,1,120.728713989258,0,120.695911407471,,,,,,,,,,,,,,,,,,,,,,,,,,,,,,,,,
,3832574321.07137,123.442878723145,9999.494140625,-6.8059964911015E-5,2.64810794736602E-8,1,2,13.4005146026611,4.99373597605673,29.3600000441074,-0.0905329796681378,-0.0134113688079163,1,-5.54515813917072E-7,,,,,,,,,,,,,,,,,,,,,123.359130859375,123.526626586914,9999.494140625,9999.494140625,47.0755316419761,5.26528297212903,7.71972799301148,27,1,0,0,1,0.286941528320313,40.5669593811035,2,1,1,123.526626586914,0,123.442878723145,,,,,,,,,,,,,,,,,,,,,,,,,,,,,,,,,
,3832574376.21664,126.192050933838,9999.494140625,-6.8135659798722E-5,3.26075869719959E-8,1,2,13.4005146026611,4.99367186128252,29.3700005859137,-0.0906315943634357,-0.0134294803387568,1,-5.5770961714835E-7,,,,,,,,,,,,,,,,,,,,,126.145942687988,126.238159179688,9999.494140625,9999.494140625,47.1005437545915,5.26505098466615,7.74411725997925,27,1,0,0,1,0.284347534179687,40.5669593811035,2,1,1,126.238159179688,0,126.192050933838,,,,,,,,,,,,,,,,,,,,,,,,,,,,,,,,,
,3832574434.64175,129.092353820801,9999.494140625,-6.83828984390936E-5,2.60192982985147E-8,1,2,13.4005146026611,4.99362088826678,29.3799992650747,-0.0909583185913702,-0.013484255438398,1,-5.64413986434275E-7,,,,,,,,,,,,,,,,,,,,,129.054321289062,129.130386352539,9999.494140625,9999.494140625,46.9688393491011,5.26585897508588,7.75047492980957,27,1,0,0,1,0.286865234375,40.5669593811035,2,1,1,129.130386352539,0,129.092353820801,,,,,,,,,,,,,,,,,,,,,,,,,,,,,,,,,
,3832574493.1578,132.017631530762,9999.494140625,-6.86143696237011E-5,3.68712793070782E-8,1,2,13.4005146026611,4.99358397557013,29.3799992650747,-0.0912627034822124,-0.0135482001112086,1,-5.80170762280437E-7,,,,,,,,,,,,,,,,,,,,,131.963623046875,132.071640014648,9999.494140625,9999.494140625,47.1873045202262,5.26579430436364,7.77201843261719,27,1,0,0,1,0.275802612304687,40.5669593811035,2,1,1,132.071640014648,0,132.017631530762,,,,,,,,,,,,,,,,,,,,,,,,,,,,,,,,,
,3832574549.73381,134.810165405273,9999.494140625,-6.87775471803283E-5,2.63718257001794E-8,1,2,13.4005146026611,4.99346973812317,29.389999806881,-0.0914780251093896,-0.0135717722946027,1,-5.75375874768117E-7,,,,,,,,,,,,,,,,,,,,,134.776504516602,134.843826293945,9999.494140625,9999.494140625,47.0841295556877,5.26599924655677,7.78030633926392,27,1,0,0,1,0.277175903320313,40.5669593811035,2,1,1,134.843826293945,0,134.810165405273,,,,,,,,,,,,,,,,,,,,,,,,,,,,,,,,,
,3832574603.95025,137.544769287109,9999.494140625,-6.89449239199501E-5,2.4116750171693E-8,1,2,13.4005146026611,4.99345600693577,29.4000003486872,-0.091702467346995,-0.0135892493257195,1,-5.65136118649564E-7,,,,,,,,,,,,,,,,,,,,,137.503890991211,137.585647583008,9999.494140625,9999.494140625,47.0669337282646,5.26661472963456,7.7831597328186,27,1,0,0,1,0.287322998046875,40.5669593811035,2,1,1,137.585647583008,0,137.544769287109,,,,,,,,,,,,,,,,,,,,,,,,,,,,,,,,,
,3832574660.56451,140.365913391113,9999.494140625,-6.90406836755914E-5,3.420739465625E-8,1,2,13.4005146026611,4.99327562772417,29.4100008904934,-0.09183066388821,-0.0135690201689549,1,-5.3705970241569E-7,,,,,,,,,,,,,,,,,,,,,140.332824707031,140.399002075195,9999.494140625,9999.494140625,47.1552577509377,5.26663346771531,7.79759788513184,27,1,0,0,1,0.284805297851562,40.5669593811035,2,1,1,140.399002075195,0,140.365913391113,,,,,,,,,,,,,,,,,,,,,,,,,,,,,,,,,
,3832574717.05866,143.155914306641,9999.494140625,-6.93034682064899E-5,2.99754028992258E-8,1,2,13.4005146026611,4.99331968045212,29.4100008904934,-0.0921763257040424,-0.0136564548814205,1,-5.65856929697555E-7,,,,,,,,,,,,,,,,,,,,,143.12858581543,143.183242797852,9999.494140625,9999.494140625,47.0391859158319,5.26675239900633,7.80476093292236,27,1,0,0,1,0.296630859375,40.5669593811035,2,1,1,143.183242797852,0,143.155914306641,,,,,,,,,,,,,,,,,,,,,,,,,,,,,,,,,
,3832574772.43593,145.929763793945,9999.494140625,-6.94716795778487E-5,2.51691686343986E-8,1,2,13.4005146026611,4.99340181250601,29.4199995696545,-0.0924026458598778,-0.0136862629588996,1,-5.64491520465914E-7,,,,,,,,,,,,,,,,,,,,,145.848663330078,146.010864257813,9999.494140625,9999.494140625,47.1482230942646,5.26672356241393,7.80540037155151,27,1,0,0,1,0.276412963867187,40.5669593811035,2,1,1,146.010864257813,0,145.929763793945,,,,,,,,,,,,,,,,,,,,,,,,,,,,,,,,,
,3832574827.52005,148.669403076172,9999.494140625,-6.96435876353942E-5,2.37582836210131E-8,1,2,13.4005146026611,4.993296655338,29.4300001114607,-0.0926279034530766,-0.0137248854837112,1,-5.6975730211621E-7,,,,,,,,,,,,,,,,,,,,,148.621353149414,148.71745300293,9999.494140625,9999.494140625,47.0755316419761,5.26627055608182,7.82304525375366,27,1,0,0,1,0.27587890625,40.5669593811035,2,1,1,148.71745300293,0,148.669403076172,,,,,,,,,,,,,,,,,,,,,,,,,,,,,,,,,
,3832574883.27021,151.444602966309,9999.494140625,-6.97406150255362E-5,3.45500905544087E-8,1,2,13.4005146026611,4.99328531886594,29.4400006532669,-0.0927541747452243,-0.0137617673990942,1,-5.83921382190686E-7,,,,,,,,,,,,,,,,,,,,,151.370971679687,151.51823425293,9999.494140625,9999.494140625,47.0704510566011,5.26694568721643,7.83314085006714,27,1,0,0,1,0.285263061523438,40.5669593811035,2,1,1,151.51823425293,0,151.444602966309,,,,,,,,,,,,,,,,,,,,,,,,,,,,,,,,,
,3832574940.34855,154.300132751465,9999.494140625,-6.99122909510952E-5,3.04321152015279E-8,1,2,13.4005146026611,4.99320124132144,29.449999332428,-0.092981494035456,-0.0137871886759823,1,-5.79247801234779E-7,,,,,,,,,,,,,,,,,,,,,154.257446289062,154.342819213867,9999.494140625,9999.494140625,47.1697178785434,5.26738800876354,7.84147071838379,27,1,0,0,1,0.273895263671875,40.5669593811035,2,1,1,154.342819213867,0,154.300132751465,,,,,,,,,,,,,,,,,,,,,,,,,,,,,,,,,
,3832574998.97753,157.24683380127,9999.494140625,-7.01046625616745E-5,2.98072072616454E-8,1,2,13.4005146026611,4.99329753720842,29.4599998742342,-0.0932332531353346,-0.0138723644618127,1,-6.16043789879249E-7,,,,,,,,,,,,,,,,,,,,,157.190551757813,157.303115844727,9999.494140625,9999.494140625,47.1411884375915,5.26739362974177,7.86363363265991,27,1,0,0,1,0.286636352539062,40.5669593811035,2,1,1,157.303115844727,0,157.24683380127,,,,,,,,,,,,,,,,,,,,,,,,,,,,,,,,,
,3832575053.19698,159.945426940918,9999.494140625,-7.02102065083709E-5,3.36509168008238E-8,1,2,13.4005146026611,4.99308283435069,29.4700004160404,-0.0933712325402344,-0.0138701431289375,1,-6.00231985271154E-7,,,,,,,,,,,,,,,,,,,,,159.883224487305,160.007629394531,9999.494140625,9999.494140625,47.0763132704954,5.26796797912272,7.86332082748413,27,1,0,0,1,0.2764892578125,40.5669593811035,2,1,1,160.007629394531,0,159.945426940918,,,,,,,,,,,,,,,,,,,,,,,,,,,,,,,,,
,3832575109.80321,162.721557617187,9999.494140625,-7.0326947418394E-5,3.55097258510555E-8,1,2,13.4005146026611,4.99299009453104,29.4799990952015,-0.0935340014623657,-0.0138220634822075,1,-5.48063164062798E-7,,,,,,,,,,,,,,,,,,,,,162.65803527832,162.785079956055,9999.494140625,9999.494140625,47.1028886401492,5.2682261459205,7.86154747009277,27,1,0,0,1,0.276412963867187,40.5669593811035,2,1,1,162.785079956055,0,162.721557617187,,,,,,,,,,,,,,,,,,,,,,,,,,,,,,,,,
,3832575168.40061,165.658340454102,9999.494140625,-7.05112500022583E-5,2.86170218302835E-8,1,2,13.4005146026611,4.99300316102534,29.4899996370077,-0.0937792842519941,-0.0138595786450322,1,-5.50432737705217E-7,,,,,,,,,,,,,,,,,,,,,165.627807617187,165.688873291016,9999.494140625,9999.494140625,47.0927274693992,5.26824322968493,7.8845853805542,25,1,64,0,0,0.278244018554687,40.5669593811035,2,1,1,165.688873291016,0,165.658340454102,,,,,,,,,,,,,,,,,,,,,,,,,,,,,,,,,
,3832575224.49417,168.437347412109,9999.494140625,-7.06015403738023E-5,3.00577737926518E-8,1,2,13.4005146026611,4.99297119217849,29.5000001788139,-0.093893713330233,-0.0139117653924433,1,-5.77095467973909E-7,,,,,,,,,,,,,,,,,,,,,168.386672973633,168.488021850586,9999.494140625,9999.494140625,46.9653220207646,5.26801913226879,7.88210678100586,27,1,0,0,1,0.287322998046875,40.5669593811035,2,1,1,168.488021850586,0,168.437347412109,,,,,,,,,,,,,,,,,,,,,,,,,,,,,,,,,
,3832575280.84818,171.289001464844,9999.494140625,-7.08375769177784E-5,3.2128254995713E-8,1,2,13.4005146026611,4.99293165823781,29.5100007206202,-0.0942100832119515,-0.0139332022072647,1,-5.60306548496761E-7,,,,,,,,,,,,,,,,,,,,,171.247207641602,171.330795288086,9999.494140625,9999.494140625,47.0641980284473,5.2687605573301,7.89777565002441,27,1,0,0,1,0.277481079101562,40.5669593811035,2,1,1,171.330795288086,0,171.289001464844,,,,,,,,,,,,,,,,,,,,,,,,,,,,,,,,,
,3832575335.26497,173.99055480957,9999.494140625,-7.09698656175061E-5,3.2211065862895E-8,1,2,13.4005146026611,4.99272125593357,29.5199993997812,-0.0943816135537602,-0.013950949276431,1,-5.55744281521138E-7,,,,,,,,,,,,,,,,,,,,,173.945388793945,174.035720825195,9999.494140625,9999.494140625,47.1032794544088,5.26927412994886,7.91748046875,27,1,0,0,1,0.274505615234375,40.5669593811035,2,1,1,174.035720825195,0,173.99055480957,,,,,,,,,,,,,,,,,,,,,,,,,,,,,,,,,
,3832575391.69294,176.814079284668,9999.494140625,-7.11547199997125E-5,2.8565526035423E-8,1,2,13.4005146026611,4.99300564212207,29.5299999415874,-0.0946333522277571,-0.0139989795500242,1,-5.65153562385689E-7,,,,,,,,,,,,,,,,,,,,,176.76628112793,176.861877441406,9999.494140625,9999.494140625,47.16307403613,5.26801565215591,7.91927909851074,27,1,0,0,1,0.274276733398438,40.5669593811035,2,1,1,176.861877441406,0,176.814079284668,,,,,,,,,,,,,,,,,,,,,,,,,,,,,,,,,
,3832575450.19321,179.707374572754,9999.494140625,-7.13129180054279E-5,3.18953724327182E-8,1,2,13.4005146026611,4.99285151215573,29.5400004833937,-0.0948430430709198,-0.0140058739850817,1,-5.48657197008152E-7,,,,,,,,,,,,,,,,,,,,,179.65495300293,179.759796142578,9999.494140625,9999.494140625,47.1193028390531,5.26814267414762,7.91590595245361,27,1,0,0,1,0.274581909179687,40.5669593811035,2,1,1,179.759796142578,0,179.707374572754,,,,,,,,,,,,,,,,,,,,,,,,,,,,,,,,,
,3832575504.49821,182.425941467285,9999.494140625,-7.14692418455365E-5,3.7784984670324E-8,1,2,13.4005146026611,4.99305570632657,29.5499991625547,-0.0950550500937015,-0.014046114615533,1,-5.56433078828667E-7,,,,,,,,,,,,,,,,,,,,,182.371994018555,182.479888916016,9999.494140625,9999.494140625,47.0204268313704,5.26733316555257,7.94090890884399,27,1,0,0,1,0.287399291992187,40.5669593811035,2,1,1,182.479888916016,0,182.425941467285,,,,,,,,,,,,,,,,,,,,,,,,,,,,,,,,,
,3832575561.05796,185.253868103027,9999.494140625,-7.15843648626258E-5,2.57182840772439E-8,1,2,13.4005146026611,4.99302593924163,29.559999704361,-0.0952061865865605,-0.014077213899508,1,-5.63779983133717E-7,,,,,,,,,,,,,,,,,,,,,185.201110839844,185.306625366211,9999.494140625,9999.494140625,47.0446573154665,5.2672042718109,7.93987798690796,27,1,0,0,1,0.278472900390625,40.5669593811035,2,1,1,185.306625366211,0,185.253868103027,,,,,,,,,,,,,,,,,,,,,,,,,,,,,,,,,
,3832575615.2989,187.932907104492,9999.494140625,-7.16661755938408E-5,2.82117344644766E-8,1,2,13.4005146026611,4.99317236034943,29.5700002461672,-0.0953227449252597,-0.0140658249085803,1,-5.43362756143964E-7,,,,,,,,,,,,,,,,,,,,,187.883270263672,187.982543945313,9999.494140625,9999.494140625,47.046220572505,5.26653492566326,7.94752645492554,27,1,0,0,1,0.284194946289062,40.5669593811035,2,1,1,187.982543945313,0,187.932907104492,,,,,,,,,,,,,,,,,,,,,,,,,,,,,,,,,
,3832575671.88532,190.775238037109,9999.494140625,-7.17138765975754E-5,2.94226619868401E-8,1,2,13.4005146026611,4.99296408953506,29.5899994671345,-0.0953769532116864,-0.0141014646113108,1,-5.64064941572373E-7,,,,,,,,,,,,,,,,,,,,,190.716705322266,190.833770751953,9999.494140625,9999.494140625,47.0896009553223,5.26767152910308,7.94934368133545,27,1,0,0,1,0.274887084960938,40.5669593811035,2,1,1,190.833770751953,0,190.775238037109,,,,,,,,,,,,,,,,,,,,,,,,,,,,,,,,,
,3832575726.1336,193.451499938965,9999.494140625,-7.17610679677153E-5,3.17095697551927E-8,1,2,13.4005146026611,4.99295556110046,29.6000000089407,-0.0954453127708868,-0.0140690861141359,1,-5.33172696928434E-7,,,,,,,,,,,,,,,,,,,,,193.399291992187,193.503707885742,9999.494140625,9999.494140625,47.1282915670242,5.26738484892841,7.96358156204224,27,1,0,0,1,0.2850341796875,41.055721282959,2,1,1,193.503707885742,0,193.451499938965,,,,,,,,,,,,,,,,,,,,,,,,,,,,,,,,,
,3832575782.71421,196.31608581543,9999.494140625,-7.20151819140177E-5,2.94229624147175E-8,1,2,13.4005146026611,4.99306085277973,29.6100005507469,-0.0957802929314289,-0.0141605825865818,1,-5.66055363594724E-7,,,,,,,,,,,,,,,,,,,,,196.255676269531,196.376495361328,9999.494140625,9999.494140625,47.1349354094377,5.26731810489334,7.97745895385742,27,1,0,0,1,0.276718139648438,40.5669593811035,2,1,1,196.376495361328,0,196.31608581543,,,,,,,,,,,,,,,,,,,,,,,,,,,,,,,,,
,3832575836.99629,199.011444091797,9999.494140625,-7.21450113460242E-5,3.27065782489866E-8,1,2,13.4005146026611,4.9930395862389,29.619999229908,-0.095957567611164,-0.0141491146387109,1,-5.39351379408986E-7,,,,,,,,,,,,,,,,,,,,,198.963012695313,199.059875488281,9999.494140625,9999.494140625,47.1036702686684,5.26663793382913,7.9676194190979,27,1,0,0,1,0.287246704101562,40.5669593811035,2,1,1,199.059875488281,0,199.011444091797,,,,,,,,,,,,,,,,,,,,,,,,,,,,,,,,,
,3832575896.70024,201.984199523926,9999.494140625,-7.23656457681213E-5,3.89150242130002E-8,1,2,13.4005146026611,4.99263341244207,29.6299997717142,-0.0962375085485288,-0.014210742059807,1,-5.55977489751216E-7,,,,,,,,,,,,,,,,,,,,,201.896575927734,202.071823120117,9999.494140625,9999.494140625,47.1568210079761,5.26930734021721,7.99406051635742,27,1,0,0,1,0.274276733398438,41.055721282959,2,1,1,202.071823120117,0,201.984199523926,,,,,,,,,,,,,,,,,,,,,,,,,,,,,,,,,
,3832575953.79143,204.860961914062,9999.494140625,-7.25393523663622E-5,3.5245744313184E-8,1,2,13.4005146026611,4.99267896651149,29.6400003135204,-0.0964669926702295,-0.0142645618686198,1,-5.71981810396382E-7,,,,,,,,,,,,,,,,,,,,,204.813491821289,204.908432006836,9999.494140625,9999.494140625,47.0798305988319,5.26895756687201,7.98699140548706,27,1,0,0,1,0.27618408203125,40.5669593811035,2,1,1,204.908432006836,0,204.860961914062,,,,,,,,,,,,,,,,,,,,,,,,,,,,,,,,,
,3832576012.3614,207.740745544434,9999.494140625,-7.26588883537592E-5,6.31861063442689E-8,1,2,13.4005146026611,4.99292856071396,29.6500008553266,-0.0966341021066584,-0.0142781470180409,1,-5.64737640803574E-7,,,,,,,,,,,,,,,,,,,,,207.682922363281,207.798568725586,9999.494140625,9999.494140625,47.1669821787261,5.2664081557897,7.99715948104858,27,1,0,0,1,0.272369384765625,40.5669593811035,2,1,1,207.798568725586,0,207.740745544434,,,,,,,,,,,,,,,,,,,,,,,,,,,,,,,,,
,3832576068.73249,210.562614440918,9999.494140625,-7.27202444947986E-5,3.16496048830443E-8,1,2,13.4005146026611,4.99246405541674,29.6800006181002,-0.0967046687850708,-0.0142791211195139,1,-5.58257792478709E-7,,,,,,,,,,,,,,,,,,,,,210.516860961914,210.608367919922,9999.494140625,9999.494140625,47.1067967827454,5.26849291721861,8.00736713409424,27,1,0,0,1,0.273361206054687,40.5669593811035,2,1,1,210.608367919922,0,210.562614440918,,,,,,,,,,,,,,,,,,,,,,,,,,,,,,,,,
,3832576125.27359,213.382888793945,9999.494140625,-7.28502343128232E-5,2.83151075078313E-8,1,2,13.4005146026611,4.99235851440161,29.6899992972612,-0.0968767727084637,-0.0142895852709759,1,-5.48253791675715E-7,,,,,,,,,,,,,,,,,,,,,213.346939086914,213.418838500977,9999.494140625,9999.494140625,47.1314180811011,5.27001838990596,8.01824188232422,27,1,0,0,1,0.274810791015625,40.5669593811035,2,1,1,213.418838500977,0,213.382888793945,,,,,,,,,,,,,,,,,,,,,,,,,,,,,,,,,
,3832576179.56332,216.114730834961,9999.494140625,-7.31033875329609E-5,3.0258756584987E-8,1,2,13.4005146026611,4.99236775397286,29.6899992972612,-0.0972138413177097,-0.0143380114710879,1,-5.49207788986068E-7,,,,,,,,,,,,,,,,,,,,,216.074142456055,216.155319213867,9999.494140625,9999.494140625,47.1185212105338,5.27021469900353,8.02954864501953,27,1,0,0,1,0.273895263671875,41.055721282959,2,1,1,216.155319213867,0,216.114730834961,,,,,,,,,,,,,,,,,,,,,,,,,,,,,,,,,
,3832576234.15697,218.815055847168,9999.494140625,-7.3149556952846E-5,3.1548450207706E-8,1,2,13.4005146026611,4.99261023360661,29.6999998390675,-0.0972781055695946,-0.0143738209642439,1,-5.68933571201326E-7,,,,,,,,,,,,,,,,,,,,,218.759994506836,218.8701171875,9999.494140625,9999.494140625,47.1368894807358,5.26862776707534,8.03597068786621,27,1,0,0,1,0.273056030273438,41.055721282959,2,1,1,218.8701171875,0,218.815055847168,,,,,,,,,,,,,,,,,,,,,,,,,,,,,,,,,
,3832576290.43627,221.610206604004,9999.494140625,-7.32403308353274E-5,2.69000188474422E-8,1,2,13.4005146026611,4.99288423538295,29.7200009226799,-0.0974050872712522,-0.0144003167462813,1,-5.7533015093674E-7,,,,,,,,,,,,,,,,,,,,,221.568939208984,221.651473999023,9999.494140625,9999.494140625,47.1450965801877,5.26726866558622,8.05116558074951,27,1,0,0,1,0.276718139648438,40.5669593811035,2,1,1,221.651473999023,0,221.610206604004,,,,,,,,,,,,,,,,,,,,,,,,,,,,,,,,,
,3832576348.01561,224.481140136719,9999.494140625,-7.35089924966389E-5,2.56369612846883E-8,1,2,13.4005146026611,4.99311525808294,29.729999601841,-0.0977670971326631,-0.014464727996024,1,-5.8545518686844E-7,,,,,,,,,,,,,,,,,,,,,224.404556274414,224.557723999023,9999.494140625,9999.494140625,47.1091416683031,5.26628177334127,8.05911254882813,27,1,0,0,1,0.27618408203125,41.055721282959,2,1,1,224.557723999023,0,224.481140136719,,,,,,,,,,,,,,,,,,,,,,,,,,,,,,,,,
,3832576405.42074,227.375717163086,9999.494140625,-7.35939932504563E-5,2.56357009625532E-8,1,2,13.4005146026611,4.99303574818421,29.7500006854534,-0.0978824171303304,-0.0144496364235207,1,-5.62472645004029E-7,,,,,,,,,,,,,,,,,,,,,227.338653564453,227.412780761719,9999.494140625,9999.494140625,47.13259052388,5.26657742773426,8.07043266296387,26,1,64,0,0,0.284805297851562,41.055721282959,2,1,1,227.412780761719,0,227.375717163086,,,,,,,,,,,,,,,,,,,,,,,,,,,,,,,,,
,3832576461.56353,230.16357421875,9999.494140625,-7.37591492515424E-5,2.99720230761246E-8,1,2,13.4005146026611,4.99299696588892,29.7599993646145,-0.0981011391258791,-0.0144811709061342,1,-5.63180228276951E-7,,,,,,,,,,,,,,,,,,,,,230.115036010742,230.212112426758,9999.494140625,9999.494140625,47.2216961750723,5.26705496089153,8.09153366088867,27,1,0,0,1,0.272674560546875,41.055721282959,2,1,1,230.212112426758,0,230.16357421875,,,,,,,,,,,,,,,,,,,,,,,,,,,,,,,,,
,3832576517.98261,232.953842163086,9999.494140625,-7.39578459129815E-5,2.52473092172636E-8,1,2,13.4005146026611,4.99284839505564,29.7699999064207,-0.098359619085227,-0.0145323175890678,1,-5.74257705319534E-7,,,,,,,,,,,,,,,,,,,,,232.902694702148,233.004989624023,9999.494140625,9999.494140625,47.086865255505,5.26811231437799,8.10533046722412,27,1,0,0,1,0.28656005859375,40.5669593811035,2,1,1,233.004989624023,0,232.953842163086,,,,,,,,,,,,,,,,,,,,,,,,,,,,,,,,,
,3832576574.62773,235.782974243164,9999.494140625,-7.4128978079191E-5,3.38568749720621E-8,1,2,13.4005146026611,4.99299732430484,29.7800004482269,-0.098593690306878,-0.0145490480737402,1,-5.62449265746044E-7,,,,,,,,,,,,,,,,,,,,,235.720748901367,235.845199584961,9999.494140625,9999.494140625,47.1658097359473,5.26626501702294,8.12952709197998,27,1,0,0,1,0.276641845703125,40.5669593811035,2,1,1,235.845199584961,0,235.782974243164,,,,,,,,,,,,,,,,,,,,,,,,,,,,,,,,,
,3832576630.92397,238.60669708252,9999.494140625,-7.41661202794707E-5,2.80601621815621E-8,1,2,13.4005146026611,4.99304924138456,29.7999996691942,-0.098643685380253,-0.0145623428784252,1,-5.67085414546494E-7,,,,,,,,,,,,,,,,,,,,,238.568801879883,238.644592285156,9999.494140625,9999.494140625,47.0774857132742,5.26664764007501,8.14928245544434,27,1,0,0,1,0.275650024414062,41.055721282959,2,1,1,238.644592285156,0,238.60669708252,,,,,,,,,,,,,,,,,,,,,,,,,,,,,,,,,
,3832576685.74817,241.324897766113,9999.494140625,-7.44661026819209E-5,2.61113601119326E-8,1,2,13.4005146026611,4.99291279291688,29.8100002110004,-0.0990405861686624,-0.0146090960007984,1,-5.60666418504226E-7,,,,,,,,,,,,,,,,,,,,,241.277038574219,241.372756958008,9999.494140625,9999.494140625,47.1001529403319,5.26736621503727,8.16287517547607,26,1,64,0,0,0.275955200195313,41.055721282959,2,1,1,241.372756958008,0,241.324897766113,,,,,,,,,,,,,,,,,,,,,,,,,,,,,,,,,
,3832576743.58979,244.20645904541,9999.494140625,-7.45799873911273E-5,3.16985090985198E-8,1,2,13.4005146026611,4.99280026021434,29.8299994319677,-0.0991843439078513,-0.014664217275174,1,-5.86483701205831E-7,,,,,,,,,,,,,,,,,,,,,244.163223266602,244.249694824219,9999.494140625,9999.494140625,47.1114865538608,5.2680217445726,8.18091106414795,27,1,0,0,1,0.276336669921875,41.055721282959,2,1,1,244.249694824219,0,244.20645904541,,,,,,,,,,,,,,,,,,,,,,,,,,,,,,,,,
,3832576799.31209,247.007965087891,9999.494140625,-7.47458261370484E-5,2.71725691037858E-8,1,2,13.4005146026611,4.99275705372256,29.839999973774,-0.0994000681100271,-0.0147227331122732,1,-6.0737859479886E-7,,,,,,,,,,,,,,,,,,,,,246.919006347656,247.096923828125,9999.494140625,9999.494140625,47.137671109255,5.26842534293286,8.21514797210693,27,1,0,0,1,0.274810791015625,40.5669593811035,2,1,1,247.096923828125,0,247.007965087891,,,,,,,,,,,,,,,,,,,,,,,,,,,,,,,,,
,3832576856.46313,249.826942443848,9999.494140625,-7.48482634154647E-5,2.90816823388235E-8,1,2,13.4005146026611,4.99264825220564,29.8599991947412,-0.0995451526497929,-0.0146578502284348,1,-5.44649910438518E-7,,,,,,,,,,,,,,,,,,,,,249.773239135742,249.880645751953,9999.494140625,9999.494140625,47.1974656909762,5.26894920052068,8.24890041351318,27,1,0,0,1,0.27191162109375,40.5669593811035,2,1,1,249.880645751953,0,249.826942443848,,,,,,,,,,,,,,,,,,,,,,,,,,,,,,,,,
,3832576915.03282,252.75138092041,9999.494140625,-7.50472814166261E-5,2.69933641953945E-8,1,2,13.4005146026611,4.99262008716526,29.8699997365475,-0.0997994022631513,-0.0147658323409664,1,-5.98018042732502E-7,,,,,,,,,,,,,,,,,,,,,252.696029663086,252.806732177734,9999.494140625,9999.494140625,47.1435333231492,5.26896011789486,8.28840351104736,27,1,0,0,1,0.276641845703125,41.055721282959,2,1,1,252.806732177734,0,252.75138092041,,,,,,,,,,,,,,,,,,,,,,,,,,,,,,,,,
,3832576969.30503,255.483200073242,9999.494140625,-7.51055005287655E-5,2.73359698696221E-8,1,2,13.4005146026611,4.99273298006267,29.899999499321,-0.0998841995536001,-0.0147471243571119,1,-5.75482127776989E-7,,,,,,,,,,,,,,,,,,,,,255.419937133789,255.546463012695,9999.494140625,9999.494140625,47.0997621260723,5.26846867753785,8.34239292144775,27,1,0,0,1,0.275344848632813,40.5669593811035,2,1,1,255.546463012695,0,255.483200073242,,,,,,,,,,,,,,,,,,,,,,,,,,,,,,,,,
,3832577025.87843,258.295227050781,9999.494140625,-7.52506325906954E-5,3.03310528682641E-8,1,2,13.4005146026611,4.99263362853322,29.899999499321,-0.100071675010324,-0.0147953106363969,1,-5.91686252901189E-7,,,,,,,,,,,,,,,,,,,,,258.233306884766,258.357147216797,9999.494140625,9999.494140625,47.0770948990146,5.26909588068528,8.38418865203857,27,1,0,0,1,0.278472900390625,41.055721282959,2,1,1,258.357147216797,0,258.295227050781,,,,,,,,,,,,,,,,,,,,,,,,,,,,,,,,,
,3832577084.09209,261.178756713867,9999.494140625,-7.53844174699592E-5,2.41789733276019E-8,1,2,13.4005146026611,4.99262198386909,29.9200005829334,-0.100251278331434,-0.0148071875028159,1,-5.81936967799657E-7,,,,,,,,,,,,,,,,,,,,,261.119995117187,261.237518310547,9999.494140625,9999.494140625,47.1251650529473,5.26931531468286,8.37063789367676,27,1,0,0,1,0.277099609375,41.055721282959,2,1,1,261.237518310547,0,261.178756713867,,,,,,,,,,,,,,,,,,,,,,,,,,,,,,,,,
,3832577142.5325,264.123321533203,9999.494140625,-7.56363361351777E-5,3.03516920246833E-8,1,2,13.4005146026611,4.99245224711141,29.9399998039007,-0.100583370719588,-0.0148433881163853,1,-5.74424588200289E-7,,,,,,,,,,,,,,,,,,,,,264.083068847656,264.16357421875,9999.494140625,9999.494140625,47.1435333231492,5.27053914337815,8.34740924835205,27,1,0,0,1,0.27435302734375,41.055721282959,2,1,1,264.16357421875,0,264.123321533203,,,,,,,,,,,,,,,,,,,,,,,,,,,,,,,,,
,3832577199.01055,266.919692993164,9999.494140625,-7.57629035452551E-5,3.07236224934715E-8,1,2,13.4005146026611,4.99250321326776,29.9600008875132,-0.100748704093925,-0.0148998255125922,1,-5.98965665988656E-7,,,,,,,,,,,,,,,,,,,,,266.869079589844,266.970306396484,9999.494140625,9999.494140625,47.1189120247934,5.26990952372749,8.33719444274902,27,1,0,0,1,0.275039672851562,41.055721282959,2,1,1,266.970306396484,0,266.919692993164,,,,,,,,,,,,,,,,,,,,,,,,,,,,,,,,,
,3832577255.55825,269.752960205078,9999.494140625,-7.60987318357453E-5,3.2422472364766E-8,1,2,13.4005146026611,4.99233538673475,29.9600008875132,-0.101196021245279,-0.0149265742382042,1,-5.72618904677933E-7,,,,,,,,,,,,,,,,,,,,,269.697662353516,269.808258056641,9999.494140625,9999.494140625,47.1462690229665,5.27023900344446,8.34417819976807,27,1,0,0,1,0.275650024414062,40.5669593811035,2,1,1,269.808258056641,0,269.752960205078,,,,,,,,,,,,,,,,,,,,,,,,,,,,,,,,,
,3832577311.88219,272.546798706055,9999.494140625,-7.62381774542682E-5,3.14841576774367E-8,1,2,13.4005146026611,4.9922049714657,29.9800001084805,-0.10137519333321,-0.014972222125211,1,-5.87814840102078E-7,,,,,,,,,,,,,,,,,,,,,272.509460449219,272.584136962891,9999.494140625,9999.494140625,47.0946815406973,5.270575955215,8.34972763061523,27,1,0,0,1,0.273590087890625,40.5669593811035,2,1,1,272.584136962891,0,272.546798706055,,,,,,,,,,,,,,,,,,,,,,,,,,,,,,,,,
,3832577368.44298,275.362396240234,9999.494140625,-7.64106105860376E-5,3.55681569802701E-8,1,2,13.4005146026611,4.99226268915446,29.9999993294477,-0.101607143223287,-0.0149987945366387,1,-5.83488379876975E-7,,,,,,,,,,,,,,,,,,,,,275.327819824219,275.39697265625,9999.494140625,9999.494140625,47.1040610829281,5.27060758994468,8.37552833557129,27,1,0,0,1,0.278244018554687,41.055721282959,2,1,1,275.39697265625,0,275.362396240234,,,,,,,,,,,,,,,,,,,,,,,,,,,,,,,,,
,3832577424.90509,278.201965332031,9999.494140625,-7.67244297169054E-5,3.070985999287E-8,1,2,13.4005146026611,4.99223458386939,30.009999871254,-0.102021323579779,-0.0150769713493182,1,-5.98424796470208E-7,,,,,,,,,,,,,,,,,,,,,278.162780761719,278.241149902344,9999.494140625,9999.494140625,47.1310272668415,5.27092381962166,8.4114933013916,27,1,0,0,1,0.2777099609375,41.055721282959,2,1,1,278.241149902344,0,278.201965332031,,,,,,,,,,,,,,,,,,,,,,,,,,,,,,,,,
,3832577480.28406,280.948547363281,9999.494140625,-7.69715962712806E-5,3.00993433178328E-8,1,2,13.4005146026611,4.99229616741094,30.0399996340275,-0.102351477322223,-0.0151274900799194,1,-6.01624253915325E-7,,,,,,,,,,,,,,,,,,,,,280.860717773438,281.036376953125,9999.494140625,9999.494140625,47.107187597005,5.27101936778216,8.44755172729492,27,1,0,0,1,0.27587890625,40.5669593811035,2,1,1,281.036376953125,0,280.948547363281,,,,,,,,,,,,,,,,,,,,,,,,,,,,,,,,,
,3832577535.74144,283.615631103516,9999.494140625,-7.72730241259922E-5,3.17131533580951E-8,1,2,13.4005146026611,4.99214857846214,30.0399996340275,-0.102750746114605,-0.015167419640929,1,-5.89935239569828E-7,,,,,,,,,,,,,,,,,,,,,283.581665039062,283.649597167969,9999.494140625,9999.494140625,47.1826147491108,5.27142399244638,8.51235580444336,27,1,0,0,1,0.275039672851562,40.5669593811035,2,1,1,283.649597167969,0,283.615631103516,,,,,,,,,,,,,,,,,,,,,,,,,,,,,,,,,
,3832577593.88455,286.460479736328,9999.494140625,-7.76201099996946E-5,2.33471847126656E-8,1,2,13.4005146026611,4.99220810654702,30.0600007176399,-0.103207817995006,-0.0152796985126467,1,-6.2556596454253E-7,,,,,,,,,,,,,,,,,,,,,286.401824951172,286.519134521484,9999.494140625,9999.494140625,47.1200844675723,5.27108513038022,8.60072994232178,27,1,0,0,1,0.274429321289062,40.5669593811035,2,1,1,286.519134521484,0,286.460479736328,,,,,,,,,,,,,,,,,,,,,,,,,,,,,,,,,
,3832577650.25273,289.41178894043,9999.494140625,-7.7879337501395E-5,3.18099973699719E-8,1,2,13.4005146026611,4.99253646976782,30.0900004804134,-0.10356269714728,-0.0153259447796234,1,-6.23024095741437E-7,,,,,,,,,,,,,,,,,,,,,289.351013183594,289.472564697266,9999.494140625,9999.494140625,47.1673729929858,5.26975753984857,8.71981525421143,27,1,0,0,1,0.273895263671875,40.5669593811035,2,1,1,289.472564697266,0,289.41178894043,,,,,,,,,,,,,,,,,,,,,,,,,,,,,,,,,
,3832577706.83509,292.328262329102,9999.494140625,-7.81615145328294E-5,2.28825713833363E-8,1,2,13.4005146026611,4.99245954256538,30.1099997013807,-0.103936663746023,-0.0153745210945005,1,-6.20302103033577E-7,,,,,,,,,,,,,,,,,,,,,292.272827148438,292.383697509766,9999.494140625,9999.494140625,47.147832280005,5.27025526395325,8.85295009613037,27,1,0,0,1,0.275115966796875,40.5669593811035,2,1,1,292.383697509766,0,292.328262329102,,,,,,,,,,,,,,,,,,,,,,,,,,,,,,,,,
,3832577763.45522,295.169097900391,9999.494140625,-7.83793343213129E-5,2.47334903270735E-8,1,2,13.4005146026611,4.99254231229311,30.120000243187,-0.104229120670922,-0.0154145761689013,1,-6.19671525347196E-7,,,,,,,,,,,,,,,,,,,,,295.110900878906,295.227294921875,9999.494140625,9999.494140625,47.1118773681204,5.27030571844589,8.98853206634521,27,1,0,0,1,0.274581909179687,41.055721282959,2,1,1,295.227294921875,0,295.169097900391,,,,,,,,,,,,,,,,,,,,,,,,,,,,,,,,,
,3832577819.71078,297.970657348633,9999.494140625,-7.85544822811853E-5,2.84767422902823E-8,1,2,13.4005146026611,4.99231837736488,30.1300007849932,-0.104458040649029,-0.0154307019493583,1,-6.08007592404347E-7,,,,,,,,,,,,,,,,,,,,,297.935455322266,298.005859375,9999.494140625,9999.494140625,47.1744076496588,5.27056546195608,8.95867347717285,27,1,0,0,1,0.27679443359375,40.5669593811035,2,1,1,298.005859375,0,297.970657348633,,,,,,,,,,,,,,,,,,,,,,,,,,,,,,,,,
,3832577876.20288,299.702133178711,9999.494140625,-7.84568719683719E-5,2.38795469194878E-8,1,2,13.4005146026611,4.99229421419587,30.1399994641542,-0.104329099963006,-0.0154003480004433,1,-5.98930314464865E-7,,,,,,,,,,,,,,,,,,,,,299.697113037109,299.707153320313,9999.494140625,9999.494140625,47.1490047227838,5.27125294758609,8.94184303283691,27,1,0,0,1,0.275497436523438,41.055721282959,5,1,1,299.707153320313,0,299.702133178711,,,,,,,,,,,,,,,,,,,,,,,,,,,,,,,,,
,3832577920.38316,299.894287109375,9999.494140625,-7.83971778340802E-5,3.27993689274461E-8,1,2,13.4005146026611,4.99219999597402,30.1399994641542,-0.104247177114123,-0.0153871411017621,1,-5.97654663644097E-7,,,,,,,,,,,,,,,,,,,,,299.892852783203,299.895721435547,9999.494140625,9999.494140625,47.1998105765338,5.27138672012662,8.93176555633545,27,1,0,0,1,0.275497436523438,40.5669593811035,1,1,1,299.895721435547,0,299.894287109375,,,,,,,,,,,,,,,,,,,,,,,,,,,,,,,,,