File: SI Fig S11-13 SQUID all/Michaela_Gd_FC1T.dat
[Header]
; MPMS3 Data File (default extension .dat)
; Copyright (c) 2007, Quantum Design, Inc. All rights reserved.
TITLE,
FILEOPENTIME,3832343540.87727,06/08/2021,7:52 pm
BYAPP,MPMS3 w/ AC,1.0,1.1
INFO,MPMS3 Measurement Release 1.1.16 Build 424, MultiVu Release 2.3.4.19,APPNAME
INFO,Linear Motor Servo Controller,MOTOR_MODULE_NAME
INFO,3101-100 E1,MOTOR_HW_VERSION
INFO,MMC211,MOTOR_SERIAL_NUMBER
INFO,01.04.28,MOTOR_SOFTWARE_VERSION
INFO,Quantum Design Squid Module,SQUID_MODULE_NAME
INFO,3101-501 B0,SQUID_HW_VERSION
INFO,SQM059,SQUID_SERIAL_NUMBER
INFO,01.03.04,SQUID_SOFTWARE_VERSION
INFO,SQUID AC,AC_MODULE_NAME
INFO,3101-401 F1,AC_HW_VERSION
INFO,SAC057,AC_SERIAL_NUMBER
INFO,SQUID AC 00.95.07,AC_SOFTWARE_VERSION
INFO,TCIXXX,COIL_SERIAL_NUMBER
INFO,0,MOMENT_UNITS
INFO,Michaela_Gd,SAMPLE_MATERIAL
INFO,Michaela_Gd,SAMPLE_COMMENT
INFO,0.9,SAMPLE_MASS
INFO,,SAMPLE_VOLUME
INFO,,SAMPLE_MOLECULAR_WEIGHT
INFO,,SAMPLE_SIZE
INFO,,SAMPLE_SHAPE
INFO,Straw,SAMPLE_HOLDER
INFO,Standard,SAMPLE_HOLDER_DETAIL
INFO,54.44,SAMPLE_OFFSET
DATATYPE,COMMENT,1
DATATYPE,TIME,2
STARTUPAXIS,X,2
STARTUPAXIS,Y1,5
FIELDGROUP, VSM,2,3,4,5,6,8,9,10,11,14,15
FIELDGROUP, DC, 2,3,4,14,56,57,58,59,60,61,62,63,64,65,66,67,68,69
FIELDGROUP, AC, 2,3,4,11,16,17,18,19,20,21,22,23,24,25,26,27,28,29,30
STARTUPGROUP, All
[Data]
Comment,Time Stamp (sec),Temperature (K),Magnetic Field (Oe),Moment (emu),M. Std. Err. (emu),Transport Action,Averaging Time (sec),Frequency (Hz),Peak Amplitude (mm),Center Position (mm),Lockin Signal' (V),Lockin Signal (V),Range,M. Quad. Signal (emu),AC Moment (emu),AC M. Std Err. (emu),AC Phase (deg),AC Phase Std. Err. (deg),AC Susceptibility (emu/Oe),AC Suscept. Std Err. (emu/Oe),AC X' (emu/Oe),AC X' Std Err. (emu/Oe),AC X'' (emu/Oe),AC X'' Std Err. (emu/Oe),AC Drive (Oe),AC Frequency (Hz),AC Averaging Time (sec),AC Cycles,AC Range,AC Measure Type,AC Signal' (V),AC Signal'' (V),AC Trim Coil Ratio,AC Trim Coil Phase,Min. Temperature (K),Max. Temperature (K),Min. Field (Oe),Max. Field (Oe),Mass (grams),Motor Lag (deg),Pressure (Torr),Measure Count,Measurement Number,SQUID Status (code),Motor Status (code),Measure Status (code),Motor Current (amps),Motor Temp. (C),Temp. Status (code),Field Status (code),Chamber Status (code),Chamber Temp (K),Redirection State,Average Temp (K),Rotation Angle (deg),Rotator state,DC Moment Fixed Ctr (emu),DC Moment Err Fixed Ctr (emu),DC Moment Free Ctr (emu),DC Moment Err Free Ctr (emu),DC Fixed Fit,DC Free Fit,DC Calculated Center (mm),DC Calculated Center Err (mm),DC Scan Length (mm),DC Scan Time (s),DC Number of Points,DC Squid Drift,DC Min V (V),DC Max V (V),DC Scans per Measure,Map 01,Map 02,Map 03,Map 04,Map 05,Map 06,Map 07,Map 08,Map 09,Map 10,Map 11,Map 12,Map 13,Map 14,Map 15,Map 16
,3832343546.93682,299.921661376953,9999.8056640625,0.000198314068282119,2.9689831610938E-8,1,2,13.4005146026611,4.99291125903476,32.5799994170666,0.26371636211772,0.0392138162976101,1,1.72423261543995E-6,,,,,,,,,,,,,,,,,,,,,299.921661376953,299.921661376953,9999.8056640625,9999.8056640625,47.1490047227838,5.27128655347688,9.17324638366699,27,1,0,0,1,0.277252197265625,38.6119270324707,1,1,1,299.921661376953,0,299.921661376953,,,,,,,,,,,,,,,,,,,,,,,,,,,,,,,,,
,3832343598.70508,298.256301879883,9999.8056640625,0.000200828353648215,3.45133767283286E-8,1,2,13.4005146026611,4.99294326831287,32.5799994170666,0.267061337332135,0.0397173819150518,1,1.75063862493259E-6,,,,,,,,,,,,,,,,,,,,,298.208465576172,298.304138183594,9999.8056640625,9999.8056640625,47.1896494057838,5.2710390416039,9.13767242431641,27,1,0,0,1,0.285797119140625,38.6119270324707,2,1,1,298.208465576172,0,298.256301879883,,,,,,,,,,,,,,,,,,,,,,,,,,,,,,,,,
,3832343651.14355,295.598495483398,9999.8056640625,0.000203317465113822,1.87956726178116E-8,1,2,13.4005146026611,4.99293769045737,32.5599983334541,0.27034894519932,0.040366901737584,1,1.89049246694947E-6,,,,,,,,,,,,,,,,,,,,,295.559967041016,295.637023925781,9999.8056640625,9999.8056640625,47.1540853081588,5.27165559205565,9.10749435424805,27,1,0,0,1,0.274124145507813,38.6119270324707,2,1,1,295.559967041016,0,295.598495483398,,,,,,,,,,,,,,,,,,,,,,,,,,,,,,,,,
,3832343703.3552,292.954818725586,9999.8056640625,0.000206316130096119,4.1361573671842E-8,1,2,13.4005146026611,4.99290505034409,32.5599983334541,0.274349620915591,0.040848590750024,1,1.83327481423214E-6,,,,,,,,,,,,,,,,,,,,,292.911437988281,292.998199462891,9999.8056640625,9999.8056640625,47.1552577509377,5.27116948590051,9.08499431610107,27,1,0,0,1,0.276870727539062,38.6119270324707,2,1,1,292.911437988281,0,292.954818725586,,,,,,,,,,,,,,,,,,,,,,,,,,,,,,,,,
,3832343755.74827,290.364471435547,9999.8056640625,0.00020880801189567,3.45085592569078E-8,1,2,13.4005146026611,4.99290040256428,32.540000975132,0.27766448597781,0.0413302458067719,1,1.84665895048709E-6,,,,,,,,,,,,,,,,,,,,,290.319152832031,290.409790039063,9999.8056640625,9999.8056640625,47.1626832218704,5.27166347602131,9.06539154052734,27,1,0,0,1,0.28594970703125,38.6119270324707,2,1,1,290.319152832031,0,290.364471435547,,,,,,,,,,,,,,,,,,,,,,,,,,,,,,,,,
,3832343808.13396,287.701644897461,9999.8056640625,0.000211674658559972,3.30229925861795E-8,1,2,13.4005146026611,4.99291183984129,32.5299985706806,0.281480314569821,0.0418763736625506,1,1.85592954558591E-6,,,,,,,,,,,,,,,,,,,,,287.655059814453,287.748229980469,9999.8056640625,9999.8056640625,47.1404068090723,5.27177569382964,9.04596996307373,27,1,0,0,1,0.276031494140625,38.6119270324707,2,1,1,287.655059814453,0,287.701644897461,,,,,,,,,,,,,,,,,,,,,,,,,,,,,,,,,
,3832343860.61972,285.070373535156,9999.8056640625,0.000214359376002918,2.50820458502387E-8,1,2,13.4005146026611,4.99289760195301,32.5100012123585,0.285044244565388,0.0424433416655161,1,1.90651249672927E-6,,,,,,,,,,,,,,,,,,,,,285.021453857422,285.119293212891,9999.8056640625,9999.8056640625,47.2025462763511,5.27143427059719,9.03849029541016,27,1,0,0,1,0.274276733398438,38.6119270324707,2,1,1,285.021453857422,0,285.070373535156,,,,,,,,,,,,,,,,,,,,,,,,,,,,,,,,,
,3832343913.02604,282.441482543945,9999.8056640625,0.000217038370000009,2.96401695636315E-8,1,2,13.4005146026611,4.99288680526894,32.490000128746,0.288660144143453,0.0425848465531701,1,1.63830809882122E-6,,,,,,,,,,,,,,,,,,,,,282.395538330078,282.487426757813,9999.8056640625,9999.8056640625,47.0935090979185,5.27199728054275,9.01141548156738,27,1,0,0,1,0.27679443359375,38.6119270324707,2,1,1,282.395538330078,0,282.441482543945,,,,,,,,,,,,,,,,,,,,,,,,,,,,,,,,,
,3832343965.26029,279.8271484375,9999.8056640625,0.000220439780929397,3.53501784841501E-8,1,2,13.4005146026611,4.99288555999208,32.490000128746,0.293184635429162,0.0432470058181735,1,1.66006824845288E-6,,,,,,,,,,,,,,,,,,,,,279.785095214844,279.869201660156,9999.8056640625,9999.8056640625,47.1693270642838,5.27225927697563,8.99445152282715,27,1,0,0,1,0.276260375976562,38.6119270324707,2,1,1,279.785095214844,0,279.8271484375,,,,,,,,,,,,,,,,,,,,,,,,,,,,,,,,,
,3832344017.67222,277.191528320313,9999.8056640625,0.000223274654154214,3.36498422312504E-8,1,2,13.4005146026611,4.9929232958834,32.4699990451336,0.296948456159552,0.0438725119094905,1,1.73316068086271E-6,,,,,,,,,,,,,,,,,,,,,277.147399902344,277.235656738281,9999.8056640625,9999.8056640625,47.1697178785434,5.27147335171895,8.97762584686279,27,1,0,0,1,0.285797119140625,38.6119270324707,2,1,1,277.147399902344,0,277.191528320313,,,,,,,,,,,,,,,,,,,,,,,,,,,,,,,,,
,3832344070.04422,274.526000976562,9999.8056640625,0.000226674251643124,3.23406390585011E-8,1,2,13.4005146026611,4.99292154051231,32.4699990451336,0.301479153048955,0.0444726852788261,1,1.70861797488824E-6,,,,,,,,,,,,,,,,,,,,,274.470306396484,274.581695556641,9999.8056640625,9999.8056640625,47.1544761224185,5.27185059707886,8.96356010437012,27,1,0,0,1,0.285720825195313,38.6119270324707,2,1,1,274.470306396484,0,274.526000976562,,,,,,,,,,,,,,,,,,,,,,,,,,,,,,,,,
,3832344122.54856,271.915969848633,9999.8056640625,0.00022963883061918,3.2190415890231E-8,1,2,13.4005146026611,4.99287433182537,32.4500016868114,0.305419071902267,0.0450469135907913,1,1.72583596114582E-6,,,,,,,,,,,,,,,,,,,,,271.876983642578,271.954956054687,9999.8056640625,9999.8056640625,47.2728928430819,5.27211352353336,8.96180725097656,27,1,0,0,1,0.275726318359375,38.6119270324707,2,1,1,271.876983642578,0,271.915969848633,,,,,,,,,,,,,,,,,,,,,,,,,,,,,,,,,
,3832344175.31667,269.310272216797,9999.8056640625,0.000232790699758191,5.18949957576579E-8,1,2,13.4005146026611,4.99285540704525,32.430000603199,0.309606205866376,0.0456881039283783,1,1.76690674082175E-6,,,,,,,,,,,,,,,,,,,,,269.2861328125,269.334411621094,9999.8056640625,9999.8056640625,47.2041095333896,5.2714274283077,8.93182373046875,26,1,64,0,0,0.272293090820313,38.6119270324707,2,1,1,269.2861328125,0,269.310272216797,,,,,,,,,,,,,,,,,,,,,,,,,,,,,,,,,
,3832344227.19188,266.658996582031,9999.8056640625,0.000236165979197014,3.65524982145603E-8,1,2,13.4005146026611,4.9928501166156,32.430000603199,0.3140910545598,0.0463772134127865,1,1.81260657639524E-6,,,,,,,,,,,,,,,,,,,,,266.618377685547,266.699615478516,9999.8056640625,9999.8056640625,47.1150038821973,5.27225834325056,8.93537330627441,27,1,0,0,1,0.276336669921875,38.6119270324707,2,1,1,266.608489990234,0,266.658996582031,,,,,,,,,,,,,,,,,,,,,,,,,,,,,,,,,
,3832344279.57538,264.113235473633,9999.8056640625,0.000239467029914482,2.92748172229184E-8,1,2,13.4005146026611,4.99282281531808,32.4199981987476,0.318475473706662,0.047049826117595,1,1.85650950796411E-6,,,,,,,,,,,,,,,,,,,,,264.055358886719,264.171112060547,9999.8056640625,9999.8056640625,47.066542914005,5.27231713462851,8.90706825256348,27,1,0,0,1,0.274658203125,38.6119270324707,2,1,1,264.055358886719,0,264.113235473633,,,,,,,,,,,,,,,,,,,,,,,,,,,,,,,,,
,3832344331.96301,261.520690917969,9999.8056640625,0.000242491574207034,4.53756396687509E-8,1,2,13.4005146026611,4.9928063930817,32.4000008404255,0.322501558195903,0.0476074465384582,1,1.8526033078137E-6,,,,,,,,,,,,,,,,,,,,,261.4697265625,261.571655273438,9999.8056640625,9999.8056640625,47.1239926101684,5.27194230031386,8.91168117523193,27,1,0,0,1,0.276718139648438,38.6119270324707,2,1,1,261.4697265625,0,261.520690917969,,,,,,,,,,,,,,,,,,,,,,,,,,,,,,,,,
,3832344384.49133,258.898071289062,9999.8056640625,0.000246166719617587,3.51382309645764E-8,1,2,13.4005146026611,4.99283539215993,32.4099995195866,0.327391553023795,0.0483319967822901,1,1.88266254768323E-6,,,,,,,,,,,,,,,,,,,,,258.843231201172,258.952911376953,9999.8056640625,9999.8056640625,47.1107049253415,5.27179688035728,8.88370990753174,27,1,0,0,1,0.274658203125,38.1231689453125,2,1,1,258.843231201172,0,258.898071289062,,,,,,,,,,,,,,,,,,,,,,,,,,,,,,,,,
,3832344436.87678,256.27653503418,9999.8056640625,0.000249337858029499,2.75000022471497E-8,1,2,13.4005146026611,4.99278868882948,32.379999756813,0.331608089307407,0.0489303552542257,1,1.88916609678759E-6,,,,,,,,,,,,,,,,,,,,,256.233215332031,256.319854736328,9999.8056640625,9999.8056640625,47.1845688204088,5.27265860610316,8.8720235824585,27,1,0,0,1,0.27496337890625,38.6119270324707,2,1,1,256.233215332031,0,256.27653503418,,,,,,,,,,,,,,,,,,,,,,,,,,,,,,,,,
,3832344489.16121,253.637809753418,9999.8056640625,0.000253014165581132,4.16170161507953E-8,1,2,13.4005146026611,4.99280910897837,32.379999756813,0.336497710206447,0.0496634340929586,1,1.92555125967732E-6,,,,,,,,,,,,,,,,,,,,,253.59684753418,253.678771972656,9999.8056640625,9999.8056640625,47.1876953344858,5.2721609524518,8.85631656646729,27,1,0,0,1,0.27587890625,38.6119270324707,2,1,1,253.59684753418,0,253.637809753418,,,,,,,,,,,,,,,,,,,,,,,,,,,,,,,,,
,3832344541.5093,251.015014648438,9999.8056640625,0.000256309439478604,3.4218501121584E-8,1,2,13.4005146026611,4.9928089008575,32.3599986732006,0.340877588053863,0.050329361296833,1,1.96498345071135E-6,,,,,,,,,,,,,,,,,,,,,250.963073730469,251.066955566406,9999.8056640625,9999.8056640625,47.0739683849377,5.27213507031118,8.86535739898682,27,1,0,0,1,0.287094116210938,38.6119270324707,2,1,1,250.963073730469,0,251.015014648438,,,,,,,,,,,,,,,,,,,,,,,,,,,,,,,,,
,3832344593.88661,248.418251037598,9999.8056640625,0.000260171386083554,4.52803290139874E-8,1,2,13.4005146026611,4.99282631087922,32.3599986732006,0.346020883741454,0.0510488673936938,1,1.96524048796336E-6,,,,,,,,,,,,,,,,,,,,,248.373458862305,248.463043212891,9999.8056640625,9999.8056640625,47.1314180811011,5.27191811841267,8.83532047271729,27,1,0,0,1,0.27618408203125,38.6119270324707,2,1,1,248.373458862305,0,248.418251037598,,,,,,,,,,,,,,,,,,,,,,,,,,,,,,,,,
,3832344646.50278,245.795585632324,9999.8056640625,0.000263539728774126,4.22959496982883E-8,1,2,13.4005146026611,4.9927803195363,32.3400013148785,0.350496989049035,0.0517039383211263,1,1.98678761086589E-6,,,,,,,,,,,,,,,,,,,,,245.739486694336,245.851684570313,9999.8056640625,9999.8056640625,47.1665913644665,5.27304698921606,8.83087730407715,27,1,0,0,1,0.276336669921875,38.6119270324707,2,1,1,245.739486694336,0,245.795585632324,,,,,,,,,,,,,,,,,,,,,,,,,,,,,,,,,
,3832344698.85847,243.205429077148,9999.8056640625,0.000267423397239865,5.08057889390348E-8,1,2,13.4005146026611,4.99280577788367,32.3400013148785,0.355673744729635,0.0524007929725322,1,1.96690616538236E-6,,,,,,,,,,,,,,,,,,,,,243.167831420898,243.243026733398,9999.8056640625,9999.8056640625,47.1861320774473,5.27258040348096,8.82066822052002,27,1,0,0,1,0.273971557617187,38.6119270324707,2,1,1,243.167831420898,0,243.205429077148,,,,,,,,,,,,,,,,,,,,,,,,,,,,,,,,,
,3832344751.04641,240.570159912109,9999.8056640625,0.00027091389639575,3.60276766302595E-8,1,2,13.4005146026611,4.99273864836161,32.320000231266,0.360299569330407,0.0531546343095966,1,2.04580829731677E-6,,,,,,,,,,,,,,,,,,,,,240.508148193359,240.632171630859,9999.8056640625,9999.8056640625,47.0618531428896,5.2722716303785,8.8065938949585,27,1,0,0,1,0.278396606445313,38.6119270324707,2,1,1,240.508148193359,0,240.570159912109,,,,,,,,,,,,,,,,,,,,,,,,,,,,,,,,,
,3832344803.4625,237.968185424805,9999.8056640625,0.000274728598673652,3.18415844870408E-8,1,2,13.4005146026611,4.99275582854282,32.3100015521049,0.365375673018223,0.0538958363299097,1,2.06897008535876E-6,,,,,,,,,,,,,,,,,,,,,237.910766601562,238.025604248047,9999.8056640625,9999.8056640625,47.08178467013,5.27345519780926,8.79659271240234,27,1,0,0,1,0.2764892578125,38.6119270324707,2,1,1,237.910766601562,0,237.968185424805,,,,,,,,,,,,,,,,,,,,,,,,,,,,,,,,,
,3832344855.86221,235.365783691406,9999.8056640625,0.00027832738904114,4.40924617636884E-8,1,2,13.4005146026611,4.99273803755526,32.2900004684925,0.370159605881576,0.0546049773735482,1,2.09862809861494E-6,,,,,,,,,,,,,,,,,,,,,235.309143066406,235.422424316406,9999.8056640625,9999.8056640625,47.0985896832934,5.27332704150671,8.78009033203125,27,1,0,0,1,0.27679443359375,38.6119270324707,2,1,1,235.309143066406,0,235.365783691406,,,,,,,,,,,,,,,,,,,,,,,,,,,,,,,,,
,3832344908.43758,232.739410400391,9999.8056640625,0.000282454074818385,3.17675291663992E-8,1,2,13.4005146026611,4.99274527109388,32.2900004684925,0.375644918288394,0.0554410980237309,1,2.14957132170458E-6,,,,,,,,,,,,,,,,,,,,,232.68310546875,232.795715332031,9999.8056640625,9999.8056640625,47.0681061710434,5.27273790341194,8.78055953979492,27,1,0,0,1,0.276718139648438,38.6119270324707,2,1,1,232.68310546875,0,232.739410400391,,,,,,,,,,,,,,,,,,,,,,,,,,,,,,,,,
,3832344960.77801,230.120071411133,9999.8056640625,0.000286257817978702,4.90744009792432E-8,1,2,13.4005146026611,4.99284574051332,32.2699993848801,0.380718166067594,0.0561604584220811,1,2.15688648402475E-6,,,,,,,,,,,,,,,,,,,,,230.085922241211,230.154220581055,9999.8056640625,9999.8056640625,47.1650281074281,5.27296464986478,8.77623081207275,27,1,0,0,1,0.273590087890625,38.6119270324707,2,1,1,230.085922241211,0,230.120071411133,,,,,,,,,,,,,,,,,,,,,,,,,,,,,,,,,
,3832345012.96964,227.503761291504,9999.8056640625,0.000290625447090701,4.38052407325046E-8,1,2,13.4005146026611,4.99283428896707,32.2699993848801,0.386522887551959,0.0570381710886012,1,2.20557899394104E-6,,,,,,,,,,,,,,,,,,,,,227.453170776367,227.554351806641,9999.8056640625,9999.8056640625,47.0622439571492,5.27255295727908,8.76247501373291,27,1,0,0,1,0.276641845703125,38.6119270324707,2,1,1,227.453170776367,0,227.503761291504,,,,,,,,,,,,,,,,,,,,,,,,,,,,,,,,,
,3832345065.46251,224.89037322998,9999.8056640625,0.000294505540582991,4.40669348771386E-8,1,2,13.4005146026611,4.99280252229881,32.2499983012676,0.391679461719644,0.0578021469552466,1,2.23725789589544E-6,,,,,,,,,,,,,,,,,,,,,224.849548339844,224.931198120117,9999.8056640625,9999.8056640625,47.1185212105338,5.27360460033626,8.76081562042236,26,1,64,0,0,0.276412963867187,38.6119270324707,2,1,1,224.849548339844,0,224.89037322998,,,,,,,,,,,,,,,,,,,,,,,,,,,,,,,,,
,3832345117.83846,222.256866455078,9999.8056640625,0.000299117251739237,4.47609186134772E-8,1,2,13.4005146026611,4.99282609690338,32.260000705719,0.397814314337878,0.0587154924187984,1,2.27817425275952E-6,,,,,,,,,,,,,,,,,,,,,222.226043701172,222.287689208984,9999.8056640625,9999.8056640625,47.1525220511204,5.2728442949976,8.74279403686523,25,1,64,0,0,0.2752685546875,38.6119270324707,2,1,1,222.226043701172,0,222.256866455078,,,,,,,,,,,,,,,,,,,,,,,,,,,,,,,,,
,3832345170.24202,219.674591064453,9999.8056640625,0.000303245046776696,4.20741910075415E-8,1,2,13.4005146026611,4.99279134298033,32.2300009429455,0.403299430426006,0.0595312289180958,1,2.31414583641008E-6,,,,,,,,,,,,,,,,,,,,,219.636291503906,219.712890625,9999.8056640625,9999.8056640625,47.2029370906108,5.27281000691433,8.7482795715332,26,1,64,0,0,0.286178588867187,38.6119270324707,2,1,1,219.636291503906,0,219.674591064453,,,,,,,,,,,,,,,,,,,,,,,,,,,,,,,,,
,3832345222.88117,217.021926879883,9999.8056640625,0.000307587121323548,6.67508268975712E-8,1,2,13.4005146026611,4.99278706963877,32.2199985384941,0.4090763951083,0.0603641049805316,1,2.33266266309379E-6,,,,,,,,,,,,,,,,,,,,,216.996612548828,217.047241210938,9999.8056640625,9999.8056640625,47.0696694280819,5.27400529647018,8.72344589233398,25,1,64,0,0,0.277252197265625,38.6119270324707,2,1,1,216.996612548828,0,217.021926879883,,,,,,,,,,,,,,,,,,,,,,,,,,,,,,,,,
,3832345275.36428,214.410438537598,9999.8056640625,0.000312011444131574,4.79040778093273E-8,1,2,13.4005146026611,4.99273996764119,32.200001180172,0.414952564038962,0.061250238005268,1,2.38022350140257E-6,,,,,,,,,,,,,,,,,,,,,214.384170532227,214.436706542969,9999.8056640625,9999.8056640625,47.1357170379569,5.272792978307,8.72715187072754,25,1,64,0,0,0.277099609375,38.6119270324707,2,1,1,214.384170532227,0,214.410438537598,,,,,,,,,,,,,,,,,,,,,,,,,,,,,,,,,
,3832345327.33554,211.739952087402,9999.8056640625,0.000316836741306977,5.25092803739515E-8,1,2,13.4005146026611,4.9927813697635,32.200001180172,0.421371766856523,0.0622187877582977,1,2.43250693967487E-6,,,,,,,,,,,,,,,,,,,,,211.693862915039,211.786041259766,9999.8056640625,9999.8056640625,47.0583358145531,5.27293940532157,8.7111349105835,25,1,64,0,0,0.27435302734375,38.6119270324707,2,1,1,211.693862915039,0,211.739952087402,,,,,,,,,,,,,,,,,,,,,,,,,,,,,,,,,
,3832345379.99385,209.201217651367,9999.8056640625,0.000321529969790558,6.05425984958736E-8,1,2,13.4005146026611,4.99267454693313,32.1800000965595,0.42760385513079,0.0631175110377468,1,2.4527218934941E-6,,,,,,,,,,,,,,,,,,,,,209.156677246094,209.245758056641,9999.8056640625,9999.8056640625,47.0985896832934,5.27585178270982,8.7102746963501,25,1,64,0,0,0.27618408203125,38.6119270324707,2,1,1,209.156677246094,0,209.201217651367,,,,,,,,,,,,,,,,,,,,,,,,,,,,,,,,,
,3832345432.27852,206.495292663574,9999.8056640625,0.000326431347491197,4.80238909355352E-8,1,2,13.4005146026611,4.9927211177804,32.1800000965595,0.434107484525857,0.0642255271100186,1,2.59905273883968E-6,,,,,,,,,,,,,,,,,,,,,206.460205078125,206.530380249023,9999.8056640625,9999.8056640625,47.0774857132742,5.2731285824492,8.68698978424072,26,1,64,0,0,0.276565551757813,38.6119270324707,2,1,1,206.460205078125,0,206.495292663574,,,,,,,,,,,,,,,,,,,,,,,,,,,,,,,,,
,3832345484.81967,203.934150695801,9999.8056640625,0.000331117061893704,3.39038815059154E-8,1,2,13.4005146026611,4.99255506603055,32.1599990129471,0.440337611463228,0.0650095925057615,1,2.53504297332528E-6,,,,,,,,,,,,,,,,,,,,,203.908630371094,203.959671020508,9999.8056640625,9999.8056640625,47.1048427114473,5.27415490122442,8.68990993499756,25,1,64,0,0,0.274505615234375,38.6119270324707,2,1,1,203.908630371094,0,203.934150695801,,,,,,,,,,,,,,,,,,,,,,,,,,,,,,,,,
,3832345536.89793,201.309051513672,9999.8056640625,0.000336460454173508,4.44257425627904E-8,1,2,13.4005146026611,4.99264218327167,32.1599990129471,0.447450471223167,0.0660872659610531,1,2.59623541779898E-6,,,,,,,,,,,,,,,,,,,,,201.27001953125,201.348083496094,9999.8056640625,9999.8056640625,47.0841295556877,5.27236416977406,8.68692779541016,26,1,64,0,0,0.2752685546875,38.1231689453125,2,1,1,201.27001953125,0,201.309051513672,,,,,,,,,,,,,,,,,,,,,,,,,,,,,,,,,
,3832345589.55494,198.698799133301,9999.8056640625,0.000341542896512697,5.88659677555527E-8,1,2,13.4005146026611,4.9928037701293,32.1400016546249,0.454227724928201,0.0671021645751582,1,2.64569400728341E-6,,,,,,,,,,,,,,,,,,,,,198.65202331543,198.745574951172,9999.8056640625,9999.8056640625,47.0727959421588,5.2747717152314,8.66702556610107,25,1,64,0,0,0.276641845703125,38.6119270324707,2,1,1,198.65202331543,0,198.698799133301,,,,,,,,,,,,,,,,,,,,,,,,,,,,,,,,,
,3832345641.72701,196.095176696777,9999.8056640625,0.000347114000975022,4.10788372065406E-8,1,2,13.4005146026611,4.9926864403658,32.1400016546249,0.461622761082333,0.0681892886739007,1,2.68492696914206E-6,,,,,,,,,,,,,,,,,,,,,196.031433105469,196.158920288086,9999.8056640625,9999.8056640625,47.1431425088896,5.27262744816709,8.67248821258545,25,1,64,0,0,0.272979736328125,38.1231689453125,2,1,1,196.031433105469,0,196.095176696777,,,,,,,,,,,,,,,,,,,,,,,,,,,,,,,,,
,3832345694.23001,193.49153137207,9999.8056640625,0.000352644714020909,4.32862321611986E-8,1,2,13.4005146026611,4.99267828012415,32.1299992501736,0.468986295782792,0.069208708703477,1,2.6774463098224E-6,,,,,,,,,,,,,,,,,,,,,193.458709716797,193.524353027344,9999.8056640625,9999.8056640625,47.1150038821973,5.27250591769693,8.65353202819824,26,1,64,0,0,0.273361206054687,38.1231689453125,2,1,1,193.458709716797,0,193.49153137207,,,,,,,,,,,,,,,,,,,,,,,,,,,,,,,,,
,3832345746.44328,190.863815307617,9999.8056640625,0.000358116652651922,3.22437487800979E-8,1,2,13.4005146026611,4.99267850007572,32.1099981665611,0.476255306529316,0.0703413514758009,1,2.76311084118065E-6,,,,,,,,,,,,,,,,,,,,,190.820327758789,190.907302856445,9999.8056640625,9999.8056640625,47.0747500134569,5.27312872784209,8.65763282775879,25,1,64,0,0,0.276336669921875,38.6119270324707,2,1,1,190.820327758789,0,190.863815307617,,,,,,,,,,,,,,,,,,,,,,,,,,,,,,,,,
,3832345798.80935,188.243301391602,9999.8056640625,0.000364095418442228,3.55765892947491E-8,1,2,13.4005146026611,4.9926361752275,32.1099981665611,0.48420701876183,0.0714702140817802,1,2.7756973260081E-6,,,,,,,,,,,,,,,,,,,,,188.193023681641,188.293579101562,9999.8056640625,9999.8056640625,47.1009345688511,5.27268892577288,8.63423347473145,25,1,64,0,0,0.274887084960938,38.6119270324707,2,1,1,188.193023681641,0,188.243301391602,,,,,,,,,,,,,,,,,,,,,,,,,,,,,,,,,
,3832345851.19624,185.655479431152,9999.8056640625,0.000369868882734116,4.48359129288882E-8,1,2,13.4005146026611,4.99261174683956,32.090000808239,0.491879089276905,0.0726223866440592,1,2.83425041749703E-6,,,,,,,,,,,,,,,,,,,,,185.60578918457,185.705169677734,9999.8056640625,9999.8056640625,47.1177395820146,5.27262858711689,8.63987636566162,26,1,64,0,0,0.275726318359375,38.6119270324707,2,1,1,185.60578918457,0,185.655479431152,,,,,,,,,,,,,,,,,,,,,,,,,,,,,,,,,
,3832345903.6704,183.004264831543,9999.8056640625,0.000376206121608434,4.79844303250832E-8,1,2,13.4005146026611,4.99257842629029,32.090000808239,0.500301157755589,0.0738737735473489,1,2.88864750003117E-6,,,,,,,,,,,,,,,,,,,,,182.963439941406,183.04508972168,9999.8056640625,9999.8056640625,47.0856928127261,5.27271299267704,8.62179946899414,25,1,64,0,0,0.274124145507813,38.6119270324707,2,1,1,182.963439941406,0,183.004264831543,,,,,,,,,,,,,,,,,,,,,,,,,,,,,,,,,
,3832345956.10834,180.386436462402,9999.8056640625,0.000382310164338274,5.06532920195855E-8,1,2,13.4005146026611,4.99260371584014,32.0699997246265,0.508407204614287,0.0751801923061956,1,3.01609683599214E-6,,,,,,,,,,,,,,,,,,,,,180.359497070313,180.413375854492,9999.8056640625,9999.8056640625,47.0774857132742,5.27347584373046,8.6235818862915,25,1,64,0,0,0.276336669921875,38.1231689453125,2,1,1,180.359497070313,0,180.386436462402,,,,,,,,,,,,,,,,,,,,,,,,,,,,,,,,,
,3832346008.35623,177.777030944824,9999.8056640625,0.000388602503347679,9.01030179326233E-8,1,2,13.4005146026611,4.99263559736306,32.0699997246265,0.51679481839294,0.0763084087316185,1,2.98324574970015E-6,,,,,,,,,,,,,,,,,,,,,177.722396850586,177.831665039062,9999.8056640625,9999.8056640625,47.1282915670242,5.27261706634401,8.6089448928833,25,1,64,0,0,0.273971557617187,38.6119270324707,2,1,1,177.722396850586,0,177.777030944824,,,,,,,,,,,,,,,,,,,,,,,,,,,,,,,,,
,3832346060.68069,175.183296203613,9999.8056640625,0.000395468306013421,5.56579411214957E-8,1,2,13.4005146026611,4.992561751311,32.0499986410141,0.525911981897203,0.0776755873272403,1,3.05138291613963E-6,,,,,,,,,,,,,,,,,,,,,175.138336181641,175.228256225586,9999.8056640625,9999.8056640625,47.1361078522165,5.27314041504306,8.60393238067627,27,1,0,0,1,0.2752685546875,38.6119270324707,2,1,1,175.138336181641,0,175.183296203613,,,,,,,,,,,,,,,,,,,,,,,,,,,,,,,,,
,3832346113.06463,172.573654174805,9999.8056640625,0.000402268740655687,8.71519175088012E-8,1,2,13.4005146026611,4.99254098435546,32.0499986410141,0.534959430603657,0.0789610133937885,1,3.06642735712485E-6,,,,,,,,,,,,,,,,,,,,,172.514205932617,172.633102416992,9999.8056640625,9999.8056640625,47.1200844675723,5.27258262863685,8.60042667388916,27,1,0,0,1,0.287094116210938,38.6119270324707,2,1,1,172.514205932617,0,172.573654174805,,,,,,,,,,,,,,,,,,,,,,,,,,,,,,,,,
,3832346165.50868,169.933410644531,9999.8056640625,0.000409167331663913,6.42807013508614E-8,1,2,13.4005146026611,4.99256259874856,32.030001282692,0.544123648543571,0.0804095990153829,1,3.18961534959051E-6,,,,,,,,,,,,,,,,,,,,,169.875045776367,169.991775512695,9999.8056640625,9999.8056640625,47.0923366551396,5.27253122916085,8.58969974517822,27,1,0,0,1,0.277633666992187,38.6119270324707,2,1,1,169.875045776367,0,169.933410644531,,,,,,,,,,,,,,,,,,,,,,,,,,,,,,,,,
,3832346217.97086,167.348579406738,9999.8056640625,0.000416699388358552,7.09427850025323E-8,1,2,13.4005146026611,4.99252762448738,32.030001282692,0.554116998245539,0.0820155855014846,1,3.34340689881857E-6,,,,,,,,,,,,,,,,,,,,,167.306655883789,167.390502929687,9999.8056640625,9999.8056640625,47.0630255856684,5.27223132174514,8.58551788330078,27,1,0,0,1,0.27435302734375,38.1231689453125,2,1,1,167.306655883789,0,167.348579406738,,,,,,,,,,,,,,,,,,,,,,,,,,,,,,,,,
,3832346270.20404,164.721145629883,9999.8056640625,0.000424392382174194,6.99783058329011E-8,1,2,13.4005146026611,4.99257207058038,32.0100001990795,0.564344176214856,0.0835999032102801,1,3.45707319795961E-6,,,,,,,,,,,,,,,,,,,,,164.6650390625,164.777252197266,9999.8056640625,9999.8056640625,47.1279007527646,5.2729945008331,8.57014560699463,27,1,0,0,1,0.275955200195313,38.6119270324707,2,1,1,164.6650390625,0,164.721145629883,,,,,,,,,,,,,,,,,,,,,,,,,,,,,,,,,
,3832346322.60346,162.017639160156,9999.8056640625,0.000432334522509976,3.52359612377566E-8,1,2,13.4005146026611,4.992566189519,32.0100001990795,0.574901825731051,0.0851831536407533,1,3.53595660626895E-6,,,,,,,,,,,,,,,,,,,,,161.96842956543,162.066848754883,9999.8056640625,9999.8056640625,47.0692786138223,5.27279911209306,8.56448364257812,27,1,0,0,1,0.286026000976562,38.6119270324707,2,1,1,161.96842956543,0,162.017639160156,,,,,,,,,,,,,,,,,,,,,,,,,,,,,,,,,
,3832346374.96978,159.446640014648,9999.8056640625,0.000440344864577242,6.62194555466625E-8,1,2,13.4005146026611,4.99259306766461,32.0100001990795,0.585586821703384,0.0865558783210901,1,3.44658551235012E-6,,,,,,,,,,,,,,,,,,,,,159.406387329102,159.486892700195,9999.8056640625,9999.8056640625,47.0262890452646,5.27244950110891,8.5517463684082,27,1,0,0,1,0.273513793945313,38.6119270324707,2,1,1,159.406387329102,0,159.446640014648,,,,,,,,,,,,,,,,,,,,,,,,,,,,,,,,,
,3832346427.39682,156.822914123535,9999.8056640625,0.000448538541391556,6.75780853905618E-8,1,2,13.4005146026611,4.99251890953587,31.9899991154671,0.596457082215064,0.0882637265952176,1,3.58512963550888E-6,,,,,,,,,,,,,,,,,,,,,156.773040771484,156.872787475586,9999.8056640625,9999.8056640625,47.09194584088,5.27275541924888,8.5317325592041,27,1,0,0,1,0.277328491210938,38.6119270324707,2,1,1,156.773040771484,0,156.822914123535,,,,,,,,,,,,,,,,,,,,,,,,,,,,,,,,,
,3832346479.86286,154.23983001709,9999.8056640625,0.000457137007305505,7.77725039572927E-8,1,2,13.4005146026611,4.99249649618863,31.980000436306,0.607902778887592,0.0898452010324154,1,3.57123968699866E-6,,,,,,,,,,,,,,,,,,,,,154.198822021484,154.280838012695,9999.8056640625,9999.8056640625,47.0188635743319,5.27235015626657,8.53335857391357,27,1,0,0,1,0.274810791015625,38.6119270324707,2,1,1,154.198822021484,0,154.23983001709,,,,,,,,,,,,,,,,,,,,,,,,,,,,,,,,,
,3832346532.13295,151.610954284668,9999.8056640625,0.000465720699545735,9.02120455268828E-8,1,2,13.4005146026611,4.99251469339246,31.9599993526936,0.619317936209606,0.0915510498648301,1,3.65209018394508E-6,,,,,,,,,,,,,,,,,,,,,151.569488525391,151.652420043945,9999.8056640625,9999.8056640625,47.0681061710434,5.27294570461483,8.51753997802734,27,1,0,0,1,0.27587890625,38.1231689453125,2,1,1,151.569488525391,0,151.610954284668,,,,,,,,,,,,,,,,,,,,,,,,,,,,,,,,,
,3832346584.50855,148.962173461914,9999.8056640625,0.000475656219027351,6.81305842141195E-8,1,2,13.4005146026611,4.99265674755191,31.9599993526936,0.632547207872909,0.093562888003992,1,3.77137113802966E-6,,,,,,,,,,,,,,,,,,,,,148.91145324707,149.012893676758,9999.8056640625,9999.8056640625,46.9950239044954,5.27274613500426,8.49592971801758,27,1,0,0,1,0.275802612304687,38.1231689453125,2,1,1,148.91145324707,0,148.962173461914,,,,,,,,,,,,,,,,,,,,,,,,,,,,,,,,,
,3832346636.90721,146.406562805176,9999.8056640625,0.000484878222512503,7.77171103993333E-8,1,2,13.4005146026611,4.99275919264848,31.9399982690811,0.644821315634554,0.0954355151332478,1,3.88651651495871E-6,,,,,,,,,,,,,,,,,,,,,146.360229492187,146.452896118164,9999.8056640625,9999.8056640625,46.9930698331973,5.27518301102414,8.49492263793945,27,1,0,0,1,0.27557373046875,38.1231689453125,2,1,1,146.360229492187,0,146.406562805176,,,,,,,,,,,,,,,,,,,,,,,,,,,,,,,,,
,3832346689.29516,143.777709960938,9999.8056640625,0.000494925077165607,7.65572649773136E-8,1,2,13.4005146026611,4.99264159644918,31.9399982690811,0.658164010519036,0.0973883408041547,1,3.95090530545244E-6,,,,,,,,,,,,,,,,,,,,,143.728713989258,143.826705932617,9999.8056640625,9999.8056640625,47.0137829889569,5.273303484381,8.49214553833008,27,1,0,0,1,0.277023315429687,38.6119270324707,2,1,1,143.728713989258,0,143.777709960938,,,,,,,,,,,,,,,,,,,,,,,,,,,,,,,,,
,3832346741.78916,141.129600524902,9999.8056640625,0.000505356801805025,7.15520985710672E-8,1,2,13.4005146026611,4.99260673997259,31.9399982690811,0.67201126916081,0.0995737192268128,1,4.13456217796293E-6,,,,,,,,,,,,,,,,,,,,,141.089721679688,141.169479370117,9999.8056640625,9999.8056640625,47.1017161973704,5.27367322632455,8.45943260192871,27,1,0,0,1,0.275115966796875,38.1231689453125,2,1,1,141.089721679688,0,141.129600524902,,,,,,,,,,,,,,,,,,,,,,,,,,,,,,,,,
,3832346794.04555,138.533630371094,9999.8056640625,0.000515780058242222,5.09291065265438E-8,1,2,13.4005146026611,4.99260359663981,31.92999958992,0.68587409261202,0.101607220615651,1,4.20468719767441E-6,,,,,,,,,,,,,,,,,,,,,138.482376098633,138.584884643555,9999.8056640625,9999.8056640625,47.015737060255,5.27304422938541,8.46205520629883,27,1,0,0,1,0.27313232421875,38.1231689453125,2,1,1,138.482376098633,0,138.533630371094,,,,,,,,,,,,,,,,,,,,,,,,,,,,,,,,,
,3832346846.48442,135.900604248047,9999.8056640625,0.000526993187756685,7.58771013470614E-8,1,2,13.4005146026611,4.99263195119671,31.920000910759,0.700790339315412,0.103818447455352,1,4.29719725480593E-6,,,,,,,,,,,,,,,,,,,,,135.861038208008,135.940170288086,9999.8056640625,9999.8056640625,47.0935090979185,5.2733545733159,8.45366382598877,27,1,0,0,1,0.274276733398438,38.6119270324707,2,1,1,135.861038208008,0,135.900604248047,,,,,,,,,,,,,,,,,,,,,,,,,,,,,,,,,
,3832346898.81795,133.276924133301,9999.8056640625,0.000538411830334335,9.45734870331904E-8,1,2,13.4005146026611,4.99262867107337,31.8999998271465,0.715973367851113,0.106073027093212,1,4.39420192125705E-6,,,,,,,,,,,,,,,,,,,,,133.220108032227,133.333740234375,9999.8056640625,9999.8056640625,47.0841295556877,5.27389935253106,8.43840885162354,27,1,0,0,1,0.276641845703125,38.1231689453125,2,1,1,133.220108032227,0,133.276924133301,,,,,,,,,,,,,,,,,,,,,,,,,,,,,,,,,
,3832346951.24,130.686416625977,9999.8056640625,0.000550483048843389,5.15473976181531E-8,1,2,13.4005146026611,4.99262997591527,31.8999998271465,0.732023342204645,0.108468710021494,1,4.50585146774553E-6,,,,,,,,,,,,,,,,,,,,,130.640563964844,130.732269287109,9999.8056640625,9999.8056640625,47.0415308013896,5.27382343780813,8.4269208908081,27,1,0,0,1,0.27496337890625,38.1231689453125,2,1,1,130.640563964844,0,130.686416625977,,,,,,,,,,,,,,,,,,,,,,,,,,,,,,,,,
,3832347029.77362,126.740291595459,9999.8056640625,0.000569143756197042,5.08557282652861E-8,1,2,13.4005146026611,4.99259642085383,31.8799987435341,0.756785141746683,0.112473144291241,1,4.90535373489154E-6,,,,,,,,,,,,,,,,,,,,,126.687637329102,126.792945861816,9999.8056640625,9999.8056640625,47.0481746438031,5.27381914092412,8.40408229827881,27,1,0,0,1,0.277175903320313,38.6119270324707,2,1,1,126.687637329102,0,126.740291595459,,,,,,,,,,,,,,,,,,,,,,,,,,,,,,,,,
,3832347082.17407,124.106086730957,9999.8056640625,0.000582073148412252,7.55529985276971E-8,1,2,13.4005146026611,4.99255991552647,31.8799987435341,0.7740149855682,0.114701609599977,1,4.77231516485232E-6,,,,,,,,,,,,,,,,,,,,,124.042503356934,124.16967010498,9999.8056640625,9999.8056640625,46.997368790053,5.27398386646075,8.38139057159424,27,1,0,0,1,0.277099609375,38.1231689453125,2,1,1,124.042503356934,0,124.106086730957,,,,,,,,,,,,,,,,,,,,,,,,,,,,,,,,,
,3832347134.65257,121.506553649902,9999.8056640625,0.000595585684076859,8.36185900070378E-8,1,2,13.4005146026611,4.99257411718737,31.870000064373,0.791979687238574,0.117413116071989,1,4.91938930624252E-6,,,,,,,,,,,,,,,,,,,,,121.467308044434,121.545799255371,9999.8056640625,9999.8056640625,47.11226818238,5.27408251086959,8.37104320526123,27,1,0,0,1,0.275497436523438,38.1231689453125,2,1,1,121.467308044434,0,121.506553649902,,,,,,,,,,,,,,,,,,,,,,,,,,,,,,,,,
,3832347187.36021,118.888263702393,9999.8056640625,0.000610303523387596,7.08470863702693E-8,1,2,13.4005146026611,4.99261919479221,31.8499989807606,0.811547667802201,0.120409743438786,1,5.11132197486784E-6,,,,,,,,,,,,,,,,,,,,,118.860725402832,118.915802001953,9999.8056640625,9999.8056640625,47.0845203699473,5.27385237532253,8.35453033447266,25,1,64,0,0,0.276565551757813,38.1231689453125,2,1,1,118.860725402832,0,118.888263702393,,,,,,,,,,,,,,,,,,,,,,,,,,,,,,,,,
,3832347255.46728,115.48002243042,9999.8056640625,0.000629963269865258,6.94998809437182E-8,1,2,13.4005146026611,4.99247751358455,31.8600013852119,0.837633258188926,0.12445725018684,1,5.40635699675512E-6,,,,,,,,,,,,,,,,,,,,,115.425476074219,115.534568786621,9999.8056640625,9999.8056640625,47.0649796569665,5.27356247043979,8.3435640335083,27,1,0,0,1,0.274810791015625,38.1231689453125,2,1,1,115.425476074219,0,115.48002243042,,,,,,,,,,,,,,,,,,,,,,,,,,,,,,,,,
,3832347307.81256,112.852268218994,9999.8056640625,0.000645818554057962,6.09784572455355E-8,1,2,13.4005146026611,4.99261555056578,31.8499989807606,0.858792643080954,0.127274063113001,1,5.30173484461566E-6,,,,,,,,,,,,,,,,,,,,,112.79615020752,112.908386230469,9999.8056640625,9999.8056640625,47.0606807001108,5.2739946535869,8.32776165008545,27,1,0,0,1,0.276565551757813,38.1231689453125,2,1,1,112.79615020752,0,112.852268218994,,,,,,,,,,,,,,,,,,,,,,,,,,,,,,,,,
,3832347360.21753,110.256591796875,9999.8056640625,0.000662148038344654,9.14483298643031E-8,1,2,13.4005146026611,4.99264237886408,31.8300016224384,0.880509432926021,0.130523292436397,1,5.45843660880432E-6,,,,,,,,,,,,,,,,,,,,,110.211059570312,110.302124023438,9999.8056640625,9999.8056640625,47.0118289176588,5.27346030674597,8.31410884857178,27,1,0,0,1,0.276718139648438,38.1231689453125,2,1,1,110.211059570312,0,110.256591796875,,,,,,,,,,,,,,,,,,,,,,,,,,,,,,,,,
,3832347412.65066,107.627361297607,9999.8056640625,0.000679789299036688,9.23675804557806E-8,1,2,13.4005146026611,4.99269529208443,31.8300016224384,0.903941766059489,0.134286948443594,1,5.81736844376919E-6,,,,,,,,,,,,,,,,,,,,,107.57991027832,107.674812316895,9999.8056640625,9999.8056640625,47.0223809026684,5.2732517621143,8.31256484985352,27,1,0,0,1,0.27679443359375,38.1231689453125,2,1,1,107.549026489258,0,107.627361297607,,,,,,,,,,,,,,,,,,,,,,,,,,,,,,,,,
,3832347473.0211,104.572315216064,9999.8056640625,0.000700756889695628,9.65235641634804E-8,1,2,13.4005146026611,4.99269102665222,31.8300016224384,0.931814824445563,0.138480660608465,1,6.03577996509982E-6,,,,,,,,,,,,,,,,,,,,,104.529449462891,104.615180969238,9999.8056640625,9999.8056640625,47.0403583586107,5.27278092733365,8.28378677368164,27,1,0,0,1,0.277023315429687,38.1231689453125,2,1,1,104.529449462891,0,104.572315216064,,,,,,,,,,,,,,,,,,,,,,,,,,,,,,,,,
,3832347525.45161,101.970043182373,9999.8056640625,0.000720268111953856,4.95326015204956E-8,1,2,13.4005146026611,4.99268543787201,31.810000538826,0.957793417086964,0.142082434197155,1,6.01324692470203E-6,,,,,,,,,,,,,,,,,,,,,101.904479980469,102.035606384277,9999.8056640625,9999.8056640625,47.0872560697646,5.27315778670182,8.2724084854126,27,1,0,0,1,0.275344848632813,38.1231689453125,2,1,1,101.904479980469,0,101.970043182373,,,,,,,,,,,,,,,,,,,,,,,,,,,,,,,,,
,3832347577.93517,99.3453254699707,9999.8056640625,0.000740059909685272,4.1985574361639E-8,1,2,13.4005146026611,4.99263968692955,31.810000538826,0.984093561282933,0.14602845825432,1,6.21127803275984E-6,,,,,,,,,,,,,,,,,,,,,99.3083648681641,99.3822860717773,9999.8056640625,9999.8056640625,47.0071391465434,5.27360191870767,8.25681209564209,27,1,0,0,1,0.27679443359375,38.1231689453125,2,1,1,99.3083648681641,0,99.3453254699707,,,,,,,,,,,,,,,,,,,,,,,,,,,,,,,,,
,3832347630.20492,96.7325744628906,9999.8056640625,0.000760700529153808,8.24650026016833E-8,1,2,13.4005146026611,4.99265653014727,31.810000538826,1.01154686524355,0.150089120448332,1,6.37487325170056E-6,,,,,,,,,,,,,,,,,,,,,96.6868667602539,96.7782821655273,9999.8056640625,9999.8056640625,47.1419700661108,5.27379084360663,8.23959064483643,27,1,0,0,1,0.275955200195313,38.1231689453125,2,1,1,96.6868667602539,0,96.7325744628906,,,,,,,,,,,,,,,,,,,,,,,,,,,,,,,,,
,3832347682.56561,94.1279716491699,9999.8056640625,0.000783268857943867,7.57780661641333E-8,1,2,13.4005146026611,4.99264812615812,31.7899994552135,1.04150602294561,0.154890835096835,1,6.82633942876336E-6,,,,,,,,,,,,,,,,,,,,,94.0805282592773,94.1754150390625,9999.8056640625,9999.8056640625,47.1298548240627,5.27453201656379,8.23446655273437,27,1,0,0,1,0.275802612304687,38.1231689453125,2,1,1,94.0805282592773,0,94.1279716491699,,,,,,,,,,,,,,,,,,,,,,,,,,,,,,,,,
,3832347735.05902,91.5147972106934,9999.8056640625,0.000806961766491311,8.23157183091479E-8,1,2,13.4005146026611,4.99266034792458,31.7899994552135,1.07298590715202,0.159776715196656,1,7.1831221123115E-6,,,,,,,,,,,,,,,,,,,,,91.4648742675781,91.5647201538086,9999.8056640625,9999.8056640625,47.0669337282646,5.27361060167817,8.20166492462158,27,1,0,0,1,0.277175903320313,38.1231689453125,2,1,1,91.4648742675781,0,91.5147972106934,,,,,,,,,,,,,,,,,,,,,,,,,,,,,,,,,
,3832347787.37073,88.8869094848633,9999.8056640625,0.000831995743779061,5.90047553605938E-8,1,2,13.4005146026611,4.99267646612979,31.7899994552135,1.10631087741966,0.164495508286582,1,7.22673299357756E-6,,,,,,,,,,,,,,,,,,,,,88.8405609130859,88.9332580566406,9999.8056640625,9999.8056640625,47.0567725575146,5.27382845785165,8.18598651885986,27,1,0,0,1,0.276870727539062,38.1231689453125,2,1,1,88.8405609130859,0,88.8869094848633,,,,,,,,,,,,,,,,,,,,,,,,,,,,,,,,,
,3832347839.82897,86.2304039001465,9999.8056640625,0.000860315408238707,7.2227318546692E-8,1,2,13.4005146026611,4.99266064919347,31.7699983716011,1.14392238749612,0.170382775634979,1,7.68969819364382E-6,,,,,,,,,,,,,,,,,,,,,86.1924285888672,86.2683792114258,9999.8056640625,9999.8056640625,47.1279007527646,5.27382666574911,8.15368938446045,27,1,0,0,1,0.285491943359375,38.1231689453125,2,1,1,86.1924285888672,0,86.2304039001465,,,,,,,,,,,,,,,,,,,,,,,,,,,,,,,,,
,3832347892.13945,83.652473449707,9999.8056640625,0.000888565261996339,5.92762769353228E-8,1,2,13.4005146026611,4.99262703297985,31.7699983716011,1.18151264067358,0.175699844448095,1,7.73480964786874E-6,,,,,,,,,,,,,,,,,,,,,83.6031799316406,83.7017669677734,9999.8056640625,9999.8056640625,47.0626347714088,5.27369569410266,8.13690280914307,27,1,0,0,1,0.275802612304687,38.1231689453125,2,1,1,83.6031799316406,0,83.652473449707,,,,,,,,,,,,,,,,,,,,,,,,,,,,,,,,,
,3832347952.6774,80.6108512878418,9999.8056640625,0.000923365323598143,4.23227907580157E-8,1,2,13.4005146026611,4.99263566098632,31.7699983716011,1.22776797764121,0.182729629242046,1,8.14904674839208E-6,,,,,,,,,,,,,,,,,,,,,80.568229675293,80.6534729003906,9999.8056640625,9999.8056640625,46.9762648200338,5.27411348429814,8.11734771728516,27,1,0,0,1,0.2777099609375,38.1231689453125,2,1,1,80.568229675293,0,80.6108512878418,,,,,,,,,,,,,,,,,,,,,,,,,,,,,,,,,
,3832348005.13292,77.9411010742188,9999.8056640625,0.000956303183095063,7.9899610935427E-8,1,2,13.4005146026611,4.9926306516234,31.750001013279,1.27157454716527,0.189162162986754,1,8.37554878028178E-6,,,,,,,,,,,,,,,,,,,,,77.9059677124023,77.9762344360352,9999.8056640625,9999.8056640625,47.0743591991973,5.27378837527041,8.09558296203613,27,1,0,0,1,0.286407470703125,38.1231689453125,2,1,1,77.9059677124023,0,77.9411010742188,,,,,,,,,,,,,,,,,,,,,,,,,,,,,,,,,
,3832348057.33032,75.365119934082,9999.8056640625,0.000991001093913595,8.24132946124046E-8,1,2,13.4005146026611,4.99264256500629,31.750001013279,1.31769185385788,0.196198061257797,1,8.80849876488423E-6,,,,,,,,,,,,,,,,,,,,,75.3255310058594,75.4047088623047,9999.8056640625,9999.8056640625,47.0169095030338,5.27401927327368,8.07384490966797,27,1,0,0,1,0.276260375976562,38.1231689453125,2,1,1,75.3255310058594,0,75.365119934082,,,,,,,,,,,,,,,,,,,,,,,,,,,,,,,,,
,3832348119.95072,72.2100791931152,9999.8056640625,0.00103603447353447,1.00602661073343E-7,1,2,13.4005146026611,4.9925742255676,31.7399986088276,1.37753519930281,0.205179830354469,1,9.26130042773435E-6,,,,,,,,,,,,,,,,,,,,,72.1721649169922,72.2479934692383,9999.8056640625,9999.8056640625,46.9758740057742,5.27296474068412,8.04189777374268,27,1,0,0,1,0.2764892578125,38.1231689453125,2,1,1,72.1721649169922,0,72.2100791931152,,,,,,,,,,,,,,,,,,,,,,,,,,,,,,,,,
,3832348172.22304,69.5723724365234,9999.8056640625,0.00107621632157454,1.81752852165155E-7,1,2,13.4005146026611,4.9925868350076,31.7399986088276,1.43095246260005,0.213241280936842,1,9.69783283062336E-6,,,,,,,,,,,,,,,,,,,,,69.5350112915039,69.609733581543,9999.8056640625,9999.8056640625,47.0622439571492,5.27375854051007,8.02331066131592,27,1,0,0,1,0.275497436523438,38.1231689453125,2,1,1,69.5350112915039,0,69.5723724365234,,,,,,,,,,,,,,,,,,,,,,,,,,,,,,,,,
,3832348224.58013,66.9370651245117,9999.8056640625,0.0011205748775593,9.81875564377954E-8,1,2,13.4005146026611,4.99258474579913,31.7299999296665,1.48994484554092,0.221933989565714,1,1.00251694425132E-5,,,,,,,,,,,,,,,,,,,,,66.8804931640625,66.9936370849609,9999.8056640625,9999.8056640625,47.1024978258896,5.27379647457962,7.9887752532959,27,1,0,0,1,0.275955200195313,38.1231689453125,2,1,1,66.8804931640625,0,66.9370651245117,,,,,,,,,,,,,,,,,,,,,,,,,,,,,,,,,
,3832348276.99361,64.3027763366699,9999.8056640625,0.00116769510064977,8.29229475959313E-8,1,2,13.4005146026611,4.99260254600935,31.7399986088276,1.55257805995593,0.23145782462484,1,1.05897249108372E-5,,,,,,,,,,,,,,,,,,,,,64.2591857910156,64.3463668823242,9999.8056640625,9999.8056640625,47.0485654580627,5.27386623365902,7.9592137336731,27,1,0,0,1,0.274734497070313,38.1231689453125,2,1,1,64.2591857910156,0,64.3027763366699,,,,,,,,,,,,,,,,,,,,,,,,,,,,,,,,,
,3832348329.45762,61.6480293273926,9999.8056640625,0.00121922528874378,8.76261769746968E-8,1,2,13.4005146026611,4.99259729836797,31.7200012505054,1.62106289963479,0.241870735928308,1,1.12065746864334E-5,,,,,,,,,,,,,,,,,,,,,61.5999641418457,61.6960945129395,9999.8056640625,9999.8056640625,47.0516919721396,5.27404730575494,7.92625379562378,27,1,0,0,1,0.274124145507813,38.1231689453125,2,1,1,61.5999641418457,0,61.6480293273926,,,,,,,,,,,,,,,,,,,,,,,,,,,,,,,,,
,3832348381.90656,59.0195350646973,9999.8056640625,0.00127480006927201,1.37068242759898E-7,1,2,13.4005146026611,4.99254982026525,31.7200012505054,1.69491989449828,0.252980203482662,1,1.17833455539066E-5,,,,,,,,,,,,,,,,,,,,,58.9785079956055,59.0605621337891,9999.8056640625,9999.8056640625,46.9723566774377,5.27350270764336,7.88655662536621,27,1,0,0,1,0.2764892578125,38.1231689453125,2,1,1,58.9785079956055,0,59.0195350646973,,,,,,,,,,,,,,,,,,,,,,,,,,,,,,,,,
,3832348444.34151,55.8877010345459,9999.8056640625,0.00134841098002642,1.99287891162991E-7,1,2,13.4005146026611,4.99250689201335,31.7099988460541,1.79274633831851,0.267744857070716,1,1.25838977985151E-5,,,,,,,,,,,,,,,,,,,,,55.8334426879883,55.9419593811035,9999.8056640625,9999.8056640625,47.0677153567838,5.27370240121366,7.84470653533935,27,1,0,0,1,0.274276733398438,38.1231689453125,2,1,1,55.8334426879883,0,55.8877010345459,,,,,,,,,,,,,,,,,,,,,,,,,,,,,,,,,
,3832348506.62482,52.7208557128906,9999.8056640625,0.0014305228663271,1.71094200058596E-7,1,2,13.4005146026611,4.99268248815994,31.7099988460541,1.90188624053599,0.28493255408685,1,1.40033837247237E-5,,,,,,,,,,,,,,,,,,,,,52.6769256591797,52.7647857666016,9999.8056640625,9999.8056640625,47.0446573154665,5.27362458694953,7.79106998443603,27,1,0,0,1,0.276641845703125,38.1231689453125,2,1,1,52.6559867858887,0,52.7208557128906,,,,,,,,,,,,,,,,,,,,,,,,,,,,,,,,,
,3832348579.15321,49.0855579376221,9999.8056640625,0.00154103563424422,1.84826244890474E-7,1,2,13.4005146026611,4.99272596068943,31.6900014877319,2.04946692307911,0.302449353605888,10,1.17059913175766E-5,,,,,,,,,,,,,,,,,,,,,49.0407981872559,49.1303176879883,9999.8056640625,9999.8056640625,47.0720143136396,5.27337349240374,7.72747802734375,27,1,0,0,1,0.277099609375,38.1231689453125,2,1,1,49.0407981872559,0,49.0855579376221,,,,,,,,,,,,,,,,,,,,,,,,,,,,,,,,,
,3832348657.9584,45.1228809356689,9999.8056640625,0.00167760750164728,1.91090336543618E-7,1,2,13.4005146026611,4.99270477564618,31.6900014877319,2.23111164243161,0.329059156877149,10,1.2598913283302E-5,,,,,,,,,,,,,,,,,,,,,45.0661239624023,45.1796379089355,9999.8056640625,9999.8056640625,46.9805637768896,5.27222781802159,7.66169500350952,27,1,0,0,1,0.277023315429687,38.1231689453125,2,1,1,45.0661239624023,0,45.1228809356689,,,,,,,,,,,,,,,,,,,,,,,,,,,,,,,,,
,3832348710.12108,42.4991683959961,9999.8056640625,0.00178235251730686,3.39645212323002E-7,1,2,13.4005146026611,4.99259749747347,31.6900014877319,2.37032265579716,0.349761878930629,10,1.35113732520091E-5,,,,,,,,,,,,,,,,,,,,,42.4418029785156,42.5565338134766,9999.8056640625,9999.8056640625,47.1110957396011,5.27276217520788,7.56871938705444,27,1,0,0,1,0.275650024414062,38.1231689453125,2,1,1,42.4418029785156,0,42.4991683959961,,,,,,,,,,,,,,,,,,,,,,,,,,,,,,,,,
,3832348781.71165,38.8753623962402,9999.8056640625,0.00194658878515276,3.53865198216683E-7,1,2,13.4005146026611,4.99271739968255,31.6900014877319,2.58882100105996,0.382018479217577,10,1.47676158889564E-5,,,,,,,,,,,,,,,,,,,,,38.8753623962402,38.8753623962402,9999.8056640625,9999.8056640625,47.0352777732358,5.27213030163901,7.47503900527954,27,1,0,0,1,0.276565551757813,38.1231689453125,2,1,1,38.8753623962402,0,38.8753623962402,,,,,,,,,,,,,,,,,,,,,,,,,,,,,,,,,
,3832348833.02911,36.3087062835693,9999.8056640625,0.00209185493270579,2.91953408522388E-7,1,2,13.4005146026611,4.99279270876326,31.6700004041195,2.78201530948901,0.410940063236036,10,1.61735508716368E-5,,,,,,,,,,,,,,,,,,,,,36.2507553100586,36.3666572570801,9999.8056640625,9999.8056640625,47.0598990715915,5.27208661677418,7.40854263305664,27,1,0,0,1,0.27496337890625,38.1231689453125,2,1,1,36.2507553100586,0,36.3087062835693,,,,,,,,,,,,,,,,,,,,,,,,,,,,,,,,,
,3832348893.5153,33.2541236877441,9999.8056640625,0.00228384880398125,4.14994423190537E-7,1,2,13.4005146026611,4.9927918226706,31.6700004041195,3.03729806238848,0.449045982136072,10,1.79503742355564E-5,,,,,,,,,,,,,,,,,,,,,33.2106742858887,33.2975730895996,9999.8056640625,9999.8056640625,47.0450481297261,5.27161908201016,7.28396368026733,26,1,68,0,0,0.286026000976562,38.1231689453125,2,1,1,33.2106742858887,0,33.2541236877441,,,,,,,,,,,,,,,,,,,,,,,,,,,,,,,,,
,3832348955.93992,30.1321315765381,9999.8056640625,0.00252277440839206,4.31422476788089E-7,1,2,13.4005146026611,4.99280776560585,31.6700004041195,3.35483163401919,0.49766347147775,10,2.10587361683426E-5,,,,,,,,,,,,,,,,,,,,,30.0835857391357,30.1806774139404,9999.8056640625,9999.8056640625,47.0243349739665,5.27223209625329,7.15306377410889,27,1,0,0,1,0.276641845703125,38.1231689453125,2,1,1,30.0835857391357,0,30.1321315765381,,,,,,,,,,,,,,,,,,,,,,,,,,,,,,,,,
,3832349024.42724,26.7054815292358,9999.8056640625,0.00284843664872872,5.76486698525971E-7,1,2,13.4005146026611,4.9927992835134,31.6700004041195,3.78785456722699,0.562190104389586,10,2.39913245674498E-5,,,,,,,,,,,,,,,,,,,,,26.6567249298096,26.7542381286621,9999.8056640625,9999.8056640625,47.0880376982838,5.27230873907571,6.99551248550415,27,1,0,0,1,0.28564453125,38.1231689453125,2,1,1,26.6567249298096,0,26.7054815292358,,,,,,,,,,,,,,,,,,,,,,,,,,,,,,,,,
,3832349085.02915,23.652681350708,9999.8056640625,0.00321202900872116,7.87349723450669E-7,1,2,13.4005146026611,4.99276012503317,31.6700004041195,4.27107943315813,0.635624019023602,10,2.83150365090378E-5,,,,,,,,,,,,,,,,,,,,,23.6157569885254,23.6896057128906,9999.8056640625,9999.8056640625,46.9930698331973,5.27256040338393,6.77412223815918,27,1,0,0,1,0.27496337890625,38.1231689453125,2,1,1,23.6157569885254,0,23.652681350708,,,,,,,,,,,,,,,,,,,,,,,,,,,,,,,,,
,3832349145.3155,20.6406288146973,9999.8056640625,0.00368398560444016,8.57058165774653E-7,1,2,13.4005146026611,4.99278014757241,31.649999320507,4.89868474821547,0.728942937889744,10,3.24154435675791E-5,,,,,,,,,,,,,,,,,,,,,20.5960483551025,20.685209274292,9999.8056640625,9999.8056640625,47.1040610829281,5.27332331067327,6.48017930984497,27,1,0,0,1,0.274810791015625,38.1231689453125,2,1,1,20.5960483551025,0,20.6406288146973,,,,,,,,,,,,,,,,,,,,,,,,,,,,,,,,,
,3832349219.86082,16.9710903167725,9999.8056640625,0.00448381249743032,1.40896330825899E-6,1,2,13.4005146026611,4.99276795013981,31.6600017249584,5.96238897159626,0.885948381229372,10,3.85129263321113E-5,,,,,,,,,,,,,,,,,,,,,16.9254779815674,17.0167026519775,9999.8056640625,9999.8056640625,47.0368410302742,5.27269980303933,6.01927900314331,27,1,0,0,1,0.2734375,38.1231689453125,2,1,1,16.9254779815674,0,16.9710903167725,,,,,,,,,,,,,,,,,,,,,,,,,,,,,,,,,
,3832349296.52289,13.2068839073181,9999.8056640625,0.00574202160897069,2.09339349324938E-6,1,2,13.4005146026611,4.99277679324942,31.649999320507,7.6351892445005,1.1369389564023,10,5.11081627781276E-5,,,,,,,,,,,,,,,,,,,,,13.1614475250244,13.2523202896118,9999.8056640625,9999.8056640625,47.0634163999281,5.27207255915357,5.41643571853638,27,1,0,0,1,0.275650024414062,38.1231689453125,2,1,1,13.1614475250244,0,13.2068839073181,,,,,,,,,,,,,,,,,,,,,,,,,,,,,,,,,
,3832349381.05342,9.35886287689209,9999.8056640625,0.00805729784523648,4.49885472726881E-6,1,2,13.4005146026611,4.99279772365284,31.6600017249584,10.7133436921548,1.5992369032726,10,7.46124883036343E-5,,,,,,,,,,,,,,,,,,,,,9.30583190917969,9.41189384460449,9999.8056640625,9999.8056640625,47.0884285125434,5.27175742833354,4.71423006057739,27,1,0,0,1,0.274276733398438,38.1231689453125,6,1,1,9.30583190917969,0,9.35886287689209,,,,,,,,,,,,,,,,,,,,,,,,,,,,,,,,,
,3832349433.42054,8.00056552886963,9999.8056640625,0.00929474722049135,7.25549772452947E-7,1,2,13.4005146026611,4.99278499722629,31.649999320507,12.3582217342359,1.84803895518677,10,8.84719527102686E-5,,,,,,,,,,,,,,,,,,,,,8.00045013427734,8.00068092346191,9999.8056640625,9999.8056640625,47.0118289176588,5.27219953683159,4.54910087585449,27,1,0,0,1,0.275955200195313,38.1231689453125,5,1,1,8.00045013427734,0,8.00056552886963,,,,,,,,,,,,,,,,,,,,,,,,,,,,,,,,,
,3832349469.69569,8.00003385543823,9999.8056640625,0.00929539079618189,1.25913450570894E-6,1,2,13.4005146026611,4.99277363503093,31.649999320507,12.3592304056673,1.84679140205296,10,8.74492438058828E-5,,,,,,,,,,,,,,,,,,,,,8.00000476837158,8.00006294250488,9999.8056640625,9999.8056640625,47.1259466814665,5.27233486989988,4.52205514907837,27,1,0,0,1,0.28564453125,37.6344108581543,1,1,1,8.00000476837158,0,8.00003385543823,,,,,,,,,,,,,,,,,,,,,,,,,,,,,,,,,