File: SI Fig S11-13 SQUID all/Michaela_Er_Hyst300K.dat
[Header]
; MPMS3 Data File (default extension .dat)
; Copyright (c) 2007, Quantum Design, Inc. All rights reserved.
TITLE,
FILEOPENTIME,3832825006.90517,06/14/2021,9:37 am
BYAPP,MPMS3 w/ AC,1.0,1.1
INFO,MPMS3 Measurement Release 1.1.16 Build 424, MultiVu Release 2.3.4.19,APPNAME
INFO,Linear Motor Servo Controller,MOTOR_MODULE_NAME
INFO,3101-100 E1,MOTOR_HW_VERSION
INFO,MMC211,MOTOR_SERIAL_NUMBER
INFO,01.04.28,MOTOR_SOFTWARE_VERSION
INFO,Quantum Design Squid Module,SQUID_MODULE_NAME
INFO,3101-501 B0,SQUID_HW_VERSION
INFO,SQM059,SQUID_SERIAL_NUMBER
INFO,01.03.04,SQUID_SOFTWARE_VERSION
INFO,SQUID AC,AC_MODULE_NAME
INFO,3101-401 F1,AC_HW_VERSION
INFO,SAC057,AC_SERIAL_NUMBER
INFO,SQUID AC 00.95.07,AC_SOFTWARE_VERSION
INFO,TCIXXX,COIL_SERIAL_NUMBER
INFO,0,MOMENT_UNITS
INFO,Michaela_Er,SAMPLE_MATERIAL
INFO,Michaela_Er,SAMPLE_COMMENT
INFO,1.11,SAMPLE_MASS
INFO,,SAMPLE_VOLUME
INFO,,SAMPLE_MOLECULAR_WEIGHT
INFO,,SAMPLE_SIZE
INFO,,SAMPLE_SHAPE
INFO,Straw,SAMPLE_HOLDER
INFO,Standard,SAMPLE_HOLDER_DETAIL
INFO,53.51,SAMPLE_OFFSET
DATATYPE,COMMENT,1
DATATYPE,TIME,2
STARTUPAXIS,X,2
STARTUPAXIS,Y1,5
FIELDGROUP, VSM,2,3,4,5,6,8,9,10,11,14,15
FIELDGROUP, DC, 2,3,4,14,56,57,58,59,60,61,62,63,64,65,66,67,68,69
FIELDGROUP, AC, 2,3,4,11,16,17,18,19,20,21,22,23,24,25,26,27,28,29,30
STARTUPGROUP, All
[Data]
Comment,Time Stamp (sec),Temperature (K),Magnetic Field (Oe),Moment (emu),M. Std. Err. (emu),Transport Action,Averaging Time (sec),Frequency (Hz),Peak Amplitude (mm),Center Position (mm),Lockin Signal' (V),Lockin Signal (V),Range,M. Quad. Signal (emu),AC Moment (emu),AC M. Std Err. (emu),AC Phase (deg),AC Phase Std. Err. (deg),AC Susceptibility (emu/Oe),AC Suscept. Std Err. (emu/Oe),AC X' (emu/Oe),AC X' Std Err. (emu/Oe),AC X'' (emu/Oe),AC X'' Std Err. (emu/Oe),AC Drive (Oe),AC Frequency (Hz),AC Averaging Time (sec),AC Cycles,AC Range,AC Measure Type,AC Signal' (V),AC Signal'' (V),AC Trim Coil Ratio,AC Trim Coil Phase,Min. Temperature (K),Max. Temperature (K),Min. Field (Oe),Max. Field (Oe),Mass (grams),Motor Lag (deg),Pressure (Torr),Measure Count,Measurement Number,SQUID Status (code),Motor Status (code),Measure Status (code),Motor Current (amps),Motor Temp. (C),Temp. Status (code),Field Status (code),Chamber Status (code),Chamber Temp (K),Redirection State,Average Temp (K),Rotation Angle (deg),Rotator state,DC Moment Fixed Ctr (emu),DC Moment Err Fixed Ctr (emu),DC Moment Free Ctr (emu),DC Moment Err Free Ctr (emu),DC Fixed Fit,DC Free Fit,DC Calculated Center (mm),DC Calculated Center Err (mm),DC Scan Length (mm),DC Scan Time (s),DC Number of Points,DC Squid Drift,DC Min V (V),DC Max V (V),DC Scans per Measure,Map 01,Map 02,Map 03,Map 04,Map 05,Map 06,Map 07,Map 08,Map 09,Map 10,Map 11,Map 12,Map 13,Map 14,Map 15,Map 16
,3832825034.57493,299.799743652344,0.361419081687927,-8.38497064382884E-8,6.4474134859159E-9,1,2,13.4005146026611,4.98956046557203,33.7099991738796,-0.000105039817987587,-6.20531404471983E-5,100,-3.49259815325804E-8,,,,,,,,,,,,,,,,,,,,,299.799743652344,299.799743652344,0.361419081687927,0.361419081687927,47.3096293834858,5.2829907663864,10.1217746734619,27,1,0,0,1,0.280609130859375,38.1231689453125,1,1,1,299.799743652344,0,299.799743652344,,,,,,,,,,,,,,,,,,,,,,,,,,,,,,,,,
,3832825059.63357,299.874496459961,1578.70349121094,6.29163569080841E-5,2.70664806963647E-8,1,2,13.4005146026611,4.99218642472438,33.7099991738796,0.0836045518565138,0.012756184215004,10,7.85791477829972E-7,,,,,,,,,,,,,,,,,,,,,299.872802734375,299.876190185547,1578.70349121094,1578.70349121094,47.3479291809281,5.27303407656937,10.981761932373,27,1,0,0,1,0.2752685546875,38.6119270324707,1,1,1,299.876190185547,0,299.874496459961,,,,,,,,,,,,,,,,,,,,,,,,,,,,,,,,,
,3832825082.81446,299.926330566406,3683.919921875,0.000147457568334688,2.59631132620411E-8,1,2,13.4005146026611,4.99216048620888,33.7099991738796,0.19609565629136,0.0288066310009831,10,1.02287098790834E-6,,,,,,,,,,,,,,,,,,,,,299.924102783203,299.928558349609,3683.919921875,3683.919921875,47.3834932785531,5.27284549096943,11.5593948364258,27,1,0,0,1,0.2740478515625,39.1006851196289,1,1,1,299.928558349609,0,299.926330566406,,,,,,,,,,,,,,,,,,,,,,,,,,,,,,,,,
,3832825105.78259,299.936294555664,5789.14892578125,0.000231755414815747,3.17840141134974E-8,1,2,13.4005146026611,4.99232843326773,33.7099991738796,0.308189034703154,0.0454474774006426,10,1.73586663560141E-6,,,,,,,,,,,,,,,,,,,,,299.935363769531,299.937225341797,5789.14892578125,5789.14892578125,47.4632193875146,5.2737815360725,11.9993715286255,27,1,0,0,1,0.275497436523438,39.1006851196289,1,1,1,299.935363769531,0,299.936294555664,,,,,,,,,,,,,,,,,,,,,,,,,,,,,,,,,
,3832825126.89883,299.941787719727,7894.34033203125,0.000316128370908914,3.62041989638775E-8,1,2,13.4005146026611,4.9925310155067,33.7099991738796,0.420419797433354,0.0619394871488984,10,2.32496404007729E-6,,,,,,,,,,,,,,,,,,,,,299.940399169922,299.943176269531,7894.34033203125,7894.34033203125,47.4002982917166,5.27199794688991,12.3904123306274,27,1,0,0,1,0.275802612304687,39.1006851196289,1,1,1,299.943176269531,0,299.941787719727,,,,,,,,,,,,,,,,,,,,,,,,,,,,,,,,,
,3832825149.2125,299.972015380859,9999.830078125,0.000400576648394579,6.44194204447615E-8,1,2,13.4005146026611,4.99244686773715,33.7099991738796,0.53270762791096,0.0785396012586144,10,2.98799493044142E-6,,,,,,,,,,,,,,,,,,,,,299.971313476562,299.972717285156,9999.830078125,9999.830078125,47.3920911922646,5.27272902107739,12.7394094467163,27,1,0,0,1,0.276641845703125,39.1006851196289,1,1,1,299.972717285156,0,299.972015380859,,,,,,,,,,,,,,,,,,,,,,,,,,,,,,,,,
,3832825188.29486,300.01594543457,13333.01171875,0.000533989610619038,4.40898163730491E-8,1,2,13.4005146026611,4.99275084901065,33.7099991738796,0.710031952989104,0.105810495091584,1,4.81266029319432E-6,,,,,,,,,,,,,,,,,,,,,300.014282226562,300.017608642578,13333.01171875,13333.01171875,47.4081145769089,5.27206190856677,13.1563014984131,27,1,0,0,1,0.27435302734375,39.5894432067871,1,1,1,300.017608642578,0,300.01594543457,,,,,,,,,,,,,,,,,,,,,,,,,,,,,,,,,
,3832825224.43649,300.032379150391,17777.66796875,0.000712057191992159,4.77882219505605E-8,1,2,13.4005146026611,4.99258136121302,33.7099991738796,0.946764549688425,0.141053429238046,1,6.39142214002302E-6,,,,,,,,,,,,,,,,,,,,,300.031982421875,300.032775878906,17777.66796875,17777.66796875,47.4385980891589,5.27188693003987,13.4566287994385,27,1,0,0,1,0.286788940429687,39.5894432067871,1,1,1,300.031982421875,0,300.032379150391,,,,,,,,,,,,,,,,,,,,,,,,,,,,,,,,,
,3832825262.13099,300.017700195313,21999.591796875,0.000881504329725003,7.90220436963596E-8,1,2,13.4005146026611,4.99266568538061,33.7099991738796,1.17214589949859,0.174236525025089,1,7.62153215775071E-6,,,,,,,,,,,,,,,,,,,,,300.017700195313,300.017700195313,21999.591796875,21999.591796875,47.4264828471108,5.27159465063265,13.686595916748,27,1,0,0,1,0.277099609375,39.5894432067871,1,1,1,300.017700195313,0,300.017700195313,,,,,,,,,,,,,,,,,,,,,,,,,,,,,,,,,
,3832825309.44054,300.008499145508,34999.69921875,0.00140205501649672,2.37371874856253E-7,1,2,13.4005146026611,4.99274626680694,33.7099991738796,1.86420613416524,0.27829889309455,1,1.29974025892593E-5,,,,,,,,,,,,,,,,,,,,,300.008117675781,300.008880615234,34999.69921875,34999.69921875,47.3522281377839,5.27155157315722,13.9642887115479,27,1,0,0,1,0.27679443359375,39.5894432067871,1,1,1,300.008117675781,0,300.008499145508,,,,,,,,,,,,,,,,,,,,,,,,,,,,,,,,,
,3832825379.04314,300.001342773438,58332.91796875,0.00233635023822701,2.45618480141377E-7,1,2,13.4005146026611,4.99281090036538,33.7099991738796,3.10723779096348,0.458644275861346,10,1.78170850647218E-5,,,,,,,,,,,,,,,,,,,,,300.000061035156,300.002624511719,58332.91796875,58332.91796875,47.3354231246204,5.27160952901873,14.3333320617676,27,1,0,0,1,0.277557373046875,39.5894432067871,1,1,1,300.000061035156,0,300.001342773438,,,,,,,,,,,,,,,,,,,,,,,,,,,,,,,,,
,3832825433.60442,299.999420166016,58333.15234375,0.00233563805048936,2.47026044668553E-7,1,2,13.4005146026611,4.99243435366184,33.7099991738796,3.10589858910051,0.458964790938475,10,1.81930362501142E-5,,,,,,,,,,,,,,,,,,,,,299.999176025391,299.999664306641,58333.15234375,58333.15234375,47.2756285428992,5.27331657470104,14.6376419067383,27,1,0,0,1,0.276107788085938,39.5894432067871,1,1,1,299.999664306641,0,299.999420166016,,,,,,,,,,,,,,,,,,,,,,,,,,,,,,,,,
,3832825489.42617,299.999435424805,34999.69921875,0.00140194467289755,1.40498724506136E-7,1,2,13.4005146026611,4.99261626465728,33.7099991738796,1.86444266656884,0.27505038448478,10,1.05801916113952E-5,,,,,,,,,,,,,,,,,,,,,299.999359130859,299.99951171875,34999.69921875,34999.69921875,47.3584811659377,5.27277355439654,14.8685035705566,27,1,0,0,1,0.275344848632813,39.5894432067871,1,1,1,299.99951171875,0,299.999435424805,,,,,,,,,,,,,,,,,,,,,,,,,,,,,,,,,
,3832825528.98899,300.000869750977,21999.654296875,0.000880539588324924,8.56557665693122E-8,1,2,13.4005146026611,4.99267706690304,33.7099991738796,1.17106540730549,0.17262544750921,10,6.54588374133358E-6,,,,,,,,,,,,,,,,,,,,,300.000793457031,300.000946044922,21999.654296875,21999.654296875,47.3502740664858,5.2728314322578,14.8954420089722,27,1,0,0,1,0.276870727539062,39.5894432067871,1,1,1,300.000946044922,0,300.000869750977,,,,,,,,,,,,,,,,,,,,,,,,,,,,,,,,,
,3832825564.80709,300.000442504883,17777.39453125,0.00071130807572417,7.12826433610236E-8,1,2,13.4005146026611,4.99228557814445,33.7099991738796,0.945924196220314,0.139230961381999,10,5.1357073549624E-6,,,,,,,,,,,,,,,,,,,,,300.000396728516,300.00048828125,17777.39453125,17777.39453125,47.3995166631973,5.27387124629323,14.8897476196289,27,1,0,0,1,0.273971557617187,39.5894432067871,1,1,1,300.000396728516,0,300.000442504883,,,,,,,,,,,,,,,,,,,,,,,,,,,,,,,,,
,3832825595.62587,300.003265380859,13333.0986328125,0.000532763464469438,6.73045410852561E-8,1,2,13.4005146026611,4.9928709702999,33.720001578331,0.708434520178095,0.105502456174908,1,4.75011647894183E-6,,,,,,,,,,,,,,,,,,,,,300.003143310547,300.003387451172,13333.0986328125,13333.0986328125,47.4342991323031,5.27163590980343,14.8798265457153,27,1,0,0,1,0.273590087890625,40.0782012939453,1,1,1,300.003387451172,0,300.003265380859,,,,,,,,,,,,,,,,,,,,,,,,,,,,,,,,,
,3832825628.41356,300.001129150391,9999.5810546875,0.000399070927932167,7.77150142424875E-8,1,2,13.4005146026611,4.99287302785607,33.7099991738796,0.5306800100585,0.0788779994123706,1,3.44579462064377E-6,,,,,,,,,,,,,,,,,,,,,300.001129150391,300.001129150391,9999.5810546875,9999.5810546875,47.5030824419954,5.27213001612546,14.8853273391724,27,1,0,0,1,0.277175903320313,40.0782012939453,1,1,1,300.001129150391,0,300.001129150391,,,,,,,,,,,,,,,,,,,,,,,,,,,,,,,,,
,3832825653.90123,300.002365112305,7894.34033203125,0.00031464259427532,4.20980179813542E-8,1,2,13.4005146026611,4.99295645028259,33.7099991738796,0.418445398479417,0.0619940479672055,1,2.56825453383476E-6,,,,,,,,,,,,,,,,,,,,,300.002227783203,300.002502441406,7894.34033203125,7894.34033203125,47.4514949597262,5.27118959555442,14.8928489685059,27,1,0,0,1,0.27435302734375,40.0782012939453,1,1,1,300.002227783203,0,300.002365112305,,,,,,,,,,,,,,,,,,,,,,,,,,,,,,,,,
,3832825677.65782,300.005111694336,5789.111328125,0.000230151513437707,3.78270764423652E-8,1,2,13.4005146026611,4.99288742356942,33.7099991738796,0.306097322210299,0.0451813775021162,1,1.75502447016791E-6,,,,,,,,,,,,,,,,,,,,,300.004211425781,300.006011962891,5789.111328125,5789.111328125,47.3389404529569,5.27195506852184,14.8689889907837,27,1,0,0,1,0.27740478515625,40.0782012939453,1,1,1,300.006011962891,0,300.005111694336,,,,,,,,,,,,,,,,,,,,,,,,,,,,,,,,,
,3832825717.99619,300.015655517578,3683.74536132812,0.000145665176724655,1.38219854127506E-8,1,2,13.4005146026611,4.9927449979288,33.7099991738796,0.193721165278172,0.0286181864314928,1,1.12847028664072E-6,,,,,,,,,,,,,,,,,,,,,300.015655517578,300.015655517578,3683.74536132812,3683.74536132812,47.3193997399762,5.27282302710279,14.8676633834839,27,1,0,0,1,0.277862548828125,40.0782012939453,1,1,1,300.015655517578,0,300.015655517578,,,,,,,,,,,,,,,,,,,,,,,,,,,,,,,,,
,3832825740.0295,300.01252746582,1578.47924804687,6.13971529874936E-5,1.44039356361814E-8,1,2,13.4005146026611,4.99284547325529,33.7099991738796,0.0816631097290897,0.0120030880975679,1,4.30827544940252E-7,,,,,,,,,,,,,,,,,,,,,300.012481689453,300.012573242188,1578.47924804687,1578.47924804687,47.3897463067069,5.27120439914246,14.8776302337646,27,1,0,0,1,0.274276733398438,40.0782012939453,1,1,1,300.012481689453,0,300.01252746582,,,,,,,,,,,,,,,,,,,,,,,,,,,,,,,,,
,3832825765.69804,300.015029907227,-525.939514160156,-2.1944127315061E-5,1.44425370809151E-8,1,2,13.4005146026611,4.99282446088864,33.7099991738796,-0.0291761068101218,-0.00436987818059819,1,-2.13955556257132E-7,,,,,,,,,,,,,,,,,,,,,300.013824462891,300.016235351562,-525.939514160156,-525.939514160156,47.4444603030531,5.27192625950347,14.8596115112305,27,1,0,0,1,0.276870727539062,40.0782012939453,1,1,1,300.016235351562,0,300.015029907227,,,,,,,,,,,,,,,,,,,,,,,,,,,,,,,,,
,3832825788.06033,300.033447265625,-2631.25561523438,-0.00010534037505815,4.86076339190046E-8,1,2,13.4005146026611,4.99285571312942,33.7099991738796,-0.140074128616554,-0.0208612365517177,1,-9.39895063403538E-7,,,,,,,,,,,,,,,,,,,,,300.032745361328,300.034149169922,-2631.25561523438,-2631.25561523438,47.412022719505,5.27223970912386,14.8459959030151,27,1,0,0,1,0.275497436523438,40.0782012939453,1,1,1,300.032745361328,0,300.033447265625,,,,,,,,,,,,,,,,,,,,,,,,,,,,,,,,,
,3832825812.17727,300.022750854492,-4736.55908203125,-0.000189528987704335,1.97121438202427E-8,1,2,13.4005146026611,4.99293480540095,33.7099991738796,-0.252037162457651,-0.0374662254557654,1,-1.63980935662623E-6,,,,,,,,,,,,,,,,,,,,,300.021942138672,300.023559570313,-4736.55908203125,-4736.55908203125,47.493312085505,5.27213054093412,14.8507499694824,27,1,0,0,1,0.27587890625,40.0782012939453,1,1,1,300.021942138672,0,300.022750854492,,,,,,,,,,,,,,,,,,,,,,,,,,,,,,,,,
,3832825837.51054,300.019821166992,-6841.61376953125,-0.000273760061825524,4.19997849486976E-8,1,2,13.4005146026611,4.99285107713564,33.7099991738796,-0.364014215553554,-0.0542999091071936,1,-2.50683166044847E-6,,,,,,,,,,,,,,,,,,,,,300.019287109375,300.020355224609,-6841.61376953125,-6841.61376953125,47.3733321078031,5.27166315532943,14.8404369354248,26,1,68,0,0,0.28564453125,40.0782012939453,1,1,1,300.019287109375,0,300.019821166992,,,,,,,,,,,,,,,,,,,,,,,,,,,,,,,,,
,3832825863.48643,299.889801025391,-8946.9794921875,-0.000358177090784992,4.76190666754023E-8,1,2,13.4005146026611,4.99267378520323,33.7099991738796,-0.476262087076481,-0.070875074983564,1,-3.15562565187604E-6,,,,,,,,,,,,,,,,,,,,,299.884124755859,299.895477294922,-8946.9794921875,-8946.9794921875,47.3901371209666,5.27200647331836,14.8214340209961,27,1,0,0,1,0.277099609375,39.5894432067871,1,1,1,299.884124755859,0,299.889801025391,,,,,,,,,,,,,,,,,,,,,,,,,,,,,,,,,
,3832825896.82481,299.744812011719,-11999.69921875,-0.000481303788863407,4.13065617119592E-8,1,2,13.4005146026611,4.9928595827907,33.7099991738796,-0.640009706527498,-0.0952762860346628,1,-4.26472885243907E-6,,,,,,,,,,,,,,,,,,,,,299.744812011719,299.744812011719,-11999.69921875,-11999.69921875,47.3397220814762,5.27194676923435,14.7886190414429,27,1,0,0,1,0.277862548828125,39.5894432067871,1,1,1,299.744812011719,0,299.744812011719,,,,,,,,,,,,,,,,,,,,,,,,,,,,,,,,,
,3832825922.9279,299.817825317383,-14999.689453125,-0.000601297346109498,5.87666792243737E-8,1,2,13.4005146026611,4.99283572267895,33.7099991738796,-0.799539929982506,-0.119207395165666,1,-5.46212353739216E-6,,,,,,,,,,,,,,,,,,,,,299.812347412109,299.823303222656,-14999.689453125,-14999.689453125,47.4237471472935,5.27249305200092,14.7815074920654,27,1,0,0,1,0.277099609375,39.5894432067871,1,1,1,299.823303222656,0,299.817825317383,,,,,,,,,,,,,,,,,,,,,,,,,,,,,,,,,
,3832825950.68033,299.912704467773,-19999.72265625,-0.000801489274411159,8.47157794893867E-8,1,2,13.4005146026611,4.99278727294675,33.7099991738796,-1.06567253679881,-0.159227490935932,1,-7.53158719029737E-6,,,,,,,,,,,,,,,,,,,,,299.909790039063,299.915618896484,-19999.72265625,-19999.72265625,47.3936544493031,5.27248253881442,14.7833251953125,27,1,0,0,1,0.274810791015625,39.5894432067871,1,1,1,299.915618896484,0,299.912704467773,,,,,,,,,,,,,,,,,,,,,,,,,,,,,,,,,
,3832825986.66944,299.96501159668,-25555.4453125,-0.00102386253235689,1.03671904874352E-7,1,2,13.4005146026611,4.99278280512932,33.7099991738796,-1.36133921997187,-0.203423307671298,1,-9.63503736395791E-6,,,,,,,,,,,,,,,,,,,,,299.963531494141,299.966491699219,-25555.4453125,-25555.4453125,47.3791943216973,5.27246288488856,14.781213760376,27,1,0,0,1,0.273666381835938,39.5894432067871,1,1,1,299.966491699219,0,299.96501159668,,,,,,,,,,,,,,,,,,,,,,,,,,,,,,,,,
,3832826054.48142,300.011352539063,-43333.0390625,-0.00173616259931114,1.86311962374019E-7,1,2,13.4005146026611,4.99292813331544,33.7099991738796,-2.30907197463617,-0.340964497693246,10,-1.33383497190066E-5,,,,,,,,,,,,,,,,,,,,,300.011352539063,300.011352539063,-43333.0390625,-43333.0390625,47.3428485955531,5.27153897978387,14.7807149887085,27,1,0,0,1,0.274810791015625,39.5894432067871,1,1,1,300.011352539063,0,300.011352539063,,,,,,,,,,,,,,,,,,,,,,,,,,,,,,,,,
,3832826099.22841,300.00895690918,-61110.734375,-0.00244705447690833,2.13747692052449E-7,1,2,13.4005146026611,4.99292727818269,33.7099991738796,-3.25441571279561,-0.481518535366536,10,-1.9507626104562E-5,,,,,,,,,,,,,,,,,,,,,300.008819580078,300.009094238281,-61110.734375,-61110.734375,47.1970748767165,5.27024131782039,14.7596378326416,27,1,0,0,1,0.272979736328125,40.0782012939453,1,1,1,300.008819580078,0,300.00895690918,,,,,,,,,,,,,,,,,,,,,,,,,,,,,,,,,
,3832826146.91729,300.003494262695,-61110.6953125,-0.00244573512638475,1.6989137556721E-7,1,2,13.4005146026611,4.99283201717446,33.7099991738796,-3.25273472992111,-0.4801112970467,10,-1.86445793543565E-5,,,,,,,,,,,,,,,,,,,,,300.003387451172,300.003601074219,-61110.6953125,-61110.6953125,47.2564786441781,5.27131755992237,14.7499990463257,27,1,0,0,1,0.275192260742187,39.5894432067871,1,1,1,300.003387451172,0,300.003494262695,,,,,,,,,,,,,,,,,,,,,,,,,,,,,,,,,
,3832826192.63074,299.996322631836,-43332.9765625,-0.00173461112560329,1.81471473200859E-7,1,2,13.4005146026611,4.99266075458279,33.7099991738796,-2.30690790137569,-0.34014373892583,10,-1.29575730768138E-5,,,,,,,,,,,,,,,,,,,,,299.996246337891,299.996398925781,-43332.9765625,-43332.9765625,47.3412853385146,5.27258939282374,14.7540922164917,27,1,0,0,1,0.274887084960938,40.0782012939453,1,1,1,299.996398925781,0,299.996322631836,,,,,,,,,,,,,,,,,,,,,,,,,,,,,,,,,
,3832826239.07968,299.99983215332,-25555.45703125,-0.00102213805228492,1.38970021523124E-7,1,2,13.4005146026611,4.9927121545647,33.7099991738796,-1.35944843736299,-0.20001242018254,10,-7.31711906232905E-6,,,,,,,,,,,,,,,,,,,,,299.999176025391,300.00048828125,-25555.45703125,-25555.45703125,47.3225262540531,5.27260948884368,14.73171043396,27,1,0,0,1,0.277862548828125,40.0782012939453,1,1,1,299.999176025391,0,299.99983215332,,,,,,,,,,,,,,,,,,,,,,,,,,,,,,,,,
,3832826278.99624,299.998352050781,-19999.685546875,-0.000799172876401128,8.05292425466867E-8,1,2,13.4005146026611,4.99289643475132,33.7099991738796,-1.0629489581275,-0.156451224148939,10,-5.76667039057557E-6,,,,,,,,,,,,,,,,,,,,,299.998352050781,299.998352050781,-19999.685546875,-19999.685546875,47.3537913948223,5.27176555992726,14.719518661499,27,1,0,0,1,0.277786254882813,40.0782012939453,1,1,1,299.998352050781,0,299.998352050781,,,,,,,,,,,,,,,,,,,,,,,,,,,,,,,,,
,3832826304.38079,299.999618530273,-14999.6640625,-0.000598651951376458,5.88021176861251E-8,1,2,13.4005146026611,4.9926962158198,33.7099991738796,-0.796232016934446,-0.116961035023667,10,-4.14813221371841E-6,,,,,,,,,,,,,,,,,,,,,299.999114990234,300.000122070313,-14999.6640625,-14999.6640625,47.3721596650242,5.27235434675209,14.716869354248,27,1,0,0,1,0.276412963867187,40.0782012939453,1,1,1,299.999114990234,0,299.999618530273,,,,,,,,,,,,,,,,,,,,,,,,,,,,,,,,,
,3832826337.28522,299.998626708984,-9999.7685546875,-0.000398051928825069,4.98070024197689E-8,1,2,13.4005146026611,4.99239957387943,33.720001578331,-0.52929946803367,-0.0783567210681926,1,-3.20439391930369E-6,,,,,,,,,,,,,,,,,,,,,299.998474121094,299.998779296875,-9999.7685546875,-9999.7685546875,47.42726447563,5.27405309115437,14.6971340179443,27,1,0,0,1,0.274810791015625,40.0782012939453,1,1,1,299.998748779297,0,299.998626708984,,,,,,,,,,,,,,,,,,,,,,,,,,,,,,,,,
,3832826367.91822,300.019577026367,-8947.0048828125,-0.000355789339806049,4.72223596730589E-8,1,2,13.4005146026611,4.99254160122955,33.7099991738796,-0.473150315385549,-0.0698254124234982,1,-2.70295256456519E-6,,,,,,,,,,,,,,,,,,,,,300.01953125,300.019622802734,-8947.0048828125,-8947.0048828125,47.4253104043319,5.2737906578021,14.6796092987061,27,1,0,0,1,0.275192260742187,40.0782012939453,1,1,1,300.01953125,0,300.019577026367,,,,,,,,,,,,,,,,,,,,,,,,,,,,,,,,,
,3832826398.85813,300.019775390625,-6841.85009765625,-0.000271341951101693,3.33433513830355E-8,1,2,13.4005146026611,4.99251230857185,33.7099991738796,-0.360847275220416,-0.0532293267540913,1,-2.04454385208859E-6,,,,,,,,,,,,,,,,,,,,,300.019317626953,300.020233154297,-6841.85009765625,-6841.85009765625,47.3893554924473,5.27395907876878,14.6772451400757,27,1,0,0,1,0.274505615234375,40.0782012939453,1,1,1,300.019317626953,0,300.019775390625,,,,,,,,,,,,,,,,,,,,,,,,,,,,,,,,,
,3832826431.67369,300.045837402344,-4736.52197265625,-0.000186852723619406,2.31790966109836E-8,1,2,13.4005146026611,4.99221949493198,33.7099991738796,-0.248458022276948,-0.0367256708815688,1,-1.46321100099997E-6,,,,,,,,,,,,,,,,,,,,,300.045837402344,300.045837402344,-4736.52197265625,-4736.52197265625,47.3862289783704,5.27476427226635,14.6680135726929,27,1,0,0,1,0.275497436523438,39.5894432067871,1,1,1,300.045837402344,0,300.045837402344,,,,,,,,,,,,,,,,,,,,,,,,,,,,,,,,,
,3832826451.09472,300.053237915039,-2631.3427734375,-0.000102693195233491,2.94256399072973E-8,1,2,13.4005146026611,4.99221244306785,33.7099991738796,-0.136592923755198,-0.0198832923766686,1,-5.78136668124137E-7,,,,,,,,,,,,,,,,,,,,,300.052703857422,300.053771972656,-2631.3427734375,-2631.3427734375,47.450713331207,5.27484010024583,14.6792020797729,27,1,0,0,1,0.276947021484375,40.0782012939453,1,1,1,300.052703857422,0,300.053237915039,,,,,,,,,,,,,,,,,,,,,,,,,,,,,,,,,
,3832826474.0595,300.045486450195,-526.724731445313,-1.90336303652919E-5,2.72399735284742E-8,1,2,13.4005146026611,4.99263018320874,33.7099991738796,-0.0253460977178994,-0.00349664243419863,1,3.4842207619029E-8,,,,,,,,,,,,,,,,,,,,,300.04541015625,300.045562744141,-526.724731445313,-526.724731445313,47.4620469447358,5.27373013852207,14.6627979278564,27,1,0,0,1,0.274887084960938,40.0782012939453,1,1,1,300.045532226562,0,300.045486450195,,,,,,,,,,,,,,,,,,,,,,,,,,,,,,,,,
,3832826497.6169,300.043899536133,1578.728515625,6.27939217399223E-5,2.45738894340637E-8,1,2,13.4005146026611,4.9927181911949,33.7099991738796,0.0834833948236495,0.0125232629512695,1,6.26559298849441E-7,,,,,,,,,,,,,,,,,,,,,300.04345703125,300.044342041016,1578.728515625,1578.728515625,47.3604352372358,5.27318148402196,14.644606590271,27,1,0,0,1,0.275497436523438,40.0782012939453,1,1,1,300.04345703125,0,300.043899536133,,,,,,,,,,,,,,,,,,,,,,,,,,,,,,,,,
,3832826523.14715,300.046264648438,3683.82006835937,0.000146473160729018,2.20430419750271E-8,1,2,13.4005146026611,4.99291305425082,33.7099991738796,0.194785598111105,0.0289148293480758,1,1.23730856990629E-6,,,,,,,,,,,,,,,,,,,,,300.045135498047,300.047393798828,3683.82006835937,3683.82006835937,47.4194481904377,5.27246267603157,14.6497459411621,27,1,0,0,1,0.276641845703125,40.0782012939453,1,1,1,300.045135498047,0,300.046264648438,,,,,,,,,,,,,,,,,,,,,,,,,,,,,,,,,
,3832826546.6319,300.040084838867,5789.310546875,0.000230548087133873,3.33166048430566E-8,1,2,13.4005146026611,4.99303518697771,33.7099991738796,0.306581607564859,0.0456586098162405,1,2.05662776962123E-6,,,,,,,,,,,,,,,,,,,,,300.038848876953,300.041320800781,5789.310546875,5789.310546875,47.2916519275435,5.27234639375492,14.6489114761353,27,1,0,0,1,0.278167724609375,40.0782012939453,1,1,1,300.038848876953,0,300.040084838867,,,,,,,,,,,,,,,,,,,,,,,,,,,,,,,,,
,3832826569.41881,300.060302734375,7894.6396484375,0.000314696168557618,4.08952875698692E-8,1,2,13.4005146026611,4.99304087757031,33.7099991738796,0.418470950790061,0.0624022158558355,1,2.86624204400742E-6,,,,,,,,,,,,,,,,,,,,,300.058563232422,300.062042236328,7894.6396484375,7894.6396484375,47.4765070723416,5.27275627194555,14.6407136917114,27,1,0,0,1,0.275726318359375,40.0782012939453,1,1,1,300.062042236328,0,300.060302734375,,,,,,,,,,,,,,,,,,,,,,,,,,,,,,,,,
,3832826595.35908,300.093124389648,9999.5810546875,0.000398938463500219,4.7512918844543E-8,1,2,13.4005146026611,4.9931000104622,33.7099991738796,0.530533266024823,0.078882783261827,1,3.46421840660415E-6,,,,,,,,,,,,,,,,,,,,,300.090942382812,300.095306396484,9999.5810546875,9999.5810546875,47.5120711699666,5.27207066018004,14.6348819732666,27,1,0,0,1,0.275344848632813,40.0782012939453,1,1,1,300.095306396484,0,300.093124389648,,,,,,,,,,,,,,,,,,,,,,,,,,,,,,,,,
,3832826630.96335,300.081344604492,13332.962890625,0.000532339119697932,7.5008514090314E-8,1,2,13.4005146026611,4.99294042127151,33.7099991738796,0.707863896874512,0.105562399076071,1,4.85296042326318E-6,,,,,,,,,,,,,,,,,,,,,300.079711914063,300.082977294922,13332.962890625,13332.962890625,47.3928728207839,5.27288841697862,14.6180667877197,27,1,0,0,1,0.278701782226562,40.0782012939453,1,1,1,300.079711914063,0,300.081344604492,,,,,,,,,,,,,,,,,,,,,,,,,,,,,,,,,
,3832826656.77947,300.06330871582,17777.33203125,0.000710172641965688,4.58361622629754E-8,1,2,13.4005146026611,4.99312806877265,33.7099991738796,0.944368536839332,0.140929914221065,1,6.54626170763567E-6,,,,,,,,,,,,,,,,,,,,,300.062316894531,300.064300537109,17777.33203125,17777.33203125,47.3987350346781,5.27145093406441,14.6112174987793,27,1,0,0,1,0.276260375976562,40.0782012939453,1,1,1,300.062316894531,0,300.06330871582,,,,,,,,,,,,,,,,,,,,,,,,,,,,,,,,,
,3832826693.19859,300.051391601562,21999.62890625,0.000879392658618161,8.24882654715391E-8,1,2,13.4005146026611,4.99316308650104,33.7099991738796,1.16948835940097,0.173909161645159,1,7.65306443266634E-6,,,,,,,,,,,,,,,,,,,,,300.051391601562,300.051391601562,21999.62890625,21999.62890625,47.4225747045146,5.27205401301551,14.6254463195801,27,1,0,0,1,0.285186767578125,40.0782012939453,1,1,1,300.051391601562,0,300.051391601562,,,,,,,,,,,,,,,,,,,,,,,,,,,,,,,,,
,3832826739.95078,300.02180480957,34999.94921875,0.00139965581919103,1.61560442572452E-7,1,2,13.4005146026611,4.99304079539135,33.7099991738796,1.86116979642642,0.277821873536922,1,1.2957697049186E-5,,,,,,,,,,,,,,,,,,,,,300.020629882812,300.022979736328,34999.94921875,34999.94921875,47.4002982917166,5.27197194546438,14.6077909469604,27,1,0,0,1,0.276336669921875,40.0782012939453,1,1,1,300.020629882812,0,300.02180480957,,,,,,,,,,,,,,,,,,,,,,,,,,,,,,,,,
,3832826816.8946,299.800750732422,58333.1796875,0.00233538867744589,2.04336241132918E-7,1,2,13.4005146026611,4.99273298614726,33.7099991738796,3.10594380741225,0.458079043256635,10,1.75343415222097E-5,,,,,,,,,,,,,,,,,,,,,299.800750732422,299.800750732422,58333.1796875,58333.1796875,47.3045487981108,5.27341344853445,14.5714445114136,27,1,0,0,1,0.275726318359375,40.0782012939453,1,1,1,299.800750732422,0,299.800750732422,,,,,,,,,,,,,,,,,,,,,,,,,,,,,,,,,
,3832826869.47605,299.845642089844,58333.203125,0.0023335026712422,2.32484708331836E-7,1,2,13.4005146026611,4.99238034212512,33.7099991738796,3.10314671747711,0.457581929097399,10,1.74579243819038E-5,,,,,,,,,,,,,,,,,,,,,299.843139648438,299.84814453125,58333.203125,58333.203125,47.300249841255,5.27446022963572,14.5750741958618,27,1,0,0,1,0.2862548828125,40.5669593811035,1,1,1,299.84814453125,0,299.845642089844,,,,,,,,,,,,,,,,,,,,,,,,,,,,,,,,,
,3832826923.00143,299.973052978516,34999.6484375,0.00139898993428704,9.02583967488395E-8,1,2,13.4005146026611,4.99273347853101,33.7099991738796,1.86060695057078,0.274236889458069,10,1.03756489813183E-5,,,,,,,,,,,,,,,,,,,,,299.971557617188,299.974548339844,34999.6484375,34999.6484375,47.4319542467454,5.27317696987766,14.5712795257568,27,1,0,0,1,0.277481079101562,40.0782012939453,1,1,1,299.974548339844,0,299.973052978516,,,,,,,,,,,,,,,,,,,,,,,,,,,,,,,,,
,3832826964.35154,300.010070800781,21999.716796875,0.000878177466599505,9.29076954021392E-8,1,2,13.4005146026611,4.99276476603003,33.7099991738796,1.16800041339143,0.171820537926269,10,6.26846000193876E-6,,,,,,,,,,,,,,,,,,,,,300.009857177734,300.010284423828,21999.716796875,21999.716796875,47.4432878602743,5.27355426387626,14.581374168396,27,1,0,0,1,0.274734497070313,40.5669593811035,1,1,1,300.009857177734,0,300.010070800781,,,,,,,,,,,,,,,,,,,,,,,,,,,,,,,,,