File: SI Fig S11-13 SQUID all/Michaela_HO_FC1T.dat
[Header]
; MPMS3 Data File (default extension .dat)
; Copyright (c) 2007, Quantum Design, Inc. All rights reserved.
TITLE,
FILEOPENTIME,3834058693.9015,06/28/2021,4:19 pm
BYAPP,MPMS3 w/ AC,1.0,1.1
INFO,MPMS3 Measurement Release 1.1.16 Build 424, MultiVu Release 2.3.4.19,APPNAME
INFO,Linear Motor Servo Controller,MOTOR_MODULE_NAME
INFO,3101-100 E1,MOTOR_HW_VERSION
INFO,MMC211,MOTOR_SERIAL_NUMBER
INFO,01.04.28,MOTOR_SOFTWARE_VERSION
INFO,Quantum Design Squid Module,SQUID_MODULE_NAME
INFO,3101-501 B0,SQUID_HW_VERSION
INFO,SQM059,SQUID_SERIAL_NUMBER
INFO,01.03.04,SQUID_SOFTWARE_VERSION
INFO,SQUID AC,AC_MODULE_NAME
INFO,3101-401 F1,AC_HW_VERSION
INFO,SAC057,AC_SERIAL_NUMBER
INFO,SQUID AC 00.95.07,AC_SOFTWARE_VERSION
INFO,TCIXXX,COIL_SERIAL_NUMBER
INFO,0,MOMENT_UNITS
INFO,Michaela_HO,SAMPLE_MATERIAL
INFO,Michaela_HO,SAMPLE_COMMENT
INFO,1.06,SAMPLE_MASS
INFO,,SAMPLE_VOLUME
INFO,,SAMPLE_MOLECULAR_WEIGHT
INFO,,SAMPLE_SIZE
INFO,,SAMPLE_SHAPE
INFO,Straw,SAMPLE_HOLDER
INFO,Standard,SAMPLE_HOLDER_DETAIL
INFO,52.84,SAMPLE_OFFSET
DATATYPE,COMMENT,1
DATATYPE,TIME,2
STARTUPAXIS,X,2
STARTUPAXIS,Y1,5
FIELDGROUP, VSM,2,3,4,5,6,8,9,10,11,14,15
FIELDGROUP, DC, 2,3,4,14,56,57,58,59,60,61,62,63,64,65,66,67,68,69
FIELDGROUP, AC, 2,3,4,11,16,17,18,19,20,21,22,23,24,25,26,27,28,29,30
STARTUPGROUP, All
[Data]
Comment,Time Stamp (sec),Temperature (K),Magnetic Field (Oe),Moment (emu),M. Std. Err. (emu),Transport Action,Averaging Time (sec),Frequency (Hz),Peak Amplitude (mm),Center Position (mm),Lockin Signal' (V),Lockin Signal (V),Range,M. Quad. Signal (emu),AC Moment (emu),AC M. Std Err. (emu),AC Phase (deg),AC Phase Std. Err. (deg),AC Susceptibility (emu/Oe),AC Suscept. Std Err. (emu/Oe),AC X' (emu/Oe),AC X' Std Err. (emu/Oe),AC X'' (emu/Oe),AC X'' Std Err. (emu/Oe),AC Drive (Oe),AC Frequency (Hz),AC Averaging Time (sec),AC Cycles,AC Range,AC Measure Type,AC Signal' (V),AC Signal'' (V),AC Trim Coil Ratio,AC Trim Coil Phase,Min. Temperature (K),Max. Temperature (K),Min. Field (Oe),Max. Field (Oe),Mass (grams),Motor Lag (deg),Pressure (Torr),Measure Count,Measurement Number,SQUID Status (code),Motor Status (code),Measure Status (code),Motor Current (amps),Motor Temp. (C),Temp. Status (code),Field Status (code),Chamber Status (code),Chamber Temp (K),Redirection State,Average Temp (K),Rotation Angle (deg),Rotator state,DC Moment Fixed Ctr (emu),DC Moment Err Fixed Ctr (emu),DC Moment Free Ctr (emu),DC Moment Err Free Ctr (emu),DC Fixed Fit,DC Free Fit,DC Calculated Center (mm),DC Calculated Center Err (mm),DC Scan Length (mm),DC Scan Time (s),DC Number of Points,DC Squid Drift,DC Min V (V),DC Max V (V),DC Scans per Measure,Map 01,Map 02,Map 03,Map 04,Map 05,Map 06,Map 07,Map 08,Map 09,Map 10,Map 11,Map 12,Map 13,Map 14,Map 15,Map 16
,3834058700.13557,299.953384399414,9999.6064453125,0.000612951316666567,7.30901926130099E-8,1,2,13.4005146026611,4.99594556602651,34.2799983918667,0.815792089165681,0.121189435020126,1,5.24373760320193E-6,,,,,,,,,,,,,,,,,,,,,299.953125,299.953643798828,9999.6064453125,9999.6064453125,47.5820269224377,5.27779992617282,13.0952453613281,27,1,0,0,1,0.29144287109375,41.055721282959,1,1,1,299.953643798828,0,299.953384399414,,,,,,,,,,,,,,,,,,,,,,,,,,,,,,,,,
,3834058733.99745,298.828308105469,9999.6064453125,0.000616304612802698,8.97240235700482E-8,1,2,13.4005146026611,4.99595058295067,34.2799983918667,0.820255569661842,0.121857122307866,1,5.27581981120158E-6,,,,,,,,,,,,,,,,,,,,,298.740386962891,298.916229248047,9999.6064453125,9999.6064453125,47.4905763856877,5.27753100178607,13.1075992584229,27,1,0,0,1,0.291519165039063,41.055721282959,2,1,1,298.740386962891,0,298.828308105469,,,,,,,,,,,,,,,,,,,,,,,,,,,,,,,,,
,3834058764.33448,296.371154785156,9999.6064453125,0.000622637508303752,8.94058236229706E-8,1,2,13.4005146026611,4.99594062552568,34.2600010335445,0.828698490173036,0.122990431664854,1,5.24109593270882E-6,,,,,,,,,,,,,,,,,,,,,296.290832519531,296.451477050781,9999.6064453125,9999.6064453125,47.533956768505,5.27754326650902,13.1307144165039,27,1,0,0,1,0.29052734375,41.055721282959,2,1,1,296.290832519531,0,296.371154785156,,,,,,,,,,,,,,,,,,,,,,,,,,,,,,,,,
,3834058793.58688,293.710327148438,9999.6064453125,0.000629322493944802,5.69898198435426E-8,1,2,13.4005146026611,4.99593869610913,34.2600010335445,0.837610695581384,0.124201603237167,1,5.21537431109608E-6,,,,,,,,,,,,,,,,,,,,,293.552490234375,293.8681640625,9999.6064453125,9999.6064453125,47.5886707648512,5.27754153480066,13.1398305892944,27,1,0,0,1,0.291595458984375,41.055721282959,2,1,1,293.552490234375,0,293.710327148438,,,,,,,,,,,,,,,,,,,,,,,,,,,,,,,,,
,3834058824.50683,290.92057800293,9999.6064453125,0.00063585382816882,4.78486162800047E-8,1,2,13.4005146026611,4.99593431824025,34.2399999499321,0.846303240770182,0.125486619709306,1,5.26661833785064E-6,,,,,,,,,,,,,,,,,,,,,290.855010986328,290.986145019531,9999.6064453125,9999.6064453125,47.4706448584473,5.27729526238557,13.1955823898315,27,1,0,0,1,0.291213989257812,41.5444793701172,2,1,1,290.855010986328,0,290.92057800293,,,,,,,,,,,,,,,,,,,,,,,,,,,,,,,,,
,3834058855.05617,288.258193969727,9999.6064453125,0.000642040226819389,5.09471955808538E-8,1,2,13.4005146026611,4.9959327543513,34.2199988663197,0.85453584220123,0.126714265971951,1,5.32296665645791E-6,,,,,,,,,,,,,,,,,,,,,288.174499511719,288.341888427734,9999.6064453125,9999.6064453125,47.5406006109185,5.27751728070638,13.2531881332397,27,1,0,0,1,0.291976928710937,41.055721282959,2,1,1,288.174499511719,0,288.258193969727,,,,,,,,,,,,,,,,,,,,,,,,,,,,,,,,,
,3834058887.59502,285.780319213867,9999.6064453125,0.00064844568830246,9.11594629427864E-8,1,2,13.4005146026611,4.99596686887045,34.2000015079975,0.863063774301516,0.128019796503143,1,5.4061954505611E-6,,,,,,,,,,,,,,,,,,,,,285.753753662109,285.806884765625,9999.6064453125,9999.6064453125,47.5230139692358,5.27729373227749,13.2943534851074,25,1,64,0,0,0.291595458984375,41.055721282959,2,1,1,285.753753662109,0,285.780319213867,,,,,,,,,,,,,,,,,,,,,,,,,,,,,,,,,
,3834058917.21421,283.344741821289,9999.6064453125,0.000654445046060457,3.8106036031567E-8,1,2,13.4005146026611,4.99593737580523,34.2000015079975,0.871042542741666,0.129197261033949,1,5.45177201424193E-6,,,,,,,,,,,,,,,,,,,,,283.287292480469,283.402191162109,9999.6064453125,9999.6064453125,47.6367409187839,5.27702086226759,13.2448778152466,27,1,0,0,1,0.290069580078125,41.5444793701172,2,1,1,283.287292480469,0,283.344741821289,,,,,,,,,,,,,,,,,,,,,,,,,,,,,,,,,
,3834058947.49737,280.95930480957,9999.6064453125,0.000660215848081733,9.30468053702202E-8,1,2,13.4005146026611,4.99592702392176,34.1800004243851,0.878728851667669,0.130278380272177,1,5.45650298998895E-6,,,,,,,,,,,,,,,,,,,,,280.894195556641,281.0244140625,9999.6064453125,9999.6064453125,47.5554515527839,5.27722198408171,13.1911544799805,27,1,0,0,1,0.2923583984375,41.5444793701172,2,1,1,280.894195556641,0,280.95930480957,,,,,,,,,,,,,,,,,,,,,,,,,,,,,,,,,
,3834058977.63612,278.510406494141,9999.6064453125,0.000666163582206351,1.16387389279225E-7,1,2,13.4005146026611,4.99592860461048,34.170001745224,0.886620646601246,0.131629863808275,1,5.63907526696853E-6,,,,,,,,,,,,,,,,,,,,,278.412536621094,278.608276367187,9999.6064453125,9999.6064453125,47.582808550957,5.27723987448723,13.152271270752,27,1,0,0,1,0.291824340820313,41.055721282959,2,1,1,278.412536621094,0,278.510406494141,,,,,,,,,,,,,,,,,,,,,,,,,,,,,,,,,
,3834059007.87537,276.049468994141,9999.6064453125,0.000672407307469178,8.21750390264615E-8,1,2,13.4005146026611,4.99595320288864,34.1500006616116,0.894951798335745,0.132756329178917,1,5.61076448000425E-6,,,,,,,,,,,,,,,,,,,,,275.957458496094,276.141479492187,9999.6064453125,9999.6064453125,47.5867166935531,5.27684552008586,13.1418228149414,27,1,0,0,1,0.29083251953125,41.055721282959,2,1,1,275.957458496094,0,276.049468994141,,,,,,,,,,,,,,,,,,,,,,,,,,,,,,,,,
,3834059038.23344,273.536239624023,9999.6064453125,0.00067862960450195,6.54369588342794E-8,1,2,13.4005146026611,4.99592894697586,34.1500006616116,0.903208409246313,0.134120203946216,1,5.7649508244812E-6,,,,,,,,,,,,,,,,,,,,,273.430908203125,273.641571044922,9999.6064453125,9999.6064453125,47.6148553202454,5.27704455002682,13.1254081726074,27,1,0,0,1,0.291061401367188,41.055721282959,2,1,1,273.430908203125,0,273.536239624023,,,,,,,,,,,,,,,,,,,,,,,,,,,,,,,,,
,3834059069.64502,270.861831665039,9999.6064453125,0.00068556840501594,7.17158646950687E-8,1,2,13.4005146026611,4.99592997854948,34.1299995779991,0.912463598445845,0.135349444002324,1,5.71722496181351E-6,,,,,,,,,,,,,,,,,,,,,270.708435058594,271.015228271484,9999.6064453125,9999.6064453125,47.5808544796589,5.27657802070935,13.1030712127686,27,1,0,0,1,0.282745361328125,41.055721282959,2,1,1,270.708435058594,0,270.861831665039,,,,,,,,,,,,,,,,,,,,,,,,,,,,,,,,,
,3834059100.56652,268.279983520508,9999.6064453125,0.000691955967685514,7.30390860548781E-8,1,2,13.4005146026611,4.99591902433894,34.1299995779991,0.920927611855808,0.136859042248183,1,5.95730912382139E-6,,,,,,,,,,,,,,,,,,,,,268.194671630859,268.365295410156,9999.6064453125,9999.6064453125,47.4862774288319,5.27688275268342,13.0973682403564,27,1,0,0,1,0.291519165039063,41.055721282959,2,1,1,268.194671630859,0,268.279983520508,,,,,,,,,,,,,,,,,,,,,,,,,,,,,,,,,
,3834059131.00444,265.825973510742,9999.6064453125,0.000698676989012625,9.40326608737816E-8,1,2,13.4005146026611,4.99594170986174,34.1099984943867,0.929910105006112,0.137962724533048,1,5.84519425461343E-6,,,,,,,,,,,,,,,,,,,,,265.71630859375,265.935638427734,9999.6064453125,9999.6064453125,47.5437271249954,5.27648870920083,13.102068901062,27,1,0,0,1,0.292205810546875,41.055721282959,2,1,1,265.71630859375,0,265.825973510742,,,,,,,,,,,,,,,,,,,,,,,,,,,,,,,,,
,3834059165.01096,263.005142211914,9999.6064453125,0.000706324565310342,6.19707160112547E-8,1,2,13.4005146026611,4.99592482210204,34.0999998152256,0.940068465179406,0.139585866882467,1,5.99448427723182E-6,,,,,,,,,,,,,,,,,,,,,262.903411865234,263.106872558594,9999.6064453125,9999.6064453125,47.6207175341397,5.27677020625961,13.1033935546875,27,1,0,0,1,0.291061401367188,41.5444793701172,2,1,1,262.903411865234,0,263.005142211914,,,,,,,,,,,,,,,,,,,,,,,,,,,,,,,,,
,3834059193.25653,260.569625854492,9999.6064453125,0.000712911057500209,9.58111636004916E-8,1,2,13.4005146026611,4.99590772806449,34.0799987316132,0.948827143814679,0.140908546972996,1,6.06666737902874E-6,,,,,,,,,,,,,,,,,,,,,260.475524902344,260.663726806641,9999.6064453125,9999.6064453125,47.4823692862358,5.27684769370848,13.0918626785278,27,1,0,0,1,0.29205322265625,41.055721282959,2,1,1,260.475524902344,0,260.569625854492,,,,,,,,,,,,,,,,,,,,,,,,,,,,,,,,,
,3834059223.84474,258.124053955078,9999.6064453125,0.000719735670340068,1.12131184135618E-7,1,2,13.4005146026611,4.99592477276719,34.0799987316132,0.957921829560038,0.142206617947473,1,6.08609811900266E-6,,,,,,,,,,,,,,,,,,,,,258.035827636719,258.212280273438,9999.6064453125,9999.6064453125,47.5706933089089,5.27676408014759,13.0847768783569,27,1,0,0,1,0.291290283203125,41.055721282959,2,1,1,258.035827636719,0,258.124053955078,,,,,,,,,,,,,,,,,,,,,,,,,,,,,,,,,
,3834059255.67124,255.476669311523,9999.6064453125,0.000727457976496909,7.12331844133703E-8,1,2,13.4005146026611,4.99591945868835,34.060001373291,0.968199884975533,0.143720939818177,1,6.14295136342773E-6,,,,,,,,,,,,,,,,,,,,,255.384338378906,255.569000244141,9999.6064453125,9999.6064453125,47.4772887008608,5.27681776290621,13.0820083618164,27,1,0,0,1,0.291671752929687,41.5444793701172,2,1,1,255.384338378906,0,255.476669311523,,,,,,,,,,,,,,,,,,,,,,,,,,,,,,,,,
,3834059285.96685,252.880867004395,9999.6064453125,0.000734490385831906,9.00270913941666E-8,1,2,13.4005146026611,4.99588443972567,34.060001373291,0.977549027401799,0.14511719343651,1,6.2085512898738E-6,,,,,,,,,,,,,,,,,,,,,252.787750244141,252.973983764648,9999.6064453125,9999.6064453125,47.5065997703319,5.27716686625143,13.070972442627,27,1,0,0,1,0.291290283203125,41.055721282959,2,1,1,252.787750244141,0,252.880867004395,,,,,,,,,,,,,,,,,,,,,,,,,,,,,,,,,
,3834059316.2464,250.355758666992,9999.6064453125,0.000742059495775217,9.35545313014282E-8,1,2,13.4005146026611,4.99584678611154,34.0400002896786,0.987604254796266,0.146671714829945,1,6.31798499791292E-6,,,,,,,,,,,,,,,,,,,,,250.295272827148,250.416244506836,9999.6064453125,9999.6064453125,47.6480745323127,5.27724828606586,13.0577211380005,27,1,0,0,1,0.290679931640625,41.5444793701172,2,1,1,250.295272827148,0,250.355758666992,,,,,,,,,,,,,,,,,,,,,,,,,,,,,,,,,
,3834059346.3951,247.880256652832,9999.6064453125,0.00074955231921783,6.77669263744209E-8,1,2,13.4005146026611,4.99589237760251,34.0300016105175,0.997600701753719,0.148070118714786,1,6.31840912497174E-6,,,,,,,,,,,,,,,,,,,,,247.806228637695,247.954284667969,9999.6064453125,9999.6064453125,47.50855384163,5.27660651977905,13.0524387359619,27,1,0,0,1,0.290756225585937,41.055721282959,2,1,1,247.806228637695,0,247.880256652832,,,,,,,,,,,,,,,,,,,,,,,,,,,,,,,,,
,3834059376.60719,245.335563659668,9999.6064453125,0.000757489025181243,8.80079649759321E-8,1,2,13.4005146026611,4.99589291895942,34.0100005269051,1.00815026651936,0.149736511588672,1,6.45924554606502E-6,,,,,,,,,,,,,,,,,,,,,245.242568969727,245.428558349609,9999.6064453125,9999.6064453125,47.493312085505,5.27679267156406,13.0446043014526,27,1,0,0,1,0.291976928710937,41.055721282959,2,1,1,245.242568969727,0,245.335563659668,,,,,,,,,,,,,,,,,,,,,,,,,,,,,,,,,
,3834059407.06357,242.879859924316,9999.6064453125,0.000765072638436191,1.07438766329218E-7,1,2,13.4005146026611,4.99589367060129,34.0100005269051,1.01824852381423,0.151200335344457,1,6.49742319064626E-6,,,,,,,,,,,,,,,,,,,,,242.792129516602,242.967590332031,9999.6064453125,9999.6064453125,47.5722565659473,5.2768265431359,13.0554904937744,27,1,0,0,1,0.291671752929687,41.055721282959,2,1,1,242.792129516602,0,242.879859924316,,,,,,,,,,,,,,,,,,,,,,,,,,,,,,,,,
,3834059438.29918,240.187370300293,9999.6064453125,0.000773792631210029,1.10740074492702E-7,1,2,13.4005146026611,4.99590147585639,33.9899994432926,1.02985186589175,0.152955825598802,1,6.59537454755498E-6,,,,,,,,,,,,,,,,,,,,,240.045394897461,240.329345703125,9999.6064453125,9999.6064453125,47.5941421644858,5.27660649389856,13.0430774688721,27,1,0,0,1,0.290451049804687,41.5444793701172,2,1,1,240.045394897461,0,240.187370300293,,,,,,,,,,,,,,,,,,,,,,,,,,,,,,,,,
,3834059469.24594,237.66764831543,9999.6064453125,0.000781744218517411,7.94039564464413E-8,1,2,13.4005146026611,4.99590340460515,33.9899994432926,1.0404390435226,0.154500920968985,1,6.64305263566315E-6,,,,,,,,,,,,,,,,,,,,,237.592514038086,237.742782592773,9999.6064453125,9999.6064453125,47.5425546822166,5.276667607909,13.0317344665527,27,1,0,0,1,0.283203125,41.5444793701172,2,1,1,237.592514038086,0,237.66764831543,,,,,,,,,,,,,,,,,,,,,,,,,,,,,,,,,
,3834059497.5092,235.293159484863,9999.6064453125,0.000789496707033987,8.88398073885098E-8,1,2,13.4005146026611,4.99589436659845,33.9800007641315,1.05075276715899,0.156044257389055,1,6.71759988925402E-6,,,,,,,,,,,,,,,,,,,,,235.201309204102,235.385009765625,9999.6064453125,9999.6064453125,47.58984320763,5.27643725293414,13.0235624313354,27,1,0,0,1,0.290603637695313,41.055721282959,2,1,1,235.201309204102,0,235.293159484863,,,,,,,,,,,,,,,,,,,,,,,,,,,,,,,,,
,3834059527.76823,232.720115661621,9999.6064453125,0.0007982828256257,8.78261894261196E-8,1,2,13.4005146026611,4.99587727130038,33.9599996805191,1.06243619497506,0.157817051529464,1,6.82009191901178E-6,,,,,,,,,,,,,,,,,,,,,232.638397216797,232.801834106445,9999.6064453125,9999.6064453125,47.5402097966589,5.27687137349115,13.0232753753662,27,1,0,0,1,0.291900634765625,41.055721282959,2,1,1,232.638397216797,0,232.720115661621,,,,,,,,,,,,,,,,,,,,,,,,,,,,,,,,,
,3834059558.27636,230.263542175293,9999.6064453125,0.000806711898955375,1.01327337974602E-7,1,2,13.4005146026611,4.99588040507106,33.9599996805191,1.07364822821482,0.159534784896132,1,6.93053331505052E-6,,,,,,,,,,,,,,,,,,,,,230.227966308594,230.299118041992,9999.6064453125,9999.6064453125,47.577727965582,5.27642801314716,13.0262804031372,25,1,64,0,0,0.291213989257812,41.055721282959,2,1,1,230.227966308594,0,230.263542175293,,,,,,,,,,,,,,,,,,,,,,,,,,,,,,,,,
,3834059588.11249,227.694625854492,9999.6064453125,0.000815822853017465,7.84965455857692E-8,1,2,13.4005146026611,4.99591479879713,33.9399985969067,1.08580070910877,0.161219885343893,1,6.92010379560949E-6,,,,,,,,,,,,,,,,,,,,,227.611267089844,227.777984619141,9999.6064453125,9999.6064453125,47.5507617816685,5.27653643385308,13.0241794586182,27,1,0,0,1,0.291824340820313,41.055721282959,2,1,1,227.611267089844,0,227.694625854492,,,,,,,,,,,,,,,,,,,,,,,,,,,,,,,,,
,3834059618.51454,225.259841918945,9999.6064453125,0.000824607822154709,1.07299464157504E-7,1,2,13.4005146026611,4.99586757023736,33.9399985969067,1.09747666961164,0.162968006507878,1,7.00526137134701E-6,,,,,,,,,,,,,,,,,,,,,225.168395996094,225.351287841797,9999.6064453125,9999.6064453125,47.4878406858704,5.27703439406618,13.0169429779053,27,1,0,0,1,0.291976928710937,41.055721282959,2,1,1,225.168395996094,0,225.259841918945,,,,,,,,,,,,,,,,,,,,,,,,,,,,,,,,,
,3834059648.77372,222.698654174805,9999.6064453125,0.000834153381564097,1.3349611707747E-7,1,2,13.4005146026611,4.99585881497203,33.9200012385845,1.11016017533623,0.164983454185408,1,7.183424274142E-6,,,,,,,,,,,,,,,,,,,,,222.627243041992,222.770065307617,9999.6064453125,9999.6064453125,47.4702540441877,5.27654184090329,13.0215425491333,27,1,0,0,1,0.291900634765625,41.055721282959,2,1,1,222.627243041992,0,222.698654174805,,,,,,,,,,,,,,,,,,,,,,,,,,,,,,,,,
,3834059678.09609,220.244361877441,9999.6064453125,0.000843414325768344,1.45530312010893E-7,1,2,13.4005146026611,4.99586048060455,33.9200012385845,1.122490873818,0.166779759312064,1,7.2365705327859E-6,,,,,,,,,,,,,,,,,,,,,220.134216308594,220.354507446289,9999.6064453125,9999.6064453125,47.6160277630243,5.27657028243387,13.0321092605591,27,1,0,0,1,0.29052734375,41.055721282959,2,1,1,220.134216308594,0,220.244361877441,,,,,,,,,,,,,,,,,,,,,,,,,,,,,,,,,
,3834059709.02364,217.663940429687,9999.6064453125,0.000853418286488175,7.81952155580128E-8,1,2,13.4005146026611,4.99589399182085,33.9000001549721,1.13581402774207,0.168769846941193,1,7.33014896695968E-6,,,,,,,,,,,,,,,,,,,,,217.572906494141,217.754974365234,9999.6064453125,9999.6064453125,47.5382557253608,5.27633124406268,13.0325498580933,27,1,0,0,1,0.291671752929687,41.055721282959,2,1,1,217.572906494141,0,217.663940429687,,,,,,,,,,,,,,,,,,,,,,,,,,,,,,,,,
,3834059737.27048,215.23218536377,9999.6064453125,0.000862395754796761,1.29987248876772E-7,1,2,13.4005146026611,4.99584399492985,33.9000001549721,1.14775133409499,0.170507611723722,1,7.38079672041439E-6,,,,,,,,,,,,,,,,,,,,,215.139724731445,215.324645996094,9999.6064453125,9999.6064453125,47.5128527984858,5.27648545593267,13.0168876647949,27,1,0,0,1,0.291519165039063,41.055721282959,2,1,1,215.139724731445,0,215.23218536377,,,,,,,,,,,,,,,,,,,,,,,,,,,,,,,,,
,3834059769.74849,212.622695922852,9999.6064453125,0.000873122189098085,1.07692402044476E-7,1,2,13.4005146026611,4.9958652719189,33.890001475811,1.16202514796333,0.172691155112724,1,7.51895661677765E-6,,,,,,,,,,,,,,,,,,,,,212.586517333984,212.658874511719,9999.6064453125,9999.6064453125,47.5249680405339,5.27639221126738,13.0209665298462,27,1,0,0,1,0.292205810546875,41.055721282959,2,1,1,212.57292175293,0,212.622695922852,,,,,,,,,,,,,,,,,,,,,,,,,,,,,,,,,
,3834059799.70056,210.154556274414,9999.6064453125,0.00088350095879098,1.09917259865662E-7,1,2,13.4005146026611,4.99588021941305,33.8799990713596,1.17582955740634,0.174840173818784,1,7.68002639640249E-6,,,,,,,,,,,,,,,,,,,,,210.063934326172,210.245178222656,9999.6064453125,9999.6064453125,47.5937513502262,5.27658335679182,13.0061063766479,27,1,0,0,1,0.291671752929687,41.055721282959,2,1,1,210.063934326172,0,210.154556274414,,,,,,,,,,,,,,,,,,,,,,,,,,,,,,,,,
,3834059829.98102,207.568000793457,9999.6064453125,0.000894425032441606,6.93548002803787E-8,1,2,13.4005146026611,4.99585739400659,33.8600017130375,1.19037609813327,0.176890667178757,1,7.69227215535028E-6,,,,,,,,,,,,,,,,,,,,,207.481231689453,207.654769897461,9999.6064453125,9999.6064453125,47.4956569710627,5.27672217776445,12.9939575195313,27,1,0,0,1,0.292282104492188,41.055721282959,2,1,1,207.481231689453,0,207.568000793457,,,,,,,,,,,,,,,,,,,,,,,,,,,,,,,,,
,3834059858.34156,205.137245178223,9999.6064453125,0.000904482719645813,8.51751080008152E-8,1,2,13.4005146026611,4.99580263389706,33.8600017130375,1.20372306175467,0.179024285936342,1,7.88923720965248E-6,,,,,,,,,,,,,,,,,,,,,205.056640625,205.217849731445,9999.6064453125,9999.6064453125,47.6136828774666,5.27676061587013,13.0057773590088,25,1,64,0,0,0.28289794921875,41.055721282959,2,1,1,205.056640625,0,205.137245178223,,,,,,,,,,,,,,,,,,,,,,,,,,,,,,,,,
,3834059889.62155,202.352127075195,9999.6064453125,0.000916481832228723,9.92573386369684E-8,1,2,13.4005146026611,4.99581842953991,33.8600017130375,1.21969619593888,0.181407664208996,1,7.99960770567928E-6,,,,,,,,,,,,,,,,,,,,,202.20344543457,202.50080871582,9999.6064453125,9999.6064453125,47.5163701268223,5.27622454764538,12.9963235855103,27,1,0,0,1,0.29205322265625,41.055721282959,2,1,1,202.20344543457,0,202.352127075195,,,,,,,,,,,,,,,,,,,,,,,,,,,,,,,,,
,3834059926.6006,199.267387390137,9999.6064453125,0.000930719438279926,6.42731193695133E-8,1,2,13.4005146026611,4.99580532108717,33.840000629425,1.23861338127747,0.184414169021881,1,8.265714348742E-6,,,,,,,,,,,,,,,,,,,,,199.159683227539,199.375091552734,9999.6064453125,9999.6064453125,47.5062089560723,5.27673751770412,12.9725961685181,27,1,0,0,1,0.292205810546875,41.055721282959,2,1,1,199.159683227539,0,199.267387390137,,,,,,,,,,,,,,,,,,,,,,,,,,,,,,,,,
,3834059963.18096,196.226020812988,9999.6064453125,0.000944262622840309,5.2051397603996E-8,1,2,13.4005146026611,4.99581075228935,33.840000629425,1.25661854464327,0.187242039534536,1,8.49415488480401E-6,,,,,,,,,,,,,,,,,,,,,196.166412353516,196.285629272461,9999.6064453125,9999.6064453125,47.5480260818512,5.27651997930587,12.974983215332,27,1,0,0,1,0.291061401367188,41.055721282959,2,1,1,196.166412353516,0,196.226020812988,,,,,,,,,,,,,,,,,,,,,,,,,,,,,,,,,
,3834060012.28303,192.141555786133,9999.6064453125,0.000963697130374328,1.18667494773213E-7,1,2,13.4005146026611,4.99584440195468,33.8199995458126,1.28251318552048,0.190958141611255,1,8.56435007544859E-6,,,,,,,,,,,,,,,,,,,,,192.141555786133,192.141555786133,9999.6064453125,9999.6064453125,47.5151976840435,5.2766549326244,12.9455919265747,27,1,0,0,1,0.291519165039063,41.055721282959,2,1,1,192.141555786133,0,192.141555786133,,,,,,,,,,,,,,,,,,,,,,,,,,,,,,,,,
,3834060041.4972,189.672248840332,9999.6064453125,0.000976074255698493,1.38396334706755E-7,1,2,13.4005146026611,4.99581754842003,33.8100008666515,1.29896698599203,0.193469600468739,1,8.71962607304903E-6,,,,,,,,,,,,,,,,,,,,,189.568725585938,189.775772094727,9999.6064453125,9999.6064453125,47.4686907871493,5.27623406210394,12.9568490982056,27,1,0,0,1,0.291595458984375,41.055721282959,2,1,1,189.568725585938,0,189.672248840332,,,,,,,,,,,,,,,,,,,,,,,,,,,,,,,,,
,3834060074.03125,186.948959350586,9999.6064453125,0.000989501555320653,1.42226630886479E-7,1,2,13.4005146026611,4.99579807680321,33.7999984622002,1.31683729710265,0.196071435824981,1,8.79562154858076E-6,,,,,,,,,,,,,,,,,,,,,186.916015625,186.981903076172,9999.6064453125,9999.6064453125,47.5812452939185,5.27637310671375,12.9515933990479,27,1,0,0,1,0.274658203125,41.055721282959,2,1,1,186.916015625,0,186.948959350586,,,,,,,,,,,,,,,,,,,,,,,,,,,,,,,,,
,3834060101.90231,184.734100341797,9999.6064453125,0.00100165924204957,1.36135107865241E-7,1,2,13.4005146026611,4.99581618496556,33.7899997830391,1.33302535247711,0.198468028071031,1,8.89358922693046E-6,,,,,,,,,,,,,,,,,,,,,184.665679931641,184.802520751953,9999.6064453125,9999.6064453125,47.5730381944666,5.27618367545112,12.9558982849121,27,1,0,0,1,0.28289794921875,41.055721282959,2,1,1,184.665679931641,0,184.734100341797,,,,,,,,,,,,,,,,,,,,,,,,,,,,,,,,,
,3834060134.26169,182.020568847656,9999.6064453125,0.00101647756376469,1.00930711754646E-7,1,2,13.4005146026611,4.99575939630446,33.7699986994266,1.35274482029998,0.201257574159845,1,8.917530555837E-6,,,,,,,,,,,,,,,,,,,,,181.930130004883,182.11100769043,9999.6064453125,9999.6064453125,47.5648310950146,5.27947796710106,12.9350490570068,27,1,0,0,1,0.292587280273438,41.055721282959,2,1,1,181.930130004883,0,182.020568847656,,,,,,,,,,,,,,,,,,,,,,,,,,,,,,,,,
,3834060174.72839,178.676971435547,9999.6064453125,0.00103412239693408,8.58885577306812E-8,1,2,13.4005146026611,4.99579163217673,33.7699986994266,1.37623583240609,0.204775725277525,1,9.08940265028219E-6,,,,,,,,,,,,,,,,,,,,,178.62239074707,178.731552124023,9999.6064453125,9999.6064453125,47.5179333838608,5.27640533321934,12.9274158477783,27,1,0,0,1,0.292282104492188,41.055721282959,2,1,1,178.62239074707,0,178.676971435547,,,,,,,,,,,,,,,,,,,,,,,,,,,,,,,,,
,3834060205.31339,176.083831787109,9999.6064453125,0.00104856099105306,2.01620305374568E-7,1,2,13.4005146026611,4.99575543581417,33.7500013411045,1.39541872783734,0.20776506774483,1,9.31559320204116E-6,,,,,,,,,,,,,,,,,,,,,176.066421508789,176.10124206543,9999.6064453125,9999.6064453125,47.4878406858704,5.27910526964342,12.9178371429443,25,1,64,0,0,0.2911376953125,41.055721282959,2,1,1,176.066421508789,0,176.083831787109,,,,,,,,,,,,,,,,,,,,,,,,,,,,,,,,,
,3834060234.91495,173.607360839844,9999.6064453125,0.00106280390127349,1.39055463264329E-7,1,2,13.4005146026611,4.9958320621613,33.7500013411045,1.41442999772748,0.21039726476333,1,9.29626543749409E-6,,,,,,,,,,,,,,,,,,,,,173.52668762207,173.688034057617,9999.6064453125,9999.6064453125,47.603130892457,5.27643081802582,12.8915634155273,27,1,0,0,1,0.290679931640625,41.055721282959,2,1,1,173.52668762207,0,173.607360839844,,,,,,,,,,,,,,,,,,,,,,,,,,,,,,,,,
,3834060273.42196,170.403457641602,9999.6064453125,0.00108083682004505,9.51638714435265E-8,1,2,13.4005146026611,4.9957817685996,33.7500013411045,1.43831893694558,0.214609962558236,1,9.93864591331412E-6,,,,,,,,,,,,,,,,,,,,,170.315887451172,170.491027832031,9999.6064453125,9999.6064453125,47.4940937140243,5.27636978459774,12.8923063278198,27,1,0,0,1,0.292129516601562,41.055721282959,2,1,1,170.315887451172,0,170.403457641602,,,,,,,,,,,,,,,,,,,,,,,,,,,,,,,,,
,3834060315.55571,166.854690551758,9999.6064453125,0.00110316066304576,1.14310784282225E-7,1,2,13.4005146026611,4.99571958270818,33.7300002574921,1.46806658442294,0.218571673709374,1,9.79331797946492E-6,,,,,,,,,,,,,,,,,,,,,166.756912231445,166.95246887207,9999.6064453125,9999.6064453125,47.5527158529666,5.27655647660745,12.894326210022,25,1,64,0,0,0.2911376953125,41.055721282959,2,1,1,166.756912231445,0,166.854690551758,,,,,,,,,,,,,,,,,,,,,,,,,,,,,,,,,
,3834060355.96516,163.595642089844,9999.6064453125,0.00112507456213029,1.52675443389636E-7,1,2,13.4005146026611,4.99574989970799,33.7099991738796,1.49724061038565,0.222922858283352,1,9.9934741633723E-6,,,,,,,,,,,,,,,,,,,,,163.508453369141,163.682830810547,9999.6064453125,9999.6064453125,47.4925304569858,5.27651544006552,12.8779954910278,27,1,0,0,1,0.291824340820313,41.055721282959,2,1,1,163.508453369141,0,163.595642089844,,,,,,,,,,,,,,,,,,,,,,,,,,,,,,,,,
,3834060384.31882,161.132392883301,9999.6064453125,0.00114008090940187,1.24297588130697E-7,1,2,13.4005146026611,4.99573236512633,33.7099991738796,1.51717527593096,0.226098057200498,1,1.02790595731368E-5,,,,,,,,,,,,,,,,,,,,,161.019119262695,161.245666503906,9999.6064453125,9999.6064453125,47.5026916277358,5.27671662479735,12.8640413284302,27,1,0,0,1,0.292282104492188,41.055721282959,2,1,1,161.019119262695,0,161.132392883301,,,,,,,,,,,,,,,,,,,,,,,,,,,,,,,,,
,3834060416.20194,158.506004333496,9999.6064453125,0.00115836197528755,1.87764197539164E-7,1,2,13.4005146026611,4.99570426259989,33.7000004947186,1.54152649336455,0.229468821154463,1,1.02540628438183E-5,,,,,,,,,,,,,,,,,,,,,158.416351318359,158.595657348633,9999.6064453125,9999.6064453125,47.4929212712454,5.2767947916742,12.8685188293457,27,1,0,0,1,0.292816162109375,41.055721282959,2,1,1,158.416351318359,0,158.506004333496,,,,,,,,,,,,,,,,,,,,,,,,,,,,,,,,,
,3834060444.69944,156.174766540527,9999.6064453125,0.00117470932724407,1.87525780739152E-7,1,2,13.4005146026611,4.99566936984845,33.6900018155575,1.56324243318405,0.232875581455663,1,1.0526821476092E-5,,,,,,,,,,,,,,,,,,,,,156.104537963867,156.244995117187,9999.6064453125,9999.6064453125,47.5785095941012,5.27769470941091,12.8610410690308,25,1,64,0,0,0.284042358398438,40.5669593811035,2,1,1,156.104537963867,0,156.174766540527,,,,,,,,,,,,,,,,,,,,,,,,,,,,,,,,,
,3834060476.76536,153.437393188477,9999.6064453125,0.00119354888756524,8.56591632246553E-8,1,2,13.4005146026611,4.99574461033621,33.6900018155575,1.58833571141036,0.236688187461604,1,1.07503966483253E-5,,,,,,,,,,,,,,,,,,,,,153.380462646484,153.494323730469,9999.6064453125,9999.6064453125,47.5198874551589,5.2760964363778,12.8581705093384,27,1,0,0,1,0.292434692382812,40.5669593811035,2,1,1,153.380462646484,0,153.437393188477,,,,,,,,,,,,,,,,,,,,,,,,,,,,,,,,,
,3834060513.54568,150.349998474121,9999.6064453125,0.00121633665856705,1.7149515133846E-7,1,2,13.4005146026611,4.99563273949592,33.6799994111061,1.61861073092908,0.241203690136569,1,1.09586079871661E-5,,,,,,,,,,,,,,,,,,,,,150.255645751953,150.444351196289,9999.6064453125,9999.6064453125,47.472989744005,5.27754643934662,12.8467264175415,27,1,0,0,1,0.291519165039063,40.5669593811035,2,1,1,150.255645751953,0,150.349998474121,,,,,,,,,,,,,,,,,,,,,,,,,,,,,,,,,
,3834060553.29803,147.140754699707,9999.6064453125,0.00124281457943645,1.87599445450358E-7,1,2,13.4005146026611,4.9956613030927,33.6599983274937,1.65379558868361,0.24690650070062,1,1.15350581854486E-5,,,,,,,,,,,,,,,,,,,,,147.078598022461,147.202911376953,9999.6064453125,9999.6064453125,47.5140252412646,5.27693091834509,12.8486185073853,27,1,0,0,1,0.292510986328125,40.5669593811035,2,1,1,147.078598022461,0,147.140754699707,,,,,,,,,,,,,,,,,,,,,,,,,,,,,,,,,
,3834060603.98101,142.91771697998,9999.6064453125,0.0012771578828367,2.08502640830255E-7,1,2,13.4005146026611,4.99570913893531,33.6400009691715,1.69956279460288,0.25341249889606,1,1.16134863749482E-5,,,,,,,,,,,,,,,,,,,,,142.857833862305,142.977600097656,9999.6064453125,9999.6064453125,47.5613137666781,5.27686514301151,12.8278865814209,26,1,64,0,0,0.283584594726562,40.5669593811035,2,1,1,142.857833862305,0,142.91771697998,,,,,,,,,,,,,,,,,,,,,,,,,,,,,,,,,
,3834060642.18631,139.694160461426,9999.6064453125,0.00130378324082051,8.90700101921894E-8,1,2,13.4005146026611,4.99565624300337,33.6400009691715,1.7349392860488,0.258904337386293,1,1.20151652646015E-5,,,,,,,,,,,,,,,,,,,,,139.607833862305,139.780487060547,9999.6064453125,9999.6064453125,47.4976110423608,5.27659988260371,12.8354978561401,27,1,0,0,1,0.292205810546875,40.5669593811035,2,1,1,139.607833862305,0,139.694160461426,,,,,,,,,,,,,,,,,,,,,,,,,,,,,,,,,
,3834060680.339,136.511024475098,9999.6064453125,0.00133195958099052,1.44476280627712E-7,1,2,13.4005146026611,4.99567261698596,33.6299985647202,1.7724164271808,0.264679291466651,1,1.2408816439725E-5,,,,,,,,,,,,,,,,,,,,,136.459335327148,136.562713623047,9999.6064453125,9999.6064453125,47.4874498716108,5.2766113726159,12.8117294311523,27,1,0,0,1,0.291976928710937,41.055721282959,2,1,1,136.459335327148,0,136.511024475098,,,,,,,,,,,,,,,,,,,,,,,,,,,,,,,,,
,3834060735.93114,131.878540039062,9999.6064453125,0.00137561782759951,1.49510824134902E-7,1,2,13.4005146026611,4.99571479410764,33.6199998855591,1.83058677554668,0.272972626965929,1,1.25263463300652E-5,,,,,,,,,,,,,,,,,,,,,131.743759155273,132.013320922852,9999.6064453125,9999.6064453125,47.4303909897069,5.27649701644447,12.8006200790405,27,1,0,0,1,0.292129516601562,40.5669593811035,2,1,1,131.743759155273,0,131.878540039062,,,,,,,,,,,,,,,,,,,,,,,,,,,,,,,,,
,3834060782.8852,128.042095184326,9999.6064453125,0.0014147742931705,1.6538561289287E-7,1,2,13.4005146026611,4.99574314493935,33.5999988019466,1.88268877182911,0.280885274072963,1,1.29882725826678E-5,,,,,,,,,,,,,,,,,,,,,127.976890563965,128.107299804688,9999.6064453125,9999.6064453125,47.5488077103704,5.27585496406459,12.7909965515137,27,1,0,0,1,0.291824340820313,40.5669593811035,2,1,1,127.976890563965,0,128.042095184326,,,,,,,,,,,,,,,,,,,,,,,,,,,,,,,,,
,3834060821.17386,124.843563079834,9999.6064453125,0.00144726023178677,2.44968867725378E-7,1,2,13.4005146026611,4.99575839707355,33.5999988019466,1.92586051106544,0.287811527530455,1,1.36432839581439E-5,,,,,,,,,,,,,,,,,,,,,124.74437713623,124.942749023437,9999.6064453125,9999.6064453125,47.5155884983031,5.27650026112613,12.7599191665649,27,1,0,0,1,0.29205322265625,40.5669593811035,2,1,1,124.74437713623,0,124.843563079834,,,,,,,,,,,,,,,,,,,,,,,,,,,,,,,,,
,3834060881.68451,119.802379608154,9999.6064453125,0.00150453017598123,1.93745759696722E-7,1,2,13.4005146026611,4.99572515380683,33.5800014436245,2.0026177586637,0.295144683784877,10,1.11412327918173E-5,,,,,,,,,,,,,,,,,,,,,119.738609313965,119.866149902344,9999.6064453125,9999.6064453125,47.5425546822166,5.2761184161549,12.758936882019,27,1,0,0,1,0.274810791015625,40.5669593811035,2,1,1,119.738609313965,0,119.802379608154,,,,,,,,,,,,,,,,,,,,,,,,,,,,,,,,,
,3834060911.83314,117.304206848145,9999.6064453125,0.00153580424589586,2.16714649778234E-7,1,2,13.4005146026611,4.9957246488446,33.5600003600121,2.04422638589915,0.301413495993245,10,1.14732377365665E-5,,,,,,,,,,,,,,,,,,,,,117.24006652832,117.368347167969,9999.6064453125,9999.6064453125,47.4280461041493,5.27611517515492,12.7453746795654,27,1,0,0,1,0.292510986328125,40.5669593811035,2,1,1,117.24006652832,0,117.304206848145,,,,,,,,,,,,,,,,,,,,,,,,,,,,,,,,,
,3834060942.06524,114.790340423584,9999.6064453125,0.00156587127078083,2.04805643859727E-7,1,2,13.4005146026611,4.99574913998735,33.5600003600121,2.08431245910293,0.306948269691455,10,1.14215374560468E-5,,,,,,,,,,,,,,,,,,,,,114.695236206055,114.885444641113,9999.6064453125,9999.6064453125,47.5351292112839,5.27600479561997,12.7328128814697,27,1,0,0,1,0.291366577148438,40.5669593811035,2,1,1,114.695236206055,0,114.790340423584,,,,,,,,,,,,,,,,,,,,,,,,,,,,,,,,,
,3834060972.46899,112.24250793457,9999.6064453125,0.001597417314477,1.87055736519858E-7,1,2,13.4005146026611,4.99573427940131,33.5600003600121,2.12629013354401,0.313160973387284,10,1.16743005020896E-5,,,,,,,,,,,,,,,,,,,,,112.153617858887,112.331398010254,9999.6064453125,9999.6064453125,47.5468536390723,5.27635967079753,12.726095199585,27,1,0,0,1,0.292587280273438,40.5669593811035,2,1,1,112.153617858887,0,112.24250793457,,,,,,,,,,,,,,,,,,,,,,,,,,,,,,,,,
,3834061003.74565,109.594062805176,9999.6064453125,0.00163485371687232,1.59797603967636E-7,1,2,13.4005146026611,4.9957399408847,33.5399992763996,2.17612418010102,0.320501833750031,10,1.19488353502185E-5,,,,,,,,,,,,,,,,,,,,,109.452133178711,109.735992431641,9999.6064453125,9999.6064453125,47.4917488284666,5.27640859516253,12.7086782455444,27,1,0,0,1,0.291748046875,40.5669593811035,2,1,1,109.452133178711,0,109.594062805176,,,,,,,,,,,,,,,,,,,,,,,,,,,,,,,,,
,3834061034.74453,107.059410095215,9999.6064453125,0.00166886716654344,1.64578717174794E-7,1,2,13.4005146026611,4.99577735209345,33.5399992763996,2.22128534755141,0.328148137521345,10,1.29290476490489E-5,,,,,,,,,,,,,,,,,,,,,106.991317749023,107.127502441406,9999.6064453125,9999.6064453125,47.4511041454666,5.27617812194693,12.6907224655151,27,1,0,0,1,0.292587280273438,40.5669593811035,2,1,1,106.991317749023,0,107.059410095215,,,,,,,,,,,,,,,,,,,,,,,,,,,,,,,,,
,3834061065.29832,104.506450653076,9999.6064453125,0.0017048538900922,2.00055514236485E-7,1,2,13.4005146026611,4.99578158850366,33.5399992763996,2.26930963027101,0.334346173844042,10,1.25486143497866E-5,,,,,,,,,,,,,,,,,,,,,104.417579650879,104.595321655273,9999.6064453125,9999.6064453125,47.4948753425435,5.27605006429923,12.6752986907959,25,1,64,0,0,0.291976928710937,40.5669593811035,2,1,1,104.417579650879,0,104.506450653076,,,,,,,,,,,,,,,,,,,,,,,,,,,,,,,,,
,3834061095.47576,102.011001586914,9999.6064453125,0.00174496102986713,1.65428569878632E-7,1,2,13.4005146026611,4.99572172118524,33.5199981927872,2.32268126939799,0.342036978531663,10,1.27168679110821E-5,,,,,,,,,,,,,,,,,,,,,101.962661743164,102.059341430664,9999.6064453125,9999.6064453125,47.5023008134762,5.27604893814279,12.6605520248413,27,1,0,0,1,0.291671752929687,40.5669593811035,2,1,1,101.962661743164,0,102.011001586914,,,,,,,,,,,,,,,,,,,,,,,,,,,,,,,,,
,3834061125.43297,99.5089912414551,9999.6064453125,0.00178406935054033,1.210788909635E-7,1,2,13.4005146026611,4.99573074675946,33.5199981927872,2.37474847234026,0.349667468241087,10,1.29747433661074E-5,,,,,,,,,,,,,,,,,,,,,99.4145431518555,99.6034393310547,9999.6064453125,9999.6064453125,47.5312210686877,5.27615883205504,12.6522464752197,27,1,0,0,1,0.2838134765625,40.5669593811035,2,1,1,99.4145431518555,0,99.5089912414551,,,,,,,,,,,,,,,,,,,,,,,,,,,,,,,,,
,3834061155.70843,96.9547233581543,9999.6064453125,0.00182517291064882,1.72304326713036E-7,1,2,13.4005146026611,4.99572691259825,33.5199981927872,2.42940855187337,0.358078687179463,10,1.35404981495464E-5,,,,,,,,,,,,,,,,,,,,,96.8579483032227,97.0514984130859,9999.6064453125,9999.6064453125,47.5632678379762,5.27615843060246,12.6335477828979,27,1,0,0,1,0.291061401367188,40.5669593811035,2,1,1,96.8579483032227,0,96.9547233581543,,,,,,,,,,,,,,,,,,,,,,,,,,,,,,,,,
,3834061185.99585,94.4748802185059,9999.6064453125,0.00187153461926819,2.09946582594681E-7,1,2,13.4005146026611,4.99571303948223,33.500000834465,2.4911008371532,0.367232307253874,10,1.39289966772499E-5,,,,,,,,,,,,,,,,,,,,,94.4148483276367,94.534912109375,9999.6064453125,9999.6064453125,47.5531066672262,5.27610069687404,12.6159334182739,27,1,0,0,1,0.29144287109375,40.5669593811035,2,1,1,94.4148483276367,0,94.4748802185059,,,,,,,,,,,,,,,,,,,,,,,,,,,,,,,,,
,3834061218.13144,91.8090934753418,9999.6064453125,0.00192003847627857,1.55998613407442E-7,1,2,13.4005146026611,4.99573189300642,33.500000834465,2.55569358753854,0.376618515075177,10,1.41900516610334E-5,,,,,,,,,,,,,,,,,,,,,91.7375869750977,91.8805999755859,9999.6064453125,9999.6064453125,47.4342991323031,5.27624171565571,12.5906953811646,27,1,0,0,1,0.292205810546875,40.5669593811035,2,1,1,91.7375869750977,0,91.8090934753418,,,,,,,,,,,,,,,,,,,,,,,,,,,,,,,,,
,3834061248.49642,89.2280960083008,9999.6064453125,0.00196800051704497,2.33051509283344E-7,1,2,13.4005146026611,4.99574276385403,33.500000834465,2.6195089041047,0.386263680963136,10,1.47217736420228E-5,,,,,,,,,,,,,,,,,,,,,89.1238021850586,89.332389831543,9999.6064453125,9999.6064453125,47.4847141717935,5.27604553077506,12.5953369140625,27,1,0,0,1,0.292510986328125,40.5669593811035,2,1,1,89.1238021850586,0,89.2280960083008,,,,,,,,,,,,,,,,,,,,,,,,,,,,,,,,,
,3834061279.82637,86.5749969482422,9999.6064453125,0.00202545993836463,2.68895291149513E-7,1,2,13.4005146026611,4.99575145915348,33.4799997508526,2.69604369620959,0.397206534089557,10,1.48996019056436E-5,,,,,,,,,,,,,,,,,,,,,86.4426422119141,86.7073516845703,9999.6064453125,9999.6064453125,47.4944845282839,5.27623334949468,12.5628709793091,27,1,0,0,1,0.291519165039063,40.5669593811035,2,1,1,86.4426422119141,0,86.5749969482422,,,,,,,,,,,,,,,,,,,,,,,,,,,,,,,,,
,3834061308.75028,84.2649955749512,9999.6064453125,0.00207548397462363,2.43223039429819E-7,1,2,13.4005146026611,4.99581744488102,33.4799997508526,2.76265568233262,0.407194535159112,10,1.53956060319585E-5,,,,,,,,,,,,,,,,,,,,,84.1647567749023,84.365234375,9999.6064453125,9999.6064453125,47.4616561304762,5.27550751247315,12.5379495620728,27,1,0,0,1,0.291290283203125,40.5669593811035,2,1,1,84.1647567749023,0,84.2649955749512,,,,,,,,,,,,,,,,,,,,,,,,,,,,,,,,,
,3834061338.98486,81.7112159729004,9999.6064453125,0.00213189351925767,1.77988556408065E-7,1,2,13.4005146026611,4.99581689729354,33.4799997508526,2.83771357676107,0.418460807174031,10,1.59635405174893E-5,,,,,,,,,,,,,,,,,,,,,81.6396102905273,81.7828216552734,9999.6064453125,9999.6064453125,47.4839325432743,5.27561793216962,12.5102109909058,27,1,0,0,1,0.29205322265625,40.5669593811035,2,1,1,81.6396102905273,0,81.7112159729004,,,,,,,,,,,,,,,,,,,,,,,,,,,,,,,,,
,3834061369.28786,79.1609077453613,9999.6064453125,0.0021959253431654,3.22849995300001E-7,1,2,13.4005146026611,4.99582860927511,33.4599986672401,2.92296459492755,0.430956573357625,10,1.63873473435195E-5,,,,,,,,,,,,,,,,,,,,,79.0950469970703,79.2267684936523,9999.6064453125,9999.6064453125,47.4753346295627,5.2757641100811,12.4793348312378,27,1,0,0,1,0.291519165039063,40.5669593811035,2,1,1,79.0950469970703,0,79.1609077453613,,,,,,,,,,,,,,,,,,,,,,,,,,,,,,,,,
,3834061399.40761,76.5696487426758,9999.6064453125,0.00225976656296112,3.67807888635486E-7,1,2,13.4005146026611,4.99582041161246,33.4599986672401,3.00791761487326,0.443615820267907,10,1.6962250855249E-5,,,,,,,,,,,,,,,,,,,,,76.5055923461914,76.6337051391602,9999.6064453125,9999.6064453125,47.4260920328512,5.27551913048153,12.4753761291504,27,1,0,0,1,0.291671752929687,40.5669593811035,2,1,1,76.5055923461914,0,76.5696487426758,,,,,,,,,,,,,,,,,,,,,,,,,,,,,,,,,
,3834061429.6533,74.023681640625,9999.6064453125,0.00232751899534453,2.24944959566373E-7,1,2,13.4005146026611,4.99583325239296,33.4599986672401,3.09810079959768,0.45699844332124,10,1.75312300135375E-5,,,,,,,,,,,,,,,,,,,,,73.963752746582,74.083610534668,9999.6064453125,9999.6064453125,47.5273129260916,5.27604340263103,12.4746961593628,27,1,0,0,1,0.29083251953125,40.5669593811035,2,1,1,73.963752746582,0,74.023681640625,,,,,,,,,,,,,,,,,,,,,,,,,,,,,,,,,
,3834061459.99175,71.4797172546387,9999.6064453125,0.00239976790510587,3.56860814779039E-7,1,2,13.4005146026611,4.99582196309921,33.4599986672401,3.19428619208925,0.470992440484959,10,1.79325950933977E-5,,,,,,,,,,,,,,,,,,,,,71.4000015258789,71.5594329833984,9999.6064453125,9999.6064453125,47.4823692862358,5.2758902560582,12.4255666732788,27,1,0,0,1,0.292816162109375,40.5669593811035,2,1,1,71.4000015258789,0,71.4797172546387,,,,,,,,,,,,,,,,,,,,,,,,,,,,,,,,,
,3834061490.32487,68.9182052612305,9999.6064453125,0.00248179129530115,3.53943162949554E-7,1,2,13.4005146026611,4.99583815072418,33.440001308918,3.30342030431172,0.487524610972469,10,1.8869448567254E-5,,,,,,,,,,,,,,,,,,,,,68.8656845092773,68.9707260131836,9999.6064453125,9999.6064453125,47.4452419315723,5.27587860449155,12.4122009277344,27,1,0,0,1,0.283660888671875,40.5669593811035,2,1,1,68.8656845092773,0,68.9182052612305,,,,,,,,,,,,,,,,,,,,,,,,,,,,,,,,,
,3834061522.34488,66.2075386047363,9999.6064453125,0.00257087572621125,5.12054849079161E-7,1,2,13.4005146026611,4.99582542331595,33.440001308918,3.42194522089518,0.505309609484517,10,1.9762130319117E-5,,,,,,,,,,,,,,,,,,,,,66.1156845092773,66.2993927001953,9999.6064453125,9999.6064453125,47.577727965582,5.27572526448664,12.3684415817261,27,1,0,0,1,0.292587280273438,40.5669593811035,2,1,1,66.1156845092773,0,66.2075386047363,,,,,,,,,,,,,,,,,,,,,,,,,,,,,,,,,
,3834061552.78721,63.6784954071045,9999.6064453125,0.00266061754937431,4.71926395882673E-7,1,2,13.4005146026611,4.99584825016334,33.440001308918,3.54146485323922,0.522613660898668,10,2.01982203832285E-5,,,,,,,,,,,,,,,,,,,,,63.5965690612793,63.7604217529297,9999.6064453125,9999.6064453125,47.5042548847743,5.27570555269284,12.337477684021,27,1,0,0,1,0.291519165039063,40.5669593811035,2,1,1,63.5965690612793,0,63.6784954071045,,,,,,,,,,,,,,,,,,,,,,,,,,,,,,,,,
,3834061584.12002,61.0278511047363,9999.6064453125,0.00276562313401031,7.69766348246401E-7,1,2,13.4005146026611,4.99586145844189,33.440001308918,3.68113942218894,0.544016788282625,10,2.15772685074466E-5,,,,,,,,,,,,,,,,,,,,,60.8926086425781,61.1630935668945,9999.6064453125,9999.6064453125,47.5230139692358,5.27538332978439,12.2402029037476,27,1,0,0,1,0.291595458984375,40.5669593811035,2,1,1,60.8926086425781,0,61.0278511047363,,,,,,,,,,,,,,,,,,,,,,,,,,,,,,,,,
,3834061615.00078,58.4741115570068,9999.6064453125,0.00287408681229934,5.02525669666569E-6,1,2,13.4005146026611,4.99587537079578,33.4200002253056,3.82549326784796,0.565566384954509,10,2.25825230466082E-5,,,,,,,,,,,,,,,,,,,,,58.4065895080566,58.541633605957,9999.6064453125,9999.6064453125,47.5183241981204,5.2758028028548,12.1555309295654,27,1,0,0,1,0.29052734375,40.5669593811035,2,1,1,58.4065895080566,0,58.4741115570068,,,,,,,,,,,,,,,,,,,,,,,,,,,,,,,,,
,3834061645.59208,55.8745174407959,9999.6064453125,0.00299619732306806,4.08974903755201E-7,1,2,13.4005146026611,4.99586216660509,33.4200002253056,3.98810144631671,0.588949858470832,10,2.30590862420601E-5,,,,,,,,,,,,,,,,,,,,,55.7905578613281,55.9584770202637,9999.6064453125,9999.6064453125,47.5155884983031,5.27559024386728,12.0545568466187,27,1,0,0,1,0.291595458984375,40.5669593811035,2,1,1,55.7905578613281,0,55.8745174407959,,,,,,,,,,,,,,,,,,,,,,,,,,,,,,,,,
,3834061685.50517,52.5092601776123,9999.6064453125,0.00327630414593539,0.000101381492725395,1,2,13.4005146026611,4.99591695616478,33.4200002253056,4.3599280309866,0.651716770284746,10,3.09917630903244E-5,,,,,,,,,,,,,,,,,,,,,52.4086608886719,52.6098594665527,9999.6064453125,9999.6064453125,47.4460235600916,5.27561494456323,11.9216423034668,27,1,0,0,1,0.290374755859375,40.5669593811035,2,1,1,52.4086608886719,0,52.5092601776123,,,,,,,,,,,,,,,,,,,,,,,,,,,,,,,,,
,3834061715.72624,49.9714832305908,9999.6064453125,0.00331329675844784,7.78943019240449E-7,1,2,13.4005146026611,4.99593292337057,33.4100015461445,4.41015423085521,0.652075425210787,10,2.60864080175802E-5,,,,,,,,,,,,,,,,,,,,,49.8817405700684,50.0612258911133,9999.6064453125,9999.6064453125,47.5023008134762,5.27545696344511,11.8227119445801,27,1,0,0,1,0.29205322265625,40.5669593811035,2,1,1,49.8817405700684,0,49.9714832305908,,,,,,,,,,,,,,,,,,,,,,,,,,,,,,,,,
,3834061746.26746,47.3513011932373,9999.6064453125,0.00346880973191006,6.52668229911138E-7,1,2,13.4005146026611,4.99591264674395,33.4100015461445,4.61711334844993,0.682751247840471,10,2.73661773227147E-5,,,,,,,,,,,,,,,,,,,,,47.234920501709,47.4676818847656,9999.6064453125,9999.6064453125,47.4890131286493,5.2754365597352,11.7280368804932,27,1,0,0,1,0.290679931640625,40.5669593811035,2,1,1,47.234920501709,0,47.3513011932373,,,,,,,,,,,,,,,,,,,,,,,,,,,,,,,,,
,3834061784.43507,44.1148338317871,9999.6064453125,0.00369668073189417,6.52936336060669E-7,1,2,13.4005146026611,4.99593115729948,33.3999991416931,4.92039173794127,0.727972464382744,10,2.94390436269422E-5,,,,,,,,,,,,,,,,,,,,,44.0625228881836,44.1671447753906,9999.6064453125,9999.6064453125,47.4448511173127,5.27494019591712,11.5281419754028,27,1,0,0,1,0.291900634765625,40.5669593811035,2,1,1,44.0625228881836,0,44.1148338317871,,,,,,,,,,,,,,,,,,,,,,,,,,,,,,,,,
,3834061830.78908,40.2766437530518,9999.6064453125,0.00401074902502343,9.8023059981278E-7,1,2,13.4005146026611,4.99590710360282,33.3999991416931,5.3381058132338,0.791853328071151,10,3.34695217250356E-5,,,,,,,,,,,,,,,,,,,,,40.2033157348633,40.3499717712402,9999.6064453125,9999.6064453125,47.5249680405339,5.27456956290424,11.3172788619995,26,1,68,0,0,0.29083251953125,40.5669593811035,2,1,1,40.2033157348633,0,40.2766437530518,,,,,,,,,,,,,,,,,,,,,,,,,,,,,,,,,
,3834061876.35392,36.381965637207,9999.6064453125,0.00437755728071304,1.03047403546342E-6,1,2,13.4005146026611,4.99592037221199,33.380001783371,5.82655259909729,0.862687286333998,10,3.53379140014488E-5,,,,,,,,,,,,,,,,,,,,,36.381965637207,36.381965637207,9999.6064453125,9999.6064453125,47.4038156200531,5.275266025351,11.0987453460693,27,1,0,0,1,0.291976928710937,40.5669593811035,2,1,1,36.381965637207,0,36.381965637207,,,,,,,,,,,,,,,,,,,,,,,,,,,,,,,,,
,3834061931.52723,31.7872409820557,9999.6064453125,0.00493630214455069,1.12654623618615E-5,1,2,13.4005146026611,4.99591369384008,33.380001783371,6.57166434187405,0.96256091891095,10,3.21661056428787E-5,,,,,,,,,,,,,,,,,,,,,31.7363471984863,31.838134765625,9999.6064453125,9999.6064453125,47.4886223143896,5.27532870245008,10.7912654876709,26,1,64,0,0,0.291595458984375,40.5669593811035,2,1,1,31.7363471984863,0,31.7872409820557,,,,,,,,,,,,,,,,,,,,,,,,,,,,,,,,,
,3834061996.7918,26.3001976013184,9999.6064453125,0.00581390523993991,1.7676560480351E-6,1,2,13.4005146026611,4.99590817181727,33.380001783371,7.73881331159575,1.1421718661676,100,4.42511738085693E-5,,,,,,,,,,,,,,,,,,,,,26.3001976013184,26.3001976013184,9999.6064453125,9999.6064453125,47.4311726182262,5.27553500380597,10.347939491272,27,1,0,0,1,0.291976928710937,40.5669593811035,2,1,1,26.3001976013184,0,26.3001976013184,,,,,,,,,,,,,,,,,,,,,,,,,,,,,,,,,
,3834062058.42894,21.1337413787842,9999.6064453125,0.00704104199544102,2.52827461183455E-6,1,2,13.4005146026611,4.99594628061662,33.3600006997585,9.37023296090356,1.39831124069969,10,6.48837869496796E-5,,,,,,,,,,,,,,,,,,,,,21.0381755828857,21.2293071746826,9999.6064453125,9999.6064453125,47.511680355707,5.27616431076523,9.7986478805542,27,1,0,0,1,0.291519165039063,40.5669593811035,2,1,1,21.0381755828857,0,21.1337413787842,,,,,,,,,,,,,,,,,,,,,,,,,,,,,,,,,
,3834062128.76477,15.3435077667236,9999.6064453125,0.00925393212692939,5.34913559574627E-5,1,2,13.4005146026611,4.99591743737487,33.3600006997585,12.3244890713906,1.77028672481711,10,3.46363074567103E-5,,,,,,,,,,,,,,,,,,,,,15.2582454681396,15.4287700653076,9999.6064453125,9999.6064453125,47.4980018566204,5.2762099610562,8.74418163299561,27,1,0,0,1,0.291748046875,40.5669593811035,2,1,1,15.2582454681396,0,15.3435077667236,,,,,,,,,,,,,,,,,,,,,,,,,,,,,,,,,
,3834062173.48596,11.7261648178101,9999.6064453125,0.0114631186228801,6.56036218913074E-6,1,2,13.4005146026611,4.99588346601812,33.3600006997585,15.2574591000883,2.25801728749364,100,9.17842164469688E-5,,,,,,,,,,,,,,,,,,,,,11.6773557662964,11.7749738693237,9999.6064453125,9999.6064453125,47.562486209457,5.27526185709567,7.75611019134521,27,1,0,0,1,0.283432006835938,40.5669593811035,2,1,1,11.6773557662964,0,11.7261648178101,,,,,,,,,,,,,,,,,,,,,,,,,,,,,,,,,
,3834062231.55795,7.98322796821594,9999.6064453125,0.0151705027920651,1.69906043441592E-6,1,2,13.4005146026611,4.99589341286151,33.3600006997585,20.1916247631878,2.99140901658729,100,0.000123794710712231,,,,,,,,,,,,,,,,,,,,,7.98181295394897,7.98464298248291,9999.6064453125,9999.6064453125,47.5804636653993,5.27631881396149,6.78660583496094,27,1,0,0,1,0.290985107421875,40.5669593811035,5,1,1,7.98464298248291,0,7.98322796821594,,,,,,,,,,,,,,,,,,,,,,,,,,,,,,,,,
,3834062262.02208,7.99992513656616,9999.6064453125,0.0151497542669487,1.72856155704008E-6,1,2,13.4005146026611,4.99586300910055,33.3600006997585,20.1639665540745,2.98639363982222,100,0.000122950600452147,,,,,,,,,,,,,,,,,,,,,7.99986362457275,7.99998664855957,9999.6064453125,9999.6064453125,47.4784611436396,5.27753830700741,6.7456636428833,27,1,0,0,1,0.292129516601562,40.5669593811035,5,1,1,7.99998664855957,0,7.99992513656616,,,,,,,,,,,,,,,,,,,,,,,,,,,,,,,,,
,3834062287.9725,8.00016689300537,9999.6064453125,0.0151503897977747,8.65662406695812E-7,1,2,13.4005146026611,4.99586098532294,33.3600006997585,20.1647733428148,2.98671679928448,100,0.000123105506343147,,,,,,,,,,,,,,,,,,,,,8.00003528594971,8.00029850006104,9999.6064453125,9999.6064453125,47.6207175341397,5.27764376845663,6.71198749542236,27,1,0,0,1,0.282745361328125,40.5669593811035,1,1,1,8.00003528594971,0,8.00016689300537,,,,,,,,,,,,,,,,,,,,,,,,,,,,,,,,,