File: SI Fig S11-13 SQUID all/Michaela_Pdref_ZFC1T.dat
[Header]
; MPMS3 Data File (default extension .dat)
; Copyright (c) 2007, Quantum Design, Inc. All rights reserved.
TITLE,
FILEOPENTIME,3832588712.81489,06/11/2021,3:58 pm
BYAPP,MPMS3 w/ AC,1.0,1.1
INFO,MPMS3 Measurement Release 1.1.16 Build 424, MultiVu Release 2.3.4.19,APPNAME
INFO,Linear Motor Servo Controller,MOTOR_MODULE_NAME
INFO,3101-100 E1,MOTOR_HW_VERSION
INFO,MMC211,MOTOR_SERIAL_NUMBER
INFO,01.04.28,MOTOR_SOFTWARE_VERSION
INFO,Quantum Design Squid Module,SQUID_MODULE_NAME
INFO,3101-501 B0,SQUID_HW_VERSION
INFO,SQM059,SQUID_SERIAL_NUMBER
INFO,01.03.04,SQUID_SOFTWARE_VERSION
INFO,SQUID AC,AC_MODULE_NAME
INFO,3101-401 F1,AC_HW_VERSION
INFO,SAC057,AC_SERIAL_NUMBER
INFO,SQUID AC 00.95.07,AC_SOFTWARE_VERSION
INFO,TCIXXX,COIL_SERIAL_NUMBER
INFO,0,MOMENT_UNITS
INFO,Michaela_Pdref,SAMPLE_MATERIAL
INFO,Michaela_Pdref,SAMPLE_COMMENT
INFO,276.1,SAMPLE_MASS
INFO,,SAMPLE_VOLUME
INFO,,SAMPLE_MOLECULAR_WEIGHT
INFO,,SAMPLE_SIZE
INFO,,SAMPLE_SHAPE
INFO,Brass,SAMPLE_HOLDER
INFO,Standard,SAMPLE_HOLDER_DETAIL
INFO,63.77,SAMPLE_OFFSET
DATATYPE,COMMENT,1
DATATYPE,TIME,2
STARTUPAXIS,X,2
STARTUPAXIS,Y1,5
FIELDGROUP, VSM,2,3,4,5,6,8,9,10,11,14,15
FIELDGROUP, DC, 2,3,4,14,56,57,58,59,60,61,62,63,64,65,66,67,68,69
FIELDGROUP, AC, 2,3,4,11,16,17,18,19,20,21,22,23,24,25,26,27,28,29,30
STARTUPGROUP, All
[Data]
Comment,Time Stamp (sec),Temperature (K),Magnetic Field (Oe),Moment (emu),M. Std. Err. (emu),Transport Action,Averaging Time (sec),Frequency (Hz),Peak Amplitude (mm),Center Position (mm),Lockin Signal' (V),Lockin Signal (V),Range,M. Quad. Signal (emu),AC Moment (emu),AC M. Std Err. (emu),AC Phase (deg),AC Phase Std. Err. (deg),AC Susceptibility (emu/Oe),AC Suscept. Std Err. (emu/Oe),AC X' (emu/Oe),AC X' Std Err. (emu/Oe),AC X'' (emu/Oe),AC X'' Std Err. (emu/Oe),AC Drive (Oe),AC Frequency (Hz),AC Averaging Time (sec),AC Cycles,AC Range,AC Measure Type,AC Signal' (V),AC Signal'' (V),AC Trim Coil Ratio,AC Trim Coil Phase,Min. Temperature (K),Max. Temperature (K),Min. Field (Oe),Max. Field (Oe),Mass (grams),Motor Lag (deg),Pressure (Torr),Measure Count,Measurement Number,SQUID Status (code),Motor Status (code),Measure Status (code),Motor Current (amps),Motor Temp. (C),Temp. Status (code),Field Status (code),Chamber Status (code),Chamber Temp (K),Redirection State,Average Temp (K),Rotation Angle (deg),Rotator state,DC Moment Fixed Ctr (emu),DC Moment Err Fixed Ctr (emu),DC Moment Free Ctr (emu),DC Moment Err Free Ctr (emu),DC Fixed Fit,DC Free Fit,DC Calculated Center (mm),DC Calculated Center Err (mm),DC Scan Length (mm),DC Scan Time (s),DC Number of Points,DC Squid Drift,DC Min V (V),DC Max V (V),DC Scans per Measure,Map 01,Map 02,Map 03,Map 04,Map 05,Map 06,Map 07,Map 08,Map 09,Map 10,Map 11,Map 12,Map 13,Map 14,Map 15,Map 16
,3832588732.28568,7.9997353553772,9999.7685546875,0.0188818278600154,2.50023922357549E-6,1,2,13.4005146026611,5.00937958298075,34.6900001168251,25.2172929838065,3.78625925676735,100,0.000190920881914542,,,,,,,,,,,,,,,,,,,,,7.9997353553772,7.9997353553772,9999.7685546875,9999.7685546875,49.1867102724187,5.43909003421119,4.4175910949707,27,1,0,0,1,0.28564453125,39.1006851196289,1,1,1,7.9997353553772,0,7.9997353553772,,,,,,,,,,,,,,,,,,,,,,,,,,,,,,,,,
,3832588789.16774,10.4688935279846,9999.7685546875,0.0192080913501509,1.40022733926055E-6,1,2,13.4005146026611,5.00933066644056,34.6900001168251,25.6531071136925,3.84862052175807,100,0.000191968482779404,,,,,,,,,,,,,,,,,,,,,10.4222431182861,10.5155439376831,9999.7685546875,9999.7685546875,49.4157274285533,5.43695356700999,4.7888388633728,27,1,0,0,1,0.293807983398438,40.0782012939453,6,1,1,10.5155439376831,0,10.4688935279846,,,,,,,,,,,,,,,,,,,,,,,,,,,,,,,,,
,3832588845.67901,13.1399750709534,9999.7685546875,0.0191386284824674,2.62154769254499E-6,1,2,13.4005146026611,5.00934165084892,34.6900001168251,25.5602689205656,3.83574824897819,100,0.000192047495758517,,,,,,,,,,,,,,,,,,,,,13.0899324417114,13.1900177001953,9999.7685546875,9999.7685546875,49.280896508986,5.4366618576017,5.36935663223267,27,1,0,0,1,0.29510498046875,40.5669593811035,6,1,1,13.1900177001953,0,13.1399750709534,,,,,,,,,,,,,,,,,,,,,,,,,,,,,,,,,
,3832588899.97577,15.8109126091003,9999.7685546875,0.0191136198839268,2.51149334182676E-6,1,2,13.4005146026611,5.00936758056655,34.6900001168251,25.5277224457753,3.82595160561324,100,0.000188198915300132,,,,,,,,,,,,,,,,,,,,,15.7590847015381,15.8627405166626,9999.7685546875,9999.7685546875,49.3973591583514,5.43724517794178,5.61762046813965,27,1,0,0,1,0.29327392578125,40.5669593811035,2,1,1,15.8627405166626,0,15.8109126091003,,,,,,,,,,,,,,,,,,,,,,,,,,,,,,,,,
,3832588956.51464,18.5240507125854,9999.7685546875,0.0191134396515501,1.55526949388936E-6,1,2,13.4005146026611,5.00937541932189,34.6900001168251,25.5275324564251,3.82595135316774,100,0.00018821780940955,,,,,,,,,,,,,,,,,,,,,18.4646015167236,18.5834999084473,9999.7685546875,9999.7685546875,49.3410819049668,5.4370935162579,5.78894853591919,27,1,0,0,1,0.294342041015625,40.5669593811035,2,1,1,18.5834999084473,0,18.5240507125854,,,,,,,,,,,,,,,,,,,,,,,,,,,,,,,,,
,3832589020.97913,21.6185159683228,9999.7685546875,0.0191443467106426,1.89126410045207E-6,1,2,13.4005146026611,5.00932366580839,34.6900001168251,25.5684705966696,3.83193886757093,100,0.000188413692916732,,,,,,,,,,,,,,,,,,,,,21.5548725128174,21.6821594238281,9999.7685546875,9999.7685546875,49.2664363813802,5.43732106571599,5.94518423080444,27,1,0,0,1,0.29510498046875,40.5669593811035,2,1,1,21.6821594238281,0,21.6185159683228,,,,,,,,,,,,,,,,,,,,,,,,,,,,,,,,,
,3832589077.5696,24.3294706344604,9999.7685546875,0.0191864956644969,1.68939721885522E-6,1,2,13.4005146026611,5.00933863960795,34.6900001168251,25.6263410572028,3.82985467224107,100,0.000180950265514894,,,,,,,,,,,,,,,,,,,,,24.2642765045166,24.3946647644043,9999.7685546875,9999.7685546875,49.3711746029571,5.43704829597934,6.06367349624634,27,1,0,0,1,0.294570922851562,40.5669593811035,2,1,1,24.3946647644043,0,24.3294706344604,,,,,,,,,,,,,,,,,,,,,,,,,,,,,,,,,
,3832589142.09638,27.4703054428101,9999.7685546875,0.0192456515255971,1.80218013637071E-6,1,2,13.4005146026611,5.00932136551295,34.6900001168251,25.7066118126697,3.83177019703113,100,0.000174124759501909,,,,,,,,,,,,,,,,,,,,,27.4019508361816,27.5386600494385,9999.7685546875,9999.7685546875,49.1218351053225,5.43738999852589,6.17468929290771,27,1,0,0,1,0.294723510742188,40.5669593811035,2,1,1,27.5386600494385,0,27.4703054428101,,,,,,,,,,,,,,,,,,,,,,,,,,,,,,,,,
,3832589200.19628,30.2890844345093,9999.7685546875,0.0193142345007161,1.9575326847049E-6,1,2,13.4005146026611,5.00931449391089,34.6900001168251,25.7994890418999,3.83598701528187,100,0.000167693739328922,,,,,,,,,,,,,,,,,,,,,30.2469844818115,30.331184387207,9999.7685546875,9999.7685546875,49.3954050870533,5.4373700866041,6.2523136138916,27,1,0,0,1,0.293807983398438,41.055721282959,2,1,1,30.331184387207,0,30.2890844345093,,,,,,,,,,,,,,,,,,,,,,,,,,,,,,,,,
,3832589254.93604,32.9283466339111,9999.7685546875,0.0193761122574867,1.7814515811366E-6,1,2,13.4005146026611,5.00930543576435,34.6900001168251,25.8825236850715,3.84509305974309,100,0.00016585775900716,,,,,,,,,,,,,,,,,,,,,32.8954238891602,32.9612693786621,9999.7685546875,9999.7685546875,49.3551512183129,5.43726010290624,6.33972311019897,27,1,0,0,1,0.295028686523438,41.055721282959,2,1,1,32.9612693786621,0,32.9283466339111,,,,,,,,,,,,,,,,,,,,,,,,,,,,,,,,,
,3832589309.21119,35.5746402740479,9999.7685546875,0.019448232810433,2.24768257890434E-6,1,2,13.4005146026611,5.00935336860485,34.6900001168251,25.9800296939431,3.85353381893967,100,0.000162047398627988,,,,,,,,,,,,,,,,,,,,,35.5410232543945,35.6082572937012,9999.7685546875,9999.7685546875,49.3344380625533,5.43714902388984,6.38801288604736,27,1,0,0,1,0.294876098632812,41.055721282959,2,1,1,35.6082572937012,0,35.5746402740479,,,,,,,,,,,,,,,,,,,,,,,,,,,,,,,,,
,3832589365.74836,38.3522834777832,9999.7685546875,0.0195234901216386,2.06858828569457E-6,1,2,13.4005146026611,5.00935903694978,34.6900001168251,26.0814016804776,3.86273882210438,100,0.000158403015279042,,,,,,,,,,,,,,,,,,,,,38.3166275024414,38.387939453125,9999.7685546875,9999.7685546875,49.3234952632841,5.43708190360914,6.45060682296753,27,1,0,0,1,0.294952392578125,41.055721282959,2,1,1,38.387939453125,0,38.3522834777832,,,,,,,,,,,,,,,,,,,,,,,,,,,,,,,,,
,3832589425.99519,41.2667560577393,9999.7685546875,0.0196006861466987,2.19504639220215E-6,1,2,13.4005146026611,5.00935607776857,34.6900001168251,26.1866040898085,3.86300780199823,100,0.0001478127852439,,,,,,,,,,,,,,,,,,,,,41.2136764526367,41.3198356628418,9999.7685546875,9999.7685546875,49.4012673009475,5.43793499276808,6.51488590240478,27,1,0,0,1,0.295333862304687,41.055721282959,2,1,1,41.3198356628418,0,41.2667560577393,,,,,,,,,,,,,,,,,,,,,,,,,,,,,,,,,
,3832589482.54774,44.0235767364502,9999.7685546875,0.0196688031408972,1.5210926095617E-6,1,2,13.4005146026611,5.00938177171484,34.6999987959862,26.2788652107116,3.86879065057114,100,0.000142592174297203,,,,,,,,,,,,,,,,,,,,,43.966121673584,44.0810317993164,9999.7685546875,9999.7685546875,49.4036121865052,5.43992827153609,6.55105829238892,27,1,0,0,1,0.294189453125,41.055721282959,2,1,1,44.0810317993164,0,44.0235767364502,,,,,,,,,,,,,,,,,,,,,,,,,,,,,,,,,
,3832589550.02356,47.3377208709717,9999.7685546875,0.0197521690940476,2.24125657550846E-6,1,2,13.4005146026611,5.009412073555,34.6999987959862,26.3902947659722,3.88644508651692,100,0.000144112109633628,,,,,,,,,,,,,,,,,,,,,47.2567100524902,47.4187316894531,9999.7685546875,9999.7685546875,49.3680480888802,5.43810206803362,6.60489559173584,27,1,0,0,1,0.2935791015625,41.055721282959,2,1,1,47.4187316894531,0,47.3377208709717,,,,,,,,,,,,,,,,,,,,,,,,,,,,,,,,,
,3832589605.17109,50.0340328216553,9999.7685546875,0.0198122650726189,1.81099892397351E-6,1,2,13.4005146026611,5.00930247594845,34.6999987959862,26.4697055284526,3.89879868139145,100,0.00014503332916206,,,,,,,,,,,,,,,,,,,,,49.9853744506836,50.082691192627,9999.7685546875,9999.7685546875,49.1046392778994,5.43759512640842,6.66090679168701,27,1,0,0,1,0.29541015625,41.055721282959,2,1,1,50.082691192627,0,50.0340328216553,,,,,,,,,,,,,,,,,,,,,,,,,,,,,,,,,
,3832589661.5992,52.7928848266602,9999.7685546875,0.0198733911731517,1.98571046819206E-6,1,2,13.4005146026611,5.00926951795579,34.6999987959862,26.5520220090692,3.9044332243631,100,0.000140725895690781,,,,,,,,,,,,,,,,,,,,,52.742115020752,52.8436546325684,9999.7685546875,9999.7685546875,49.2027336570629,5.43875722552143,6.69377565383911,27,1,0,0,1,0.29327392578125,41.055721282959,2,1,1,52.8436546325684,0,52.7928848266602,,,,,,,,,,,,,,,,,,,,,,,,,,,,,,,,,
,3832589717.98071,55.5724506378174,9999.7685546875,0.0199277999047412,2.46657374118622E-6,1,2,13.4005146026611,5.00929548248239,34.6999987959862,26.6253219140866,3.91216062637396,100,0.000138875654163315,,,,,,,,,,,,,,,,,,,,,55.5280609130859,55.6168403625488,9999.7685546875,9999.7685546875,49.3602318036879,5.43848138237596,6.72867918014526,27,1,0,0,1,0.294342041015625,41.055721282959,2,1,1,55.6168403625488,0,55.5724506378174,,,,,,,,,,,,,,,,,,,,,,,,,,,,,,,,,
,3832589774.4024,58.3191146850586,9999.7685546875,0.0199748164747543,1.83728054573605E-6,1,2,13.4005146026611,5.00930073358802,34.6999987959862,26.6881882715552,3.92132640652715,100,0.000139150986375706,,,,,,,,,,,,,,,,,,,,,58.2702560424805,58.3679733276367,9999.7685546875,9999.7685546875,49.2558843963706,5.43807640638624,6.75947093963623,27,1,0,0,1,0.295639038085937,41.055721282959,2,1,1,58.3679733276367,0,58.3191146850586,,,,,,,,,,,,,,,,,,,,,,,,,,,,,,,,,
,3832589830.9654,61.0795516967773,9999.7685546875,0.0200119699215382,2.38615498532661E-6,1,2,13.4005146026611,5.00928790624678,34.7100012004375,26.7370445802155,3.93354508163309,100,0.000143102599213455,,,,,,,,,,,,,,,,,,,,,61.0217514038086,61.1373519897461,9999.7685546875,9999.7685546875,49.3328748055148,5.43791642567721,6.80059862136841,27,1,0,0,1,0.295791625976562,41.055721282959,2,1,1,61.1373519897461,0,61.0795516967773,,,,,,,,,,,,,,,,,,,,,,,,,,,,,,,,,
,3832589887.5742,63.8813285827637,9999.7685546875,0.0200463141148182,1.98170360146452E-6,1,2,13.4005146026611,5.00927268747602,34.7100012004375,26.7830891425248,3.93834755408914,100,0.000141903691250843,,,,,,,,,,,,,,,,,,,,,63.8192367553711,63.9434204101562,9999.7685546875,9999.7685546875,49.3657032033225,5.43804462490142,6.80218553543091,27,1,0,0,1,0.2947998046875,41.055721282959,2,1,1,63.9434204101562,0,63.8813285827637,,,,,,,,,,,,,,,,,,,,,,,,,,,,,,,,,
,3832589943.85019,66.6483268737793,9999.7685546875,0.0200724832932185,2.18599354094119E-6,1,2,13.4005146026611,5.00927534398346,34.7100012004375,26.8180190589406,3.94387162967415,100,0.00014237304197796,,,,,,,,,,,,,,,,,,,,,66.6134643554687,66.6831893920898,9999.7685546875,9999.7685546875,49.5947203594572,5.43790339536487,6.84070444107056,27,1,0,0,1,0.290603637695313,41.055721282959,2,1,1,66.6831893920898,0,66.6483268737793,,,,,,,,,,,,,,,,,,,,,,,,,,,,,,,,,
,3832590000.34416,69.4329643249512,9999.7685546875,0.0200928259464132,1.86462609837946E-6,1,2,13.4005146026611,5.00924246126407,34.7100012004375,26.8447779160428,3.94911548846514,100,0.000143476166258919,,,,,,,,,,,,,,,,,,,,,69.3968811035156,69.4690475463867,9999.7685546875,9999.7685546875,49.3481165616398,5.43769334174109,6.8642578125,27,1,0,0,1,0.291900634765625,41.055721282959,2,1,1,69.4690475463867,0,69.4329643249512,,,,,,,,,,,,,,,,,,,,,,,,,,,,,,,,,
,3832590058.52397,72.303150177002,9999.7685546875,0.0201066479624789,1.55240888443836E-6,1,2,13.4005146026611,5.00916349522875,34.7100012004375,26.8628723361282,3.95027070124044,100,0.000142470976722827,,,,,,,,,,,,,,,,,,,,,72.2587051391602,72.3475952148438,9999.7685546875,9999.7685546875,49.3082535071591,5.4379317010333,6.89341163635254,27,1,0,0,1,0.29541015625,41.055721282959,2,1,1,72.3475952148438,0,72.303150177002,,,,,,,,,,,,,,,,,,,,,,,,,,,,,,,,,
,3832590112.92853,74.9648590087891,9999.7685546875,0.0201117609225012,1.9678378443731E-6,1,2,13.4005146026611,5.00917220436893,34.7199998795986,26.8699419895749,3.95003449005422,100,0.000141572428668409,,,,,,,,,,,,,,,,,,,,,74.9118957519531,75.017822265625,9999.7685546875,9999.7685546875,49.2347804263514,5.43707882520487,6.90417337417603,27,1,0,0,1,0.295333862304687,41.055721282959,2,1,1,75.017822265625,0,74.9648590087891,,,,,,,,,,,,,,,,,,,,,,,,,,,,,,,,,
,3832590169.30557,77.7647438049316,9999.7685546875,0.0201109811670106,1.77796468443673E-6,1,2,13.4005146026611,5.00911209177277,34.7199998795986,26.8682769895336,3.95112222424339,100,0.000142543262421013,,,,,,,,,,,,,,,,,,,,,77.7114791870117,77.8180084228516,9999.7685546875,9999.7685546875,49.2672180098994,5.43756819736415,6.93034934997559,27,1,0,0,1,0.295486450195313,41.055721282959,2,1,1,77.8180084228516,0,77.7647438049316,,,,,,,,,,,,,,,,,,,,,,,,,,,,,,,,,
,3832590225.7445,80.5317802429199,9999.7685546875,0.0201057711388317,3.15360764496405E-6,1,2,13.4005146026611,5.00915678459436,34.7199998795986,26.86158349,3.95057905838364,100,0.000142829558385568,,,,,,,,,,,,,,,,,,,,,80.4835586547852,80.5800018310547,9999.7685546875,9999.7685546875,49.3176330493898,5.43793113223489,6.95323753356934,27,1,0,0,1,0.295791625976562,41.055721282959,2,1,1,80.5800018310547,0,80.5317802429199,,,,,,,,,,,,,,,,,,,,,,,,,,,,,,,,,
,3832590282.29699,83.3021812438965,9999.7685546875,0.020092748368979,2.16035256095879E-6,1,2,13.4005146026611,5.00912016256572,34.7199998795986,26.8442714230447,3.94544363225409,100,0.000140839877388537,,,,,,,,,,,,,,,,,,,,,83.2465896606445,83.3577728271484,9999.7685546875,9999.7685546875,49.2941841938129,5.43801997646114,6.97151184082031,27,1,0,0,1,0.295562744140625,41.055721282959,2,1,1,83.3577728271484,0,83.3021812438965,,,,,,,,,,,,,,,,,,,,,,,,,,,,,,,,,
,3832590336.59756,86.0247611999512,9999.7685546875,0.0200749219640292,2.56804919483636E-6,1,2,13.4005146026611,5.00910272589517,34.7199998795986,26.8201228731315,3.94338746833364,100,0.000141808908090508,,,,,,,,,,,,,,,,,,,,,85.9739303588867,86.0755920410156,9999.7685546875,9999.7685546875,49.3277942201398,5.43811190084108,6.97355270385742,27,1,0,0,1,0.294570922851562,41.055721282959,2,1,1,86.0755920410156,0,86.0247611999512,,,,,,,,,,,,,,,,,,,,,,,,,,,,,,,,,
,3832590395.18481,88.9153671264648,9999.7685546875,0.0200493851984618,2.59193817758897E-6,1,2,13.4005146026611,5.00902949902742,34.7299985587597,26.7854136007929,3.93869990468566,100,0.000141933159605185,,,,,,,,,,,,,,,,,,,,,88.8779678344727,88.952766418457,9999.7685546875,9999.7685546875,49.3399094621879,5.438234102003,7.00172233581543,27,1,0,0,1,0.291366577148438,41.055721282959,2,1,1,88.952766418457,0,88.9153671264648,,,,,,,,,,,,,,,,,,,,,,,,,,,,,,,,,
,3832590449.46731,91.6371459960937,9999.7685546875,0.0200217233150414,3.06965414105449E-6,1,2,13.4005146026611,5.00901856983932,34.7299985587597,26.7482264262894,3.93434049398488,100,0.000142549793768325,,,,,,,,,,,,,,,,,,,,,91.5967102050781,91.6775817871094,9999.7685546875,9999.7685546875,49.2648731243418,5.43824463371489,7.00598859786987,27,1,0,0,1,0.295333862304687,41.055721282959,2,1,1,91.6775817871094,0,91.6371459960937,,,,,,,,,,,,,,,,,,,,,,,,,,,,,,,,,
,3832590504.00433,94.3200798034668,9999.7685546875,0.0199885116887467,2.62676443524832E-6,1,2,13.4005146026611,5.00899585759559,34.7299985587597,26.7036131702959,3.92835039530009,100,0.000142732427563511,,,,,,,,,,,,,,,,,,,,,94.2575836181641,94.3825759887695,9999.7685546875,9999.7685546875,49.3617950607264,5.43845085850558,7.03077745437622,27,1,0,0,1,0.294647216796875,41.055721282959,2,1,1,94.3825759887695,0,94.3200798034668,,,,,,,,,,,,,,,,,,,,,,,,,,,,,,,,,
,3832590560.30166,97.1530151367187,9999.7685546875,0.0199485362071086,2.09588449029317E-6,1,2,13.4005146026611,5.0089867128534,34.7400009632111,26.6499795388924,3.92164261653954,100,0.000143313210538356,,,,,,,,,,,,,,,,,,,,,97.1139450073242,97.1920852661133,9999.7685546875,9999.7685546875,49.296138265111,5.43798517074328,7.03485584259033,27,1,0,0,1,0.2960205078125,41.055721282959,2,1,1,97.1920852661133,0,97.1530151367187,,,,,,,,,,,,,,,,,,,,,,,,,,,,,,,,,
,3832590612.56878,99.7713661193848,9999.7685546875,0.019907246526429,1.65690236844123E-6,1,2,13.4005146026611,5.00895171825958,34.7400009632111,26.5948684376849,3.9113195301419,100,0.000141394865981481,,,,,,,,,,,,,,,,,,,,,99.7205505371094,99.8221817016602,9999.7685546875,9999.7685546875,49.3320931769956,5.43809690191371,7.05073356628418,27,1,0,0,1,0.294952392578125,41.055721282959,2,1,1,99.8221817016602,0,99.7713661193848,,,,,,,,,,,,,,,,,,,,,,,,,,,,,,,,,
,3832590669.13615,102.558158874512,9999.7685546875,0.0198570336546262,2.22118752346525E-6,1,2,13.4005146026611,5.00894655523071,34.7400009632111,26.5273114166417,3.90458315076951,100,0.000143382406915552,,,,,,,,,,,,,,,,,,,,,102.489921569824,102.626396179199,9999.7685546875,9999.7685546875,49.2973107078898,5.43833983567626,7.0751256942749,27,1,0,0,1,0.295486450195313,41.055721282959,2,1,1,102.626396179199,0,102.558158874512,,,,,,,,,,,,,,,,,,,,,,,,,,,,,,,,,
,3832590725.76286,105.388595581055,9999.7685546875,0.0198054676737692,2.73643193878461E-6,1,2,13.4005146026611,5.00892444719602,34.7400009632111,26.4585687516289,3.89224071295433,100,0.000141380397562442,,,,,,,,,,,,,,,,,,,,,105.330528259277,105.446662902832,9999.7685546875,9999.7685546875,49.3735194885148,5.43873374930005,7.09120416641235,27,1,0,0,1,0.29510498046875,41.055721282959,2,1,1,105.446662902832,0,105.388595581055,,,,,,,,,,,,,,,,,,,,,,,,,,,,,,,,,
,3832590783.81215,108.267200469971,9999.7685546875,0.019744537109955,2.51812201932432E-6,1,2,13.4005146026611,5.00889817865209,34.7499996423721,26.3774892454763,3.87660499208087,100,0.000138228210452481,,,,,,,,,,,,,,,,,,,,,108.221794128418,108.312606811523,9999.7685546875,9999.7685546875,49.3301391056975,5.43857024674384,7.10897541046143,27,1,0,0,1,0.29541015625,41.055721282959,2,1,1,108.312606811523,0,108.267200469971,,,,,,,,,,,,,,,,,,,,,,,,,,,,,,,,,
,3832590840.22366,111.074695587158,9999.7685546875,0.0196832195864638,9.02178033965996E-7,1,2,13.4005146026611,5.00890966937832,34.7499996423721,26.2955880893749,3.86505842822324,100,0.000138158095598281,,,,,,,,,,,,,,,,,,,,,111.027084350586,111.12230682373,9999.7685546875,9999.7685546875,49.1679511879571,5.43885737091294,7.12507677078247,27,1,0,0,1,0.294036865234375,41.055721282959,2,1,1,111.12230682373,0,111.074695587158,,,,,,,,,,,,,,,,,,,,,,,,,,,,,,,,,
,3832590894.64781,113.797225952148,9999.7685546875,0.0196206842202957,1.95380418418499E-6,1,2,13.4005146026611,5.00880386006851,34.7599983215332,26.2113483046978,3.85223533994519,100,0.000137395933221998,,,,,,,,,,,,,,,,,,,,,113.748237609863,113.846214294434,9999.7685546875,9999.7685546875,49.1769399159283,5.43840277311796,7.12634420394897,27,1,0,0,1,0.295791625976562,41.055721282959,2,1,1,113.846214294434,0,113.797225952148,,,,,,,,,,,,,,,,,,,,,,,,,,,,,,,,,
,3832590951.05138,116.5927734375,9999.7685546875,0.0195514259491229,2.28424295711353E-6,1,2,13.4005146026611,5.00882736974622,34.7599983215332,26.1189634939587,3.83887644574404,100,0.000137071227156367,,,,,,,,,,,,,,,,,,,,,116.542213439941,116.643333435059,9999.7685546875,9999.7685546875,49.2914484939956,5.43904049442139,7.14785146713257,27,1,0,0,1,0.295867919921875,41.055721282959,2,1,1,116.643333435059,0,116.5927734375,,,,,,,,,,,,,,,,,,,,,,,,,,,,,,,,,
,3832591007.476,119.396991729736,9999.7685546875,0.0194805012893794,2.49630355099534E-6,1,2,13.4005146026611,5.00878492981861,34.7599983215332,26.0236400608708,3.8268590144963,100,0.000138034310985388,,,,,,,,,,,,,,,,,,,,,119.337684631348,119.456298828125,9999.7685546875,9999.7685546875,49.2308722837552,5.43929356014673,7.15679311752319,27,1,0,0,1,0.295791625976562,41.055721282959,2,1,1,119.456298828125,0,119.396991729736,,,,,,,,,,,,,,,,,,,,,,,,,,,,,,,,,
,3832591063.87048,122.239418029785,9999.7685546875,0.0194056401581524,2.01389721890207E-6,1,2,13.4005146026611,5.00883572682156,34.7700007259846,25.9235287881276,3.81553137146189,100,0.000139990847599566,,,,,,,,,,,,,,,,,,,,,122.191879272461,122.286956787109,9999.7685546875,9999.7685546875,49.2805056947264,5.4395841049189,7.17263078689575,27,1,0,0,1,0.293121337890625,41.055721282959,2,1,1,122.297172546387,0,122.239418029785,,,,,,,,,,,,,,,,,,,,,,,,,,,,,,,,,
,3832591122.43236,125.122627258301,9999.7685546875,0.0193262874109038,8.19074724393995E-7,1,2,13.4005146026611,5.00877202834912,34.7700007259846,25.8171335268521,3.79944175007143,100,0.000139103371146135,,,,,,,,,,,,,,,,,,,,,125.081245422363,125.164009094238,9999.7685546875,9999.7685546875,49.2539303250725,5.43935487135143,7.20064353942871,27,1,0,0,1,0.294189453125,41.055721282959,2,1,1,125.164009094238,0,125.122627258301,,,,,,,,,,,,,,,,,,,,,,,,,,,,,,,,,
,3832591178.99774,127.965423583984,9999.7685546875,0.0192475198128134,1.23429971191416E-6,1,2,13.4005146026611,5.00873984584854,34.7700007259846,25.7121315859936,3.78073343159809,100,0.000136150971386207,,,,,,,,,,,,,,,,,,,,,127.938896179199,127.99195098877,9999.7685546875,9999.7685546875,49.2797240662071,5.43917143939961,7.20126724243164,27,1,0,0,1,0.295562744140625,41.055721282959,2,1,1,127.99195098877,0,127.965423583984,,,,,,,,,,,,,,,,,,,,,,,,,,,,,,,,,
,3832591235.16357,130.783782958984,9999.7685546875,0.019164397480112,3.02882186883772E-6,1,2,13.4005146026611,5.00868868907255,34.7799994051456,25.6004990089966,3.76603270333392,100,0.000136818845684813,,,,,,,,,,,,,,,,,,,,,130.746719360352,130.820846557617,9999.7685546875,9999.7685546875,49.2488497396975,5.43952818200342,7.20412158966065,27,1,0,0,1,0.29571533203125,41.055721282959,2,1,1,130.820846557617,0,130.783782958984,,,,,,,,,,,,,,,,,,,,,,,,,,,,,,,,,
,3832591291.54375,133.563774108887,9999.7685546875,0.0190813278399639,1.81336699080145E-6,1,2,13.4005146026611,5.00872181317553,34.7799994051456,25.4898121526017,3.74938342607964,100,0.000135957322305394,,,,,,,,,,,,,,,,,,,,,133.514434814453,133.61311340332,9999.7685546875,9999.7685546875,49.2883219799187,5.43924929848777,7.2282829284668,27,1,0,0,1,0.293655395507812,41.055721282959,2,1,1,133.61311340332,0,133.563774108887,,,,,,,,,,,,,,,,,,,,,,,,,,,,,,,,,
,3832591347.95064,136.385726928711,9999.7685546875,0.0189945603854766,1.62967190435054E-6,1,2,13.4005146026611,5.0086614483502,34.790001809597,25.373719771165,3.73059921199604,100,0.000134087653721849,,,,,,,,,,,,,,,,,,,,,136.316329956055,136.455123901367,9999.7685546875,9999.7685546875,49.2422058972841,5.43936299497497,7.22804641723633,27,1,0,0,1,0.2960205078125,41.055721282959,2,1,1,136.455123901367,0,136.385726928711,,,,,,,,,,,,,,,,,,,,,,,,,,,,,,,,,
,3832591404.38721,139.187606811523,9999.7685546875,0.0189067670214118,2.27418925050172E-6,1,2,13.4005146026611,5.00859943879525,34.790001809597,25.2559391931987,3.71383128155318,100,0.000133870123704815,,,,,,,,,,,,,,,,,,,,,139.130447387695,139.244766235352,9999.7685546875,9999.7685546875,49.3219320062456,5.43973944442366,7.24208307266235,27,1,0,0,1,0.294647216796875,41.055721282959,2,1,1,139.244766235352,0,139.187606811523,,,,,,,,,,,,,,,,,,,,,,,,,,,,,,,,,
,3832591460.98685,142.008796691895,9999.7685546875,0.018817011683159,2.69499990680583E-6,1,2,13.4005146026611,5.00859022734766,34.8000004887581,25.1356493218892,3.69855289227345,100,0.000135000639980093,,,,,,,,,,,,,,,,,,,,,141.953186035156,142.064407348633,9999.7685546875,9999.7685546875,49.250412996736,5.44007139715542,7.25432682037353,27,1,0,0,1,0.297012329101562,41.055721282959,2,1,1,142.064407348633,0,142.008796691895,,,,,,,,,,,,,,,,,,,,,,,,,,,,,,,,,
,3832591517.3313,144.823387145996,9999.7685546875,0.0187259281615066,1.94847961117759E-6,1,2,13.4005146026611,5.00858990238575,34.8099991679192,25.0138931014826,3.68125904109086,100,0.000134802829184301,,,,,,,,,,,,,,,,,,,,,144.782836914062,144.86393737793,9999.7685546875,9999.7685546875,49.2539303250725,5.44014743622477,7.25681018829346,27,1,0,0,1,0.294876098632812,41.055721282959,2,1,1,144.86393737793,0,144.823387145996,,,,,,,,,,,,,,,,,,,,,,,,,,,,,,,,,
,3832591571.88229,147.578224182129,9999.7685546875,0.0186370705909939,1.34972381367779E-6,1,2,13.4005146026611,5.0085612599732,34.8099991679192,24.8956296246074,3.65928443881946,100,0.000130814345055026,,,,,,,,,,,,,,,,,,,,,147.517333984375,147.639114379883,9999.7685546875,9999.7685546875,49.3254493345821,5.44050432799479,7.25514888763428,27,1,0,0,1,0.295562744140625,41.055721282959,2,1,1,147.639114379883,0,147.578224182129,,,,,,,,,,,,,,,,,,,,,,,,,,,,,,,,,
,3832591628.22065,150.363876342773,9999.7685546875,0.018544279092902,2.48962867551165E-6,1,2,13.4005146026611,5.00851440417953,34.8099991679192,24.77102747613,3.64340307200443,100,0.000131946200692621,,,,,,,,,,,,,,,,,,,,,150.318588256836,150.409164428711,9999.7685546875,9999.7685546875,49.1652154881398,5.44045708930921,7.27249765396118,27,1,0,0,1,0.294647216796875,41.055721282959,2,1,1,150.409164428711,0,150.363876342773,,,,,,,,,,,,,,,,,,,,,,,,,,,,,,,,,
,3832591682.78305,153.076179504395,9999.7685546875,0.0184534504681082,1.36426605017801E-6,1,2,13.4005146026611,5.00851572946757,34.8200015723705,24.6497923141254,3.62496748533503,100,0.000130857372987546,,,,,,,,,,,,,,,,,,,,,153.007232666016,153.145126342773,9999.7685546875,9999.7685546875,49.2164121561494,5.43992584213044,7.2793493270874,27,1,0,0,1,0.294723510742188,41.055721282959,2,1,1,153.145126342773,0,153.076179504395,,,,,,,,,,,,,,,,,,,,,,,,,,,,,,,,,
,3832591740.84657,155.979866027832,9999.7685546875,0.0183551836833569,2.54175417350108E-6,1,2,13.4005146026611,5.0085036165762,34.8200015723705,24.5185825709638,3.60469143539379,100,0.000129442007766978,,,,,,,,,,,,,,,,,,,,,155.923034667969,156.036697387695,9999.7685546875,9999.7685546875,49.2824597660244,5.44094487942764,7.28947019577026,27,1,0,0,1,0.294570922851562,41.055721282959,2,1,1,156.036697387695,0,155.979866027832,,,,,,,,,,,,,,,,,,,,,,,,,,,,,,,,,
,3832591799.28032,158.873924255371,9999.7685546875,0.0182541626900164,1.49009481488697E-6,1,2,13.4005146026611,5.0085245393523,34.8300002515316,24.3836686183295,3.58566549519991,100,0.000129322406331171,,,,,,,,,,,,,,,,,,,,,158.824768066406,158.923080444336,9999.7685546875,9999.7685546875,49.2074234281783,5.44040871754599,7.30560779571533,27,1,0,0,1,0.2972412109375,41.055721282959,2,1,1,158.923080444336,0,158.873924255371,,,,,,,,,,,,,,,,,,,,,,,,,,,,,,,,,
,3832591855.79271,161.700202941895,9999.7685546875,0.0181551816699129,1.31564897628962E-6,1,2,13.4005146026611,5.00850090095687,34.8300002515316,24.2515538173082,3.56434604218728,100,0.000127234886491909,,,,,,,,,,,,,,,,,,,,,161.647445678711,161.752960205078,9999.7685546875,9999.7685546875,49.3653123890629,5.44027350976764,7.30573987960815,27,1,0,0,1,0.294418334960937,41.055721282959,2,1,1,161.752960205078,0,161.700202941895,,,,,,,,,,,,,,,,,,,,,,,,,,,,,,,,,
,3832591910.08605,164.405059814453,9999.7685546875,0.0180610325781116,1.161545728814E-6,1,2,13.4005146026611,5.0084970949871,34.8399989306927,24.1255922077343,3.54709502840006,100,0.000127499942356525,,,,,,,,,,,,,,,,,,,,,164.362915039062,164.447204589844,9999.7685546875,9999.7685546875,49.2926209367744,5.44050677060909,7.30637216567993,27,1,0,0,1,0.296630859375,41.055721282959,2,1,1,164.447204589844,0,164.405059814453,,,,,,,,,,,,,,,,,,,,,,,,,,,,,,,,,
,3832591968.67664,167.326072692871,9999.7685546875,0.0179590384737243,1.42283567974003E-6,1,2,13.4005146026611,5.00841510382004,34.8399989306927,23.9888921361537,3.52642337643603,100,0.000126359896132891,,,,,,,,,,,,,,,,,,,,,167.283401489258,167.368743896484,9999.7685546875,9999.7685546875,49.4016581152072,5.44072693087325,7.33115577697754,27,1,0,0,1,0.2947998046875,41.055721282959,2,1,1,167.368743896484,0,167.326072692871,,,,,,,,,,,,,,,,,,,,,,,,,,,,,,,,,
,3832592023.35638,170.03328704834,9999.7685546875,0.0178644405745039,2.59159205292021E-6,1,2,13.4005146026611,5.00835983080175,34.850001335144,23.862202267842,3.50758226813058,100,0.000125534982374634,,,,,,,,,,,,,,,,,,,,,169.970977783203,170.095596313477,9999.7685546875,9999.7685546875,49.3246677060629,5.44076181299682,7.3307957649231,27,1,0,0,1,0.295639038085937,41.055721282959,2,1,1,170.095596313477,0,170.03328704834,,,,,,,,,,,,,,,,,,,,,,,,,,,,,,,,,
,3832592079.52652,172.847480773926,9999.7685546875,0.017763680132175,2.16631438888994E-6,1,2,13.4005146026611,5.00837311930412,34.850001335144,23.7272882148374,3.4907478138113,100,0.000127023279401837,,,,,,,,,,,,,,,,,,,,,172.80322265625,172.891738891602,9999.7685546875,9999.7685546875,49.3320931769956,5.44080452811662,7.34658002853394,27,1,0,0,1,0.295486450195313,41.055721282959,2,1,1,172.891738891602,0,172.847480773926,,,,,,,,,,,,,,,,,,,,,,,,,,,,,,,,,
,3832592136.04833,175.643745422363,9999.7685546875,0.0176653208466288,1.54386082527336E-6,1,2,13.4005146026611,5.0084542344984,34.8600000143051,23.5964926769247,3.4710489997203,100,0.00012598560078024,,,,,,,,,,,,,,,,,,,,,175.611587524414,175.675903320313,9999.7685546875,9999.7685546875,49.3410819049668,5.44047915163293,7.35427665710449,27,1,0,0,1,0.294647216796875,41.055721282959,2,1,1,175.675903320313,0,175.643745422363,,,,,,,,,,,,,,,,,,,,,,,,,,,,,,,,,
,3832592194.19587,178.541770935059,9999.7685546875,0.0175619455545608,1.58680246019855E-6,1,2,13.4005146026611,5.00840753977586,34.8699986934662,23.4582663744666,3.44957422816923,100,0.000124411708134142,,,,,,,,,,,,,,,,,,,,,178.492721557617,178.5908203125,9999.7685546875,9999.7685546875,49.2891036084379,5.44016357526605,7.35396099090576,27,1,0,0,1,0.294570922851562,41.055721282959,2,1,1,178.5908203125,0,178.541770935059,,,,,,,,,,,,,,,,,,,,,,,,,,,,,,,,,
,3832592250.66029,181.372291564941,9999.7685546875,0.0174613076678365,1.56172950318219E-6,1,2,13.4005146026611,5.00853405302813,34.8699986934662,23.3248311296121,3.42859511623616,100,0.000122704161637856,,,,,,,,,,,,,,,,,,,,,181.326354980469,181.418228149414,9999.7685546875,9999.7685546875,49.2304814694956,5.43994046978871,7.36395215988159,27,1,0,0,1,0.294189453125,41.055721282959,2,1,1,181.418228149414,0,181.372291564941,,,,,,,,,,,,,,,,,,,,,,,,,,,,,,,,,
,3832592307.15615,184.188087463379,9999.7685546875,0.0173610902286802,1.76729898011259E-6,1,2,13.4005146026611,5.00844978992553,34.8800010979176,23.1898738855318,3.41279671103506,100,0.000124960133482493,,,,,,,,,,,,,,,,,,,,,184.131378173828,184.24479675293,9999.7685546875,9999.7685546875,49.3082535071591,5.44040556714181,7.36639404296875,27,1,0,0,1,0.296249389648438,41.055721282959,2,1,1,184.24479675293,0,184.188087463379,,,,,,,,,,,,,,,,,,,,,,,,,,,,,,,,,
,3832592363.50071,186.998413085938,9999.7685546875,0.0172602433360812,1.94993867417319E-6,1,2,13.4005146026611,5.00849546474346,34.8800010979176,23.0557883757853,3.39063907379964,100,0.000122457499138021,,,,,,,,,,,,,,,,,,,,,186.953247070313,187.043579101562,9999.7685546875,9999.7685546875,49.3512430757168,5.44071368815329,7.37284660339356,27,1,0,0,1,0.295791625976562,41.055721282959,2,1,1,187.043579101562,0,186.998413085938,,,,,,,,,,,,,,,,,,,,,,,,,,,,,,,,,
,3832592418.03632,189.754936218262,9999.7685546875,0.0171707240524247,1.56765158191671E-6,1,2,13.4005146026611,5.00846169409461,34.8899997770786,22.9360118848259,3.37293366309852,100,0.000121755843291766,,,,,,,,,,,,,,,,,,,,,189.697814941406,189.812057495117,9999.7685546875,9999.7685546875,49.2871495371398,5.4408573363588,7.38488149642944,27,1,0,0,1,0.294570922851562,41.055721282959,2,1,1,189.812057495117,0,189.754936218262,,,,,,,,,,,,,,,,,,,,,,,,,,,,,,,,,
,3832592474.39458,192.541702270508,9999.7685546875,0.0170717439710584,1.95072976551323E-6,1,2,13.4005146026611,5.00846971047398,34.8999984562397,22.8037123369778,3.35446720263987,100,0.000121778969741945,,,,,,,,,,,,,,,,,,,,,192.496795654297,192.586608886719,9999.7685546875,9999.7685546875,49.3516338899764,5.44118730943526,7.39482355117798,27,1,0,0,1,0.294570922851562,41.055721282959,2,1,1,192.586608886719,0,192.541702270508,,,,,,,,,,,,,,,,,,,,,,,,,,,,,,,,,
,3832592529.00174,195.278045654297,9999.7685546875,0.0169730101268744,2.26311066624556E-6,1,2,13.4005146026611,5.00845650065771,34.8999984562397,22.6721905066282,3.33187649876957,100,0.0001186976794649,,,,,,,,,,,,,,,,,,,,,195.211685180664,195.34440612793,9999.7685546875,9999.7685546875,49.2719077810148,5.4406938121496,7.39302444458008,27,1,0,0,1,0.294570922851562,41.055721282959,2,1,1,195.34440612793,0,195.278045654297,,,,,,,,,,,,,,,,,,,,,,,,,,,,,,,,,
,3832592587.08271,198.159088134766,9999.7685546875,0.0168643501271212,1.27904247580232E-6,1,2,13.4005146026611,5.00848907055509,34.9100008606911,22.5272937206881,3.31022695334591,100,0.000117677120223931,,,,,,,,,,,,,,,,,,,,,198.105209350586,198.212966918945,9999.7685546875,9999.7685546875,49.3324839912552,5.44069359969536,7.41453266143799,27,1,0,0,1,0.29541015625,41.055721282959,2,1,1,198.212966918945,0,198.159088134766,,,,,,,,,,,,,,,,,,,,,,,,,,,,,,,,,
,3832592643.47354,200.948753356934,9999.7685546875,0.0167639193780236,2.00917646870646E-6,1,2,13.4005146026611,5.00842722527359,34.9100008606911,22.3925855980538,3.2917128914118,100,0.000117914622557968,,,,,,,,,,,,,,,,,,,,,200.893829345703,201.003677368164,9999.7685546875,9999.7685546875,49.3195871206879,5.44057193767039,7.41898250579834,27,1,0,0,1,0.284042358398438,41.055721282959,2,1,1,201.003677368164,0,200.948753356934,,,,,,,,,,,,,,,,,,,,,,,,,,,,,,,,,
,3832592702.03084,203.881759643555,9999.7685546875,0.016660944292026,1.36709325707811E-6,1,2,13.4005146026611,5.00840585859523,34.9199995398521,22.2549558678237,3.2711154935672,100,0.000116922231649773,,,,,,,,,,,,,,,,,,,,,203.828964233398,203.934555053711,9999.7685546875,9999.7685546875,49.2578384676687,5.44053699660129,7.41463565826416,27,1,0,0,1,0.296859741210937,41.055721282959,2,1,1,203.934555053711,0,203.881759643555,,,,,,,,,,,,,,,,,,,,,,,,,,,,,,,,,
,3832592754.31628,206.497268676758,9999.7685546875,0.0165690611298769,1.71920211685251E-6,1,2,13.4005146026611,5.00838208474548,34.9299982190132,22.1321334971832,3.25266331190811,100,0.000115984795119578,,,,,,,,,,,,,,,,,,,,,206.445266723633,206.549270629883,9999.7685546875,9999.7685546875,49.3121616497552,5.44084578887386,7.43174934387207,27,1,0,0,1,0.296173095703125,41.055721282959,2,1,1,206.549270629883,0,206.497268676758,,,,,,,,,,,,,,,,,,,,,,,,,,,,,,,,,
,3832592810.69854,209.279296875,9999.7685546875,0.0164695609798084,2.10015456036457E-6,1,2,13.4005146026611,5.0084013885744,34.9299982190132,21.9992043597123,3.23413196813272,100,0.000116024557158666,,,,,,,,,,,,,,,,,,,,,209.239028930664,209.319564819336,9999.7685546875,9999.7685546875,49.2906668654764,5.44028774727789,7.43703651428223,27,1,0,0,1,0.293731689453125,41.055721282959,2,1,1,209.319564819336,0,209.279296875,,,,,,,,,,,,,,,,,,,,,,,,,,,,,,,,,
,3832592869.20674,212.222587585449,9999.7685546875,0.0163701764605066,1.41325485444406E-6,1,2,13.4005146026611,5.00837268684102,34.9400006234646,21.8664744019629,3.21320228438618,100,0.000114286058140301,,,,,,,,,,,,,,,,,,,,,212.183624267578,212.26155090332,9999.7685546875,9999.7685546875,49.3531971470148,5.44046491527378,7.44175577163696,27,1,0,0,1,0.29571533203125,41.055721282959,2,1,1,212.26155090332,0,212.222587585449,,,,,,,,,,,,,,,,,,,,,,,,,,,,,,,,,
,3832592925.77256,215.044296264648,9999.7685546875,0.0162718434991374,2.27207581861918E-6,1,2,13.4005146026611,5.00837030773726,34.9499993026257,21.7350276271732,3.19450224530836,100,0.000114050711069977,,,,,,,,,,,,,,,,,,,,,215.004287719727,215.08430480957,9999.7685546875,9999.7685546875,49.3219320062456,5.44023667494187,7.4424262046814,27,1,0,0,1,0.296249389648438,41.055721282959,2,1,1,215.08430480957,0,215.044296264648,,,,,,,,,,,,,,,,,,,,,,,,,,,,,,,,,
,3832592979.976,217.747741699219,9999.7685546875,0.0161766510911452,1.67936276301474E-6,1,2,13.4005146026611,5.00838158164247,34.9499993026257,21.607946121553,3.17578971344948,100,0.00011335803469127,,,,,,,,,,,,,,,,,,,,,217.69596862793,217.799514770508,9999.7685546875,9999.7685546875,49.1613073455437,5.44009493434369,7.45392894744873,27,1,0,0,1,0.295944213867188,41.055721282959,2,1,1,217.829452514648,0,217.747741699219,,,,,,,,,,,,,,,,,,,,,,,,,,,,,,,,,
,3832593036.69855,220.571495056152,9999.7685546875,0.0160789233850627,1.89690425622551E-6,1,2,13.4005146026611,5.00835232611835,34.960001707077,21.476914427762,3.15887107350923,100,0.000114387731778956,,,,,,,,,,,,,,,,,,,,,220.537155151367,220.605834960938,9999.7685546875,9999.7685546875,49.2527578822937,5.44003296745693,7.45934629440308,26,1,64,0,0,0.285491943359375,41.055721282959,2,1,1,220.605834960938,0,220.571495056152,,,,,,,,,,,,,,,,,,,,,,,,,,,,,,,,,
,3832593092.76367,223.376609802246,9999.7685546875,0.0159828747139343,1.62580395161263E-6,1,2,13.4005146026611,5.00840184632895,34.9700003862381,21.3491224637945,3.13851680600386,100,0.000112562415440074,,,,,,,,,,,,,,,,,,,,,223.323150634766,223.430068969727,9999.7685546875,9999.7685546875,49.1988255144667,5.44017012066143,7.4700288772583,27,1,0,0,1,0.295028686523438,41.055721282959,2,1,1,223.430068969727,0,223.376609802246,,,,,,,,,,,,,,,,,,,,,,,,,,,,,,,,,
,3832593148.48612,226.158622741699,9999.7685546875,0.0158862886167834,1.85229138532031E-6,1,2,13.4005146026611,5.00837677537292,34.9700003862381,21.2201471649689,3.11820774147399,100,0.000110893935637825,,,,,,,,,,,,,,,,,,,,,226.078765869141,226.238479614258,9999.7685546875,9999.7685546875,49.3109892069764,5.44038066253516,7.49076890945435,27,1,0,0,1,0.29296875,41.055721282959,2,1,1,226.238479614258,0,226.158622741699,,,,,,,,,,,,,,,,,,,,,,,,,,,,,,,,,
,3832593203.5875,228.894157409668,9999.7685546875,0.0157940124483043,2.30576255588638E-6,1,2,13.4005146026611,5.00838342964813,34.9799990653992,21.0970821628305,3.09899405298469,100,0.000109421808560239,,,,,,,,,,,,,,,,,,,,,228.852310180664,228.936004638672,9999.7685546875,9999.7685546875,49.105030092159,5.44077719719797,7.49682188034058,27,1,0,0,1,0.294723510742188,41.055721282959,2,1,1,228.936004638672,0,228.894157409668,,,,,,,,,,,,,,,,,,,,,,,,,,,,,,,,,
,3832593262.02141,231.830375671387,9999.7685546875,0.0156968736657995,1.29167684268229E-6,1,2,13.4005146026611,5.00841312303078,34.9900014698505,20.9674902987938,3.08001080442957,100,0.000108787497094965,,,,,,,,,,,,,,,,,,,,,231.768081665039,231.892669677734,9999.7685546875,9999.7685546875,49.3371737623706,5.44014379328026,7.50857925415039,27,1,0,0,1,0.295486450195313,41.055721282959,2,1,1,231.892669677734,0,231.830375671387,,,,,,,,,,,,,,,,,,,,,,,,,,,,,,,,,
,3832593318.48601,234.635101318359,9999.7685546875,0.015602251991192,1.61786283578402E-6,1,2,13.4005146026611,5.00835532963162,35.0000001490116,20.8407184226201,3.06175297200515,100,0.000108398679616633,,,,,,,,,,,,,,,,,,,,,234.587493896484,234.682708740234,9999.7685546875,9999.7685546875,49.1851470153802,5.44056636519219,7.52299880981445,27,1,0,0,1,0.286483764648438,41.055721282959,2,1,1,234.682708740234,0,234.635101318359,,,,,,,,,,,,,,,,,,,,,,,,,,,,,,,,,
,3832593375.0771,237.438873291016,9999.7685546875,0.0155090995164288,1.73142452792994E-6,1,2,13.4005146026611,5.00835700796035,35.0000001490116,20.7162410347398,3.04389197299101,100,0.000108063858784043,,,,,,,,,,,,,,,,,,,,,237.376907348633,237.500839233398,9999.7685546875,9999.7685546875,49.2359528691302,5.44025013770762,7.54616403579712,27,1,0,0,1,0.295333862304687,41.055721282959,2,1,1,237.500839233398,0,237.438873291016,,,,,,,,,,,,,,,,,,,,,,,,,,,,,,,,,
,3832593431.37359,240.248558044434,9999.7685546875,0.0154171167433743,1.81766776474119E-6,1,2,13.4005146026611,5.00832289249252,35.0200012326241,20.5928671538976,3.02807360098551,100,0.00010911533470366,,,,,,,,,,,,,,,,,,,,,240.206970214844,240.290145874023,9999.7685546875,9999.7685546875,49.2211019272648,5.4403523792124,7.56370162963867,27,1,0,0,1,0.29541015625,41.055721282959,2,1,1,240.290145874023,0,240.248558044434,,,,,,,,,,,,,,,,,,,,,,,,,,,,,,,,,
,3832593485.91799,242.984222412109,9999.7685546875,0.0153281203140212,2.04803506966877E-6,1,2,13.4005146026611,5.00833326219404,35.0200012326241,20.4744654661992,3.00764003069751,100,0.000106269884014098,,,,,,,,,,,,,,,,,,,,,242.908615112305,243.059829711914,9999.7685546875,9999.7685546875,49.2640914958225,5.44038971376965,7.57196617126465,27,1,0,0,1,0.293121337890625,41.055721282959,2,1,1,243.059829711914,0,242.984222412109,,,,,,,,,,,,,,,,,,,,,,,,,,,,,,,,,
,3832593542.22874,245.788673400879,9999.7685546875,0.0152359752822191,1.28099578589074E-6,1,2,13.4005146026611,5.00830338513612,35.0299999117851,20.3510317690429,2.99086160608461,100,0.000106623081706676,,,,,,,,,,,,,,,,,,,,,245.749664306641,245.827682495117,9999.7685546875,9999.7685546875,49.3828990307456,5.44071337954548,7.59502506256104,27,1,0,0,1,0.293731689453125,41.055721282959,2,1,1,245.827682495117,0,245.788673400879,,,,,,,,,,,,,,,,,,,,,,,,,,,,,,,,,
,3832593599.8115,248.67244720459,9999.7685546875,0.0151426272230662,1.55212081497241E-6,1,2,13.4005146026611,5.00831124016447,35.0399985909462,20.2266408774766,2.97073527092297,100,0.000104617394066303,,,,,,,,,,,,,,,,,,,,,248.592132568359,248.75276184082,9999.7685546875,9999.7685546875,49.2738618523129,5.44079386687916,7.62559795379639,27,1,0,0,1,0.28778076171875,41.055721282959,2,1,1,248.75276184082,0,248.67244720459,,,,,,,,,,,,,,,,,,,,,,,,,,,,,,,,,
,3832593656.90424,251.517303466797,9999.7685546875,0.015052923828311,1.46966654626034E-6,1,2,13.4005146026611,5.00825383117526,35.0500009953976,20.1064725166016,2.95332491791566,100,0.000104172856629516,,,,,,,,,,,,,,,,,,,,,251.470794677734,251.563812255859,9999.7685546875,9999.7685546875,49.1788939872264,5.44097492360829,7.65680551528931,27,1,0,0,1,0.293655395507812,41.5444793701172,2,1,1,251.563812255859,0,251.517303466797,,,,,,,,,,,,,,,,,,,,,,,,,,,,,,,,,
,3832593713.36444,254.338439941406,9999.7685546875,0.0149622629712725,1.8330453629578E-6,1,2,13.4005146026611,5.00814383954804,35.0500009953976,19.9847690491405,2.93549325320648,100,0.00010357817708913,,,,,,,,,,,,,,,,,,,,,254.283233642578,254.393646240234,9999.7685546875,9999.7685546875,49.209768313736,5.44145645913657,7.70463562011719,27,1,0,0,1,0.293426513671875,41.055721282959,2,1,1,254.393646240234,0,254.338439941406,,,,,,,,,,,,,,,,,,,,,,,,,,,,,,,,,
,3832593767.73699,257.081466674805,9999.7685546875,0.0148772482193125,1.06434268627651E-6,1,2,13.4005146026611,5.00821229641274,35.0599996745586,19.8716142088386,2.9186808006417,100,0.00010284927964654,,,,,,,,,,,,,,,,,,,,,257.041900634766,257.121032714844,9999.7685546875,9999.7685546875,49.2527578822937,5.4413941856065,7.72680473327637,27,1,0,0,1,0.295944213867188,41.055721282959,2,1,1,257.121032714844,0,257.081466674805,,,,,,,,,,,,,,,,,,,,,,,,,,,,,,,,,
,3832593824.16464,259.830001831055,9999.7685546875,0.014789653061586,2.06135808752236E-6,1,2,13.4005146026611,5.00821715342247,35.0699983537197,19.7545639112272,2.90203767391817,100,0.000102645970246022,,,,,,,,,,,,,,,,,,,,,259.775909423828,259.884094238281,9999.7685546875,9999.7685546875,49.3352196910725,5.44134471104474,7.68118715286255,27,1,0,0,1,0.293807983398438,41.055721282959,2,1,1,259.884094238281,0,259.830001831055,,,,,,,,,,,,,,,,,,,,,,,,,,,,,,,,,
,3832593880.65585,262.664031982422,9999.7685546875,0.0147013361240078,1.3686836054736E-6,1,2,13.4005146026611,5.00824034785373,35.0800007581711,19.6366833224173,2.8850110743068,100,0.000102245999413417,,,,,,,,,,,,,,,,,,,,,262.606384277344,262.7216796875,9999.7685546875,9999.7685546875,49.2785516234283,5.44108140365245,7.66013860702515,27,1,0,0,1,0.286636352539062,39.5894432067871,2,1,1,262.7216796875,0,262.664031982422,,,,,,,,,,,,,,,,,,,,,,,,,,,,,,,,,
,3832593937.18215,265.491027832031,9999.7685546875,0.0146146663744693,1.75496962175183E-6,1,2,13.4005146026611,5.00822287777704,35.0899994373322,19.5206444005791,2.86927957564022,100,0.000102608344855917,,,,,,,,,,,,,,,,,,,,,265.427825927734,265.554229736328,9999.7685546875,9999.7685546875,49.1910092292744,5.44122682046303,7.67100381851196,27,1,0,0,1,0.29541015625,41.055721282959,2,1,1,265.554229736328,0,265.491027832031,,,,,,,,,,,,,,,,,,,,,,,,,,,,,,,,,
,3832593993.49899,268.294540405273,9999.7685546875,0.0145280191979896,2.00619406144527E-6,1,2,13.4005146026611,5.00816509984928,35.0899994373322,19.4050406700605,2.84910559773124,100,9.96681303561471E-5,,,,,,,,,,,,,,,,,,,,,268.255767822266,268.333312988281,9999.7685546875,9999.7685546875,49.2054693568802,5.44193881418865,7.67843437194824,27,1,0,0,1,0.294876098632812,41.055721282959,2,1,1,268.333312988281,0,268.294540405273,,,,,,,,,,,,,,,,,,,,,,,,,,,,,,,,,
,3832594048.02061,271.048706054687,9999.7685546875,0.0144458253341456,8.46990223162178E-7,1,2,13.4005146026611,5.00815433437311,35.1000018417835,19.2950676715678,2.83390902180849,100,9.98005015200419E-5,,,,,,,,,,,,,,,,,,,,,270.995178222656,271.102233886719,9999.7685546875,9999.7685546875,49.3262309631014,5.44185396324882,7.68247699737549,27,1,0,0,1,0.2862548828125,41.055721282959,2,1,1,271.102233886719,0,271.048706054687,,,,,,,,,,,,,,,,,,,,,,,,,,,,,,,,,
,3832594104.42293,273.816711425781,9999.7685546875,0.0143616601612388,1.46930238952226E-6,1,2,13.4005146026611,5.00812191344868,35.1100005209446,19.182542572811,2.81692403332349,100,9.88832320948355E-5,,,,,,,,,,,,,,,,,,,,,273.780639648438,273.852783203125,9999.7685546875,9999.7685546875,49.3059086216014,5.44146939433647,7.70955085754394,27,1,0,0,1,0.284805297851562,41.055721282959,2,1,1,273.852783203125,0,273.816711425781,,,,,,,,,,,,,,,,,,,,,,,,,,,,,,,,,
,3832594160.91723,276.662094116211,9999.7685546875,0.0142778159196801,8.66582025131354E-7,1,2,13.4005146026611,5.00823896631945,35.1199992001057,19.0712821990938,2.79971549926338,100,9.76682310644276E-5,,,,,,,,,,,,,,,,,,,,,276.623565673828,276.700622558594,9999.7685546875,9999.7685546875,49.306299435861,5.44120312340972,7.74446821212769,27,1,0,0,1,0.297164916992188,41.055721282959,2,1,1,276.700622558594,0,276.662094116211,,,,,,,,,,,,,,,,,,,,,,,,,,,,,,,,,
,3832594219.04794,279.556076049805,9999.7685546875,0.0141926292583227,1.19532065627148E-6,1,2,13.4005146026611,5.00828170524589,35.130001604557,18.9577078857929,2.7831097007615,100,9.7134768509669E-5,,,,,,,,,,,,,,,,,,,,,279.503509521484,279.608642578125,9999.7685546875,9999.7685546875,49.1804572442648,5.44115860491762,7.77850914001465,27,1,0,0,1,0.293350219726562,41.055721282959,2,1,1,279.608642578125,0,279.556076049805,,,,,,,,,,,,,,,,,,,,,,,,,,,,,,,,,
,3832594275.47313,282.226608276367,9999.7685546875,0.014121874928349,1.8887182367485E-6,1,2,13.4005146026611,5.00823082391198,35.1400002837181,18.862803806293,2.77014444319799,100,9.73594205137509E-5,,,,,,,,,,,,,,,,,,,,,282.180358886719,282.272857666016,9999.7685546875,9999.7685546875,49.2984831506687,5.4416634003533,7.8284649848938,27,1,0,0,1,0.295028686523438,41.055721282959,2,1,1,282.272857666016,0,282.226608276367,,,,,,,,,,,,,,,,,,,,,,,,,,,,,,,,,
,3832594334.01587,285.262405395508,9999.7685546875,0.0140336336392698,1.15627803675283E-6,1,2,13.4005146026611,5.00823740478481,35.1499989628792,18.7449779408733,2.75279920016124,100,9.6720555080132E-5,,,,,,,,,,,,,,,,,,,,,285.220947265625,285.303863525391,9999.7685546875,9999.7685546875,49.2765975521302,5.44176342815285,7.92654418945313,27,1,0,0,1,0.28656005859375,41.055721282959,2,1,1,285.303863525391,0,285.262405395508,,,,,,,,,,,,,,,,,,,,,,,,,,,,,,,,,
,3832594391.6226,288.225662231445,9999.7685546875,0.0139450106656289,1.83917894540175E-6,1,2,13.4005146026611,5.00825700831065,35.1600013673306,18.6267040915762,2.73541691467026,100,9.6100127093682E-5,,,,,,,,,,,,,,,,,,,,,288.142333984375,288.308990478516,9999.7685546875,9999.7685546875,49.3145065353129,5.44175918799852,8.02608585357666,27,1,0,0,1,0.29327392578125,41.055721282959,2,1,1,288.308990478516,0,288.225662231445,,,,,,,,,,,,,,,,,,,,,,,,,,,,,,,,,
,3832594446.71052,291.020156860352,9999.7685546875,0.0138661471112838,1.52440175698928E-6,1,2,13.4005146026611,5.00827438217871,35.1700000464916,18.5216015966954,2.7188892730931,100,9.47557121364537E-5,,,,,,,,,,,,,,,,,,,,,290.973815917969,291.066497802734,9999.7685546875,9999.7685546875,49.1015127638225,5.44160223042557,8.13420486450195,27,1,0,0,1,0.295333862304687,41.055721282959,2,1,1,291.066497802734,0,291.020156860352,,,,,,,,,,,,,,,,,,,,,,,,,,,,,,,,,
,3832594503.11962,293.806015014648,9999.7685546875,0.0137831862391912,1.31862937059606E-6,1,2,13.4005146026611,5.00825615502774,35.1799987256527,18.4106304400869,2.70307516112817,100,9.45376209293572E-5,,,,,,,,,,,,,,,,,,,,,293.748046875,293.863983154297,9999.7685546875,9999.7685546875,49.3258401488418,5.44177176259904,8.13169956207275,27,1,0,0,1,0.285263061523438,41.055721282959,2,1,1,293.863983154297,0,293.806015014648,,,,,,,,,,,,,,,,,,,,,,,,,,,,,,,,,
,3832594557.55327,296.49772644043,9999.7685546875,0.0137049811028062,1.67726426129224E-6,1,2,13.4005146026611,5.00826248671114,35.1900011301041,18.3063863671863,2.68641724416122,100,9.30098746440346E-5,,,,,,,,,,,,,,,,,,,,,296.44580078125,296.549652099609,9999.7685546875,9999.7685546875,49.3512430757168,5.44161176925416,8.07900810241699,27,1,0,0,1,0.294647216796875,41.055721282959,2,1,1,296.549652099609,0,296.49772644043,,,,,,,,,,,,,,,,,,,,,,,,,,,,,,,,,
,3832594615.96121,299.257568359375,9999.7685546875,0.0136288875870998,1.62433259857724E-6,1,2,13.4005146026611,5.00824135989024,35.1999998092651,18.2044027653104,2.67318086870172,100,9.376098841079E-5,,,,,,,,,,,,,,,,,,,,,299.23046875,299.28466796875,9999.7685546875,9999.7685546875,49.2863679086206,5.4414330663234,8.05996608734131,27,1,0,0,1,0.29205322265625,41.055721282959,6,1,1,299.28466796875,0,299.257568359375,,,,,,,,,,,,,,,,,,,,,,,,,,,,,,,,,
,3832594676.74231,299.866592407227,9999.7685546875,0.0136188340586991,1.16085695785148E-6,1,2,13.4005146026611,5.00822429937055,35.1999998092651,18.1910492410973,2.67005297006086,100,9.28365121272382E-5,,,,,,,,,,,,,,,,,,,,,299.865234375,299.867950439453,9999.7685546875,9999.7685546875,49.2789424376879,5.44145508342069,8.03593063354492,27,1,0,0,1,0.293807983398438,41.055721282959,5,1,1,299.867950439453,0,299.866592407227,,,,,,,,,,,,,,,,,,,,,,,,,,,,,,,,,
,3832594688.51175,299.898300170898,9999.7685546875,0.0136179752846026,1.23517564924504E-6,1,2,13.4005146026611,5.00824230711096,35.1999998092651,18.1899620015821,2.67010906277656,100,9.29887264303345E-5,,,,,,,,,,,,,,,,,,,,,299.896575927734,299.900024414063,9999.7685546875,9999.7685546875,49.2816781375052,5.44177692240396,8.02557468414307,27,1,0,0,1,0.295028686523438,41.055721282959,1,1,1,299.900024414063,0,299.898300170898,,,,,,,,,,,,,,,,,,,,,,,,,,,,,,,,,