File: SI Fig S11-13 SQUID all/Michaela_Dy_Hyst300K.dat
[Header]
; MPMS3 Data File (default extension .dat)
; Copyright (c) 2007, Quantum Design, Inc. All rights reserved.
TITLE,
FILEOPENTIME,3832410432.20469,06/09/2021,2:27 pm
BYAPP,MPMS3 w/ AC,1.0,1.1
INFO,MPMS3 Measurement Release 1.1.16 Build 424, MultiVu Release 2.3.4.19,APPNAME
INFO,Linear Motor Servo Controller,MOTOR_MODULE_NAME
INFO,3101-100 E1,MOTOR_HW_VERSION
INFO,MMC211,MOTOR_SERIAL_NUMBER
INFO,01.04.28,MOTOR_SOFTWARE_VERSION
INFO,Quantum Design Squid Module,SQUID_MODULE_NAME
INFO,3101-501 B0,SQUID_HW_VERSION
INFO,SQM059,SQUID_SERIAL_NUMBER
INFO,01.03.04,SQUID_SOFTWARE_VERSION
INFO,SQUID AC,AC_MODULE_NAME
INFO,3101-401 F1,AC_HW_VERSION
INFO,SAC057,AC_SERIAL_NUMBER
INFO,SQUID AC 00.95.07,AC_SOFTWARE_VERSION
INFO,TCIXXX,COIL_SERIAL_NUMBER
INFO,0,MOMENT_UNITS
INFO,Michaela_Dy,SAMPLE_MATERIAL
INFO,Michaela_Dy,SAMPLE_COMMENT
INFO,.85,SAMPLE_MASS
INFO,,SAMPLE_VOLUME
INFO,,SAMPLE_MOLECULAR_WEIGHT
INFO,,SAMPLE_SIZE
INFO,,SAMPLE_SHAPE
INFO,Straw,SAMPLE_HOLDER
INFO,Standard,SAMPLE_HOLDER_DETAIL
INFO,54.24,SAMPLE_OFFSET
DATATYPE,COMMENT,1
DATATYPE,TIME,2
STARTUPAXIS,X,2
STARTUPAXIS,Y1,5
FIELDGROUP, VSM,2,3,4,5,6,8,9,10,11,14,15
FIELDGROUP, DC, 2,3,4,14,56,57,58,59,60,61,62,63,64,65,66,67,68,69
FIELDGROUP, AC, 2,3,4,11,16,17,18,19,20,21,22,23,24,25,26,27,28,29,30
STARTUPGROUP, All
[Data]
Comment,Time Stamp (sec),Temperature (K),Magnetic Field (Oe),Moment (emu),M. Std. Err. (emu),Transport Action,Averaging Time (sec),Frequency (Hz),Peak Amplitude (mm),Center Position (mm),Lockin Signal' (V),Lockin Signal (V),Range,M. Quad. Signal (emu),AC Moment (emu),AC M. Std Err. (emu),AC Phase (deg),AC Phase Std. Err. (deg),AC Susceptibility (emu/Oe),AC Suscept. Std Err. (emu/Oe),AC X' (emu/Oe),AC X' Std Err. (emu/Oe),AC X'' (emu/Oe),AC X'' Std Err. (emu/Oe),AC Drive (Oe),AC Frequency (Hz),AC Averaging Time (sec),AC Cycles,AC Range,AC Measure Type,AC Signal' (V),AC Signal'' (V),AC Trim Coil Ratio,AC Trim Coil Phase,Min. Temperature (K),Max. Temperature (K),Min. Field (Oe),Max. Field (Oe),Mass (grams),Motor Lag (deg),Pressure (Torr),Measure Count,Measurement Number,SQUID Status (code),Motor Status (code),Measure Status (code),Motor Current (amps),Motor Temp. (C),Temp. Status (code),Field Status (code),Chamber Status (code),Chamber Temp (K),Redirection State,Average Temp (K),Rotation Angle (deg),Rotator state,DC Moment Fixed Ctr (emu),DC Moment Err Fixed Ctr (emu),DC Moment Free Ctr (emu),DC Moment Err Free Ctr (emu),DC Fixed Fit,DC Free Fit,DC Calculated Center (mm),DC Calculated Center Err (mm),DC Scan Length (mm),DC Scan Time (s),DC Number of Points,DC Squid Drift,DC Min V (V),DC Max V (V),DC Scans per Measure,Map 01,Map 02,Map 03,Map 04,Map 05,Map 06,Map 07,Map 08,Map 09,Map 10,Map 11,Map 12,Map 13,Map 14,Map 15,Map 16
,3832410457.43728,299.735412597656,0.137089997529984,5.84801720471526E-8,1.09265094181358E-8,1,2,13.4005146026611,5.00506625850022,33.100001513958,7.78347696806973E-5,1.29678546529375E-5,1,1.53077579576325E-9,,,,,,,,,,,,,,,,,,,,,299.735412597656,299.735412597656,0.137089997529984,0.137089997529984,47.2936059988415,5.26546517985563,8.32947063446045,27,1,0,0,1,0.276336669921875,39.1006851196289,1,1,1,299.735412597656,0,299.735412597656,,,,,,,,,,,,,,,,,,,,,,,,,,,,,,,,,
,3832410477.12808,299.707824707031,1578.7783203125,3.919238693237E-5,3.34186295314951E-8,1,2,13.4005146026611,5.00516952350054,33.100001513958,0.0522394912430675,0.00815810863847082,1,6.2693897858256E-7,,,,,,,,,,,,,,,,,,,,,299.706665039063,299.708984375,1578.7783203125,1578.7783203125,47.3549638376012,5.2649684118801,9.15167617797852,25,1,68,0,0,0.27496337890625,39.5894432067871,1,1,1,299.708984375,0,299.707824707031,,,,,,,,,,,,,,,,,,,,,,,,,,,,,,,,,
,3832410500.33347,299.681640625,3684.05712890625,9.73463661003309E-5,1.49025671846891E-8,1,2,13.4005146026611,5.00518819516811,33.100001513958,0.129907137754668,0.0191646873636264,1,7.34831300652198E-7,,,,,,,,,,,,,,,,,,,,,299.676879882812,299.686401367188,3684.05712890625,3684.05712890625,47.3616076800146,5.26514639638715,9.88132476806641,27,1,0,0,1,0.283432006835938,39.5894432067871,1,1,1,299.676879882812,0,299.681640625,,,,,,,,,,,,,,,,,,,,,,,,,,,,,,,,,
,3832410526.17863,299.751998901367,5789.24853515625,0.000155624203795361,2.24310589949268E-8,1,2,13.4005146026611,5.00534385276501,33.100001513958,0.207676273927924,0.0307144523524896,1,1.23106778944118E-6,,,,,,,,,,,,,,,,,,,,,299.74560546875,299.758392333984,5789.24853515625,5789.24853515625,47.3877922354089,5.2652689450502,10.4513740539551,27,1,0,0,1,0.278854370117187,39.5894432067871,1,1,1,299.758392333984,0,299.751998901367,,,,,,,,,,,,,,,,,,,,,,,,,,,,,,,,,
,3832410550.93353,299.79084777832,7894.34033203125,0.000214022264467221,2.85875327928924E-8,1,2,13.4005146026611,5.00537805998806,33.100001513958,0.285580481630754,0.042448494660263,1,1.848744881641E-6,,,,,,,,,,,,,,,,,,,,,299.788879394531,299.792816162109,7894.34033203125,7894.34033203125,47.3502740664858,5.26511638014809,10.8772888183594,27,1,0,0,1,0.279998779296875,39.5894432067871,1,1,1,299.792816162109,0,299.79084777832,,,,,,,,,,,,,,,,,,,,,,,,,,,,,,,,,
,3832410572.82875,299.855545043945,9999.66796875,0.000272583767112769,2.83057976028155E-8,1,2,13.4005146026611,5.00535331371482,33.100001513958,0.363725065760584,0.0540234315397088,1,2.32496330580757E-6,,,,,,,,,,,,,,,,,,,,,299.853454589844,299.857635498047,9999.66796875,9999.66796875,47.39678096338,5.26525451103964,11.1629514694214,27,1,0,0,1,0.275115966796875,40.0782012939453,1,1,1,299.857635498047,0,299.855545043945,,,,,,,,,,,,,,,,,,,,,,,,,,,,,,,,,
,3832410606.35113,299.866104125977,13333.07421875,0.000365515511669348,5.19211913629364E-8,1,2,13.4005146026611,5.00547120959414,33.100001513958,0.487735034115806,0.0725169403573988,1,3.17226259144378E-6,,,,,,,,,,,,,,,,,,,,,299.865661621094,299.866546630859,13333.07421875,13333.07421875,47.4452419315723,5.26544497869853,11.5343065261841,27,1,0,0,1,0.275192260742187,40.0782012939453,1,1,1,299.865661621094,0,299.866104125977,,,,,,,,,,,,,,,,,,,,,,,,,,,,,,,,,
,3832410631.63619,299.887481689453,17777.630859375,0.000489422277118484,7.3413793701035E-8,1,2,13.4005146026611,5.00550884034055,33.100001513958,0.653094115416738,0.0969991402613675,1,4.17170062071381E-6,,,,,,,,,,,,,,,,,,,,,299.885467529297,299.889495849609,17777.630859375,17777.630859375,47.4354715750819,5.26506338803139,11.7363538742065,27,1,0,0,1,0.282745361328125,40.0782012939453,1,1,1,299.889495849609,0,299.887481689453,,,,,,,,,,,,,,,,,,,,,,,,,,,,,,,,,
,3832410675.49024,299.967742919922,21999.56640625,0.000607121450756544,7.47301553076767E-8,1,2,13.4005146026611,5.00558788703283,33.100001513958,0.810172465937138,0.120322183327665,1,5.17008259990517E-6,,,,,,,,,,,,,,,,,,,,,299.967742919922,299.967742919922,21999.56640625,21999.56640625,47.3299517249858,5.26477035398729,11.987286567688,27,1,0,0,1,0.283279418945313,39.5894432067871,1,1,1,299.967742919922,0,299.967742919922,,,,,,,,,,,,,,,,,,,,,,,,,,,,,,,,,
,3832410712.25767,299.990112304687,34999.9609375,0.000969519012784387,1.33411661641775E-7,1,2,13.4005146026611,5.00564216893034,33.100001513958,1.29376160265138,0.192368576572493,1,8.4222415239278E-6,,,,,,,,,,,,,,,,,,,,,299.989837646484,299.990386962891,34999.9609375,34999.9609375,47.3491016237069,5.26431572013271,12.1953458786011,26,1,68,0,0,0.283279418945313,40.0782012939453,1,1,1,299.990386962891,0,299.990112304687,,,,,,,,,,,,,,,,,,,,,,,,,,,,,,,,,
,3832410790.35631,299.977447509766,58332.85546875,0.00161872419941927,2.40772419841981E-7,1,2,13.4005146026611,5.00567638905696,33.100001513958,2.16055580314102,0.317959922824352,10,1.16483525984805E-5,,,,,,,,,,,,,,,,,,,,,299.977447509766,299.977447509766,58332.85546875,58332.85546875,47.2197421037742,5.26392678624814,12.479006767273,27,1,0,0,1,0.282974243164062,40.0782012939453,1,1,1,299.977447509766,0,299.977447509766,,,,,,,,,,,,,,,,,,,,,,,,,,,,,,,,,
,3832410843.89082,299.99169921875,58332.953125,0.00161817149232698,2.28114273486792E-7,1,2,13.4005146026611,5.00564495302439,33.100001513958,2.15984583451698,0.317517545033684,10,1.13965706285314E-5,,,,,,,,,,,,,,,,,,,,,299.991149902344,299.992248535156,58332.953125,58332.953125,47.1556485651973,5.26400721218196,12.6258239746094,27,1,0,0,1,0.278778076171875,40.0782012939453,1,1,1,299.992248535156,0,299.99169921875,,,,,,,,,,,,,,,,,,,,,,,,,,,,,,,,,
,3832410900.07862,299.994338989258,34999.66015625,0.000968877306240003,1.40122455797287E-7,1,2,13.4005146026611,5.00566603316591,33.100001513958,1.29324756508349,0.189854818830258,10,6.6295680703346E-6,,,,,,,,,,,,,,,,,,,,,299.993927001953,299.994750976562,34999.66015625,34999.66015625,47.3119742690435,5.26412748967594,12.7711448669434,27,1,0,0,1,0.274810791015625,40.0782012939453,1,1,1,299.993927001953,0,299.994338989258,,,,,,,,,,,,,,,,,,,,,,,,,,,,,,,,,
,3832410941.03658,299.963943481445,21999.56640625,0.000606365845159724,8.00350723635708E-8,1,2,13.4005146026611,5.00569165760903,33.100001513958,0.809392309582283,0.118708100209879,10,4.06510368331174E-6,,,,,,,,,,,,,,,,,,,,,299.961669921875,299.966217041016,21999.56640625,21999.56640625,47.3092385692262,5.26445536464316,12.8627738952637,27,1,0,0,1,0.275039672851562,40.0782012939453,1,1,1,299.961669921875,0,299.963943481445,,,,,,,,,,,,,,,,,,,,,,,,,,,,,,,,,
,3832410982.19295,299.978759765625,17777.408203125,0.000488215577581199,4.84037949203388E-8,1,2,13.4005146026611,5.0056738320176,33.100001513958,0.651538984814223,0.0965802079514486,1,4.02359557074647E-6,,,,,,,,,,,,,,,,,,,,,299.978759765625,299.978759765625,17777.408203125,17777.408203125,47.36629745113,5.26444196337738,12.9706916809082,27,1,0,0,1,0.27557373046875,39.5894432067871,1,1,1,299.978759765625,0,299.978759765625,,,,,,,,,,,,,,,,,,,,,,,,,,,,,,,,,
,3832411010.87026,299.993789672852,13333.07421875,0.000364172089393087,3.54492364829155E-8,1,2,13.4005146026611,5.00562231629412,33.100001513958,0.486002683279328,0.0719657499229699,1,2.9453099615964E-6,,,,,,,,,,,,,,,,,,,,,299.990173339844,299.997406005859,13333.07421875,13333.07421875,47.3491016237069,5.2639910038354,13.0539798736572,27,1,0,0,1,0.29022216796875,40.0782012939453,1,1,1,299.997406005859,0,299.993789672852,,,,,,,,,,,,,,,,,,,,,,,,,,,,,,,,,
,3832411056.55018,300.036987304687,9999.494140625,0.000271247616311621,4.04130025460806E-8,1,2,13.4005146026611,5.00566843003839,33.100001513958,0.362007040129054,0.0535220738351032,1,2.13305675740447E-6,,,,,,,,,,,,,,,,,,,,,300.036956787109,300.037017822266,9999.494140625,9999.494140625,47.35613628038,5.26365187629983,13.1370363235474,27,1,0,0,1,0.278701782226562,40.0782012939453,1,1,1,300.037017822266,0,300.036987304687,,,,,,,,,,,,,,,,,,,,,,,,,,,,,,,,,
,3832411080.2709,300.036163330078,7894.4775390625,0.000212770157150012,2.97714712856678E-8,1,2,13.4005146026611,5.00564770721249,33.100001513958,0.283999125520228,0.0417135171263685,1,1.47136852285537E-6,,,,,,,,,,,,,,,,,,,,,300.035705566406,300.03662109375,7894.4775390625,7894.4775390625,47.3565270946396,5.26405192474487,13.1501169204712,27,1,0,0,1,0.274887084960938,40.0782012939453,1,1,1,300.03662109375,0,300.036163330078,,,,,,,,,,,,,,,,,,,,,,,,,,,,,,,,,
,3832411103.33971,299.904571533203,5789.22314453125,0.000154428952158258,2.42323317236132E-8,1,2,13.4005146026611,5.00567734781647,33.100001513958,0.206144402355197,0.0301639080122254,1,9.84033554166182E-7,,,,,,,,,,,,,,,,,,,,,299.896667480469,299.912475585937,5789.22314453125,5789.22314453125,47.4663459015916,5.26380793219481,13.1265249252319,27,1,0,0,1,0.275039672851562,40.0782012939453,1,1,1,299.896667480469,0,299.904571533203,,,,,,,,,,,,,,,,,,,,,,,,,,,,,,,,,
,3832411126.58647,299.798156738281,3683.7578125,9.61151970423492E-5,2.25981038275079E-8,1,2,13.4005146026611,5.00564969852889,33.100001513958,0.128318055238665,0.0186549236730759,1,5.2362488378681E-7,,,,,,,,,,,,,,,,,,,,,299.798034667969,299.798278808594,3683.7578125,3683.7578125,47.3580903516781,5.26382338678047,13.1081972122192,27,1,0,0,1,0.286331176757813,40.0782012939453,1,1,1,299.798278808594,0,299.798156738281,,,,,,,,,,,,,,,,,,,,,,,,,,,,,,,,,
,3832411150.26907,299.826187133789,1578.76574707031,3.82503294542572E-5,2.29730235214638E-8,1,2,13.4005146026611,5.00565274799701,33.100001513958,0.0510922139864137,0.00723600457695097,1,6.76879196959419E-8,,,,,,,,,,,,,,,,,,,,,299.824554443359,299.827819824219,1578.76574707031,1578.76574707031,47.3491016237069,5.26372630722695,13.0873508453369,26,1,68,0,0,0.2899169921875,40.0782012939453,1,1,1,299.827819824219,0,299.826187133789,,,,,,,,,,,,,,,,,,,,,,,,,,,,,,,,,
,3832411175.53909,299.899673461914,-525.83984375,-1.19065660793881E-5,2.71283610424421E-8,1,2,13.4005146026611,5.0056496194444,33.100001513958,-0.015859034408197,-0.00257383926377476,1,-2.61640320874008E-7,,,,,,,,,,,,,,,,,,,,,299.897094726562,299.902252197266,-525.83984375,-525.83984375,47.3432394098127,5.26434897076698,13.0794067382812,27,1,0,0,1,0.283203125,40.0782012939453,1,1,1,299.902252197266,0,299.899673461914,,,,,,,,,,,,,,,,,,,,,,,,,,,,,,,,,
,3832411197.10047,299.923599243164,-2631.28051757813,-6.82384643965498E-5,2.13542259159597E-8,1,2,13.4005146026611,5.00552943934924,33.100001513958,-0.091052616348647,-0.0135712625522057,1,-6.16772641666248E-7,,,,,,,,,,,,,,,,,,,,,299.923065185547,299.924133300781,-2631.28051757813,-2631.28051757813,47.3686423366877,5.26512387840708,13.1045150756836,27,1,0,0,1,0.283584594726562,40.0782012939453,1,1,1,299.924133300781,0,299.923599243164,,,,,,,,,,,,,,,,,,,,,,,,,,,,,,,,,
,3832411219.71654,299.942413330078,-4736.62158203125,-0.000126169061896778,2.91841908302095E-8,1,2,13.4005146026611,5.00557290547929,33.100001513958,-0.168354446736278,-0.0250834338839321,1,-1.13337110052352E-6,,,,,,,,,,,,,,,,,,,,,299.940948486328,299.943878173828,-4736.62158203125,-4736.62158203125,47.42726447563,5.26445591411162,13.1073560714722,27,1,0,0,1,0.27435302734375,40.0782012939453,1,1,1,299.943878173828,0,299.942413330078,,,,,,,,,,,,,,,,,,,,,,,,,,,,,,,,,
,3832411240.97374,299.971603393555,-6841.7880859375,-0.000184410375500214,3.14848302309996E-8,1,2,13.4005146026611,5.00560268538362,33.100001513958,-0.246082222123131,-0.0365830030649992,1,-1.59699005072217E-6,,,,,,,,,,,,,,,,,,,,,299.970825195313,299.972381591797,-6841.7880859375,-6841.7880859375,47.3444118525915,5.26422923963196,13.1060314178467,27,1,0,0,1,0.276031494140625,40.0782012939453,1,1,1,299.972381591797,0,299.971603393555,,,,,,,,,,,,,,,,,,,,,,,,,,,,,,,,,
,3832411273.59701,300.001754760742,-8947.12890625,-0.000242782914068571,3.18968817774609E-8,1,2,13.4005146026611,5.0055458132679,33.100001513958,-0.323955782446137,-0.0482715900293925,1,-2.18445060532633E-6,,,,,,,,,,,,,,,,,,,,,300.001708984375,300.001800537109,-8947.12890625,-8947.12890625,47.41710330488,5.26465954455458,13.0977258682251,27,1,0,0,1,0.284042358398438,40.0782012939453,1,1,1,300.001708984375,0,300.001754760742,,,,,,,,,,,,,,,,,,,,,,,,,,,,,,,,,
,3832411306.96779,300.053070068359,-11999.57421875,-0.000327630937252831,4.86155897822262E-8,1,2,13.4005146026611,5.00558423586035,33.100001513958,-0.437230514346781,-0.0647579171310922,1,-2.66018698001542E-6,,,,,,,,,,,,,,,,,,,,,300.053070068359,300.053070068359,-11999.57421875,-11999.57421875,47.3604352372358,5.26461422316936,13.0957508087158,27,1,0,0,1,0.275192260742187,40.0782012939453,1,1,1,300.053070068359,0,300.053070068359,,,,,,,,,,,,,,,,,,,,,,,,,,,,,,,,,
,3832411331.26824,300.078460693359,-14999.5400390625,-0.000410966939128303,8.62753689937196E-8,1,2,13.4005146026611,5.00559706488078,33.100001513958,-0.548385702487706,-0.0816620805770396,1,-3.66024461255585E-6,,,,,,,,,,,,,,,,,,,,,300.076171875,300.080749511719,-14999.5400390625,-14999.5400390625,47.3725504792839,5.26412588660581,13.0937385559082,27,1,0,0,1,0.274429321289062,40.0782012939453,1,1,1,300.080749511719,0,300.078460693359,,,,,,,,,,,,,,,,,,,,,,,,,,,,,,,,,
,3832411359.12894,300.135848999023,-19999.810546875,-0.000550103545736155,5.2110330289127E-8,1,2,13.4005146026611,5.00554058901495,33.100001513958,-0.734077193072762,-0.109008647655937,1,-4.67551380302817E-6,,,,,,,,,,,,,,,,,,,,,300.130126953125,300.141571044922,-19999.810546875,-19999.810546875,47.3221354397935,5.26442696406443,13.0849056243896,27,1,0,0,1,0.28289794921875,40.0782012939453,1,1,1,300.141571044922,0,300.135848999023,,,,,,,,,,,,,,,,,,,,,,,,,,,,,,,,,
,3832411397.90342,300.193969726562,-25555.408203125,-0.000704731114069334,1.5079580776832E-7,1,2,13.4005146026611,5.0055514135067,33.100001513958,-0.940367767838646,-0.140026147066569,1,-6.27121510702414E-6,,,,,,,,,,,,,,,,,,,,,300.191650390625,300.1962890625,-25555.408203125,-25555.408203125,47.2666398149281,5.26452243124857,13.0568981170654,26,1,68,0,0,0.282821655273438,39.5894432067871,1,1,1,300.191650390625,0,300.193969726562,,,,,,,,,,,,,,,,,,,,,,,,,,,,,,,,,
,3832411453.08313,300.074981689453,-43332.9765625,-0.00119989545264142,1.91356356547014E-7,1,2,13.4005146026611,5.00558278268707,33.100001513958,-1.60112899528999,-0.238285268014924,1,-1.05807587610575E-5,,,,,,,,,,,,,,,,,,,,,300.074981689453,300.074981689453,-43332.9765625,-43332.9765625,47.2127074471012,5.2640172798958,13.038498878479,27,1,0,0,1,0.27557373046875,40.0782012939453,1,1,1,300.074981689453,0,300.074981689453,,,,,,,,,,,,,,,,,,,,,,,,,,,,,,,,,
,3832411510.809,300.017715454102,-61110.734375,-0.00169412811297573,2.21157632468403E-7,1,2,13.4005146026611,5.00558681825952,33.100001513958,-2.26105127506179,-0.333427369188232,10,-1.26881614940632E-5,,,,,,,,,,,,,,,,,,,,,300.017059326172,300.018371582031,-61110.734375,-61110.734375,47.1619015933511,5.26362625909392,13.0131702423096,27,1,0,0,1,0.282974243164062,40.0782012939453,1,1,1,300.017059326172,0,300.017715454102,,,,,,,,,,,,,,,,,,,,,,,,,,,,,,,,,
,3832411557.8758,300.010208129883,-61110.74609375,-0.00169403549471253,2.04977276447665E-7,1,2,13.4005146026611,5.00552533052904,33.100001513958,-2.26096943251789,-0.332833187077695,10,-1.22605621760229E-5,,,,,,,,,,,,,,,,,,,,,300.009643554687,300.010772705078,-61110.74609375,-61110.74609375,47.1341537809185,5.26366163821451,12.9955673217773,27,1,0,0,1,0.276260375976562,40.0782012939453,1,1,1,300.009643554687,0,300.010208129883,,,,,,,,,,,,,,,,,,,,,,,,,,,,,,,,,
,3832411607.07544,299.986312866211,-43333.1015625,-0.00120065953925231,1.78456950471919E-7,1,2,13.4005146026611,5.00551945944101,33.100001513958,-1.6025385053612,-0.235445964366063,10,-8.35180416084696E-6,,,,,,,,,,,,,,,,,,,,,299.986297607422,299.986328125,-43333.1015625,-43333.1015625,47.2857897136492,5.26394360446722,12.9776792526245,27,1,0,0,1,0.275497436523438,40.0782012939453,1,1,1,299.986297607422,0,299.986312866211,,,,,,,,,,,,,,,,,,,,,,,,,,,,,,,,,
,3832411652.66514,299.994918823242,-25555.271484375,-0.000705352365584304,1.13397088128599E-7,1,2,13.4005146026611,5.00552133894671,33.100001513958,-0.941482635985625,-0.138048435733528,10,-4.70490583322764E-6,,,,,,,,,,,,,,,,,,,,,299.994476318359,299.995361328125,-25555.271484375,-25555.271484375,47.3338598675819,5.2644150646765,12.9819860458374,27,1,0,0,1,0.27557373046875,40.0782012939453,1,1,1,299.994476318359,0,299.994918823242,,,,,,,,,,,,,,,,,,,,,,,,,,,,,,,,,
,3832411693.6282,300.013244628906,-19999.63671875,-0.000550307459741949,8.89184055021539E-8,1,2,13.4005146026611,5.00551964218252,33.100001513958,-0.734540520180757,-0.107650797832572,10,-3.63112559436683E-6,,,,,,,,,,,,,,,,,,,,,300.013244628906,300.013244628906,-19999.63671875,-19999.63671875,47.3487108094473,5.26462068812911,12.9633092880249,27,1,0,0,1,0.275802612304687,40.0782012939453,1,1,1,300.013244628906,0,300.013244628906,,,,,,,,,,,,,,,,,,,,,,,,,,,,,,,,,
,3832411725.28135,300.034774780273,-14999.7138671875,-0.000410711536568833,4.80710704095986E-8,1,2,13.4005146026611,5.00551694089383,33.100001513958,-0.548095883647038,-0.081159105829735,1,-3.32081910540346E-6,,,,,,,,,,,,,,,,,,,,,300.033752441406,300.035797119141,-14999.7138671875,-14999.7138671875,47.3084569407069,5.26464203649265,12.9543628692627,27,1,0,0,1,0.2838134765625,40.0782012939453,1,1,1,300.033752441406,0,300.034774780273,,,,,,,,,,,,,,,,,,,,,,,,,,,,,,,,,
,3832411755.26084,300.045150756836,-9999.505859375,-0.000271433424557335,4.33175337425764E-8,1,2,13.4005146026611,5.00546189794524,33.100001513958,-0.36225529049332,-0.0534076029913663,1,-2.02365484646613E-6,,,,,,,,,,,,,,,,,,,,,300.045104980469,300.045196533203,-9999.505859375,-9999.505859375,47.32565276813,5.26494264113503,12.9359302520752,27,1,0,0,1,0.283126831054687,40.0782012939453,1,1,1,300.045196533203,0,300.045150756836,,,,,,,,,,,,,,,,,,,,,,,,,,,,,,,,,
,3832411789.73793,300.067398071289,-8946.966796875,-0.000242066855764655,2.94822431081005E-8,1,2,13.4005146026611,5.00550081035936,33.100001513958,-0.323058195920368,-0.0476862621353561,1,-1.84689818871944E-6,,,,,,,,,,,,,,,,,,,,,300.066192626953,300.068603515625,-8946.966796875,-8946.966796875,47.3698147794665,5.26513660580622,12.9399251937866,27,1,0,0,1,0.275115966796875,39.5894432067871,1,1,1,300.066192626953,0,300.067398071289,,,,,,,,,,,,,,,,,,,,,,,,,,,,,,,,,
,3832411813.42741,299.910339355469,-6841.7509765625,-0.000183695519956312,3.39974113867555E-8,1,2,13.4005146026611,5.00545684887503,33.100001513958,-0.245192000139592,-0.0359143078763556,1,-1.19750987344676E-6,,,,,,,,,,,,,,,,,,,,,299.906799316406,299.913879394531,-6841.7509765625,-6841.7509765625,47.3362047531396,5.26491028287679,12.9066944122314,27,1,0,0,1,0.275955200195313,40.0782012939453,1,1,1,299.906799316406,0,299.910339355469,,,,,,,,,,,,,,,,,,,,,,,,,,,,,,,,,
,3832411838.70596,299.804107666016,-4736.6337890625,-0.000125328895489731,2.10548176996435E-8,1,2,13.4005146026611,5.00547237591127,33.100001513958,-0.167268809829877,-0.0246293743765093,1,-9.11494679531139E-7,,,,,,,,,,,,,,,,,,,,,299.803283691406,299.804931640625,-4736.6337890625,-4736.6337890625,47.351055695005,5.2648760907051,12.9135475158691,27,1,0,0,1,0.275039672851562,39.5894432067871,1,1,1,299.803283691406,0,299.804107666016,,,,,,,,,,,,,,,,,,,,,,,,,,,,,,,,,
,3832411873.58549,299.759948730469,-2631.23071289062,-6.70796981982765E-5,1.37833989293439E-8,1,2,13.4005146026611,5.00542789408728,33.100001513958,-0.0895281991646003,-0.0131670582935276,1,-4.76522765835078E-7,,,,,,,,,,,,,,,,,,,,,299.759948730469,299.759948730469,-2631.23071289062,-2631.23071289062,47.3076753121877,5.26517994870987,12.8997745513916,27,1,0,0,1,0.287551879882813,39.5894432067871,1,1,1,299.759948730469,0,299.759948730469,,,,,,,,,,,,,,,,,,,,,,,,,,,,,,,,,
,3832411894.44322,299.824417114258,-526.076599121094,-1.04423869581267E-5,3.11360073177535E-8,1,2,13.4005146026611,5.00543819256222,33.100001513958,-0.013970176635054,-0.00181256539341039,1,1.03346565031972E-7,,,,,,,,,,,,,,,,,,,,,299.821105957031,299.827728271484,-526.076599121094,-526.076599121094,47.3432394098127,5.26515058570061,12.9091262817383,27,1,0,0,1,0.274658203125,40.0782012939453,1,1,1,299.827728271484,0,299.824417114258,,,,,,,,,,,,,,,,,,,,,,,,,,,,,,,,,
,3832411916.18452,299.885528564453,1578.65368652344,3.97497979453756E-5,2.87110620834172E-8,1,2,13.4005146026611,5.00545711441664,33.100001513958,0.0530193044999042,0.00804107850461131,1,4.60923049179889E-7,,,,,,,,,,,,,,,,,,,,,299.883880615234,299.887176513672,1578.65368652344,1578.65368652344,47.3236986968319,5.26446738640052,12.9085655212402,27,1,0,0,1,0.284194946289062,40.0782012939453,1,1,1,299.883880615234,0,299.885528564453,,,,,,,,,,,,,,,,,,,,,,,,,,,,,,,,,
,3832411939.16384,299.91227722168,3683.79541015625,9.72706644252937E-5,1.91450634181929E-8,1,2,13.4005146026611,5.00548500882197,33.100001513958,0.129807336570687,0.0192178880262654,1,7.84073527264078E-7,,,,,,,,,,,,,,,,,,,,,299.909515380859,299.9150390625,3683.79541015625,3683.79541015625,47.2896978562454,5.26442289237521,12.8997755050659,27,1,0,0,1,0.27679443359375,39.5894432067871,1,1,1,299.9150390625,0,299.91227722168,,,,,,,,,,,,,,,,,,,,,,,,,,,,,,,,,
,3832411964.14875,299.956848144531,5789.0615234375,0.000155387025863667,2.76910066297801E-8,1,2,13.4005146026611,5.00549565798125,33.100001513958,0.207344773357183,0.0308376518494614,1,1.35549171314461E-6,,,,,,,,,,,,,,,,,,,,,299.955078125,299.958618164063,5789.0615234375,5789.0615234375,47.3147099688608,5.26396116878284,12.8905668258667,27,1,0,0,1,0.283737182617187,39.5894432067871,1,1,1,299.958618164063,0,299.956848144531,,,,,,,,,,,,,,,,,,,,,,,,,,,,,,,,,
,3832411988.28329,300.013153076172,7894.45263671875,0.000213857262913913,3.35941008863628E-8,1,2,13.4005146026611,5.00545531423755,33.100001513958,0.285386895983528,0.0422696112470673,1,1.73724941551102E-6,,,,,,,,,,,,,,,,,,,,,300.0087890625,300.017517089844,7894.45263671875,7894.45263671875,47.3006406555146,5.26418425663519,12.8939085006714,27,1,0,0,1,0.274810791015625,39.5894432067871,1,1,1,300.017517089844,0,300.013153076172,,,,,,,,,,,,,,,,,,,,,,,,,,,,,,,,,
,3832412011.54949,300.089248657227,9999.7802734375,0.000272202732789225,5.11982226798561E-8,1,2,13.4005146026611,5.00544376541167,33.100001513958,0.363209066837944,0.0540675234885969,1,2.4102441705448E-6,,,,,,,,,,,,,,,,,,,,,300.088745117188,300.089752197266,9999.7802734375,9999.7802734375,47.3037671695915,5.26435573783954,12.9004907608032,27,1,0,0,1,0.28289794921875,40.0782012939453,1,1,1,300.089752197266,0,300.089248657227,,,,,,,,,,,,,,,,,,,,,,,,,,,,,,,,,
,3832412044.5793,300.056427001953,13333.048828125,0.000365013567610379,3.86434150408105E-8,1,2,13.4005146026611,5.00544628707546,33.100001513958,0.487044553752115,0.0725411793284857,1,3.26095795811521E-6,,,,,,,,,,,,,,,,,,,,,300.053680419922,300.059173583984,13333.048828125,13333.048828125,47.3623893085339,5.26419309206166,12.8814525604248,27,1,0,0,1,0.276870727539062,40.0782012939453,1,1,1,300.053680419922,0,300.056427001953,,,,,,,,,,,,,,,,,,,,,,,,,,,,,,,,,
,3832412070.40643,300.040679931641,17777.294921875,0.000488890915797088,5.96063081722738E-8,1,2,13.4005146026611,5.00539741538203,33.100001513958,0.652361742321139,0.0969155942772082,1,4.1856708284752E-6,,,,,,,,,,,,,,,,,,,,,300.039916992188,300.041442871094,17777.294921875,17777.294921875,47.3705964079858,5.26490342927601,12.8804893493652,27,1,0,0,1,0.27618408203125,39.5894432067871,1,1,1,300.039916992188,0,300.040679931641,,,,,,,,,,,,,,,,,,,,,,,,,,,,,,,,,
,3832412114.56736,300.019897460937,21999.48046875,0.000606744157131726,8.49897752168037E-8,1,2,13.4005146026611,5.00541066079402,33.100001513958,0.809650535131113,0.120093189811495,1,5.05579139809866E-6,,,,,,,,,,,,,,,,,,,,,300.019897460937,300.019897460937,21999.48046875,21999.48046875,47.3080661264473,5.26452631718306,12.8743190765381,27,1,0,0,1,0.27862548828125,40.0782012939453,1,1,1,300.019897460937,0,300.019897460937,,,,,,,,,,,,,,,,,,,,,,,,,,,,,,,,,
,3832412150.92428,300.014511108398,34999.734375,0.000968934834948492,1.62856213404896E-7,1,2,13.4005146026611,5.00538334938948,33.100001513958,1.29284513628716,0.192564468658298,1,8.66073295381958E-6,,,,,,,,,,,,,,,,,,,,,300.013580322266,300.015441894531,34999.734375,34999.734375,47.2474899162069,5.26500014476998,12.8630857467651,26,1,68,0,0,0.276718139648438,39.5894432067871,1,1,1,300.013580322266,0,300.014511108398,,,,,,,,,,,,,,,,,,,,,,,,,,,,,,,,,
,3832412228.7944,300.010986328125,58332.89453125,0.00161793431999004,2.66459188593688E-7,1,2,13.4005146026611,5.00522711512185,33.100001513958,2.15924118507113,0.317732151229744,10,1.16175073648095E-5,,,,,,,,,,,,,,,,,,,,,300.010986328125,300.010986328125,58332.89453125,58332.89453125,47.1513496083415,5.26498440251319,12.8597364425659,27,1,0,0,1,0.28289794921875,39.5894432067871,1,1,1,300.010986328125,0,300.010986328125,,,,,,,,,,,,,,,,,,,,,,,,,,,,,,,,,
,3832412281.8187,300.008880615234,58333.08984375,0.00161776171431282,2.13879783984607E-7,1,2,13.4005146026611,5.0052655260532,33.110000193119,2.15909027961913,0.317295427522924,10,1.13122372446851E-5,,,,,,,,,,,,,,,,,,,,,300.0087890625,300.008972167969,58333.08984375,58333.08984375,47.1646372931684,5.26505659832398,12.849817276001,27,1,0,0,1,0.279769897460938,39.5894432067871,1,1,1,300.0087890625,0,300.008880615234,,,,,,,,,,,,,,,,,,,,,,,,,,,,,,,,,
,3832412336.7463,300.007995605469,34999.72265625,0.000969055806418863,9.23165580231745E-8,1,2,13.4005146026611,5.00528506443077,33.100001513958,1.293337775033,0.189966097730025,10,6.70269732643114E-6,,,,,,,,,,,,,,,,,,,,,300.007965087891,300.008026123047,34999.72265625,34999.72265625,47.2736744716012,5.26468791215235,12.8518848419189,27,1,0,0,1,0.276107788085938,40.0782012939453,1,1,1,300.008026123047,0,300.007995605469,,,,,,,,,,,,,,,,,,,,,,,,,,,,,,,,,
,3832412377.90505,299.999893188477,21999.505859375,0.000606455474021407,8.91276930277911E-8,1,2,13.4005146026611,5.00526748381042,33.100001513958,0.809420609220174,0.11869426718232,10,4.05251354700297E-6,,,,,,,,,,,,,,,,,,,,,299.998168945313,300.001617431641,21999.505859375,21999.505859375,47.3729412935435,5.26512133926666,12.8395195007324,27,1,0,0,1,0.276031494140625,40.0782012939453,1,1,1,299.998168945313,0,299.999893188477,,,,,,,,,,,,,,,,,,,,,,,,,,,,,,,,,