File: SI Fig S11-13 SQUID all/Michaela_La_Hyst300K_00001.dat
[Header]
; MPMS3 Data File (default extension .dat)
; Copyright (c) 2007, Quantum Design, Inc. All rights reserved.
TITLE,
FILEOPENTIME,3834151807.6083,06/29/2021,6:11 pm
BYAPP,MPMS3 w/ AC,1.0,1.1
INFO,MPMS3 Measurement Release 1.1.16 Build 424, MultiVu Release 2.3.4.19,APPNAME
INFO,Linear Motor Servo Controller,MOTOR_MODULE_NAME
INFO,3101-100 E1,MOTOR_HW_VERSION
INFO,MMC211,MOTOR_SERIAL_NUMBER
INFO,01.04.28,MOTOR_SOFTWARE_VERSION
INFO,Quantum Design Squid Module,SQUID_MODULE_NAME
INFO,3101-501 B0,SQUID_HW_VERSION
INFO,SQM059,SQUID_SERIAL_NUMBER
INFO,01.03.04,SQUID_SOFTWARE_VERSION
INFO,SQUID AC,AC_MODULE_NAME
INFO,3101-401 F1,AC_HW_VERSION
INFO,SAC057,AC_SERIAL_NUMBER
INFO,SQUID AC 00.95.07,AC_SOFTWARE_VERSION
INFO,TCIXXX,COIL_SERIAL_NUMBER
INFO,0,MOMENT_UNITS
INFO,La_02,SAMPLE_MATERIAL
INFO,La_02,SAMPLE_COMMENT
INFO,0.07,SAMPLE_MASS
INFO,,SAMPLE_VOLUME
INFO,,SAMPLE_MOLECULAR_WEIGHT
INFO,,SAMPLE_SIZE
INFO,,SAMPLE_SHAPE
INFO,Straw,SAMPLE_HOLDER
INFO,Standard,SAMPLE_HOLDER_DETAIL
INFO,58.69,SAMPLE_OFFSET
DATATYPE,COMMENT,1
DATATYPE,TIME,2
STARTUPAXIS,X,2
STARTUPAXIS,Y1,5
FIELDGROUP, VSM,2,3,4,5,6,8,9,10,11,14,15
FIELDGROUP, DC, 2,3,4,14,56,57,58,59,60,61,62,63,64,65,66,67,68,69
FIELDGROUP, AC, 2,3,4,11,16,17,18,19,20,21,22,23,24,25,26,27,28,29,30
STARTUPGROUP, All
[Data]
Comment,Time Stamp (sec),Temperature (K),Magnetic Field (Oe),Moment (emu),M. Std. Err. (emu),Transport Action,Averaging Time (sec),Frequency (Hz),Peak Amplitude (mm),Center Position (mm),Lockin Signal' (V),Lockin Signal (V),Range,M. Quad. Signal (emu),AC Moment (emu),AC M. Std Err. (emu),AC Phase (deg),AC Phase Std. Err. (deg),AC Susceptibility (emu/Oe),AC Suscept. Std Err. (emu/Oe),AC X' (emu/Oe),AC X' Std Err. (emu/Oe),AC X'' (emu/Oe),AC X'' Std Err. (emu/Oe),AC Drive (Oe),AC Frequency (Hz),AC Averaging Time (sec),AC Cycles,AC Range,AC Measure Type,AC Signal' (V),AC Signal'' (V),AC Trim Coil Ratio,AC Trim Coil Phase,Min. Temperature (K),Max. Temperature (K),Min. Field (Oe),Max. Field (Oe),Mass (grams),Motor Lag (deg),Pressure (Torr),Measure Count,Measurement Number,SQUID Status (code),Motor Status (code),Measure Status (code),Motor Current (amps),Motor Temp. (C),Temp. Status (code),Field Status (code),Chamber Status (code),Chamber Temp (K),Redirection State,Average Temp (K),Rotation Angle (deg),Rotator state,DC Moment Fixed Ctr (emu),DC Moment Err Fixed Ctr (emu),DC Moment Free Ctr (emu),DC Moment Err Free Ctr (emu),DC Fixed Fit,DC Free Fit,DC Calculated Center (mm),DC Calculated Center Err (mm),DC Scan Length (mm),DC Scan Time (s),DC Number of Points,DC Squid Drift,DC Min V (V),DC Max V (V),DC Scans per Measure,Map 01,Map 02,Map 03,Map 04,Map 05,Map 06,Map 07,Map 08,Map 09,Map 10,Map 11,Map 12,Map 13,Map 14,Map 15,Map 16
,3834151831.2244,299.900146484375,0.211866363883018,-2.13740691117753E-6,1.19476813594481E-8,1,2,13.4005146026611,4.99546608376515,28.3899996429682,-0.00284467597895709,-0.000420237184741075,1,-1.65561301370556E-8,,,,,,,,,,,,,,,,,,,,,299.900146484375,299.900146484375,0.211866363883018,0.211866363883018,46.6331299000915,5.25466326783611,7.98968648910522,27,1,0,0,1,0.289382934570313,34.7018585205078,1,1,1,299.900146484375,0,299.900146484375,,,,,,,,,,,,,,,,,,,,,,,,,,,,,,,,,
,3834151852.99769,299.914993286133,1578.6162109375,-1.48687256064122E-5,3.90716604371547E-8,1,2,13.4005146026611,4.9957511879903,28.3899996429682,-0.0198500776626881,-0.00249635022273333,1,2.05463636992345E-7,,,,,,,,,,,,,,,,,,,,,299.913879394531,299.916107177734,1578.6162109375,1578.6162109375,46.692533667553,5.25755230231493,8.86626625061035,25,1,68,0,0,0.289688110351562,35.190616607666,1,1,1,299.913604736328,0,299.914993286133,,,,,,,,,,,,,,,,,,,,,,,,,,,,,,,,,
,3834151878.94738,299.930511474609,3684.09423828125,-4.10047497708355E-5,3.75104959240602E-8,1,2,13.4005146026611,4.99589830122716,28.3899996429682,-0.0545816346317322,-0.0080491688616303,1,-3.07291044706395E-7,,,,,,,,,,,,,,,,,,,,,299.929260253906,299.931762695313,3684.09423828125,3684.09423828125,46.5838873033799,5.25625236458323,9.64397239685059,27,1,0,0,1,0.2813720703125,35.6793746948242,1,1,1,299.931762695313,0,299.930511474609,,,,,,,,,,,,,,,,,,,,,,,,,,,,,,,,,
,3834151904.23058,299.958404541016,5789.23583984375,-6.77232949617706E-5,5.33130129972169E-8,1,2,13.4005146026611,4.9959586461184,28.3899996429682,-0.0901588072914278,-0.0132191915356949,1,-4.51231858093831E-7,,,,,,,,,,,,,,,,,,,,,299.957611083984,299.959197998047,5789.23583984375,5789.23583984375,46.6073361589569,5.2569101646959,10.1556024551392,27,1,0,0,1,0.290298461914063,35.6793746948242,1,1,1,299.959197998047,0,299.958404541016,,,,,,,,,,,,,,,,,,,,,,,,,,,,,,,,,
,3834151927.83614,299.978530883789,7894.5146484375,-9.45376264206895E-5,6.83731890145416E-8,1,2,13.4005146026611,4.99599787564277,28.3899996429682,-0.125836148644584,-0.0186068039449373,1,-7.45020917951885E-7,,,,,,,,,,,,,,,,,,,,,299.977813720703,299.979248046875,7894.5146484375,7894.5146484375,46.7152008946107,5.25714438128766,10.5787696838379,27,1,0,0,1,0.28900146484375,35.6793746948242,1,1,1,299.979248046875,0,299.978530883789,,,,,,,,,,,,,,,,,,,,,,,,,,,,,,,,,
,3834151962.65258,299.960388183594,9999.85546875,-0.000121362951049029,4.57145677484874E-8,1,2,13.4005146026611,4.99599432073737,28.3899996429682,-0.161539336247534,-0.0239081547364337,1,-9.72662231295801E-7,,,,,,,,,,,,,,,,,,,,,299.960388183594,299.960388183594,9999.85546875,9999.85546875,46.6983958814472,5.25676097254837,11.0189695358276,27,1,0,0,1,0.289382934570313,35.6793746948242,1,1,1,299.960388183594,0,299.960388183594,,,,,,,,,,,,,,,,,,,,,,,,,,,,,,,,,
,3834151994.54541,299.958358764648,13333.0869140625,-0.00016397924542373,5.66531685972413E-8,1,2,13.4005146026611,4.99602016317363,28.3899996429682,-0.218284599454771,-0.032163592571353,1,-1.20908856857899E-6,,,,,,,,,,,,,,,,,,,,,299.958160400391,299.958557128906,13333.0869140625,13333.0869140625,46.6542338701107,5.25663966119328,11.3726997375488,27,1,0,0,1,0.290298461914063,35.6793746948242,1,1,1,299.958557128906,0,299.958358764648,,,,,,,,,,,,,,,,,,,,,,,,,,,,,,,,,
,3834152037.69596,299.980560302734,17777.60546875,-0.000220111566995379,5.42799200402872E-8,1,2,13.4005146026611,4.99601778954197,28.3899996429682,-0.292964634684636,-0.0434708023245851,1,-1.84601049665236E-6,,,,,,,,,,,,,,,,,,,,,299.98046875,299.980651855469,17777.60546875,17777.60546875,46.6514981702934,5.25676160804754,11.7255239486694,27,1,0,0,1,0.290756225585937,35.6793746948242,1,1,1,299.980651855469,0,299.980560302734,,,,,,,,,,,,,,,,,,,,,,,,,,,,,,,,,
,3834152072.06437,299.993133544922,21999.580078125,-0.000273912733151461,5.71923922930413E-8,1,2,13.4005146026611,4.99600449698668,28.3899996429682,-0.364559088343046,-0.0541863367623535,1,-2.36499206594506E-6,,,,,,,,,,,,,,,,,,,,,299.993133544922,299.993133544922,21999.580078125,21999.580078125,46.697614252928,5.25677597698585,11.9519424438477,27,1,0,0,1,0.290298461914063,35.6793746948242,1,1,1,299.993133544922,0,299.993133544922,,,,,,,,,,,,,,,,,,,,,,,,,,,,,,,,,
,3834152108.28353,299.998596191406,34999.72265625,-0.000440201029093027,1.21618920456175E-7,1,2,13.4005146026611,4.99606739762893,28.3899996429682,-0.585856470647037,-0.0873056428434354,1,-3.96741088460177E-6,,,,,,,,,,,,,,,,,,,,,299.998565673828,299.998626708984,34999.72265625,34999.72265625,46.6456359563992,5.25709573232627,12.1809091567993,27,1,0,0,1,0.290298461914063,35.6793746948242,1,1,1,299.998565673828,0,299.998596191406,,,,,,,,,,,,,,,,,,,,,,,,,,,,,,,,,
,3834152159.99863,300.000930786133,58332.85546875,-0.000738349263898631,1.63073316569082E-7,1,2,13.4005146026611,4.99608010690664,28.3899996429682,-0.982600794259262,-0.14686590470844,1,-6.97544146884263E-6,,,,,,,,,,,,,,,,,,,,,300.000518798828,300.001342773438,58332.85546875,58332.85546875,46.4134922861876,5.2566505493809,12.4315795898438,27,1,0,0,1,0.2899169921875,36.1681327819824,1,1,1,300.000518798828,0,300.000930786133,,,,,,,,,,,,,,,,,,,,,,,,,,,,,,,,,
,3834152211.71963,299.976867675781,58332.98046875,-0.00073699796878478,1.27470914116915E-7,1,2,13.4005146026611,4.99611897571899,28.3899996429682,-0.980779145645721,-0.146840312703233,1,-7.1440027077279E-6,,,,,,,,,,,,,,,,,,,,,299.976623535156,299.977111816406,58332.98046875,58332.98046875,46.4564818547453,5.25612354177866,12.658766746521,27,1,0,0,1,0.288772583007812,36.1681327819824,1,1,1,299.976623535156,0,299.976867675781,,,,,,,,,,,,,,,,,,,,,,,,,,,,,,,,,
,3834152265.61525,299.987762451172,34999.61328125,-0.000437935525432883,1.24773176349925E-7,1,2,13.4005146026611,4.99611825332159,28.3899996429682,-0.582816086755038,-0.087096317181835,1,-4.12618132156135E-6,,,,,,,,,,,,,,,,,,,,,299.987457275391,299.988067626953,34999.61328125,34999.61328125,46.7288793936972,5.25633195082126,12.8603658676147,27,1,0,0,1,0.287094116210938,36.1681327819824,1,1,1,299.987457275391,0,299.987762451172,,,,,,,,,,,,,,,,,,,,,,,,,,,,,,,,,
,3834152306.65431,299.99641418457,21999.666015625,-0.000271624560630788,6.38946173022225E-8,1,2,13.4005146026611,4.99612709427739,28.3899996429682,-0.361488856440465,-0.0539999766496228,1,-2.54371307211528E-6,,,,,,,,,,,,,,,,,,,,,299.995849609375,299.996978759766,21999.666015625,21999.666015625,46.636647228428,5.25612081138874,12.9997205734253,27,1,0,0,1,0.290374755859375,36.1681327819824,1,1,1,299.995849609375,0,299.99641418457,,,,,,,,,,,,,,,,,,,,,,,,,,,,,,,,,
,3834152343.33143,299.987274169922,17777.39453125,-0.000217542680987223,7.68478902886423E-8,1,2,13.4005146026611,4.99610343547484,28.3899996429682,-0.289478715591266,-0.0434906773652213,1,-2.21934537648066E-6,,,,,,,,,,,,,,,,,,,,,299.987213134766,299.987335205078,17777.39453125,17777.39453125,46.702694838303,5.25639494859856,13.1520004272461,27,1,0,0,1,0.287551879882813,36.1681327819824,1,1,1,299.987213134766,0,299.987274169922,,,,,,,,,,,,,,,,,,,,,,,,,,,,,,,,,
,3834152371.17249,299.992874145508,13333.037109375,-0.000160929652983512,5.47689420505028E-8,1,2,13.4005146026611,4.9961280825964,28.3899996429682,-0.214150266171674,-0.0321466677012783,1,-1.62207297535441E-6,,,,,,,,,,,,,,,,,,,,,299.992736816406,299.993011474609,13333.037109375,13333.037109375,46.8089963169184,5.25624401338736,13.2222156524658,27,1,0,0,1,0.288162231445313,36.1681327819824,1,1,1,299.992736816406,0,299.992874145508,,,,,,,,,,,,,,,,,,,,,,,,,,,,,,,,,
,3834152406.9178,299.996307373047,9999.8427734375,-0.000118626134024945,4.13270520309317E-8,1,2,13.4005146026611,4.99611845640626,28.3899996429682,-0.157877809314607,-0.0235420134265525,1,-1.0799572910913E-6,,,,,,,,,,,,,,,,,,,,,299.996307373047,299.996307373047,9999.8427734375,9999.8427734375,46.5365987779665,5.2558797185124,13.3431282043457,27,1,0,0,1,0.290451049804687,36.1681327819824,1,1,1,299.996307373047,0,299.996307373047,,,,,,,,,,,,,,,,,,,,,,,,,,,,,,,,,
,3834152436.01865,299.998428344727,7894.3525390625,-9.17631438445785E-5,4.18995878975401E-8,1,2,13.4005146026611,4.99612789357856,28.3899996429682,-0.122082188147176,-0.0185282930816035,1,-1.07353995230219E-6,,,,,,,,,,,,,,,,,,,,,299.998107910156,299.998748779297,7894.3525390625,7894.3525390625,46.6217962865626,5.25604137136613,13.438289642334,27,1,0,0,1,0.28961181640625,36.1681327819824,1,1,1,299.998748779297,0,299.998428344727,,,,,,,,,,,,,,,,,,,,,,,,,,,,,,,,,
,3834152461.8608,300.016250610352,5789.22314453125,-6.52378479045422E-5,2.98929598759433E-8,1,2,13.4005146026611,4.99611484631275,28.3899996429682,-0.0868153655478118,-0.0130087250964111,1,-6.40387543484294E-7,,,,,,,,,,,,,,,,,,,,,300.015441894531,300.017059326172,5789.22314453125,5789.22314453125,46.7605353487261,5.25596692899437,13.5183668136597,27,1,0,0,1,0.288314819335937,36.1681327819824,1,1,1,300.015441894531,0,300.016250610352,,,,,,,,,,,,,,,,,,,,,,,,,,,,,,,,,
,3834152487.5819,300.026000976562,3683.86987304687,-3.8858174592544E-5,2.61751334138391E-8,1,2,13.4005146026611,4.99612464033738,28.3899996429682,-0.0517109500272603,-0.00774682975280585,1,-3.80172246971073E-7,,,,,,,,,,,,,,,,,,,,,300.025848388672,300.026153564453,3683.86987304687,3683.86987304687,46.6542338701107,5.25593428746198,13.5873470306396,27,1,0,0,1,0.2886962890625,36.6568908691406,1,1,1,300.025848388672,0,300.026000976562,,,,,,,,,,,,,,,,,,,,,,,,,,,,,,,,,
,3834152513.36445,300.024536132812,1578.79064941406,-1.29742635035713E-5,2.71807559314036E-8,1,2,13.4005146026611,4.99610806911078,28.3899996429682,-0.0172317462264279,-0.00282844875899596,1,-3.08455092978464E-7,,,,,,,,,,,,,,,,,,,,,300.023529052734,300.025543212891,1578.79064941406,1578.79064941406,46.7222355512838,5.25553990738915,13.6402282714844,26,1,68,0,0,0.289459228515625,36.6568908691406,1,1,1,300.023529052734,0,300.024536132812,,,,,,,,,,,,,,,,,,,,,,,,,,,,,,,,,
,3834152536.31139,300.021621704102,-526.051696777344,5.55464985095969E-6,2.32087170418551E-8,1,2,13.4005146026611,4.99611167990423,28.3899996429682,0.00740562899560159,0.0010090914598107,1,-1.94138895912173E-8,,,,,,,,,,,,,,,,,,,,,300.02099609375,300.022247314453,-526.051696777344,-526.051696777344,46.6761194686492,5.25569157623425,13.6730298995972,27,1,0,0,1,0.286483764648438,36.1681327819824,1,1,1,300.02099609375,0,300.021621704102,,,,,,,,,,,,,,,,,,,,,,,,,,,,,,,,,
,3834152557.53606,299.878677368164,-2631.36767578125,2.42618814469152E-5,2.40777354522692E-8,1,2,13.4005146026611,4.9961164722616,28.3899996429682,0.0323120514975894,0.0046555472124834,1,1.0129342341248E-7,,,,,,,,,,,,,,,,,,,,,299.871032714844,299.886322021484,-2631.36767578125,-2631.36767578125,46.7155917088703,5.25581145201407,13.6632413864136,27,1,0,0,1,0.289306640625,36.6568908691406,1,1,1,299.871032714844,0,299.878677368164,,,,,,,,,,,,,,,,,,,,,,,,,,,,,,,,,
,3834152583.06033,299.754547119141,-4736.60888671875,4.97973672639033E-5,5.63610707138604E-8,1,2,13.4005146026611,4.99608078460411,28.3899996429682,0.0662892086457884,0.00977306601004901,1,3.71255315284988E-7,,,,,,,,,,,,,,,,,,,,,299.751953125,299.757141113281,-4736.60888671875,-4736.60888671875,46.7257528796203,5.25619781264617,13.664210319519,27,1,0,0,1,0.288772583007812,36.6568908691406,1,1,1,299.751953125,0,299.754547119141,,,,,,,,,,,,,,,,,,,,,,,,,,,,,,,,,
,3834152608.81717,299.790130615234,-6841.712890625,7.59821240067794E-5,2.99059821966851E-8,1,2,13.4005146026611,4.99608111899905,28.3899996429682,0.101139063771003,0.0149602906293628,1,6.02709210634621E-7,,,,,,,,,,,,,,,,,,,,,299.790008544922,299.790252685547,-6841.712890625,-6841.712890625,46.6276585004569,5.25582163344071,13.6694450378418,27,1,0,0,1,0.291061401367188,36.6568908691406,1,1,1,299.790008544922,0,299.790130615234,,,,,,,,,,,,,,,,,,,,,,,,,,,,,,,,,
,3834152634.65126,299.858337402344,-8946.9541015625,0.000102550553338866,3.74622265093311E-8,1,2,13.4005146026611,4.99608894836505,28.3899996429682,0.136504075209552,0.0201933006830508,1,8.14844285386578E-7,,,,,,,,,,,,,,,,,,,,,299.853637695313,299.863037109375,-8946.9541015625,-8946.9541015625,46.7015223955242,5.25584254755318,13.6881160736084,27,1,0,0,1,0.289764404296875,36.6568908691406,1,1,1,299.863037109375,0,299.858337402344,,,,,,,,,,,,,,,,,,,,,,,,,,,,,,,,,
,3834152672.61756,299.962097167969,-11999.599609375,0.000140878461190838,5.17915444057058E-8,1,2,13.4005146026611,4.99609561716114,28.3899996429682,0.187515441480387,0.0277898285928732,1,1.15638722986756E-6,,,,,,,,,,,,,,,,,,,,,299.962097167969,299.962097167969,-11999.599609375,-11999.599609375,46.7066029808992,5.25559937741761,13.7318296432495,27,1,0,0,1,0.290298461914063,36.6568908691406,1,1,1,299.962097167969,0,299.962097167969,,,,,,,,,,,,,,,,,,,,,,,,,,,,,,,,,
,3834152704.20319,300.014953613281,-14999.7900390625,0.000178647987359986,8.64430145150513E-8,1,2,13.4005146026611,4.99613021528433,28.3899996429682,0.237784235539828,0.0352861430331511,1,1.5005776600572E-6,,,,,,,,,,,,,,,,,,,,,300.010009765625,300.019897460937,-14999.7900390625,-14999.7900390625,46.7663975626203,5.25585324157631,13.7529306411743,27,1,0,0,1,0.28900146484375,36.6568908691406,1,1,1,300.019897460937,0,300.014953613281,,,,,,,,,,,,,,,,,,,,,,,,,,,,,,,,,
,3834152742.50865,300.052764892578,-19999.599609375,0.000241205281897467,2.88562055588475E-7,1,2,13.4005146026611,4.99610397938652,28.3899996429682,0.321055771312843,0.0475792690256605,1,1.97898018303405E-6,,,,,,,,,,,,,,,,,,,,,300.052764892578,300.052764892578,-19999.599609375,-19999.599609375,46.6042096448799,5.25586581753741,13.7779092788696,27,1,0,0,1,0.290985107421875,36.6568908691406,1,1,1,300.052764892578,0,300.052764892578,,,,,,,,,,,,,,,,,,,,,,,,,,,,,,,,,
,3834152778.92999,300.033157348633,-25555.18359375,0.000311360584696027,1.01747359922081E-7,1,2,13.4005146026611,4.99609236539415,28.3899996429682,0.414420439920366,0.0615183272441174,1,2.63012289204068E-6,,,,,,,,,,,,,,,,,,,,,300.032196044922,300.034118652344,-25555.18359375,-25555.18359375,46.6538430558511,5.25597005265444,13.7909727096558,27,1,0,0,1,0.287628173828125,36.6568908691406,1,1,1,300.032196044922,0,300.033157348633,,,,,,,,,,,,,,,,,,,,,,,,,,,,,,,,,
,3834152824.97022,300.016403198242,-43332.890625,0.000536089207002849,1.42486314865669E-7,1,2,13.4005146026611,4.99604967068225,28.3899996429682,0.713465002319188,0.106351612090161,1,4.85328143201665E-6,,,,,,,,,,,,,,,,,,,,,300.015655517578,300.017150878906,-43332.890625,-43332.890625,46.5971749882069,5.25578136041771,13.7949123382568,27,1,0,0,1,0.290069580078125,36.6568908691406,1,1,1,300.015655517578,0,300.016403198242,,,,,,,,,,,,,,,,,,,,,,,,,,,,,,,,,
,3834152871.32565,300.007446289063,-61110.8203125,0.000760711493400199,1.89360544358184E-7,1,2,13.4005146026611,4.99608886047678,28.3899996429682,1.01240310308768,0.151027892382907,1,6.97172805147127E-6,,,,,,,,,,,,,,,,,,,,,300.007446289063,300.007446289063,-61110.8203125,-61110.8203125,46.3689394605914,5.25565249650754,13.8084659576416,27,1,0,0,1,0.29083251953125,36.6568908691406,1,1,1,300.007446289063,0,300.007446289063,,,,,,,,,,,,,,,,,,,,,,,,,,,,,,,,,
,3834152917.76649,300.012084960937,-61110.76953125,0.000759892243165998,2.67537924075877E-7,1,2,13.4005146026611,4.99605010747735,28.3899996429682,1.01131042819604,0.150803712991435,1,6.91924856024248E-6,,,,,,,,,,,,,,,,,,,,,300.010833740234,300.013336181641,-61110.76953125,-61110.76953125,46.5971749882069,5.25583581521931,13.8277683258057,27,1,0,0,1,0.288543701171875,36.6568908691406,1,1,1,300.010833740234,0,300.012084960937,,,,,,,,,,,,,,,,,,,,,,,,,,,,,,,,,
,3834152967.2436,299.999786376953,-43333.07421875,0.000534531371698885,3.63489455701981E-7,1,2,13.4005146026611,4.99605639388455,28.3899996429682,0.711399265433324,0.105998214494743,1,4.80575136479486E-6,,,,,,,,,,,,,,,,,,,,,299.998901367188,300.000671386719,-43333.07421875,-43333.07421875,46.6131983728511,5.25632102073989,13.8414030075073,27,1,0,0,1,0.290374755859375,36.6568908691406,1,1,1,299.998901367188,0,299.999786376953,,,,,,,,,,,,,,,,,,,,,,,,,,,,,,,,,
,3834153013.24724,299.996292114258,-25555.4453125,0.000309683293966585,2.83907586845018E-7,1,2,13.4005146026611,4.99605566087882,28.3899996429682,0.412136221635503,0.0615267444718686,1,2.87142567466172E-6,,,,,,,,,,,,,,,,,,,,,299.996063232422,299.996520996094,-25555.4453125,-25555.4453125,46.5631741476203,5.25658779150851,13.8842830657959,26,1,68,0,0,0.2911376953125,36.6568908691406,1,1,1,299.996063232422,0,299.996292114258,,,,,,,,,,,,,,,,,,,,,,,,,,,,,,,,,
,3834153053.98944,299.986297607422,-19999.611328125,0.000239597161708031,1.70523785226575E-7,1,2,13.4005146026611,4.99603262322023,28.3899996429682,0.31888580452929,0.0474273692564999,1,2.0905369989247E-6,,,,,,,,,,,,,,,,,,,,,299.986297607422,299.986297607422,-19999.611328125,-19999.611328125,46.7148100803511,5.25658120870369,13.8839750289917,27,1,0,0,1,0.290298461914063,37.1456527709961,1,1,1,299.986297607422,0,299.986297607422,,,,,,,,,,,,,,,,,,,,,,,,,,,,,,,,,
,3834153080.23887,299.991409301758,-14999.689453125,0.000176525799379429,1.73438738909877E-7,1,2,13.4005146026611,4.99607914854518,28.3899996429682,0.234928593490305,0.0350644224126689,1,1.63129028812946E-6,,,,,,,,,,,,,,,,,,,,,299.990173339844,299.992645263672,-14999.689453125,-14999.689453125,46.7718689622549,5.256531090021,13.9024496078491,27,1,0,0,1,0.289306640625,37.1456527709961,1,1,1,299.990173339844,0,299.991409301758,,,,,,,,,,,,,,,,,,,,,,,,,,,,,,,,,
,3834153106.64106,299.992523193359,-9999.7431640625,0.000113669053626979,9.25845677228378E-8,1,2,13.4005146026611,4.99604934037641,28.3899996429682,0.151242139570915,0.022811696987798,1,1.22534292400066E-6,,,,,,,,,,,,,,,,,,,,,299.992279052734,299.992767333984,-9999.7431640625,-9999.7431640625,46.802352474505,5.25651620550683,13.9270639419556,27,1,0,0,1,0.286331176757813,37.1456527709961,1,1,1,299.992767333984,0,299.992523193359,,,,,,,,,,,,,,,,,,,,,,,,,,,,,,,,,
,3834153139.99419,299.997817993164,-8947.1162109375,0.000100447738367473,1.31286093953291E-7,1,2,13.4005146026611,4.99601420482702,28.3899996429682,0.133670217015072,0.0200082736339994,1,9.70321480614051E-7,,,,,,,,,,,,,,,,,,,,,299.997772216797,299.997863769531,-8947.1162109375,-8947.1162109375,46.778903618928,5.25637445677323,13.9433126449585,27,1,0,0,1,0.288543701171875,37.1456527709961,1,1,1,299.997863769531,0,299.997817993164,,,,,,,,,,,,,,,,,,,,,,,,,,,,,,,,,
,3834153162.97001,299.999618530273,-6841.9130859375,7.40281523067143E-5,3.69670668547832E-8,1,2,13.4005146026611,4.99607197522711,28.3899996429682,0.0984832941053767,0.0149661010486186,1,8.80305362542771E-7,,,,,,,,,,,,,,,,,,,,,299.999298095703,299.999938964844,-6841.9130859375,-6841.9130859375,46.667130740678,5.25677101947212,13.9428329467773,27,1,0,0,1,0.290603637695313,37.1456527709961,1,1,1,299.999298095703,0,299.999618530273,,,,,,,,,,,,,,,,,,,,,,,,,,,,,,,,,
,3834153186.11719,300.029693603516,-4736.421875,4.78765986470058E-5,2.99099751590669E-8,1,2,13.4005146026611,4.99606103884282,28.3899996429682,0.0636774278408303,0.00978618405267078,1,6.49704420934767E-7,,,,,,,,,,,,,,,,,,,,,300.029327392578,300.030059814453,-4736.421875,-4736.421875,46.6194514010049,5.25701938236014,13.9562520980835,26,1,68,0,0,0.290145874023438,37.1456527709961,1,1,1,300.030059814453,0,300.029693603516,,,,,,,,,,,,,,,,,,,,,,,,,,,,,,,,,
,3834153212.22531,300.017471313477,-2631.75415039062,2.23040746420427E-5,2.14822819197329E-8,1,2,13.4005146026611,4.99605458393839,28.3899996429682,0.0296759831697529,0.00448113119409875,1,2.44208534151737E-7,,,,,,,,,,,,,,,,,,,,,300.015777587891,300.019165039063,-2631.75415039062,-2631.75415039062,46.7749954763319,5.25681167931146,13.9511795043945,27,1,0,0,1,0.287933349609375,37.1456527709961,1,1,1,300.015655517578,0,300.017471313477,,,,,,,,,,,,,,,,,,,,,,,,,,,,,,,,,
,3834153237.75327,300.03889465332,-526.487915039063,-1.50073040890782E-6,4.50139460106769E-8,1,2,13.4005146026611,4.99603503966633,28.3899996429682,-0.00203409024519715,-3.43753921912335E-5,1,1.84038032984985E-7,,,,,,,,,,,,,,,,,,,,,300.03857421875,300.039215087891,-526.487915039063,-526.487915039063,46.6726021403126,5.25688241234665,13.964729309082,27,1,0,0,1,0.290451049804687,37.1456527709961,1,1,1,300.039215087891,0,300.03889465332,,,,,,,,,,,,,,,,,,,,,,,,,,,,,,,,,
,3834153261.24832,300.041900634766,1578.62878417969,-1.47540457136159E-5,6.56641729602621E-8,1,2,13.4005146026611,4.99603576961186,28.3899996429682,-0.019657190623759,-0.00277283489353801,1,-1.79100856998018E-8,,,,,,,,,,,,,,,,,,,,,300.040466308594,300.043334960937,1578.62878417969,1578.62878417969,46.7023040240434,5.25715244597155,13.9720106124878,27,1,0,0,1,0.288009643554687,37.1456527709961,1,1,1,300.040466308594,0,300.041900634766,,,,,,,,,,,,,,,,,,,,,,,,,,,,,,,,,
,3834153284.33521,300.027145385742,3683.90747070313,-3.8995736817416E-5,2.68950207222243E-8,1,2,13.4005146026611,4.99598952166054,28.3899996429682,-0.051910286675169,-0.00764382665682794,1,-2.83854779530582E-7,,,,,,,,,,,,,,,,,,,,,300.025421142578,300.028869628906,3683.90747070313,3683.90747070313,46.7406038214857,5.2569984011762,13.9716920852661,27,1,0,0,1,0.283279418945313,37.1456527709961,1,1,1,300.025421142578,0,300.027145385742,,,,,,,,,,,,,,,,,,,,,,,,,,,,,,,,,
,3834153310.16548,300.049133300781,5789.02392578125,-6.5044819428147E-5,4.86961781368757E-8,1,2,13.4005146026611,4.99603533636129,28.3899996429682,-0.0865862511302872,-0.0127579303181779,1,-4.79383451610147E-7,,,,,,,,,,,,,,,,,,,,,300.048858642578,300.049407958984,5789.02392578125,5789.02392578125,46.6389921139857,5.25727749356168,13.9735946655273,27,1,0,0,1,0.290069580078125,37.1456527709961,1,1,1,300.048858642578,0,300.049133300781,,,,,,,,,,,,,,,,,,,,,,,,,,,,,,,,,
,3834153335.49096,300.010589599609,7894.25244140625,-9.13816781971197E-5,3.34429237959997E-8,1,2,13.4005146026611,4.99603320219407,28.3899996429682,-0.12165713522597,-0.0178385332099352,1,-6.09614325455213E-7,,,,,,,,,,,,,,,,,,,,,299.9853515625,300.035827636719,7894.25244140625,7894.25244140625,46.7613169772453,5.25725022834645,13.9687328338623,27,1,0,0,1,0.287857055664062,37.1456527709961,1,1,1,299.9853515625,0,300.010589599609,,,,,,,,,,,,,,,,,,,,,,,,,,,,,,,,,
,3834153357.09566,299.833953857422,9999.53125,-0.000117580165175264,3.10308793566345E-8,1,2,13.4005146026611,4.99599413191271,28.3899996429682,-0.156535760955225,-0.0229377802385237,1,-7.73362666530036E-7,,,,,,,,,,,,,,,,,,,,,299.829254150391,299.838653564453,9999.53125,9999.53125,46.7601445344665,5.25721491785731,13.9615173339844,27,1,0,0,1,0.28839111328125,37.1456527709961,1,1,1,299.829254150391,0,299.833953857422,,,,,,,,,,,,,,,,,,,,,,,,,,,,,,,,,
,3834153392.1754,299.756759643555,13333.07421875,-0.000159203449275079,5.71300945562188E-8,1,2,13.4005146026611,4.99598363829503,28.3899996429682,-0.211922962540299,-0.0312416125507825,1,-1.18518974005376E-6,,,,,,,,,,,,,,,,,,,,,299.752319335937,299.761199951172,13333.07421875,13333.07421875,46.6792459827261,5.25704099148693,13.9514865875244,27,1,0,0,1,0.289840698242188,37.1456527709961,1,1,1,299.752319335937,0,299.756759643555,,,,,,,,,,,,,,,,,,,,,,,,,,,,,,,,,
,3834153417.93203,299.790298461914,17777.34375,-0.000216822528648237,4.72751933881504E-8,1,2,13.4005146026611,4.99600073252202,28.3899996429682,-0.288599067369886,-0.0427249524771909,1,-1.7463211276033E-6,,,,,,,,,,,,,,,,,,,,,299.78564453125,299.794952392578,17777.34375,17777.34375,46.6210146580434,5.25708267486504,13.9536666870117,27,1,0,0,1,0.286941528320313,37.1456527709961,1,1,1,299.794952392578,0,299.790298461914,,,,,,,,,,,,,,,,,,,,,,,,,,,,,,,,,
,3834153453.7064,299.909362792969,21999.62890625,-0.000269543196307776,4.65977452142593E-8,1,2,13.4005146026611,4.99599234578687,28.3899996429682,-0.358762073145821,-0.053180624917648,1,-2.22134833180063E-6,,,,,,,,,,,,,,,,,,,,,299.909362792969,299.909362792969,21999.62890625,21999.62890625,46.7194998514665,5.25693261058412,13.9467086791992,27,1,0,0,1,0.289306640625,37.1456527709961,1,1,1,299.909362792969,0,299.909362792969,,,,,,,,,,,,,,,,,,,,,,,,,,,,,,,,,
,3834153490.88546,299.981018066406,34999.9140625,-0.000432386247274994,1.92443145712149E-7,1,2,13.4005146026611,4.99597379399488,28.3899996429682,-0.575489493418642,-0.0854076813559029,1,-3.63743799797508E-6,,,,,,,,,,,,,,,,,,,,,299.98095703125,299.981079101562,34999.9140625,34999.9140625,46.7288793936972,5.25736577667889,13.947546005249,27,1,0,0,1,0.290679931640625,37.1456527709961,1,1,1,299.98095703125,0,299.981018066406,,,,,,,,,,,,,,,,,,,,,,,,,,,,,,,,,
,3834153547.40904,300.014999389648,58333.25390625,-0.000724982962487125,2.0474061400522E-7,1,2,13.4005146026611,4.99596831750359,28.3899996429682,-0.964818613966238,-0.143949869140133,1,-6.65936826500884E-6,,,,,,,,,,,,,,,,,,,,,300.012054443359,300.017944335937,58333.25390625,58333.25390625,46.4717236108703,5.25692192615497,13.9786424636841,27,1,0,0,1,0.290145874023438,37.1456527709961,1,1,1,300.017944335937,0,300.014999389648,,,,,,,,,,,,,,,,,,,,,,,,,,,,,,,,,
,3834153601.8651,300.03791809082,58333.10546875,-0.000724417329689248,2.89581169584693E-7,1,2,13.4005146026611,4.99596514386338,28.3899996429682,-0.96404055859509,-0.144012397286101,1,-6.78547453305686E-6,,,,,,,,,,,,,,,,,,,,,300.036682128906,300.039154052734,58333.10546875,58333.10546875,46.4728960536491,5.25694415255967,13.995059967041,27,1,0,0,1,0.290908813476562,38.1231689453125,1,1,1,300.036682128906,0,300.03791809082,,,,,,,,,,,,,,,,,,,,,,,,,,,,,,,,,
,3834153657.93286,300.012802124023,34999.5,-0.000431533974795912,1.32530358820437E-7,1,2,13.4005146026611,4.99592108990792,28.3899996429682,-0.574272272888295,-0.0857714962101598,1,-4.03056008823395E-6,,,,,,,,,,,,,,,,,,,,,300.011322021484,300.014282226562,34999.5,34999.5,46.6260952434184,5.25676513534778,13.9841470718384,27,1,0,0,1,0.289382934570313,37.6344108581543,1,1,1,300.014282226562,0,300.012802124023,,,,,,,,,,,,,,,,,,,,,,,,,,,,,,,,,
,3834153697.63923,300.02685546875,21999.69140625,-0.000268486808315207,6.28733342559643E-8,1,2,13.4005146026611,4.99593090138486,28.3899996429682,-0.357308256270914,-0.0532698639626009,1,-2.43669706291172E-6,,,,,,,,,,,,,,,,,,,,,300.026428222656,300.027282714844,21999.69140625,21999.69140625,46.6198422152645,5.25697342086579,13.996075630188,27,1,0,0,1,0.282440185546875,37.1456527709961,1,1,1,300.027282714844,0,300.02685546875,,,,,,,,,,,,,,,,,,,,,,,,,,,,,,,,,