File: SI Fig S11-13 SQUID all/Michaela_Pdref_FC1T.dat
[Header]
; MPMS3 Data File (default extension .dat)
; Copyright (c) 2007, Quantum Design, Inc. All rights reserved.
TITLE,
FILEOPENTIME,3832594697.13758,06/11/2021,5:38 pm
BYAPP,MPMS3 w/ AC,1.0,1.1
INFO,MPMS3 Measurement Release 1.1.16 Build 424, MultiVu Release 2.3.4.19,APPNAME
INFO,Linear Motor Servo Controller,MOTOR_MODULE_NAME
INFO,3101-100 E1,MOTOR_HW_VERSION
INFO,MMC211,MOTOR_SERIAL_NUMBER
INFO,01.04.28,MOTOR_SOFTWARE_VERSION
INFO,Quantum Design Squid Module,SQUID_MODULE_NAME
INFO,3101-501 B0,SQUID_HW_VERSION
INFO,SQM059,SQUID_SERIAL_NUMBER
INFO,01.03.04,SQUID_SOFTWARE_VERSION
INFO,SQUID AC,AC_MODULE_NAME
INFO,3101-401 F1,AC_HW_VERSION
INFO,SAC057,AC_SERIAL_NUMBER
INFO,SQUID AC 00.95.07,AC_SOFTWARE_VERSION
INFO,TCIXXX,COIL_SERIAL_NUMBER
INFO,0,MOMENT_UNITS
INFO,Michaela_Pdref,SAMPLE_MATERIAL
INFO,Michaela_Pdref,SAMPLE_COMMENT
INFO,276.1,SAMPLE_MASS
INFO,,SAMPLE_VOLUME
INFO,,SAMPLE_MOLECULAR_WEIGHT
INFO,,SAMPLE_SIZE
INFO,,SAMPLE_SHAPE
INFO,Brass,SAMPLE_HOLDER
INFO,Standard,SAMPLE_HOLDER_DETAIL
INFO,63.77,SAMPLE_OFFSET
DATATYPE,COMMENT,1
DATATYPE,TIME,2
STARTUPAXIS,X,2
STARTUPAXIS,Y1,5
FIELDGROUP, VSM,2,3,4,5,6,8,9,10,11,14,15
FIELDGROUP, DC, 2,3,4,14,56,57,58,59,60,61,62,63,64,65,66,67,68,69
FIELDGROUP, AC, 2,3,4,11,16,17,18,19,20,21,22,23,24,25,26,27,28,29,30
STARTUPGROUP, All
[Data]
Comment,Time Stamp (sec),Temperature (K),Magnetic Field (Oe),Moment (emu),M. Std. Err. (emu),Transport Action,Averaging Time (sec),Frequency (Hz),Peak Amplitude (mm),Center Position (mm),Lockin Signal' (V),Lockin Signal (V),Range,M. Quad. Signal (emu),AC Moment (emu),AC M. Std Err. (emu),AC Phase (deg),AC Phase Std. Err. (deg),AC Susceptibility (emu/Oe),AC Suscept. Std Err. (emu/Oe),AC X' (emu/Oe),AC X' Std Err. (emu/Oe),AC X'' (emu/Oe),AC X'' Std Err. (emu/Oe),AC Drive (Oe),AC Frequency (Hz),AC Averaging Time (sec),AC Cycles,AC Range,AC Measure Type,AC Signal' (V),AC Signal'' (V),AC Trim Coil Ratio,AC Trim Coil Phase,Min. Temperature (K),Max. Temperature (K),Min. Field (Oe),Max. Field (Oe),Mass (grams),Motor Lag (deg),Pressure (Torr),Measure Count,Measurement Number,SQUID Status (code),Motor Status (code),Measure Status (code),Motor Current (amps),Motor Temp. (C),Temp. Status (code),Field Status (code),Chamber Status (code),Chamber Temp (K),Redirection State,Average Temp (K),Rotation Angle (deg),Rotator state,DC Moment Fixed Ctr (emu),DC Moment Err Fixed Ctr (emu),DC Moment Free Ctr (emu),DC Moment Err Free Ctr (emu),DC Fixed Fit,DC Free Fit,DC Calculated Center (mm),DC Calculated Center Err (mm),DC Scan Length (mm),DC Scan Time (s),DC Number of Points,DC Squid Drift,DC Min V (V),DC Max V (V),DC Scans per Measure,Map 01,Map 02,Map 03,Map 04,Map 05,Map 06,Map 07,Map 08,Map 09,Map 10,Map 11,Map 12,Map 13,Map 14,Map 15,Map 16
,3832594703.32351,299.928802490234,9999.7685546875,0.0136178886590966,1.99701765578676E-6,1,2,13.4005146026611,5.00823298720357,35.1999998092651,18.1899479380401,2.66902742058712,100,9.21969144104597E-5,,,,,,,,,,,,,,,,,,,,,299.928802490234,299.928802490234,9999.7685546875,9999.7685546875,49.3090351356783,5.44094523579383,8.01667499542236,27,1,0,0,1,0.295791625976562,41.055721282959,1,1,1,299.928802490234,0,299.928802490234,,,,,,,,,,,,,,,,,,,,,,,,,,,,,,,,,
,3832594759.35128,298.00325012207,9999.7685546875,0.013679991545257,1.48178307072771E-6,1,2,13.4005146026611,5.00818720965292,35.1999998092651,18.272543887472,2.68208843578364,100,9.33075066949666E-5,,,,,,,,,,,,,,,,,,,,,297.979949951172,298.026550292969,9999.7685546875,9999.7685546875,49.3000464077071,5.44194793898424,7.98790407180786,27,1,0,0,1,0.294570922851562,41.055721282959,2,1,1,297.979949951172,0,298.00325012207,,,,,,,,,,,,,,,,,,,,,,,,,,,,,,,,,
,3832594809.41341,295.50325012207,9999.7685546875,0.013755157613035,6.09140770087147E-7,1,2,13.4005146026611,5.00823104424105,35.1999998092651,18.3734704908803,2.69466565429298,100,9.21806735846698E-5,,,,,,,,,,,,,,,,,,,,,295.441497802734,295.565002441406,9999.7685546875,9999.7685546875,49.2687812669379,5.44163233598106,7.97676944732666,27,1,0,0,1,0.296401977539063,41.055721282959,2,1,1,295.441497802734,0,295.50325012207,,,,,,,,,,,,,,,,,,,,,,,,,,,,,,,,,
,3832594861.16633,292.894546508789,9999.7685546875,0.0138287208372259,9.02537218006978E-7,1,2,13.4005146026611,5.00828948112469,35.1799987256527,18.4714779419862,2.71304881410716,100,9.5612090330045E-5,,,,,,,,,,,,,,,,,,,,,292.828277587891,292.960815429687,9999.7685546875,9999.7685546875,49.321541191986,5.44117205067247,7.95039129257202,27,1,0,0,1,0.28533935546875,41.055721282959,2,1,1,292.828277587891,0,292.894546508789,,,,,,,,,,,,,,,,,,,,,,,,,,,,,,,,,
,3832594912.38951,290.328491210937,9999.7685546875,0.0139016673281474,1.01359196494725E-6,1,2,13.4005146026611,5.00827998150041,35.1799987256527,18.5690768541989,2.72585099436595,100,9.49929928080851E-5,,,,,,,,,,,,,,,,,,,,,290.260162353516,290.396820068359,9999.7685546875,9999.7685546875,49.2316539122744,5.44100910359249,7.93682050704956,27,1,0,0,1,0.29754638671875,41.055721282959,2,1,1,290.260162353516,0,290.328491210937,,,,,,,,,,,,,,,,,,,,,,,,,,,,,,,,,
,3832594964.51015,287.718536376953,9999.7685546875,0.013978009222477,1.62596582711172E-6,1,2,13.4005146026611,5.0082264046418,35.1799987256527,18.6707833783822,2.74073531712001,100,9.54811558599436E-5,,,,,,,,,,,,,,,,,,,,,287.663818359375,287.773254394531,9999.7685546875,9999.7685546875,49.2988739649283,5.44159286833849,7.93955945968628,27,1,0,0,1,0.29296875,41.055721282959,2,1,1,287.663818359375,0,287.718536376953,,,,,,,,,,,,,,,,,,,,,,,,,,,,,,,,,
,3832595016.89192,285.080978393555,9999.7685546875,0.0140527676566018,8.00462177126518E-7,1,2,13.4005146026611,5.00825577065574,35.1600013673306,18.7706277108559,2.75658037405449,100,9.68629589323379E-5,,,,,,,,,,,,,,,,,,,,,285.031585693359,285.13037109375,9999.7685546875,9999.7685546875,49.3391278336687,5.44172560285426,7.92373037338257,27,1,0,0,1,0.296173095703125,41.055721282959,2,1,1,285.022125244141,0,285.080978393555,,,,,,,,,,,,,,,,,,,,,,,,,,,,,,,,,
,3832595069.64256,282.408798217773,9999.7685546875,0.0141299361107166,9.15308328846372E-7,1,2,13.4005146026611,5.00822589369493,35.1600013673306,18.8734014767714,2.7727545812726,100,9.81873116014563E-5,,,,,,,,,,,,,,,,,,,,,282.362091064453,282.455505371094,9999.7685546875,9999.7685546875,49.2777699949091,5.4418191274548,7.9125189781189,27,1,0,0,1,0.297393798828125,41.055721282959,2,1,1,282.362091064453,0,282.408798217773,,,,,,,,,,,,,,,,,,,,,,,,,,,,,,,,,
,3832595121.75887,279.82829284668,9999.7685546875,0.0142060756495841,1.25557408482758E-6,1,2,13.4005146026611,5.0082220118142,35.1499989628792,18.9751527363263,2.78718108244709,100,9.83337433608768E-5,,,,,,,,,,,,,,,,,,,,,279.797149658203,279.859436035156,9999.7685546875,9999.7685546875,49.1042484636398,5.44198569957214,7.91722297668457,27,1,0,0,1,0.288009643554687,41.055721282959,2,1,1,279.78515625,0,279.82829284668,,,,,,,,,,,,,,,,,,,,,,,,,,,,,,,,,
,3832595176.07008,277.131454467773,9999.7685546875,0.0142865655986984,7.65509002375875E-7,1,2,13.4005146026611,5.00817585418169,35.1400002837181,19.0825139189884,2.80228964798424,100,9.84062452739604E-5,,,,,,,,,,,,,,,,,,,,,277.087066650391,277.175842285156,9999.7685546875,9999.7685546875,49.2851954658418,5.4420798462161,7.90183353424072,27,1,0,0,1,0.297622680664063,41.055721282959,2,1,1,277.087066650391,0,277.131454467773,,,,,,,,,,,,,,,,,,,,,,,,,,,,,,,,,
,3832595226.58625,274.554748535156,9999.7685546875,0.014362139144243,6.798777549298E-7,1,2,13.4005146026611,5.00818559732638,35.1400002837181,19.1836692159887,2.81596950410095,100,9.80656984660776E-5,,,,,,,,,,,,,,,,,,,,,274.514343261719,274.595153808594,9999.7685546875,9999.7685546875,49.3184146779091,5.44232952329055,7.8895001411438,27,1,0,0,1,0.292282104492188,41.055721282959,2,1,1,274.514343261719,0,274.554748535156,,,,,,,,,,,,,,,,,,,,,,,,,,,,,,,,,
,3832595278.83101,271.964920043945,9999.7685546875,0.014440874302069,1.68825180955906E-6,1,2,13.4005146026611,5.00817432839517,35.130001604557,19.2887787894121,2.83138779607202,100,9.85954397484688E-5,,,,,,,,,,,,,,,,,,,,,271.923553466797,272.006286621094,9999.7685546875,9999.7685546875,49.265654752861,5.44293192692515,7.88750314712524,27,1,0,0,1,0.286483764648438,41.055721282959,2,1,1,271.923553466797,0,271.964920043945,,,,,,,,,,,,,,,,,,,,,,,,,,,,,,,,,
,3832595333.2162,269.250717163086,9999.7685546875,0.0145215353477021,1.31698449473788E-6,1,2,13.4005146026611,5.00813537004585,35.1100005209446,19.3959854409216,2.84950867550367,100,0.000100893491006818,,,,,,,,,,,,,,,,,,,,,269.192962646484,269.308471679687,9999.7685546875,9999.7685546875,49.2367344976494,5.44210753106339,7.86900520324707,27,1,0,0,1,0.296783447265625,41.055721282959,2,1,1,269.192962646484,0,269.250717163086,,,,,,,,,,,,,,,,,,,,,,,,,,,,,,,,,
,3832595385.61342,266.627716064453,9999.7685546875,0.0146022282843879,2.16731703529809E-6,1,2,13.4005146026611,5.00819355825103,35.1100005209446,19.5043278838257,2.86357505268674,100,0.0001000979435656,,,,,,,,,,,,,,,,,,,,,266.565551757813,266.689880371094,9999.7685546875,9999.7685546875,49.2980923364091,5.44178997969864,7.87204885482788,27,1,0,0,1,0.296554565429687,41.055721282959,2,1,1,266.565551757813,0,266.627716064453,,,,,,,,,,,,,,,,,,,,,,,,,,,,,,,,,
,3832595440.36384,263.904022216797,9999.7685546875,0.0146866544962289,1.53971636219761E-6,1,2,13.4005146026611,5.00818064804345,35.1100005209446,19.6170368973524,2.88005494305567,100,0.000100627024607288,,,,,,,,,,,,,,,,,,,,,263.885437011719,263.922607421875,9999.7685546875,9999.7685546875,49.174204216111,5.44162013009724,7.86951971054077,27,1,0,0,1,0.295181274414063,41.055721282959,2,1,1,263.885437011719,0,263.904022216797,,,,,,,,,,,,,,,,,,,,,,,,,,,,,,,,,
,3832595490.41329,261.369201660156,9999.7685546875,0.0147655079029324,1.56544498144919E-6,1,2,13.4005146026611,5.00807688398051,35.1100005209446,19.721744797516,2.89585409188049,100,0.000101479938723439,,,,,,,,,,,,,,,,,,,,,261.330932617187,261.407470703125,9999.7685546875,9999.7685546875,49.3016096647456,5.44284943311421,7.85733890533447,27,1,0,0,1,0.2978515625,41.055721282959,2,1,1,261.330932617187,0,261.369201660156,,,,,,,,,,,,,,,,,,,,,,,,,,,,,,,,,
,3832595542.0327,258.832763671875,9999.7685546875,0.0148459751912813,2.03395698213873E-6,1,2,13.4005146026611,5.00803874078175,35.0899994373322,19.8289719614392,2.91191701959777,100,0.000102266164233216,,,,,,,,,,,,,,,,,,,,,258.741943359375,258.923583984375,9999.7685546875,9999.7685546875,49.3246677060629,5.44246801894304,7.8498911857605,27,1,0,0,1,0.289077758789063,41.055721282959,2,1,1,258.741943359375,0,258.832763671875,,,,,,,,,,,,,,,,,,,,,,,,,,,,,,,,,
,3832595593.31535,256.269073486328,9999.7685546875,0.0149257368340766,1.54933246664013E-6,1,2,13.4005146026611,5.00804053290504,35.0899994373322,19.935571408901,2.92716001764234,100,0.000102514142216919,,,,,,,,,,,,,,,,,,,,,256.218719482422,256.319427490234,9999.7685546875,9999.7685546875,49.2648731243418,5.44268321381128,7.84562397003174,27,1,0,0,1,0.285186767578125,41.055721282959,2,1,1,256.218719482422,0,256.269073486328,,,,,,,,,,,,,,,,,,,,,,,,,,,,,,,,,
,3832595647.61348,253.537208557129,9999.7685546875,0.0150117353783214,1.18494346521923E-6,1,2,13.4005146026611,5.00817040262389,35.0899994373322,20.0511161822606,2.94434428265263,100,0.000103265098023769,,,,,,,,,,,,,,,,,,,,,253.492965698242,253.581451416016,9999.7685546875,9999.7685546875,49.3531971470148,5.44159773124428,7.83244037628174,27,1,0,0,1,0.294113159179687,41.055721282959,2,1,1,253.492965698242,0,253.537208557129,,,,,,,,,,,,,,,,,,,,,,,,,,,,,,,,,
,3832595698.26324,251.037956237793,9999.7685546875,0.0150903137998191,1.1511476067657E-6,1,2,13.4005146026611,5.00814593645426,35.0699983537197,20.1559986426337,2.95930630664245,100,0.000103483802119245,,,,,,,,,,,,,,,,,,,,,251.014694213867,251.061218261719,9999.7685546875,9999.7685546875,49.2777699949091,5.4416507674719,7.82558298110962,27,1,0,0,1,0.294647216796875,41.055721282959,2,1,1,251.014694213867,0,251.037956237793,,,,,,,,,,,,,,,,,,,,,,,,,,,,,,,,,
,3832595748.29362,248.539222717285,9999.7685546875,0.0151721368522806,2.2368042741679E-6,1,2,13.4005146026611,5.0081903059652,35.0699983537197,20.265398789941,2.97635807888858,100,0.000104770216790763,,,,,,,,,,,,,,,,,,,,,248.499435424805,248.579010009766,9999.7685546875,9999.7685546875,49.2101591279956,5.44174454750493,7.81581926345825,27,1,0,0,1,0.29022216796875,41.055721282959,2,1,1,248.499435424805,0,248.539222717285,,,,,,,,,,,,,,,,,,,,,,,,,,,,,,,,,
,3832595802.67036,245.808860778809,9999.7685546875,0.0152603025707155,1.31212893843021E-6,1,2,13.4005146026611,5.00813622700686,35.0699983537197,20.3829445910903,2.99300997243365,100,0.000104930545601039,,,,,,,,,,,,,,,,,,,,,245.747650146484,245.870071411133,9999.7685546875,9999.7685546875,49.2476772969187,5.44105992270803,7.82232713699341,27,1,0,0,1,0.297317504882812,41.055721282959,2,1,1,245.747650146484,0,245.808860778809,,,,,,,,,,,,,,,,,,,,,,,,,,,,,,,,,
,3832595853.24818,243.308349609375,9999.7685546875,0.0153419500468755,1.3625877475403E-6,1,2,13.4005146026611,5.00812825748781,35.0699983537197,20.4919880726993,3.0087823063738,100,0.000105316427936753,,,,,,,,,,,,,,,,,,,,,243.27880859375,243.337890625,9999.7685546875,9999.7685546875,49.2977015221494,5.44182861169967,7.8220067024231,27,1,0,0,1,0.294876098632812,41.055721282959,2,1,1,243.266265869141,0,243.308349609375,,,,,,,,,,,,,,,,,,,,,,,,,,,,,,,,,
,3832595905.4997,240.674049377441,9999.7685546875,0.0154263327612314,2.01454880362103E-6,1,2,13.4005146026611,5.00815807475102,35.0500009953976,20.6047835086095,3.02593377100679,100,0.000106328113629036,,,,,,,,,,,,,,,,,,,,,240.624649047852,240.723449707031,9999.7685546875,9999.7685546875,49.2867587228802,5.44155533952015,7.80119276046753,27,1,0,0,1,0.293197631835937,41.055721282959,2,1,1,240.624649047852,0,240.674049377441,,,,,,,,,,,,,,,,,,,,,,,,,,,,,,,,,
,3832595957.82432,238.063568115234,9999.7685546875,0.0155122542531548,2.00183742932282E-6,1,2,13.4005146026611,5.0081476155334,35.0500009953976,20.7194000838007,3.04341309624527,100,0.000107394682381183,,,,,,,,,,,,,,,,,,,,,238.01432800293,238.112808227539,9999.7685546875,9999.7685546875,49.2836322088033,5.44196746021487,7.80468368530273,27,1,0,0,1,0.296554565429687,41.055721282959,2,1,1,238.01432800293,0,238.063568115234,,,,,,,,,,,,,,,,,,,,,,,,,,,,,,,,,
,3832596008.50996,235.491752624512,9999.7685546875,0.0155956405191042,1.69142384598066E-6,1,2,13.4005146026611,5.00817686152461,35.0500009953976,20.8307463237361,3.06120892753664,100,0.000109027727034582,,,,,,,,,,,,,,,,,,,,,235.420852661133,235.562652587891,9999.7685546875,9999.7685546875,49.2398610117264,5.44145300907403,7.79387331008911,27,1,0,0,1,0.294113159179687,40.5669593811035,2,1,1,235.420852661133,0,235.491752624512,,,,,,,,,,,,,,,,,,,,,,,,,,,,,,,,,
,3832596058.56314,233.039482116699,9999.7685546875,0.0156770116783638,6.98890395552183E-7,1,2,13.4005146026611,5.0081918497322,35.0299999117851,20.9399065861389,3.07441159302184,100,0.000107515823664045,,,,,,,,,,,,,,,,,,,,,232.98193359375,233.097030639648,9999.7685546875,9999.7685546875,49.2746434808321,5.44216002339458,7.79059553146362,27,1,0,0,1,0.296554565429687,41.055721282959,2,1,1,232.98193359375,0,233.039482116699,,,,,,,,,,,,,,,,,,,,,,,,,,,,,,,,,
,3832596111.1569,230.384216308594,9999.7685546875,0.0157651598828543,1.9933741753436E-6,1,2,13.4005146026611,5.00814610541305,35.0299999117851,21.0572453657489,3.09265068908736,100,0.000108861580312689,,,,,,,,,,,,,,,,,,,,,230.350036621094,230.418395996094,9999.7685546875,9999.7685546875,49.270735338236,5.44132589578614,7.8008074760437,27,1,0,0,1,0.286712646484375,41.055721282959,2,1,1,230.350036621094,0,230.384216308594,,,,,,,,,,,,,,,,,,,,,,,,,,,,,,,,,
,3832596163.39853,227.792808532715,9999.7685546875,0.0158525528968773,1.59186870741044E-6,1,2,13.4005146026611,5.00813666697627,35.0299999117851,21.1736152765153,3.11196682493545,100,0.000111095796460466,,,,,,,,,,,,,,,,,,,,,227.747375488281,227.838241577148,9999.7685546875,9999.7685546875,49.265654752861,5.44295345916155,7.78161430358887,27,1,0,0,1,0.296401977539063,41.055721282959,2,1,1,227.747375488281,0,227.792808532715,,,,,,,,,,,,,,,,,,,,,,,,,,,,,,,,,
,3832596215.71299,225.169845581055,9999.7685546875,0.0159415200553772,1.25515297313908E-6,1,2,13.4005146026611,5.00805447156186,35.0299999117851,21.2921930906363,3.12774771813188,100,0.000110512217273447,,,,,,,,,,,,,,,,,,,,,225.117080688477,225.222610473633,9999.7685546875,9999.7685546875,49.2953566365918,5.44182614463762,7.7835750579834,27,1,0,0,1,0.29510498046875,41.055721282959,2,1,1,225.117080688477,0,225.169845581055,,,,,,,,,,,,,,,,,,,,,,,,,,,,,,,,,
,3832596266.33773,222.616149902344,9999.7685546875,0.0160264688646812,1.39903222791067E-6,1,2,13.4005146026611,5.0081659862944,35.0099988281727,21.4063003123214,3.14455089479945,100,0.000111131329858629,,,,,,,,,,,,,,,,,,,,,222.548141479492,222.684158325195,9999.7685546875,9999.7685546875,49.2105499422552,5.44158507696313,7.77176713943481,27,1,0,0,1,0.295181274414063,41.055721282959,2,1,1,222.548141479492,0,222.616149902344,,,,,,,,,,,,,,,,,,,,,,,,,,,,,,,,,
,3832596318.50435,220.049011230469,9999.7685546875,0.0161160094878346,1.79631140123515E-6,1,2,13.4005146026611,5.00813341575097,35.0099988281727,21.525589202822,3.1629336555242,100,0.000112382097608565,,,,,,,,,,,,,,,,,,,,,219.987075805664,220.110946655273,9999.7685546875,9999.7685546875,49.1226167338417,5.44118251802421,7.7794017791748,27,1,0,0,1,0.286636352539062,41.055721282959,2,1,1,219.987075805664,0,220.049011230469,,,,,,,,,,,,,,,,,,,,,,,,,,,,,,,,,
,3832596371.27192,217.386413574219,9999.7685546875,0.0162055401943213,1.95689624522988E-6,1,2,13.4005146026611,5.00815402793079,35.0099988281727,21.6453344802548,3.18023336347535,100,0.000112789881197864,,,,,,,,,,,,,,,,,,,,,217.36669921875,217.406127929687,9999.7685546875,9999.7685546875,49.265654752861,5.4411268338754,7.77160596847534,26,1,64,0,0,0.293655395507812,41.055721282959,2,1,1,217.36669921875,0,217.386413574219,,,,,,,,,,,,,,,,,,,,,,,,,,,,,,,,,
,3832596423.6733,214.747276306152,9999.7685546875,0.0162940492403129,1.17458275614653E-6,1,2,13.4005146026611,5.00818179182864,34.9900014698505,21.7636017315427,3.19846357520796,100,0.000114031672664345,,,,,,,,,,,,,,,,,,,,,214.683639526367,214.810913085938,9999.7685546875,9999.7685546875,49.2105499422552,5.44129728080833,7.76937198638916,27,1,0,0,1,0.293960571289063,41.055721282959,2,1,1,214.683639526367,0,214.747276306152,,,,,,,,,,,,,,,,,,,,,,,,,,,,,,,,,
,3832596477.88968,212.104560852051,9999.7685546875,0.0163887227348925,9.19354541894293E-7,1,2,13.4005146026611,5.00816903557072,34.9900014698505,21.8900523575277,3.21651048096026,100,0.000114300836820227,,,,,,,,,,,,,,,,,,,,,212.055511474609,212.153610229492,9999.7685546875,9999.7685546875,49.1480196607167,5.44183622830571,7.77122116088867,27,1,0,0,1,0.288162231445313,41.055721282959,2,1,1,212.055511474609,0,212.104560852051,,,,,,,,,,,,,,,,,,,,,,,,,,,,,,,,,
,3832596532.15031,209.372001647949,9999.7685546875,0.0164830708719758,1.39936695397072E-6,1,2,13.4005146026611,5.00815644437662,34.9900014698505,22.0161069935572,3.23421841093352,100,0.000114361939099401,,,,,,,,,,,,,,,,,,,,,209.323867797852,209.420135498047,9999.7685546875,9999.7685546875,49.2273549554187,5.4415321140684,7.76434946060181,27,1,0,0,1,0.294952392578125,41.055721282959,2,1,1,209.323867797852,0,209.372001647949,,,,,,,,,,,,,,,,,,,,,,,,,,,,,,,,,
,3832596584.40906,206.784973144531,9999.7685546875,0.0165732004256345,1.84465311080546E-6,1,2,13.4005146026611,5.00811826731177,34.9900014698505,22.1360151196147,3.25362474391518,100,0.000116300311479948,,,,,,,,,,,,,,,,,,,,,206.737106323242,206.83283996582,9999.7685546875,9999.7685546875,49.2820689517648,5.44218199941386,7.75359725952148,27,1,0,0,1,0.287246704101562,41.055721282959,2,1,1,206.737106323242,0,206.784973144531,,,,,,,,,,,,,,,,,,,,,,,,,,,,,,,,,
,3832596635.12505,204.220291137695,9999.7685546875,0.016661917038815,2.51855152485727E-6,1,2,13.4005146026611,5.00813995474895,34.9700003862381,22.2548627970412,3.2694766754694,100,0.000115737998768339,,,,,,,,,,,,,,,,,,,,,204.136856079102,204.303726196289,9999.7685546875,9999.7685546875,49.2676088241591,5.44162269428411,7.74869346618652,27,1,0,0,1,0.286407470703125,41.055721282959,2,1,1,204.136856079102,0,204.220291137695,,,,,,,,,,,,,,,,,,,,,,,,,,,,,,,,,
,3832596687.22001,201.595764160156,9999.7685546875,0.0167530854480118,2.00140019769832E-6,1,2,13.4005146026611,5.00818590907014,34.9700003862381,22.3766449416099,3.28933583452301,100,0.000117813662769547,,,,,,,,,,,,,,,,,,,,,201.544967651367,201.646560668945,9999.7685546875,9999.7685546875,49.199607142986,5.44156165231344,7.73198556900024,27,1,0,0,1,0.286407470703125,41.055721282959,2,1,1,201.544967651367,0,201.595764160156,,,,,,,,,,,,,,,,,,,,,,,,,,,,,,,,,
,3832596739.55238,198.973258972168,9999.7685546875,0.0168447251704761,7.35840241301344E-7,1,2,13.4005146026611,5.00814378100998,34.9700003862381,22.4989483208714,3.30613648510389,100,0.000117594919124468,,,,,,,,,,,,,,,,,,,,,198.913864135742,199.032653808594,9999.7685546875,9999.7685546875,49.2891036084379,5.44185210773669,7.74007892608643,27,1,0,0,1,0.29693603515625,41.055721282959,2,1,1,198.913864135742,0,198.973258972168,,,,,,,,,,,,,,,,,,,,,,,,,,,,,,,,,
,3832596790.31705,196.47607421875,9999.7685546875,0.0169329013602381,2.58854673146478E-6,1,2,13.4005146026611,5.00803721477623,34.9499993026257,22.6161594365802,3.32266770485566,100,0.000117702926907615,,,,,,,,,,,,,,,,,,,,,196.438873291016,196.513275146484,9999.7685546875,9999.7685546875,49.2945750080725,5.44239981122894,7.72844123840332,25,1,64,0,0,0.292434692382812,41.055721282959,2,1,1,196.438873291016,0,196.47607421875,,,,,,,,,,,,,,,,,,,,,,,,,,,,,,,,,
,3832596840.28802,193.97444152832,9999.7685546875,0.0170215082478675,1.95596509361111E-6,1,2,13.4005146026611,5.00814733532374,34.9499993026257,22.7349795551708,3.34165388187736,100,0.00011943992449849,,,,,,,,,,,,,,,,,,,,,193.935775756836,194.013107299805,9999.7685546875,9999.7685546875,49.3219320062456,5.44176123959724,7.72242021560669,27,1,0,0,1,0.279388427734375,41.055721282959,2,1,1,193.935775756836,0,193.97444152832,,,,,,,,,,,,,,,,,,,,,,,,,,,,,,,,,
,3832596890.71966,191.476364135742,9999.7685546875,0.0171108105573,1.80811467911988E-6,1,2,13.4005146026611,5.0081513297278,34.9499993026257,22.854394683737,3.35838456580182,100,0.000119464631042849,,,,,,,,,,,,,,,,,,,,,191.438323974609,191.514404296875,9999.7685546875,9999.7685546875,49.3543695897937,5.44126300548383,7.71584796905518,27,1,0,0,1,0.293960571289063,41.055721282959,2,1,1,191.438323974609,0,191.476364135742,,,,,,,,,,,,,,,,,,,,,,,,,,,,,,,,,
,3832596945.07036,188.724517822266,9999.7685546875,0.0172063651472555,1.71247654819107E-6,1,2,13.4005146026611,5.00812376459503,34.9400006234646,22.9817455078091,3.37786961630878,100,0.000120697013805658,,,,,,,,,,,,,,,,,,,,,188.671173095703,188.777862548828,9999.7685546875,9999.7685546875,49.291057679736,5.44169171378473,7.71425914764404,27,1,0,0,1,0.295028686523438,41.055721282959,2,1,1,188.671173095703,0,188.724517822266,,,,,,,,,,,,,,,,,,,,,,,,,,,,,,,,,
,3832596997.45467,186.135665893555,9999.7685546875,0.0172990045373068,2.04054187099494E-6,1,2,13.4005146026611,5.00808939406058,34.9400006234646,23.1050015281188,3.39789362069043,100,0.000122745065621822,,,,,,,,,,,,,,,,,,,,,186.077362060547,186.193969726562,9999.7685546875,9999.7685546875,49.2687812669379,5.44124556100996,7.70583152770996,27,1,0,0,1,0.284881591796875,40.5669593811035,2,1,1,186.077362060547,0,186.135665893555,,,,,,,,,,,,,,,,,,,,,,,,,,,,,,,,,
,3832597049.87436,183.482978820801,9999.7685546875,0.0173913525853204,1.26352129469951E-6,1,2,13.4005146026611,5.00812989481204,34.9299982190132,23.2287213398023,3.41520810930373,100,0.000122755279295458,,,,,,,,,,,,,,,,,,,,,183.44465637207,183.521301269531,9999.7685546875,9999.7685546875,49.2672180098994,5.44087468154219,7.69282054901123,27,1,0,0,1,0.287857055664062,41.055721282959,2,1,1,183.417419433594,0,183.482978820801,,,,,,,,,,,,,,,,,,,,,,,,,,,,,,,,,
,3832597102.20617,180.906303405762,9999.7685546875,0.0174827627159329,2.18004476672352E-6,1,2,13.4005146026611,5.00810863586295,34.9299982190132,23.3506876037329,3.43306713467995,100,0.000123346919794553,,,,,,,,,,,,,,,,,,,,,180.866394042969,180.946212768555,9999.7685546875,9999.7685546875,49.2367344976494,5.44119787697707,7.69905042648315,27,1,0,0,1,0.294876098632812,41.055721282959,2,1,1,180.841583251953,0,180.906303405762,,,,,,,,,,,,,,,,,,,,,,,,,,,,,,,,,
,3832597154.61013,178.326690673828,9999.7685546875,0.0175746334224476,2.45356338306614E-6,1,2,13.4005146026611,5.00809543605025,34.9199995398521,23.4729302487131,3.4538060613394,100,0.00012602271481696,,,,,,,,,,,,,,,,,,,,,178.266906738281,178.386474609375,9999.7685546875,9999.7685546875,49.3363921338514,5.44179862310644,7.69481754302979,27,1,0,0,1,0.2960205078125,41.055721282959,2,1,1,178.266906738281,0,178.326690673828,,,,,,,,,,,,,,,,,,,,,,,,,,,,,,,,,
,3832597205.1566,175.757484436035,9999.7685546875,0.0176621645084627,1.79591055313988E-6,1,2,13.4005146026611,5.00812864350899,34.9199995398521,23.5906340823552,3.46687498904377,100,0.000123535611825029,,,,,,,,,,,,,,,,,,,,,175.708419799805,175.806549072266,9999.7685546875,9999.7685546875,49.257447653409,5.44124217582015,7.69315004348755,27,1,0,0,1,0.284957885742187,40.5669593811035,2,1,1,175.708419799805,0,175.757484436035,,,,,,,,,,,,,,,,,,,,,,,,,,,,,,,,,
,3832597257.34821,173.17227935791,9999.7685546875,0.0177542483264417,1.94866213829882E-6,1,2,13.4005146026611,5.00813653235028,34.8999984562397,23.7134775911506,3.4863889728626,100,0.000125250392557008,,,,,,,,,,,,,,,,,,,,,173.118423461914,173.226135253906,9999.7685546875,9999.7685546875,49.3008280362264,5.44121165902175,7.68745851516724,27,1,0,0,1,0.28594970703125,40.5669593811035,2,1,1,173.118423461914,0,173.17227935791,,,,,,,,,,,,,,,,,,,,,,,,,,,,,,,,,
,3832597311.75532,170.466697692871,9999.7685546875,0.017850466616558,2.10988495330896E-6,1,2,13.4005146026611,5.00809395176959,34.8999984562397,23.8418370184102,3.50436668897635,100,0.000125274062591966,,,,,,,,,,,,,,,,,,,,,170.411743164062,170.52165222168,9999.7685546875,9999.7685546875,49.326621777361,5.44133272689534,7.68816995620728,27,1,0,0,1,0.296249389648438,40.5669593811035,2,1,1,170.411743164062,0,170.466697692871,,,,,,,,,,,,,,,,,,,,,,,,,,,,,,,,,
,3832597362.46995,167.932861328125,9999.7685546875,0.017937995683615,1.80440718159637E-6,1,2,13.4005146026611,5.00807416200345,34.8999984562397,23.9586914337882,3.5209854515969,100,0.000125480139093136,,,,,,,,,,,,,,,,,,,,,167.871032714844,167.994689941406,9999.7685546875,9999.7685546875,49.1820205013033,5.44148718448156,7.68387126922607,27,1,0,0,1,0.28533935546875,41.055721282959,2,1,1,167.871032714844,0,167.932861328125,,,,,,,,,,,,,,,,,,,,,,,,,,,,,,,,,
,3832597414.51605,165.306655883789,9999.7685546875,0.0180279154579101,1.97176058633265E-6,1,2,13.4005146026611,5.00803378523616,34.8999984562397,24.0785232976088,3.53861909188783,100,0.000126126054838857,,,,,,,,,,,,,,,,,,,,,165.248123168945,165.365188598633,9999.7685546875,9999.7685546875,49.2089866852167,5.44152776325298,7.67528057098389,27,1,0,0,1,0.294876098632812,41.055721282959,2,1,1,165.248123168945,0,165.306655883789,,,,,,,,,,,,,,,,,,,,,,,,,,,,,,,,,
,3832597466.88334,162.668647766113,9999.7685546875,0.0181193301534262,1.5391103392764E-6,1,2,13.4005146026611,5.00803769934054,34.8800010979176,24.2008555220997,3.55505953440265,100,0.000125638594372191,,,,,,,,,,,,,,,,,,,,,162.605133056641,162.732162475586,9999.7685546875,9999.7685546875,49.1785031729667,5.44188278520729,7.67106056213379,27,1,0,0,1,0.296401977539063,41.055721282959,2,1,1,162.605133056641,0,162.668647766113,,,,,,,,,,,,,,,,,,,,,,,,,,,,,,,,,
,3832597519.35689,160.050064086914,9999.7685546875,0.0182147616276206,2.16817645785195E-6,1,2,13.4005146026611,5.00805286479145,34.8800010979176,24.3279750969861,3.57696637512199,100,0.000128670012228479,,,,,,,,,,,,,,,,,,,,,160.005401611328,160.0947265625,9999.7685546875,9999.7685546875,49.2679996384187,5.44301364580752,7.66844892501831,27,1,0,0,1,0.296859741210937,41.055721282959,2,1,1,160.005401611328,0,160.050064086914,,,,,,,,,,,,,,,,,,,,,,,,,,,,,,,,,
,3832597571.65708,157.468276977539,9999.7685546875,0.0183029454956516,1.83693437903798E-6,1,2,13.4005146026611,5.00802442861203,34.8800010979176,24.4455007622833,3.59471794810465,100,0.00012963863277756,,,,,,,,,,,,,,,,,,,,,157.429962158203,157.506591796875,9999.7685546875,9999.7685546875,49.2668271956398,5.44218735175789,7.65261697769165,27,1,0,0,1,0.287246704101562,40.5669593811035,2,1,1,157.429962158203,0,157.468276977539,,,,,,,,,,,,,,,,,,,,,,,,,,,,,,,,,
,3832597626.05878,154.694885253906,9999.7685546875,0.0183964106050655,2.07316828638662E-6,1,2,13.4005146026611,5.00805199325277,34.8800010979176,24.5705721534438,3.6127149170294,100,0.000130011277032137,,,,,,,,,,,,,,,,,,,,,154.642150878906,154.747619628906,9999.7685546875,9999.7685546875,49.3137249067937,5.44336908838995,7.65053749084473,27,1,0,0,1,0.297470092773438,41.055721282959,2,1,1,154.642150878906,0,154.694885253906,,,,,,,,,,,,,,,,,,,,,,,,,,,,,,,,,
,3832597678.45915,152.12606048584,9999.7685546875,0.0184811304676666,2.56432704912093E-6,1,2,13.4005146026611,5.00810640138602,34.8600000143051,24.683796634907,3.63151909983602,100,0.000132190366865799,,,,,,,,,,,,,,,,,,,,,152.070953369141,152.181167602539,9999.7685546875,9999.7685546875,49.3059086216014,5.44259771349164,7.64698791503906,27,1,0,0,1,0.284805297851562,41.055721282959,2,1,1,152.070953369141,0,152.12606048584,,,,,,,,,,,,,,,,,,,,,,,,,,,,,,,,,
,3832597728.8549,149.578659057617,9999.7685546875,0.0185575513790827,3.36430481106725E-6,1,2,13.4005146026611,5.00812887594188,34.8600000143051,24.7866697956574,3.64189711769513,100,0.000129250761738942,,,,,,,,,,,,,,,,,,,,,149.520797729492,149.636520385742,9999.7685546875,9999.7685546875,49.3918877587168,5.44167278573032,7.63189649581909,27,1,0,0,1,0.28533935546875,41.055721282959,2,1,1,149.520797729492,0,149.578659057617,,,,,,,,,,,,,,,,,,,,,,,,,,,,,,,,,
,3832597783.20476,146.868522644043,9999.7685546875,0.0186459509487116,1.86369678159399E-6,1,2,13.4005146026611,5.00814981240394,34.8600000143051,24.9047044180212,3.66055290686435,100,0.000130828752200404,,,,,,,,,,,,,,,,,,,,,146.809951782227,146.927093505859,9999.7685546875,9999.7685546875,49.2699537097168,5.4412533566004,7.62830924987793,27,1,0,0,1,0.29541015625,41.055721282959,2,1,1,146.809951782227,0,146.868522644043,,,,,,,,,,,,,,,,,,,,,,,,,,,,,,,,,
,3832597843.98324,143.847564697266,9999.7685546875,0.0187410516416727,2.79867571120533E-6,1,2,13.4005146026611,5.00808358636211,34.8399989306927,25.0310675502465,3.68063607049906,100,0.000132602721911813,,,,,,,,,,,,,,,,,,,,,143.810440063477,143.884689331055,9999.7685546875,9999.7685546875,49.2832413945437,5.44290651735519,7.62446784973145,27,1,0,0,1,0.297775268554687,41.055721282959,2,1,1,143.810440063477,0,143.847564697266,,,,,,,,,,,,,,,,,,,,,,,,,,,,,,,,,
,3832597894.06235,141.348968505859,9999.7685546875,0.0188172156786205,2.27672188235756E-6,1,2,13.4005146026611,5.00811024300978,34.8399989306927,25.1329282238743,3.69597143666858,100,0.000133403630382373,,,,,,,,,,,,,,,,,,,,,141.309097290039,141.38883972168,9999.7685546875,9999.7685546875,49.3309207342168,5.4422537655828,7.61102485656738,27,1,0,0,1,0.2923583984375,41.055721282959,2,1,1,141.309097290039,0,141.348968505859,,,,,,,,,,,,,,,,,,,,,,,,,,,,,,,,,
,3832597948.4431,138.625679016113,9999.7685546875,0.0189020525296693,2.51791652141046E-6,1,2,13.4005146026611,5.00813705857429,34.8399989306927,25.2465522683294,3.71174476599506,100,0.000133319183038077,,,,,,,,,,,,,,,,,,,,,138.564636230469,138.686721801758,9999.7685546875,9999.7685546875,49.2558843963706,5.44162002816892,7.59135150909424,27,1,0,0,1,0.295028686523438,41.055721282959,2,1,1,138.564636230469,0,138.625679016113,,,,,,,,,,,,,,,,,,,,,,,,,,,,,,,,,
,3832598007.19012,135.64217376709,9999.7685546875,0.0189905703185291,2.07663128429682E-6,1,2,13.4005146026611,5.00814619773775,34.8399989306927,25.3648448955034,3.72913282884644,100,0.000133941091967773,,,,,,,,,,,,,,,,,,,,,135.59553527832,135.688812255859,9999.7685546875,9999.7685546875,49.2562752106302,5.44219984895515,7.58883810043335,27,1,0,0,1,0.28778076171875,41.055721282959,2,1,1,135.59553527832,0,135.64217376709,,,,,,,,,,,,,,,,,,,,,,,,,,,,,,,,,
,3832598059.23451,133.100860595703,9999.7685546875,0.0190681694755467,2.40334888582472E-6,1,2,13.4005146026611,5.00813982910723,34.8399989306927,25.4687336431716,3.74230926073482,100,0.000132951329381906,,,,,,,,,,,,,,,,,,,,,133.060653686523,133.141067504883,9999.7685546875,9999.7685546875,49.2449415971014,5.44224035527831,7.58703136444092,27,1,0,0,1,0.297164916992188,41.055721282959,2,1,1,133.036880493164,0,133.100860595703,,,,,,,,,,,,,,,,,,,,,,,,,,,,,,,,,
,3832598111.6617,130.463714599609,9999.7685546875,0.0191440207969049,2.24608343165262E-6,1,2,13.4005146026611,5.00818111178832,34.8200015723705,25.5698321195855,3.76082678944628,100,0.000136164333788218,,,,,,,,,,,,,,,,,,,,,130.401290893555,130.526138305664,9999.7685546875,9999.7685546875,49.3426451620052,5.44179087226801,7.58110857009888,27,1,0,0,1,0.286483764648438,41.055721282959,2,1,1,130.401290893555,0,130.463714599609,,,,,,,,,,,,,,,,,,,,,,,,,,,,,,,,,
,3832598162.13833,127.950477600098,9999.7685546875,0.0192154886039566,1.28037535724302E-6,1,2,13.4005146026611,5.00815307988854,34.8200015723705,25.6642187638375,3.78108441264489,100,0.000141344928874901,,,,,,,,,,,,,,,,,,,,,127.902168273926,127.99878692627,9999.7685546875,9999.7685546875,49.2738618523129,5.44187588031324,7.56763982772827,27,1,0,0,1,0.287551879882813,40.5669593811035,2,1,1,127.902168273926,0,127.950477600098,,,,,,,,,,,,,,,,,,,,,,,,,,,,,,,,,
,3832598214.37933,125.333351135254,9999.7685546875,0.0192892033091068,1.90453506024368E-6,1,2,13.4005146026611,5.00815503195591,34.8200015723705,25.7636869648583,3.78843187447611,100,0.000136532086006426,,,,,,,,,,,,,,,,,,,,,125.27709197998,125.389610290527,9999.7685546875,9999.7685546875,49.2668271956398,5.4417076417569,7.55168437957764,27,1,0,0,1,0.29327392578125,40.5669593811035,2,1,1,125.27709197998,0,125.333351135254,,,,,,,,,,,,,,,,,,,,,,,,,,,,,,,,,
,3832598278.86558,122.100299835205,9999.7685546875,0.0193757357698377,2.24094092448611E-6,1,2,13.4005146026611,5.0081834908813,34.8200015723705,25.8796654670294,3.80402523804811,100,0.000136074024150185,,,,,,,,,,,,,,,,,,,,,122.048973083496,122.151626586914,9999.7685546875,9999.7685546875,49.3133340925341,5.44178896438259,7.54482841491699,27,1,0,0,1,0.294570922851562,40.5669593811035,2,1,1,122.048973083496,0,122.100299835205,,,,,,,,,,,,,,,,,,,,,,,,,,,,,,,,,
,3832598333.2394,119.391033172607,9999.7685546875,0.0194455672456641,1.93824747860835E-6,1,2,13.4005146026611,5.00819672364284,34.8000004887581,25.9727432424129,3.81980955096356,100,0.000138105634095989,,,,,,,,,,,,,,,,,,,,,119.340682983398,119.441383361816,9999.7685546875,9999.7685546875,49.3434267905244,5.44211258437031,7.5396728515625,27,1,0,0,1,0.29632568359375,40.5669593811035,2,1,1,119.340682983398,0,119.391033172607,,,,,,,,,,,,,,,,,,,,,,,,,,,,,,,,,
,3832598383.89002,116.858123779297,9999.7685546875,0.0195090178566821,2.36648634128782E-6,1,2,13.4005146026611,5.00816835102474,34.8000004887581,26.0571809534716,3.83302487951078,100,0.000139140437324721,,,,,,,,,,,,,,,,,,,,,116.790374755859,116.925872802734,9999.7685546875,9999.7685546875,49.3344380625533,5.44255929906174,7.52434873580933,27,1,0,0,1,0.288238525390625,41.055721282959,2,1,1,116.790374755859,0,116.858123779297,,,,,,,,,,,,,,,,,,,,,,,,,,,,,,,,,
,3832598438.142,114.188121795654,9999.7685546875,0.0195729047100009,1.9675737851477E-6,1,2,13.4005146026611,5.00819927299441,34.8000004887581,26.1429560091643,3.84400687560157,100,0.000138397426989899,,,,,,,,,,,,,,,,,,,,,114.139976501465,114.236267089844,9999.7685546875,9999.7685546875,49.2953566365918,5.44236119652551,7.51861429214478,27,1,0,0,1,0.295639038085937,40.5669593811035,2,1,1,114.139976501465,0,114.188121795654,,,,,,,,,,,,,,,,,,,,,,,,,,,,,,,,,
,3832598488.40083,111.667797088623,9999.7685546875,0.0196298032699636,2.68049205375632E-6,1,2,13.4005146026611,5.00820648412638,34.8000004887581,26.219007424596,3.85517419307427,100,0.000138788662670149,,,,,,,,,,,,,,,,,,,,,111.629997253418,111.705596923828,9999.7685546875,9999.7685546875,49.336782948111,5.44247937434029,7.50850343704224,27,1,0,0,1,0.294876098632812,41.055721282959,2,1,1,111.629997253418,0,111.667797088623,,,,,,,,,,,,,,,,,,,,,,,,,,,,,,,,,
,3832598548.36343,108.654010772705,9999.7685546875,0.0196925587801701,2.85068125246924E-6,1,2,13.4005146026611,5.00813887600672,34.8000004887581,26.3018617046248,3.87086951916246,100,0.000141806756393608,,,,,,,,,,,,,,,,,,,,,108.563323974609,108.744697570801,9999.7685546875,9999.7685546875,49.3328748055148,5.44281610660253,7.48565101623535,27,1,0,0,1,0.295639038085937,40.5669593811035,2,1,1,108.563323974609,0,108.654010772705,,,,,,,,,,,,,,,,,,,,,,,,,,,,,,,,,
,3832598599.1981,106.086910247803,9999.7685546875,0.0197466203188944,1.84925734957481E-6,1,2,13.4005146026611,5.00819802694813,34.7799994051456,26.3747570418322,3.87967323463524,100,0.000140785756139292,,,,,,,,,,,,,,,,,,,,,106.035820007324,106.138000488281,9999.7685546875,9999.7685546875,49.3574961038706,5.44313179750509,7.46708679199219,27,1,0,0,1,0.294418334960937,40.5669593811035,2,1,1,106.035820007324,0,106.086910247803,,,,,,,,,,,,,,,,,,,,,,,,,,,,,,,,,
,3832598653.91126,103.383792877197,9999.7685546875,0.0197977543238245,2.07274055750044E-6,1,2,13.4005146026611,5.00820119007499,34.7799994051456,26.4432604665573,3.8884143133262,100,0.000140171469447026,,,,,,,,,,,,,,,,,,,,,103.35961151123,103.407974243164,9999.7685546875,9999.7685546875,49.3516338899764,5.44276393517783,7.46330261230469,27,1,0,0,1,0.293121337890625,40.5669593811035,2,1,1,103.35961151123,0,103.383792877197,,,,,,,,,,,,,,,,,,,,,,,,,,,,,,,,,
,3832598716.15089,100.286277770996,9999.7685546875,0.0198520791428143,1.6433165746233E-6,1,2,13.4005146026611,5.00823233171177,34.7799994051456,26.515808601979,3.90081399044063,100,0.000141825182754217,,,,,,,,,,,,,,,,,,,,,100.247085571289,100.325469970703,9999.7685546875,9999.7685546875,49.3574961038706,5.44236215288064,7.44234991073608,27,1,0,0,1,0.293197631835937,41.055721282959,2,1,1,100.247085571289,0,100.286277770996,,,,,,,,,,,,,,,,,,,,,,,,,,,,,,,,,
,3832598768.46105,97.6431617736816,9999.7685546875,0.0198942290062996,1.97247303419095E-6,1,2,13.4005146026611,5.0082179513171,34.7799994051456,26.5722968707788,3.90697611177356,100,0.00014055208571802,,,,,,,,,,,,,,,,,,,,,97.6041717529297,97.6821517944336,9999.7685546875,9999.7685546875,49.2676088241591,5.44190073445922,7.43015336990356,27,1,0,0,1,0.296783447265625,41.055721282959,2,1,1,97.6041717529297,0,97.6431617736816,,,,,,,,,,,,,,,,,,,,,,,,,,,,,,,,,
,3832598820.08013,95.0552749633789,9999.7685546875,0.0199308511974553,2.79717491522515E-6,1,2,13.4005146026611,5.00822657929498,34.7799994051456,26.6214840680365,3.91268247997282,100,0.00013969265783277,,,,,,,,,,,,,,,,,,,,,94.9731292724609,95.1374206542969,9999.7685546875,9999.7685546875,49.3137249067937,5.44247665042279,7.42178583145142,27,1,0,0,1,0.295639038085937,40.5669593811035,2,1,1,94.9731292724609,0,95.0552749633789,,,,,,,,,,,,,,,,,,,,,,,,,,,,,,,,,
,3832598871.37009,92.5036544799805,9999.7685546875,0.0199647695263208,2.16177609660186E-6,1,2,13.4005146026611,5.00823726065841,34.7599983215332,26.6666751809946,3.92071907618576,100,0.000140952495861159,,,,,,,,,,,,,,,,,,,,,92.4443130493164,92.5629959106445,9999.7685546875,9999.7685546875,49.3766460025918,5.44272393170183,7.40426588058472,27,1,0,0,1,0.286407470703125,40.5669593811035,2,1,1,92.4443130493164,0,92.5036544799805,,,,,,,,,,,,,,,,,,,,,,,,,,,,,,,,,
,3832598921.58738,90.0075836181641,9999.7685546875,0.0199926900184088,1.62111694545371E-6,1,2,13.4005146026611,5.00817342296907,34.7599983215332,26.703608329391,3.92538009479917,100,0.0001405859179786,,,,,,,,,,,,,,,,,,,,,89.9547271728516,90.0604400634766,9999.7685546875,9999.7685546875,49.2726894095341,5.44259315762086,7.38484477996826,27,1,0,0,1,0.287704467773438,41.055721282959,2,1,1,89.9547271728516,0,90.0075836181641,,,,,,,,,,,,,,,,,,,,,,,,,,,,,,,,,
,3832598974.03622,87.3761711120605,9999.7685546875,0.0200171712635305,1.34965825226241E-6,1,2,13.4005146026611,5.00819425814335,34.7599983215332,26.7367385173088,3.92821141230815,100,0.000139263891967533,,,,,,,,,,,,,,,,,,,,,87.3422012329102,87.4101409912109,9999.7685546875,9999.7685546875,49.4071295148418,5.44250674288589,7.36640501022339,27,1,0,0,1,0.289688110351562,40.5669593811035,2,1,1,87.3422012329102,0,87.3761711120605,,,,,,,,,,,,,,,,,,,,,,,,,,,,,,,,,
,3832599034.44475,84.3253059387207,9999.7685546875,0.0200369669939113,1.60987672713571E-6,1,2,13.4005146026611,5.00813455493397,34.7599983215332,26.7617460205789,3.93916520529612,100,0.000144736899591769,,,,,,,,,,,,,,,,,,,,,84.2787246704102,84.3718872070312,9999.7685546875,9999.7685546875,49.3348288768129,5.44258483516177,7.34842824935913,27,1,0,0,1,0.29541015625,40.5669593811035,2,1,1,84.2787246704102,0,84.3253059387207,,,,,,,,,,,,,,,,,,,,,,,,,,,,,,,,,
,3832599088.80374,81.5969505310059,9999.7685546875,0.0200528777866883,1.83897923912535E-6,1,2,13.4005146026611,5.00813936078342,34.7599983215332,26.7832547917085,3.94070425707438,100,0.000143659509036131,,,,,,,,,,,,,,,,,,,,,81.5407638549805,81.6531372070312,9999.7685546875,9999.7685546875,49.2973107078898,5.44247170963277,7.3350191116333,27,1,0,0,1,0.29449462890625,41.055721282959,2,1,1,81.5407638549805,0,81.5969505310059,,,,,,,,,,,,,,,,,,,,,,,,,,,,,,,,,
,3832599141.43493,78.9954071044922,9999.7685546875,0.0200617494607999,1.95853543792883E-6,1,2,13.4005146026611,5.00817898862354,34.7599983215332,26.7954912118512,3.94179424654874,100,0.000143202436842563,,,,,,,,,,,,,,,,,,,,,78.9651107788086,79.0257034301758,9999.7685546875,9999.7685546875,49.255493582111,5.44239871828288,7.31032752990723,27,1,0,0,1,0.296859741210937,40.5669593811035,2,1,1,78.9651107788086,0,78.9954071044922,,,,,,,,,,,,,,,,,,,,,,,,,,,,,,,,,
,3832599193.70918,76.379222869873,9999.7685546875,0.0200701762606534,2.38737294725601E-6,1,2,13.4005146026611,5.00816725580081,34.7400009632111,26.8061884248399,3.94681455669103,100,0.00014578858851251,,,,,,,,,,,,,,,,,,,,,76.3328628540039,76.4255828857422,9999.7685546875,9999.7685546875,49.306299435861,5.441967631591,7.28438758850098,27,1,0,0,1,0.285491943359375,40.5669593811035,2,1,1,76.3328628540039,0,76.379222869873,,,,,,,,,,,,,,,,,,,,,,,,,,,,,,,,,
,3832599256.04423,73.2148933410644,9999.7685546875,0.0200661277874958,2.05795739194711E-6,1,2,13.4005146026611,5.00814583520983,34.7400009632111,26.8012094839128,3.94181160889049,100,0.000142629915618622,,,,,,,,,,,,,,,,,,,,,73.161865234375,73.2679214477539,9999.7685546875,9999.7685546875,49.346944118861,5.44186870627706,7.27706527709961,27,1,0,0,1,0.293731689453125,40.5669593811035,2,1,1,73.161865234375,0,73.2148933410644,,,,,,,,,,,,,,,,,,,,,,,,,,,,,,,,,
,3832599306.59442,70.7125778198242,9999.7685546875,0.0200572545629672,2.19734271453427E-6,1,2,13.4005146026611,5.00809129191479,34.7400009632111,26.788892152099,3.94048948588687,100,0.000142925568542257,,,,,,,,,,,,,,,,,,,,,70.6828536987305,70.742301940918,9999.7685546875,9999.7685546875,49.3629675035052,5.4421637937393,7.25889158248901,27,1,0,0,1,0.2947998046875,40.5669593811035,2,1,1,70.6828536987305,0,70.7125778198242,,,,,,,,,,,,,,,,,,,,,,,,,,,,,,,,,
,3832599364.85945,67.7754554748535,9999.7685546875,0.0200392880370972,1.52021661535076E-6,1,2,13.4005146026611,5.00811897959259,34.7400009632111,26.7640480180426,3.94449851924723,100,0.000148414017581976,,,,,,,,,,,,,,,,,,,,,67.7188110351562,67.8320999145508,9999.7685546875,9999.7685546875,49.265654752861,5.44226753298349,7.22101926803589,27,1,0,0,1,0.293807983398438,40.5669593811035,2,1,1,67.7188110351562,0,67.7754554748535,,,,,,,,,,,,,,,,,,,,,,,,,,,,,,,,,
,3832599418.52194,65.037483215332,9999.7685546875,0.0200179106317415,2.1894151121842E-6,1,2,13.4005146026611,5.00804278315261,34.7400009632111,26.7352808472323,3.937776683116,100,0.000146436607565748,,,,,,,,,,,,,,,,,,,,,64.9499053955078,65.1250610351562,9999.7685546875,9999.7685546875,49.3481165616398,5.44214816559963,7.21327447891235,27,1,0,0,1,0.28656005859375,40.5669593811035,2,1,1,64.9499053955078,0,65.037483215332,,,,,,,,,,,,,,,,,,,,,,,,,,,,,,,,,
,3832599471.71877,62.3923091888428,9999.7685546875,0.0199892801323312,2.23972749977436E-6,1,2,13.4005146026611,5.00807927091094,34.7400009632111,26.6975200995759,3.93067225335511,100,0.000145096527357197,,,,,,,,,,,,,,,,,,,,,62.3535537719727,62.4310646057129,9999.7685546875,9999.7685546875,49.3141157210533,5.44267592228187,7.16789054870605,27,1,0,0,1,0.28717041015625,40.5669593811035,2,1,1,62.3535537719727,0,62.3923091888428,,,,,,,,,,,,,,,,,,,,,,,,,,,,,,,,,
,3832599524.01018,59.7646484375,9999.7685546875,0.019955264820006,2.07439939258635E-6,1,2,13.4005146026611,5.00809340051751,34.7400009632111,26.6519513811756,3.92572175263597,100,0.000146138447928937,,,,,,,,,,,,,,,,,,,,,59.7200508117676,59.8092460632324,9999.7685546875,9999.7685546875,49.3594501751687,5.44241700155985,7.14919567108154,27,1,0,0,1,0.294265747070313,40.5669593811035,2,1,1,59.7200508117676,0,59.7646484375,,,,,,,,,,,,,,,,,,,,,,,,,,,,,,,,,
,3832599575.67557,57.1416759490967,9999.7685546875,0.0199199249009214,1.78113724302837E-6,1,2,13.4005146026611,5.0080867300247,34.7199998795986,26.6042631797436,3.92191134490767,100,0.00014823501033551,,,,,,,,,,,,,,,,,,,,,57.0727005004883,57.2106513977051,9999.7685546875,9999.7685546875,49.3481165616398,5.44259381095477,7.13212823867798,27,1,0,0,1,0.296173095703125,40.5669593811035,2,1,1,57.0727005004883,0,57.1416759490967,,,,,,,,,,,,,,,,,,,,,,,,,,,,,,,,,
,3832599634.87471,54.1779441833496,9999.7685546875,0.0198693443841102,9.00868804302763E-7,1,2,13.4005146026611,5.0081083485983,34.7199998795986,26.5364630936634,3.91486054087419,100,0.000150016195517272,,,,,,,,,,,,,,,,,,,,,54.1160736083984,54.2398147583008,9999.7685546875,9999.7685546875,49.2672180098994,5.44271649368996,7.08394527435303,27,1,0,0,1,0.287933349609375,40.5669593811035,2,1,1,54.1160736083984,0,54.1779441833496,,,,,,,,,,,,,,,,,,,,,,,,,,,,,,,,,
,3832599695.28189,51.1467571258545,9999.7685546875,0.0198086363944679,2.10387164420844E-6,1,2,13.4005146026611,5.00810457784906,34.7199998795986,26.4554872579428,3.90196671213401,100,0.0001488633507793,,,,,,,,,,,,,,,,,,,,,51.1065864562988,51.1869277954102,9999.7685546875,9999.7685546875,49.3047361788225,5.44226370794155,7.05153608322144,27,1,0,0,1,0.289840698242188,40.5669593811035,2,1,1,51.1065864562988,0,51.1467571258545,,,,,,,,,,,,,,,,,,,,,,,,,,,,,,,,,
,3832599753.68064,48.1561222076416,9999.7685546875,0.0197448343773051,1.19646850050175E-6,1,2,13.4005146026611,5.00817580362175,34.7199998795986,26.3707640736174,3.88965201394074,100,0.000148516718957405,,,,,,,,,,,,,,,,,,,,,48.1008338928223,48.2114105224609,9999.7685546875,9999.7685546875,49.3227136347648,5.44218881497095,7.01348066329956,27,1,0,0,1,0.290374755859375,40.5669593811035,2,1,1,48.1008338928223,0,48.1561222076416,,,,,,,,,,,,,,,,,,,,,,,,,,,,,,,,,
,3832599823.45441,44.676441192627,9999.7685546875,0.0196587493030729,1.27104777093291E-6,1,2,13.4005146026611,5.0082310863131,34.7199998795986,26.2548004141176,3.88266816010787,100,0.000155285877833684,,,,,,,,,,,,,,,,,,,,,44.5892562866211,44.7636260986328,9999.7685546875,9999.7685546875,49.3211503777264,5.44146481172015,6.9603099822998,27,1,0,0,1,0.287933349609375,40.5669593811035,2,1,1,44.5892562866211,0,44.676441192627,,,,,,,,,,,,,,,,,,,,,,,,,,,,,,,,,
,3832599880.64348,41.7935199737549,9999.7685546875,0.0195903235887666,2.00783635576935E-6,1,2,13.4005146026611,5.00827376031899,34.7100012004375,26.1641408294622,3.86619421660228,100,0.000152498065969637,,,,,,,,,,,,,,,,,,,,,41.7400512695313,41.8469886779785,9999.7685546875,9999.7685546875,49.2660455671206,5.44147002250913,6.8858060836792,27,1,0,0,1,0.287322998046875,40.5669593811035,2,1,1,41.7400512695313,0,41.7935199737549,,,,,,,,,,,,,,,,,,,,,,,,,,,,,,,,,
,3832599952.46449,38.2143211364746,9999.7685546875,0.0194948817065035,1.45039906557947E-6,1,2,13.4005146026611,5.00825765553112,34.7100012004375,26.0361573444311,3.85020425455051,100,0.00015389616514589,,,,,,,,,,,,,,,,,,,,,38.1365699768066,38.2920722961426,9999.7685546875,9999.7685546875,49.3524155184956,5.44183691283525,6.81661987304687,27,1,0,0,1,0.294723510742188,41.055721282959,2,1,1,38.1365699768066,0,38.2143211364746,,,,,,,,,,,,,,,,,,,,,,,,,,,,,,,,,
,3832600011.66093,35.2283611297607,9999.7685546875,0.0194173194897743,1.85422775267183E-6,1,2,13.4005146026611,5.00827899057812,34.7100012004375,25.9319662922619,3.84030616686132,100,0.000157321192934345,,,,,,,,,,,,,,,,,,,,,35.1707382202148,35.2859840393066,9999.7685546875,9999.7685546875,49.2558843963706,5.44158042626097,6.73818063735962,27,1,0,0,1,0.286483764648438,40.5669593811035,2,1,1,35.1707382202148,0,35.2283611297607,,,,,,,,,,,,,,,,,,,,,,,,,,,,,,,,,
,3832600100.23331,30.7602529525757,9999.7685546875,0.0193010160434263,1.32293634564409E-6,1,2,13.4005146026611,5.00826762349597,34.7100012004375,25.7752173044524,3.82691119717216,100,0.000163573306721846,,,,,,,,,,,,,,,,,,,,,30.704402923584,30.8161029815674,9999.7685546875,9999.7685546875,49.2410334545052,5.44159589648829,6.596519947052,27,1,0,0,1,0.295944213867188,40.5669593811035,2,1,1,30.704402923584,0,30.7602529525757,,,,,,,,,,,,,,,,,,,,,,,,,,,,,,,,,
,3832600150.72569,28.2528409957886,9999.7685546875,0.0192430411283024,1.99725266314398E-6,1,2,13.4005146026611,5.00822461748295,34.6999987959862,25.6961698454719,3.82484216580758,100,0.000170165538673037,,,,,,,,,,,,,,,,,,,,,28.2096652984619,28.2960166931152,9999.7685546875,9999.7685546875,49.3125524640148,5.44218356021855,6.49366474151611,27,1,0,0,1,0.29541015625,40.5669593811035,2,1,1,28.2096652984619,0,28.2528409957886,,,,,,,,,,,,,,,,,,,,,,,,,,,,,,,,,
,3832600219.43415,24.8328771591187,9999.7685546875,0.01917120700143,2.7697614889435E-6,1,2,13.4005146026611,5.00825563411229,34.6999987959862,25.6001123086634,3.81310407234606,100,0.000171405952858007,,,,,,,,,,,,,,,,,,,,,24.8106002807617,24.8551540374756,9999.7685546875,9999.7685546875,49.3598409894283,5.44119146740964,6.3166651725769,27,1,0,0,1,0.293197631835937,40.5669593811035,2,1,1,24.8106002807617,0,24.8328771591187,,,,,,,,,,,,,,,,,,,,,,,,,,,,,,,,,
,3832600307.91545,20.3836469650269,9999.7685546875,0.0191052435555617,2.70440954112345E-6,1,2,13.4005146026611,5.00823794371694,34.6999987959862,25.5106388980562,3.8090237028466,100,0.000177590975580038,,,,,,,,,,,,,,,,,,,,,20.3265190124512,20.4407749176025,9999.7685546875,9999.7685546875,49.2676088241591,5.44136794847539,5.9858980178833,27,1,0,0,1,0.294876098632812,40.5669593811035,2,1,1,20.3265190124512,0,20.3836469650269,,,,,,,,,,,,,,,,,,,,,,,,,,,,,,,,,
,3832600394.3939,16.1396532058716,9999.7685546875,0.0190879058563169,1.48125337499572E-6,1,2,13.4005146026611,5.00829559542191,34.6999987959862,25.486835072184,3.81316772122282,100,0.000183069763256599,,,,,,,,,,,,,,,,,,,,,16.0991249084473,16.1801815032959,9999.7685546875,9999.7685546875,49.3098167641975,5.44104346250122,5.50481271743774,27,1,0,0,1,0.286865234375,40.5669593811035,2,1,1,16.0991249084473,0,16.1396532058716,,,,,,,,,,,,,,,,,,,,,,,,,,,,,,,,,
,3832600474.62596,12.2050504684448,9999.7685546875,0.0191327593149339,2.38401729438876E-6,1,2,13.4005146026611,5.00821683925603,34.6999987959862,25.5452236634556,3.82885603925225,100,0.000188593555921714,,,,,,,,,,,,,,,,,,,,,12.2050504684448,12.2050504684448,9999.7685546875,9999.7685546875,49.3403002764475,5.44090426573222,4.62787103652954,27,1,0,0,1,0.297088623046875,40.5669593811035,2,1,1,12.2050504684448,0,12.2050504684448,,,,,,,,,,,,,,,,,,,,,,,,,,,,,,,,,
,3832600547.15875,8.9444317817688,9999.7685546875,0.019244152176534,2.16664472462336E-6,1,2,13.4005146026611,5.00817591408972,34.6999987959862,25.6922616906781,3.86113108795729,100,0.000197190591502675,,,,,,,,,,,,,,,,,,,,,8.84962463378906,9.03923892974854,9999.7685546875,9999.7685546875,49.3016096647456,5.44064883553974,4.23795938491821,27,1,0,0,1,0.294952392578125,40.5669593811035,6,1,1,8.84962463378906,0,8.9444317817688,,,,,,,,,,,,,,,,,,,,,,,,,,,,,,,,,
,3832600599.9499,8.00021457672119,9999.7685546875,0.019296126406663,2.65642124362915E-6,1,2,13.4005146026611,5.00821669537431,34.6900001168251,25.7635643718927,3.85996752061529,100,0.000189021038988054,,,,,,,,,,,,,,,,,,,,,8.00009155273437,8.00033760070801,9999.7685546875,9999.7685546875,49.255493582111,5.44111711024331,4.16451978683472,27,1,0,0,1,0.28717041015625,40.5669593811035,5,1,1,8.00009155273437,0,8.00021457672119,,,,,,,,,,,,,,,,,,,,,,,,,,,,,,,,,
,3832600628.11784,7.99991822242737,9999.7685546875,0.019297509602333,1.74236695755289E-6,1,2,13.4005146026611,5.00821174219503,34.6900001168251,25.7649206965971,3.86349773528884,100,0.000191471946610182,,,,,,,,,,,,,,,,,,,,,7.99967527389526,8.00016117095947,9999.7685546875,9999.7685546875,49.2867587228802,5.44109750583885,4.1680269241333,27,1,0,0,1,0.289154052734375,40.5669593811035,1,1,1,7.99967527389526,0,7.99991822242737,,,,,,,,,,,,,,,,,,,,,,,,,,,,,,,,,